Workbook
Name lst_region: OFFSET(Lists!$A$2,0,0,MAX(1,COUNTA(Lists!$A$2:$A$100)),1)
Name lst_currency: OFFSET(Lists!$B$2,0,0,MAX(1,COUNTA(Lists!$B$2:$B$100)),1)
Name lst_contract_type: OFFSET(Lists!$C$2,0,0,MAX(1,COUNTA(Lists!$C$2:$C$100)),1)
Name lst_employment_type: OFFSET(Lists!$D$2,0,0,MAX(1,COUNTA(Lists!$D$2:$D$100)),1)
Name lst_allocation_type: OFFSET(Lists!$E$2,0,0,MAX(1,COUNTA(Lists!$E$2:$E$100)),1)
Name lst_source_type: OFFSET(Lists!$F$2,0,0,MAX(1,COUNTA(Lists!$F$2:$F$100)),1)
Name lst_cost_category: OFFSET(Lists!$G$2,0,0,MAX(1,COUNTA(Lists!$G$2:$G$100)),1)
Name lst_rate_type: OFFSET(Lists!$H$2,0,0,MAX(1,COUNTA(Lists!$H$2:$H$100)),1)
Name lst_yes_no: OFFSET(Lists!$I$2,0,0,MAX(1,COUNTA(Lists!$I$2:$I$100)),1)
Name lst_cost_center: OFFSET(Cost_Centers!$A$2,0,0,MAX(1,COUNTA(Cost_Centers!$A$2:$A$2000)),1)
Name lst_account: OFFSET(Accounts!$A$2,0,0,MAX(1,COUNTA(Accounts!$A$2:$A$5000)),1)
Name rng_BvA: Budget_vs_Actual!$A$8:$V$1209
Name prm_close_month: Budget_vs_Actual!$C$4

Sheet Field_Definitions
A1: GDS Budget Ledger – Field Definitions / 項目定義
A3: How to use / 使い方
A4: • | B4: Opex_Budget is the only place where budgets are entered. It will be locked once the budget is final. | E4: 予算を入れる場所はOpex_Budgetだけです。予算確定後はロックされます。
A5: • | B5: Actuals: the budget manager pastes the accounting data as values at the end of the table every month, with import_batch set to the closing month. | E5: Actuals：予算管理者が毎月、会計データを表の末尾に値で貼り付けます。import_batchには締め月を入れます。
A6: • | B6: Budget_vs_Actual: set fiscal_year, close_month and display_currency at the top. Owners enter only the Forecast (input) and Rationale rows (light blue cells). | E6: Budget_vs_Actual：上部で会計年度・締め月・表示通貨を指定します。責任者が入力するのは見込み入力行と理由行（薄い青のセル）だけです。
A7: • | B7: Monthly order (budget manager, Excel desktop): 1) on Prior_Forecast, right-click the table > Refresh; 2) paste the new actuals into Actuals; 3) advance close_month. Always refresh Prior_Forecast before pasting actuals. See the monthly runbook for details. | E7: 毎月の手順（予算管理者、デスクトップ版Excel）：①Prior_Forecastの表を右クリック＞更新 ②新しい実績をActualsに貼り付ける ③締め月を進める。Prior_Forecastの更新は必ず実績の貼り付けより前に行う。詳細は月次運用手順書を参照。
A8: • | B8: If a check at the top of Budget_vs_Actual is not 0, some budget or actual rows have no block. Ask IT Finance to add the cost center and account. | E8: Budget_vs_Actual上部のチェックが0でない場合、ブロックのない予算・実績があります。ITファイナンスにコストセンター・勘定科目の追加を依頼してください。
A9: • | B9: Use Sheet View (View > Sheet View) to filter or sort, so other users are not affected. | E9: 絞り込み・並べ替えは「シートビュー」（表示＞シートビュー）で行い、他の人の表示を変えないでください。
A10: • | B10: Enter one record per row. Do not insert blank rows, merge cells or change column headers. | E10: 1行に1件を入力します。空行の挿入、セルの結合、列見出しの変更はしないでください。
A11: • | B11: Yes = required. Yes* = required depending on the type (see description). Use the dropdowns for List fields. | E11: Yes＝必須。Yes*＝種別によって必須（説明を参照）。List型はプルダウンから選びます。
A12: • | B12: Dates: YYYY-MM-DD. Amounts: excluding tax, in the currency of the row. Do not convert currencies. | E12: 日付はYYYY-MM-DD。金額は税抜で、その行の通貨のまま入力します。換算はしないでください。
A13: • | B13: The Example column shows the expected format only. Do not copy example values. | E13: Example列は入力形式の例です。例の値を転記しないでください。
A14: • | B14: Grey sheets (Cost_Centers, Accounts, FX_Rates, Lists) are copies of the master data file and must not be edited. To get the latest values, open in Excel desktop and click Data > Refresh All (not needed every time). To add or change values, ask IT Finance. | E14: グレーのシート（Cost_Centers・Accounts・FX_Rates・Lists）はマスタファイルの写しで、編集しません。最新にするときはデスクトップ版Excelで「データ＞すべて更新」を押します（毎回は不要）。値の追加・変更はITファイナンスに依頼してください。
A16: Sheets / シート一覧
A17: Sheet | B17: Maintained by | C17: Purpose (EN) | E17: 目的（日本語）
A18: Opex_Budget | B18: Input | C18: All budgets of GDS. Fixed (locked) once the budget is final. One row per fiscal year. | E18: GDSの予算をすべて集約するシート。予算確定後は固定（ロック）する。1行＝1会計年度
A19: Actuals | B19: ITF only | C19: Actuals downloaded from each region's accounting system, pasted monthly by the budget manager. | E19: 各リージョンの会計システムからダウンロードした実績。予算管理者が毎月貼り付ける
A20: Dashboard | B20: Auto (do not edit) | C20: Overview: KPIs, region x sub-function, monthly trend and the largest variances. Follows the settings at the top of Budget_vs_Actual. | E20: 全体像：KPI、リージョン×サブファンクション、月次推移、差異の大きい項目。Budget_vs_Actual上部の設定（年度・締め月・通貨）に連動する
A21: Budget_vs_Actual | B21: Auto (do not edit) / Forecast & Rationale: Input | C21: Budget, actual and actual + forecast by cost center and account, with variances and rationale. Budget and actual are filled automatically. | E21: コストセンター×勘定科目ごとの予算・実績・実績＋見込みと、差異・理由。予算と実績は自動で表示される
A22: Prior_Forecast | B22: ITF only | C22: Snapshot of the Actual + Forecast rows, refreshed by Power Query before new actuals are pasted. Feeds the Prior Month Forecast row. | E22: 実績＋見込み行の控え。新しい実績を貼り付ける前にPower Queryで更新する。前月見込みの行に表示される
A24: Opex_Budget — Input
A25: Sheet | B25: Field (EN) | C25: 項目名（日本語） | D25: Type | E25: Required | F25: Example | G25: Description (EN) | H25: 説明（日本語）
A26: Opex_Budget | B26: fiscal_year | C26: 会計年度 | D26: Integer | E26: Yes | F26: 2027 | G26: Fiscal year (January to December). | H26: 会計年度（1月〜12月）
A27: Opex_Budget | B27: region | C27: リージョン | D27: List | E27: Yes | F27: JP | G27: Region of the cost center. JP / NA / EMEA. | H27: コストセンターのリージョン。JP／NA／EMEA
A28: Opex_Budget | B28: owner | C28: 入力責任者 | D28: Text | E28: Yes | F28: T. Yamada | G28: Person responsible for keeping this row up to date. | H28: この行を最新に保つ責任者
A29: Opex_Budget | B29: budget_id | C29: 予算ID | D29: Text | E29: No | F29: BT-0012 | G29: Optional ID to identify the budget line (e.g. budget transfer case ID, internal budget number). | H29: 予算行を識別する任意のID（予算移管の案件ID、社内の予算番号など）
A30: Opex_Budget | B30: cost_center_code | C30: コストセンター | D30: List | E30: Yes | F30: JP-GDS-APP | G30: Cost center that bears the cost. | H30: 費用を計上するコストセンター
A31: Opex_Budget | B31: account_key | C31: 勘定科目 | D31: List | E31: Yes | F31: JP|5101 | G31: Local account of the region (format: region|local code). | H31: 当該リージョンの現地勘定科目（形式：リージョン|現地科目コード）
A32: Opex_Budget | B32: cost_category | C32: 費用区分 | D32: List | E32: Yes | F32: SaaS / License | G32: Nature of the cost, independent of the accounting account: SaaS / License, Maintenance, Outsourcing, Cloud, Telecom, Hardware, Personnel, Depreciation, Travel & Training, Other. | H32: 会計上の勘定科目とは別に、費用の性質で分類する区分（SaaS・ライセンス、保守、業務委託、クラウド、通信、ハードウェア、人件費、減価償却、出張・研修、その他）
A33: Opex_Budget | B33: system_name | C33: システム名 | D33: Text | E33: Yes | F33: Salesforce | G33: System the cost relates to. Use 'Common' for costs not tied to one system. | H33: 費用が関係するシステム。特定のシステムに紐づかない費用は「Common」と書く
A34: Opex_Budget | B34: vendor_name | C34: ベンダー名 | D34: Text | E34: Yes | F34: Salesforce Japan | G34: Vendor or supplier. Use 'Internal' for internal staff cost. | H34: ベンダー・取引先。社内人件費は「Internal」と書く
A35: Opex_Budget | B35: expense_item | C35: 費目 | D35: Text | E35: Yes | F35: Domestic travel | G35: What the budget is for. Several items may share the same cost center and account. | H35: 予算の内容。同じコストセンター・勘定科目の中で複数に分けてよい
A36: Opex_Budget | B36: project_id | C36: プロジェクトID | D36: Text | E36: Yes* | F36: CAPEX-2027-014 | G36: Capital investment budget number. *Required when the cost belongs to a project. | H36: 設備投資予算の管理番号。※プロジェクト案件の費用の場合は必須
... A51: Opex_Budget | B51: m12 | C51: 12月 | D51: Number | E51: No | F51: 500000 | G51: Budget for month 12, excluding tax. | H51: 12月の予算額（税抜）
A52: Opex_Budget | B52: note | C52: 備考 | D52: Text | E52: No | G52: Free comment. | H52: 備考
A54: Actuals — ITF only
A55: Sheet | B55: Field (EN) | C55: 項目名（日本語） | D55: Type | E55: Required | F55: Example | G55: Description (EN) | H55: 説明（日本語）
A56: Actuals | B56: region | C56: リージョン | D56: List | E56: Yes | F56: JP | G56: Region of the cost center. JP / NA / EMEA. | H56: コストセンターのリージョン。JP／NA／EMEA
A57: Actuals | B57: fiscal_year | C57: 会計年度 | D57: Integer | E57: Yes | F57: 2027 | G57: Fiscal year of the posting. | H57: 計上の会計年度
A58: Actuals | B58: month | C58: 月 | D58: Integer | E58: Yes | F58: 4 | G58: Posting month (1-12). | H58: 計上月（1〜12）
...

Sheet Dashboard
A1: GDS Budget Dashboard / 予算ダッシュボード
A2: ="FY "&Budget_vs_Actual!$C$3&" | Close month: "&Budget_vs_Actual!$C$4&" | Currency: "&Budget_vs_Actual!$C$5&" | Prior forecast as of month: "&Budget_vs_Actual!$G$7
A4: Key figures / 主要指標
A5: FY Budget | B5: YTD Budget | C5: YTD Actual | D5: YTD Variance | E5: FY Actual + Forecast | F5: FY Variance vs Budget | G5: FY Variance vs Budget (prior month) | H5: Change vs Prior Month
A6: 通期予算 | B6: 累計予算 | C6: 累計実績 | D6: 累計差異 | E6: 通期着地見込み | F6: 通期差異（対予算） | G6: 前月時点の通期差異（対予算） | H6: 前月からの変化
A7: =SUMIFS(Budget_vs_Actual!$V:$V,Budget_vs_Actual!$G:$G,"Budget") | B7: =SUMIFS(Budget_vs_Actual!$T:$T,Budget_vs_Actual!$G:$G,"Budget") | C7: =SUMIFS(Budget_vs_Actual!$T:$T,Budget_vs_Actual!$G:$G,"Actual") | D7: =C7-B7 | E7: =SUMIFS(Budget_vs_Actual!$V:$V,Budget_vs_Actual!$G:$G,"Actual + Forecast") | F7: =E7-A7 | G7: =F7-H7 | H7: =SUMIFS(Budget_vs_Actual!$V:$V,Budget_vs_Actual!$G:$G,"Variance vs Prior Month")
D8: =IFERROR(D7/B7,0) | F8: =IFERROR(F7/A7,0) | G8: =IFERROR(G7/A7,0) | H8: =IFERROR(H7/A7,0)
A11: By region and sub-function / リージョン×サブファンクション別
A12: Region | B12: Sub-function | C12: FY Budget | D12: YTD Budget | E12: YTD Actual | F12: YTD Variance | G12: FY Actual + Forecast | H12: FY Variance | I12: Change vs Prior
A13: JP | B13: Applications | C13: =SUMIFS(Budget_vs_Actual!$V:$V,Budget_vs_Actual!$G:$G,"Budget",Budget_vs_Actual!$A:$A,"JP",Budget_vs_Actual!$X:$X,"Applications",Budget_vs_Actual!$Y:$Y,"GDS") | D13: =SUMIFS(Budget_vs_Actual!$T:$T,Budget_vs_Actual!$G:$G,"Budget",Budget_vs_Actual!$A:$A,"JP",Budget_vs_Actual!$X:$X,"Applications",Budget_vs_Actual!$Y:$Y,"GDS") | E13: =SUMIFS(Budget_vs_Actual!$T:$T,Budget_vs_Actual!$G:$G,"Actual",Budget_vs_Actual!$A:$A,"JP",Budget_vs_Actual!$X:$X,"Applications",Budget_vs_Actual!$Y:$Y,"GDS") | F13: =E13-D13 | G13: =SUMIFS(Budget_vs_Actual!$V:$V,Budget_vs_Actual!$G:$G,"Actual + Forecast",Budget_vs_Actual!$A:$A,"JP",Budget_vs_Actual!$X:$X,"Applications",Budget_vs_Actual!$Y:$Y,"GDS") | H13: =G13-C13 | I13: =SUMIFS(Budget_vs_Actual!$V:$V,Budget_vs_Actual!$G:$G,"Variance vs Prior Month",Budget_vs_Actual!$A:$A,"JP",Budget_vs_Actual!$X:$X,"Applications",Budget_vs_Actual!$Y:$Y,"GDS")
A14: JP | B14: Infrastructure | C14: =SUMIFS(Budget_vs_Actual!$V:$V,Budget_vs_Actual!$G:$G,"Budget",Budget_vs_Actual!$A:$A,"JP",Budget_vs_Actual!$X:$X,"Infrastructure",Budget_vs_Actual!$Y:$Y,"GDS") | D14: =SUMIFS(Budget_vs_Actual!$T:$T,Budget_vs_Actual!$G:$G,"Budget",Budget_vs_Actual!$A:$A,"JP",Budget_vs_Actual!$X:$X,"Infrastructure",Budget_vs_Actual!$Y:$Y,"GDS") | E14: =SUMIFS(Budget_vs_Actual!$T:$T,Budget_vs_Actual!$G:$G,"Actual",Budget_vs_Actual!$A:$A,"JP",Budget_vs_Actual!$X:$X,"Infrastructure",Budget_vs_Actual!$Y:$Y,"GDS") | F14: =E14-D14 | G14: =SUMIFS(Budget_vs_Actual!$V:$V,Budget_vs_Actual!$G:$G,"Actual + Forecast",Budget_vs_Actual!$A:$A,"JP",Budget_vs_Actual!$X:$X,"Infrastructure",Budget_vs_Actual!$Y:$Y,"GDS") | H14: =G14-C14 | I14: =SUMIFS(Budget_vs_Actual!$V:$V,Budget_vs_Actual!$G:$G,"Variance vs Prior Month",Budget_vs_Actual!$A:$A,"JP",Budget_vs_Actual!$X:$X,"Infrastructure",Budget_vs_Actual!$Y:$Y,"GDS")
A15: JP | B15: Data | C15: =SUMIFS(Budget_vs_Actual!$V:$V,Budget_vs_Actual!$G:$G,"Budget",Budget_vs_Actual!$A:$A,"JP",Budget_vs_Actual!$X:$X,"Data",Budget_vs_Actual!$Y:$Y,"GDS") | D15: =SUMIFS(Budget_vs_Actual!$T:$T,Budget_vs_Actual!$G:$G,"Budget",Budget_vs_Actual!$A:$A,"JP",Budget_vs_Actual!$X:$X,"Data",Budget_vs_Actual!$Y:$Y,"GDS") | E15: =SUMIFS(Budget_vs_Actual!$T:$T,Budget_vs_Actual!$G:$G,"Actual",Budget_vs_Actual!$A:$A,"JP",Budget_vs_Actual!$X:$X,"Data",Budget_vs_Actual!$Y:$Y,"GDS") | F15: =E15-D15 | G15: =SUMIFS(Budget_vs_Actual!$V:$V,Budget_vs_Actual!$G:$G,"Actual + Forecast",Budget_vs_Actual!$A:$A,"JP",Budget_vs_Actual!$X:$X,"Data",Budget_vs_Actual!$Y:$Y,"GDS") | H15: =G15-C15 | I15: =SUMIFS(Budget_vs_Actual!$V:$V,Budget_vs_Actual!$G:$G,"Variance vs Prior Month",Budget_vs_Actual!$A:$A,"JP",Budget_vs_Actual!$X:$X,"Data",Budget_vs_Actual!$Y:$Y,"GDS")
A16: JP | B16: Security | C16: =SUMIFS(Budget_vs_Actual!$V:$V,Budget_vs_Actual!$G:$G,"Budget",Budget_vs_Actual!$A:$A,"JP",Budget_vs_Actual!$X:$X,"Security",Budget_vs_Actual!$Y:$Y,"GDS") | D16: =SUMIFS(Budget_vs_Actual!$T:$T,Budget_vs_Actual!$G:$G,"Budget",Budget_vs_Actual!$A:$A,"JP",Budget_vs_Actual!$X:$X,"Security",Budget_vs_Actual!$Y:$Y,"GDS") | E16: =SUMIFS(Budget_vs_Actual!$T:$T,Budget_vs_Actual!$G:$G,"Actual",Budget_vs_Actual!$A:$A,"JP",Budget_vs_Actual!$X:$X,"Security",Budget_vs_Actual!$Y:$Y,"GDS") | F16: =E16-D16 | G16: =SUMIFS(Budget_vs_Actual!$V:$V,Budget_vs_Actual!$G:$G,"Actual + Forecast",Budget_vs_Actual!$A:$A,"JP",Budget_vs_Actual!$X:$X,"Security",Budget_vs_Actual!$Y:$Y,"GDS") | H16: =G16-C16 | I16: =SUMIFS(Budget_vs_Actual!$V:$V,Budget_vs_Actual!$G:$G,"Variance vs Prior Month",Budget_vs_Actual!$A:$A,"JP",Budget_vs_Actual!$X:$X,"Security",Budget_vs_Actual!$Y:$Y,"GDS")
A17: JP | B17: Governance | C17: =SUMIFS(Budget_vs_Actual!$V:$V,Budget_vs_Actual!$G:$G,"Budget",Budget_vs_Actual!$A:$A,"JP",Budget_vs_Actual!$X:$X,"Governance",Budget_vs_Actual!$Y:$Y,"GDS") | D17: =SUMIFS(Budget_vs_Actual!$T:$T,Budget_vs_Actual!$G:$G,"Budget",Budget_vs_Actual!$A:$A,"JP",Budget_vs_Actual!$X:$X,"Governance",Budget_vs_Actual!$Y:$Y,"GDS") | E17: =SUMIFS(Budget_vs_Actual!$T:$T,Budget_vs_Actual!$G:$G,"Actual",Budget_vs_Actual!$A:$A,"JP",Budget_vs_Actual!$X:$X,"Governance",Budget_vs_Actual!$Y:$Y,"GDS") | F17: =E17-D17 | G17: =SUMIFS(Budget_vs_Actual!$V:$V,Budget_vs_Actual!$G:$G,"Actual + Forecast",Budget_vs_Actual!$A:$A,"JP",Budget_vs_Actual!$X:$X,"Governance",Budget_vs_Actual!$Y:$Y,"GDS") | H17: =G17-C17 | I17: =SUMIFS(Budget_vs_Actual!$V:$V,Budget_vs_Actual!$G:$G,"Variance vs Prior Month",Budget_vs_Actual!$A:$A,"JP",Budget_vs_Actual!$X:$X,"Governance",Budget_vs_Actual!$Y:$Y,"GDS")
A18: JP | B18: Transferred (other functions) | C18: =SUMIFS(Budget_vs_Actual!$V:$V,Budget_vs_Actual!$G:$G,"Budget",Budget_vs_Actual!$A:$A,"JP",Budget_vs_Actual!$Y:$Y,"<>GDS") | D18: =SUMIFS(Budget_vs_Actual!$T:$T,Budget_vs_Actual!$G:$G,"Budget",Budget_vs_Actual!$A:$A,"JP",Budget_vs_Actual!$Y:$Y,"<>GDS") | E18: =SUMIFS(Budget_vs_Actual!$T:$T,Budget_vs_Actual!$G:$G,"Actual",Budget_vs_Actual!$A:$A,"JP",Budget_vs_Actual!$Y:$Y,"<>GDS") | F18: =E18-D18 | G18: =SUMIFS(Budget_vs_Actual!$V:$V,Budget_vs_Actual!$G:$G,"Actual + Forecast",Budget_vs_Actual!$A:$A,"JP",Budget_vs_Actual!$Y:$Y,"<>GDS") | H18: =G18-C18 | I18: =SUMIFS(Budget_vs_Actual!$V:$V,Budget_vs_Actual!$G:$G,"Variance vs Prior Month",Budget_vs_Actual!$A:$A,"JP",Budget_vs_Actual!$Y:$Y,"<>GDS")
A19: JP | B19: Subtotal | C19: =SUM(C13:C18) | D19: =SUM(D13:D18) | E19: =SUM(E13:E18) | F19: =SUM(F13:F18) | G19: =SUM(G13:G18) | H19: =SUM(H13:H18) | I19: =SUM(I13:I18)
A20: NA | B20: Applications | C20: =SUMIFS(Budget_vs_Actual!$V:$V,Budget_vs_Actual!$G:$G,"Budget",Budget_vs_Actual!$A:$A,"NA",Budget_vs_Actual!$X:$X,"Applications",Budget_vs_Actual!$Y:$Y,"GDS") | D20: =SUMIFS(Budget_vs_Actual!$T:$T,Budget_vs_Actual!$G:$G,"Budget",Budget_vs_Actual!$A:$A,"NA",Budget_vs_Actual!$X:$X,"Applications",Budget_vs_Actual!$Y:$Y,"GDS") | E20: =SUMIFS(Budget_vs_Actual!$T:$T,Budget_vs_Actual!$G:$G,"Actual",Budget_vs_Actual!$A:$A,"NA",Budget_vs_Actual!$X:$X,"Applications",Budget_vs_Actual!$Y:$Y,"GDS") | F20: =E20-D20 | G20: =SUMIFS(Budget_vs_Actual!$V:$V,Budget_vs_Actual!$G:$G,"Actual + Forecast",Budget_vs_Actual!$A:$A,"NA",Budget_vs_Actual!$X:$X,"Applications",Budget_vs_Actual!$Y:$Y,"GDS") | H20: =G20-C20 | I20: =SUMIFS(Budget_vs_Actual!$V:$V,Budget_vs_Actual!$G:$G,"Variance vs Prior Month",Budget_vs_Actual!$A:$A,"NA",Budget_vs_Actual!$X:$X,"Applications",Budget_vs_Actual!$Y:$Y,"GDS")
A21: NA | B21: Infrastructure | C21: =SUMIFS(Budget_vs_Actual!$V:$V,Budget_vs_Actual!$G:$G,"Budget",Budget_vs_Actual!$A:$A,"NA",Budget_vs_Actual!$X:$X,"Infrastructure",Budget_vs_Actual!$Y:$Y,"GDS") | D21: =SUMIFS(Budget_vs_Actual!$T:$T,Budget_vs_Actual!$G:$G,"Budget",Budget_vs_Actual!$A:$A,"NA",Budget_vs_Actual!$X:$X,"Infrastructure",Budget_vs_Actual!$Y:$Y,"GDS") | E21: =SUMIFS(Budget_vs_Actual!$T:$T,Budget_vs_Actual!$G:$G,"Actual",Budget_vs_Actual!$A:$A,"NA",Budget_vs_Actual!$X:$X,"Infrastructure",Budget_vs_Actual!$Y:$Y,"GDS") | F21: =E21-D21 | G21: =SUMIFS(Budget_vs_Actual!$V:$V,Budget_vs_Actual!$G:$G,"Actual + Forecast",Budget_vs_Actual!$A:$A,"NA",Budget_vs_Actual!$X:$X,"Infrastructure",Budget_vs_Actual!$Y:$Y,"GDS") | H21: =G21-C21 | I21: =SUMIFS(Budget_vs_Actual!$V:$V,Budget_vs_Actual!$G:$G,"Variance vs Prior Month",Budget_vs_Actual!$A:$A,"NA",Budget_vs_Actual!$X:$X,"Infrastructure",Budget_vs_Actual!$Y:$Y,"GDS")
A22: NA | B22: Data | C22: =SUMIFS(Budget_vs_Actual!$V:$V,Budget_vs_Actual!$G:$G,"Budget",Budget_vs_Actual!$A:$A,"NA",Budget_vs_Actual!$X:$X,"Data",Budget_vs_Actual!$Y:$Y,"GDS") | D22: =SUMIFS(Budget_vs_Actual!$T:$T,Budget_vs_Actual!$G:$G,"Budget",Budget_vs_Actual!$A:$A,"NA",Budget_vs_Actual!$X:$X,"Data",Budget_vs_Actual!$Y:$Y,"GDS") | E22: =SUMIFS(Budget_vs_Actual!$T:$T,Budget_vs_Actual!$G:$G,"Actual",Budget_vs_Actual!$A:$A,"NA",Budget_vs_Actual!$X:$X,"Data",Budget_vs_Actual!$Y:$Y,"GDS") | F22: =E22-D22 | G22: =SUMIFS(Budget_vs_Actual!$V:$V,Budget_vs_Actual!$G:$G,"Actual + Forecast",Budget_vs_Actual!$A:$A,"NA",Budget_vs_Actual!$X:$X,"Data",Budget_vs_Actual!$Y:$Y,"GDS") | H22: =G22-C22 | I22: =SUMIFS(Budget_vs_Actual!$V:$V,Budget_vs_Actual!$G:$G,"Variance vs Prior Month",Budget_vs_Actual!$A:$A,"NA",Budget_vs_Actual!$X:$X,"Data",Budget_vs_Actual!$Y:$Y,"GDS")
A23: NA | B23: Security | C23: =SUMIFS(Budget_vs_Actual!$V:$V,Budget_vs_Actual!$G:$G,"Budget",Budget_vs_Actual!$A:$A,"NA",Budget_vs_Actual!$X:$X,"Security",Budget_vs_Actual!$Y:$Y,"GDS") | D23: =SUMIFS(Budget_vs_Actual!$T:$T,Budget_vs_Actual!$G:$G,"Budget",Budget_vs_Actual!$A:$A,"NA",Budget_vs_Actual!$X:$X,"Security",Budget_vs_Actual!$Y:$Y,"GDS") | E23: =SUMIFS(Budget_vs_Actual!$T:$T,Budget_vs_Actual!$G:$G,"Actual",Budget_vs_Actual!$A:$A,"NA",Budget_vs_Actual!$X:$X,"Security",Budget_vs_Actual!$Y:$Y,"GDS") | F23: =E23-D23 | G23: =SUMIFS(Budget_vs_Actual!$V:$V,Budget_vs_Actual!$G:$G,"Actual + Forecast",Budget_vs_Actual!$A:$A,"NA",Budget_vs_Actual!$X:$X,"Security",Budget_vs_Actual!$Y:$Y,"GDS") | H23: =G23-C23 | I23: =SUMIFS(Budget_vs_Actual!$V:$V,Budget_vs_Actual!$G:$G,"Variance vs Prior Month",Budget_vs_Actual!$A:$A,"NA",Budget_vs_Actual!$X:$X,"Security",Budget_vs_Actual!$Y:$Y,"GDS")
A24: NA | B24: Governance | C24: =SUMIFS(Budget_vs_Actual!$V:$V,Budget_vs_Actual!$G:$G,"Budget",Budget_vs_Actual!$A:$A,"NA",Budget_vs_Actual!$X:$X,"Governance",Budget_vs_Actual!$Y:$Y,"GDS") | D24: =SUMIFS(Budget_vs_Actual!$T:$T,Budget_vs_Actual!$G:$G,"Budget",Budget_vs_Actual!$A:$A,"NA",Budget_vs_Actual!$X:$X,"Governance",Budget_vs_Actual!$Y:$Y,"GDS") | E24: =SUMIFS(Budget_vs_Actual!$T:$T,Budget_vs_Actual!$G:$G,"Actual",Budget_vs_Actual!$A:$A,"NA",Budget_vs_Actual!$X:$X,"Governance",Budget_vs_Actual!$Y:$Y,"GDS") | F24: =E24-D24 | G24: =SUMIFS(Budget_vs_Actual!$V:$V,Budget_vs_Actual!$G:$G,"Actual + Forecast",Budget_vs_Actual!$A:$A,"NA",Budget_vs_Actual!$X:$X,"Governance",Budget_vs_Actual!$Y:$Y,"GDS") | H24: =G24-C24 | I24: =SUMIFS(Budget_vs_Actual!$V:$V,Budget_vs_Actual!$G:$G,"Variance vs Prior Month",Budget_vs_Actual!$A:$A,"NA",Budget_vs_Actual!$X:$X,"Governance",Budget_vs_Actual!$Y:$Y,"GDS")
A25: NA | B25: Transferred (other functions) | C25: =SUMIFS(Budget_vs_Actual!$V:$V,Budget_vs_Actual!$G:$G,"Budget",Budget_vs_Actual!$A:$A,"NA",Budget_vs_Actual!$Y:$Y,"<>GDS") | D25: =SUMIFS(Budget_vs_Actual!$T:$T,Budget_vs_Actual!$G:$G,"Budget",Budget_vs_Actual!$A:$A,"NA",Budget_vs_Actual!$Y:$Y,"<>GDS") | E25: =SUMIFS(Budget_vs_Actual!$T:$T,Budget_vs_Actual!$G:$G,"Actual",Budget_vs_Actual!$A:$A,"NA",Budget_vs_Actual!$Y:$Y,"<>GDS") | F25: =E25-D25 | G25: =SUMIFS(Budget_vs_Actual!$V:$V,Budget_vs_Actual!$G:$G,"Actual + Forecast",Budget_vs_Actual!$A:$A,"NA",Budget_vs_Actual!$Y:$Y,"<>GDS") | H25: =G25-C25 | I25: =SUMIFS(Budget_vs_Actual!$V:$V,Budget_vs_Actual!$G:$G,"Variance vs Prior Month",Budget_vs_Actual!$A:$A,"NA",Budget_vs_Actual!$Y:$Y,"<>GDS")
A26: NA | B26: Subtotal | C26: =SUM(C20:C25) | D26: =SUM(D20:D25) | E26: =SUM(E20:E25) | F26: =SUM(F20:F25) | G26: =SUM(G20:G25) | H26: =SUM(H20:H25) | I26: =SUM(I20:I25)
A27: EMEA | B27: Applications | C27: =SUMIFS(Budget_vs_Actual!$V:$V,Budget_vs_Actual!$G:$G,"Budget",Budget_vs_Actual!$A:$A,"EMEA",Budget_vs_Actual!$X:$X,"Applications",Budget_vs_Actual!$Y:$Y,"GDS") | D27: =SUMIFS(Budget_vs_Actual!$T:$T,Budget_vs_Actual!$G:$G,"Budget",Budget_vs_Actual!$A:$A,"EMEA",Budget_vs_Actual!$X:$X,"Applications",Budget_vs_Actual!$Y:$Y,"GDS") | E27: =SUMIFS(Budget_vs_Actual!$T:$T,Budget_vs_Actual!$G:$G,"Actual",Budget_vs_Actual!$A:$A,"EMEA",Budget_vs_Actual!$X:$X,"Applications",Budget_vs_Actual!$Y:$Y,"GDS") | F27: =E27-D27 | G27: =SUMIFS(Budget_vs_Actual!$V:$V,Budget_vs_Actual!$G:$G,"Actual + Forecast",Budget_vs_Actual!$A:$A,"EMEA",Budget_vs_Actual!$X:$X,"Applications",Budget_vs_Actual!$Y:$Y,"GDS") | H27: =G27-C27 | I27: =SUMIFS(Budget_vs_Actual!$V:$V,Budget_vs_Actual!$G:$G,"Variance vs Prior Month",Budget_vs_Actual!$A:$A,"EMEA",Budget_vs_Actual!$X:$X,"Applications",Budget_vs_Actual!$Y:$Y,"GDS")
A28: EMEA | B28: Infrastructure | C28: =SUMIFS(Budget_vs_Actual!$V:$V,Budget_vs_Actual!$G:$G,"Budget",Budget_vs_Actual!$A:$A,"EMEA",Budget_vs_Actual!$X:$X,"Infrastructure",Budget_vs_Actual!$Y:$Y,"GDS") | D28: =SUMIFS(Budget_vs_Actual!$T:$T,Budget_vs_Actual!$G:$G,"Budget",Budget_vs_Actual!$A:$A,"EMEA",Budget_vs_Actual!$X:$X,"Infrastructure",Budget_vs_Actual!$Y:$Y,"GDS") | E28: =SUMIFS(Budget_vs_Actual!$T:$T,Budget_vs_Actual!$G:$G,"Actual",Budget_vs_Actual!$A:$A,"EMEA",Budget_vs_Actual!$X:$X,"Infrastructure",Budget_vs_Actual!$Y:$Y,"GDS") | F28: =E28-D28 | G28: =SUMIFS(Budget_vs_Actual!$V:$V,Budget_vs_Actual!$G:$G,"Actual + Forecast",Budget_vs_Actual!$A:$A,"EMEA",Budget_vs_Actual!$X:$X,"Infrastructure",Budget_vs_Actual!$Y:$Y,"GDS") | H28: =G28-C28 | I28: =SUMIFS(Budget_vs_Actual!$V:$V,Budget_vs_Actual!$G:$G,"Variance vs Prior Month",Budget_vs_Actual!$A:$A,"EMEA",Budget_vs_Actual!$X:$X,"Infrastructure",Budget_vs_Actual!$Y:$Y,"GDS")
A29: EMEA | B29: Data | C29: =SUMIFS(Budget_vs_Actual!$V:$V,Budget_vs_Actual!$G:$G,"Budget",Budget_vs_Actual!$A:$A,"EMEA",Budget_vs_Actual!$X:$X,"Data",Budget_vs_Actual!$Y:$Y,"GDS") | D29: =SUMIFS(Budget_vs_Actual!$T:$T,Budget_vs_Actual!$G:$G,"Budget",Budget_vs_Actual!$A:$A,"EMEA",Budget_vs_Actual!$X:$X,"Data",Budget_vs_Actual!$Y:$Y,"GDS") | E29: =SUMIFS(Budget_vs_Actual!$T:$T,Budget_vs_Actual!$G:$G,"Actual",Budget_vs_Actual!$A:$A,"EMEA",Budget_vs_Actual!$X:$X,"Data",Budget_vs_Actual!$Y:$Y,"GDS") | F29: =E29-D29 | G29: =SUMIFS(Budget_vs_Actual!$V:$V,Budget_vs_Actual!$G:$G,"Actual + Forecast",Budget_vs_Actual!$A:$A,"EMEA",Budget_vs_Actual!$X:$X,"Data",Budget_vs_Actual!$Y:$Y,"GDS") | H29: =G29-C29 | I29: =SUMIFS(Budget_vs_Actual!$V:$V,Budget_vs_Actual!$G:$G,"Variance vs Prior Month",Budget_vs_Actual!$A:$A,"EMEA",Budget_vs_Actual!$X:$X,"Data",Budget_vs_Actual!$Y:$Y,"GDS")
A30: EMEA | B30: Security | C30: =SUMIFS(Budget_vs_Actual!$V:$V,Budget_vs_Actual!$G:$G,"Budget",Budget_vs_Actual!$A:$A,"EMEA",Budget_vs_Actual!$X:$X,"Security",Budget_vs_Actual!$Y:$Y,"GDS") | D30: =SUMIFS(Budget_vs_Actual!$T:$T,Budget_vs_Actual!$G:$G,"Budget",Budget_vs_Actual!$A:$A,"EMEA",Budget_vs_Actual!$X:$X,"Security",Budget_vs_Actual!$Y:$Y,"GDS") | E30: =SUMIFS(Budget_vs_Actual!$T:$T,Budget_vs_Actual!$G:$G,"Actual",Budget_vs_Actual!$A:$A,"EMEA",Budget_vs_Actual!$X:$X,"Security",Budget_vs_Actual!$Y:$Y,"GDS") | F30: =E30-D30 | G30: =SUMIFS(Budget_vs_Actual!$V:$V,Budget_vs_Actual!$G:$G,"Actual + Forecast",Budget_vs_Actual!$A:$A,"EMEA",Budget_vs_Actual!$X:$X,"Security",Budget_vs_Actual!$Y:$Y,"GDS") | H30: =G30-C30 | I30: =SUMIFS(Budget_vs_Actual!$V:$V,Budget_vs_Actual!$G:$G,"Variance vs Prior Month",Budget_vs_Actual!$A:$A,"EMEA",Budget_vs_Actual!$X:$X,"Security",Budget_vs_Actual!$Y:$Y,"GDS")
A31: EMEA | B31: Governance | C31: =SUMIFS(Budget_vs_Actual!$V:$V,Budget_vs_Actual!$G:$G,"Budget",Budget_vs_Actual!$A:$A,"EMEA",Budget_vs_Actual!$X:$X,"Governance",Budget_vs_Actual!$Y:$Y,"GDS") | D31: =SUMIFS(Budget_vs_Actual!$T:$T,Budget_vs_Actual!$G:$G,"Budget",Budget_vs_Actual!$A:$A,"EMEA",Budget_vs_Actual!$X:$X,"Governance",Budget_vs_Actual!$Y:$Y,"GDS") | E31: =SUMIFS(Budget_vs_Actual!$T:$T,Budget_vs_Actual!$G:$G,"Actual",Budget_vs_Actual!$A:$A,"EMEA",Budget_vs_Actual!$X:$X,"Governance",Budget_vs_Actual!$Y:$Y,"GDS") | F31: =E31-D31 | G31: =SUMIFS(Budget_vs_Actual!$V:$V,Budget_vs_Actual!$G:$G,"Actual + Forecast",Budget_vs_Actual!$A:$A,"EMEA",Budget_vs_Actual!$X:$X,"Governance",Budget_vs_Actual!$Y:$Y,"GDS") | H31: =G31-C31 | I31: =SUMIFS(Budget_vs_Actual!$V:$V,Budget_vs_Actual!$G:$G,"Variance vs Prior Month",Budget_vs_Actual!$A:$A,"EMEA",Budget_vs_Actual!$X:$X,"Governance",Budget_vs_Actual!$Y:$Y,"GDS")
A32: EMEA | B32: Transferred (other functions) | C32: =SUMIFS(Budget_vs_Actual!$V:$V,Budget_vs_Actual!$G:$G,"Budget",Budget_vs_Actual!$A:$A,"EMEA",Budget_vs_Actual!$Y:$Y,"<>GDS") | D32: =SUMIFS(Budget_vs_Actual!$T:$T,Budget_vs_Actual!$G:$G,"Budget",Budget_vs_Actual!$A:$A,"EMEA",Budget_vs_Actual!$Y:$Y,"<>GDS") | E32: =SUMIFS(Budget_vs_Actual!$T:$T,Budget_vs_Actual!$G:$G,"Actual",Budget_vs_Actual!$A:$A,"EMEA",Budget_vs_Actual!$Y:$Y,"<>GDS") | F32: =E32-D32 | G32: =SUMIFS(Budget_vs_Actual!$V:$V,Budget_vs_Actual!$G:$G,"Actual + Forecast",Budget_vs_Actual!$A:$A,"EMEA",Budget_vs_Actual!$Y:$Y,"<>GDS") | H32: =G32-C32 | I32: =SUMIFS(Budget_vs_Actual!$V:$V,Budget_vs_Actual!$G:$G,"Variance vs Prior Month",Budget_vs_Actual!$A:$A,"EMEA",Budget_vs_Actual!$Y:$Y,"<>GDS")
A33: EMEA | B33: Subtotal | C33: =SUM(C27:C32) | D33: =SUM(D27:D32) | E33: =SUM(E27:E32) | F33: =SUM(F27:F32) | G33: =SUM(G27:G32) | H33: =SUM(H27:H32) | I33: =SUM(I27:I32)
A34: Total | C34: =SUMIFS(C13:C33,$B13:$B33,"Subtotal") | D34: =SUMIFS(D13:D33,$B13:$B33,"Subtotal") | E34: =SUMIFS(E13:E33,$B13:$B33,"Subtotal") | F34: =SUMIFS(F13:F33,$B13:$B33,"Subtotal") | G34: =SUMIFS(G13:G33,$B13:$B33,"Subtotal") | H34: =SUMIFS(H13:H33,$B13:$B33,"Subtotal") | I34: =SUMIFS(I13:I33,$B13:$B33,"Subtotal")
A37: Monthly budget vs actual / 月次の予算と実績
A38: Month | B38: Budget | C38: Actual | D38: Forecast | E38: Variance %
A39: Jan | B39: =SUMIFS(Budget_vs_Actual!$H:$H,Budget_vs_Actual!$G:$G,"Budget") | C39: =IF(1<=Budget_vs_Actual!$C$4,SUMIFS(Budget_vs_Actual!$H:$H,Budget_vs_Actual!$G:$G,"Actual"),0) | D39: =IF(1>Budget_vs_Actual!$C$4,SUMIFS(Budget_vs_Actual!$H:$H,Budget_vs_Actual!$G:$G,"Actual + Forecast"),0) | E39: =IFERROR((C39+D39-B39)/B39,0)
A40: Feb | B40: =SUMIFS(Budget_vs_Actual!$I:$I,Budget_vs_Actual!$G:$G,"Budget") | C40: =IF(2<=Budget_vs_Actual!$C$4,SUMIFS(Budget_vs_Actual!$I:$I,Budget_vs_Actual!$G:$G,"Actual"),0) | D40: =IF(2>Budget_vs_Actual!$C$4,SUMIFS(Budget_vs_Actual!$I:$I,Budget_vs_Actual!$G:$G,"Actual + Forecast"),0) | E40: =IFERROR((C40+D40-B40)/B40,0)
A41: Mar | B41: =SUMIFS(Budget_vs_Actual!$J:$J,Budget_vs_Actual!$G:$G,"Budget") | C41: =IF(3<=Budget_vs_Actual!$C$4,SUMIFS(Budget_vs_Actual!$J:$J,Budget_vs_Actual!$G:$G,"Actual"),0) | D41: =IF(3>Budget_vs_Actual!$C$4,SUMIFS(Budget_vs_Actual!$J:$J,Budget_vs_Actual!$G:$G,"Actual + Forecast"),0) | E41: =IFERROR((C41+D41-B41)/B41,0)
A42: Apr | B42: =SUMIFS(Budget_vs_Actual!$K:$K,Budget_vs_Actual!$G:$G,"Budget") | C42: =IF(4<=Budget_vs_Actual!$C$4,SUMIFS(Budget_vs_Actual!$K:$K,Budget_vs_Actual!$G:$G,"Actual"),0) | D42: =IF(4>Budget_vs_Actual!$C$4,SUMIFS(Budget_vs_Actual!$K:$K,Budget_vs_Actual!$G:$G,"Actual + Forecast"),0) | E42: =IFERROR((C42+D42-B42)/B42,0)
A43: May | B43: =SUMIFS(Budget_vs_Actual!$L:$L,Budget_vs_Actual!$G:$G,"Budget") | C43: =IF(5<=Budget_vs_Actual!$C$4,SUMIFS(Budget_vs_Actual!$L:$L,Budget_vs_Actual!$G:$G,"Actual"),0) | D43: =IF(5>Budget_vs_Actual!$C$4,SUMIFS(Budget_vs_Actual!$L:$L,Budget_vs_Actual!$G:$G,"Actual + Forecast"),0) | E43: =IFERROR((C43+D43-B43)/B43,0)
A44: Jun | B44: =SUMIFS(Budget_vs_Actual!$M:$M,Budget_vs_Actual!$G:$G,"Budget") | C44: =IF(6<=Budget_vs_Actual!$C$4,SUMIFS(Budget_vs_Actual!$M:$M,Budget_vs_Actual!$G:$G,"Actual"),0) | D44: =IF(6>Budget_vs_Actual!$C$4,SUMIFS(Budget_vs_Actual!$M:$M,Budget_vs_Actual!$G:$G,"Actual + Forecast"),0) | E44: =IFERROR((C44+D44-B44)/B44,0)
A45: Jul | B45: =SUMIFS(Budget_vs_Actual!$N:$N,Budget_vs_Actual!$G:$G,"Budget") | C45: =IF(7<=Budget_vs_Actual!$C$4,SUMIFS(Budget_vs_Actual!$N:$N,Budget_vs_Actual!$G:$G,"Actual"),0) | D45: =IF(7>Budget_vs_Actual!$C$4,SUMIFS(Budget_vs_Actual!$N:$N,Budget_vs_Actual!$G:$G,"Actual + Forecast"),0) | E45: =IFERROR((C45+D45-B45)/B45,0)
...

Sheet Budget_vs_Actual
A1: Budget vs Actual / 予実対比
A3: fiscal_year | C3: 2027 | E3: FX factor to display currency (budget rate) | J3: Checks (should be 0) / チェック（0であること）
A4: close_month | C4: 1 | E4: JPY | F4: USD | G4: EUR | H4: GBP | J4: Budget not in any block / ブロック外の予算 | P4: =ROUND((SUMPRODUCT((Opex_Budget!$A$2:$A$2001=$C$3)*(Opex_Budget!$N$2:$N$2001="JPY")*Opex_Budget!$O$2:$Z$2001)*$E$5+SUMPRODUCT((Opex_Budget!$A$2:$A$2001=$C$3)*(Opex_Budget!$N$2:$N$2001="USD")*Opex_Budget!$O$2:$Z$2001)*$F$5+SUMPRODUCT((Opex_Budget!$A$2:$A$2001=$C$3)*(Opex_Budget!$N$2:$N$2001="EUR")*Opex_Budget!$O$2:$Z$2001)*$G$5+SUMPRODUCT((Opex_Budget!$A$2:$A$2001=$C$3)*(Opex_Budget!$N$2:$N$2001="GBP")*Opex_Budget!$O$2:$Z$2001)*$H$5)-SUMIFS($V$10:$V$1210,$G$10:$G$1210,"Budget"),0)
A5: display_currency | C5: JPY | E5: =IF(E$4=$C$5,1,IFERROR(SUMIFS(FX_Rates!$D:$D,FX_Rates!$A:$A,$C$3,FX_Rates!$B:$B,"BUDGET",FX_Rates!$C:$C,E$4)/SUMIFS(FX_Rates!$D:$D,FX_Rates!$A:$A,$C$3,FX_Rates!$B:$B,"BUDGET",FX_Rates!$C:$C,$C$5),0)) | F5: =IF(F$4=$C$5,1,IFERROR(SUMIFS(FX_Rates!$D:$D,FX_Rates!$A:$A,$C$3,FX_Rates!$B:$B,"BUDGET",FX_Rates!$C:$C,F$4)/SUMIFS(FX_Rates!$D:$D,FX_Rates!$A:$A,$C$3,FX_Rates!$B:$B,"BUDGET",FX_Rates!$C:$C,$C$5),0)) | G5: =IF(G$4=$C$5,1,IFERROR(SUMIFS(FX_Rates!$D:$D,FX_Rates!$A:$A,$C$3,FX_Rates!$B:$B,"BUDGET",FX_Rates!$C:$C,G$4)/SUMIFS(FX_Rates!$D:$D,FX_Rates!$A:$A,$C$3,FX_Rates!$B:$B,"BUDGET",FX_Rates!$C:$C,$C$5),0)) | H5: =IF(H$4=$C$5,1,IFERROR(SUMIFS(FX_Rates!$D:$D,FX_Rates!$A:$A,$C$3,FX_Rates!$B:$B,"BUDGET",FX_Rates!$C:$C,H$4)/SUMIFS(FX_Rates!$D:$D,FX_Rates!$A:$A,$C$3,FX_Rates!$B:$B,"BUDGET",FX_Rates!$C:$C,$C$5),0)) | J5: Actual not in any block / ブロック外の実績 | P5: =ROUND((SUMIFS(Actuals!$G:$G,Actuals!$B:$B,$C$3,Actuals!$C:$C,"<="&$C$4,Actuals!$F:$F,"JPY")*$E$5+SUMIFS(Actuals!$G:$G,Actuals!$B:$B,$C$3,Actuals!$C:$C,"<="&$C$4,Actuals!$F:$F,"USD")*$F$5+SUMIFS(Actuals!$G:$G,Actuals!$B:$B,$C$3,Actuals!$C:$C,"<="&$C$4,Actuals!$F:$F,"EUR")*$G$5+SUMIFS(Actuals!$G:$G,Actuals!$B:$B,$C$3,Actuals!$C:$C,"<="&$C$4,Actuals!$F:$F,"GBP")*$H$5)-SUMIFS($T$10:$T$1210,$G$10:$G$1210,"Actual"),0)
E7: Prior forecast as of close month / 前月見込みの基準月: | G7: =IFERROR(MAX(Prior_Forecast!$R:$R),"") | H7: 1 | I7: 2 | J7: 3 | K7: 4 | L7: 5 | M7: 6 | N7: 7 | O7: 8 | P7: 9 | Q7: 10 | R7: 11 | S7: 12
A8: region | B8: cost_center_code | C8: cost_center_name | D8: account_key | E8: account_name | F8: owner | G8: line | H8: Jan | I8: Feb | J8: Mar | K8: Apr | L8: May | M8: Jun | N8: Jul | O8: Aug | P8: Sep | Q8: Oct | R8: Nov | S8: Dec | T8: YTD | U8: MTG | V8: FY | X8: sub_function | Y8: function | Z8: abs_fy_var
A10: =IF($D$10="","",LEFT($D$10,FIND("|",$D$10&"|")-1)) | C10: =IF($B$10="","",IFERROR(INDEX(Cost_Centers!$B:$B,MATCH($B$10,Cost_Centers!$A:$A,0)),"(not in master)")) | E10: =IF($D$10="","",IFERROR(INDEX(Accounts!$D:$D,MATCH($D$10,Accounts!$A:$A,0)),"(not in master)")) | G10: Budget | H10: =IF($B$10="","",SUMIFS(Opex_Budget!$O:$O,Opex_Budget!$A:$A,$C$3,Opex_Budget!$E:$E,$B$10,Opex_Budget!$F:$F,$D$10,Opex_Budget!$N:$N,"JPY")*$E$5+SUMIFS(Opex_Budget!$O:$O,Opex_Budget!$A:$A,$C$3,Opex_Budget!$E:$E,$B$10,Opex_Budget!$F:$F,$D$10,Opex_Budget!$N:$N,"USD")*$F$5+SUMIFS(Opex_Budget!$O:$O,Opex_Budget!$A:$A,$C$3,Opex_Budget!$E:$E,$B$10,Opex_Budget!$F:$F,$D$10,Opex_Budget!$N:$N,"EUR")*$G$5+SUMIFS(Opex_Budget!$O:$O,Opex_Budget!$A:$A,$C$3,Opex_Budget!$E:$E,$B$10,Opex_Budget!$F:$F,$D$10,Opex_Budget!$N:$N,"GBP")*$H$5) | I10: =IF($B$10="","",SUMIFS(Opex_Budget!$P:$P,Opex_Budget!$A:$A,$C$3,Opex_Budget!$E:$E,$B$10,Opex_Budget!$F:$F,$D$10,Opex_Budget!$N:$N,"JPY")*$E$5+SUMIFS(Opex_Budget!$P:$P,Opex_Budget!$A:$A,$C$3,Opex_Budget!$E:$E,$B$10,Opex_Budget!$F:$F,$D$10,Opex_Budget!$N:$N,"USD")*$F$5+SUMIFS(Opex_Budget!$P:$P,Opex_Budget!$A:$A,$C$3,Opex_Budget!$E:$E,$B$10,Opex_Budget!$F:$F,$D$10,Opex_Budget!$N:$N,"EUR")*$G$5+SUMIFS(Opex_Budget!$P:$P,Opex_Budget!$A:$A,$C$3,Opex_Budget!$E:$E,$B$10,Opex_Budget!$F:$F,$D$10,Opex_Budget!$N:$N,"GBP")*$H$5) | J10: =IF($B$10="","",SUMIFS(Opex_Budget!$Q:$Q,Opex_Budget!$A:$A,$C$3,Opex_Budget!$E:$E,$B$10,Opex_Budget!$F:$F,$D$10,Opex_Budget!$N:$N,"JPY")*$E$5+SUMIFS(Opex_Budget!$Q:$Q,Opex_Budget!$A:$A,$C$3,Opex_Budget!$E:$E,$B$10,Opex_Budget!$F:$F,$D$10,Opex_Budget!$N:$N,"USD")*$F$5+SUMIFS(Opex_Budget!$Q:$Q,Opex_Budget!$A:$A,$C$3,Opex_Budget!$E:$E,$B$10,Opex_Budget!$F:$F,$D$10,Opex_Budget!$N:$N,"EUR")*$G$5+SUMIFS(Opex_Budget!$Q:$Q,Opex_Budget!$A:$A,$C$3,Opex_Budget!$E:$E,$B$10,Opex_Budget!$F:$F,$D$10,Opex_Budget!$N:$N,"GBP")*$H$5) | K10: =IF($B$10="","",SUMIFS(Opex_Budget!$R:$R,Opex_Budget!$A:$A,$C$3,Opex_Budget!$E:$E,$B$10,Opex_Budget!$F:$F,$D$10,Opex_Budget!$N:$N,"JPY")*$E$5+SUMIFS(Opex_Budget!$R:$R,Opex_Budget!$A:$A,$C$3,Opex_Budget!$E:$E,$B$10,Opex_Budget!$F:$F,$D$10,Opex_Budget!$N:$N,"USD")*$F$5+SUMIFS(Opex_Budget!$R:$R,Opex_Budget!$A:$A,$C$3,Opex_Budget!$E:$E,$B$10,Opex_Budget!$F:$F,$D$10,Opex_Budget!$N:$N,"EUR")*$G$5+SUMIFS(Opex_Budget!$R:$R,Opex_Budget!$A:$A,$C$3,Opex_Budget!$E:$E,$B$10,Opex_Budget!$F:$F,$D$10,Opex_Budget!$N:$N,"GBP")*$H$5) | L10: =IF($B$10="","",SUMIFS(Opex_Budget!$S:$S,Opex_Budget!$A:$A,$C$3,Opex_Budget!$E:$E,$B$10,Opex_Budget!$F:$F,$D$10,Opex_Budget!$N:$N,"JPY")*$E$5+SUMIFS(Opex_Budget!$S:$S,Opex_Budget!$A:$A,$C$3,Opex_Budget!$E:$E,$B$10,Opex_Budget!$F:$F,$D$10,Opex_Budget!$N:$N,"USD")*$F$5+SUMIFS(Opex_Budget!$S:$S,Opex_Budget!$A:$A,$C$3,Opex_Budget!$E:$E,$B$10,Opex_Budget!$F:$F,$D$10,Opex_Budget!$N:$N,"EUR")*$G$5+SUMIFS(Opex_Budget!$S:$S,Opex_Budget!$A:$A,$C$3,Opex_Budget!$E:$E,$B$10,Opex_Budget!$F:$F,$D$10,Opex_Budget!$N:$N,"GBP")*$H$5) | M10: =IF($B$10="","",SUMIFS(Opex_Budget!$T:$T,Opex_Budget!$A:$A,$C$3,Opex_Budget!$E:$E,$B$10,Opex_Budget!$F:$F,$D$10,Opex_Budget!$N:$N,"JPY")*$E$5+SUMIFS(Opex_Budget!$T:$T,Opex_Budget!$A:$A,$C$3,Opex_Budget!$E:$E,$B$10,Opex_Budget!$F:$F,$D$10,Opex_Budget!$N:$N,"USD")*$F$5+SUMIFS(Opex_Budget!$T:$T,Opex_Budget!$A:$A,$C$3,Opex_Budget!$E:$E,$B$10,Opex_Budget!$F:$F,$D$10,Opex_Budget!$N:$N,"EUR")*$G$5+SUMIFS(Opex_Budget!$T:$T,Opex_Budget!$A:$A,$C$3,Opex_Budget!$E:$E,$B$10,Opex_Budget!$F:$F,$D$10,Opex_Budget!$N:$N,"GBP")*$H$5) | N10: =IF($B$10="","",SUMIFS(Opex_Budget!$U:$U,Opex_Budget!$A:$A,$C$3,Opex_Budget!$E:$E,$B$10,Opex_Budget!$F:$F,$D$10,Opex_Budget!$N:$N,"JPY")*$E$5+SUMIFS(Opex_Budget!$U:$U,Opex_Budget!$A:$A,$C$3,Opex_Budget!$E:$E,$B$10,Opex_Budget!$F:$F,$D$10,Opex_Budget!$N:$N,"USD")*$F$5+SUMIFS(Opex_Budget!$U:$U,Opex_Budget!$A:$A,$C$3,Opex_Budget!$E:$E,$B$10,Opex_Budget!$F:$F,$D$10,Opex_Budget!$N:$N,"EUR")*$G$5+SUMIFS(Opex_Budget!$U:$U,Opex_Budget!$A:$A,$C$3,Opex_Budget!$E:$E,$B$10,Opex_Budget!$F:$F,$D$10,Opex_Budget!$N:$N,"GBP")*$H$5) | O10: =IF($B$10="","",SUMIFS(Opex_Budget!$V:$V,Opex_Budget!$A:$A,$C$3,Opex_Budget!$E:$E,$B$10,Opex_Budget!$F:$F,$D$10,Opex_Budget!$N:$N,"JPY")*$E$5+SUMIFS(Opex_Budget!$V:$V,Opex_Budget!$A:$A,$C$3,Opex_Budget!$E:$E,$B$10,Opex_Budget!$F:$F,$D$10,Opex_Budget!$N:$N,"USD")*$F$5+SUMIFS(Opex_Budget!$V:$V,Opex_Budget!$A:$A,$C$3,Opex_Budget!$E:$E,$B$10,Opex_Budget!$F:$F,$D$10,Opex_Budget!$N:$N,"EUR")*$G$5+SUMIFS(Opex_Budget!$V:$V,Opex_Budget!$A:$A,$C$3,Opex_Budget!$E:$E,$B$10,Opex_Budget!$F:$F,$D$10,Opex_Budget!$N:$N,"GBP")*$H$5) | P10: =IF($B$10="","",SUMIFS(Opex_Budget!$W:$W,Opex_Budget!$A:$A,$C$3,Opex_Budget!$E:$E,$B$10,Opex_Budget!$F:$F,$D$10,Opex_Budget!$N:$N,"JPY")*$E$5+SUMIFS(Opex_Budget!$W:$W,Opex_Budget!$A:$A,$C$3,Opex_Budget!$E:$E,$B$10,Opex_Budget!$F:$F,$D$10,Opex_Budget!$N:$N,"USD")*$F$5+SUMIFS(Opex_Budget!$W:$W,Opex_Budget!$A:$A,$C$3,Opex_Budget!$E:$E,$B$10,Opex_Budget!$F:$F,$D$10,Opex_Budget!$N:$N,"EUR")*$G$5+SUMIFS(Opex_Budget!$W:$W,Opex_Budget!$A:$A,$C$3,Opex_Budget!$E:$E,$B$10,Opex_Budget!$F:$F,$D$10,Opex_Budget!$N:$N,"GBP")*$H$5) | Q10: =IF($B$10="","",SUMIFS(Opex_Budget!$X:$X,Opex_Budget!$A:$A,$C$3,Opex_Budget!$E:$E,$B$10,Opex_Budget!$F:$F,$D$10,Opex_Budget!$N:$N,"JPY")*$E$5+SUMIFS(Opex_Budget!$X:$X,Opex_Budget!$A:$A,$C$3,Opex_Budget!$E:$E,$B$10,Opex_Budget!$F:$F,$D$10,Opex_Budget!$N:$N,"USD")*$F$5+SUMIFS(Opex_Budget!$X:$X,Opex_Budget!$A:$A,$C$3,Opex_Budget!$E:$E,$B$10,Opex_Budget!$F:$F,$D$10,Opex_Budget!$N:$N,"EUR")*$G$5+SUMIFS(Opex_Budget!$X:$X,Opex_Budget!$A:$A,$C$3,Opex_Budget!$E:$E,$B$10,Opex_Budget!$F:$F,$D$10,Opex_Budget!$N:$N,"GBP")*$H$5) | R10: =IF($B$10="","",SUMIFS(Opex_Budget!$Y:$Y,Opex_Budget!$A:$A,$C$3,Opex_Budget!$E:$E,$B$10,Opex_Budget!$F:$F,$D$10,Opex_Budget!$N:$N,"JPY")*$E$5+SUMIFS(Opex_Budget!$Y:$Y,Opex_Budget!$A:$A,$C$3,Opex_Budget!$E:$E,$B$10,Opex_Budget!$F:$F,$D$10,Opex_Budget!$N:$N,"USD")*$F$5+SUMIFS(Opex_Budget!$Y:$Y,Opex_Budget!$A:$A,$C$3,Opex_Budget!$E:$E,$B$10,Opex_Budget!$F:$F,$D$10,Opex_Budget!$N:$N,"EUR")*$G$5+SUMIFS(Opex_Budget!$Y:$Y,Opex_Budget!$A:$A,$C$3,Opex_Budget!$E:$E,$B$10,Opex_Budget!$F:$F,$D$10,Opex_Budget!$N:$N,"GBP")*$H$5) | S10: =IF($B$10="","",SUMIFS(Opex_Budget!$Z:$Z,Opex_Budget!$A:$A,$C$3,Opex_Budget!$E:$E,$B$10,Opex_Budget!$F:$F,$D$10,Opex_Budget!$N:$N,"JPY")*$E$5+SUMIFS(Opex_Budget!$Z:$Z,Opex_Budget!$A:$A,$C$3,Opex_Budget!$E:$E,$B$10,Opex_Budget!$F:$F,$D$10,Opex_Budget!$N:$N,"USD")*$F$5+SUMIFS(Opex_Budget!$Z:$Z,Opex_Budget!$A:$A,$C$3,Opex_Budget!$E:$E,$B$10,Opex_Budget!$F:$F,$D$10,Opex_Budget!$N:$N,"EUR")*$G$5+SUMIFS(Opex_Budget!$Z:$Z,Opex_Budget!$A:$A,$C$3,Opex_Budget!$E:$E,$B$10,Opex_Budget!$F:$F,$D$10,Opex_Budget!$N:$N,"GBP")*$H$5) | T10: =IF($B$10="","",SUMIF($H$7:$S$7,"<="&$C$4,$H10:$S10)) | U10: =IF($B$10="","",SUMIF($H$7:$S$7,">"&$C$4,$H10:$S10)) | V10: =IF($B$10="","",SUM($H10:$S10)) | X10: =IF($B10="","",IFERROR(INDEX(Cost_Centers!$E:$E,MATCH($B10,Cost_Centers!$A:$A,0)),"(unknown)")) | Y10: =IF($B10="","",IFERROR(INDEX(Cost_Centers!$D:$D,MATCH($B10,Cost_Centers!$A:$A,0)),"(unknown)")) | Z10: =IF(OR($B10="",$G10<>"Variance vs Budget"),"",ABS(N($V10))+ROW()/1000000000)
A11: =IF(A$10="","",A$10) | B11: =IF(B$10="","",B$10) | C11: =IF(C$10="","",C$10) | D11: =IF(D$10="","",D$10) | E11: =IF(E$10="","",E$10) | F11: =IF(F$10="","",F$10) | G11: Actual | H11: =IF(OR($B$10="",1>$C$4),"",SUMIFS(Actuals!$G:$G,Actuals!$B:$B,$C$3,Actuals!$C:$C,1,Actuals!$D:$D,$B$10,Actuals!$A:$A,LEFT($D$10,FIND("|",$D$10&"|")-1),Actuals!$E:$E,MID($D$10,FIND("|",$D$10&"|")+1,50),Actuals!$F:$F,"JPY")*$E$5+SUMIFS(Actuals!$G:$G,Actuals!$B:$B,$C$3,Actuals!$C:$C,1,Actuals!$D:$D,$B$10,Actuals!$A:$A,LEFT($D$10,FIND("|",$D$10&"|")-1),Actuals!$E:$E,MID($D$10,FIND("|",$D$10&"|")+1,50),Actuals!$F:$F,"USD")*$F$5+SUMIFS(Actuals!$G:$G,Actuals!$B:$B,$C$3,Actuals!$C:$C,1,Actuals!$D:$D,$B$10,Actuals!$A:$A,LEFT($D$10,FIND("|",$D$10&"|")-1),Actuals!$E:$E,MID($D$10,FIND("|",$D$10&"|")+1,50),Actuals!$F:$F,"EUR")*$G$5+SUMIFS(Actuals!$G:$G,Actuals!$B:$B,$C$3,Actuals!$C:$C,1,Actuals!$D:$D,$B$10,Actuals!$A:$A,LEFT($D$10,FIND("|",$D$10&"|")-1),Actuals!$E:$E,MID($D$10,FIND("|",$D$10&"|")+1,50),Actuals!$F:$F,"GBP")*$H$5) | I11: =IF(OR($B$10="",2>$C$4),"",SUMIFS(Actuals!$G:$G,Actuals!$B:$B,$C$3,Actuals!$C:$C,2,Actuals!$D:$D,$B$10,Actuals!$A:$A,LEFT($D$10,FIND("|",$D$10&"|")-1),Actuals!$E:$E,MID($D$10,FIND("|",$D$10&"|")+1,50),Actuals!$F:$F,"JPY")*$E$5+SUMIFS(Actuals!$G:$G,Actuals!$B:$B,$C$3,Actuals!$C:$C,2,Actuals!$D:$D,$B$10,Actuals!$A:$A,LEFT($D$10,FIND("|",$D$10&"|")-1),Actuals!$E:$E,MID($D$10,FIND("|",$D$10&"|")+1,50),Actuals!$F:$F,"USD")*$F$5+SUMIFS(Actuals!$G:$G,Actuals!$B:$B,$C$3,Actuals!$C:$C,2,Actuals!$D:$D,$B$10,Actuals!$A:$A,LEFT($D$10,FIND("|",$D$10&"|")-1),Actuals!$E:$E,MID($D$10,FIND("|",$D$10&"|")+1,50),Actuals!$F:$F,"EUR")*$G$5+SUMIFS(Actuals!$G:$G,Actuals!$B:$B,$C$3,Actuals!$C:$C,2,Actuals!$D:$D,$B$10,Actuals!$A:$A,LEFT($D$10,FIND("|",$D$10&"|")-1),Actuals!$E:$E,MID($D$10,FIND("|",$D$10&"|")+1,50),Actuals!$F:$F,"GBP")*$H$5) | J11: =IF(OR($B$10="",3>$C$4),"",SUMIFS(Actuals!$G:$G,Actuals!$B:$B,$C$3,Actuals!$C:$C,3,Actuals!$D:$D,$B$10,Actuals!$A:$A,LEFT($D$10,FIND("|",$D$10&"|")-1),Actuals!$E:$E,MID($D$10,FIND("|",$D$10&"|")+1,50),Actuals!$F:$F,"JPY")*$E$5+SUMIFS(Actuals!$G:$G,Actuals!$B:$B,$C$3,Actuals!$C:$C,3,Actuals!$D:$D,$B$10,Actuals!$A:$A,LEFT($D$10,FIND("|",$D$10&"|")-1),Actuals!$E:$E,MID($D$10,FIND("|",$D$10&"|")+1,50),Actuals!$F:$F,"USD")*$F$5+SUMIFS(Actuals!$G:$G,Actuals!$B:$B,$C$3,Actuals!$C:$C,3,Actuals!$D:$D,$B$10,Actuals!$A:$A,LEFT($D$10,FIND("|",$D$10&"|")-1),Actuals!$E:$E,MID($D$10,FIND("|",$D$10&"|")+1,50),Actuals!$F:$F,"EUR")*$G$5+SUMIFS(Actuals!$G:$G,Actuals!$B:$B,$C$3,Actuals!$C:$C,3,Actuals!$D:$D,$B$10,Actuals!$A:$A,LEFT($D$10,FIND("|",$D$10&"|")-1),Actuals!$E:$E,MID($D$10,FIND("|",$D$10&"|")+1,50),Actuals!$F:$F,"GBP")*$H$5) | K11: =IF(OR($B$10="",4>$C$4),"",SUMIFS(Actuals!$G:$G,Actuals!$B:$B,$C$3,Actuals!$C:$C,4,Actuals!$D:$D,$B$10,Actuals!$A:$A,LEFT($D$10,FIND("|",$D$10&"|")-1),Actuals!$E:$E,MID($D$10,FIND("|",$D$10&"|")+1,50),Actuals!$F:$F,"JPY")*$E$5+SUMIFS(Actuals!$G:$G,Actuals!$B:$B,$C$3,Actuals!$C:$C,4,Actuals!$D:$D,$B$10,Actuals!$A:$A,LEFT($D$10,FIND("|",$D$10&"|")-1),Actuals!$E:$E,MID($D$10,FIND("|",$D$10&"|")+1,50),Actuals!$F:$F,"USD")*$F$5+SUMIFS(Actuals!$G:$G,Actuals!$B:$B,$C$3,Actuals!$C:$C,4,Actuals!$D:$D,$B$10,Actuals!$A:$A,LEFT($D$10,FIND("|",$D$10&"|")-1),Actuals!$E:$E,MID($D$10,FIND("|",$D$10&"|")+1,50),Actuals!$F:$F,"EUR")*$G$5+SUMIFS(Actuals!$G:$G,Actuals!$B:$B,$C$3,Actuals!$C:$C,4,Actuals!$D:$D,$B$10,Actuals!$A:$A,LEFT($D$10,FIND("|",$D$10&"|")-1),Actuals!$E:$E,MID($D$10,FIND("|",$D$10&"|")+1,50),Actuals!$F:$F,"GBP")*$H$5) | L11: =IF(OR($B$10="",5>$C$4),"",SUMIFS(Actuals!$G:$G,Actuals!$B:$B,$C$3,Actuals!$C:$C,5,Actuals!$D:$D,$B$10,Actuals!$A:$A,LEFT($D$10,FIND("|",$D$10&"|")-1),Actuals!$E:$E,MID($D$10,FIND("|",$D$10&"|")+1,50),Actuals!$F:$F,"JPY")*$E$5+SUMIFS(Actuals!$G:$G,Actuals!$B:$B,$C$3,Actuals!$C:$C,5,Actuals!$D:$D,$B$10,Actuals!$A:$A,LEFT($D$10,FIND("|",$D$10&"|")-1),Actuals!$E:$E,MID($D$10,FIND("|",$D$10&"|")+1,50),Actuals!$F:$F,"USD")*$F$5+SUMIFS(Actuals!$G:$G,Actuals!$B:$B,$C$3,Actuals!$C:$C,5,Actuals!$D:$D,$B$10,Actuals!$A:$A,LEFT($D$10,FIND("|",$D$10&"|")-1),Actuals!$E:$E,MID($D$10,FIND("|",$D$10&"|")+1,50),Actuals!$F:$F,"EUR")*$G$5+SUMIFS(Actuals!$G:$G,Actuals!$B:$B,$C$3,Actuals!$C:$C,5,Actuals!$D:$D,$B$10,Actuals!$A:$A,LEFT($D$10,FIND("|",$D$10&"|")-1),Actuals!$E:$E,MID($D$10,FIND("|",$D$10&"|")+1,50),Actuals!$F:$F,"GBP")*$H$5) | M11: =IF(OR($B$10="",6>$C$4),"",SUMIFS(Actuals!$G:$G,Actuals!$B:$B,$C$3,Actuals!$C:$C,6,Actuals!$D:$D,$B$10,Actuals!$A:$A,LEFT($D$10,FIND("|",$D$10&"|")-1),Actuals!$E:$E,MID($D$10,FIND("|",$D$10&"|")+1,50),Actuals!$F:$F,"JPY")*$E$5+SUMIFS(Actuals!$G:$G,Actuals!$B:$B,$C$3,Actuals!$C:$C,6,Actuals!$D:$D,$B$10,Actuals!$A:$A,LEFT($D$10,FIND("|",$D$10&"|")-1),Actuals!$E:$E,MID($D$10,FIND("|",$D$10&"|")+1,50),Actuals!$F:$F,"USD")*$F$5+SUMIFS(Actuals!$G:$G,Actuals!$B:$B,$C$3,Actuals!$C:$C,6,Actuals!$D:$D,$B$10,Actuals!$A:$A,LEFT($D$10,FIND("|",$D$10&"|")-1),Actuals!$E:$E,MID($D$10,FIND("|",$D$10&"|")+1,50),Actuals!$F:$F,"EUR")*$G$5+SUMIFS(Actuals!$G:$G,Actuals!$B:$B,$C$3,Actuals!$C:$C,6,Actuals!$D:$D,$B$10,Actuals!$A:$A,LEFT($D$10,FIND("|",$D$10&"|")-1),Actuals!$E:$E,MID($D$10,FIND("|",$D$10&"|")+1,50),Actuals!$F:$F,"GBP")*$H$5) | N11: =IF(OR($B$10="",7>$C$4),"",SUMIFS(Actuals!$G:$G,Actuals!$B:$B,$C$3,Actuals!$C:$C,7,Actuals!$D:$D,$B$10,Actuals!$A:$A,LEFT($D$10,FIND("|",$D$10&"|")-1),Actuals!$E:$E,MID($D$10,FIND("|",$D$10&"|")+1,50),Actuals!$F:$F,"JPY")*$E$5+SUMIFS(Actuals!$G:$G,Actuals!$B:$B,$C$3,Actuals!$C:$C,7,Actuals!$D:$D,$B$10,Actuals!$A:$A,LEFT($D$10,FIND("|",$D$10&"|")-1),Actuals!$E:$E,MID($D$10,FIND("|",$D$10&"|")+1,50),Actuals!$F:$F,"USD")*$F$5+SUMIFS(Actuals!$G:$G,Actuals!$B:$B,$C$3,Actuals!$C:$C,7,Actuals!$D:$D,$B$10,Actuals!$A:$A,LEFT($D$10,FIND("|",$D$10&"|")-1),Actuals!$E:$E,MID($D$10,FIND("|",$D$10&"|")+1,50),Actuals!$F:$F,"EUR")*$G$5+SUMIFS(Actuals!$G:$G,Actuals!$B:$B,$C$3,Actuals!$C:$C,7,Actuals!$D:$D,$B$10,Actuals!$A:$A,LEFT($D$10,FIND("|",$D$10&"|")-1),Actuals!$E:$E,MID($D$10,FIND("|",$D$10&"|")+1,50),Actuals!$F:$F,"GBP")*$H$5) | O11: =IF(OR($B$10="",8>$C$4),"",SUMIFS(Actuals!$G:$G,Actuals!$B:$B,$C$3,Actuals!$C:$C,8,Actuals!$D:$D,$B$10,Actuals!$A:$A,LEFT($D$10,FIND("|",$D$10&"|")-1),Actuals!$E:$E,MID($D$10,FIND("|",$D$10&"|")+1,50),Actuals!$F:$F,"JPY")*$E$5+SUMIFS(Actuals!$G:$G,Actuals!$B:$B,$C$3,Actuals!$C:$C,8,Actuals!$D:$D,$B$10,Actuals!$A:$A,LEFT($D$10,FIND("|",$D$10&"|")-1),Actuals!$E:$E,MID($D$10,FIND("|",$D$10&"|")+1,50),Actuals!$F:$F,"USD")*$F$5+SUMIFS(Actuals!$G:$G,Actuals!$B:$B,$C$3,Actuals!$C:$C,8,Actuals!$D:$D,$B$10,Actuals!$A:$A,LEFT($D$10,FIND("|",$D$10&"|")-1),Actuals!$E:$E,MID($D$10,FIND("|",$D$10&"|")+1,50),Actuals!$F:$F,"EUR")*$G$5+SUMIFS(Actuals!$G:$G,Actuals!$B:$B,$C$3,Actuals!$C:$C,8,Actuals!$D:$D,$B$10,Actuals!$A:$A,LEFT($D$10,FIND("|",$D$10&"|")-1),Actuals!$E:$E,MID($D$10,FIND("|",$D$10&"|")+1,50),Actuals!$F:$F,"GBP")*$H$5) | P11: =IF(OR($B$10="",9>$C$4),"",SUMIFS(Actuals!$G:$G,Actuals!$B:$B,$C$3,Actuals!$C:$C,9,Actuals!$D:$D,$B$10,Actuals!$A:$A,LEFT($D$10,FIND("|",$D$10&"|")-1),Actuals!$E:$E,MID($D$10,FIND("|",$D$10&"|")+1,50),Actuals!$F:$F,"JPY")*$E$5+SUMIFS(Actuals!$G:$G,Actuals!$B:$B,$C$3,Actuals!$C:$C,9,Actuals!$D:$D,$B$10,Actuals!$A:$A,LEFT($D$10,FIND("|",$D$10&"|")-1),Actuals!$E:$E,MID($D$10,FIND("|",$D$10&"|")+1,50),Actuals!$F:$F,"USD")*$F$5+SUMIFS(Actuals!$G:$G,Actuals!$B:$B,$C$3,Actuals!$C:$C,9,Actuals!$D:$D,$B$10,Actuals!$A:$A,LEFT($D$10,FIND("|",$D$10&"|")-1),Actuals!$E:$E,MID($D$10,FIND("|",$D$10&"|")+1,50),Actuals!$F:$F,"EUR")*$G$5+SUMIFS(Actuals!$G:$G,Actuals!$B:$B,$C$3,Actuals!$C:$C,9,Actuals!$D:$D,$B$10,Actuals!$A:$A,LEFT($D$10,FIND("|",$D$10&"|")-1),Actuals!$E:$E,MID($D$10,FIND("|",$D$10&"|")+1,50),Actuals!$F:$F,"GBP")*$H$5) | Q11: =IF(OR($B$10="",10>$C$4),"",SUMIFS(Actuals!$G:$G,Actuals!$B:$B,$C$3,Actuals!$C:$C,10,Actuals!$D:$D,$B$10,Actuals!$A:$A,LEFT($D$10,FIND("|",$D$10&"|")-1),Actuals!$E:$E,MID($D$10,FIND("|",$D$10&"|")+1,50),Actuals!$F:$F,"JPY")*$E$5+SUMIFS(Actuals!$G:$G,Actuals!$B:$B,$C$3,Actuals!$C:$C,10,Actuals!$D:$D,$B$10,Actuals!$A:$A,LEFT($D$10,FIND("|",$D$10&"|")-1),Actuals!$E:$E,MID($D$10,FIND("|",$D$10&"|")+1,50),Actuals!$F:$F,"USD")*$F$5+SUMIFS(Actuals!$G:$G,Actuals!$B:$B,$C$3,Actuals!$C:$C,10,Actuals!$D:$D,$B$10,Actuals!$A:$A,LEFT($D$10,FIND("|",$D$10&"|")-1),Actuals!$E:$E,MID($D$10,FIND("|",$D$10&"|")+1,50),Actuals!$F:$F,"EUR")*$G$5+SUMIFS(Actuals!$G:$G,Actuals!$B:$B,$C$3,Actuals!$C:$C,10,Actuals!$D:$D,$B$10,Actuals!$A:$A,LEFT($D$10,FIND("|",$D$10&"|")-1),Actuals!$E:$E,MID($D$10,FIND("|",$D$10&"|")+1,50),Actuals!$F:$F,"GBP")*$H$5) | R11: =IF(OR($B$10="",11>$C$4),"",SUMIFS(Actuals!$G:$G,Actuals!$B:$B,$C$3,Actuals!$C:$C,11,Actuals!$D:$D,$B$10,Actuals!$A:$A,LEFT($D$10,FIND("|",$D$10&"|")-1),Actuals!$E:$E,MID($D$10,FIND("|",$D$10&"|")+1,50),Actuals!$F:$F,"JPY")*$E$5+SUMIFS(Actuals!$G:$G,Actuals!$B:$B,$C$3,Actuals!$C:$C,11,Actuals!$D:$D,$B$10,Actuals!$A:$A,LEFT($D$10,FIND("|",$D$10&"|")-1),Actuals!$E:$E,MID($D$10,FIND("|",$D$10&"|")+1,50),Actuals!$F:$F,"USD")*$F$5+SUMIFS(Actuals!$G:$G,Actuals!$B:$B,$C$3,Actuals!$C:$C,11,Actuals!$D:$D,$B$10,Actuals!$A:$A,LEFT($D$10,FIND("|",$D$10&"|")-1),Actuals!$E:$E,MID($D$10,FIND("|",$D$10&"|")+1,50),Actuals!$F:$F,"EUR")*$G$5+SUMIFS(Actuals!$G:$G,Actuals!$B:$B,$C$3,Actuals!$C:$C,11,Actuals!$D:$D,$B$10,Actuals!$A:$A,LEFT($D$10,FIND("|",$D$10&"|")-1),Actuals!$E:$E,MID($D$10,FIND("|",$D$10&"|")+1,50),Actuals!$F:$F,"GBP")*$H$5) | S11: =IF(OR($B$10="",12>$C$4),"",SUMIFS(Actuals!$G:$G,Actuals!$B:$B,$C$3,Actuals!$C:$C,12,Actuals!$D:$D,$B$10,Actuals!$A:$A,LEFT($D$10,FIND("|",$D$10&"|")-1),Actuals!$E:$E,MID($D$10,FIND("|",$D$10&"|")+1,50),Actuals!$F:$F,"JPY")*$E$5+SUMIFS(Actuals!$G:$G,Actuals!$B:$B,$C$3,Actuals!$C:$C,12,Actuals!$D:$D,$B$10,Actuals!$A:$A,LEFT($D$10,FIND("|",$D$10&"|")-1),Actuals!$E:$E,MID($D$10,FIND("|",$D$10&"|")+1,50),Actuals!$F:$F,"USD")*$F$5+SUMIFS(Actuals!$G:$G,Actuals!$B:$B,$C$3,Actuals!$C:$C,12,Actuals!$D:$D,$B$10,Actuals!$A:$A,LEFT($D$10,FIND("|",$D$10&"|")-1),Actuals!$E:$E,MID($D$10,FIND("|",$D$10&"|")+1,50),Actuals!$F:$F,"EUR")*$G$5+SUMIFS(Actuals!$G:$G,Actuals!$B:$B,$C$3,Actuals!$C:$C,12,Actuals!$D:$D,$B$10,Actuals!$A:$A,LEFT($D$10,FIND("|",$D$10&"|")-1),Actuals!$E:$E,MID($D$10,FIND("|",$D$10&"|")+1,50),Actuals!$F:$F,"GBP")*$H$5) | T11: =IF($B$10="","",SUMIF($H$7:$S$7,"<="&$C$4,$H11:$S11)) | X11: =IF($B11="","",IFERROR(INDEX(Cost_Centers!$E:$E,MATCH($B11,Cost_Centers!$A:$A,0)),"(unknown)")) | Y11: =IF($B11="","",IFERROR(INDEX(Cost_Centers!$D:$D,MATCH($B11,Cost_Centers!$A:$A,0)),"(unknown)")) | Z11: =IF(OR($B11="",$G11<>"Variance vs Budget"),"",ABS(N($V11))+ROW()/1000000000)
A12: =IF(A$10="","",A$10) | B12: =IF(B$10="","",B$10) | C12: =IF(C$10="","",C$10) | D12: =IF(D$10="","",D$10) | E12: =IF(E$10="","",E$10) | F12: =IF(F$10="","",F$10) | G12: Variance vs Budget | H12: =IF(OR($B$10="",1>$C$4),"",N(H11)-H10) | I12: =IF(OR($B$10="",2>$C$4),"",N(I11)-I10) | J12: =IF(OR($B$10="",3>$C$4),"",N(J11)-J10) | K12: =IF(OR($B$10="",4>$C$4),"",N(K11)-K10) | L12: =IF(OR($B$10="",5>$C$4),"",N(L11)-L10) | M12: =IF(OR($B$10="",6>$C$4),"",N(M11)-M10) | N12: =IF(OR($B$10="",7>$C$4),"",N(N11)-N10) | O12: =IF(OR($B$10="",8>$C$4),"",N(O11)-O10) | P12: =IF(OR($B$10="",9>$C$4),"",N(P11)-P10) | Q12: =IF(OR($B$10="",10>$C$4),"",N(Q11)-Q10) | R12: =IF(OR($B$10="",11>$C$4),"",N(R11)-R10) | S12: =IF(OR($B$10="",12>$C$4),"",N(S11)-S10) | T12: =IF($B$10="","",T11-T10) | U12: =IF($B$10="","",U14-U10) | V12: =IF($B$10="","",V14-V10) | X12: =IF($B12="","",IFERROR(INDEX(Cost_Centers!$E:$E,MATCH($B12,Cost_Centers!$A:$A,0)),"(unknown)")) | Y12: =IF($B12="","",IFERROR(INDEX(Cost_Centers!$D:$D,MATCH($B12,Cost_Centers!$A:$A,0)),"(unknown)")) | Z12: =IF(OR($B12="",$G12<>"Variance vs Budget"),"",ABS(N($V12))+ROW()/1000000000)
A13: =IF(A$10="","",A$10) | B13: =IF(B$10="","",B$10) | C13: =IF(C$10="","",C$10) | D13: =IF(D$10="","",D$10) | E13: =IF(E$10="","",E$10) | F13: =IF(F$10="","",F$10) | G13: Forecast (input) | X13: =IF($B13="","",IFERROR(INDEX(Cost_Centers!$E:$E,MATCH($B13,Cost_Centers!$A:$A,0)),"(unknown)")) | Y13: =IF($B13="","",IFERROR(INDEX(Cost_Centers!$D:$D,MATCH($B13,Cost_Centers!$A:$A,0)),"(unknown)")) | Z13: =IF(OR($B13="",$G13<>"Variance vs Budget"),"",ABS(N($V13))+ROW()/1000000000)
A14: =IF(A$10="","",A$10) | B14: =IF(B$10="","",B$10) | C14: =IF(C$10="","",C$10) | D14: =IF(D$10="","",D$10) | E14: =IF(E$10="","",E$10) | F14: =IF(F$10="","",F$10) | G14: Actual + Forecast | H14: =IF($B$10="","",IF(1<=$C$4,N(H11),IF(H13="",H10,H13))) | I14: =IF($B$10="","",IF(2<=$C$4,N(I11),IF(I13="",I10,I13))) | J14: =IF($B$10="","",IF(3<=$C$4,N(J11),IF(J13="",J10,J13))) | K14: =IF($B$10="","",IF(4<=$C$4,N(K11),IF(K13="",K10,K13))) | L14: =IF($B$10="","",IF(5<=$C$4,N(L11),IF(L13="",L10,L13))) | M14: =IF($B$10="","",IF(6<=$C$4,N(M11),IF(M13="",M10,M13))) | N14: =IF($B$10="","",IF(7<=$C$4,N(N11),IF(N13="",N10,N13))) | O14: =IF($B$10="","",IF(8<=$C$4,N(O11),IF(O13="",O10,O13))) | P14: =IF($B$10="","",IF(9<=$C$4,N(P11),IF(P13="",P10,P13))) | Q14: =IF($B$10="","",IF(10<=$C$4,N(Q11),IF(Q13="",Q10,Q13))) | R14: =IF($B$10="","",IF(11<=$C$4,N(R11),IF(R13="",R10,R13))) | S14: =IF($B$10="","",IF(12<=$C$4,N(S11),IF(S13="",S10,S13))) | T14: =IF($B$10="","",SUMIF($H$7:$S$7,"<="&$C$4,$H14:$S14)) | U14: =IF($B$10="","",SUMIF($H$7:$S$7,">"&$C$4,$H14:$S14)) | V14: =IF($B$10="","",SUM($H14:$S14)) | X14: =IF($B14="","",IFERROR(INDEX(Cost_Centers!$E:$E,MATCH($B14,Cost_Centers!$A:$A,0)),"(unknown)")) | Y14: =IF($B14="","",IFERROR(INDEX(Cost_Centers!$D:$D,MATCH($B14,Cost_Centers!$A:$A,0)),"(unknown)")) | Z14: =IF(OR($B14="",$G14<>"Variance vs Budget"),"",ABS(N($V14))+ROW()/1000000000)
A15: =IF(A$10="","",A$10) | B15: =IF(B$10="","",B$10) | C15: =IF(C$10="","",C$10) | D15: =IF(D$10="","",D$10) | E15: =IF(E$10="","",E$10) | F15: =IF(F$10="","",F$10) | G15: Prior Month Forecast | H15: =IF($B$10="","",IF(COUNTIFS(Prior_Forecast!$A:$A,$B$10,Prior_Forecast!$B:$B,$D$10)>0,SUMIFS(Prior_Forecast!$C:$C,Prior_Forecast!$A:$A,$B$10,Prior_Forecast!$B:$B,$D$10),"")) | I15: =IF($B$10="","",IF(COUNTIFS(Prior_Forecast!$A:$A,$B$10,Prior_Forecast!$B:$B,$D$10)>0,SUMIFS(Prior_Forecast!$D:$D,Prior_Forecast!$A:$A,$B$10,Prior_Forecast!$B:$B,$D$10),"")) | J15: =IF($B$10="","",IF(COUNTIFS(Prior_Forecast!$A:$A,$B$10,Prior_Forecast!$B:$B,$D$10)>0,SUMIFS(Prior_Forecast!$E:$E,Prior_Forecast!$A:$A,$B$10,Prior_Forecast!$B:$B,$D$10),"")) | K15: =IF($B$10="","",IF(COUNTIFS(Prior_Forecast!$A:$A,$B$10,Prior_Forecast!$B:$B,$D$10)>0,SUMIFS(Prior_Forecast!$F:$F,Prior_Forecast!$A:$A,$B$10,Prior_Forecast!$B:$B,$D$10),"")) | L15: =IF($B$10="","",IF(COUNTIFS(Prior_Forecast!$A:$A,$B$10,Prior_Forecast!$B:$B,$D$10)>0,SUMIFS(Prior_Forecast!$G:$G,Prior_Forecast!$A:$A,$B$10,Prior_Forecast!$B:$B,$D$10),"")) | M15: =IF($B$10="","",IF(COUNTIFS(Prior_Forecast!$A:$A,$B$10,Prior_Forecast!$B:$B,$D$10)>0,SUMIFS(Prior_Forecast!$H:$H,Prior_Forecast!$A:$A,$B$10,Prior_Forecast!$B:$B,$D$10),"")) | N15: =IF($B$10="","",IF(COUNTIFS(Prior_Forecast!$A:$A,$B$10,Prior_Forecast!$B:$B,$D$10)>0,SUMIFS(Prior_Forecast!$I:$I,Prior_Forecast!$A:$A,$B$10,Prior_Forecast!$B:$B,$D$10),"")) | O15: =IF($B$10="","",IF(COUNTIFS(Prior_Forecast!$A:$A,$B$10,Prior_Forecast!$B:$B,$D$10)>0,SUMIFS(Prior_Forecast!$J:$J,Prior_Forecast!$A:$A,$B$10,Prior_Forecast!$B:$B,$D$10),"")) | P15: =IF($B$10="","",IF(COUNTIFS(Prior_Forecast!$A:$A,$B$10,Prior_Forecast!$B:$B,$D$10)>0,SUMIFS(Prior_Forecast!$K:$K,Prior_Forecast!$A:$A,$B$10,Prior_Forecast!$B:$B,$D$10),"")) | Q15: =IF($B$10="","",IF(COUNTIFS(Prior_Forecast!$A:$A,$B$10,Prior_Forecast!$B:$B,$D$10)>0,SUMIFS(Prior_Forecast!$L:$L,Prior_Forecast!$A:$A,$B$10,Prior_Forecast!$B:$B,$D$10),"")) | R15: =IF($B$10="","",IF(COUNTIFS(Prior_Forecast!$A:$A,$B$10,Prior_Forecast!$B:$B,$D$10)>0,SUMIFS(Prior_Forecast!$M:$M,Prior_Forecast!$A:$A,$B$10,Prior_Forecast!$B:$B,$D$10),"")) | S15: =IF($B$10="","",IF(COUNTIFS(Prior_Forecast!$A:$A,$B$10,Prior_Forecast!$B:$B,$D$10)>0,SUMIFS(Prior_Forecast!$N:$N,Prior_Forecast!$A:$A,$B$10,Prior_Forecast!$B:$B,$D$10),"")) | T15: =IF($B$10="","",IF(COUNTIFS(Prior_Forecast!$A:$A,$B$10,Prior_Forecast!$B:$B,$D$10)>0,SUMIFS(Prior_Forecast!$O:$O,Prior_Forecast!$A:$A,$B$10,Prior_Forecast!$B:$B,$D$10),"")) | U15: =IF($B$10="","",IF(COUNTIFS(Prior_Forecast!$A:$A,$B$10,Prior_Forecast!$B:$B,$D$10)>0,SUMIFS(Prior_Forecast!$P:$P,Prior_Forecast!$A:$A,$B$10,Prior_Forecast!$B:$B,$D$10),"")) | V15: =IF($B$10="","",IF(COUNTIFS(Prior_Forecast!$A:$A,$B$10,Prior_Forecast!$B:$B,$D$10)>0,SUMIFS(Prior_Forecast!$Q:$Q,Prior_Forecast!$A:$A,$B$10,Prior_Forecast!$B:$B,$D$10),"")) | X15: =IF($B15="","",IFERROR(INDEX(Cost_Centers!$E:$E,MATCH($B15,Cost_Centers!$A:$A,0)),"(unknown)")) | Y15: =IF($B15="","",IFERROR(INDEX(Cost_Centers!$D:$D,MATCH($B15,Cost_Centers!$A:$A,0)),"(unknown)")) | Z15: =IF(OR($B15="",$G15<>"Variance vs Budget"),"",ABS(N($V15))+ROW()/1000000000)
A16: =IF(A$10="","",A$10) | B16: =IF(B$10="","",B$10) | C16: =IF(C$10="","",C$10) | D16: =IF(D$10="","",D$10) | E16: =IF(E$10="","",E$10) | F16: =IF(F$10="","",F$10) | G16: Variance vs Prior Month | H16: =IF(OR($B$10="",H15=""),"",H14-H15) | I16: =IF(OR($B$10="",I15=""),"",I14-I15) | J16: =IF(OR($B$10="",J15=""),"",J14-J15) | K16: =IF(OR($B$10="",K15=""),"",K14-K15) | L16: =IF(OR($B$10="",L15=""),"",L14-L15) | M16: =IF(OR($B$10="",M15=""),"",M14-M15) | N16: =IF(OR($B$10="",N15=""),"",N14-N15) | O16: =IF(OR($B$10="",O15=""),"",O14-O15) | ... V16: =IF(OR($B$10="",V15=""),"",V14-V15) | X16: =IF($B16="","",IFERROR(INDEX(Cost_Centers!$E:$E,MATCH($B16,Cost_Centers!$A:$A,0)),"(unknown)")) | Y16: =IF($B16="","",IFERROR(INDEX(Cost_Centers!$D:$D,MATCH($B16,Cost_Centers!$A:$A,0)),"(unknown)")) | Z16: =IF(OR($B16="",$G16<>"Variance vs Budget"),"",ABS(N($V16))+ROW()/1000000000)
A17: =IF(A$10="","",A$10) | B17: =IF(B$10="","",B$10) | C17: =IF(C$10="","",C$10) | D17: =IF(D$10="","",D$10) | E17: =IF(E$10="","",E$10) | F17: =IF(F$10="","",F$10) | G17: Rationale | X17: =IF($B17="","",IFERROR(INDEX(Cost_Centers!$E:$E,MATCH($B17,Cost_Centers!$A:$A,0)),"(unknown)")) | Y17: =IF($B17="","",IFERROR(INDEX(Cost_Centers!$D:$D,MATCH($B17,Cost_Centers!$A:$A,0)),"(unknown)")) | Z17: =IF(OR($B17="",$G17<>"Variance vs Budget"),"",ABS(N($V17))+ROW()/1000000000)
