Workbook

Sheet バリューストリーム
A1: バリューストリーム（L1〜L4）
A2: 対象：希少疾患向け新規バイオ医薬品（抗体医薬）／米国基準（FDA・BLA・21 CFR）。1行1項目。L1〜L4列の●がその行のレベル。出口はL2、入力・出力情報・GxP区分・主な関与者はL4の項目。 入力情報・出力情報はVS定義の過程で得られる正本（直接入力する）。情報オブジェクトはこれを取りまとめて一覧化したもの。
A3: ID | B3: L1 | C3: L2 | D3: L3 | E3: L4 | F3: VS項目名 | G3: VSの定義 | H3: 出口（ゲート） | I3: 入力情報 | J3: 出力情報 | K3: GxP区分 | L3: 主な関与者（社内／外部）
A4: VS | B4: ● | F4: Target-to-Patient | G4: 希少疾患の標的探索から、FDA承認・上市を経て、少数の患者へ確実に届け、市販後に価値を最大化するまで
A5: 01 | C5: ● | F5: 創薬研究 | G5: 疾患の原因を理解して標的を定め、抗体を創出・最適化し、開発候補品を1つに絞り込む段階 | H5: 開発候補品（DC）決定
A6: 01-01 | D6: ● | F6: 標的探索・検証 | G6: 患者団体・専門医の知見と遺伝学的解析から病態を理解し、抗体で狙う標的を選んで検証する
A7: 01-01-01 | E7: ● | F7: ★患者団体・専門医との連携による疾患理解 | I7: — | J7: 疾患知見 | K7: 非GxP | L7: 研究・メディカル／患者団体、専門医
A8: 01-01-02 | E8: ● | F8: 疾患生物学の調査・標的仮説の立案 | I8: 疾患知見、遺伝子・オミクスデータ | J8: 標的 | K8: 非GxP | L8: 研究／アカデミア
A9: 01-01-03 | E9: ● | F9: ★遺伝学的原因の解析（単一遺伝子疾患等、患者ゲノム・検体データ） | I9: 疾患知見 | J9: 遺伝子・オミクスデータ、標的 | K9: 非GxP | L9: 研究（ゲノム解析）／アカデミア、専門医
A10: 01-01-04 | E10: ● | F10: 標的の機能検証（遺伝子ノックダウン、in vitro／in vivo） | I10: 標的 | J10: 研究実験データ | K10: 非GxP | L10: 研究／—
A11: 01-01-05 | E11: ● | F11: 抗体モダリティ適合性評価（細胞外・膜タンパクか、組織発現分布） | I11: 標的、研究実験データ | J11: 標的 | K11: 非GxP | L11: 研究／—
A12: 01-01-06 | E12: ● | F12: 標的選定（競合・知財〔FTO〕調査を含む） | I12: 標的、特許・独占期間 | J12: 標的、目標製品プロファイル（TPP）、開発判定記録、適応症 | K12: 非GxP | L12: 研究・知財／—
A13: 01-02 | D13: ● | F13: ヒット・リード創出 | G13: 抗原・評価系を整え、抗体を取得・選別して、目的の機能を持つリード抗体を得る
A14: 01-02-01 | E14: ● | F14: 抗原・評価系（アッセイ）の準備 | I14: 標的 | J14: 抗原・試薬、アッセイ（評価系） | K14: 非GxP | L14: 研究／試薬メーカー
A15: 01-02-02 | E15: ● | F15: 抗体取得（動物免疫／ヒト抗体産生動物／ディスプレイライブラリ） | I15: 抗原・試薬 | J15: 抗体分子 | K15: 非GxP | L15: 研究／受託研究機関（免疫・ライブラリ）
A16: 01-02-03 | E16: ● | F16: 一次スクリーニング（結合性） | I16: 抗体分子、アッセイ（評価系） | J16: 抗体分子、研究実験データ | K16: 非GxP | L16: 研究／—
A17: 01-02-04 | E17: ● | F17: 機能評価（中和活性、ADCC等のエフェクター機能） | I17: 抗体分子、アッセイ（評価系） | J17: 研究実験データ | K17: 非GxP | L17: 研究／—
A18: 01-02-05 | E18: ● | F18: リード抗体の選定 | I18: 研究実験データ | J18: 抗体分子、開発判定記録 | K18: 非GxP | L18: 研究／—
A19: 01-03 | D19: ● | F19: リード最適化 | G19: ヒト化・親和性成熟・Fc設計でリード抗体を改良し、開発適性・免疫原性リスク・薬効を評価する
A20: 01-03-01 | E20: ● | F20: ヒト化（動物由来抗体の場合） | I20: 抗体分子 | J20: 抗体分子 | K20: 非GxP | L20: 研究（抗体工学）／—
A21: 01-03-02 | E21: ● | F21: 親和性成熟 | I21: 抗体分子 | J21: 抗体分子 | K21: 非GxP | L21: 研究（抗体工学）／—
A22: 01-03-03 | E22: ● | F22: Fc設計（エフェクター機能・血中半減期の調整） | I22: 抗体分子 | J22: 抗体分子 | K22: 非GxP | L22: 研究（抗体工学）／—
A23: 01-03-04 | E23: ● | F23: 開発適性評価（凝集性・安定性・発現性・粘度） | I23: 抗体分子 | J23: 研究実験データ | K23: 非GxP | L23: 研究・CMC（分析）／—
A24: 01-03-05 | E24: ● | F24: 免疫原性リスクの予測（in silico／in vitro） | I24: 抗体分子 | J24: 免疫原性リスク評価 | K24: 非GxP | L24: 研究（トランスレーショナル）／—
A25: 01-03-06 | E25: ● | F25: ★疾患モデルの構築・薬効評価（遺伝子改変動物・患者由来細胞） | I25: 抗体分子、遺伝子・オミクスデータ | J25: 疾患モデル、in vivo薬効データ | K25: 非GxP | L25: 研究（薬理）／受託研究機関
A26: 01-04 | D26: ● | F26: 開発候補品選定 | G26: TPPと照らして候補を比較し、患者数の確認と特許出願を経て、開発候補品を決定する
A27: 01-04-01 | E27: ● | F27: 目標製品プロファイル（TPP）との照合・候補比較 | I27: 目標製品プロファイル（TPP）、研究実験データ、in vivo薬効データ、免疫原性リスク評価 | J27: 目標製品プロファイル（TPP）、開発判定記録 | K27: 非GxP | L27: 研究・開発企画／—
A28: 01-04-02 | E28: ● | F28: ★患者数・疫学の確認（米国で20万人未満の根拠） | I28: 疾患知見、適応症 | J28: 疫学データ | K28: 非GxP | L28: メディカル（疫学）／データ提供事業者
A29: 01-04-03 | E29: ● | F29: 物質特許の出願 | I29: 抗体分子 | J29: 特許・独占期間 | K29: 非GxP | L29: 知財／特許事務所、USPTO
A30: 01-04-04 | E30: ● | F30: 開発移行判定会議 | I30: 開発判定記録、目標製品プロファイル（TPP）、疫学データ、特許・独占期間 | J30: 開発判定記録、製品マスタ | K30: 非GxP | L30: 経営（ポートフォリオ委員会）／—
A31: 02 | C31: ● | F31: 非臨床開発 | G31: 開発候補品をヒトに初めて投与できるよう、薬理・体内動態・安全性を非臨床で評価し、INDを発効させる段階 | H31: IND発効（臨床試験の開始が可能）
A32: 02-01 | D32: ● | F32: 非臨床薬理 | G32: 作用機序と用量反応を明らかにし、安全性薬理を評価する
A33: 02-01-01 | E33: ● | F33: 作用機序（MoA）の解明 | I33: 抗体分子、研究実験データ | J33: 非臨床試験報告書 | K33: 非GxP | L33: 研究（トランスレーショナル）／—
A34: 02-01-02 | E34: ● | F34: 薬効薬理試験（用量反応） | I34: 疾患モデル | J34: 非臨床試験データ、非臨床試験報告書 | K34: 非GxP | L34: 非臨床（薬理）／—
A35: 02-01-03 | E35: ● | F35: 安全性薬理評価（毒性試験への組込みが一般的） | I35: 非臨床試験計画 | J35: 非臨床試験データ | K35: GLP | L35: 非臨床（安全性）／受託試験機関
A36: 02-02 | D36: ● | F36: 薬物動態・免疫原性評価 | G36: PK・ADAの測定法を確立し、動物での体内動態・免疫原性を評価して、ヒトPKを予測する
A37: 02-02-01 | E37: ● | F37: PK／TK測定法（リガンド結合法）の確立 | I37: 抗体分子 | J37: 生体試料分析法 | K37: GLP | L37: 非臨床（バイオアナリシス）／受託試験機関
A38: 02-02-02 | E38: ● | F38: 動物PK試験 | I38: 非臨床試験計画、生体試料分析法 | J38: 非臨床試験データ | K38: 非GxP | L38: 非臨床（薬物動態）／受託試験機関
A39: 02-02-03 | E39: ● | F39: 抗薬物抗体（ADA）測定法の確立・動物での評価 | I39: 生体試料分析法 | J39: 生体試料分析法、非臨床試験データ | K39: GLP | L39: 非臨床（バイオアナリシス）／受託試験機関
A40: 02-02-04 | E40: ● | F40: ヒトPKの予測 | I40: 非臨床試験データ | J40: PK/PDモデル・解析結果 | K40: 非GxP | L40: 臨床薬理（ファーマコメトリクス）／—
...

Sheet ケイパビリティマップ
A1: ビジネス・ケイパビリティマップ（L1〜L3）
A2: 対象：希少疾患向け新規バイオ医薬品（抗体医薬）／米国基準（FDA・BLA・21 CFR）。1行1項目。L1〜L3列の●がその行のレベル。区分はL1、範囲・アウトカムはL3の項目。★＝希少疾患に限定したことで追加・強調した能力。
A3: ID | B3: L1 | C3: L2 | D3: L3 | E3: ケイパビリティ名 | F3: ケイパビリティの定義 | G3: 区分 | H3: 範囲（含む） | I3: 範囲（含まない） | J3: アウトカム
A4: C01 | B4: ● | E4: 戦略・ガバナンス | F4: 研究開発の方向性・資源配分と、知財・外部パートナーを通じた事業基盤を統制する能力 | G4: 戦略
A5: C01-01 | C5: ● | E5: 研究開発ポートフォリオ管理 | F5: パイプラインの価値・リスクを評価し、資源配分と段階移行を判断する
A6: C01-01-01 | D6: ● | E6: パイプライン評価・優先順位付け | F6: 開発品の価値・成功確率・必要資源を評価し、優先順位と資源配分を決める | H6: 価値評価（rNPV等）、成功確率の推定、資源配分 | I6: 価格戦略・設定（C11-01-01） | J6: 資源が優先度に沿って配分されたパイプライン
A7: C01-01-02 | D7: ● | E7: 段階移行判定 | F7: 開発候補品決定・Go／No-Goなど、段階移行の判断基準を定め、判断を下す | H7: 判断基準の設定、判定会議の運営、判断記録 | I7: 科学的評価そのもの（各ケイパビリティが担う） | J7: 根拠が明確で一貫した移行判断
A8: C01-01-03 | D8: ● | E8: 目標製品プロファイル（TPP）管理 | F8: 開発品が目指す製品像（適応・用法・有効性・安全性・剤形）を設定し、更新する | H8: TPPの設定・改訂、機能横断での共有 | I8: 試験デザイン★（C05-01-02） | J8: 全機能で共有された、根拠のある製品像
A9: C01-01-04 | D9: ● | E9: 開発プロジェクト管理 | F9: 開発品ごとに、機能横断の統合計画・進捗・リスクを管理する | H9: 統合スケジュール、課題・リスク管理、部門間調整 | I9: モニタリング・施設管理（C05-04-02） | J9: 計画どおりに進む、見通しの立つ開発
A10: C01-02 | C10: ● | E10: 知財・独占期間管理 | F10: 特許と規制上の独占期間により、製品の排他性を確保・維持する
A11: C01-02-01 | D11: ● | E11: 特許戦略・調査 | F11: 物質・製法・用途の特許の出願・権利化と、他者特許の調査（FTO）を行う | H11: 特許出願・権利化、FTO調査、競合知財の監視 | I11: 規制上の独占期間管理（C01-02-02） | J11: 事業化の自由度と排他権の確保
A12: C01-02-02 | D12: ● | E12: 規制上の独占期間管理 | F12: Orphan 7年・生物製剤12年の独占期間の範囲を確認し、維持する | H12: 独占範囲の確認、Purple Bookの掲載情報の確認 | I12: 指定制度・インセンティブ管理★（C06-01-03） | J12: 最大限に確保された独占期間
A13: C01-02-03 | D13: ● | E13: バイオシミラー対応 | F13: 後続のバイオシミラー申請者との特許情報交換（BPCIA）と紛争に対応する | H13: 特許情報の交換手続き、訴訟対応 | I13: 特許戦略・調査（C01-02-01） | J13: 後続品参入に対する権利の適切な行使
A14: C01-03 | C14: ● | E14: 外部パートナー管理 | F14: CRO・CDMO・受託機関・提携先を選び、契約し、委託業務を監督する
A15: C01-03-01 | D15: ● | E15: パートナー選定・評価 | F15: 委託先・提携先の能力・リスクを評価し、選定する | H15: 候補の調査・評価、選定判断 | I15: 内部監査・パートナー監査（C08-04-02） | J15: 目的に合った委託先・提携先
A16: C01-03-02 | D16: ● | E16: 委託業務の契約・監督 | F16: 業務契約・品質取決めを結び、委託業務の実績・課題を管理する（責任はスポンサーに残る） | H16: 業務契約、品質取決め、実績・KPIの管理 | I16: 保険者・PBM契約（C11-01-03）、流通ネットワーク設計・パートナー管理（C12-02-01） | J16: 委託しても品質・期限が守られる状態
A17: C01-03-03 | D17: ● | E17: 提携・ライセンス管理 | F17: 共同開発・導入・導出の契約と、提携関係を管理する | H17: 提携交渉・契約、提携先との共同運営 | I17: — | J17: 価値を生む提携関係
A18: C02 | B18: ● | E18: 研究（創薬） | F18: 疾患を理解し、標的に対する抗体を創出・最適化して開発候補品を生み出す能力 | G18: コア
A19: C02-01 | C19: ● | E19: 疾患・標的研究★ | F19: 遺伝学的原因を起点に疾患を理解し、抗体で狙う標的を探索・検証する
A20: C02-01-01 | D20: ● | E20: 病態・遺伝学的原因の解析★ | F20: 患者ゲノム・検体データや疾患生物学から、病態と原因遺伝子・経路を明らかにする | H20: 遺伝学的解析、病態メカニズムの解明、標的仮説の立案 | I20: 患者団体との協働★（C10-01-01） | J20: 根拠のある標的仮説
A21: C02-01-02 | D21: ● | E21: 標的検証 | F21: 標的の関与を実験的に検証する | H21: 遺伝子ノックダウン等の機能検証、in vitro／in vivoでの検証 | I21: in vitro／in vivo薬効評価（C02-04-02） | J21: 検証された標的
A22: C02-01-03 | D22: ● | E22: モダリティ適合性評価 | F22: 標的が抗体で狙えるか（細胞外・膜タンパクか、発現分布など）を評価する | H22: 標的の局在・発現分布の評価、モダリティ選択 | I22: — | J22: 抗体で狙うことの妥当性
A23: C02-02 | C23: ● | E23: 抗体創出 | F23: 抗原・評価系を整え、抗体を取得して選別する
A24: C02-02-01 | D24: ● | E24: 抗原・アッセイ開発 | F24: 抗体取得・評価に使う抗原と評価系（アッセイ）をつくる | H24: 抗原タンパク・細胞の調製、結合・機能アッセイの構築 | I24: 分析法開発・バリデーション（C04-04-02） | J24: 信頼できる抗原と評価系
A25: C02-02-02 | D25: ● | E25: 抗体取得 | F25: 動物免疫・ヒト抗体産生動物・ディスプレイライブラリから抗体を得る | H25: 免疫、ライブラリ構築・パニング、配列取得 | I25: — | J25: 多様な抗体クローン群
A26: C02-02-03 | D26: ● | E26: スクリーニング・機能評価 | F26: 抗体を結合性・機能（中和・エフェクター機能）で選別する | H26: 一次スクリーニング、機能評価、ヒット・リードの選定 | I26: — | J26: 目的の機能を持つリード抗体
A27: C02-03 | C27: ● | E27: 抗体エンジニアリング | F27: 抗体分子を改変し、医薬品として最適化する
A28: C02-03-01 | D28: ● | E28: ヒト化 | F28: 動物由来抗体をヒト型に改変し、免疫原性を下げる | H28: CDR移植、フレームワーク最適化 | I28: — | J28: ヒトに投与できる抗体配列
A29: C02-03-02 | D29: ● | E29: 親和性成熟 | F29: 標的への結合力・特異性を高める | H29: 変異導入・選択 | I29: — | J29: 最適な結合特性
A30: C02-03-03 | D30: ● | E30: Fcエンジニアリング | F30: Fc領域を設計し、エフェクター機能・血中半減期を調整する | H30: エフェクター機能の増強・低減、半減期延長 | I30: — | J30: 目的に合った作用・体内動態
A31: C02-04 | C31: ● | E31: 疾患モデル・薬効評価 | F31: 疾患モデルを構築し、候補抗体の薬効を評価する
A32: C02-04-01 | D32: ● | E32: 疾患モデル構築★ | F32: 遺伝子改変動物・患者由来細胞などで疾患を再現するモデルをつくる | H32: モデルの作製・特性評価・維持 | I32: — | J32: 疾患を反映した評価系
A33: C02-04-02 | D33: ● | E33: in vitro／in vivo薬効評価 | F33: 候補選定のために、疾患モデルで候補抗体の薬効を比較評価する | H33: 候補間の薬効比較 | I33: 作用機序・薬効薬理評価（C03-01-01） | J33: 候補選定の根拠となる薬効データ
A34: C02-05 | C34: ● | E34: 開発適性・免疫原性リスク評価 | F34: 医薬品として開発・製造できるか、免疫原性のリスクはどうかを早期に評価する
A35: C02-05-01 | D35: ● | E35: 開発適性評価 | F35: 凝集性・安定性・発現性・粘度など、開発・製造上の適性を評価する | H35: 開発適性の各種評価、配列上のリスク部位の特定 | I35: 処方開発（C04-03-01） | J35: 開発・製造で問題が起きにくい候補
A36: C02-05-02 | D36: ● | E36: 免疫原性リスク予測 | F36: in silico／in vitroで免疫原性（抗薬物抗体の発生）のリスクを予測する | H36: T細胞エピトープ予測、in vitro評価 | I36: 測定法開発・バリデーション（C03-03-01） | J36: 免疫原性リスクの低い候補
A37: C03 | B37: ● | E37: 非臨床・臨床薬理 | F37: ヒトへの投与を可能にし、用法用量を裏づける薬理・安全性・体内動態の知見を生み出す能力 | G37: コア
A38: C03-01 | C38: ● | E38: 非臨床薬理評価 | F38: 作用機序と薬効・安全性薬理を明らかにする
A39: C03-01-01 | D39: ● | E39: 作用機序・薬効薬理評価 | F39: 作用機序を明らかにし、用量反応を含む薬効薬理を評価する | H39: 作用機序解析、用量反応試験 | I39: in vitro／in vivo薬効評価（C02-04-02） | J39: 臨床での作用・用量を裏づける薬理データ
A40: C03-01-02 | D40: ● | E40: 安全性薬理評価 | F40: 主要な生理機能への影響を評価する（毒性試験に組み込むことが多い） | H40: 心血管・呼吸・中枢神経系への影響評価 | I40: — | J40: 安全性薬理の知見
...

Sheet ケイパビリティレベル
A1: ケイパビリティの成熟度レベル（L2ごとの定義）
A2: 対象：希少疾患向け新規バイオ医薬品（抗体医薬）／米国基準（FDA・BLA・21 CFR）。評価の対象はL2。規制上の最低水準：GxP・法令が関わるL2はレベル3が事実上の最低水準。
A3: レベル | B3: 名称 | C3: 共通定義
A4: 1 | B4: 初期 | C4: 属人的・場当たり的。成果が個人に依存し、再現できない
A5: 2 | B5: 管理された | C5: 案件（製品・試験・プロジェクト）ごとに計画・管理され、再現できる。ただし方法は案件・部門で異なる
A6: 3 | B6: 定義された | C6: 全社標準のプロセス・役割・データ定義があり、一貫して運用される
A7: 4 | B7: 定量的に管理された | C7: 指標で成果・品質を測定し、データに基づいて管理・予測する
A8: 5 | B8: 最適化された | C8: 継続的な改善と先進的な手法により、変化に先回りし、業界をリードする
A10: L2 ID | B10: ケイパビリティL1 | C10: ケイパビリティL2 | D10: 規制上の最低水準 | E10: レベル1 初期 | F10: レベル2 管理された | G10: レベル3 定義された | H10: レベル4 定量的に管理された | I10: レベル5 最適化された
A11: C01-01 | B11: 戦略・ガバナンス | C11: 研究開発ポートフォリオ管理 | D11: — | E11: 優先順位が個人の判断で決まり、根拠が残らない | F11: 開発品ごとに価値・リスクを評価するが、方法が案件ごとに異なる | G11: 全社共通の評価基準と判定プロセスで、全開発品を比較・判断する | H11: 成功確率・価値の予測を実績で検証し、資源配分を定量的に最適化する | I11: ポートフォリオ全体のシナリオ分析で、環境変化に先回りして組み替える
A12: C01-02 | C12: 知財・独占期間管理 | D12: — | E12: 特許出願が研究者任せで、独占期間を把握していない | F12: 主要製品ごとに特許・独占期間を管理している | G12: 特許と規制上の独占期間を一元管理し、全製品で戦略的に出願・維持する | H12: 独占期間の残りと競合参入リスクを定量的に監視し、製品戦略に反映する | I12: 知財と規制上の独占を組み合わせ、製品価値を最大化する戦略を先導する
A13: C01-03 | C13: 外部パートナー管理 | D13: — | E13: 委託先の選定・監督が担当者任せ | F13: 委託案件ごとに契約・品質取決めを結び、進捗を管理する | G13: 全社標準の選定基準・契約・監督の仕組みで、委託先を一元管理する | H13: 委託先の実績をKPIで評価し、選定・更新に反映する | I13: 戦略的パートナーと共同で改善し、委託ネットワーク全体を最適化する
A14: C02-01 | B14: 研究（創薬） | C14: 疾患・標的研究★ | D14: — | E14: 公開情報が中心で、標的仮説の根拠が限られる | F14: プロジェクトごとに遺伝学的解析・標的検証を行う | G14: 遺伝学的データと患者団体・専門医の知見を体系的に使う、標準的な探索・検証の流れがある | H14: 標的の検証成功率・臨床移行率を測定し、標的選定を改善する | I14: 独自の患者データ・解析基盤により、他社に先んじて新しい標的を見出す
A15: C02-02 | C15: 抗体創出 | D15: — | E15: 外部技術に依存し、取得・選別が場当たり的 | F15: 標準的な取得法・アッセイを持ち、案件ごとに運用する | G15: 複数の取得プラットフォームと、標準化されたスクリーニング体系を持つ | H15: ヒット率・期間を測定し、自動化で効率を管理する | I15: 独自のプラットフォームで、難しい標的にも抗体を創出できる
A16: C02-03 | C16: 抗体エンジニアリング | D16: — | E16: 改変を外部に依存している | F16: ヒト化・親和性成熟を案件ごとに実施できる | G16: ヒト化・親和性成熟・Fc設計を標準手法として社内で実施する | H16: 設計の成功率を測定し、構造・計算手法で予測精度を高める | I16: AI・計算設計などで、独自の分子設計により差別化する
A17: C02-04 | C17: 疾患モデル・薬効評価 | D17: — | E17: 既存モデルに依存し、疾患の再現性が不十分 | F17: 案件ごとにモデルを構築・評価する | G17: 疾患ごとに検証済みのモデル群を持ち、標準的に評価する | H17: モデルの予測性（臨床結果との相関）を検証し、改善する | I17: 患者由来細胞などの独自モデルで、臨床予測性の高い評価を先導する
A18: C02-05 | C18: 開発適性・免疫原性リスク評価 | D18: — | E18: 評価をせず、後工程で問題が発覚する | F18: 候補選定時に一部の評価を行う | G18: 標準的な評価項目で全候補を評価し、選定基準に組み込む | H18: 評価結果と後工程（製造性・ADA発生）の相関を測定し、基準を改善する | I18: 予測モデルにより、設計段階からリスクを回避する
A19: C03-01 | B19: 非臨床・臨床薬理 | C19: 非臨床薬理評価 | D19: — | E19: 試験が場当たり的で、臨床の用量設定に結びつかない | F19: 開発品ごとに計画して実施する | G19: 標準的な試験構成で、臨床の作用・用量の根拠を体系的に作る | H19: 非臨床と臨床の結果の整合を検証し、試験設計を改善する | I19: トランスレーショナルな指標で、臨床結果を高い精度で予測する
A20: C03-02 | C20: 非臨床安全性評価 | D20: レベル3（GLP） | E20: 試験構成が指針に沿わず、追加試験が発生する | F20: 開発品ごとに受託試験機関と試験を設計・実施する | G20: 抗体医薬の指針（ICH S6）に沿った標準戦略で、過不足のない試験構成を組む | H20: 当局からの指摘・追加試験の発生を測定し、戦略を改善する | I20: 動物試験に代わる新しい手法を活用し、効率と予測性を高める
A21: C03-03 | C21: バイオアナリシス | D21: レベル3（GLP・GCP） | E21: 測定法が安定せず、データの信頼性に課題がある | F21: 開発品ごとに測定法を確立・運用する | G21: 規制ガイダンスに沿った標準的な測定法の開発・バリデーションと、検査機関の管理を行う | H21: 再測定率・納期を測定し、管理する | I21: 新しいバイオマーカー・高感度測定を先導する
A22: C03-04 | C22: 臨床薬理・ファーマコメトリクス | D22: — | E22: 経験則で用量を決める | F22: 開発品ごとにPK解析を行う | G22: モデルに基づく医薬品開発（MIDD）を標準的に適用する | H22: モデルの予測と実績の差を検証し、意思決定に定量的に活用する | I22: モデルで試験を代替・縮小し、当局と合意する（少数例の希少疾患で特に有効）
A23: C04-01 | B23: CMC開発 | C23: 細胞株開発・セルバンク管理 | D23: レベル3（GMP：セルバンク） | E23: 細胞株構築をCDMOに全面依存し、記録が不十分 | F23: 案件ごとに細胞株を構築し、セルバンクを管理する | G23: 標準的な細胞株開発プラットフォームと、セルバンクの一元管理を持つ | H23: 生産性・安定性を指標で管理し、開発期間を短縮する | I23: 独自の高生産プラットフォームで、開発期間・コストの優位に立つ
A24: C04-02 | C24: 原薬プロセス開発 | D24: — | E24: 工程が経験則で、スケールを変えると問題が起きる | F24: 開発品ごとに工程を開発する | G24: プラットフォーム工程とQbD（リスク評価・管理戦略）を標準的に適用する | H24: 工程性能・収率を指標で管理し、データに基づいて最適化する | I24: 連続生産などの先進的な工程技術を導入し、業界をリードする
A25: C04-03 | C25: 製剤・デバイス開発 | D25: — | E25: 既存処方の流用のみ | F25: 開発品ごとに処方・容器を開発する | G25: 標準的な処方開発・容器評価と、デバイスの設計管理を運用する | H25: 安定性・使いやすさの指標で設計を最適化する | I25: 高濃度製剤・在宅自己投与デバイスなど、患者中心の製剤で差別化する
A26: C04-04 | C26: 分析法開発・品質特性評価 | D26: レベル3（GMP） | E26: 特性解析が不十分で、規格の根拠が弱い | F26: 開発品ごとに分析法・規格を設定する | G26: 標準的な特性解析・分析法バリデーション・同等性評価の手順を持つ | H26: 分析法の性能と同等性判断の実績を指標で管理する | I26: 高度な分析技術で品質を深く理解し、製法変更を迅速にする
A27: C04-05 | C27: 技術移転・製造規模管理 | D27: レベル3（GMP） | E27: 移転のたびに問題が起き、規模の判断が場当たり的 | F27: 案件ごとに移転計画を作り、実施する | G27: 標準的な移転手順と、需要に基づく規模・拠点の判断基準を持つ | H27: 移転の期間・成功率を指標で管理する | I27: 需要の変動に柔軟に対応できる製造ネットワークを先回りして構築する
A28: C05-01 | B28: 臨床開発 | C28: 臨床開発戦略・試験デザイン | D28: — | E28: 一般的な第I〜III相の流用のみ | F28: 開発品ごとに計画・設計する | G28: 希少疾患向けの設計手法（単一ピボタル、外部対照、適応的デザイン）を標準的に検討・適用する | H28: 設計の妥当性（当局合意・成功率）を検証し、改善する | I28: 革新的なデザインで当局と合意を形成し、開発期間を大幅に短縮する
A29: C05-02 | C29: 患者エビデンス管理★ | D29: — | E29: 自然歴データがなく、外部対照を作れない | F29: 開発品ごとに自然歴研究・レジストリを行う | G29: 疾患ごとに標準化された自然歴研究・レジストリを運営し、データ品質を管理する | H29: データの完全性・利用実績を指標で管理し、当局提出に使える品質を維持する | I29: 患者団体・業界と共有するデータ基盤を主導し、疾患領域のエビデンスを先導する
A30: C05-03 | C30: 患者特定・組入れ★ | D30: — | E30: 施設任せで、組入れが遅れる | F30: 試験ごとに組入れ計画・施設網をつくる | G30: 遺伝子検査・紹介ネットワーク・負担軽減策を組み合わせた、標準的な組入れ戦略を持つ | H30: 組入れ速度・脱落率を指標で管理し、予測する | I30: 患者コミュニティと一体となり、世界規模で迅速に組み入れる
A31: C05-04 | C31: 臨床試験運営 | D31: レベル3（GCP） | E31: CRO任せで、スポンサーとしての監督が弱い | F31: 試験ごとに運営計画を立て、監督する | G31: 標準的な立ち上げ・リスクに基づくモニタリング・TMF管理を運用する | H31: 立ち上げ期間・品質指標を管理する | I31: 分散型試験などの先進的な運営で、患者と施設の負担を最小にする
A32: C05-05 | C32: 臨床データマネジメント・統計解析 | D32: レベル3（GCP） | E32: データ品質の問題で、データベース固定が遅れる | F32: 試験ごとにデータマネジメント・解析を行う | G32: CDISC標準と、標準的なデータマネジメント・解析・文書作成の手順を持つ | H32: データベース固定までの期間・データ品質を指標で管理する | I32: 自動化とデータの再利用で、解析・報告を大幅に短縮する
A33: C05-06 | C33: 治験薬供給管理 | D33: レベル3（GCP・GMP） | E33: 欠品・廃棄が頻発する | F33: 試験ごとに供給計画を立てる | G33: IRTを用いた標準的な需給・割付・供給管理を行う | H33: 廃棄率・欠品を指標で管理する | I33: 需要予測に基づく動的な供給で、少量・多国間の供給を最適化する
A34: C06-01 | B34: 薬事 | C34: 薬事戦略・当局対応 | D34: — | E34: 当局対応が場当たり的で、合意が得られない | F34: 開発品ごとに規制戦略を立て、会議に臨む | G34: 標準的な規制戦略の立案・会議準備と、指定制度の体系的な活用 | H34: 当局との合意事項の達成率・審査期間を指標で管理する | I34: 規制動向を先取りし、新しい制度・枠組みの活用を先導する
A35: C06-02 | C35: 申請資料作成・管理 | D35: レベル3（法令） | E35: 申請資料の作成が遅れ、技術的な不備がある | F35: 申請ごとに作成・提出する | G35: 標準的なテンプレート・パブリッシング・提出管理を持つ | H35: 作成期間・照会件数を指標で管理する | I35: 構造化データにより、申請資料を自動生成する
A36: C06-03 | C36: ラベリング管理 | D36: レベル3（法令） | E36: 改訂の反映漏れがある | F36: 製品ごとに表示を管理する | G36: 標準的な作成・改訂・関連資材への反映の手順を持つ | H36: 改訂の期間・整合性を指標で管理する | I36: 構造化された表示情報で、改訂を迅速かつ一貫して反映する
A37: C06-04 | C37: 市販後薬事コンプライアンス | D37: レベル3（法令） | E37: 期限の遅れ・報告漏れがある | F37: 製品ごとに要求事項・期限を管理する | G37: 全製品の市販後要求・変更・報告を一元管理する | H37: 期限の遵守率を指標で管理する | I37: 規制の変化を先取りし、負担を最小にした運用を行う
A38: C07-01 | B38: 製造 | C38: 生産計画・製造実行管理 | D38: レベル3（GMP） | E38: 紙の記録と場当たり的な計画 | F38: 製造所ごとに計画・記録を管理する | G38: 標準的な計画プロセスと電子バッチ記録を持つ | H38: 計画の遵守率・記録の不備率を指標で管理する | I38: 需要と連動した動的な計画と、記録照査の自動化を行う
A39: C07-02 | C39: 原薬製造 | D39: レベル3（GMP） | E39: ロット間のばらつきが大きく、失敗ロットが多い | F39: 製造所ごとに安定して製造できる | G39: 標準化された製造と工程データの監視で、一貫した品質を保つ | H39: 収率・成功率を統計的に管理する | I39: リアルタイムの工程制御など先進的な製造技術で、業界をリードする
A40: C07-03 | C40: 製剤化・無菌充填・包装 | D40: レベル3（GMP） | E40: 無菌性の問題・不良が発生する | F40: 製造所ごとに管理する | G40: 標準化された無菌操作と、シリアル化を含む包装を行う | H40: 不良率・無菌性の指標を管理する | I40: 自動化・閉鎖系の技術で、無菌保証の水準を高める
A41: C07-04 | C41: 設備・環境管理 | D41: レベル3（GMP） | E41: 故障への対応が中心 | F41: 設備ごとに保全計画を持つ | G41: 標準的な予防保全・環境モニタリングを行う | H41: 稼働率・環境の傾向を指標で管理する | I41: 予知保全・リアルタイム監視を行う
...

Sheet VS×ケイパビリティ関係
A1: VS×ケイパビリティ関係（正本：VS L4 × ケイパビリティL3）
A2: 1行1関係。区分は「主」（そのL4の中核）か「支援」（下支え）。マトリクスはこのシートから数式で集計する。関係の追加・変更はこのシートで行う。灰色の列は数式（編集しない）。
A3: VS L4 ID | B3: VS L4 | C3: ケイパビリティL3 ID | D3: ケイパビリティL3 | E3: 区分 | F3: VS L3 ID | G3: ケイパビリティL2 ID
A4: 01-01-01 | B4: ★患者団体・専門医との連携による疾患理解 | C4: C10-01-01 | D4: =IFERROR(INDEX(ケイパビリティマップ!$E:$E,MATCH(C4,ケイパビリティマップ!$A:$A,0)),"（IDなし）") | E4: 主 | F4: =LEFT(A4,5) | G4: =LEFT(C4,6)
A5: 01-01-01 | B5: ★患者団体・専門医との連携による疾患理解 | C5: C10-01-02 | D5: =IFERROR(INDEX(ケイパビリティマップ!$E:$E,MATCH(C5,ケイパビリティマップ!$A:$A,0)),"（IDなし）") | E5: 支援 | F5: =LEFT(A5,5) | G5: =LEFT(C5,6)
A6: 01-01-01 | B6: ★患者団体・専門医との連携による疾患理解 | C6: C02-01-01 | D6: =IFERROR(INDEX(ケイパビリティマップ!$E:$E,MATCH(C6,ケイパビリティマップ!$A:$A,0)),"（IDなし）") | E6: 支援 | F6: =LEFT(A6,5) | G6: =LEFT(C6,6)
A7: 01-01-02 | B7: 疾患生物学の調査・標的仮説の立案 | C7: C02-01-01 | D7: =IFERROR(INDEX(ケイパビリティマップ!$E:$E,MATCH(C7,ケイパビリティマップ!$A:$A,0)),"（IDなし）") | E7: 主 | F7: =LEFT(A7,5) | G7: =LEFT(C7,6)
A8: 01-01-03 | B8: ★遺伝学的原因の解析（単一遺伝子疾患等、患者ゲノム・検体データ） | C8: C02-01-01 | D8: =IFERROR(INDEX(ケイパビリティマップ!$E:$E,MATCH(C8,ケイパビリティマップ!$A:$A,0)),"（IDなし）") | E8: 主 | F8: =LEFT(A8,5) | G8: =LEFT(C8,6)
A9: 01-01-03 | B9: ★遺伝学的原因の解析（単一遺伝子疾患等、患者ゲノム・検体データ） | C9: C13-01-03 | D9: =IFERROR(INDEX(ケイパビリティマップ!$E:$E,MATCH(C9,ケイパビリティマップ!$A:$A,0)),"（IDなし）") | E9: 支援 | F9: =LEFT(A9,5) | G9: =LEFT(C9,6)
A10: 01-01-04 | B10: 標的の機能検証（遺伝子ノックダウン、in vitro／in vivo） | C10: C02-01-02 | D10: =IFERROR(INDEX(ケイパビリティマップ!$E:$E,MATCH(C10,ケイパビリティマップ!$A:$A,0)),"（IDなし）") | E10: 主 | F10: =LEFT(A10,5) | G10: =LEFT(C10,6)
A11: 01-01-05 | B11: 抗体モダリティ適合性評価（細胞外・膜タンパクか、組織発現分布） | C11: C02-01-03 | D11: =IFERROR(INDEX(ケイパビリティマップ!$E:$E,MATCH(C11,ケイパビリティマップ!$A:$A,0)),"（IDなし）") | E11: 主 | F11: =LEFT(A11,5) | G11: =LEFT(C11,6)
A12: 01-01-06 | B12: 標的選定（競合・知財〔FTO〕調査を含む） | C12: C02-01-02 | D12: =IFERROR(INDEX(ケイパビリティマップ!$E:$E,MATCH(C12,ケイパビリティマップ!$A:$A,0)),"（IDなし）") | E12: 主 | F12: =LEFT(A12,5) | G12: =LEFT(C12,6)
A13: 01-01-06 | B13: 標的選定（競合・知財〔FTO〕調査を含む） | C13: C01-02-01 | D13: =IFERROR(INDEX(ケイパビリティマップ!$E:$E,MATCH(C13,ケイパビリティマップ!$A:$A,0)),"（IDなし）") | E13: 支援 | F13: =LEFT(A13,5) | G13: =LEFT(C13,6)
A14: 01-01-06 | B14: 標的選定（競合・知財〔FTO〕調査を含む） | C14: C01-01-03 | D14: =IFERROR(INDEX(ケイパビリティマップ!$E:$E,MATCH(C14,ケイパビリティマップ!$A:$A,0)),"（IDなし）") | E14: 支援 | F14: =LEFT(A14,5) | G14: =LEFT(C14,6)
A15: 01-02-01 | B15: 抗原・評価系（アッセイ）の準備 | C15: C02-02-01 | D15: =IFERROR(INDEX(ケイパビリティマップ!$E:$E,MATCH(C15,ケイパビリティマップ!$A:$A,0)),"（IDなし）") | E15: 主 | F15: =LEFT(A15,5) | G15: =LEFT(C15,6)
... A294: 09-03-05 | B294: ★Medicare価格交渉の除外要件の管理（希少疾病のみの適応の場合、IRA） | C294: C11-02-03 | D294: =IFERROR(INDEX(ケイパビリティマップ!$E:$E,MATCH(C294,ケイパビリティマップ!$A:$A,0)),"（IDなし）") | E294: 主 | F294: =LEFT(A294,5) | G294: =LEFT(C294,6)
D295: =IF(C295="","",IFERROR(INDEX(ケイパビリティマップ!$E:$E,MATCH(C295,ケイパビリティマップ!$A:$A,0)),"（IDなし）")) | F295: =IF(A295="","",LEFT(A295,5)) | G295: =IF(C295="","",LEFT(C295,6))
D296: =IF(C296="","",IFERROR(INDEX(ケイパビリティマップ!$E:$E,MATCH(C296,ケイパビリティマップ!$A:$A,0)),"（IDなし）")) | F296: =IF(A296="","",LEFT(A296,5)) | G296: =IF(C296="","",LEFT(C296,6))
D297: =IF(C297="","",IFERROR(INDEX(ケイパビリティマップ!$E:$E,MATCH(C297,ケイパビリティマップ!$A:$A,0)),"（IDなし）")) | F297: =IF(A297="","",LEFT(A297,5)) | G297: =IF(C297="","",LEFT(C297,6))
D298: =IF(C298="","",IFERROR(INDEX(ケイパビリティマップ!$E:$E,MATCH(C298,ケイパビリティマップ!$A:$A,0)),"（IDなし）")) | F298: =IF(A298="","",LEFT(A298,5)) | G298: =IF(C298="","",LEFT(C298,6))
D299: =IF(C299="","",IFERROR(INDEX(ケイパビリティマップ!$E:$E,MATCH(C299,ケイパビリティマップ!$A:$A,0)),"（IDなし）")) | F299: =IF(A299="","",LEFT(A299,5)) | G299: =IF(C299="","",LEFT(C299,6))
D300: =IF(C300="","",IFERROR(INDEX(ケイパビリティマップ!$E:$E,MATCH(C300,ケイパビリティマップ!$A:$A,0)),"（IDなし）")) | F300: =IF(A300="","",LEFT(A300,5)) | G300: =IF(C300="","",LEFT(C300,6))
D301: =IF(C301="","",IFERROR(INDEX(ケイパビリティマップ!$E:$E,MATCH(C301,ケイパビリティマップ!$A:$A,0)),"（IDなし）")) | F301: =IF(A301="","",LEFT(A301,5)) | G301: =IF(C301="","",LEFT(C301,6))
D302: =IF(C302="","",IFERROR(INDEX(ケイパビリティマップ!$E:$E,MATCH(C302,ケイパビリティマップ!$A:$A,0)),"（IDなし）")) | F302: =IF(A302="","",LEFT(A302,5)) | G302: =IF(C302="","",LEFT(C302,6))
D303: =IF(C303="","",IFERROR(INDEX(ケイパビリティマップ!$E:$E,MATCH(C303,ケイパビリティマップ!$A:$A,0)),"（IDなし）")) | F303: =IF(A303="","",LEFT(A303,5)) | G303: =IF(C303="","",LEFT(C303,6))
D304: =IF(C304="","",IFERROR(INDEX(ケイパビリティマップ!$E:$E,MATCH(C304,ケイパビリティマップ!$A:$A,0)),"（IDなし）")) | F304: =IF(A304="","",LEFT(A304,5)) | G304: =IF(C304="","",LEFT(C304,6))
D305: =IF(C305="","",IFERROR(INDEX(ケイパビリティマップ!$E:$E,MATCH(C305,ケイパビリティマップ!$A:$A,0)),"（IDなし）")) | F305: =IF(A305="","",LEFT(A305,5)) | G305: =IF(C305="","",LEFT(C305,6))
D306: =IF(C306="","",IFERROR(INDEX(ケイパビリティマップ!$E:$E,MATCH(C306,ケイパビリティマップ!$A:$A,0)),"（IDなし）")) | F306: =IF(A306="","",LEFT(A306,5)) | G306: =IF(C306="","",LEFT(C306,6))
... D494: =IF(C494="","",IFERROR(INDEX(ケイパビリティマップ!$E:$E,MATCH(C494,ケイパビリティマップ!$A:$A,0)),"（IDなし）")) | F494: =IF(A494="","",LEFT(A494,5)) | G494: =IF(C494="","",LEFT(C494,6))

Sheet VS×ケイパビリティ
A1: バリューストリーム×ケイパビリティマップ（行：バリューストリームL3 × 列：ケイパビリティL2）
A2: ●＝主（配下のL4×L3の関係に「主」が1つ以上） ○＝支援のみ 空欄＝関係なし。各セルは「VS×ケイパビリティ関係」シートから数式で集計（直接入力しない）。
A4: VS L2 | B4: L3 ID | C4: VS L3 | D4: C01 戦略・ガバナンス | G4: C02 研究（創薬） | L4: C03 非臨床・臨床薬理 | P4: C04 CMC開発 | U4: C05 臨床開発 | AA4: C06 薬事 | AE4: C07 製造 | AI4: C08 品質 | AM4: C09 ファーマコビジランス（安全性） | AO4: C10 メディカル・患者エンゲージメント | AS4: C11 市場アクセス・商業 | AW4: C12 サプライチェーン | BB4: C13 共通基盤 | BE4: ●の数 | BF4: ○の数
D5: C01-01 | E5: C01-02 | F5: C01-03 | G5: C02-01 | H5: C02-02 | I5: C02-03 | J5: C02-04 | K5: C02-05 | L5: C03-01 | M5: C03-02 | N5: C03-03 | O5: C03-04 | P5: C04-01 | Q5: C04-02 | R5: C04-03 | S5: C04-04 | T5: C04-05 | U5: C05-01 | V5: C05-02 | W5: C05-03 | X5: C05-04 | Y5: C05-05 | Z5: C05-06 | AA5: C06-01 | AB5: C06-02 | AC5: C06-03 | AD5: C06-04 | AE5: C07-01 | AF5: C07-02 | AG5: C07-03 | AH5: C07-04 | AI5: C08-01 | AJ5: C08-02 | AK5: C08-03 | AL5: C08-04 | AM5: C09-01 | AN5: C09-02 | AO5: C10-01 | AP5: C10-02 | AQ5: C10-03 | AR5: C10-04 | AS5: C11-01 | AT5: C11-02 | AU5: C11-03 | AV5: C11-04 | AW5: C12-01 | AX5: C12-02 | AY5: C12-03 | AZ5: C12-04 | BA5: C12-05 | BB5: C13-01 | BC5: C13-02 | BD5: C13-03
D6: 研究開発ポートフォリオ管理 | E6: 知財・独占期間管理 | F6: 外部パートナー管理 | G6: 疾患・標的研究★ | H6: 抗体創出 | I6: 抗体エンジニアリング | J6: 疾患モデル・薬効評価 | K6: 開発適性・免疫原性リスク評価 | L6: 非臨床薬理評価 | M6: 非臨床安全性評価 | N6: バイオアナリシス | O6: 臨床薬理・ファーマコメトリクス | P6: 細胞株開発・セルバンク管理 | Q6: 原薬プロセス開発 | R6: 製剤・デバイス開発 | S6: 分析法開発・品質特性評価 | T6: 技術移転・製造規模管理 | U6: 臨床開発戦略・試験デザイン | V6: 患者エビデンス管理★ | W6: 患者特定・組入れ★ | X6: 臨床試験運営 | Y6: 臨床データマネジメント・統計解析 | Z6: 治験薬供給管理 | AA6: 薬事戦略・当局対応 | AB6: 申請資料作成・管理 | AC6: ラベリング管理 | AD6: 市販後薬事コンプライアンス | AE6: 生産計画・製造実行管理 | AF6: 原薬製造 | AG6: 製剤化・無菌充填・包装 | AH6: 設備・環境管理 | AI6: 品質管理（試験・安定性） | AJ6: 品質保証（出荷判定・逸脱・変更） | AK6: バリデーション管理 | AL6: 品質システム・監査管理 | AM6: 有害事象管理 | AN6: 安全性シグナル・リスク管理 | AO6: 患者団体・専門医連携★ | AP6: メディカルアフェアーズ | AQ6: 疾患啓発・診断支援★ | AR6: 患者支援サービス★ | AS6: 価格・保険者契約管理 | AT6: 政府価格報告・政策対応 | AU6: 販促・商業コンプライアンス | AV6: 営業・顧客管理 | AW6: 需給計画 | AX6: 流通ネットワーク管理★ | AY6: コールドチェーン物流 | AZ6: トレーサビリティ | BA6: 供給継続・回収管理 | BB6: 情報・データ管理 | BC6: GxP文書・記録管理 | BD6: GxP教育・資格管理
A7: 01 創薬研究 | B7: 01-01 | C7: 標的探索・検証 | D7: =IF(COUNTIFS('VS×ケイパビリティ関係'!$F$4:$F$494,$B7,'VS×ケイパビリティ関係'!$G$4:$G$494,D$5,'VS×ケイパビリティ関係'!$E$4:$E$494,"主")>0,"●",IF(COUNTIFS('VS×ケイパビリティ関係'!$F$4:$F$494,$B7,'VS×ケイパビリティ関係'!$G$4:$G$494,D$5,'VS×ケイパビリティ関係'!$E$4:$E$494,"支援")>0,"○","")) | E7: =IF(COUNTIFS('VS×ケイパビリティ関係'!$F$4:$F$494,$B7,'VS×ケイパビリティ関係'!$G$4:$G$494,E$5,'VS×ケイパビリティ関係'!$E$4:$E$494,"主")>0,"●",IF(COUNTIFS('VS×ケイパビリティ関係'!$F$4:$F$494,$B7,'VS×ケイパビリティ関係'!$G$4:$G$494,E$5,'VS×ケイパビリティ関係'!$E$4:$E$494,"支援")>0,"○","")) | F7: =IF(COUNTIFS('VS×ケイパビリティ関係'!$F$4:$F$494,$B7,'VS×ケイパビリティ関係'!$G$4:$G$494,F$5,'VS×ケイパビリティ関係'!$E$4:$E$494,"主")>0,"●",IF(COUNTIFS('VS×ケイパビリティ関係'!$F$4:$F$494,$B7,'VS×ケイパビリティ関係'!$G$4:$G$494,F$5,'VS×ケイパビリティ関係'!$E$4:$E$494,"支援")>0,"○","")) | G7: =IF(COUNTIFS('VS×ケイパビリティ関係'!$F$4:$F$494,$B7,'VS×ケイパビリティ関係'!$G$4:$G$494,G$5,'VS×ケイパビリティ関係'!$E$4:$E$494,"主")>0,"●",IF(COUNTIFS('VS×ケイパビリティ関係'!$F$4:$F$494,$B7,'VS×ケイパビリティ関係'!$G$4:$G$494,G$5,'VS×ケイパビリティ関係'!$E$4:$E$494,"支援")>0,"○","")) | H7: =IF(COUNTIFS('VS×ケイパビリティ関係'!$F$4:$F$494,$B7,'VS×ケイパビリティ関係'!$G$4:$G$494,H$5,'VS×ケイパビリティ関係'!$E$4:$E$494,"主")>0,"●",IF(COUNTIFS('VS×ケイパビリティ関係'!$F$4:$F$494,$B7,'VS×ケイパビリティ関係'!$G$4:$G$494,H$5,'VS×ケイパビリティ関係'!$E$4:$E$494,"支援")>0,"○","")) | I7: =IF(COUNTIFS('VS×ケイパビリティ関係'!$F$4:$F$494,$B7,'VS×ケイパビリティ関係'!$G$4:$G$494,I$5,'VS×ケイパビリティ関係'!$E$4:$E$494,"主")>0,"●",IF(COUNTIFS('VS×ケイパビリティ関係'!$F$4:$F$494,$B7,'VS×ケイパビリティ関係'!$G$4:$G$494,I$5,'VS×ケイパビリティ関係'!$E$4:$E$494,"支援")>0,"○","")) | J7: =IF(COUNTIFS('VS×ケイパビリティ関係'!$F$4:$F$494,$B7,'VS×ケイパビリティ関係'!$G$4:$G$494,J$5,'VS×ケイパビリティ関係'!$E$4:$E$494,"主")>0,"●",IF(COUNTIFS('VS×ケイパビリティ関係'!$F$4:$F$494,$B7,'VS×ケイパビリティ関係'!$G$4:$G$494,J$5,'VS×ケイパビリティ関係'!$E$4:$E$494,"支援")>0,"○","")) | K7: =IF(COUNTIFS('VS×ケイパビリティ関係'!$F$4:$F$494,$B7,'VS×ケイパビリティ関係'!$G$4:$G$494,K$5,'VS×ケイパビリティ関係'!$E$4:$E$494,"主")>0,"●",IF(COUNTIFS('VS×ケイパビリティ関係'!$F$4:$F$494,$B7,'VS×ケイパビリティ関係'!$G$4:$G$494,K$5,'VS×ケイパビリティ関係'!$E$4:$E$494,"支援")>0,"○","")) | ... BD7: =IF(COUNTIFS('VS×ケイパビリティ関係'!$F$4:$F$494,$B7,'VS×ケイパビリティ関係'!$G$4:$G$494,BD$5,'VS×ケイパビリティ関係'!$E$4:$E$494,"主")>0,"●",IF(COUNTIFS('VS×ケイパビリティ関係'!$F$4:$F$494,$B7,'VS×ケイパビリティ関係'!$G$4:$G$494,BD$5,'VS×ケイパビリティ関係'!$E$4:$E$494,"支援")>0,"○","")) | BE7: =COUNTIF(D7:BD7,"●") | BF7: =COUNTIF(D7:BD7,"○")
B8: 01-02 | C8: ヒット・リード創出 | D8: =IF(COUNTIFS('VS×ケイパビリティ関係'!$F$4:$F$494,$B8,'VS×ケイパビリティ関係'!$G$4:$G$494,D$5,'VS×ケイパビリティ関係'!$E$4:$E$494,"主")>0,"●",IF(COUNTIFS('VS×ケイパビリティ関係'!$F$4:$F$494,$B8,'VS×ケイパビリティ関係'!$G$4:$G$494,D$5,'VS×ケイパビリティ関係'!$E$4:$E$494,"支援")>0,"○","")) | E8: =IF(COUNTIFS('VS×ケイパビリティ関係'!$F$4:$F$494,$B8,'VS×ケイパビリティ関係'!$G$4:$G$494,E$5,'VS×ケイパビリティ関係'!$E$4:$E$494,"主")>0,"●",IF(COUNTIFS('VS×ケイパビリティ関係'!$F$4:$F$494,$B8,'VS×ケイパビリティ関係'!$G$4:$G$494,E$5,'VS×ケイパビリティ関係'!$E$4:$E$494,"支援")>0,"○","")) | F8: =IF(COUNTIFS('VS×ケイパビリティ関係'!$F$4:$F$494,$B8,'VS×ケイパビリティ関係'!$G$4:$G$494,F$5,'VS×ケイパビリティ関係'!$E$4:$E$494,"主")>0,"●",IF(COUNTIFS('VS×ケイパビリティ関係'!$F$4:$F$494,$B8,'VS×ケイパビリティ関係'!$G$4:$G$494,F$5,'VS×ケイパビリティ関係'!$E$4:$E$494,"支援")>0,"○","")) | G8: =IF(COUNTIFS('VS×ケイパビリティ関係'!$F$4:$F$494,$B8,'VS×ケイパビリティ関係'!$G$4:$G$494,G$5,'VS×ケイパビリティ関係'!$E$4:$E$494,"主")>0,"●",IF(COUNTIFS('VS×ケイパビリティ関係'!$F$4:$F$494,$B8,'VS×ケイパビリティ関係'!$G$4:$G$494,G$5,'VS×ケイパビリティ関係'!$E$4:$E$494,"支援")>0,"○","")) | H8: =IF(COUNTIFS('VS×ケイパビリティ関係'!$F$4:$F$494,$B8,'VS×ケイパビリティ関係'!$G$4:$G$494,H$5,'VS×ケイパビリティ関係'!$E$4:$E$494,"主")>0,"●",IF(COUNTIFS('VS×ケイパビリティ関係'!$F$4:$F$494,$B8,'VS×ケイパビリティ関係'!$G$4:$G$494,H$5,'VS×ケイパビリティ関係'!$E$4:$E$494,"支援")>0,"○","")) | I8: =IF(COUNTIFS('VS×ケイパビリティ関係'!$F$4:$F$494,$B8,'VS×ケイパビリティ関係'!$G$4:$G$494,I$5,'VS×ケイパビリティ関係'!$E$4:$E$494,"主")>0,"●",IF(COUNTIFS('VS×ケイパビリティ関係'!$F$4:$F$494,$B8,'VS×ケイパビリティ関係'!$G$4:$G$494,I$5,'VS×ケイパビリティ関係'!$E$4:$E$494,"支援")>0,"○","")) | J8: =IF(COUNTIFS('VS×ケイパビリティ関係'!$F$4:$F$494,$B8,'VS×ケイパビリティ関係'!$G$4:$G$494,J$5,'VS×ケイパビリティ関係'!$E$4:$E$494,"主")>0,"●",IF(COUNTIFS('VS×ケイパビリティ関係'!$F$4:$F$494,$B8,'VS×ケイパビリティ関係'!$G$4:$G$494,J$5,'VS×ケイパビリティ関係'!$E$4:$E$494,"支援")>0,"○","")) | K8: =IF(COUNTIFS('VS×ケイパビリティ関係'!$F$4:$F$494,$B8,'VS×ケイパビリティ関係'!$G$4:$G$494,K$5,'VS×ケイパビリティ関係'!$E$4:$E$494,"主")>0,"●",IF(COUNTIFS('VS×ケイパビリティ関係'!$F$4:$F$494,$B8,'VS×ケイパビリティ関係'!$G$4:$G$494,K$5,'VS×ケイパビリティ関係'!$E$4:$E$494,"支援")>0,"○","")) | ... BD8: =IF(COUNTIFS('VS×ケイパビリティ関係'!$F$4:$F$494,$B8,'VS×ケイパビリティ関係'!$G$4:$G$494,BD$5,'VS×ケイパビリティ関係'!$E$4:$E$494,"主")>0,"●",IF(COUNTIFS('VS×ケイパビリティ関係'!$F$4:$F$494,$B8,'VS×ケイパビリティ関係'!$G$4:$G$494,BD$5,'VS×ケイパビリティ関係'!$E$4:$E$494,"支援")>0,"○","")) | BE8: =COUNTIF(D8:BD8,"●") | BF8: =COUNTIF(D8:BD8,"○")
B9: 01-03 | C9: リード最適化 | D9: =IF(COUNTIFS('VS×ケイパビリティ関係'!$F$4:$F$494,$B9,'VS×ケイパビリティ関係'!$G$4:$G$494,D$5,'VS×ケイパビリティ関係'!$E$4:$E$494,"主")>0,"●",IF(COUNTIFS('VS×ケイパビリティ関係'!$F$4:$F$494,$B9,'VS×ケイパビリティ関係'!$G$4:$G$494,D$5,'VS×ケイパビリティ関係'!$E$4:$E$494,"支援")>0,"○","")) | E9: =IF(COUNTIFS('VS×ケイパビリティ関係'!$F$4:$F$494,$B9,'VS×ケイパビリティ関係'!$G$4:$G$494,E$5,'VS×ケイパビリティ関係'!$E$4:$E$494,"主")>0,"●",IF(COUNTIFS('VS×ケイパビリティ関係'!$F$4:$F$494,$B9,'VS×ケイパビリティ関係'!$G$4:$G$494,E$5,'VS×ケイパビリティ関係'!$E$4:$E$494,"支援")>0,"○","")) | F9: =IF(COUNTIFS('VS×ケイパビリティ関係'!$F$4:$F$494,$B9,'VS×ケイパビリティ関係'!$G$4:$G$494,F$5,'VS×ケイパビリティ関係'!$E$4:$E$494,"主")>0,"●",IF(COUNTIFS('VS×ケイパビリティ関係'!$F$4:$F$494,$B9,'VS×ケイパビリティ関係'!$G$4:$G$494,F$5,'VS×ケイパビリティ関係'!$E$4:$E$494,"支援")>0,"○","")) | G9: =IF(COUNTIFS('VS×ケイパビリティ関係'!$F$4:$F$494,$B9,'VS×ケイパビリティ関係'!$G$4:$G$494,G$5,'VS×ケイパビリティ関係'!$E$4:$E$494,"主")>0,"●",IF(COUNTIFS('VS×ケイパビリティ関係'!$F$4:$F$494,$B9,'VS×ケイパビリティ関係'!$G$4:$G$494,G$5,'VS×ケイパビリティ関係'!$E$4:$E$494,"支援")>0,"○","")) | H9: =IF(COUNTIFS('VS×ケイパビリティ関係'!$F$4:$F$494,$B9,'VS×ケイパビリティ関係'!$G$4:$G$494,H$5,'VS×ケイパビリティ関係'!$E$4:$E$494,"主")>0,"●",IF(COUNTIFS('VS×ケイパビリティ関係'!$F$4:$F$494,$B9,'VS×ケイパビリティ関係'!$G$4:$G$494,H$5,'VS×ケイパビリティ関係'!$E$4:$E$494,"支援")>0,"○","")) | I9: =IF(COUNTIFS('VS×ケイパビリティ関係'!$F$4:$F$494,$B9,'VS×ケイパビリティ関係'!$G$4:$G$494,I$5,'VS×ケイパビリティ関係'!$E$4:$E$494,"主")>0,"●",IF(COUNTIFS('VS×ケイパビリティ関係'!$F$4:$F$494,$B9,'VS×ケイパビリティ関係'!$G$4:$G$494,I$5,'VS×ケイパビリティ関係'!$E$4:$E$494,"支援")>0,"○","")) | J9: =IF(COUNTIFS('VS×ケイパビリティ関係'!$F$4:$F$494,$B9,'VS×ケイパビリティ関係'!$G$4:$G$494,J$5,'VS×ケイパビリティ関係'!$E$4:$E$494,"主")>0,"●",IF(COUNTIFS('VS×ケイパビリティ関係'!$F$4:$F$494,$B9,'VS×ケイパビリティ関係'!$G$4:$G$494,J$5,'VS×ケイパビリティ関係'!$E$4:$E$494,"支援")>0,"○","")) | K9: =IF(COUNTIFS('VS×ケイパビリティ関係'!$F$4:$F$494,$B9,'VS×ケイパビリティ関係'!$G$4:$G$494,K$5,'VS×ケイパビリティ関係'!$E$4:$E$494,"主")>0,"●",IF(COUNTIFS('VS×ケイパビリティ関係'!$F$4:$F$494,$B9,'VS×ケイパビリティ関係'!$G$4:$G$494,K$5,'VS×ケイパビリティ関係'!$E$4:$E$494,"支援")>0,"○","")) | ... BD9: =IF(COUNTIFS('VS×ケイパビリティ関係'!$F$4:$F$494,$B9,'VS×ケイパビリティ関係'!$G$4:$G$494,BD$5,'VS×ケイパビリティ関係'!$E$4:$E$494,"主")>0,"●",IF(COUNTIFS('VS×ケイパビリティ関係'!$F$4:$F$494,$B9,'VS×ケイパビリティ関係'!$G$4:$G$494,BD$5,'VS×ケイパビリティ関係'!$E$4:$E$494,"支援")>0,"○","")) | BE9: =COUNTIF(D9:BD9,"●") | BF9: =COUNTIF(D9:BD9,"○")
B10: 01-04 | C10: 開発候補品選定 | D10: =IF(COUNTIFS('VS×ケイパビリティ関係'!$F$4:$F$494,$B10,'VS×ケイパビリティ関係'!$G$4:$G$494,D$5,'VS×ケイパビリティ関係'!$E$4:$E$494,"主")>0,"●",IF(COUNTIFS('VS×ケイパビリティ関係'!$F$4:$F$494,$B10,'VS×ケイパビリティ関係'!$G$4:$G$494,D$5,'VS×ケイパビリティ関係'!$E$4:$E$494,"支援")>0,"○","")) | E10: =IF(COUNTIFS('VS×ケイパビリティ関係'!$F$4:$F$494,$B10,'VS×ケイパビリティ関係'!$G$4:$G$494,E$5,'VS×ケイパビリティ関係'!$E$4:$E$494,"主")>0,"●",IF(COUNTIFS('VS×ケイパビリティ関係'!$F$4:$F$494,$B10,'VS×ケイパビリティ関係'!$G$4:$G$494,E$5,'VS×ケイパビリティ関係'!$E$4:$E$494,"支援")>0,"○","")) | F10: =IF(COUNTIFS('VS×ケイパビリティ関係'!$F$4:$F$494,$B10,'VS×ケイパビリティ関係'!$G$4:$G$494,F$5,'VS×ケイパビリティ関係'!$E$4:$E$494,"主")>0,"●",IF(COUNTIFS('VS×ケイパビリティ関係'!$F$4:$F$494,$B10,'VS×ケイパビリティ関係'!$G$4:$G$494,F$5,'VS×ケイパビリティ関係'!$E$4:$E$494,"支援")>0,"○","")) | G10: =IF(COUNTIFS('VS×ケイパビリティ関係'!$F$4:$F$494,$B10,'VS×ケイパビリティ関係'!$G$4:$G$494,G$5,'VS×ケイパビリティ関係'!$E$4:$E$494,"主")>0,"●",IF(COUNTIFS('VS×ケイパビリティ関係'!$F$4:$F$494,$B10,'VS×ケイパビリティ関係'!$G$4:$G$494,G$5,'VS×ケイパビリティ関係'!$E$4:$E$494,"支援")>0,"○","")) | H10: =IF(COUNTIFS('VS×ケイパビリティ関係'!$F$4:$F$494,$B10,'VS×ケイパビリティ関係'!$G$4:$G$494,H$5,'VS×ケイパビリティ関係'!$E$4:$E$494,"主")>0,"●",IF(COUNTIFS('VS×ケイパビリティ関係'!$F$4:$F$494,$B10,'VS×ケイパビリティ関係'!$G$4:$G$494,H$5,'VS×ケイパビリティ関係'!$E$4:$E$494,"支援")>0,"○","")) | I10: =IF(COUNTIFS('VS×ケイパビリティ関係'!$F$4:$F$494,$B10,'VS×ケイパビリティ関係'!$G$4:$G$494,I$5,'VS×ケイパビリティ関係'!$E$4:$E$494,"主")>0,"●",IF(COUNTIFS('VS×ケイパビリティ関係'!$F$4:$F$494,$B10,'VS×ケイパビリティ関係'!$G$4:$G$494,I$5,'VS×ケイパビリティ関係'!$E$4:$E$494,"支援")>0,"○","")) | J10: =IF(COUNTIFS('VS×ケイパビリティ関係'!$F$4:$F$494,$B10,'VS×ケイパビリティ関係'!$G$4:$G$494,J$5,'VS×ケイパビリティ関係'!$E$4:$E$494,"主")>0,"●",IF(COUNTIFS('VS×ケイパビリティ関係'!$F$4:$F$494,$B10,'VS×ケイパビリティ関係'!$G$4:$G$494,J$5,'VS×ケイパビリティ関係'!$E$4:$E$494,"支援")>0,"○","")) | K10: =IF(COUNTIFS('VS×ケイパビリティ関係'!$F$4:$F$494,$B10,'VS×ケイパビリティ関係'!$G$4:$G$494,K$5,'VS×ケイパビリティ関係'!$E$4:$E$494,"主")>0,"●",IF(COUNTIFS('VS×ケイパビリティ関係'!$F$4:$F$494,$B10,'VS×ケイパビリティ関係'!$G$4:$G$494,K$5,'VS×ケイパビリティ関係'!$E$4:$E$494,"支援")>0,"○","")) | ... BD10: =IF(COUNTIFS('VS×ケイパビリティ関係'!$F$4:$F$494,$B10,'VS×ケイパビリティ関係'!$G$4:$G$494,BD$5,'VS×ケイパビリティ関係'!$E$4:$E$494,"主")>0,"●",IF(COUNTIFS('VS×ケイパビリティ関係'!$F$4:$F$494,$B10,'VS×ケイパビリティ関係'!$G$4:$G$494,BD$5,'VS×ケイパビリティ関係'!$E$4:$E$494,"支援")>0,"○","")) | BE10: =COUNTIF(D10:BD10,"●") | BF10: =COUNTIF(D10:BD10,"○")
A11: 02 非臨床開発 | B11: 02-01 | C11: 非臨床薬理 | D11: =IF(COUNTIFS('VS×ケイパビリティ関係'!$F$4:$F$494,$B11,'VS×ケイパビリティ関係'!$G$4:$G$494,D$5,'VS×ケイパビリティ関係'!$E$4:$E$494,"主")>0,"●",IF(COUNTIFS('VS×ケイパビリティ関係'!$F$4:$F$494,$B11,'VS×ケイパビリティ関係'!$G$4:$G$494,D$5,'VS×ケイパビリティ関係'!$E$4:$E$494,"支援")>0,"○","")) | E11: =IF(COUNTIFS('VS×ケイパビリティ関係'!$F$4:$F$494,$B11,'VS×ケイパビリティ関係'!$G$4:$G$494,E$5,'VS×ケイパビリティ関係'!$E$4:$E$494,"主")>0,"●",IF(COUNTIFS('VS×ケイパビリティ関係'!$F$4:$F$494,$B11,'VS×ケイパビリティ関係'!$G$4:$G$494,E$5,'VS×ケイパビリティ関係'!$E$4:$E$494,"支援")>0,"○","")) | F11: =IF(COUNTIFS('VS×ケイパビリティ関係'!$F$4:$F$494,$B11,'VS×ケイパビリティ関係'!$G$4:$G$494,F$5,'VS×ケイパビリティ関係'!$E$4:$E$494,"主")>0,"●",IF(COUNTIFS('VS×ケイパビリティ関係'!$F$4:$F$494,$B11,'VS×ケイパビリティ関係'!$G$4:$G$494,F$5,'VS×ケイパビリティ関係'!$E$4:$E$494,"支援")>0,"○","")) | G11: =IF(COUNTIFS('VS×ケイパビリティ関係'!$F$4:$F$494,$B11,'VS×ケイパビリティ関係'!$G$4:$G$494,G$5,'VS×ケイパビリティ関係'!$E$4:$E$494,"主")>0,"●",IF(COUNTIFS('VS×ケイパビリティ関係'!$F$4:$F$494,$B11,'VS×ケイパビリティ関係'!$G$4:$G$494,G$5,'VS×ケイパビリティ関係'!$E$4:$E$494,"支援")>0,"○","")) | H11: =IF(COUNTIFS('VS×ケイパビリティ関係'!$F$4:$F$494,$B11,'VS×ケイパビリティ関係'!$G$4:$G$494,H$5,'VS×ケイパビリティ関係'!$E$4:$E$494,"主")>0,"●",IF(COUNTIFS('VS×ケイパビリティ関係'!$F$4:$F$494,$B11,'VS×ケイパビリティ関係'!$G$4:$G$494,H$5,'VS×ケイパビリティ関係'!$E$4:$E$494,"支援")>0,"○","")) | I11: =IF(COUNTIFS('VS×ケイパビリティ関係'!$F$4:$F$494,$B11,'VS×ケイパビリティ関係'!$G$4:$G$494,I$5,'VS×ケイパビリティ関係'!$E$4:$E$494,"主")>0,"●",IF(COUNTIFS('VS×ケイパビリティ関係'!$F$4:$F$494,$B11,'VS×ケイパビリティ関係'!$G$4:$G$494,I$5,'VS×ケイパビリティ関係'!$E$4:$E$494,"支援")>0,"○","")) | J11: =IF(COUNTIFS('VS×ケイパビリティ関係'!$F$4:$F$494,$B11,'VS×ケイパビリティ関係'!$G$4:$G$494,J$5,'VS×ケイパビリティ関係'!$E$4:$E$494,"主")>0,"●",IF(COUNTIFS('VS×ケイパビリティ関係'!$F$4:$F$494,$B11,'VS×ケイパビリティ関係'!$G$4:$G$494,J$5,'VS×ケイパビリティ関係'!$E$4:$E$494,"支援")>0,"○","")) | K11: =IF(COUNTIFS('VS×ケイパビリティ関係'!$F$4:$F$494,$B11,'VS×ケイパビリティ関係'!$G$4:$G$494,K$5,'VS×ケイパビリティ関係'!$E$4:$E$494,"主")>0,"●",IF(COUNTIFS('VS×ケイパビリティ関係'!$F$4:$F$494,$B11,'VS×ケイパビリティ関係'!$G$4:$G$494,K$5,'VS×ケイパビリティ関係'!$E$4:$E$494,"支援")>0,"○","")) | ... BD11: =IF(COUNTIFS('VS×ケイパビリティ関係'!$F$4:$F$494,$B11,'VS×ケイパビリティ関係'!$G$4:$G$494,BD$5,'VS×ケイパビリティ関係'!$E$4:$E$494,"主")>0,"●",IF(COUNTIFS('VS×ケイパビリティ関係'!$F$4:$F$494,$B11,'VS×ケイパビリティ関係'!$G$4:$G$494,BD$5,'VS×ケイパビリティ関係'!$E$4:$E$494,"支援")>0,"○","")) | BE11: =COUNTIF(D11:BD11,"●") | BF11: =COUNTIF(D11:BD11,"○")
B12: 02-02 | C12: 薬物動態・免疫原性評価 | D12: =IF(COUNTIFS('VS×ケイパビリティ関係'!$F$4:$F$494,$B12,'VS×ケイパビリティ関係'!$G$4:$G$494,D$5,'VS×ケイパビリティ関係'!$E$4:$E$494,"主")>0,"●",IF(COUNTIFS('VS×ケイパビリティ関係'!$F$4:$F$494,$B12,'VS×ケイパビリティ関係'!$G$4:$G$494,D$5,'VS×ケイパビリティ関係'!$E$4:$E$494,"支援")>0,"○","")) | E12: =IF(COUNTIFS('VS×ケイパビリティ関係'!$F$4:$F$494,$B12,'VS×ケイパビリティ関係'!$G$4:$G$494,E$5,'VS×ケイパビリティ関係'!$E$4:$E$494,"主")>0,"●",IF(COUNTIFS('VS×ケイパビリティ関係'!$F$4:$F$494,$B12,'VS×ケイパビリティ関係'!$G$4:$G$494,E$5,'VS×ケイパビリティ関係'!$E$4:$E$494,"支援")>0,"○","")) | F12: =IF(COUNTIFS('VS×ケイパビリティ関係'!$F$4:$F$494,$B12,'VS×ケイパビリティ関係'!$G$4:$G$494,F$5,'VS×ケイパビリティ関係'!$E$4:$E$494,"主")>0,"●",IF(COUNTIFS('VS×ケイパビリティ関係'!$F$4:$F$494,$B12,'VS×ケイパビリティ関係'!$G$4:$G$494,F$5,'VS×ケイパビリティ関係'!$E$4:$E$494,"支援")>0,"○","")) | G12: =IF(COUNTIFS('VS×ケイパビリティ関係'!$F$4:$F$494,$B12,'VS×ケイパビリティ関係'!$G$4:$G$494,G$5,'VS×ケイパビリティ関係'!$E$4:$E$494,"主")>0,"●",IF(COUNTIFS('VS×ケイパビリティ関係'!$F$4:$F$494,$B12,'VS×ケイパビリティ関係'!$G$4:$G$494,G$5,'VS×ケイパビリティ関係'!$E$4:$E$494,"支援")>0,"○","")) | H12: =IF(COUNTIFS('VS×ケイパビリティ関係'!$F$4:$F$494,$B12,'VS×ケイパビリティ関係'!$G$4:$G$494,H$5,'VS×ケイパビリティ関係'!$E$4:$E$494,"主")>0,"●",IF(COUNTIFS('VS×ケイパビリティ関係'!$F$4:$F$494,$B12,'VS×ケイパビリティ関係'!$G$4:$G$494,H$5,'VS×ケイパビリティ関係'!$E$4:$E$494,"支援")>0,"○","")) | I12: =IF(COUNTIFS('VS×ケイパビリティ関係'!$F$4:$F$494,$B12,'VS×ケイパビリティ関係'!$G$4:$G$494,I$5,'VS×ケイパビリティ関係'!$E$4:$E$494,"主")>0,"●",IF(COUNTIFS('VS×ケイパビリティ関係'!$F$4:$F$494,$B12,'VS×ケイパビリティ関係'!$G$4:$G$494,I$5,'VS×ケイパビリティ関係'!$E$4:$E$494,"支援")>0,"○","")) | J12: =IF(COUNTIFS('VS×ケイパビリティ関係'!$F$4:$F$494,$B12,'VS×ケイパビリティ関係'!$G$4:$G$494,J$5,'VS×ケイパビリティ関係'!$E$4:$E$494,"主")>0,"●",IF(COUNTIFS('VS×ケイパビリティ関係'!$F$4:$F$494,$B12,'VS×ケイパビリティ関係'!$G$4:$G$494,J$5,'VS×ケイパビリティ関係'!$E$4:$E$494,"支援")>0,"○","")) | K12: =IF(COUNTIFS('VS×ケイパビリティ関係'!$F$4:$F$494,$B12,'VS×ケイパビリティ関係'!$G$4:$G$494,K$5,'VS×ケイパビリティ関係'!$E$4:$E$494,"主")>0,"●",IF(COUNTIFS('VS×ケイパビリティ関係'!$F$4:$F$494,$B12,'VS×ケイパビリティ関係'!$G$4:$G$494,K$5,'VS×ケイパビリティ関係'!$E$4:$E$494,"支援")>0,"○","")) | ... BD12: =IF(COUNTIFS('VS×ケイパビリティ関係'!$F$4:$F$494,$B12,'VS×ケイパビリティ関係'!$G$4:$G$494,BD$5,'VS×ケイパビリティ関係'!$E$4:$E$494,"主")>0,"●",IF(COUNTIFS('VS×ケイパビリティ関係'!$F$4:$F$494,$B12,'VS×ケイパビリティ関係'!$G$4:$G$494,BD$5,'VS×ケイパビリティ関係'!$E$4:$E$494,"支援")>0,"○","")) | BE12: =COUNTIF(D12:BD12,"●") | BF12: =COUNTIF(D12:BD12,"○")
B13: 02-03 | C13: 安全性評価 | D13: =IF(COUNTIFS('VS×ケイパビリティ関係'!$F$4:$F$494,$B13,'VS×ケイパビリティ関係'!$G$4:$G$494,D$5,'VS×ケイパビリティ関係'!$E$4:$E$494,"主")>0,"●",IF(COUNTIFS('VS×ケイパビリティ関係'!$F$4:$F$494,$B13,'VS×ケイパビリティ関係'!$G$4:$G$494,D$5,'VS×ケイパビリティ関係'!$E$4:$E$494,"支援")>0,"○","")) | E13: =IF(COUNTIFS('VS×ケイパビリティ関係'!$F$4:$F$494,$B13,'VS×ケイパビリティ関係'!$G$4:$G$494,E$5,'VS×ケイパビリティ関係'!$E$4:$E$494,"主")>0,"●",IF(COUNTIFS('VS×ケイパビリティ関係'!$F$4:$F$494,$B13,'VS×ケイパビリティ関係'!$G$4:$G$494,E$5,'VS×ケイパビリティ関係'!$E$4:$E$494,"支援")>0,"○","")) | F13: =IF(COUNTIFS('VS×ケイパビリティ関係'!$F$4:$F$494,$B13,'VS×ケイパビリティ関係'!$G$4:$G$494,F$5,'VS×ケイパビリティ関係'!$E$4:$E$494,"主")>0,"●",IF(COUNTIFS('VS×ケイパビリティ関係'!$F$4:$F$494,$B13,'VS×ケイパビリティ関係'!$G$4:$G$494,F$5,'VS×ケイパビリティ関係'!$E$4:$E$494,"支援")>0,"○","")) | G13: =IF(COUNTIFS('VS×ケイパビリティ関係'!$F$4:$F$494,$B13,'VS×ケイパビリティ関係'!$G$4:$G$494,G$5,'VS×ケイパビリティ関係'!$E$4:$E$494,"主")>0,"●",IF(COUNTIFS('VS×ケイパビリティ関係'!$F$4:$F$494,$B13,'VS×ケイパビリティ関係'!$G$4:$G$494,G$5,'VS×ケイパビリティ関係'!$E$4:$E$494,"支援")>0,"○","")) | H13: =IF(COUNTIFS('VS×ケイパビリティ関係'!$F$4:$F$494,$B13,'VS×ケイパビリティ関係'!$G$4:$G$494,H$5,'VS×ケイパビリティ関係'!$E$4:$E$494,"主")>0,"●",IF(COUNTIFS('VS×ケイパビリティ関係'!$F$4:$F$494,$B13,'VS×ケイパビリティ関係'!$G$4:$G$494,H$5,'VS×ケイパビリティ関係'!$E$4:$E$494,"支援")>0,"○","")) | I13: =IF(COUNTIFS('VS×ケイパビリティ関係'!$F$4:$F$494,$B13,'VS×ケイパビリティ関係'!$G$4:$G$494,I$5,'VS×ケイパビリティ関係'!$E$4:$E$494,"主")>0,"●",IF(COUNTIFS('VS×ケイパビリティ関係'!$F$4:$F$494,$B13,'VS×ケイパビリティ関係'!$G$4:$G$494,I$5,'VS×ケイパビリティ関係'!$E$4:$E$494,"支援")>0,"○","")) | J13: =IF(COUNTIFS('VS×ケイパビリティ関係'!$F$4:$F$494,$B13,'VS×ケイパビリティ関係'!$G$4:$G$494,J$5,'VS×ケイパビリティ関係'!$E$4:$E$494,"主")>0,"●",IF(COUNTIFS('VS×ケイパビリティ関係'!$F$4:$F$494,$B13,'VS×ケイパビリティ関係'!$G$4:$G$494,J$5,'VS×ケイパビリティ関係'!$E$4:$E$494,"支援")>0,"○","")) | K13: =IF(COUNTIFS('VS×ケイパビリティ関係'!$F$4:$F$494,$B13,'VS×ケイパビリティ関係'!$G$4:$G$494,K$5,'VS×ケイパビリティ関係'!$E$4:$E$494,"主")>0,"●",IF(COUNTIFS('VS×ケイパビリティ関係'!$F$4:$F$494,$B13,'VS×ケイパビリティ関係'!$G$4:$G$494,K$5,'VS×ケイパビリティ関係'!$E$4:$E$494,"支援")>0,"○","")) | ... BD13: =IF(COUNTIFS('VS×ケイパビリティ関係'!$F$4:$F$494,$B13,'VS×ケイパビリティ関係'!$G$4:$G$494,BD$5,'VS×ケイパビリティ関係'!$E$4:$E$494,"主")>0,"●",IF(COUNTIFS('VS×ケイパビリティ関係'!$F$4:$F$494,$B13,'VS×ケイパビリティ関係'!$G$4:$G$494,BD$5,'VS×ケイパビリティ関係'!$E$4:$E$494,"支援")>0,"○","")) | BE13: =COUNTIF(D13:BD13,"●") | BF13: =COUNTIF(D13:BD13,"○")
B14: 02-04 | C14: 初回ヒト投与量の設定・IND申請 | D14: =IF(COUNTIFS('VS×ケイパビリティ関係'!$F$4:$F$494,$B14,'VS×ケイパビリティ関係'!$G$4:$G$494,D$5,'VS×ケイパビリティ関係'!$E$4:$E$494,"主")>0,"●",IF(COUNTIFS('VS×ケイパビリティ関係'!$F$4:$F$494,$B14,'VS×ケイパビリティ関係'!$G$4:$G$494,D$5,'VS×ケイパビリティ関係'!$E$4:$E$494,"支援")>0,"○","")) | E14: =IF(COUNTIFS('VS×ケイパビリティ関係'!$F$4:$F$494,$B14,'VS×ケイパビリティ関係'!$G$4:$G$494,E$5,'VS×ケイパビリティ関係'!$E$4:$E$494,"主")>0,"●",IF(COUNTIFS('VS×ケイパビリティ関係'!$F$4:$F$494,$B14,'VS×ケイパビリティ関係'!$G$4:$G$494,E$5,'VS×ケイパビリティ関係'!$E$4:$E$494,"支援")>0,"○","")) | F14: =IF(COUNTIFS('VS×ケイパビリティ関係'!$F$4:$F$494,$B14,'VS×ケイパビリティ関係'!$G$4:$G$494,F$5,'VS×ケイパビリティ関係'!$E$4:$E$494,"主")>0,"●",IF(COUNTIFS('VS×ケイパビリティ関係'!$F$4:$F$494,$B14,'VS×ケイパビリティ関係'!$G$4:$G$494,F$5,'VS×ケイパビリティ関係'!$E$4:$E$494,"支援")>0,"○","")) | G14: =IF(COUNTIFS('VS×ケイパビリティ関係'!$F$4:$F$494,$B14,'VS×ケイパビリティ関係'!$G$4:$G$494,G$5,'VS×ケイパビリティ関係'!$E$4:$E$494,"主")>0,"●",IF(COUNTIFS('VS×ケイパビリティ関係'!$F$4:$F$494,$B14,'VS×ケイパビリティ関係'!$G$4:$G$494,G$5,'VS×ケイパビリティ関係'!$E$4:$E$494,"支援")>0,"○","")) | H14: =IF(COUNTIFS('VS×ケイパビリティ関係'!$F$4:$F$494,$B14,'VS×ケイパビリティ関係'!$G$4:$G$494,H$5,'VS×ケイパビリティ関係'!$E$4:$E$494,"主")>0,"●",IF(COUNTIFS('VS×ケイパビリティ関係'!$F$4:$F$494,$B14,'VS×ケイパビリティ関係'!$G$4:$G$494,H$5,'VS×ケイパビリティ関係'!$E$4:$E$494,"支援")>0,"○","")) | I14: =IF(COUNTIFS('VS×ケイパビリティ関係'!$F$4:$F$494,$B14,'VS×ケイパビリティ関係'!$G$4:$G$494,I$5,'VS×ケイパビリティ関係'!$E$4:$E$494,"主")>0,"●",IF(COUNTIFS('VS×ケイパビリティ関係'!$F$4:$F$494,$B14,'VS×ケイパビリティ関係'!$G$4:$G$494,I$5,'VS×ケイパビリティ関係'!$E$4:$E$494,"支援")>0,"○","")) | J14: =IF(COUNTIFS('VS×ケイパビリティ関係'!$F$4:$F$494,$B14,'VS×ケイパビリティ関係'!$G$4:$G$494,J$5,'VS×ケイパビリティ関係'!$E$4:$E$494,"主")>0,"●",IF(COUNTIFS('VS×ケイパビリティ関係'!$F$4:$F$494,$B14,'VS×ケイパビリティ関係'!$G$4:$G$494,J$5,'VS×ケイパビリティ関係'!$E$4:$E$494,"支援")>0,"○","")) | K14: =IF(COUNTIFS('VS×ケイパビリティ関係'!$F$4:$F$494,$B14,'VS×ケイパビリティ関係'!$G$4:$G$494,K$5,'VS×ケイパビリティ関係'!$E$4:$E$494,"主")>0,"●",IF(COUNTIFS('VS×ケイパビリティ関係'!$F$4:$F$494,$B14,'VS×ケイパビリティ関係'!$G$4:$G$494,K$5,'VS×ケイパビリティ関係'!$E$4:$E$494,"支援")>0,"○","")) | ... BD14: =IF(COUNTIFS('VS×ケイパビリティ関係'!$F$4:$F$494,$B14,'VS×ケイパビリティ関係'!$G$4:$G$494,BD$5,'VS×ケイパビリティ関係'!$E$4:$E$494,"主")>0,"●",IF(COUNTIFS('VS×ケイパビリティ関係'!$F$4:$F$494,$B14,'VS×ケイパビリティ関係'!$G$4:$G$494,BD$5,'VS×ケイパビリティ関係'!$E$4:$E$494,"支援")>0,"○","")) | BE14: =COUNTIF(D14:BD14,"●") | BF14: =COUNTIF(D14:BD14,"○")
A15: 03 CMC開発（臨床と並行） | B15: 03-01 | C15: 細胞株構築・セルバンク | D15: =IF(COUNTIFS('VS×ケイパビリティ関係'!$F$4:$F$494,$B15,'VS×ケイパビリティ関係'!$G$4:$G$494,D$5,'VS×ケイパビリティ関係'!$E$4:$E$494,"主")>0,"●",IF(COUNTIFS('VS×ケイパビリティ関係'!$F$4:$F$494,$B15,'VS×ケイパビリティ関係'!$G$4:$G$494,D$5,'VS×ケイパビリティ関係'!$E$4:$E$494,"支援")>0,"○","")) | E15: =IF(COUNTIFS('VS×ケイパビリティ関係'!$F$4:$F$494,$B15,'VS×ケイパビリティ関係'!$G$4:$G$494,E$5,'VS×ケイパビリティ関係'!$E$4:$E$494,"主")>0,"●",IF(COUNTIFS('VS×ケイパビリティ関係'!$F$4:$F$494,$B15,'VS×ケイパビリティ関係'!$G$4:$G$494,E$5,'VS×ケイパビリティ関係'!$E$4:$E$494,"支援")>0,"○","")) | F15: =IF(COUNTIFS('VS×ケイパビリティ関係'!$F$4:$F$494,$B15,'VS×ケイパビリティ関係'!$G$4:$G$494,F$5,'VS×ケイパビリティ関係'!$E$4:$E$494,"主")>0,"●",IF(COUNTIFS('VS×ケイパビリティ関係'!$F$4:$F$494,$B15,'VS×ケイパビリティ関係'!$G$4:$G$494,F$5,'VS×ケイパビリティ関係'!$E$4:$E$494,"支援")>0,"○","")) | G15: =IF(COUNTIFS('VS×ケイパビリティ関係'!$F$4:$F$494,$B15,'VS×ケイパビリティ関係'!$G$4:$G$494,G$5,'VS×ケイパビリティ関係'!$E$4:$E$494,"主")>0,"●",IF(COUNTIFS('VS×ケイパビリティ関係'!$F$4:$F$494,$B15,'VS×ケイパビリティ関係'!$G$4:$G$494,G$5,'VS×ケイパビリティ関係'!$E$4:$E$494,"支援")>0,"○","")) | H15: =IF(COUNTIFS('VS×ケイパビリティ関係'!$F$4:$F$494,$B15,'VS×ケイパビリティ関係'!$G$4:$G$494,H$5,'VS×ケイパビリティ関係'!$E$4:$E$494,"主")>0,"●",IF(COUNTIFS('VS×ケイパビリティ関係'!$F$4:$F$494,$B15,'VS×ケイパビリティ関係'!$G$4:$G$494,H$5,'VS×ケイパビリティ関係'!$E$4:$E$494,"支援")>0,"○","")) | I15: =IF(COUNTIFS('VS×ケイパビリティ関係'!$F$4:$F$494,$B15,'VS×ケイパビリティ関係'!$G$4:$G$494,I$5,'VS×ケイパビリティ関係'!$E$4:$E$494,"主")>0,"●",IF(COUNTIFS('VS×ケイパビリティ関係'!$F$4:$F$494,$B15,'VS×ケイパビリティ関係'!$G$4:$G$494,I$5,'VS×ケイパビリティ関係'!$E$4:$E$494,"支援")>0,"○","")) | J15: =IF(COUNTIFS('VS×ケイパビリティ関係'!$F$4:$F$494,$B15,'VS×ケイパビリティ関係'!$G$4:$G$494,J$5,'VS×ケイパビリティ関係'!$E$4:$E$494,"主")>0,"●",IF(COUNTIFS('VS×ケイパビリティ関係'!$F$4:$F$494,$B15,'VS×ケイパビリティ関係'!$G$4:$G$494,J$5,'VS×ケイパビリティ関係'!$E$4:$E$494,"支援")>0,"○","")) | K15: =IF(COUNTIFS('VS×ケイパビリティ関係'!$F$4:$F$494,$B15,'VS×ケイパビリティ関係'!$G$4:$G$494,K$5,'VS×ケイパビリティ関係'!$E$4:$E$494,"主")>0,"●",IF(COUNTIFS('VS×ケイパビリティ関係'!$F$4:$F$494,$B15,'VS×ケイパビリティ関係'!$G$4:$G$494,K$5,'VS×ケイパビリティ関係'!$E$4:$E$494,"支援")>0,"○","")) | ... BD15: =IF(COUNTIFS('VS×ケイパビリティ関係'!$F$4:$F$494,$B15,'VS×ケイパビリティ関係'!$G$4:$G$494,BD$5,'VS×ケイパビリティ関係'!$E$4:$E$494,"主")>0,"●",IF(COUNTIFS('VS×ケイパビリティ関係'!$F$4:$F$494,$B15,'VS×ケイパビリティ関係'!$G$4:$G$494,BD$5,'VS×ケイパビリティ関係'!$E$4:$E$494,"支援")>0,"○","")) | BE15: =COUNTIF(D15:BD15,"●") | BF15: =COUNTIF(D15:BD15,"○")
B16: 03-02 | C16: 原薬プロセス開発 | D16: =IF(COUNTIFS('VS×ケイパビリティ関係'!$F$4:$F$494,$B16,'VS×ケイパビリティ関係'!$G$4:$G$494,D$5,'VS×ケイパビリティ関係'!$E$4:$E$494,"主")>0,"●",IF(COUNTIFS('VS×ケイパビリティ関係'!$F$4:$F$494,$B16,'VS×ケイパビリティ関係'!$G$4:$G$494,D$5,'VS×ケイパビリティ関係'!$E$4:$E$494,"支援")>0,"○","")) | E16: =IF(COUNTIFS('VS×ケイパビリティ関係'!$F$4:$F$494,$B16,'VS×ケイパビリティ関係'!$G$4:$G$494,E$5,'VS×ケイパビリティ関係'!$E$4:$E$494,"主")>0,"●",IF(COUNTIFS('VS×ケイパビリティ関係'!$F$4:$F$494,$B16,'VS×ケイパビリティ関係'!$G$4:$G$494,E$5,'VS×ケイパビリティ関係'!$E$4:$E$494,"支援")>0,"○","")) | F16: =IF(COUNTIFS('VS×ケイパビリティ関係'!$F$4:$F$494,$B16,'VS×ケイパビリティ関係'!$G$4:$G$494,F$5,'VS×ケイパビリティ関係'!$E$4:$E$494,"主")>0,"●",IF(COUNTIFS('VS×ケイパビリティ関係'!$F$4:$F$494,$B16,'VS×ケイパビリティ関係'!$G$4:$G$494,F$5,'VS×ケイパビリティ関係'!$E$4:$E$494,"支援")>0,"○","")) | G16: =IF(COUNTIFS('VS×ケイパビリティ関係'!$F$4:$F$494,$B16,'VS×ケイパビリティ関係'!$G$4:$G$494,G$5,'VS×ケイパビリティ関係'!$E$4:$E$494,"主")>0,"●",IF(COUNTIFS('VS×ケイパビリティ関係'!$F$4:$F$494,$B16,'VS×ケイパビリティ関係'!$G$4:$G$494,G$5,'VS×ケイパビリティ関係'!$E$4:$E$494,"支援")>0,"○","")) | H16: =IF(COUNTIFS('VS×ケイパビリティ関係'!$F$4:$F$494,$B16,'VS×ケイパビリティ関係'!$G$4:$G$494,H$5,'VS×ケイパビリティ関係'!$E$4:$E$494,"主")>0,"●",IF(COUNTIFS('VS×ケイパビリティ関係'!$F$4:$F$494,$B16,'VS×ケイパビリティ関係'!$G$4:$G$494,H$5,'VS×ケイパビリティ関係'!$E$4:$E$494,"支援")>0,"○","")) | I16: =IF(COUNTIFS('VS×ケイパビリティ関係'!$F$4:$F$494,$B16,'VS×ケイパビリティ関係'!$G$4:$G$494,I$5,'VS×ケイパビリティ関係'!$E$4:$E$494,"主")>0,"●",IF(COUNTIFS('VS×ケイパビリティ関係'!$F$4:$F$494,$B16,'VS×ケイパビリティ関係'!$G$4:$G$494,I$5,'VS×ケイパビリティ関係'!$E$4:$E$494,"支援")>0,"○","")) | J16: =IF(COUNTIFS('VS×ケイパビリティ関係'!$F$4:$F$494,$B16,'VS×ケイパビリティ関係'!$G$4:$G$494,J$5,'VS×ケイパビリティ関係'!$E$4:$E$494,"主")>0,"●",IF(COUNTIFS('VS×ケイパビリティ関係'!$F$4:$F$494,$B16,'VS×ケイパビリティ関係'!$G$4:$G$494,J$5,'VS×ケイパビリティ関係'!$E$4:$E$494,"支援")>0,"○","")) | K16: =IF(COUNTIFS('VS×ケイパビリティ関係'!$F$4:$F$494,$B16,'VS×ケイパビリティ関係'!$G$4:$G$494,K$5,'VS×ケイパビリティ関係'!$E$4:$E$494,"主")>0,"●",IF(COUNTIFS('VS×ケイパビリティ関係'!$F$4:$F$494,$B16,'VS×ケイパビリティ関係'!$G$4:$G$494,K$5,'VS×ケイパビリティ関係'!$E$4:$E$494,"支援")>0,"○","")) | ... BD16: =IF(COUNTIFS('VS×ケイパビリティ関係'!$F$4:$F$494,$B16,'VS×ケイパビリティ関係'!$G$4:$G$494,BD$5,'VS×ケイパビリティ関係'!$E$4:$E$494,"主")>0,"●",IF(COUNTIFS('VS×ケイパビリティ関係'!$F$4:$F$494,$B16,'VS×ケイパビリティ関係'!$G$4:$G$494,BD$5,'VS×ケイパビリティ関係'!$E$4:$E$494,"支援")>0,"○","")) | BE16: =COUNTIF(D16:BD16,"●") | BF16: =COUNTIF(D16:BD16,"○")
B17: 03-03 | C17: 製剤開発 | D17: =IF(COUNTIFS('VS×ケイパビリティ関係'!$F$4:$F$494,$B17,'VS×ケイパビリティ関係'!$G$4:$G$494,D$5,'VS×ケイパビリティ関係'!$E$4:$E$494,"主")>0,"●",IF(COUNTIFS('VS×ケイパビリティ関係'!$F$4:$F$494,$B17,'VS×ケイパビリティ関係'!$G$4:$G$494,D$5,'VS×ケイパビリティ関係'!$E$4:$E$494,"支援")>0,"○","")) | E17: =IF(COUNTIFS('VS×ケイパビリティ関係'!$F$4:$F$494,$B17,'VS×ケイパビリティ関係'!$G$4:$G$494,E$5,'VS×ケイパビリティ関係'!$E$4:$E$494,"主")>0,"●",IF(COUNTIFS('VS×ケイパビリティ関係'!$F$4:$F$494,$B17,'VS×ケイパビリティ関係'!$G$4:$G$494,E$5,'VS×ケイパビリティ関係'!$E$4:$E$494,"支援")>0,"○","")) | F17: =IF(COUNTIFS('VS×ケイパビリティ関係'!$F$4:$F$494,$B17,'VS×ケイパビリティ関係'!$G$4:$G$494,F$5,'VS×ケイパビリティ関係'!$E$4:$E$494,"主")>0,"●",IF(COUNTIFS('VS×ケイパビリティ関係'!$F$4:$F$494,$B17,'VS×ケイパビリティ関係'!$G$4:$G$494,F$5,'VS×ケイパビリティ関係'!$E$4:$E$494,"支援")>0,"○","")) | G17: =IF(COUNTIFS('VS×ケイパビリティ関係'!$F$4:$F$494,$B17,'VS×ケイパビリティ関係'!$G$4:$G$494,G$5,'VS×ケイパビリティ関係'!$E$4:$E$494,"主")>0,"●",IF(COUNTIFS('VS×ケイパビリティ関係'!$F$4:$F$494,$B17,'VS×ケイパビリティ関係'!$G$4:$G$494,G$5,'VS×ケイパビリティ関係'!$E$4:$E$494,"支援")>0,"○","")) | H17: =IF(COUNTIFS('VS×ケイパビリティ関係'!$F$4:$F$494,$B17,'VS×ケイパビリティ関係'!$G$4:$G$494,H$5,'VS×ケイパビリティ関係'!$E$4:$E$494,"主")>0,"●",IF(COUNTIFS('VS×ケイパビリティ関係'!$F$4:$F$494,$B17,'VS×ケイパビリティ関係'!$G$4:$G$494,H$5,'VS×ケイパビリティ関係'!$E$4:$E$494,"支援")>0,"○","")) | I17: =IF(COUNTIFS('VS×ケイパビリティ関係'!$F$4:$F$494,$B17,'VS×ケイパビリティ関係'!$G$4:$G$494,I$5,'VS×ケイパビリティ関係'!$E$4:$E$494,"主")>0,"●",IF(COUNTIFS('VS×ケイパビリティ関係'!$F$4:$F$494,$B17,'VS×ケイパビリティ関係'!$G$4:$G$494,I$5,'VS×ケイパビリティ関係'!$E$4:$E$494,"支援")>0,"○","")) | J17: =IF(COUNTIFS('VS×ケイパビリティ関係'!$F$4:$F$494,$B17,'VS×ケイパビリティ関係'!$G$4:$G$494,J$5,'VS×ケイパビリティ関係'!$E$4:$E$494,"主")>0,"●",IF(COUNTIFS('VS×ケイパビリティ関係'!$F$4:$F$494,$B17,'VS×ケイパビリティ関係'!$G$4:$G$494,J$5,'VS×ケイパビリティ関係'!$E$4:$E$494,"支援")>0,"○","")) | K17: =IF(COUNTIFS('VS×ケイパビリティ関係'!$F$4:$F$494,$B17,'VS×ケイパビリティ関係'!$G$4:$G$494,K$5,'VS×ケイパビリティ関係'!$E$4:$E$494,"主")>0,"●",IF(COUNTIFS('VS×ケイパビリティ関係'!$F$4:$F$494,$B17,'VS×ケイパビリティ関係'!$G$4:$G$494,K$5,'VS×ケイパビリティ関係'!$E$4:$E$494,"支援")>0,"○","")) | ... BD17: =IF(COUNTIFS('VS×ケイパビリティ関係'!$F$4:$F$494,$B17,'VS×ケイパビリティ関係'!$G$4:$G$494,BD$5,'VS×ケイパビリティ関係'!$E$4:$E$494,"主")>0,"●",IF(COUNTIFS('VS×ケイパビリティ関係'!$F$4:$F$494,$B17,'VS×ケイパビリティ関係'!$G$4:$G$494,BD$5,'VS×ケイパビリティ関係'!$E$4:$E$494,"支援")>0,"○","")) | BE17: =COUNTIF(D17:BD17,"●") | BF17: =COUNTIF(D17:BD17,"○")
B18: 03-04 | C18: 分析法開発・特性解析 | D18: =IF(COUNTIFS('VS×ケイパビリティ関係'!$F$4:$F$494,$B18,'VS×ケイパビリティ関係'!$G$4:$G$494,D$5,'VS×ケイパビリティ関係'!$E$4:$E$494,"主")>0,"●",IF(COUNTIFS('VS×ケイパビリティ関係'!$F$4:$F$494,$B18,'VS×ケイパビリティ関係'!$G$4:$G$494,D$5,'VS×ケイパビリティ関係'!$E$4:$E$494,"支援")>0,"○","")) | E18: =IF(COUNTIFS('VS×ケイパビリティ関係'!$F$4:$F$494,$B18,'VS×ケイパビリティ関係'!$G$4:$G$494,E$5,'VS×ケイパビリティ関係'!$E$4:$E$494,"主")>0,"●",IF(COUNTIFS('VS×ケイパビリティ関係'!$F$4:$F$494,$B18,'VS×ケイパビリティ関係'!$G$4:$G$494,E$5,'VS×ケイパビリティ関係'!$E$4:$E$494,"支援")>0,"○","")) | F18: =IF(COUNTIFS('VS×ケイパビリティ関係'!$F$4:$F$494,$B18,'VS×ケイパビリティ関係'!$G$4:$G$494,F$5,'VS×ケイパビリティ関係'!$E$4:$E$494,"主")>0,"●",IF(COUNTIFS('VS×ケイパビリティ関係'!$F$4:$F$494,$B18,'VS×ケイパビリティ関係'!$G$4:$G$494,F$5,'VS×ケイパビリティ関係'!$E$4:$E$494,"支援")>0,"○","")) | G18: =IF(COUNTIFS('VS×ケイパビリティ関係'!$F$4:$F$494,$B18,'VS×ケイパビリティ関係'!$G$4:$G$494,G$5,'VS×ケイパビリティ関係'!$E$4:$E$494,"主")>0,"●",IF(COUNTIFS('VS×ケイパビリティ関係'!$F$4:$F$494,$B18,'VS×ケイパビリティ関係'!$G$4:$G$494,G$5,'VS×ケイパビリティ関係'!$E$4:$E$494,"支援")>0,"○","")) | H18: =IF(COUNTIFS('VS×ケイパビリティ関係'!$F$4:$F$494,$B18,'VS×ケイパビリティ関係'!$G$4:$G$494,H$5,'VS×ケイパビリティ関係'!$E$4:$E$494,"主")>0,"●",IF(COUNTIFS('VS×ケイパビリティ関係'!$F$4:$F$494,$B18,'VS×ケイパビリティ関係'!$G$4:$G$494,H$5,'VS×ケイパビリティ関係'!$E$4:$E$494,"支援")>0,"○","")) | I18: =IF(COUNTIFS('VS×ケイパビリティ関係'!$F$4:$F$494,$B18,'VS×ケイパビリティ関係'!$G$4:$G$494,I$5,'VS×ケイパビリティ関係'!$E$4:$E$494,"主")>0,"●",IF(COUNTIFS('VS×ケイパビリティ関係'!$F$4:$F$494,$B18,'VS×ケイパビリティ関係'!$G$4:$G$494,I$5,'VS×ケイパビリティ関係'!$E$4:$E$494,"支援")>0,"○","")) | J18: =IF(COUNTIFS('VS×ケイパビリティ関係'!$F$4:$F$494,$B18,'VS×ケイパビリティ関係'!$G$4:$G$494,J$5,'VS×ケイパビリティ関係'!$E$4:$E$494,"主")>0,"●",IF(COUNTIFS('VS×ケイパビリティ関係'!$F$4:$F$494,$B18,'VS×ケイパビリティ関係'!$G$4:$G$494,J$5,'VS×ケイパビリティ関係'!$E$4:$E$494,"支援")>0,"○","")) | K18: =IF(COUNTIFS('VS×ケイパビリティ関係'!$F$4:$F$494,$B18,'VS×ケイパビリティ関係'!$G$4:$G$494,K$5,'VS×ケイパビリティ関係'!$E$4:$E$494,"主")>0,"●",IF(COUNTIFS('VS×ケイパビリティ関係'!$F$4:$F$494,$B18,'VS×ケイパビリティ関係'!$G$4:$G$494,K$5,'VS×ケイパビリティ関係'!$E$4:$E$494,"支援")>0,"○","")) | ... BD18: =IF(COUNTIFS('VS×ケイパビリティ関係'!$F$4:$F$494,$B18,'VS×ケイパビリティ関係'!$G$4:$G$494,BD$5,'VS×ケイパビリティ関係'!$E$4:$E$494,"主")>0,"●",IF(COUNTIFS('VS×ケイパビリティ関係'!$F$4:$F$494,$B18,'VS×ケイパビリティ関係'!$G$4:$G$494,BD$5,'VS×ケイパビリティ関係'!$E$4:$E$494,"支援")>0,"○","")) | BE18: =COUNTIF(D18:BD18,"●") | BF18: =COUNTIF(D18:BD18,"○")
B19: 03-05 | C19: 治験薬GMP製造・供給 | D19: =IF(COUNTIFS('VS×ケイパビリティ関係'!$F$4:$F$494,$B19,'VS×ケイパビリティ関係'!$G$4:$G$494,D$5,'VS×ケイパビリティ関係'!$E$4:$E$494,"主")>0,"●",IF(COUNTIFS('VS×ケイパビリティ関係'!$F$4:$F$494,$B19,'VS×ケイパビリティ関係'!$G$4:$G$494,D$5,'VS×ケイパビリティ関係'!$E$4:$E$494,"支援")>0,"○","")) | E19: =IF(COUNTIFS('VS×ケイパビリティ関係'!$F$4:$F$494,$B19,'VS×ケイパビリティ関係'!$G$4:$G$494,E$5,'VS×ケイパビリティ関係'!$E$4:$E$494,"主")>0,"●",IF(COUNTIFS('VS×ケイパビリティ関係'!$F$4:$F$494,$B19,'VS×ケイパビリティ関係'!$G$4:$G$494,E$5,'VS×ケイパビリティ関係'!$E$4:$E$494,"支援")>0,"○","")) | F19: =IF(COUNTIFS('VS×ケイパビリティ関係'!$F$4:$F$494,$B19,'VS×ケイパビリティ関係'!$G$4:$G$494,F$5,'VS×ケイパビリティ関係'!$E$4:$E$494,"主")>0,"●",IF(COUNTIFS('VS×ケイパビリティ関係'!$F$4:$F$494,$B19,'VS×ケイパビリティ関係'!$G$4:$G$494,F$5,'VS×ケイパビリティ関係'!$E$4:$E$494,"支援")>0,"○","")) | G19: =IF(COUNTIFS('VS×ケイパビリティ関係'!$F$4:$F$494,$B19,'VS×ケイパビリティ関係'!$G$4:$G$494,G$5,'VS×ケイパビリティ関係'!$E$4:$E$494,"主")>0,"●",IF(COUNTIFS('VS×ケイパビリティ関係'!$F$4:$F$494,$B19,'VS×ケイパビリティ関係'!$G$4:$G$494,G$5,'VS×ケイパビリティ関係'!$E$4:$E$494,"支援")>0,"○","")) | H19: =IF(COUNTIFS('VS×ケイパビリティ関係'!$F$4:$F$494,$B19,'VS×ケイパビリティ関係'!$G$4:$G$494,H$5,'VS×ケイパビリティ関係'!$E$4:$E$494,"主")>0,"●",IF(COUNTIFS('VS×ケイパビリティ関係'!$F$4:$F$494,$B19,'VS×ケイパビリティ関係'!$G$4:$G$494,H$5,'VS×ケイパビリティ関係'!$E$4:$E$494,"支援")>0,"○","")) | I19: =IF(COUNTIFS('VS×ケイパビリティ関係'!$F$4:$F$494,$B19,'VS×ケイパビリティ関係'!$G$4:$G$494,I$5,'VS×ケイパビリティ関係'!$E$4:$E$494,"主")>0,"●",IF(COUNTIFS('VS×ケイパビリティ関係'!$F$4:$F$494,$B19,'VS×ケイパビリティ関係'!$G$4:$G$494,I$5,'VS×ケイパビリティ関係'!$E$4:$E$494,"支援")>0,"○","")) | J19: =IF(COUNTIFS('VS×ケイパビリティ関係'!$F$4:$F$494,$B19,'VS×ケイパビリティ関係'!$G$4:$G$494,J$5,'VS×ケイパビリティ関係'!$E$4:$E$494,"主")>0,"●",IF(COUNTIFS('VS×ケイパビリティ関係'!$F$4:$F$494,$B19,'VS×ケイパビリティ関係'!$G$4:$G$494,J$5,'VS×ケイパビリティ関係'!$E$4:$E$494,"支援")>0,"○","")) | K19: =IF(COUNTIFS('VS×ケイパビリティ関係'!$F$4:$F$494,$B19,'VS×ケイパビリティ関係'!$G$4:$G$494,K$5,'VS×ケイパビリティ関係'!$E$4:$E$494,"主")>0,"●",IF(COUNTIFS('VS×ケイパビリティ関係'!$F$4:$F$494,$B19,'VS×ケイパビリティ関係'!$G$4:$G$494,K$5,'VS×ケイパビリティ関係'!$E$4:$E$494,"支援")>0,"○","")) | ... BD19: =IF(COUNTIFS('VS×ケイパビリティ関係'!$F$4:$F$494,$B19,'VS×ケイパビリティ関係'!$G$4:$G$494,BD$5,'VS×ケイパビリティ関係'!$E$4:$E$494,"主")>0,"●",IF(COUNTIFS('VS×ケイパビリティ関係'!$F$4:$F$494,$B19,'VS×ケイパビリティ関係'!$G$4:$G$494,BD$5,'VS×ケイパビリティ関係'!$E$4:$E$494,"支援")>0,"○","")) | BE19: =COUNTIF(D19:BD19,"●") | BF19: =COUNTIF(D19:BD19,"○")
B20: 03-06 | C20: 後期プロセス開発・スケールアップ・技術移転 | D20: =IF(COUNTIFS('VS×ケイパビリティ関係'!$F$4:$F$494,$B20,'VS×ケイパビリティ関係'!$G$4:$G$494,D$5,'VS×ケイパビリティ関係'!$E$4:$E$494,"主")>0,"●",IF(COUNTIFS('VS×ケイパビリティ関係'!$F$4:$F$494,$B20,'VS×ケイパビリティ関係'!$G$4:$G$494,D$5,'VS×ケイパビリティ関係'!$E$4:$E$494,"支援")>0,"○","")) | E20: =IF(COUNTIFS('VS×ケイパビリティ関係'!$F$4:$F$494,$B20,'VS×ケイパビリティ関係'!$G$4:$G$494,E$5,'VS×ケイパビリティ関係'!$E$4:$E$494,"主")>0,"●",IF(COUNTIFS('VS×ケイパビリティ関係'!$F$4:$F$494,$B20,'VS×ケイパビリティ関係'!$G$4:$G$494,E$5,'VS×ケイパビリティ関係'!$E$4:$E$494,"支援")>0,"○","")) | F20: =IF(COUNTIFS('VS×ケイパビリティ関係'!$F$4:$F$494,$B20,'VS×ケイパビリティ関係'!$G$4:$G$494,F$5,'VS×ケイパビリティ関係'!$E$4:$E$494,"主")>0,"●",IF(COUNTIFS('VS×ケイパビリティ関係'!$F$4:$F$494,$B20,'VS×ケイパビリティ関係'!$G$4:$G$494,F$5,'VS×ケイパビリティ関係'!$E$4:$E$494,"支援")>0,"○","")) | G20: =IF(COUNTIFS('VS×ケイパビリティ関係'!$F$4:$F$494,$B20,'VS×ケイパビリティ関係'!$G$4:$G$494,G$5,'VS×ケイパビリティ関係'!$E$4:$E$494,"主")>0,"●",IF(COUNTIFS('VS×ケイパビリティ関係'!$F$4:$F$494,$B20,'VS×ケイパビリティ関係'!$G$4:$G$494,G$5,'VS×ケイパビリティ関係'!$E$4:$E$494,"支援")>0,"○","")) | H20: =IF(COUNTIFS('VS×ケイパビリティ関係'!$F$4:$F$494,$B20,'VS×ケイパビリティ関係'!$G$4:$G$494,H$5,'VS×ケイパビリティ関係'!$E$4:$E$494,"主")>0,"●",IF(COUNTIFS('VS×ケイパビリティ関係'!$F$4:$F$494,$B20,'VS×ケイパビリティ関係'!$G$4:$G$494,H$5,'VS×ケイパビリティ関係'!$E$4:$E$494,"支援")>0,"○","")) | I20: =IF(COUNTIFS('VS×ケイパビリティ関係'!$F$4:$F$494,$B20,'VS×ケイパビリティ関係'!$G$4:$G$494,I$5,'VS×ケイパビリティ関係'!$E$4:$E$494,"主")>0,"●",IF(COUNTIFS('VS×ケイパビリティ関係'!$F$4:$F$494,$B20,'VS×ケイパビリティ関係'!$G$4:$G$494,I$5,'VS×ケイパビリティ関係'!$E$4:$E$494,"支援")>0,"○","")) | J20: =IF(COUNTIFS('VS×ケイパビリティ関係'!$F$4:$F$494,$B20,'VS×ケイパビリティ関係'!$G$4:$G$494,J$5,'VS×ケイパビリティ関係'!$E$4:$E$494,"主")>0,"●",IF(COUNTIFS('VS×ケイパビリティ関係'!$F$4:$F$494,$B20,'VS×ケイパビリティ関係'!$G$4:$G$494,J$5,'VS×ケイパビリティ関係'!$E$4:$E$494,"支援")>0,"○","")) | K20: =IF(COUNTIFS('VS×ケイパビリティ関係'!$F$4:$F$494,$B20,'VS×ケイパビリティ関係'!$G$4:$G$494,K$5,'VS×ケイパビリティ関係'!$E$4:$E$494,"主")>0,"●",IF(COUNTIFS('VS×ケイパビリティ関係'!$F$4:$F$494,$B20,'VS×ケイパビリティ関係'!$G$4:$G$494,K$5,'VS×ケイパビリティ関係'!$E$4:$E$494,"支援")>0,"○","")) | ... BD20: =IF(COUNTIFS('VS×ケイパビリティ関係'!$F$4:$F$494,$B20,'VS×ケイパビリティ関係'!$G$4:$G$494,BD$5,'VS×ケイパビリティ関係'!$E$4:$E$494,"主")>0,"●",IF(COUNTIFS('VS×ケイパビリティ関係'!$F$4:$F$494,$B20,'VS×ケイパビリティ関係'!$G$4:$G$494,BD$5,'VS×ケイパビリティ関係'!$E$4:$E$494,"支援")>0,"○","")) | BE20: =COUNTIF(D20:BD20,"●") | BF20: =COUNTIF(D20:BD20,"○")
B21: 03-07 | C21: プロセスバリデーション（PPQ） | D21: =IF(COUNTIFS('VS×ケイパビリティ関係'!$F$4:$F$494,$B21,'VS×ケイパビリティ関係'!$G$4:$G$494,D$5,'VS×ケイパビリティ関係'!$E$4:$E$494,"主")>0,"●",IF(COUNTIFS('VS×ケイパビリティ関係'!$F$4:$F$494,$B21,'VS×ケイパビリティ関係'!$G$4:$G$494,D$5,'VS×ケイパビリティ関係'!$E$4:$E$494,"支援")>0,"○","")) | E21: =IF(COUNTIFS('VS×ケイパビリティ関係'!$F$4:$F$494,$B21,'VS×ケイパビリティ関係'!$G$4:$G$494,E$5,'VS×ケイパビリティ関係'!$E$4:$E$494,"主")>0,"●",IF(COUNTIFS('VS×ケイパビリティ関係'!$F$4:$F$494,$B21,'VS×ケイパビリティ関係'!$G$4:$G$494,E$5,'VS×ケイパビリティ関係'!$E$4:$E$494,"支援")>0,"○","")) | F21: =IF(COUNTIFS('VS×ケイパビリティ関係'!$F$4:$F$494,$B21,'VS×ケイパビリティ関係'!$G$4:$G$494,F$5,'VS×ケイパビリティ関係'!$E$4:$E$494,"主")>0,"●",IF(COUNTIFS('VS×ケイパビリティ関係'!$F$4:$F$494,$B21,'VS×ケイパビリティ関係'!$G$4:$G$494,F$5,'VS×ケイパビリティ関係'!$E$4:$E$494,"支援")>0,"○","")) | G21: =IF(COUNTIFS('VS×ケイパビリティ関係'!$F$4:$F$494,$B21,'VS×ケイパビリティ関係'!$G$4:$G$494,G$5,'VS×ケイパビリティ関係'!$E$4:$E$494,"主")>0,"●",IF(COUNTIFS('VS×ケイパビリティ関係'!$F$4:$F$494,$B21,'VS×ケイパビリティ関係'!$G$4:$G$494,G$5,'VS×ケイパビリティ関係'!$E$4:$E$494,"支援")>0,"○","")) | H21: =IF(COUNTIFS('VS×ケイパビリティ関係'!$F$4:$F$494,$B21,'VS×ケイパビリティ関係'!$G$4:$G$494,H$5,'VS×ケイパビリティ関係'!$E$4:$E$494,"主")>0,"●",IF(COUNTIFS('VS×ケイパビリティ関係'!$F$4:$F$494,$B21,'VS×ケイパビリティ関係'!$G$4:$G$494,H$5,'VS×ケイパビリティ関係'!$E$4:$E$494,"支援")>0,"○","")) | I21: =IF(COUNTIFS('VS×ケイパビリティ関係'!$F$4:$F$494,$B21,'VS×ケイパビリティ関係'!$G$4:$G$494,I$5,'VS×ケイパビリティ関係'!$E$4:$E$494,"主")>0,"●",IF(COUNTIFS('VS×ケイパビリティ関係'!$F$4:$F$494,$B21,'VS×ケイパビリティ関係'!$G$4:$G$494,I$5,'VS×ケイパビリティ関係'!$E$4:$E$494,"支援")>0,"○","")) | J21: =IF(COUNTIFS('VS×ケイパビリティ関係'!$F$4:$F$494,$B21,'VS×ケイパビリティ関係'!$G$4:$G$494,J$5,'VS×ケイパビリティ関係'!$E$4:$E$494,"主")>0,"●",IF(COUNTIFS('VS×ケイパビリティ関係'!$F$4:$F$494,$B21,'VS×ケイパビリティ関係'!$G$4:$G$494,J$5,'VS×ケイパビリティ関係'!$E$4:$E$494,"支援")>0,"○","")) | K21: =IF(COUNTIFS('VS×ケイパビリティ関係'!$F$4:$F$494,$B21,'VS×ケイパビリティ関係'!$G$4:$G$494,K$5,'VS×ケイパビリティ関係'!$E$4:$E$494,"主")>0,"●",IF(COUNTIFS('VS×ケイパビリティ関係'!$F$4:$F$494,$B21,'VS×ケイパビリティ関係'!$G$4:$G$494,K$5,'VS×ケイパビリティ関係'!$E$4:$E$494,"支援")>0,"○","")) | ... BD21: =IF(COUNTIFS('VS×ケイパビリティ関係'!$F$4:$F$494,$B21,'VS×ケイパビリティ関係'!$G$4:$G$494,BD$5,'VS×ケイパビリティ関係'!$E$4:$E$494,"主")>0,"●",IF(COUNTIFS('VS×ケイパビリティ関係'!$F$4:$F$494,$B21,'VS×ケイパビリティ関係'!$G$4:$G$494,BD$5,'VS×ケイパビリティ関係'!$E$4:$E$494,"支援")>0,"○","")) | BE21: =COUNTIF(D21:BD21,"●") | BF21: =COUNTIF(D21:BD21,"○")
A22: 04 臨床開発 | B22: 04-01 | C22: ★自然歴研究・患者特定 | D22: =IF(COUNTIFS('VS×ケイパビリティ関係'!$F$4:$F$494,$B22,'VS×ケイパビリティ関係'!$G$4:$G$494,D$5,'VS×ケイパビリティ関係'!$E$4:$E$494,"主")>0,"●",IF(COUNTIFS('VS×ケイパビリティ関係'!$F$4:$F$494,$B22,'VS×ケイパビリティ関係'!$G$4:$G$494,D$5,'VS×ケイパビリティ関係'!$E$4:$E$494,"支援")>0,"○","")) | E22: =IF(COUNTIFS('VS×ケイパビリティ関係'!$F$4:$F$494,$B22,'VS×ケイパビリティ関係'!$G$4:$G$494,E$5,'VS×ケイパビリティ関係'!$E$4:$E$494,"主")>0,"●",IF(COUNTIFS('VS×ケイパビリティ関係'!$F$4:$F$494,$B22,'VS×ケイパビリティ関係'!$G$4:$G$494,E$5,'VS×ケイパビリティ関係'!$E$4:$E$494,"支援")>0,"○","")) | F22: =IF(COUNTIFS('VS×ケイパビリティ関係'!$F$4:$F$494,$B22,'VS×ケイパビリティ関係'!$G$4:$G$494,F$5,'VS×ケイパビリティ関係'!$E$4:$E$494,"主")>0,"●",IF(COUNTIFS('VS×ケイパビリティ関係'!$F$4:$F$494,$B22,'VS×ケイパビリティ関係'!$G$4:$G$494,F$5,'VS×ケイパビリティ関係'!$E$4:$E$494,"支援")>0,"○","")) | G22: =IF(COUNTIFS('VS×ケイパビリティ関係'!$F$4:$F$494,$B22,'VS×ケイパビリティ関係'!$G$4:$G$494,G$5,'VS×ケイパビリティ関係'!$E$4:$E$494,"主")>0,"●",IF(COUNTIFS('VS×ケイパビリティ関係'!$F$4:$F$494,$B22,'VS×ケイパビリティ関係'!$G$4:$G$494,G$5,'VS×ケイパビリティ関係'!$E$4:$E$494,"支援")>0,"○","")) | H22: =IF(COUNTIFS('VS×ケイパビリティ関係'!$F$4:$F$494,$B22,'VS×ケイパビリティ関係'!$G$4:$G$494,H$5,'VS×ケイパビリティ関係'!$E$4:$E$494,"主")>0,"●",IF(COUNTIFS('VS×ケイパビリティ関係'!$F$4:$F$494,$B22,'VS×ケイパビリティ関係'!$G$4:$G$494,H$5,'VS×ケイパビリティ関係'!$E$4:$E$494,"支援")>0,"○","")) | I22: =IF(COUNTIFS('VS×ケイパビリティ関係'!$F$4:$F$494,$B22,'VS×ケイパビリティ関係'!$G$4:$G$494,I$5,'VS×ケイパビリティ関係'!$E$4:$E$494,"主")>0,"●",IF(COUNTIFS('VS×ケイパビリティ関係'!$F$4:$F$494,$B22,'VS×ケイパビリティ関係'!$G$4:$G$494,I$5,'VS×ケイパビリティ関係'!$E$4:$E$494,"支援")>0,"○","")) | J22: =IF(COUNTIFS('VS×ケイパビリティ関係'!$F$4:$F$494,$B22,'VS×ケイパビリティ関係'!$G$4:$G$494,J$5,'VS×ケイパビリティ関係'!$E$4:$E$494,"主")>0,"●",IF(COUNTIFS('VS×ケイパビリティ関係'!$F$4:$F$494,$B22,'VS×ケイパビリティ関係'!$G$4:$G$494,J$5,'VS×ケイパビリティ関係'!$E$4:$E$494,"支援")>0,"○","")) | K22: =IF(COUNTIFS('VS×ケイパビリティ関係'!$F$4:$F$494,$B22,'VS×ケイパビリティ関係'!$G$4:$G$494,K$5,'VS×ケイパビリティ関係'!$E$4:$E$494,"主")>0,"●",IF(COUNTIFS('VS×ケイパビリティ関係'!$F$4:$F$494,$B22,'VS×ケイパビリティ関係'!$G$4:$G$494,K$5,'VS×ケイパビリティ関係'!$E$4:$E$494,"支援")>0,"○","")) | ... BD22: =IF(COUNTIFS('VS×ケイパビリティ関係'!$F$4:$F$494,$B22,'VS×ケイパビリティ関係'!$G$4:$G$494,BD$5,'VS×ケイパビリティ関係'!$E$4:$E$494,"主")>0,"●",IF(COUNTIFS('VS×ケイパビリティ関係'!$F$4:$F$494,$B22,'VS×ケイパビリティ関係'!$G$4:$G$494,BD$5,'VS×ケイパビリティ関係'!$E$4:$E$494,"支援")>0,"○","")) | BE22: =COUNTIF(D22:BD22,"●") | BF22: =COUNTIF(D22:BD22,"○")
