Workbook

Sheet バリューストリーム
A1: バリューストリーム（L1〜L4）
A2: 対象：日本の事業会社（直接材・間接材・役務の調達、月末締め・振込払い）／日本の法令・制度基準（取適法・フリーランス法・消費税法〔インボイス〕・電帳法・印紙税法ほか）。1行1項目。L1〜L4列の●がその行のレベル。出口はL2、入力・出力情報・関連法令・主な関与者はL4の項目。 入力情報・出力情報はVS定義の過程で得られる正本（直接入力する）。情報オブジェクトはこれを取りまとめて一覧化したもの。★＝日本の制度・商慣行に固有の項目。
A3: ID | B3: L1 | C3: L2 | D3: L3 | E3: L4 | F3: VS項目名 | G3: VSの定義 | H3: 出口（ゲート） | I3: 入力情報 | J3: 出力情報 | K3: 関連法令 | L3: 主な関与者（社内／外部）
A4: VS | B4: ● | F4: Procure-to-Pay | G4: 事業部門の需要を購買申請にまとめ、サプライヤーを選定して契約・発注し、受入・検収を経て、請求を照合して支払うまで。適正な品質の資材・サービスを最適なコストでタイムリーに調達し、サプライヤーへ公正かつ確実に支払う
A5: 01 | C5: ● | F5: 需要特定・購買申請 | G5: 事業部門の需要を把握して仕様にまとめ、予算と職務権限に基づいて購買申請を承認する段階 | H5: 購買申請の承認
A6: 01-01 | D6: ● | F6: 需要の把握・購買計画 | G6: 年間の購買計画と予算を立て、生産計画・在庫から必要な量を把握する
A7: 01-01-01 | E7: ● | F7: 年間購買計画・購買予算の策定 | I7: 支出分析、カテゴリ戦略 | J7: 購買計画・予算 | K7: なし | L7: 調達部門・事業部門・経理／—
A8: 01-01-02 | E8: ● | F8: 所要量計算（MRP）による購買依頼（直接材） | I8: 品目マスタ、在庫 | J8: 所要量・補充依頼 | K8: なし | L8: 生産管理／—
A9: 01-01-03 | E9: ● | F9: 補充点による補充依頼（消耗品・MRO） | I9: 在庫、品目マスタ | J9: 所要量・補充依頼 | K9: なし | L9: 拠点の資材担当／—
A10: 01-02 | D10: ● | F10: 仕様策定・購買申請作成 | G10: 要求事項を仕様にまとめ、購買申請を作成して予算と権限に基づき承認する
A11: 01-02-01 | E11: ● | F11: 購買仕様・要求事項の作成（品質・数量・納期・作業範囲） | I11: 所要量・補充依頼、品目マスタ | J11: 購買仕様書 | K11: なし | L11: 事業部門（需要者）／—
A12: 01-02-02 | E12: ● | F12: 既存契約・カタログからの選択（単価契約品） | I12: 単価契約・カタログ、購買仕様書 | J12: 購買申請（PR） | K12: なし | L12: 事業部門（需要者）／—
A13: 01-02-03 | E13: ● | F13: 購買申請（PR）の作成 | I13: 購買仕様書、所要量・補充依頼、品目マスタ | J13: 購買申請（PR） | K13: なし | L13: 事業部門（需要者）／—
A14: 01-02-04 | E14: ● | F14: 予算の確認・引当 | I14: 購買申請（PR）、購買計画・予算 | J14: 購買計画・予算 | K14: なし | L14: 事業部門・経理／—
A15: 01-02-05 | E15: ● | F15: ★稟議・購買申請の承認（職務権限に基づく） | I15: 購買申請（PR）、購買規程・職務権限 | J15: 購買申請（PR） | K15: 金商法 | L15: 部門長・決裁者／—
A16: 02 | C16: ● | F16: サプライヤー選定・見積 | G16: 候補サプライヤーを探して審査し、見積・提案を比較・交渉して発注先を決める段階 | H16: 発注先の決定
A17: 02-01 | D17: ● | F17: 調達戦略の適用 | G17: 支出を分析し、カテゴリ戦略に沿って調達の方法を決める
A18: 02-01-01 | E18: ● | F18: 支出分析（品目・サプライヤー・部門別） | I18: 調達実績レポート、買掛金（債務） | J18: 支出分析 | K18: なし | L18: 調達企画／—
A19: 02-01-02 | E19: ● | F19: カテゴリ戦略と調達方法の決定（集約・競争入札・随意契約） | I19: 支出分析、サプライヤーリスク情報、購買申請（PR） | J19: カテゴリ戦略 | K19: なし | L19: 調達企画・バイヤー／—
A20: 02-02 | D20: ● | F20: サプライヤー探索・登録 | G20: 候補を探し、新規の取引先を審査してマスタに登録し、適用される取引ルールを判定する
A21: 02-02-01 | E21: ● | F21: 候補サプライヤーの探索・情報収集（RFI） | I21: 購買仕様書、カテゴリ戦略 | J21: 候補サプライヤー情報（RFI） | K21: なし | L21: バイヤー／候補サプライヤー
A22: 02-02-02 | E22: ● | F22: ★新規取引先の審査（与信・反社チェック・インボイス登録番号の確認） | I22: 候補サプライヤー情報（RFI） | J22: 取引先審査記録 | K22: 暴排条例・消費税法 | L22: バイヤー・法務・経理／信用調査会社
A23: 02-02-03 | E23: ● | F23: ★取適法・フリーランス法の適用判定（資本金・従業員数・取引内容） | I23: 取引先審査記録、購買仕様書 | J23: 取引区分判定 | K23: 取適法・フリーランス法 | L23: バイヤー・法務／—
A24: 02-02-04 | E24: ● | F24: サプライヤーマスタの登録（口座・支払条件・登録番号） | I24: 取引先審査記録、取引区分判定 | J24: サプライヤーマスタ | K24: 消費税法 | L24: 購買管理・経理／サプライヤー
A25: 02-02-05 | E25: ● | F25: ★個人事業者のマイナンバーの取得（報酬の支払調書用） | I25: サプライヤーマスタ | J25: 個人事業者の番号情報 | K25: 番号法 | L25: 経理／個人事業者
A26: 02-03 | D26: ● | F26: RFP/RFQ・見積比較 | G26: 見積・提案を依頼して比較し、交渉を経て発注先を選ぶ
A27: 02-03-01 | E27: ● | F27: RFP/RFQの作成・発行 | I27: 購買仕様書、候補サプライヤー情報（RFI） | J27: 見積依頼書（RFP・RFQ） | K27: なし | L27: バイヤー・事業部門／候補サプライヤー
A28: 02-03-02 | E28: ● | F28: 見積・提案の受領と比較評価（総保有コストを含む） | I28: 見積依頼書（RFP・RFQ）、見積書・提案書 | J28: 見積比較・選定記録 | K28: なし | L28: バイヤー・事業部門／—
A29: 02-03-03 | E29: ● | F29: ★価格交渉（価格転嫁の協議を含む） | I29: 見積比較・選定記録、見積書・提案書 | J29: 価格交渉・協議記録 | K29: 取適法 | L29: バイヤー／サプライヤー
A30: 02-03-04 | E30: ● | F30: 発注先の選定・承認（選定理由の記録） | I30: 見積比較・選定記録、価格交渉・協議記録、サプライヤー評価 | J30: 見積比較・選定記録 | K30: なし | L30: バイヤー・決裁者／—
A31: 03 | C31: ● | F31: 契約締結・発注 | G31: 購買契約を結び、取引条件を明示した発注書を送って、受注の確認と納期を管理する段階 | H31: 発注の確定（注文請書の受領）
A32: 03-01 | D32: ● | F32: 契約締結 | G32: 契約書を作成・審査して締結し、単価契約の登録と期限を管理する
A33: 03-01-01 | E33: ● | F33: 契約書の作成・法務審査 | I33: 見積比較・選定記録、価格交渉・協議記録 | J33: 契約書 | K33: 民法 | L33: バイヤー・法務／サプライヤー
A34: 03-01-02 | E34: ● | F34: ★契約の締結（電子契約・印紙税の処理） | I34: 契約書 | J34: 契約書 | K34: 印紙税法・電帳法 | L34: バイヤー・決裁者／サプライヤー
A35: 03-01-03 | E35: ● | F35: 単価契約・カタログの登録 | I35: 契約書、品目マスタ | J35: 単価契約・カタログ | K35: なし | L35: 購買管理／サプライヤー
A36: 03-01-04 | E36: ● | F36: 契約の期限・更新の管理 | I36: 契約書 | J36: 契約書 | K36: 民法 | L36: バイヤー／—
A37: 03-02 | D37: ● | F37: 発注 | G37: 承認された申請・契約から発注書を作り、取引条件を明示して送付し、請書と納期を管理する
A38: 03-02-01 | E38: ● | F38: 発注書（PO）の作成・承認 | I38: 購買申請（PR）、単価契約・カタログ、見積比較・選定記録、サプライヤーマスタ | J38: 発注書（PO） | K38: なし | L38: バイヤー・決裁者／—
A39: 03-02-02 | E39: ● | F39: ★取引条件の明示（給付内容・代金・支払期日など、取適法・フリーランス法） | I39: 発注書（PO）、取引区分判定 | J39: 発注書（PO） | K39: 取適法・フリーランス法 | L39: バイヤー／—
A40: 03-02-03 | E40: ● | F40: 発注書の送付と注文請書の受領 | I40: 発注書（PO） | J40: 注文請書・納期回答 | K40: なし | L40: バイヤー／サプライヤー
...

Sheet ケイパビリティマップ
A1: ビジネス・ケイパビリティマップ（L1〜L3）
A2: 対象：日本の事業会社（直接材・間接材・役務の調達、月末締め・振込払い）／日本の法令・制度基準（取適法・フリーランス法・消費税法〔インボイス〕・電帳法・印紙税法ほか）。1行1項目。L1〜L3列の●がその行のレベル。区分はL1、範囲・アウトカムはL3の項目。★＝日本の制度・商慣行に固有、または特に強調する能力。
A3: ID | B3: L1 | C3: L2 | D3: L3 | E3: ケイパビリティ名 | F3: ケイパビリティの定義 | G3: 区分 | H3: 範囲（含む） | I3: 範囲（含まない） | J3: アウトカム
A4: C01 | B4: ● | E4: 調達戦略・ガバナンス | F4: 支出の実態から調達の方針とカテゴリ戦略を定め、購買規程と取引の適正化で調達全体を統制する能力 | G4: 戦略
A5: C01-01 | C5: ● | E5: 調達戦略・カテゴリ管理 | F5: 支出を分析し、カテゴリごとの調達戦略と購買計画・予算を定める
A6: C01-01-01 | D6: ● | E6: 支出分析 | F6: 全社の購買実績を品目・サプライヤー・部門別に集計し、集約や削減の余地を見つける | H6: 支出の分類、集中度・単価差の分析 | I6: 個別の見積比較（C02-02-02） | J6: 見える化された全社の支出
A7: C01-01-02 | D7: ● | E7: カテゴリ戦略 | F7: カテゴリごとに、集約・長期契約・競争入札などの調達方針を定める | H7: 調達方針、サプライヤー数の方針、契約形態 | I7: 個別案件の発注先選定（C02-02-04） | J7: カテゴリごとに最適な調達方針
A8: C01-01-03 | D8: ● | E8: 購買計画・予算管理 | F8: 年間の購買計画と予算を立て、実績と比較する | H8: 購買計画、予算、予実管理 | I8: 個々の予算引当（C02-01-03） | J8: 予算内に管理された購買
A9: C01-02 | C9: ● | E9: 調達ガバナンス・取引適正化★ | F9: 購買規程と職務権限を定め、取適法・フリーランス法などの取引ルールと持続可能な調達を守らせる
A10: C01-02-01 | D10: ● | E10: 購買規程・職務権限★ | F10: 購買規程と職務権限（金額に応じた承認者・稟議）を定め、改定する | H10: 購買規程、職務権限表、稟議の基準 | I10: 個々の申請の承認（C02-01-03） | J10: 誰が何をどこまで決められるかが明確な購買
A11: C01-02-02 | D11: ● | E11: 取引適正化（取適法・フリーランス法）★ | F11: 中小事業者・フリーランスとの取引で、発注内容の明示・支払期日・禁止行為を守る | H11: 明示事項、60日以内の支払、減額・返品・買いたたき・一方的な代金決定の禁止、手形払いの禁止、社内教育 | I11: 個別取引の適用判定（C05-01-03） | J11: 法令を守った公正な取引
A12: C01-02-03 | D12: ● | E12: 持続可能な調達 | F12: 人権・環境・腐敗防止などの観点で、サプライヤーの取り組みを求め、確認する | H12: 調達方針、サプライヤー行動規範、自己評価 | I12: 経営・供給面のリスク監視（C05-03-01） | J12: 社会から信頼されるサプライチェーン
A13: C02 | B13: ● | E13: 調達・購買管理 | F13: 需要を購買申請にまとめ、サプライヤーを選び、契約を結び、発注するまでを管理する能力 | G13: コア
A14: C02-01 | C14: ● | E14: 需要・購買申請管理 | F14: 需要を把握して仕様にまとめ、購買申請を承認する
A15: C02-01-01 | D15: ● | E15: 所要量計算・補充依頼 | F15: 生産計画・在庫から必要な量を計算し、購買を依頼する | H15: 所要量計算（MRP）、補充点発注、補充依頼 | I15: 生産計画の立案 | J15: 欠品も過剰在庫もない補充
A16: C02-01-02 | D16: ● | E16: 購買仕様作成 | F16: 品質・数量・納期・サービス内容などの要求事項をまとめる | H16: 仕様書、要求事項、作業範囲（SOW） | I16: 見積依頼書の作成（C02-02-02） | J16: 誤解のない購買仕様
A17: C02-01-03 | D17: ● | E17: 購買申請・承認★ | F17: 購買申請を作成し、予算を確認して職務権限に基づき承認する | H17: 購買申請、予算の確認・引当、稟議・承認 | I17: 規程の制定（C01-02-01） | J17: 予算と権限の範囲内で承認された需要
A18: C02-02 | C18: ● | E18: ソーシング | F18: サプライヤーを探し、見積・提案を比較して交渉し、発注先を選ぶ
A19: C02-02-01 | D19: ● | E19: サプライヤー探索（RFI） | F19: 候補となるサプライヤーを探し、情報を集める | H19: 市場調査、情報提供依頼（RFI）、展示会・紹介 | I19: 取引先の審査（C05-01-01） | J19: 十分な数の有力な候補
A20: C02-02-02 | D20: ● | E20: RFP・RFQと見積評価 | F20: 提案依頼・見積依頼を出し、受け取った提案・見積を比較評価する | H20: RFP・RFQの作成、見積・提案の比較、総保有コストの評価 | I20: 価格の交渉（C02-02-03） | J20: 公平に比較された見積・提案
A21: C02-02-03 | D21: ● | E21: 価格交渉・価格転嫁の協議★ | F21: 価格・条件を交渉し、サプライヤーからの価格転嫁の協議に誠実に応じる | H21: 価格交渉、コスト構造の確認、価格転嫁の協議と記録 | I21: 一方的な代金決定の禁止の点検（C01-02-02） | J21: 双方が納得した適正な価格
A22: C02-02-04 | D22: ● | E22: 発注先選定 | F22: 評価に基づいて発注先を決め、選定の理由を記録する | H22: 選定、選定理由の記録、承認 | I22: カテゴリ方針の策定（C01-01-02） | J22: 説明できる発注先の選定
A23: C02-03 | C23: ● | E23: 契約管理★ | F23: 購買契約を作成・審査・締結し、期限と更新を管理する
A24: C02-03-01 | D24: ● | E24: 契約書作成・審査 | F24: ひな形に基づいて契約書を作り、法務が審査する | H24: 基本契約・個別契約、秘密保持契約、法務審査 | I24: 取引条件の明示（C02-04-02） | J24: リスクを抑えた契約条件
A25: C02-03-02 | D25: ● | E25: 契約締結★ | F25: 契約を締結し、印紙税を処理して保管する（電子契約を含む） | H25: 押印・電子署名、印紙税、契約書の保管 | I25: — | J25: 有効に成立し、すぐ取り出せる契約
A26: C02-03-03 | D26: ● | E26: 契約期限・更新管理 | F26: 契約の期限・自動更新・解約通知の期限を管理する | H26: 期限の通知、更新・解約の判断 | I26: — | J26: 期限切れや不要な自動更新のない契約
A27: C02-03-04 | D27: ● | E27: 単価・カタログ管理 | F27: 単価契約・カタログを登録し、購買で使えるようにする | H27: 単価契約の登録、カタログの公開・改定 | I27: 品目マスタ（C06-01-01） | J27: 契約単価で迷わず買える状態
A28: C02-04 | C28: ● | E28: 発注管理★ | F28: 発注書を作成・承認して送付し、請書・納期・変更を管理する
A29: C02-04-01 | D29: ● | E29: 発注書作成・承認 | F29: 承認された申請・契約から発注書を作成し、承認する | H29: 発注書、発注承認 | I29: 購買申請の承認（C02-01-03） | J29: 正しい内容で承認された発注
A30: C02-04-02 | D30: ● | E30: 取引条件の明示★ | F30: 給付の内容・代金・支払期日などの取引条件を、発注時に書面または電磁的方法で明示する | H30: 取適法・フリーランス法の明示事項、明示の記録の保存 | I30: 契約書の作成（C02-03-01） | J30: 条件が明確で紛争のない発注
A31: C02-04-03 | D31: ● | E31: 発注送付・請書管理 | F31: 発注書を送付し、注文請書（受注の確認）を受け取る | H31: 送付（EDI・ポータル・メール）、注文請書 | I31: — | J31: 双方が確認した発注
A32: C02-04-04 | D32: ● | E32: 納期管理・発注変更 | F32: 納期回答を管理し、発注の変更・取消を協議して行う | H32: 納期回答、納期フォロー、変更・取消の協議 | I32: 入荷予定の管理（C03-01-01） | J32: 計画どおりの納入
A33: C03 | B33: ● | E33: 受入・ロジスティクス | F33: 納品物を受け入れて検査・検収し、在庫や資産として計上する能力 | G33: コア
A34: C03-01 | C34: ● | E34: 入荷・受入管理 | F34: 入荷を予定どおり受け入れ、数量と品質を確認する
A35: C03-01-01 | D35: ● | E35: 入荷予定管理 | F35: 発注と納期回答から入荷予定を作り、受入を準備する | H35: 入荷予定、事前出荷通知 | I35: 納期の調整（C02-04-04） | J35: 準備が整った受入
A36: C03-01-02 | D36: ● | E36: 受入・数量確認 | F36: 納品物を受け取り、納品書・発注書と数量・品目を照合する | H36: 荷受け、納品書との照合、受領の記録 | I36: 品質の検査（C03-01-03） | J36: 正しく記録された受入
A37: C03-01-03 | D37: ● | E37: 受入検査 | F37: 仕様・品質の基準に照らして受入品を検査する | H37: 検査の基準、抜取検査、合否判定 | I37: サービスの検収（C03-02-02） | J37: 基準を満たした受入品
A38: C03-02 | C38: ● | E38: 検収管理★ | F38: 物品・役務の給付を確認して検収し、不適合品を処理する
A39: C03-02-01 | D39: ● | E39: 物品の検収 | F39: 受入検査の結果に基づいて物品を検収する | H39: 検収の判定、検収書 | I39: — | J39: 期日どおりの物品の検収
A40: C03-02-02 | D40: ● | E40: 役務・サービスの検収 | F40: 作業完了報告・成果物を確認して役務を検収する | H40: 作業完了報告、成果物の確認、検収書 | I40: — | J40: 給付の内容が確認された役務
...

Sheet ケイパビリティレベル
A1: ケイパビリティの成熟度レベル（L2ごとの定義）
A2: 対象：日本の事業会社（直接材・間接材・役務の調達、月末締め・振込払い）／日本の法令・制度基準（取適法・フリーランス法・消費税法〔インボイス〕・電帳法・印紙税法ほか）。評価の対象はL2。法令上の最低水準：取引適正化・税務・内部統制などの法令順守が関わるL2はレベル3が事実上の最低水準。
A3: レベル | B3: 名称 | C3: 共通定義
A4: 1 | B4: 初期 | C4: 属人的・場当たり的。成果が個人に依存し、再現できない
A5: 2 | B5: 管理された | C5: 部門・拠点ごとに計画・管理され、再現できる。ただし方法は部門・拠点で異なる
A6: 3 | B6: 定義された | C6: 全社標準のプロセス・役割・データ定義があり、一貫して運用される
A7: 4 | B7: 定量的に管理された | C7: 指標で成果・品質を測定し、データに基づいて管理・予測する
A8: 5 | B8: 最適化された | C8: 継続的な改善と先進的な手法により、変化に先回りし、先進的な水準にある
A10: L2 ID | B10: ケイパビリティL1 | C10: ケイパビリティL2 | D10: 法令上の最低水準 | E10: レベル1 初期 | F10: レベル2 管理された | G10: レベル3 定義された | H10: レベル4 定量的に管理された | I10: レベル5 最適化された
A11: C01-01 | B11: 調達戦略・ガバナンス | C11: 調達戦略・カテゴリ管理 | D11: — | E11: 支出の全体像を把握しておらず、部門ごとに個別に購入する | F11: 主要な品目について年度ごとに購買計画を立てる | G11: 全社の支出を分析し、カテゴリ戦略と購買計画を全社共通の方法で立てる | H11: カテゴリ別のコスト削減・集約の効果を指標で管理する | I11: 市場・技術・リスクの変化に先回りして、調達戦略を組み替える
A12: C01-02 | C12: 調達ガバナンス・取引適正化★ | D12: レベル3（取適法・フリーランス法） | E12: 購買のルールがなく、担当者の判断で発注する | F12: 購買規程はあるが、例外が多く運用が部門ごと | G12: 全社標準の購買規程・職務権限・取引適正化のルールを持ち、一貫して運用する | H12: 規程違反・取適法の違反の兆候を指標で監視する | I12: サプライヤーと公正で持続可能な取引関係を先回りして築く
A13: C02-01 | B13: 調達・購買管理 | C13: 需要・購買申請管理 | D13: — | E13: 口頭・メールで購入を依頼し、記録が残らない | F13: 申請書で依頼するが、仕様や承認の基準がばらばら | G13: 全社標準の購買申請と承認フローで、仕様・予算・承認を一貫して管理する | H13: 申請から承認までの期間と差し戻しを指標で管理する | I13: 需要を予測し、申請を待たずに先回りして補充する
A14: C02-02 | C14: ソーシング | D14: レベル3（取適法） | E14: いつもの業者に随意で発注する | F14: 一定金額以上は相見積もりを取る | G14: 全社標準のRFI・RFP・RFQと評価基準で発注先を選び、理由を記録する | H14: 競争の度合い・削減額・選定期間を指標で管理する | I14: 市場の情報を常に集め、交渉と選定を先回りして行う
A15: C02-03 | C15: 契約管理★ | D15: レベル3（民法・印紙税法） | E15: 契約書がないまま取引する、または所在が分からない | F15: 重要な取引は契約書を結ぶが、管理が部門ごと | G15: 全社標準のひな形・法務審査・締結・保管の手順で契約を一元管理する | H15: 契約の期限切れ・条件の不履行を指標で監視する | I15: 契約の条件データを活用し、交渉と更新を先回りして行う
A16: C02-04 | C16: 発注管理★ | D16: レベル3（取適法・フリーランス法） | E16: 電話や口頭で発注し、記録が残らない | F16: 発注書を出すが、明示事項や承認が不十分 | G16: 全社標準の発注書で取引条件を明示し、承認・送付・変更を一貫して管理する | H16: 納期遵守率・発注の変更率を指標で管理する | I16: サプライヤーと発注・納期の情報を自動でやりとりする
A17: C03-01 | B17: 受入・ロジスティクス | C17: 入荷・受入管理 | D17: — | E17: 入荷の予定がなく、届いてから確認する | F17: 拠点ごとに入荷と受入検査を行う | G17: 全社標準の受入・検査の手順で、発注・納品書と照合して記録する | H17: 受入の誤り・検査の不合格率を指標で管理する | I17: 事前出荷通知と自動照合で、受入を先回りして準備する
A18: C03-02 | C18: 検収管理★ | D18: レベル3（取適法） | E18: 検収の基準がなく、支払の直前に確認する | F18: 検収書を発行するが、役務の検収の基準がばらばら | G18: 全社標準の検収基準・手順で、物品と役務を期日どおりに検収する | H18: 検収の遅れ・返品の件数を指標で管理する | I18: 給付の完了を自動で把握し、遅れなく検収する
A19: C03-03 | C19: 在庫・資産計上 | D19: レベル3（会社法・法人税法） | E19: 在庫・資産の計上が遅れ、実物と合わない | F19: 拠点ごとに在庫と資産を計上する | G19: 受入・検収と連動して、在庫と固定資産を正確に計上する | H19: 在庫差異・資産の計上漏れを指標で管理する | I19: 計上が自動化され、実物と帳簿が常に一致する
A20: C04-01 | B20: 財務・債務管理 | C20: 請求書受領・照合★ | D20: レベル3（消費税法・電帳法） | E20: 紙の請求書を手作業で確認する | F20: 請求書を電子化するが、照合は担当者の目視 | G20: インボイスの要件確認と3-Wayマッチングを全社標準の手順・システムで行う | H20: 照合の自動化率・差異の件数を指標で管理する | I20: 電子請求書（デジタルインボイス）で、受領から照合まで自動で完了する
A21: C04-02 | C21: 支払管理★ | D21: レベル3（取適法・フリーランス法） | E21: 支払が遅れる、または二重に支払う | F21: 月次の締めで支払予定を作るが、期日の管理が手作業 | G21: 全社標準の締め・支払サイト・承認で、法定の期日内に確実に支払う | H21: 期日遵守率・二重払いを指標で管理する | I21: 資金計画と連動して支払を先回りして最適化する
A22: C04-03 | C22: 債務会計・税務★ | D22: レベル3（消費税法・所得税法・電帳法） | E22: 仕訳や税区分の誤りが多い | F22: 経理担当者が確認して修正する | G22: 全社標準の仕訳ルール・税区分・保存方法で、正しく処理する | H22: 修正仕訳・税務の指摘を指標で管理する | I22: 取引データから仕訳と税務処理が自動で行われる
A23: C05-01 | B23: サプライヤー管理 | C23: サプライヤー登録・審査★ | D23: レベル3（取適法・暴排条例） | E23: 審査をせずに取引を始める | F23: 新規取引先の審査を部門ごとに行う | G23: 全社標準の審査（与信・反社・インボイス登録）と登録の手順を持つ | H23: 審査の期間・登録情報の誤りを指標で管理する | I23: 外部データで取引先の状態を常に監視し、先回りして対応する
A24: C05-02 | C24: サプライヤー評価・関係管理 | D24: — | E24: サプライヤーを評価していない | F24: 問題が起きたときに個別に評価する | G24: 全社共通の基準（品質・納期・価格・対応）で定期的に評価する | H24: 評価結果を発注先の選定と改善に定量的に反映する | I24: 戦略的なサプライヤーと共同で価値を生み出す
A25: C05-03 | C25: サプライヤーリスク管理 | D25: — | E25: 問題が起きてから対応する | F25: 主要なサプライヤーのリスクを年1回確認する | G25: 全社標準の方法でリスクを評価・監視し、重要品目の代替策を持つ | H25: リスクの指標を監視し、事前に手を打つ | I25: サプライチェーン全体の強靭性を先回りして設計する
A26: C06-01 | B26: 調達基盤 | C26: 調達マスタ・データ管理 | D26: — | E26: 品目の登録が重複し、名称がばらばら | F26: 部門ごとにマスタを管理する | G26: 全社標準の品目分類とマスタ管理で、データの品質を保つ | H26: マスタの重複・誤りを指標で管理する | I26: マスタを全社のデータ資産として活用する
A27: C06-02 | C27: 調達分析・レポーティング | D27: — | E27: 集計が手作業で、時間がかかる | F27: 定型のレポートを定期的に作成する | G27: 全社共通の定義で調達データを集約し、ダッシュボードで提供する | H27: 削減効果・プロセスの効率を指標で検証する | I27: 予測と要因分析で、調達の意思決定を先回りして支援する
A28: C06-03 | C28: 内部統制・監査対応 | D28: レベル3（金商法〔J-SOX〕） | E28: 一人で発注から支払までできてしまう | F28: 職務分掌を定めているが、点検が不十分 | G28: 職務分掌・アクセス権・証跡を全社標準で管理し、定期的に点検する | H28: 統制の不備を指標で監視し、早期に是正する | I28: データ分析で不正・誤りを先回りして検知する

Sheet VS×ケイパビリティ関係
A1: VS×ケイパビリティ関係（正本：VS L4 × ケイパビリティL3）
A2: 1行1関係。区分は「主」（そのL4の中核）か「支援」（下支え）。マトリクスはこのシートから数式で集計する。関係の追加・変更はこのシートで行う。灰色の列は数式（編集しない）。
A3: VS L4 ID | B3: VS L4 | C3: ケイパビリティL3 ID | D3: ケイパビリティL3 | E3: 区分 | F3: VS L3 ID | G3: ケイパビリティL2 ID
A4: 01-01-01 | B4: 年間購買計画・購買予算の策定 | C4: C01-01-03 | D4: =IFERROR(INDEX(ケイパビリティマップ!$E:$E,MATCH(C4,ケイパビリティマップ!$A:$A,0)),"（IDなし）") | E4: 主 | F4: =LEFT(A4,5) | G4: =LEFT(C4,6)
A5: 01-01-02 | B5: 所要量計算（MRP）による購買依頼（直接材） | C5: C02-01-01 | D5: =IFERROR(INDEX(ケイパビリティマップ!$E:$E,MATCH(C5,ケイパビリティマップ!$A:$A,0)),"（IDなし）") | E5: 主 | F5: =LEFT(A5,5) | G5: =LEFT(C5,6)
A6: 01-01-03 | B6: 補充点による補充依頼（消耗品・MRO） | C6: C02-01-01 | D6: =IFERROR(INDEX(ケイパビリティマップ!$E:$E,MATCH(C6,ケイパビリティマップ!$A:$A,0)),"（IDなし）") | E6: 主 | F6: =LEFT(A6,5) | G6: =LEFT(C6,6)
A7: 01-01-03 | B7: 補充点による補充依頼（消耗品・MRO） | C7: C03-03-01 | D7: =IFERROR(INDEX(ケイパビリティマップ!$E:$E,MATCH(C7,ケイパビリティマップ!$A:$A,0)),"（IDなし）") | E7: 支援 | F7: =LEFT(A7,5) | G7: =LEFT(C7,6)
A8: 01-02-01 | B8: 購買仕様・要求事項の作成（品質・数量・納期・作業範囲） | C8: C02-01-02 | D8: =IFERROR(INDEX(ケイパビリティマップ!$E:$E,MATCH(C8,ケイパビリティマップ!$A:$A,0)),"（IDなし）") | E8: 主 | F8: =LEFT(A8,5) | G8: =LEFT(C8,6)
A9: 01-02-02 | B9: 既存契約・カタログからの選択（単価契約品） | C9: C02-01-03 | D9: =IFERROR(INDEX(ケイパビリティマップ!$E:$E,MATCH(C9,ケイパビリティマップ!$A:$A,0)),"（IDなし）") | E9: 主 | F9: =LEFT(A9,5) | G9: =LEFT(C9,6)
A10: 01-02-02 | B10: 既存契約・カタログからの選択（単価契約品） | C10: C02-03-04 | D10: =IFERROR(INDEX(ケイパビリティマップ!$E:$E,MATCH(C10,ケイパビリティマップ!$A:$A,0)),"（IDなし）") | E10: 支援 | F10: =LEFT(A10,5) | G10: =LEFT(C10,6)
A11: 01-02-03 | B11: 購買申請（PR）の作成 | C11: C02-01-03 | D11: =IFERROR(INDEX(ケイパビリティマップ!$E:$E,MATCH(C11,ケイパビリティマップ!$A:$A,0)),"（IDなし）") | E11: 主 | F11: =LEFT(A11,5) | G11: =LEFT(C11,6)
A12: 01-02-04 | B12: 予算の確認・引当 | C12: C02-01-03 | D12: =IFERROR(INDEX(ケイパビリティマップ!$E:$E,MATCH(C12,ケイパビリティマップ!$A:$A,0)),"（IDなし）") | E12: 主 | F12: =LEFT(A12,5) | G12: =LEFT(C12,6)
A13: 01-02-04 | B13: 予算の確認・引当 | C13: C01-01-03 | D13: =IFERROR(INDEX(ケイパビリティマップ!$E:$E,MATCH(C13,ケイパビリティマップ!$A:$A,0)),"（IDなし）") | E13: 支援 | F13: =LEFT(A13,5) | G13: =LEFT(C13,6)
A14: 01-02-05 | B14: ★稟議・購買申請の承認（職務権限に基づく） | C14: C02-01-03 | D14: =IFERROR(INDEX(ケイパビリティマップ!$E:$E,MATCH(C14,ケイパビリティマップ!$A:$A,0)),"（IDなし）") | E14: 主 | F14: =LEFT(A14,5) | G14: =LEFT(C14,6)
A15: 01-02-05 | B15: ★稟議・購買申請の承認（職務権限に基づく） | C15: C01-02-01 | D15: =IFERROR(INDEX(ケイパビリティマップ!$E:$E,MATCH(C15,ケイパビリティマップ!$A:$A,0)),"（IDなし）") | E15: 支援 | F15: =LEFT(A15,5) | G15: =LEFT(C15,6)
... A82: 05-04-07 | B82: 品目・取引先マスタの点検と重複の解消 | C82: C05-01-02 | D82: =IFERROR(INDEX(ケイパビリティマップ!$E:$E,MATCH(C82,ケイパビリティマップ!$A:$A,0)),"（IDなし）") | E82: 支援 | F82: =LEFT(A82,5) | G82: =LEFT(C82,6)
D83: =IF(C83="","",IFERROR(INDEX(ケイパビリティマップ!$E:$E,MATCH(C83,ケイパビリティマップ!$A:$A,0)),"（IDなし）")) | F83: =IF(A83="","",LEFT(A83,5)) | G83: =IF(C83="","",LEFT(C83,6))
D84: =IF(C84="","",IFERROR(INDEX(ケイパビリティマップ!$E:$E,MATCH(C84,ケイパビリティマップ!$A:$A,0)),"（IDなし）")) | F84: =IF(A84="","",LEFT(A84,5)) | G84: =IF(C84="","",LEFT(C84,6))
D85: =IF(C85="","",IFERROR(INDEX(ケイパビリティマップ!$E:$E,MATCH(C85,ケイパビリティマップ!$A:$A,0)),"（IDなし）")) | F85: =IF(A85="","",LEFT(A85,5)) | G85: =IF(C85="","",LEFT(C85,6))
D86: =IF(C86="","",IFERROR(INDEX(ケイパビリティマップ!$E:$E,MATCH(C86,ケイパビリティマップ!$A:$A,0)),"（IDなし）")) | F86: =IF(A86="","",LEFT(A86,5)) | G86: =IF(C86="","",LEFT(C86,6))
D87: =IF(C87="","",IFERROR(INDEX(ケイパビリティマップ!$E:$E,MATCH(C87,ケイパビリティマップ!$A:$A,0)),"（IDなし）")) | F87: =IF(A87="","",LEFT(A87,5)) | G87: =IF(C87="","",LEFT(C87,6))
D88: =IF(C88="","",IFERROR(INDEX(ケイパビリティマップ!$E:$E,MATCH(C88,ケイパビリティマップ!$A:$A,0)),"（IDなし）")) | F88: =IF(A88="","",LEFT(A88,5)) | G88: =IF(C88="","",LEFT(C88,6))
D89: =IF(C89="","",IFERROR(INDEX(ケイパビリティマップ!$E:$E,MATCH(C89,ケイパビリティマップ!$A:$A,0)),"（IDなし）")) | F89: =IF(A89="","",LEFT(A89,5)) | G89: =IF(C89="","",LEFT(C89,6))
D90: =IF(C90="","",IFERROR(INDEX(ケイパビリティマップ!$E:$E,MATCH(C90,ケイパビリティマップ!$A:$A,0)),"（IDなし）")) | F90: =IF(A90="","",LEFT(A90,5)) | G90: =IF(C90="","",LEFT(C90,6))
D91: =IF(C91="","",IFERROR(INDEX(ケイパビリティマップ!$E:$E,MATCH(C91,ケイパビリティマップ!$A:$A,0)),"（IDなし）")) | F91: =IF(A91="","",LEFT(A91,5)) | G91: =IF(C91="","",LEFT(C91,6))
D92: =IF(C92="","",IFERROR(INDEX(ケイパビリティマップ!$E:$E,MATCH(C92,ケイパビリティマップ!$A:$A,0)),"（IDなし）")) | F92: =IF(A92="","",LEFT(A92,5)) | G92: =IF(C92="","",LEFT(C92,6))
D93: =IF(C93="","",IFERROR(INDEX(ケイパビリティマップ!$E:$E,MATCH(C93,ケイパビリティマップ!$A:$A,0)),"（IDなし）")) | F93: =IF(A93="","",LEFT(A93,5)) | G93: =IF(C93="","",LEFT(C93,6))
D94: =IF(C94="","",IFERROR(INDEX(ケイパビリティマップ!$E:$E,MATCH(C94,ケイパビリティマップ!$A:$A,0)),"（IDなし）")) | F94: =IF(A94="","",LEFT(A94,5)) | G94: =IF(C94="","",LEFT(C94,6))
... D282: =IF(C282="","",IFERROR(INDEX(ケイパビリティマップ!$E:$E,MATCH(C282,ケイパビリティマップ!$A:$A,0)),"（IDなし）")) | F282: =IF(A282="","",LEFT(A282,5)) | G282: =IF(C282="","",LEFT(C282,6))

Sheet VS×ケイパビリティ
A1: バリューストリーム×ケイパビリティマップ（行：バリューストリームL3 × 列：ケイパビリティL2）
A2: ●＝主（配下のL4×L3の関係に「主」が1つ以上） ○＝支援のみ 空欄＝関係なし。各セルは「VS×ケイパビリティ関係」シートから数式で集計（直接入力しない）。
A4: VS L2 | B4: L3 ID | C4: VS L3 | D4: C01 調達戦略・ガバナンス | F4: C02 調達・購買管理 | J4: C03 受入・ロジスティクス | M4: C04 財務・債務管理 | P4: C05 サプライヤー管理 | S4: C06 調達基盤 | V4: ●の数 | W4: ○の数
D5: C01-01 | E5: C01-02 | F5: C02-01 | G5: C02-02 | H5: C02-03 | I5: C02-04 | J5: C03-01 | K5: C03-02 | L5: C03-03 | M5: C04-01 | N5: C04-02 | O5: C04-03 | P5: C05-01 | Q5: C05-02 | R5: C05-03 | S5: C06-01 | T5: C06-02 | U5: C06-03
D6: 調達戦略・カテゴリ管理 | E6: 調達ガバナンス・取引適正化★ | F6: 需要・購買申請管理 | G6: ソーシング | H6: 契約管理★ | I6: 発注管理★ | J6: 入荷・受入管理 | K6: 検収管理★ | L6: 在庫・資産計上 | M6: 請求書受領・照合★ | N6: 支払管理★ | O6: 債務会計・税務★ | P6: サプライヤー登録・審査★ | Q6: サプライヤー評価・関係管理 | R6: サプライヤーリスク管理 | S6: 調達マスタ・データ管理 | T6: 調達分析・レポーティング | U6: 内部統制・監査対応
A7: 01 需要特定・購買申請 | B7: 01-01 | C7: 需要の把握・購買計画 | D7: =IF(COUNTIFS('VS×ケイパビリティ関係'!$F$4:$F$282,$B7,'VS×ケイパビリティ関係'!$G$4:$G$282,D$5,'VS×ケイパビリティ関係'!$E$4:$E$282,"主")>0,"●",IF(COUNTIFS('VS×ケイパビリティ関係'!$F$4:$F$282,$B7,'VS×ケイパビリティ関係'!$G$4:$G$282,D$5,'VS×ケイパビリティ関係'!$E$4:$E$282,"支援")>0,"○","")) | E7: =IF(COUNTIFS('VS×ケイパビリティ関係'!$F$4:$F$282,$B7,'VS×ケイパビリティ関係'!$G$4:$G$282,E$5,'VS×ケイパビリティ関係'!$E$4:$E$282,"主")>0,"●",IF(COUNTIFS('VS×ケイパビリティ関係'!$F$4:$F$282,$B7,'VS×ケイパビリティ関係'!$G$4:$G$282,E$5,'VS×ケイパビリティ関係'!$E$4:$E$282,"支援")>0,"○","")) | F7: =IF(COUNTIFS('VS×ケイパビリティ関係'!$F$4:$F$282,$B7,'VS×ケイパビリティ関係'!$G$4:$G$282,F$5,'VS×ケイパビリティ関係'!$E$4:$E$282,"主")>0,"●",IF(COUNTIFS('VS×ケイパビリティ関係'!$F$4:$F$282,$B7,'VS×ケイパビリティ関係'!$G$4:$G$282,F$5,'VS×ケイパビリティ関係'!$E$4:$E$282,"支援")>0,"○","")) | G7: =IF(COUNTIFS('VS×ケイパビリティ関係'!$F$4:$F$282,$B7,'VS×ケイパビリティ関係'!$G$4:$G$282,G$5,'VS×ケイパビリティ関係'!$E$4:$E$282,"主")>0,"●",IF(COUNTIFS('VS×ケイパビリティ関係'!$F$4:$F$282,$B7,'VS×ケイパビリティ関係'!$G$4:$G$282,G$5,'VS×ケイパビリティ関係'!$E$4:$E$282,"支援")>0,"○","")) | H7: =IF(COUNTIFS('VS×ケイパビリティ関係'!$F$4:$F$282,$B7,'VS×ケイパビリティ関係'!$G$4:$G$282,H$5,'VS×ケイパビリティ関係'!$E$4:$E$282,"主")>0,"●",IF(COUNTIFS('VS×ケイパビリティ関係'!$F$4:$F$282,$B7,'VS×ケイパビリティ関係'!$G$4:$G$282,H$5,'VS×ケイパビリティ関係'!$E$4:$E$282,"支援")>0,"○","")) | I7: =IF(COUNTIFS('VS×ケイパビリティ関係'!$F$4:$F$282,$B7,'VS×ケイパビリティ関係'!$G$4:$G$282,I$5,'VS×ケイパビリティ関係'!$E$4:$E$282,"主")>0,"●",IF(COUNTIFS('VS×ケイパビリティ関係'!$F$4:$F$282,$B7,'VS×ケイパビリティ関係'!$G$4:$G$282,I$5,'VS×ケイパビリティ関係'!$E$4:$E$282,"支援")>0,"○","")) | J7: =IF(COUNTIFS('VS×ケイパビリティ関係'!$F$4:$F$282,$B7,'VS×ケイパビリティ関係'!$G$4:$G$282,J$5,'VS×ケイパビリティ関係'!$E$4:$E$282,"主")>0,"●",IF(COUNTIFS('VS×ケイパビリティ関係'!$F$4:$F$282,$B7,'VS×ケイパビリティ関係'!$G$4:$G$282,J$5,'VS×ケイパビリティ関係'!$E$4:$E$282,"支援")>0,"○","")) | K7: =IF(COUNTIFS('VS×ケイパビリティ関係'!$F$4:$F$282,$B7,'VS×ケイパビリティ関係'!$G$4:$G$282,K$5,'VS×ケイパビリティ関係'!$E$4:$E$282,"主")>0,"●",IF(COUNTIFS('VS×ケイパビリティ関係'!$F$4:$F$282,$B7,'VS×ケイパビリティ関係'!$G$4:$G$282,K$5,'VS×ケイパビリティ関係'!$E$4:$E$282,"支援")>0,"○","")) | ... U7: =IF(COUNTIFS('VS×ケイパビリティ関係'!$F$4:$F$282,$B7,'VS×ケイパビリティ関係'!$G$4:$G$282,U$5,'VS×ケイパビリティ関係'!$E$4:$E$282,"主")>0,"●",IF(COUNTIFS('VS×ケイパビリティ関係'!$F$4:$F$282,$B7,'VS×ケイパビリティ関係'!$G$4:$G$282,U$5,'VS×ケイパビリティ関係'!$E$4:$E$282,"支援")>0,"○","")) | V7: =COUNTIF(D7:U7,"●") | W7: =COUNTIF(D7:U7,"○")
B8: 01-02 | C8: 仕様策定・購買申請作成 | D8: =IF(COUNTIFS('VS×ケイパビリティ関係'!$F$4:$F$282,$B8,'VS×ケイパビリティ関係'!$G$4:$G$282,D$5,'VS×ケイパビリティ関係'!$E$4:$E$282,"主")>0,"●",IF(COUNTIFS('VS×ケイパビリティ関係'!$F$4:$F$282,$B8,'VS×ケイパビリティ関係'!$G$4:$G$282,D$5,'VS×ケイパビリティ関係'!$E$4:$E$282,"支援")>0,"○","")) | E8: =IF(COUNTIFS('VS×ケイパビリティ関係'!$F$4:$F$282,$B8,'VS×ケイパビリティ関係'!$G$4:$G$282,E$5,'VS×ケイパビリティ関係'!$E$4:$E$282,"主")>0,"●",IF(COUNTIFS('VS×ケイパビリティ関係'!$F$4:$F$282,$B8,'VS×ケイパビリティ関係'!$G$4:$G$282,E$5,'VS×ケイパビリティ関係'!$E$4:$E$282,"支援")>0,"○","")) | F8: =IF(COUNTIFS('VS×ケイパビリティ関係'!$F$4:$F$282,$B8,'VS×ケイパビリティ関係'!$G$4:$G$282,F$5,'VS×ケイパビリティ関係'!$E$4:$E$282,"主")>0,"●",IF(COUNTIFS('VS×ケイパビリティ関係'!$F$4:$F$282,$B8,'VS×ケイパビリティ関係'!$G$4:$G$282,F$5,'VS×ケイパビリティ関係'!$E$4:$E$282,"支援")>0,"○","")) | G8: =IF(COUNTIFS('VS×ケイパビリティ関係'!$F$4:$F$282,$B8,'VS×ケイパビリティ関係'!$G$4:$G$282,G$5,'VS×ケイパビリティ関係'!$E$4:$E$282,"主")>0,"●",IF(COUNTIFS('VS×ケイパビリティ関係'!$F$4:$F$282,$B8,'VS×ケイパビリティ関係'!$G$4:$G$282,G$5,'VS×ケイパビリティ関係'!$E$4:$E$282,"支援")>0,"○","")) | H8: =IF(COUNTIFS('VS×ケイパビリティ関係'!$F$4:$F$282,$B8,'VS×ケイパビリティ関係'!$G$4:$G$282,H$5,'VS×ケイパビリティ関係'!$E$4:$E$282,"主")>0,"●",IF(COUNTIFS('VS×ケイパビリティ関係'!$F$4:$F$282,$B8,'VS×ケイパビリティ関係'!$G$4:$G$282,H$5,'VS×ケイパビリティ関係'!$E$4:$E$282,"支援")>0,"○","")) | I8: =IF(COUNTIFS('VS×ケイパビリティ関係'!$F$4:$F$282,$B8,'VS×ケイパビリティ関係'!$G$4:$G$282,I$5,'VS×ケイパビリティ関係'!$E$4:$E$282,"主")>0,"●",IF(COUNTIFS('VS×ケイパビリティ関係'!$F$4:$F$282,$B8,'VS×ケイパビリティ関係'!$G$4:$G$282,I$5,'VS×ケイパビリティ関係'!$E$4:$E$282,"支援")>0,"○","")) | J8: =IF(COUNTIFS('VS×ケイパビリティ関係'!$F$4:$F$282,$B8,'VS×ケイパビリティ関係'!$G$4:$G$282,J$5,'VS×ケイパビリティ関係'!$E$4:$E$282,"主")>0,"●",IF(COUNTIFS('VS×ケイパビリティ関係'!$F$4:$F$282,$B8,'VS×ケイパビリティ関係'!$G$4:$G$282,J$5,'VS×ケイパビリティ関係'!$E$4:$E$282,"支援")>0,"○","")) | K8: =IF(COUNTIFS('VS×ケイパビリティ関係'!$F$4:$F$282,$B8,'VS×ケイパビリティ関係'!$G$4:$G$282,K$5,'VS×ケイパビリティ関係'!$E$4:$E$282,"主")>0,"●",IF(COUNTIFS('VS×ケイパビリティ関係'!$F$4:$F$282,$B8,'VS×ケイパビリティ関係'!$G$4:$G$282,K$5,'VS×ケイパビリティ関係'!$E$4:$E$282,"支援")>0,"○","")) | ... U8: =IF(COUNTIFS('VS×ケイパビリティ関係'!$F$4:$F$282,$B8,'VS×ケイパビリティ関係'!$G$4:$G$282,U$5,'VS×ケイパビリティ関係'!$E$4:$E$282,"主")>0,"●",IF(COUNTIFS('VS×ケイパビリティ関係'!$F$4:$F$282,$B8,'VS×ケイパビリティ関係'!$G$4:$G$282,U$5,'VS×ケイパビリティ関係'!$E$4:$E$282,"支援")>0,"○","")) | V8: =COUNTIF(D8:U8,"●") | W8: =COUNTIF(D8:U8,"○")
A9: 02 サプライヤー選定・見積 | B9: 02-01 | C9: 調達戦略の適用 | D9: =IF(COUNTIFS('VS×ケイパビリティ関係'!$F$4:$F$282,$B9,'VS×ケイパビリティ関係'!$G$4:$G$282,D$5,'VS×ケイパビリティ関係'!$E$4:$E$282,"主")>0,"●",IF(COUNTIFS('VS×ケイパビリティ関係'!$F$4:$F$282,$B9,'VS×ケイパビリティ関係'!$G$4:$G$282,D$5,'VS×ケイパビリティ関係'!$E$4:$E$282,"支援")>0,"○","")) | E9: =IF(COUNTIFS('VS×ケイパビリティ関係'!$F$4:$F$282,$B9,'VS×ケイパビリティ関係'!$G$4:$G$282,E$5,'VS×ケイパビリティ関係'!$E$4:$E$282,"主")>0,"●",IF(COUNTIFS('VS×ケイパビリティ関係'!$F$4:$F$282,$B9,'VS×ケイパビリティ関係'!$G$4:$G$282,E$5,'VS×ケイパビリティ関係'!$E$4:$E$282,"支援")>0,"○","")) | F9: =IF(COUNTIFS('VS×ケイパビリティ関係'!$F$4:$F$282,$B9,'VS×ケイパビリティ関係'!$G$4:$G$282,F$5,'VS×ケイパビリティ関係'!$E$4:$E$282,"主")>0,"●",IF(COUNTIFS('VS×ケイパビリティ関係'!$F$4:$F$282,$B9,'VS×ケイパビリティ関係'!$G$4:$G$282,F$5,'VS×ケイパビリティ関係'!$E$4:$E$282,"支援")>0,"○","")) | G9: =IF(COUNTIFS('VS×ケイパビリティ関係'!$F$4:$F$282,$B9,'VS×ケイパビリティ関係'!$G$4:$G$282,G$5,'VS×ケイパビリティ関係'!$E$4:$E$282,"主")>0,"●",IF(COUNTIFS('VS×ケイパビリティ関係'!$F$4:$F$282,$B9,'VS×ケイパビリティ関係'!$G$4:$G$282,G$5,'VS×ケイパビリティ関係'!$E$4:$E$282,"支援")>0,"○","")) | H9: =IF(COUNTIFS('VS×ケイパビリティ関係'!$F$4:$F$282,$B9,'VS×ケイパビリティ関係'!$G$4:$G$282,H$5,'VS×ケイパビリティ関係'!$E$4:$E$282,"主")>0,"●",IF(COUNTIFS('VS×ケイパビリティ関係'!$F$4:$F$282,$B9,'VS×ケイパビリティ関係'!$G$4:$G$282,H$5,'VS×ケイパビリティ関係'!$E$4:$E$282,"支援")>0,"○","")) | I9: =IF(COUNTIFS('VS×ケイパビリティ関係'!$F$4:$F$282,$B9,'VS×ケイパビリティ関係'!$G$4:$G$282,I$5,'VS×ケイパビリティ関係'!$E$4:$E$282,"主")>0,"●",IF(COUNTIFS('VS×ケイパビリティ関係'!$F$4:$F$282,$B9,'VS×ケイパビリティ関係'!$G$4:$G$282,I$5,'VS×ケイパビリティ関係'!$E$4:$E$282,"支援")>0,"○","")) | J9: =IF(COUNTIFS('VS×ケイパビリティ関係'!$F$4:$F$282,$B9,'VS×ケイパビリティ関係'!$G$4:$G$282,J$5,'VS×ケイパビリティ関係'!$E$4:$E$282,"主")>0,"●",IF(COUNTIFS('VS×ケイパビリティ関係'!$F$4:$F$282,$B9,'VS×ケイパビリティ関係'!$G$4:$G$282,J$5,'VS×ケイパビリティ関係'!$E$4:$E$282,"支援")>0,"○","")) | K9: =IF(COUNTIFS('VS×ケイパビリティ関係'!$F$4:$F$282,$B9,'VS×ケイパビリティ関係'!$G$4:$G$282,K$5,'VS×ケイパビリティ関係'!$E$4:$E$282,"主")>0,"●",IF(COUNTIFS('VS×ケイパビリティ関係'!$F$4:$F$282,$B9,'VS×ケイパビリティ関係'!$G$4:$G$282,K$5,'VS×ケイパビリティ関係'!$E$4:$E$282,"支援")>0,"○","")) | ... U9: =IF(COUNTIFS('VS×ケイパビリティ関係'!$F$4:$F$282,$B9,'VS×ケイパビリティ関係'!$G$4:$G$282,U$5,'VS×ケイパビリティ関係'!$E$4:$E$282,"主")>0,"●",IF(COUNTIFS('VS×ケイパビリティ関係'!$F$4:$F$282,$B9,'VS×ケイパビリティ関係'!$G$4:$G$282,U$5,'VS×ケイパビリティ関係'!$E$4:$E$282,"支援")>0,"○","")) | V9: =COUNTIF(D9:U9,"●") | W9: =COUNTIF(D9:U9,"○")
B10: 02-02 | C10: サプライヤー探索・登録 | D10: =IF(COUNTIFS('VS×ケイパビリティ関係'!$F$4:$F$282,$B10,'VS×ケイパビリティ関係'!$G$4:$G$282,D$5,'VS×ケイパビリティ関係'!$E$4:$E$282,"主")>0,"●",IF(COUNTIFS('VS×ケイパビリティ関係'!$F$4:$F$282,$B10,'VS×ケイパビリティ関係'!$G$4:$G$282,D$5,'VS×ケイパビリティ関係'!$E$4:$E$282,"支援")>0,"○","")) | E10: =IF(COUNTIFS('VS×ケイパビリティ関係'!$F$4:$F$282,$B10,'VS×ケイパビリティ関係'!$G$4:$G$282,E$5,'VS×ケイパビリティ関係'!$E$4:$E$282,"主")>0,"●",IF(COUNTIFS('VS×ケイパビリティ関係'!$F$4:$F$282,$B10,'VS×ケイパビリティ関係'!$G$4:$G$282,E$5,'VS×ケイパビリティ関係'!$E$4:$E$282,"支援")>0,"○","")) | F10: =IF(COUNTIFS('VS×ケイパビリティ関係'!$F$4:$F$282,$B10,'VS×ケイパビリティ関係'!$G$4:$G$282,F$5,'VS×ケイパビリティ関係'!$E$4:$E$282,"主")>0,"●",IF(COUNTIFS('VS×ケイパビリティ関係'!$F$4:$F$282,$B10,'VS×ケイパビリティ関係'!$G$4:$G$282,F$5,'VS×ケイパビリティ関係'!$E$4:$E$282,"支援")>0,"○","")) | G10: =IF(COUNTIFS('VS×ケイパビリティ関係'!$F$4:$F$282,$B10,'VS×ケイパビリティ関係'!$G$4:$G$282,G$5,'VS×ケイパビリティ関係'!$E$4:$E$282,"主")>0,"●",IF(COUNTIFS('VS×ケイパビリティ関係'!$F$4:$F$282,$B10,'VS×ケイパビリティ関係'!$G$4:$G$282,G$5,'VS×ケイパビリティ関係'!$E$4:$E$282,"支援")>0,"○","")) | H10: =IF(COUNTIFS('VS×ケイパビリティ関係'!$F$4:$F$282,$B10,'VS×ケイパビリティ関係'!$G$4:$G$282,H$5,'VS×ケイパビリティ関係'!$E$4:$E$282,"主")>0,"●",IF(COUNTIFS('VS×ケイパビリティ関係'!$F$4:$F$282,$B10,'VS×ケイパビリティ関係'!$G$4:$G$282,H$5,'VS×ケイパビリティ関係'!$E$4:$E$282,"支援")>0,"○","")) | I10: =IF(COUNTIFS('VS×ケイパビリティ関係'!$F$4:$F$282,$B10,'VS×ケイパビリティ関係'!$G$4:$G$282,I$5,'VS×ケイパビリティ関係'!$E$4:$E$282,"主")>0,"●",IF(COUNTIFS('VS×ケイパビリティ関係'!$F$4:$F$282,$B10,'VS×ケイパビリティ関係'!$G$4:$G$282,I$5,'VS×ケイパビリティ関係'!$E$4:$E$282,"支援")>0,"○","")) | J10: =IF(COUNTIFS('VS×ケイパビリティ関係'!$F$4:$F$282,$B10,'VS×ケイパビリティ関係'!$G$4:$G$282,J$5,'VS×ケイパビリティ関係'!$E$4:$E$282,"主")>0,"●",IF(COUNTIFS('VS×ケイパビリティ関係'!$F$4:$F$282,$B10,'VS×ケイパビリティ関係'!$G$4:$G$282,J$5,'VS×ケイパビリティ関係'!$E$4:$E$282,"支援")>0,"○","")) | K10: =IF(COUNTIFS('VS×ケイパビリティ関係'!$F$4:$F$282,$B10,'VS×ケイパビリティ関係'!$G$4:$G$282,K$5,'VS×ケイパビリティ関係'!$E$4:$E$282,"主")>0,"●",IF(COUNTIFS('VS×ケイパビリティ関係'!$F$4:$F$282,$B10,'VS×ケイパビリティ関係'!$G$4:$G$282,K$5,'VS×ケイパビリティ関係'!$E$4:$E$282,"支援")>0,"○","")) | ... U10: =IF(COUNTIFS('VS×ケイパビリティ関係'!$F$4:$F$282,$B10,'VS×ケイパビリティ関係'!$G$4:$G$282,U$5,'VS×ケイパビリティ関係'!$E$4:$E$282,"主")>0,"●",IF(COUNTIFS('VS×ケイパビリティ関係'!$F$4:$F$282,$B10,'VS×ケイパビリティ関係'!$G$4:$G$282,U$5,'VS×ケイパビリティ関係'!$E$4:$E$282,"支援")>0,"○","")) | V10: =COUNTIF(D10:U10,"●") | W10: =COUNTIF(D10:U10,"○")
B11: 02-03 | C11: RFP/RFQ・見積比較 | D11: =IF(COUNTIFS('VS×ケイパビリティ関係'!$F$4:$F$282,$B11,'VS×ケイパビリティ関係'!$G$4:$G$282,D$5,'VS×ケイパビリティ関係'!$E$4:$E$282,"主")>0,"●",IF(COUNTIFS('VS×ケイパビリティ関係'!$F$4:$F$282,$B11,'VS×ケイパビリティ関係'!$G$4:$G$282,D$5,'VS×ケイパビリティ関係'!$E$4:$E$282,"支援")>0,"○","")) | E11: =IF(COUNTIFS('VS×ケイパビリティ関係'!$F$4:$F$282,$B11,'VS×ケイパビリティ関係'!$G$4:$G$282,E$5,'VS×ケイパビリティ関係'!$E$4:$E$282,"主")>0,"●",IF(COUNTIFS('VS×ケイパビリティ関係'!$F$4:$F$282,$B11,'VS×ケイパビリティ関係'!$G$4:$G$282,E$5,'VS×ケイパビリティ関係'!$E$4:$E$282,"支援")>0,"○","")) | F11: =IF(COUNTIFS('VS×ケイパビリティ関係'!$F$4:$F$282,$B11,'VS×ケイパビリティ関係'!$G$4:$G$282,F$5,'VS×ケイパビリティ関係'!$E$4:$E$282,"主")>0,"●",IF(COUNTIFS('VS×ケイパビリティ関係'!$F$4:$F$282,$B11,'VS×ケイパビリティ関係'!$G$4:$G$282,F$5,'VS×ケイパビリティ関係'!$E$4:$E$282,"支援")>0,"○","")) | G11: =IF(COUNTIFS('VS×ケイパビリティ関係'!$F$4:$F$282,$B11,'VS×ケイパビリティ関係'!$G$4:$G$282,G$5,'VS×ケイパビリティ関係'!$E$4:$E$282,"主")>0,"●",IF(COUNTIFS('VS×ケイパビリティ関係'!$F$4:$F$282,$B11,'VS×ケイパビリティ関係'!$G$4:$G$282,G$5,'VS×ケイパビリティ関係'!$E$4:$E$282,"支援")>0,"○","")) | H11: =IF(COUNTIFS('VS×ケイパビリティ関係'!$F$4:$F$282,$B11,'VS×ケイパビリティ関係'!$G$4:$G$282,H$5,'VS×ケイパビリティ関係'!$E$4:$E$282,"主")>0,"●",IF(COUNTIFS('VS×ケイパビリティ関係'!$F$4:$F$282,$B11,'VS×ケイパビリティ関係'!$G$4:$G$282,H$5,'VS×ケイパビリティ関係'!$E$4:$E$282,"支援")>0,"○","")) | I11: =IF(COUNTIFS('VS×ケイパビリティ関係'!$F$4:$F$282,$B11,'VS×ケイパビリティ関係'!$G$4:$G$282,I$5,'VS×ケイパビリティ関係'!$E$4:$E$282,"主")>0,"●",IF(COUNTIFS('VS×ケイパビリティ関係'!$F$4:$F$282,$B11,'VS×ケイパビリティ関係'!$G$4:$G$282,I$5,'VS×ケイパビリティ関係'!$E$4:$E$282,"支援")>0,"○","")) | J11: =IF(COUNTIFS('VS×ケイパビリティ関係'!$F$4:$F$282,$B11,'VS×ケイパビリティ関係'!$G$4:$G$282,J$5,'VS×ケイパビリティ関係'!$E$4:$E$282,"主")>0,"●",IF(COUNTIFS('VS×ケイパビリティ関係'!$F$4:$F$282,$B11,'VS×ケイパビリティ関係'!$G$4:$G$282,J$5,'VS×ケイパビリティ関係'!$E$4:$E$282,"支援")>0,"○","")) | K11: =IF(COUNTIFS('VS×ケイパビリティ関係'!$F$4:$F$282,$B11,'VS×ケイパビリティ関係'!$G$4:$G$282,K$5,'VS×ケイパビリティ関係'!$E$4:$E$282,"主")>0,"●",IF(COUNTIFS('VS×ケイパビリティ関係'!$F$4:$F$282,$B11,'VS×ケイパビリティ関係'!$G$4:$G$282,K$5,'VS×ケイパビリティ関係'!$E$4:$E$282,"支援")>0,"○","")) | ... U11: =IF(COUNTIFS('VS×ケイパビリティ関係'!$F$4:$F$282,$B11,'VS×ケイパビリティ関係'!$G$4:$G$282,U$5,'VS×ケイパビリティ関係'!$E$4:$E$282,"主")>0,"●",IF(COUNTIFS('VS×ケイパビリティ関係'!$F$4:$F$282,$B11,'VS×ケイパビリティ関係'!$G$4:$G$282,U$5,'VS×ケイパビリティ関係'!$E$4:$E$282,"支援")>0,"○","")) | V11: =COUNTIF(D11:U11,"●") | W11: =COUNTIF(D11:U11,"○")
A12: 03 契約締結・発注 | B12: 03-01 | C12: 契約締結 | D12: =IF(COUNTIFS('VS×ケイパビリティ関係'!$F$4:$F$282,$B12,'VS×ケイパビリティ関係'!$G$4:$G$282,D$5,'VS×ケイパビリティ関係'!$E$4:$E$282,"主")>0,"●",IF(COUNTIFS('VS×ケイパビリティ関係'!$F$4:$F$282,$B12,'VS×ケイパビリティ関係'!$G$4:$G$282,D$5,'VS×ケイパビリティ関係'!$E$4:$E$282,"支援")>0,"○","")) | E12: =IF(COUNTIFS('VS×ケイパビリティ関係'!$F$4:$F$282,$B12,'VS×ケイパビリティ関係'!$G$4:$G$282,E$5,'VS×ケイパビリティ関係'!$E$4:$E$282,"主")>0,"●",IF(COUNTIFS('VS×ケイパビリティ関係'!$F$4:$F$282,$B12,'VS×ケイパビリティ関係'!$G$4:$G$282,E$5,'VS×ケイパビリティ関係'!$E$4:$E$282,"支援")>0,"○","")) | F12: =IF(COUNTIFS('VS×ケイパビリティ関係'!$F$4:$F$282,$B12,'VS×ケイパビリティ関係'!$G$4:$G$282,F$5,'VS×ケイパビリティ関係'!$E$4:$E$282,"主")>0,"●",IF(COUNTIFS('VS×ケイパビリティ関係'!$F$4:$F$282,$B12,'VS×ケイパビリティ関係'!$G$4:$G$282,F$5,'VS×ケイパビリティ関係'!$E$4:$E$282,"支援")>0,"○","")) | G12: =IF(COUNTIFS('VS×ケイパビリティ関係'!$F$4:$F$282,$B12,'VS×ケイパビリティ関係'!$G$4:$G$282,G$5,'VS×ケイパビリティ関係'!$E$4:$E$282,"主")>0,"●",IF(COUNTIFS('VS×ケイパビリティ関係'!$F$4:$F$282,$B12,'VS×ケイパビリティ関係'!$G$4:$G$282,G$5,'VS×ケイパビリティ関係'!$E$4:$E$282,"支援")>0,"○","")) | H12: =IF(COUNTIFS('VS×ケイパビリティ関係'!$F$4:$F$282,$B12,'VS×ケイパビリティ関係'!$G$4:$G$282,H$5,'VS×ケイパビリティ関係'!$E$4:$E$282,"主")>0,"●",IF(COUNTIFS('VS×ケイパビリティ関係'!$F$4:$F$282,$B12,'VS×ケイパビリティ関係'!$G$4:$G$282,H$5,'VS×ケイパビリティ関係'!$E$4:$E$282,"支援")>0,"○","")) | I12: =IF(COUNTIFS('VS×ケイパビリティ関係'!$F$4:$F$282,$B12,'VS×ケイパビリティ関係'!$G$4:$G$282,I$5,'VS×ケイパビリティ関係'!$E$4:$E$282,"主")>0,"●",IF(COUNTIFS('VS×ケイパビリティ関係'!$F$4:$F$282,$B12,'VS×ケイパビリティ関係'!$G$4:$G$282,I$5,'VS×ケイパビリティ関係'!$E$4:$E$282,"支援")>0,"○","")) | J12: =IF(COUNTIFS('VS×ケイパビリティ関係'!$F$4:$F$282,$B12,'VS×ケイパビリティ関係'!$G$4:$G$282,J$5,'VS×ケイパビリティ関係'!$E$4:$E$282,"主")>0,"●",IF(COUNTIFS('VS×ケイパビリティ関係'!$F$4:$F$282,$B12,'VS×ケイパビリティ関係'!$G$4:$G$282,J$5,'VS×ケイパビリティ関係'!$E$4:$E$282,"支援")>0,"○","")) | K12: =IF(COUNTIFS('VS×ケイパビリティ関係'!$F$4:$F$282,$B12,'VS×ケイパビリティ関係'!$G$4:$G$282,K$5,'VS×ケイパビリティ関係'!$E$4:$E$282,"主")>0,"●",IF(COUNTIFS('VS×ケイパビリティ関係'!$F$4:$F$282,$B12,'VS×ケイパビリティ関係'!$G$4:$G$282,K$5,'VS×ケイパビリティ関係'!$E$4:$E$282,"支援")>0,"○","")) | ... U12: =IF(COUNTIFS('VS×ケイパビリティ関係'!$F$4:$F$282,$B12,'VS×ケイパビリティ関係'!$G$4:$G$282,U$5,'VS×ケイパビリティ関係'!$E$4:$E$282,"主")>0,"●",IF(COUNTIFS('VS×ケイパビリティ関係'!$F$4:$F$282,$B12,'VS×ケイパビリティ関係'!$G$4:$G$282,U$5,'VS×ケイパビリティ関係'!$E$4:$E$282,"支援")>0,"○","")) | V12: =COUNTIF(D12:U12,"●") | W12: =COUNTIF(D12:U12,"○")
B13: 03-02 | C13: 発注 | D13: =IF(COUNTIFS('VS×ケイパビリティ関係'!$F$4:$F$282,$B13,'VS×ケイパビリティ関係'!$G$4:$G$282,D$5,'VS×ケイパビリティ関係'!$E$4:$E$282,"主")>0,"●",IF(COUNTIFS('VS×ケイパビリティ関係'!$F$4:$F$282,$B13,'VS×ケイパビリティ関係'!$G$4:$G$282,D$5,'VS×ケイパビリティ関係'!$E$4:$E$282,"支援")>0,"○","")) | E13: =IF(COUNTIFS('VS×ケイパビリティ関係'!$F$4:$F$282,$B13,'VS×ケイパビリティ関係'!$G$4:$G$282,E$5,'VS×ケイパビリティ関係'!$E$4:$E$282,"主")>0,"●",IF(COUNTIFS('VS×ケイパビリティ関係'!$F$4:$F$282,$B13,'VS×ケイパビリティ関係'!$G$4:$G$282,E$5,'VS×ケイパビリティ関係'!$E$4:$E$282,"支援")>0,"○","")) | F13: =IF(COUNTIFS('VS×ケイパビリティ関係'!$F$4:$F$282,$B13,'VS×ケイパビリティ関係'!$G$4:$G$282,F$5,'VS×ケイパビリティ関係'!$E$4:$E$282,"主")>0,"●",IF(COUNTIFS('VS×ケイパビリティ関係'!$F$4:$F$282,$B13,'VS×ケイパビリティ関係'!$G$4:$G$282,F$5,'VS×ケイパビリティ関係'!$E$4:$E$282,"支援")>0,"○","")) | G13: =IF(COUNTIFS('VS×ケイパビリティ関係'!$F$4:$F$282,$B13,'VS×ケイパビリティ関係'!$G$4:$G$282,G$5,'VS×ケイパビリティ関係'!$E$4:$E$282,"主")>0,"●",IF(COUNTIFS('VS×ケイパビリティ関係'!$F$4:$F$282,$B13,'VS×ケイパビリティ関係'!$G$4:$G$282,G$5,'VS×ケイパビリティ関係'!$E$4:$E$282,"支援")>0,"○","")) | H13: =IF(COUNTIFS('VS×ケイパビリティ関係'!$F$4:$F$282,$B13,'VS×ケイパビリティ関係'!$G$4:$G$282,H$5,'VS×ケイパビリティ関係'!$E$4:$E$282,"主")>0,"●",IF(COUNTIFS('VS×ケイパビリティ関係'!$F$4:$F$282,$B13,'VS×ケイパビリティ関係'!$G$4:$G$282,H$5,'VS×ケイパビリティ関係'!$E$4:$E$282,"支援")>0,"○","")) | I13: =IF(COUNTIFS('VS×ケイパビリティ関係'!$F$4:$F$282,$B13,'VS×ケイパビリティ関係'!$G$4:$G$282,I$5,'VS×ケイパビリティ関係'!$E$4:$E$282,"主")>0,"●",IF(COUNTIFS('VS×ケイパビリティ関係'!$F$4:$F$282,$B13,'VS×ケイパビリティ関係'!$G$4:$G$282,I$5,'VS×ケイパビリティ関係'!$E$4:$E$282,"支援")>0,"○","")) | J13: =IF(COUNTIFS('VS×ケイパビリティ関係'!$F$4:$F$282,$B13,'VS×ケイパビリティ関係'!$G$4:$G$282,J$5,'VS×ケイパビリティ関係'!$E$4:$E$282,"主")>0,"●",IF(COUNTIFS('VS×ケイパビリティ関係'!$F$4:$F$282,$B13,'VS×ケイパビリティ関係'!$G$4:$G$282,J$5,'VS×ケイパビリティ関係'!$E$4:$E$282,"支援")>0,"○","")) | K13: =IF(COUNTIFS('VS×ケイパビリティ関係'!$F$4:$F$282,$B13,'VS×ケイパビリティ関係'!$G$4:$G$282,K$5,'VS×ケイパビリティ関係'!$E$4:$E$282,"主")>0,"●",IF(COUNTIFS('VS×ケイパビリティ関係'!$F$4:$F$282,$B13,'VS×ケイパビリティ関係'!$G$4:$G$282,K$5,'VS×ケイパビリティ関係'!$E$4:$E$282,"支援")>0,"○","")) | ... U13: =IF(COUNTIFS('VS×ケイパビリティ関係'!$F$4:$F$282,$B13,'VS×ケイパビリティ関係'!$G$4:$G$282,U$5,'VS×ケイパビリティ関係'!$E$4:$E$282,"主")>0,"●",IF(COUNTIFS('VS×ケイパビリティ関係'!$F$4:$F$282,$B13,'VS×ケイパビリティ関係'!$G$4:$G$282,U$5,'VS×ケイパビリティ関係'!$E$4:$E$282,"支援")>0,"○","")) | V13: =COUNTIF(D13:U13,"●") | W13: =COUNTIF(D13:U13,"○")
A14: 04 受入・検収 | B14: 04-01 | C14: 入荷・受入 | D14: =IF(COUNTIFS('VS×ケイパビリティ関係'!$F$4:$F$282,$B14,'VS×ケイパビリティ関係'!$G$4:$G$282,D$5,'VS×ケイパビリティ関係'!$E$4:$E$282,"主")>0,"●",IF(COUNTIFS('VS×ケイパビリティ関係'!$F$4:$F$282,$B14,'VS×ケイパビリティ関係'!$G$4:$G$282,D$5,'VS×ケイパビリティ関係'!$E$4:$E$282,"支援")>0,"○","")) | E14: =IF(COUNTIFS('VS×ケイパビリティ関係'!$F$4:$F$282,$B14,'VS×ケイパビリティ関係'!$G$4:$G$282,E$5,'VS×ケイパビリティ関係'!$E$4:$E$282,"主")>0,"●",IF(COUNTIFS('VS×ケイパビリティ関係'!$F$4:$F$282,$B14,'VS×ケイパビリティ関係'!$G$4:$G$282,E$5,'VS×ケイパビリティ関係'!$E$4:$E$282,"支援")>0,"○","")) | F14: =IF(COUNTIFS('VS×ケイパビリティ関係'!$F$4:$F$282,$B14,'VS×ケイパビリティ関係'!$G$4:$G$282,F$5,'VS×ケイパビリティ関係'!$E$4:$E$282,"主")>0,"●",IF(COUNTIFS('VS×ケイパビリティ関係'!$F$4:$F$282,$B14,'VS×ケイパビリティ関係'!$G$4:$G$282,F$5,'VS×ケイパビリティ関係'!$E$4:$E$282,"支援")>0,"○","")) | G14: =IF(COUNTIFS('VS×ケイパビリティ関係'!$F$4:$F$282,$B14,'VS×ケイパビリティ関係'!$G$4:$G$282,G$5,'VS×ケイパビリティ関係'!$E$4:$E$282,"主")>0,"●",IF(COUNTIFS('VS×ケイパビリティ関係'!$F$4:$F$282,$B14,'VS×ケイパビリティ関係'!$G$4:$G$282,G$5,'VS×ケイパビリティ関係'!$E$4:$E$282,"支援")>0,"○","")) | H14: =IF(COUNTIFS('VS×ケイパビリティ関係'!$F$4:$F$282,$B14,'VS×ケイパビリティ関係'!$G$4:$G$282,H$5,'VS×ケイパビリティ関係'!$E$4:$E$282,"主")>0,"●",IF(COUNTIFS('VS×ケイパビリティ関係'!$F$4:$F$282,$B14,'VS×ケイパビリティ関係'!$G$4:$G$282,H$5,'VS×ケイパビリティ関係'!$E$4:$E$282,"支援")>0,"○","")) | I14: =IF(COUNTIFS('VS×ケイパビリティ関係'!$F$4:$F$282,$B14,'VS×ケイパビリティ関係'!$G$4:$G$282,I$5,'VS×ケイパビリティ関係'!$E$4:$E$282,"主")>0,"●",IF(COUNTIFS('VS×ケイパビリティ関係'!$F$4:$F$282,$B14,'VS×ケイパビリティ関係'!$G$4:$G$282,I$5,'VS×ケイパビリティ関係'!$E$4:$E$282,"支援")>0,"○","")) | J14: =IF(COUNTIFS('VS×ケイパビリティ関係'!$F$4:$F$282,$B14,'VS×ケイパビリティ関係'!$G$4:$G$282,J$5,'VS×ケイパビリティ関係'!$E$4:$E$282,"主")>0,"●",IF(COUNTIFS('VS×ケイパビリティ関係'!$F$4:$F$282,$B14,'VS×ケイパビリティ関係'!$G$4:$G$282,J$5,'VS×ケイパビリティ関係'!$E$4:$E$282,"支援")>0,"○","")) | K14: =IF(COUNTIFS('VS×ケイパビリティ関係'!$F$4:$F$282,$B14,'VS×ケイパビリティ関係'!$G$4:$G$282,K$5,'VS×ケイパビリティ関係'!$E$4:$E$282,"主")>0,"●",IF(COUNTIFS('VS×ケイパビリティ関係'!$F$4:$F$282,$B14,'VS×ケイパビリティ関係'!$G$4:$G$282,K$5,'VS×ケイパビリティ関係'!$E$4:$E$282,"支援")>0,"○","")) | ... U14: =IF(COUNTIFS('VS×ケイパビリティ関係'!$F$4:$F$282,$B14,'VS×ケイパビリティ関係'!$G$4:$G$282,U$5,'VS×ケイパビリティ関係'!$E$4:$E$282,"主")>0,"●",IF(COUNTIFS('VS×ケイパビリティ関係'!$F$4:$F$282,$B14,'VS×ケイパビリティ関係'!$G$4:$G$282,U$5,'VS×ケイパビリティ関係'!$E$4:$E$282,"支援")>0,"○","")) | V14: =COUNTIF(D14:U14,"●") | W14: =COUNTIF(D14:U14,"○")
B15: 04-02 | C15: 検収 | D15: =IF(COUNTIFS('VS×ケイパビリティ関係'!$F$4:$F$282,$B15,'VS×ケイパビリティ関係'!$G$4:$G$282,D$5,'VS×ケイパビリティ関係'!$E$4:$E$282,"主")>0,"●",IF(COUNTIFS('VS×ケイパビリティ関係'!$F$4:$F$282,$B15,'VS×ケイパビリティ関係'!$G$4:$G$282,D$5,'VS×ケイパビリティ関係'!$E$4:$E$282,"支援")>0,"○","")) | E15: =IF(COUNTIFS('VS×ケイパビリティ関係'!$F$4:$F$282,$B15,'VS×ケイパビリティ関係'!$G$4:$G$282,E$5,'VS×ケイパビリティ関係'!$E$4:$E$282,"主")>0,"●",IF(COUNTIFS('VS×ケイパビリティ関係'!$F$4:$F$282,$B15,'VS×ケイパビリティ関係'!$G$4:$G$282,E$5,'VS×ケイパビリティ関係'!$E$4:$E$282,"支援")>0,"○","")) | F15: =IF(COUNTIFS('VS×ケイパビリティ関係'!$F$4:$F$282,$B15,'VS×ケイパビリティ関係'!$G$4:$G$282,F$5,'VS×ケイパビリティ関係'!$E$4:$E$282,"主")>0,"●",IF(COUNTIFS('VS×ケイパビリティ関係'!$F$4:$F$282,$B15,'VS×ケイパビリティ関係'!$G$4:$G$282,F$5,'VS×ケイパビリティ関係'!$E$4:$E$282,"支援")>0,"○","")) | G15: =IF(COUNTIFS('VS×ケイパビリティ関係'!$F$4:$F$282,$B15,'VS×ケイパビリティ関係'!$G$4:$G$282,G$5,'VS×ケイパビリティ関係'!$E$4:$E$282,"主")>0,"●",IF(COUNTIFS('VS×ケイパビリティ関係'!$F$4:$F$282,$B15,'VS×ケイパビリティ関係'!$G$4:$G$282,G$5,'VS×ケイパビリティ関係'!$E$4:$E$282,"支援")>0,"○","")) | H15: =IF(COUNTIFS('VS×ケイパビリティ関係'!$F$4:$F$282,$B15,'VS×ケイパビリティ関係'!$G$4:$G$282,H$5,'VS×ケイパビリティ関係'!$E$4:$E$282,"主")>0,"●",IF(COUNTIFS('VS×ケイパビリティ関係'!$F$4:$F$282,$B15,'VS×ケイパビリティ関係'!$G$4:$G$282,H$5,'VS×ケイパビリティ関係'!$E$4:$E$282,"支援")>0,"○","")) | I15: =IF(COUNTIFS('VS×ケイパビリティ関係'!$F$4:$F$282,$B15,'VS×ケイパビリティ関係'!$G$4:$G$282,I$5,'VS×ケイパビリティ関係'!$E$4:$E$282,"主")>0,"●",IF(COUNTIFS('VS×ケイパビリティ関係'!$F$4:$F$282,$B15,'VS×ケイパビリティ関係'!$G$4:$G$282,I$5,'VS×ケイパビリティ関係'!$E$4:$E$282,"支援")>0,"○","")) | J15: =IF(COUNTIFS('VS×ケイパビリティ関係'!$F$4:$F$282,$B15,'VS×ケイパビリティ関係'!$G$4:$G$282,J$5,'VS×ケイパビリティ関係'!$E$4:$E$282,"主")>0,"●",IF(COUNTIFS('VS×ケイパビリティ関係'!$F$4:$F$282,$B15,'VS×ケイパビリティ関係'!$G$4:$G$282,J$5,'VS×ケイパビリティ関係'!$E$4:$E$282,"支援")>0,"○","")) | K15: =IF(COUNTIFS('VS×ケイパビリティ関係'!$F$4:$F$282,$B15,'VS×ケイパビリティ関係'!$G$4:$G$282,K$5,'VS×ケイパビリティ関係'!$E$4:$E$282,"主")>0,"●",IF(COUNTIFS('VS×ケイパビリティ関係'!$F$4:$F$282,$B15,'VS×ケイパビリティ関係'!$G$4:$G$282,K$5,'VS×ケイパビリティ関係'!$E$4:$E$282,"支援")>0,"○","")) | ... U15: =IF(COUNTIFS('VS×ケイパビリティ関係'!$F$4:$F$282,$B15,'VS×ケイパビリティ関係'!$G$4:$G$282,U$5,'VS×ケイパビリティ関係'!$E$4:$E$282,"主")>0,"●",IF(COUNTIFS('VS×ケイパビリティ関係'!$F$4:$F$282,$B15,'VS×ケイパビリティ関係'!$G$4:$G$282,U$5,'VS×ケイパビリティ関係'!$E$4:$E$282,"支援")>0,"○","")) | V15: =COUNTIF(D15:U15,"●") | W15: =COUNTIF(D15:U15,"○")
A16: 05 請求照合・支払決済 | B16: 05-01 | C16: 請求書受領 | D16: =IF(COUNTIFS('VS×ケイパビリティ関係'!$F$4:$F$282,$B16,'VS×ケイパビリティ関係'!$G$4:$G$282,D$5,'VS×ケイパビリティ関係'!$E$4:$E$282,"主")>0,"●",IF(COUNTIFS('VS×ケイパビリティ関係'!$F$4:$F$282,$B16,'VS×ケイパビリティ関係'!$G$4:$G$282,D$5,'VS×ケイパビリティ関係'!$E$4:$E$282,"支援")>0,"○","")) | E16: =IF(COUNTIFS('VS×ケイパビリティ関係'!$F$4:$F$282,$B16,'VS×ケイパビリティ関係'!$G$4:$G$282,E$5,'VS×ケイパビリティ関係'!$E$4:$E$282,"主")>0,"●",IF(COUNTIFS('VS×ケイパビリティ関係'!$F$4:$F$282,$B16,'VS×ケイパビリティ関係'!$G$4:$G$282,E$5,'VS×ケイパビリティ関係'!$E$4:$E$282,"支援")>0,"○","")) | F16: =IF(COUNTIFS('VS×ケイパビリティ関係'!$F$4:$F$282,$B16,'VS×ケイパビリティ関係'!$G$4:$G$282,F$5,'VS×ケイパビリティ関係'!$E$4:$E$282,"主")>0,"●",IF(COUNTIFS('VS×ケイパビリティ関係'!$F$4:$F$282,$B16,'VS×ケイパビリティ関係'!$G$4:$G$282,F$5,'VS×ケイパビリティ関係'!$E$4:$E$282,"支援")>0,"○","")) | G16: =IF(COUNTIFS('VS×ケイパビリティ関係'!$F$4:$F$282,$B16,'VS×ケイパビリティ関係'!$G$4:$G$282,G$5,'VS×ケイパビリティ関係'!$E$4:$E$282,"主")>0,"●",IF(COUNTIFS('VS×ケイパビリティ関係'!$F$4:$F$282,$B16,'VS×ケイパビリティ関係'!$G$4:$G$282,G$5,'VS×ケイパビリティ関係'!$E$4:$E$282,"支援")>0,"○","")) | H16: =IF(COUNTIFS('VS×ケイパビリティ関係'!$F$4:$F$282,$B16,'VS×ケイパビリティ関係'!$G$4:$G$282,H$5,'VS×ケイパビリティ関係'!$E$4:$E$282,"主")>0,"●",IF(COUNTIFS('VS×ケイパビリティ関係'!$F$4:$F$282,$B16,'VS×ケイパビリティ関係'!$G$4:$G$282,H$5,'VS×ケイパビリティ関係'!$E$4:$E$282,"支援")>0,"○","")) | I16: =IF(COUNTIFS('VS×ケイパビリティ関係'!$F$4:$F$282,$B16,'VS×ケイパビリティ関係'!$G$4:$G$282,I$5,'VS×ケイパビリティ関係'!$E$4:$E$282,"主")>0,"●",IF(COUNTIFS('VS×ケイパビリティ関係'!$F$4:$F$282,$B16,'VS×ケイパビリティ関係'!$G$4:$G$282,I$5,'VS×ケイパビリティ関係'!$E$4:$E$282,"支援")>0,"○","")) | J16: =IF(COUNTIFS('VS×ケイパビリティ関係'!$F$4:$F$282,$B16,'VS×ケイパビリティ関係'!$G$4:$G$282,J$5,'VS×ケイパビリティ関係'!$E$4:$E$282,"主")>0,"●",IF(COUNTIFS('VS×ケイパビリティ関係'!$F$4:$F$282,$B16,'VS×ケイパビリティ関係'!$G$4:$G$282,J$5,'VS×ケイパビリティ関係'!$E$4:$E$282,"支援")>0,"○","")) | K16: =IF(COUNTIFS('VS×ケイパビリティ関係'!$F$4:$F$282,$B16,'VS×ケイパビリティ関係'!$G$4:$G$282,K$5,'VS×ケイパビリティ関係'!$E$4:$E$282,"主")>0,"●",IF(COUNTIFS('VS×ケイパビリティ関係'!$F$4:$F$282,$B16,'VS×ケイパビリティ関係'!$G$4:$G$282,K$5,'VS×ケイパビリティ関係'!$E$4:$E$282,"支援")>0,"○","")) | ... U16: =IF(COUNTIFS('VS×ケイパビリティ関係'!$F$4:$F$282,$B16,'VS×ケイパビリティ関係'!$G$4:$G$282,U$5,'VS×ケイパビリティ関係'!$E$4:$E$282,"主")>0,"●",IF(COUNTIFS('VS×ケイパビリティ関係'!$F$4:$F$282,$B16,'VS×ケイパビリティ関係'!$G$4:$G$282,U$5,'VS×ケイパビリティ関係'!$E$4:$E$282,"支援")>0,"○","")) | V16: =COUNTIF(D16:U16,"●") | W16: =COUNTIF(D16:U16,"○")
B17: 05-02 | C17: 照合・支払承認 | D17: =IF(COUNTIFS('VS×ケイパビリティ関係'!$F$4:$F$282,$B17,'VS×ケイパビリティ関係'!$G$4:$G$282,D$5,'VS×ケイパビリティ関係'!$E$4:$E$282,"主")>0,"●",IF(COUNTIFS('VS×ケイパビリティ関係'!$F$4:$F$282,$B17,'VS×ケイパビリティ関係'!$G$4:$G$282,D$5,'VS×ケイパビリティ関係'!$E$4:$E$282,"支援")>0,"○","")) | E17: =IF(COUNTIFS('VS×ケイパビリティ関係'!$F$4:$F$282,$B17,'VS×ケイパビリティ関係'!$G$4:$G$282,E$5,'VS×ケイパビリティ関係'!$E$4:$E$282,"主")>0,"●",IF(COUNTIFS('VS×ケイパビリティ関係'!$F$4:$F$282,$B17,'VS×ケイパビリティ関係'!$G$4:$G$282,E$5,'VS×ケイパビリティ関係'!$E$4:$E$282,"支援")>0,"○","")) | F17: =IF(COUNTIFS('VS×ケイパビリティ関係'!$F$4:$F$282,$B17,'VS×ケイパビリティ関係'!$G$4:$G$282,F$5,'VS×ケイパビリティ関係'!$E$4:$E$282,"主")>0,"●",IF(COUNTIFS('VS×ケイパビリティ関係'!$F$4:$F$282,$B17,'VS×ケイパビリティ関係'!$G$4:$G$282,F$5,'VS×ケイパビリティ関係'!$E$4:$E$282,"支援")>0,"○","")) | G17: =IF(COUNTIFS('VS×ケイパビリティ関係'!$F$4:$F$282,$B17,'VS×ケイパビリティ関係'!$G$4:$G$282,G$5,'VS×ケイパビリティ関係'!$E$4:$E$282,"主")>0,"●",IF(COUNTIFS('VS×ケイパビリティ関係'!$F$4:$F$282,$B17,'VS×ケイパビリティ関係'!$G$4:$G$282,G$5,'VS×ケイパビリティ関係'!$E$4:$E$282,"支援")>0,"○","")) | H17: =IF(COUNTIFS('VS×ケイパビリティ関係'!$F$4:$F$282,$B17,'VS×ケイパビリティ関係'!$G$4:$G$282,H$5,'VS×ケイパビリティ関係'!$E$4:$E$282,"主")>0,"●",IF(COUNTIFS('VS×ケイパビリティ関係'!$F$4:$F$282,$B17,'VS×ケイパビリティ関係'!$G$4:$G$282,H$5,'VS×ケイパビリティ関係'!$E$4:$E$282,"支援")>0,"○","")) | I17: =IF(COUNTIFS('VS×ケイパビリティ関係'!$F$4:$F$282,$B17,'VS×ケイパビリティ関係'!$G$4:$G$282,I$5,'VS×ケイパビリティ関係'!$E$4:$E$282,"主")>0,"●",IF(COUNTIFS('VS×ケイパビリティ関係'!$F$4:$F$282,$B17,'VS×ケイパビリティ関係'!$G$4:$G$282,I$5,'VS×ケイパビリティ関係'!$E$4:$E$282,"支援")>0,"○","")) | J17: =IF(COUNTIFS('VS×ケイパビリティ関係'!$F$4:$F$282,$B17,'VS×ケイパビリティ関係'!$G$4:$G$282,J$5,'VS×ケイパビリティ関係'!$E$4:$E$282,"主")>0,"●",IF(COUNTIFS('VS×ケイパビリティ関係'!$F$4:$F$282,$B17,'VS×ケイパビリティ関係'!$G$4:$G$282,J$5,'VS×ケイパビリティ関係'!$E$4:$E$282,"支援")>0,"○","")) | K17: =IF(COUNTIFS('VS×ケイパビリティ関係'!$F$4:$F$282,$B17,'VS×ケイパビリティ関係'!$G$4:$G$282,K$5,'VS×ケイパビリティ関係'!$E$4:$E$282,"主")>0,"●",IF(COUNTIFS('VS×ケイパビリティ関係'!$F$4:$F$282,$B17,'VS×ケイパビリティ関係'!$G$4:$G$282,K$5,'VS×ケイパビリティ関係'!$E$4:$E$282,"支援")>0,"○","")) | ... U17: =IF(COUNTIFS('VS×ケイパビリティ関係'!$F$4:$F$282,$B17,'VS×ケイパビリティ関係'!$G$4:$G$282,U$5,'VS×ケイパビリティ関係'!$E$4:$E$282,"主")>0,"●",IF(COUNTIFS('VS×ケイパビリティ関係'!$F$4:$F$282,$B17,'VS×ケイパビリティ関係'!$G$4:$G$282,U$5,'VS×ケイパビリティ関係'!$E$4:$E$282,"支援")>0,"○","")) | V17: =COUNTIF(D17:U17,"●") | W17: =COUNTIF(D17:U17,"○")
B18: 05-03 | C18: 支払・会計処理 | D18: =IF(COUNTIFS('VS×ケイパビリティ関係'!$F$4:$F$282,$B18,'VS×ケイパビリティ関係'!$G$4:$G$282,D$5,'VS×ケイパビリティ関係'!$E$4:$E$282,"主")>0,"●",IF(COUNTIFS('VS×ケイパビリティ関係'!$F$4:$F$282,$B18,'VS×ケイパビリティ関係'!$G$4:$G$282,D$5,'VS×ケイパビリティ関係'!$E$4:$E$282,"支援")>0,"○","")) | E18: =IF(COUNTIFS('VS×ケイパビリティ関係'!$F$4:$F$282,$B18,'VS×ケイパビリティ関係'!$G$4:$G$282,E$5,'VS×ケイパビリティ関係'!$E$4:$E$282,"主")>0,"●",IF(COUNTIFS('VS×ケイパビリティ関係'!$F$4:$F$282,$B18,'VS×ケイパビリティ関係'!$G$4:$G$282,E$5,'VS×ケイパビリティ関係'!$E$4:$E$282,"支援")>0,"○","")) | F18: =IF(COUNTIFS('VS×ケイパビリティ関係'!$F$4:$F$282,$B18,'VS×ケイパビリティ関係'!$G$4:$G$282,F$5,'VS×ケイパビリティ関係'!$E$4:$E$282,"主")>0,"●",IF(COUNTIFS('VS×ケイパビリティ関係'!$F$4:$F$282,$B18,'VS×ケイパビリティ関係'!$G$4:$G$282,F$5,'VS×ケイパビリティ関係'!$E$4:$E$282,"支援")>0,"○","")) | G18: =IF(COUNTIFS('VS×ケイパビリティ関係'!$F$4:$F$282,$B18,'VS×ケイパビリティ関係'!$G$4:$G$282,G$5,'VS×ケイパビリティ関係'!$E$4:$E$282,"主")>0,"●",IF(COUNTIFS('VS×ケイパビリティ関係'!$F$4:$F$282,$B18,'VS×ケイパビリティ関係'!$G$4:$G$282,G$5,'VS×ケイパビリティ関係'!$E$4:$E$282,"支援")>0,"○","")) | H18: =IF(COUNTIFS('VS×ケイパビリティ関係'!$F$4:$F$282,$B18,'VS×ケイパビリティ関係'!$G$4:$G$282,H$5,'VS×ケイパビリティ関係'!$E$4:$E$282,"主")>0,"●",IF(COUNTIFS('VS×ケイパビリティ関係'!$F$4:$F$282,$B18,'VS×ケイパビリティ関係'!$G$4:$G$282,H$5,'VS×ケイパビリティ関係'!$E$4:$E$282,"支援")>0,"○","")) | I18: =IF(COUNTIFS('VS×ケイパビリティ関係'!$F$4:$F$282,$B18,'VS×ケイパビリティ関係'!$G$4:$G$282,I$5,'VS×ケイパビリティ関係'!$E$4:$E$282,"主")>0,"●",IF(COUNTIFS('VS×ケイパビリティ関係'!$F$4:$F$282,$B18,'VS×ケイパビリティ関係'!$G$4:$G$282,I$5,'VS×ケイパビリティ関係'!$E$4:$E$282,"支援")>0,"○","")) | J18: =IF(COUNTIFS('VS×ケイパビリティ関係'!$F$4:$F$282,$B18,'VS×ケイパビリティ関係'!$G$4:$G$282,J$5,'VS×ケイパビリティ関係'!$E$4:$E$282,"主")>0,"●",IF(COUNTIFS('VS×ケイパビリティ関係'!$F$4:$F$282,$B18,'VS×ケイパビリティ関係'!$G$4:$G$282,J$5,'VS×ケイパビリティ関係'!$E$4:$E$282,"支援")>0,"○","")) | K18: =IF(COUNTIFS('VS×ケイパビリティ関係'!$F$4:$F$282,$B18,'VS×ケイパビリティ関係'!$G$4:$G$282,K$5,'VS×ケイパビリティ関係'!$E$4:$E$282,"主")>0,"●",IF(COUNTIFS('VS×ケイパビリティ関係'!$F$4:$F$282,$B18,'VS×ケイパビリティ関係'!$G$4:$G$282,K$5,'VS×ケイパビリティ関係'!$E$4:$E$282,"支援")>0,"○","")) | ... U18: =IF(COUNTIFS('VS×ケイパビリティ関係'!$F$4:$F$282,$B18,'VS×ケイパビリティ関係'!$G$4:$G$282,U$5,'VS×ケイパビリティ関係'!$E$4:$E$282,"主")>0,"●",IF(COUNTIFS('VS×ケイパビリティ関係'!$F$4:$F$282,$B18,'VS×ケイパビリティ関係'!$G$4:$G$282,U$5,'VS×ケイパビリティ関係'!$E$4:$E$282,"支援")>0,"○","")) | V18: =COUNTIF(D18:U18,"●") | W18: =COUNTIF(D18:U18,"○")
B19: 05-04 | C19: 振り返り・評価 | D19: =IF(COUNTIFS('VS×ケイパビリティ関係'!$F$4:$F$282,$B19,'VS×ケイパビリティ関係'!$G$4:$G$282,D$5,'VS×ケイパビリティ関係'!$E$4:$E$282,"主")>0,"●",IF(COUNTIFS('VS×ケイパビリティ関係'!$F$4:$F$282,$B19,'VS×ケイパビリティ関係'!$G$4:$G$282,D$5,'VS×ケイパビリティ関係'!$E$4:$E$282,"支援")>0,"○","")) | E19: =IF(COUNTIFS('VS×ケイパビリティ関係'!$F$4:$F$282,$B19,'VS×ケイパビリティ関係'!$G$4:$G$282,E$5,'VS×ケイパビリティ関係'!$E$4:$E$282,"主")>0,"●",IF(COUNTIFS('VS×ケイパビリティ関係'!$F$4:$F$282,$B19,'VS×ケイパビリティ関係'!$G$4:$G$282,E$5,'VS×ケイパビリティ関係'!$E$4:$E$282,"支援")>0,"○","")) | F19: =IF(COUNTIFS('VS×ケイパビリティ関係'!$F$4:$F$282,$B19,'VS×ケイパビリティ関係'!$G$4:$G$282,F$5,'VS×ケイパビリティ関係'!$E$4:$E$282,"主")>0,"●",IF(COUNTIFS('VS×ケイパビリティ関係'!$F$4:$F$282,$B19,'VS×ケイパビリティ関係'!$G$4:$G$282,F$5,'VS×ケイパビリティ関係'!$E$4:$E$282,"支援")>0,"○","")) | G19: =IF(COUNTIFS('VS×ケイパビリティ関係'!$F$4:$F$282,$B19,'VS×ケイパビリティ関係'!$G$4:$G$282,G$5,'VS×ケイパビリティ関係'!$E$4:$E$282,"主")>0,"●",IF(COUNTIFS('VS×ケイパビリティ関係'!$F$4:$F$282,$B19,'VS×ケイパビリティ関係'!$G$4:$G$282,G$5,'VS×ケイパビリティ関係'!$E$4:$E$282,"支援")>0,"○","")) | H19: =IF(COUNTIFS('VS×ケイパビリティ関係'!$F$4:$F$282,$B19,'VS×ケイパビリティ関係'!$G$4:$G$282,H$5,'VS×ケイパビリティ関係'!$E$4:$E$282,"主")>0,"●",IF(COUNTIFS('VS×ケイパビリティ関係'!$F$4:$F$282,$B19,'VS×ケイパビリティ関係'!$G$4:$G$282,H$5,'VS×ケイパビリティ関係'!$E$4:$E$282,"支援")>0,"○","")) | I19: =IF(COUNTIFS('VS×ケイパビリティ関係'!$F$4:$F$282,$B19,'VS×ケイパビリティ関係'!$G$4:$G$282,I$5,'VS×ケイパビリティ関係'!$E$4:$E$282,"主")>0,"●",IF(COUNTIFS('VS×ケイパビリティ関係'!$F$4:$F$282,$B19,'VS×ケイパビリティ関係'!$G$4:$G$282,I$5,'VS×ケイパビリティ関係'!$E$4:$E$282,"支援")>0,"○","")) | J19: =IF(COUNTIFS('VS×ケイパビリティ関係'!$F$4:$F$282,$B19,'VS×ケイパビリティ関係'!$G$4:$G$282,J$5,'VS×ケイパビリティ関係'!$E$4:$E$282,"主")>0,"●",IF(COUNTIFS('VS×ケイパビリティ関係'!$F$4:$F$282,$B19,'VS×ケイパビリティ関係'!$G$4:$G$282,J$5,'VS×ケイパビリティ関係'!$E$4:$E$282,"支援")>0,"○","")) | K19: =IF(COUNTIFS('VS×ケイパビリティ関係'!$F$4:$F$282,$B19,'VS×ケイパビリティ関係'!$G$4:$G$282,K$5,'VS×ケイパビリティ関係'!$E$4:$E$282,"主")>0,"●",IF(COUNTIFS('VS×ケイパビリティ関係'!$F$4:$F$282,$B19,'VS×ケイパビリティ関係'!$G$4:$G$282,K$5,'VS×ケイパビリティ関係'!$E$4:$E$282,"支援")>0,"○","")) | ... U19: =IF(COUNTIFS('VS×ケイパビリティ関係'!$F$4:$F$282,$B19,'VS×ケイパビリティ関係'!$G$4:$G$282,U$5,'VS×ケイパビリティ関係'!$E$4:$E$282,"主")>0,"●",IF(COUNTIFS('VS×ケイパビリティ関係'!$F$4:$F$282,$B19,'VS×ケイパビリティ関係'!$G$4:$G$282,U$5,'VS×ケイパビリティ関係'!$E$4:$E$282,"支援")>0,"○","")) | V19: =COUNTIF(D19:U19,"●") | W19: =COUNTIF(D19:U19,"○")

Sheet 情報オブジェクト
A1: 情報オブジェクト（正本：用語集と分類）
A2: 1行1オブジェクト。業務上ひとまとまりで管理される情報の単位（状態の違いは属性として扱う）。名称・分類・オーナーはこのシートで編集する。灰色の列は数式（編集しない）。個人情報：取引先が個人事業者（フリーランス）の場合に該当する。特定個人情報（マイナンバー）は取扱いを特に厳格にする。
A3: ID | B3: 領域 | C3: 情報オブジェクト | D3: 英語名 | E3: 説明 | F3: データ種別 | G3: 関連法令 | H3: 法定保存・届出 の対象 | I3: 個人情報 | J3: オーナー ケイパビリティL2 ID | K3: オーナー ケイパビリティL2 | L3: 作成する ケイパビリティL2の数 | M3: 利用する ケイパビリティL2の数
A4: MST-01 | B4: 共通・マスタ | C4: 品目マスタ | D4: Item Master | E4: 品目・サービスの分類、品目コード、単位、勘定科目との対応 | F4: マスタ | G4: なし | H4: =IF(G4="なし","—","対象候補") | I4: なし | J4: C06-01 | K4: =IFERROR(INDEX(ケイパビリティマップ!$E:$E,MATCH(J4,ケイパビリティマップ!$A:$A,0)),"（IDなし）") | L4: =COUNTIF('ケイパビリティ×情報オブジェクト'!D$6:D$23,"C") | M4: =COUNTIF('ケイパビリティ×情報オブジェクト'!D$6:D$23,"R")
A5: MST-02 | B5: 共通・マスタ | C5: サプライヤーマスタ | D5: Supplier Master | E5: 取引先の名称・所在地・口座・支払条件・インボイス登録番号・取適法等の区分 | F5: マスタ | G5: 消費税法・取適法 | H5: =IF(G5="なし","—","対象候補") | I5: 個人情報 | J5: C05-01 | K5: =IFERROR(INDEX(ケイパビリティマップ!$E:$E,MATCH(J5,ケイパビリティマップ!$A:$A,0)),"（IDなし）") | L5: =COUNTIF('ケイパビリティ×情報オブジェクト'!E$6:E$23,"C") | M5: =COUNTIF('ケイパビリティ×情報オブジェクト'!E$6:E$23,"R")
A6: MST-03 | B6: 共通・マスタ | C6: 購買規程・職務権限 | D6: Procurement Policy & Authority | E6: 購買規程、金額別の承認者（職務権限表）、稟議の基準、調達方針 | F6: 文書 | G6: 金商法 | H6: =IF(G6="なし","—","対象候補") | I6: なし | J6: C01-02 | K6: =IFERROR(INDEX(ケイパビリティマップ!$E:$E,MATCH(J6,ケイパビリティマップ!$A:$A,0)),"（IDなし）") | L6: =COUNTIF('ケイパビリティ×情報オブジェクト'!F$6:F$23,"C") | M6: =COUNTIF('ケイパビリティ×情報オブジェクト'!F$6:F$23,"R")
A7: PLN-01 | B7: 計画・戦略 | C7: 購買計画・予算 | D7: Purchasing Plan & Budget | E7: 年間の購買計画と、部門・費目別の購買予算および予算の引当状況 | F7: トランザクション | G7: なし | H7: =IF(G7="なし","—","対象候補") | I7: なし | J7: C01-01 | K7: =IFERROR(INDEX(ケイパビリティマップ!$E:$E,MATCH(J7,ケイパビリティマップ!$A:$A,0)),"（IDなし）") | L7: =COUNTIF('ケイパビリティ×情報オブジェクト'!G$6:G$23,"C") | M7: =COUNTIF('ケイパビリティ×情報オブジェクト'!G$6:G$23,"R")
A8: PLN-02 | B8: 計画・戦略 | C8: 支出分析 | D8: Spend Analysis | E8: 品目・サプライヤー・部門別の支出と、集約・削減の余地 | F8: 分析・評価 | G8: なし | H8: =IF(G8="なし","—","対象候補") | I8: なし | J8: C01-01 | K8: =IFERROR(INDEX(ケイパビリティマップ!$E:$E,MATCH(J8,ケイパビリティマップ!$A:$A,0)),"（IDなし）") | L8: =COUNTIF('ケイパビリティ×情報オブジェクト'!H$6:H$23,"C") | M8: =COUNTIF('ケイパビリティ×情報オブジェクト'!H$6:H$23,"R")
A9: PLN-03 | B9: 計画・戦略 | C9: カテゴリ戦略 | D9: Category Strategy | E9: カテゴリごとの調達方針・サプライヤー数・契約形態 | F9: 文書 | G9: なし | H9: =IF(G9="なし","—","対象候補") | I9: なし | J9: C01-01 | K9: =IFERROR(INDEX(ケイパビリティマップ!$E:$E,MATCH(J9,ケイパビリティマップ!$A:$A,0)),"（IDなし）") | L9: =COUNTIF('ケイパビリティ×情報オブジェクト'!I$6:I$23,"C") | M9: =COUNTIF('ケイパビリティ×情報オブジェクト'!I$6:I$23,"R")
A10: PLN-04 | B10: 計画・戦略 | C10: 所要量・補充依頼 | D10: Material Requirement | E10: 生産計画・在庫から計算した必要量と補充の依頼（MRP・補充点） | F10: トランザクション | G10: なし | H10: =IF(G10="なし","—","対象候補") | I10: なし | J10: C02-01 | K10: =IFERROR(INDEX(ケイパビリティマップ!$E:$E,MATCH(J10,ケイパビリティマップ!$A:$A,0)),"（IDなし）") | L10: =COUNTIF('ケイパビリティ×情報オブジェクト'!J$6:J$23,"C") | M10: =COUNTIF('ケイパビリティ×情報オブジェクト'!J$6:J$23,"R")
A11: REQ-01 | B11: 需要・申請 | C11: 購買仕様書 | D11: Purchase Specification | E11: 品質・数量・納期・作業範囲（SOW）などの要求事項 | F11: 定義・仕様 | G11: なし | H11: =IF(G11="なし","—","対象候補") | I11: なし | J11: C02-01 | K11: =IFERROR(INDEX(ケイパビリティマップ!$E:$E,MATCH(J11,ケイパビリティマップ!$A:$A,0)),"（IDなし）") | L11: =COUNTIF('ケイパビリティ×情報オブジェクト'!K$6:K$23,"C") | M11: =COUNTIF('ケイパビリティ×情報オブジェクト'!K$6:K$23,"R")
A12: REQ-02 | B12: 需要・申請 | C12: 購買申請（PR） | D12: Purchase Requisition | E12: 品目・数量・希望納期・予算・申請者と、承認・稟議の記録 | F12: トランザクション | G12: なし | H12: =IF(G12="なし","—","対象候補") | I12: なし | J12: C02-01 | K12: =IFERROR(INDEX(ケイパビリティマップ!$E:$E,MATCH(J12,ケイパビリティマップ!$A:$A,0)),"（IDなし）") | L12: =COUNTIF('ケイパビリティ×情報オブジェクト'!L$6:L$23,"C") | M12: =COUNTIF('ケイパビリティ×情報オブジェクト'!L$6:L$23,"R")
A13: SRC-01 | B13: ソーシング | C13: 候補サプライヤー情報（RFI） | D13: Supplier Candidates | E13: 情報提供依頼（RFI）の回答と候補サプライヤーの情報 | F13: 文書 | G13: なし | H13: =IF(G13="なし","—","対象候補") | I13: なし | J13: C02-02 | K13: =IFERROR(INDEX(ケイパビリティマップ!$E:$E,MATCH(J13,ケイパビリティマップ!$A:$A,0)),"（IDなし）") | L13: =COUNTIF('ケイパビリティ×情報オブジェクト'!M$6:M$23,"C") | M13: =COUNTIF('ケイパビリティ×情報オブジェクト'!M$6:M$23,"R")
A14: SRC-02 | B14: ソーシング | C14: 見積依頼書（RFP・RFQ） | D14: RFP / RFQ | E14: 提案依頼書・見積依頼書と評価基準 | F14: 文書 | G14: なし | H14: =IF(G14="なし","—","対象候補") | I14: なし | J14: C02-02 | K14: =IFERROR(INDEX(ケイパビリティマップ!$E:$E,MATCH(J14,ケイパビリティマップ!$A:$A,0)),"（IDなし）") | L14: =COUNTIF('ケイパビリティ×情報オブジェクト'!N$6:N$23,"C") | M14: =COUNTIF('ケイパビリティ×情報オブジェクト'!N$6:N$23,"R")
A15: SRC-03 | B15: ソーシング | C15: 見積書・提案書 | D15: Quotation & Proposal | E15: サプライヤーから受け取った見積書・提案書 | F15: 文書 | G15: なし | H15: =IF(G15="なし","—","対象候補") | I15: なし | J15: C02-02 | K15: =IFERROR(INDEX(ケイパビリティマップ!$E:$E,MATCH(J15,ケイパビリティマップ!$A:$A,0)),"（IDなし）") | L15: =COUNTIF('ケイパビリティ×情報オブジェクト'!O$6:O$23,"C") | M15: =COUNTIF('ケイパビリティ×情報オブジェクト'!O$6:O$23,"R")
A16: SRC-04 | B16: ソーシング | C16: 見積比較・選定記録 | D16: Bid Evaluation & Award | E16: 見積・提案の比較評価、発注先の選定理由と承認 | F16: 分析・評価 | G16: なし | H16: =IF(G16="なし","—","対象候補") | I16: なし | J16: C02-02 | K16: =IFERROR(INDEX(ケイパビリティマップ!$E:$E,MATCH(J16,ケイパビリティマップ!$A:$A,0)),"（IDなし）") | L16: =COUNTIF('ケイパビリティ×情報オブジェクト'!P$6:P$23,"C") | M16: =COUNTIF('ケイパビリティ×情報オブジェクト'!P$6:P$23,"R")
A17: SRC-05 | B17: ソーシング | C17: 価格交渉・協議記録 | D17: Negotiation & Price Consultation | E17: 価格交渉の経緯と、価格転嫁の協議の記録 | F17: 文書 | G17: 取適法 | H17: =IF(G17="なし","—","対象候補") | I17: なし | J17: C02-02 | K17: =IFERROR(INDEX(ケイパビリティマップ!$E:$E,MATCH(J17,ケイパビリティマップ!$A:$A,0)),"（IDなし）") | L17: =COUNTIF('ケイパビリティ×情報オブジェクト'!Q$6:Q$23,"C") | M17: =COUNTIF('ケイパビリティ×情報オブジェクト'!Q$6:Q$23,"R")
A18: SUP-01 | B18: サプライヤー | C18: 取引先審査記録 | D18: Supplier Due Diligence | E18: 与信・反社チェック・インボイス登録の確認の結果 | F18: 分析・評価 | G18: 暴排条例 | H18: =IF(G18="なし","—","対象候補") | I18: 個人情報 | J18: C05-01 | K18: =IFERROR(INDEX(ケイパビリティマップ!$E:$E,MATCH(J18,ケイパビリティマップ!$A:$A,0)),"（IDなし）") | L18: =COUNTIF('ケイパビリティ×情報オブジェクト'!R$6:R$23,"C") | M18: =COUNTIF('ケイパビリティ×情報オブジェクト'!R$6:R$23,"R")
A19: SUP-02 | B19: サプライヤー | C19: 取引区分判定 | D19: Transaction Classification | E19: 取適法・フリーランス法の対象か否かの判定と根拠（資本金・従業員数・取引内容） | F19: 分析・評価 | G19: 取適法・フリーランス法 | H19: =IF(G19="なし","—","対象候補") | I19: なし | J19: C05-01 | K19: =IFERROR(INDEX(ケイパビリティマップ!$E:$E,MATCH(J19,ケイパビリティマップ!$A:$A,0)),"（IDなし）") | L19: =COUNTIF('ケイパビリティ×情報オブジェクト'!S$6:S$23,"C") | M19: =COUNTIF('ケイパビリティ×情報オブジェクト'!S$6:S$23,"R")
A20: SUP-03 | B20: サプライヤー | C20: サプライヤー評価 | D20: Supplier Performance | E20: 品質・納期・価格・対応の評価結果と改善要請 | F20: 分析・評価 | G20: なし | H20: =IF(G20="なし","—","対象候補") | I20: なし | J20: C05-02 | K20: =IFERROR(INDEX(ケイパビリティマップ!$E:$E,MATCH(J20,ケイパビリティマップ!$A:$A,0)),"（IDなし）") | L20: =COUNTIF('ケイパビリティ×情報オブジェクト'!T$6:T$23,"C") | M20: =COUNTIF('ケイパビリティ×情報オブジェクト'!T$6:T$23,"R")
A21: SUP-04 | B21: サプライヤー | C21: サプライヤーリスク情報 | D21: Supplier Risk | E21: 経営・供給・地政学・ESGのリスクと、代替策・BCP | F21: 分析・評価 | G21: なし | H21: =IF(G21="なし","—","対象候補") | I21: なし | J21: C05-03 | K21: =IFERROR(INDEX(ケイパビリティマップ!$E:$E,MATCH(J21,ケイパビリティマップ!$A:$A,0)),"（IDなし）") | L21: =COUNTIF('ケイパビリティ×情報オブジェクト'!U$6:U$23,"C") | M21: =COUNTIF('ケイパビリティ×情報オブジェクト'!U$6:U$23,"R")
A22: SUP-05 | B22: サプライヤー | C22: 個人事業者の番号情報 | D22: Payee Individual Number | E22: 個人の報酬受領者のマイナンバー（支払調書の作成に使う） | F22: マスタ | G22: 番号法 | H22: =IF(G22="なし","—","対象候補") | I22: 特定個人情報 | J22: C04-03 | K22: =IFERROR(INDEX(ケイパビリティマップ!$E:$E,MATCH(J22,ケイパビリティマップ!$A:$A,0)),"（IDなし）") | L22: =COUNTIF('ケイパビリティ×情報オブジェクト'!V$6:V$23,"C") | M22: =COUNTIF('ケイパビリティ×情報オブジェクト'!V$6:V$23,"R")
A23: CON-01 | B23: 契約・発注 | C23: 契約書 | D23: Contract | E23: 基本契約・個別契約・秘密保持契約と、期限・更新・印紙税の情報 | F23: 文書 | G23: 民法・印紙税法 | H23: =IF(G23="なし","—","対象候補") | I23: なし | J23: C02-03 | K23: =IFERROR(INDEX(ケイパビリティマップ!$E:$E,MATCH(J23,ケイパビリティマップ!$A:$A,0)),"（IDなし）") | L23: =COUNTIF('ケイパビリティ×情報オブジェクト'!W$6:W$23,"C") | M23: =COUNTIF('ケイパビリティ×情報オブジェクト'!W$6:W$23,"R")
A24: CON-02 | B24: 契約・発注 | C24: 単価契約・カタログ | D24: Price Agreement & Catalog | E24: 契約単価・価格表・購買カタログ | F24: 定義・仕様 | G24: なし | H24: =IF(G24="なし","—","対象候補") | I24: なし | J24: C02-03 | K24: =IFERROR(INDEX(ケイパビリティマップ!$E:$E,MATCH(J24,ケイパビリティマップ!$A:$A,0)),"（IDなし）") | L24: =COUNTIF('ケイパビリティ×情報オブジェクト'!X$6:X$23,"C") | M24: =COUNTIF('ケイパビリティ×情報オブジェクト'!X$6:X$23,"R")
A25: CON-03 | B25: 契約・発注 | C25: 発注書（PO） | D25: Purchase Order | E25: 品目・数量・単価・納期・支払条件と、取適法等の明示事項 | F25: トランザクション | G25: 取適法・フリーランス法 | H25: =IF(G25="なし","—","対象候補") | I25: なし | J25: C02-04 | K25: =IFERROR(INDEX(ケイパビリティマップ!$E:$E,MATCH(J25,ケイパビリティマップ!$A:$A,0)),"（IDなし）") | L25: =COUNTIF('ケイパビリティ×情報オブジェクト'!Y$6:Y$23,"C") | M25: =COUNTIF('ケイパビリティ×情報オブジェクト'!Y$6:Y$23,"R")
A26: CON-04 | B26: 契約・発注 | C26: 注文請書・納期回答 | D26: Order Confirmation | E26: サプライヤーの受注確認と納期回答、発注の変更・取消の記録 | F26: トランザクション | G26: なし | H26: =IF(G26="なし","—","対象候補") | I26: なし | J26: C02-04 | K26: =IFERROR(INDEX(ケイパビリティマップ!$E:$E,MATCH(J26,ケイパビリティマップ!$A:$A,0)),"（IDなし）") | L26: =COUNTIF('ケイパビリティ×情報オブジェクト'!Z$6:Z$23,"C") | M26: =COUNTIF('ケイパビリティ×情報オブジェクト'!Z$6:Z$23,"R")
A27: RCV-01 | B27: 受入・検収 | C27: 入荷予定 | D27: Expected Receipt | E27: 発注と納期回答から作る入荷の予定、事前出荷通知 | F27: トランザクション | G27: なし | H27: =IF(G27="なし","—","対象候補") | I27: なし | J27: C03-01 | K27: =IFERROR(INDEX(ケイパビリティマップ!$E:$E,MATCH(J27,ケイパビリティマップ!$A:$A,0)),"（IDなし）") | L27: =COUNTIF('ケイパビリティ×情報オブジェクト'!AA$6:AA$23,"C") | M27: =COUNTIF('ケイパビリティ×情報オブジェクト'!AA$6:AA$23,"R")
A28: RCV-02 | B28: 受入・検収 | C28: 納品書 | D28: Delivery Note | E28: サプライヤーが納品時に渡す品目・数量の記録 | F28: 文書 | G28: なし | H28: =IF(G28="なし","—","対象候補") | I28: なし | J28: C03-01 | K28: =IFERROR(INDEX(ケイパビリティマップ!$E:$E,MATCH(J28,ケイパビリティマップ!$A:$A,0)),"（IDなし）") | L28: =COUNTIF('ケイパビリティ×情報オブジェクト'!AB$6:AB$23,"C") | M28: =COUNTIF('ケイパビリティ×情報オブジェクト'!AB$6:AB$23,"R")
A29: RCV-03 | B29: 受入・検収 | C29: 受入記録 | D29: Goods Receipt | E29: 受け入れた品目・数量・日時と受入検査の結果 | F29: トランザクション | G29: なし | H29: =IF(G29="なし","—","対象候補") | I29: なし | J29: C03-01 | K29: =IFERROR(INDEX(ケイパビリティマップ!$E:$E,MATCH(J29,ケイパビリティマップ!$A:$A,0)),"（IDなし）") | L29: =COUNTIF('ケイパビリティ×情報オブジェクト'!AC$6:AC$23,"C") | M29: =COUNTIF('ケイパビリティ×情報オブジェクト'!AC$6:AC$23,"R")
A30: RCV-04 | B30: 受入・検収 | C30: 検収記録 | D30: Acceptance Record | E30: 物品・役務の検収の判定と検収日（検収書） | F30: トランザクション | G30: 取適法 | H30: =IF(G30="なし","—","対象候補") | I30: なし | J30: C03-02 | K30: =IFERROR(INDEX(ケイパビリティマップ!$E:$E,MATCH(J30,ケイパビリティマップ!$A:$A,0)),"（IDなし）") | L30: =COUNTIF('ケイパビリティ×情報オブジェクト'!AD$6:AD$23,"C") | M30: =COUNTIF('ケイパビリティ×情報オブジェクト'!AD$6:AD$23,"R")
A31: RCV-05 | B31: 受入・検収 | C31: 返品・不適合記録 | D31: Return & Nonconformance | E31: 不適合の内容と、返品・再納品・値引きの協議と結果 | F31: トランザクション | G31: 取適法 | H31: =IF(G31="なし","—","対象候補") | I31: なし | J31: C03-02 | K31: =IFERROR(INDEX(ケイパビリティマップ!$E:$E,MATCH(J31,ケイパビリティマップ!$A:$A,0)),"（IDなし）") | L31: =COUNTIF('ケイパビリティ×情報オブジェクト'!AE$6:AE$23,"C") | M31: =COUNTIF('ケイパビリティ×情報オブジェクト'!AE$6:AE$23,"R")
A32: RCV-06 | B32: 受入・検収 | C32: 在庫 | D32: Inventory | E32: 入庫した物品の在庫（拠点・ロケーション別） | F32: トランザクション | G32: なし | H32: =IF(G32="なし","—","対象候補") | I32: なし | J32: C03-03 | K32: =IFERROR(INDEX(ケイパビリティマップ!$E:$E,MATCH(J32,ケイパビリティマップ!$A:$A,0)),"（IDなし）") | L32: =COUNTIF('ケイパビリティ×情報オブジェクト'!AF$6:AF$23,"C") | M32: =COUNTIF('ケイパビリティ×情報オブジェクト'!AF$6:AF$23,"R")
A33: RCV-07 | B33: 受入・検収 | C33: 固定資産台帳 | D33: Fixed Asset Register | E33: 資産番号・取得価額・耐用年数・設置場所 | F33: マスタ | G33: 法人税法 | H33: =IF(G33="なし","—","対象候補") | I33: なし | J33: C03-03 | K33: =IFERROR(INDEX(ケイパビリティマップ!$E:$E,MATCH(J33,ケイパビリティマップ!$A:$A,0)),"（IDなし）") | L33: =COUNTIF('ケイパビリティ×情報オブジェクト'!AG$6:AG$23,"C") | M33: =COUNTIF('ケイパビリティ×情報オブジェクト'!AG$6:AG$23,"R")
A34: AP-01 | B34: 請求・支払 | C34: 請求書 | D34: Supplier Invoice | E34: 受け取った請求書（適格請求書の記載事項・登録番号を含む）と電子化データ | F34: 文書 | G34: 消費税法・電帳法 | H34: =IF(G34="なし","—","対象候補") | I34: なし | J34: C04-01 | K34: =IFERROR(INDEX(ケイパビリティマップ!$E:$E,MATCH(J34,ケイパビリティマップ!$A:$A,0)),"（IDなし）") | L34: =COUNTIF('ケイパビリティ×情報オブジェクト'!AH$6:AH$23,"C") | M34: =COUNTIF('ケイパビリティ×情報オブジェクト'!AH$6:AH$23,"R")
