Workbook

Sheet 予算シート
A1: IT予算移管シート
A2: 既存の予算シートに、移管の協議に必要な列を追加したもの。色帯は記入者。案件とシステムの対応は「紐付け」シートに書く。移管判定（AL〜AN）は業務→契約→予算の順に自動で決まり、値は他のシートと同じ（移管／一部／留保／対象外／判定保留）。薄い色の3行は記入例なので、使うときは削除する。
A3: 基本 | G3: 今年度実績（見込み含む） | T3: 来年度予算 | AG3: IT部門が記入 | AH3: 協議前（現場部門が記入） | AL3: 移管判定（自動）
A4: 案件ID | B4: 案件名 | C4: 案件概要 | D4: 担当者 | E4: コストセンター | F4: 勘定科目 | G4: 4月 | H4: 5月 | I4: 6月 | J4: 7月 | K4: 8月 | L4: 9月 | M4: 10月 | N4: 11月 | O4: 12月 | P4: 1月 | Q4: 2月 | R4: 3月 | S4: 年額 | T4: 4月 | U4: 5月 | V4: 6月 | W4: 7月 | X4: 8月 | Y4: 9月 | Z4: 10月 | AA4: 11月 | AB4: 12月 | AC4: 1月 | AD4: 2月 | AE4: 3月 | AF4: 年額 | AG4: 費用の性質 | AH4: 予算（申告） | AI4: 契約（申告） | AJ4: 業務（申告） | AK4: 現場のコメント（理由・条件） | AL4: 予算（自動） | AM4: 契約（自動） | AN4: 業務（自動） | AO4: 業務数 | AP4: 業務 移管 | AQ4: 業務 留保 | AR4: 業務 判定保留 | AS4: 業務なしシステム 留保 | AT4: 業務なしシステム その他 | AU4: 契約数 | AV4: 契約 移管 | AW4: 契約 一部 | AX4: 契約 判定保留 | AY4: 契約 留保
A5: BUD-001 | B5: クラウド基盤の利用料（研究本部） | C5: 研究本部が利用しているクラウド環境の利用料と運用委託 | D5: 山田 | E5: CC-4100 | F5: 支払手数料 | G5: 1200000 | H5: 1200000 | I5: 1200000 | J5: 1200000 | K5: 1200000 | L5: 1200000 | M5: 1200000 | N5: 1200000 | O5: 1200000 | P5: 1200000 | Q5: 1200000 | R5: 1200000 | S5: =IF(COUNT(G5:R5)=0,"",SUM(G5:R5)) | T5: 1250000 | U5: 1250000 | V5: 1250000 | W5: 1250000 | X5: 1250000 | Y5: 1250000 | Z5: 1250000 | AA5: 1250000 | AB5: 1250000 | AC5: 1250000 | AD5: 1250000 | AE5: 1250000 | AF5: =IF(COUNT(T5:AE5)=0,"",SUM(T5:AE5)) | AG5: 変動費 | AH5: 移管 | AI5: 移管 | AJ5: 一部 | AK5: 基盤の運用は任せたい。構成変更への回答は今までどおり早くしてほしい | AL5: =IF($A5="","",IF(OR(AM5="移管",AN5="移管"),"移管",IF(OR(AM5="一部",AN5="一部"),"一部",IF(OR(AM5="判定保留",AN5="判定保留"),"判定保留",IF(OR(AM5="留保",AN5="留保"),"留保","対象外"))))) | AM5: =IF($A5="","",IF(AU5=0,"対象外",IF(AV5=AU5,"移管",IF(AV5+AW5>0,"一部",IF(AX5>0,"判定保留",IF(AY5>0,"留保","対象外")))))) | AN5: =IF($A5="","",IF((AO5+AS5+AT5)=0,"対象外",IF(AP5=(AO5+AS5+AT5),"移管",IF(AP5>0,"一部",IF(AR5+AT5>0,"判定保留",IF(AQ5+AS5>0,"留保","対象外")))))) | AO5: =IF($A5="","",SUMPRODUCT((COUNTIFS('紐付け'!$A$4:$A$200,$A5,'紐付け'!$C$4:$C$200,'業務'!$C$4:$C$200)>0)*('業務'!$A$4:$A$200<>""))) | AP5: =IF($A5="","",SUMPRODUCT((COUNTIFS('紐付け'!$A$4:$A$200,$A5,'紐付け'!$C$4:$C$200,'業務'!$C$4:$C$200)>0)*('業務'!$A$4:$A$200<>"")*('業務'!$P$4:$P$200="移管"))) | AQ5: =IF($A5="","",SUMPRODUCT((COUNTIFS('紐付け'!$A$4:$A$200,$A5,'紐付け'!$C$4:$C$200,'業務'!$C$4:$C$200)>0)*('業務'!$A$4:$A$200<>"")*('業務'!$P$4:$P$200="留保"))) | AR5: =IF($A5="","",AO5-AP5-AQ5) | AS5: =IF($A5="","",SUMPRODUCT(('紐付け'!$A$4:$A$200=$A5)*('紐付け'!$C$4:$C$200<>"")*(COUNTIF('業務'!$C$4:$C$200,'紐付け'!$C$4:$C$200)=0)*(COUNTIFS('システム'!$A$4:$A$200,'紐付け'!$C$4:$C$200,'システム'!$N$4:$N$200,"留保")>0))) | AT5: =IF($A5="","",SUMPRODUCT(('紐付け'!$A$4:$A$200=$A5)*('紐付け'!$C$4:$C$200<>"")*(COUNTIF('業務'!$C$4:$C$200,'紐付け'!$C$4:$C$200)=0))-AS5) | AU5: =IF($A5="","",COUNTIF('契約'!$C$4:$C$200,$A5)) | AV5: =IF($A5="","",COUNTIFS('契約'!$C$4:$C$200,$A5,'契約'!$O$4:$O$200,"移管")) | AW5: =IF($A5="","",COUNTIFS('契約'!$C$4:$C$200,$A5,'契約'!$O$4:$O$200,"一部")) | AX5: =IF($A5="","",COUNTIFS('契約'!$C$4:$C$200,$A5,'契約'!$O$4:$O$200,"判定保留")) | AY5: =IF($A5="","",COUNTIFS('契約'!$C$4:$C$200,$A5,'契約'!$O$4:$O$200,"留保"))
A6: BUD-002 | B6: 品質文書システムの保守 | C6: eDMSの保守契約とバリデーション支援 | D6: 佐藤 | E6: CC-3200 | F6: 修繕費 | G6: 0 | H6: 0 | I6: 0 | J6: 4500000 | K6: 0 | L6: 0 | M6: 0 | N6: 0 | O6: 0 | P6: 4500000 | Q6: 0 | R6: 0 | S6: =IF(COUNT(G6:R6)=0,"",SUM(G6:R6)) | T6: 0 | U6: 0 | V6: 0 | W6: 4700000 | X6: 0 | Y6: 0 | Z6: 0 | AA6: 0 | AB6: 0 | AC6: 4700000 | AD6: 0 | AE6: 0 | AF6: =IF(COUNT(T6:AE6)=0,"",SUM(T6:AE6)) | AG6: 固定費 | AH6: 現場 | AI6: 現場 | AJ6: 現場 | AK6: GxP対応があるため当面は自部門で管理したい | AL6: =IF($A6="","",IF(OR(AM6="移管",AN6="移管"),"移管",IF(OR(AM6="一部",AN6="一部"),"一部",IF(OR(AM6="判定保留",AN6="判定保留"),"判定保留",IF(OR(AM6="留保",AN6="留保"),"留保","対象外"))))) | AM6: =IF($A6="","",IF(AU6=0,"対象外",IF(AV6=AU6,"移管",IF(AV6+AW6>0,"一部",IF(AX6>0,"判定保留",IF(AY6>0,"留保","対象外")))))) | AN6: =IF($A6="","",IF((AO6+AS6+AT6)=0,"対象外",IF(AP6=(AO6+AS6+AT6),"移管",IF(AP6>0,"一部",IF(AR6+AT6>0,"判定保留",IF(AQ6+AS6>0,"留保","対象外")))))) | AO6: =IF($A6="","",SUMPRODUCT((COUNTIFS('紐付け'!$A$4:$A$200,$A6,'紐付け'!$C$4:$C$200,'業務'!$C$4:$C$200)>0)*('業務'!$A$4:$A$200<>""))) | AP6: =IF($A6="","",SUMPRODUCT((COUNTIFS('紐付け'!$A$4:$A$200,$A6,'紐付け'!$C$4:$C$200,'業務'!$C$4:$C$200)>0)*('業務'!$A$4:$A$200<>"")*('業務'!$P$4:$P$200="移管"))) | AQ6: =IF($A6="","",SUMPRODUCT((COUNTIFS('紐付け'!$A$4:$A$200,$A6,'紐付け'!$C$4:$C$200,'業務'!$C$4:$C$200)>0)*('業務'!$A$4:$A$200<>"")*('業務'!$P$4:$P$200="留保"))) | AR6: =IF($A6="","",AO6-AP6-AQ6) | AS6: =IF($A6="","",SUMPRODUCT(('紐付け'!$A$4:$A$200=$A6)*('紐付け'!$C$4:$C$200<>"")*(COUNTIF('業務'!$C$4:$C$200,'紐付け'!$C$4:$C$200)=0)*(COUNTIFS('システム'!$A$4:$A$200,'紐付け'!$C$4:$C$200,'システム'!$N$4:$N$200,"留保")>0))) | AT6: =IF($A6="","",SUMPRODUCT(('紐付け'!$A$4:$A$200=$A6)*('紐付け'!$C$4:$C$200<>"")*(COUNTIF('業務'!$C$4:$C$200,'紐付け'!$C$4:$C$200)=0))-AS6) | AU6: =IF($A6="","",COUNTIF('契約'!$C$4:$C$200,$A6)) | AV6: =IF($A6="","",COUNTIFS('契約'!$C$4:$C$200,$A6,'契約'!$O$4:$O$200,"移管")) | AW6: =IF($A6="","",COUNTIFS('契約'!$C$4:$C$200,$A6,'契約'!$O$4:$O$200,"一部")) | AX6: =IF($A6="","",COUNTIFS('契約'!$C$4:$C$200,$A6,'契約'!$O$4:$O$200,"判定保留")) | AY6: =IF($A6="","",COUNTIFS('契約'!$C$4:$C$200,$A6,'契約'!$O$4:$O$200,"留保"))
A7: BUD-003 | B7: 実験データ集計ツールの改修 | C7: 研究本部だけで使う集計ツールの機能追加 | D7: 鈴木 | E7: CC-4100 | F7: 外注費 | G7: 0 | H7: 0 | I7: 0 | J7: 0 | K7: 0 | L7: 0 | M7: 0 | N7: 0 | O7: 0 | P7: 0 | Q7: 0 | R7: 0 | S7: =IF(COUNT(G7:R7)=0,"",SUM(G7:R7)) | T7: 0 | U7: 0 | V7: 3000000 | W7: 0 | X7: 0 | Y7: 0 | Z7: 0 | AA7: 0 | AB7: 0 | AC7: 0 | AD7: 0 | AE7: 0 | AF7: =IF(COUNT(T7:AE7)=0,"",SUM(T7:AE7)) | AG7: 現場固有の増分 | AH7: 現場 | AI7: 現場 | AJ7: 現場 | AK7: 業務に密着しているため現場で持つ | AL7: =IF($A7="","",IF(OR(AM7="移管",AN7="移管"),"移管",IF(OR(AM7="一部",AN7="一部"),"一部",IF(OR(AM7="判定保留",AN7="判定保留"),"判定保留",IF(OR(AM7="留保",AN7="留保"),"留保","対象外"))))) | AM7: =IF($A7="","",IF(AU7=0,"対象外",IF(AV7=AU7,"移管",IF(AV7+AW7>0,"一部",IF(AX7>0,"判定保留",IF(AY7>0,"留保","対象外")))))) | AN7: =IF($A7="","",IF((AO7+AS7+AT7)=0,"対象外",IF(AP7=(AO7+AS7+AT7),"移管",IF(AP7>0,"一部",IF(AR7+AT7>0,"判定保留",IF(AQ7+AS7>0,"留保","対象外")))))) | AO7: =IF($A7="","",SUMPRODUCT((COUNTIFS('紐付け'!$A$4:$A$200,$A7,'紐付け'!$C$4:$C$200,'業務'!$C$4:$C$200)>0)*('業務'!$A$4:$A$200<>""))) | AP7: =IF($A7="","",SUMPRODUCT((COUNTIFS('紐付け'!$A$4:$A$200,$A7,'紐付け'!$C$4:$C$200,'業務'!$C$4:$C$200)>0)*('業務'!$A$4:$A$200<>"")*('業務'!$P$4:$P$200="移管"))) | AQ7: =IF($A7="","",SUMPRODUCT((COUNTIFS('紐付け'!$A$4:$A$200,$A7,'紐付け'!$C$4:$C$200,'業務'!$C$4:$C$200)>0)*('業務'!$A$4:$A$200<>"")*('業務'!$P$4:$P$200="留保"))) | AR7: =IF($A7="","",AO7-AP7-AQ7) | AS7: =IF($A7="","",SUMPRODUCT(('紐付け'!$A$4:$A$200=$A7)*('紐付け'!$C$4:$C$200<>"")*(COUNTIF('業務'!$C$4:$C$200,'紐付け'!$C$4:$C$200)=0)*(COUNTIFS('システム'!$A$4:$A$200,'紐付け'!$C$4:$C$200,'システム'!$N$4:$N$200,"留保")>0))) | AT7: =IF($A7="","",SUMPRODUCT(('紐付け'!$A$4:$A$200=$A7)*('紐付け'!$C$4:$C$200<>"")*(COUNTIF('業務'!$C$4:$C$200,'紐付け'!$C$4:$C$200)=0))-AS7) | AU7: =IF($A7="","",COUNTIF('契約'!$C$4:$C$200,$A7)) | AV7: =IF($A7="","",COUNTIFS('契約'!$C$4:$C$200,$A7,'契約'!$O$4:$O$200,"移管")) | AW7: =IF($A7="","",COUNTIFS('契約'!$C$4:$C$200,$A7,'契約'!$O$4:$O$200,"一部")) | AX7: =IF($A7="","",COUNTIFS('契約'!$C$4:$C$200,$A7,'契約'!$O$4:$O$200,"判定保留")) | AY7: =IF($A7="","",COUNTIFS('契約'!$C$4:$C$200,$A7,'契約'!$O$4:$O$200,"留保"))
S8: =IF(COUNT(G8:R8)=0,"",SUM(G8:R8)) | AF8: =IF(COUNT(T8:AE8)=0,"",SUM(T8:AE8)) | AL8: =IF($A8="","",IF(OR(AM8="移管",AN8="移管"),"移管",IF(OR(AM8="一部",AN8="一部"),"一部",IF(OR(AM8="判定保留",AN8="判定保留"),"判定保留",IF(OR(AM8="留保",AN8="留保"),"留保","対象外"))))) | AM8: =IF($A8="","",IF(AU8=0,"対象外",IF(AV8=AU8,"移管",IF(AV8+AW8>0,"一部",IF(AX8>0,"判定保留",IF(AY8>0,"留保","対象外")))))) | AN8: =IF($A8="","",IF((AO8+AS8+AT8)=0,"対象外",IF(AP8=(AO8+AS8+AT8),"移管",IF(AP8>0,"一部",IF(AR8+AT8>0,"判定保留",IF(AQ8+AS8>0,"留保","対象外")))))) | AO8: =IF($A8="","",SUMPRODUCT((COUNTIFS('紐付け'!$A$4:$A$200,$A8,'紐付け'!$C$4:$C$200,'業務'!$C$4:$C$200)>0)*('業務'!$A$4:$A$200<>""))) | AP8: =IF($A8="","",SUMPRODUCT((COUNTIFS('紐付け'!$A$4:$A$200,$A8,'紐付け'!$C$4:$C$200,'業務'!$C$4:$C$200)>0)*('業務'!$A$4:$A$200<>"")*('業務'!$P$4:$P$200="移管"))) | AQ8: =IF($A8="","",SUMPRODUCT((COUNTIFS('紐付け'!$A$4:$A$200,$A8,'紐付け'!$C$4:$C$200,'業務'!$C$4:$C$200)>0)*('業務'!$A$4:$A$200<>"")*('業務'!$P$4:$P$200="留保"))) | AR8: =IF($A8="","",AO8-AP8-AQ8) | AS8: =IF($A8="","",SUMPRODUCT(('紐付け'!$A$4:$A$200=$A8)*('紐付け'!$C$4:$C$200<>"")*(COUNTIF('業務'!$C$4:$C$200,'紐付け'!$C$4:$C$200)=0)*(COUNTIFS('システム'!$A$4:$A$200,'紐付け'!$C$4:$C$200,'システム'!$N$4:$N$200,"留保")>0))) | AT8: =IF($A8="","",SUMPRODUCT(('紐付け'!$A$4:$A$200=$A8)*('紐付け'!$C$4:$C$200<>"")*(COUNTIF('業務'!$C$4:$C$200,'紐付け'!$C$4:$C$200)=0))-AS8) | AU8: =IF($A8="","",COUNTIF('契約'!$C$4:$C$200,$A8)) | AV8: =IF($A8="","",COUNTIFS('契約'!$C$4:$C$200,$A8,'契約'!$O$4:$O$200,"移管")) | AW8: =IF($A8="","",COUNTIFS('契約'!$C$4:$C$200,$A8,'契約'!$O$4:$O$200,"一部")) | AX8: =IF($A8="","",COUNTIFS('契約'!$C$4:$C$200,$A8,'契約'!$O$4:$O$200,"判定保留")) | AY8: =IF($A8="","",COUNTIFS('契約'!$C$4:$C$200,$A8,'契約'!$O$4:$O$200,"留保"))
S9: =IF(COUNT(G9:R9)=0,"",SUM(G9:R9)) | AF9: =IF(COUNT(T9:AE9)=0,"",SUM(T9:AE9)) | AL9: =IF($A9="","",IF(OR(AM9="移管",AN9="移管"),"移管",IF(OR(AM9="一部",AN9="一部"),"一部",IF(OR(AM9="判定保留",AN9="判定保留"),"判定保留",IF(OR(AM9="留保",AN9="留保"),"留保","対象外"))))) | AM9: =IF($A9="","",IF(AU9=0,"対象外",IF(AV9=AU9,"移管",IF(AV9+AW9>0,"一部",IF(AX9>0,"判定保留",IF(AY9>0,"留保","対象外")))))) | AN9: =IF($A9="","",IF((AO9+AS9+AT9)=0,"対象外",IF(AP9=(AO9+AS9+AT9),"移管",IF(AP9>0,"一部",IF(AR9+AT9>0,"判定保留",IF(AQ9+AS9>0,"留保","対象外")))))) | AO9: =IF($A9="","",SUMPRODUCT((COUNTIFS('紐付け'!$A$4:$A$200,$A9,'紐付け'!$C$4:$C$200,'業務'!$C$4:$C$200)>0)*('業務'!$A$4:$A$200<>""))) | AP9: =IF($A9="","",SUMPRODUCT((COUNTIFS('紐付け'!$A$4:$A$200,$A9,'紐付け'!$C$4:$C$200,'業務'!$C$4:$C$200)>0)*('業務'!$A$4:$A$200<>"")*('業務'!$P$4:$P$200="移管"))) | AQ9: =IF($A9="","",SUMPRODUCT((COUNTIFS('紐付け'!$A$4:$A$200,$A9,'紐付け'!$C$4:$C$200,'業務'!$C$4:$C$200)>0)*('業務'!$A$4:$A$200<>"")*('業務'!$P$4:$P$200="留保"))) | AR9: =IF($A9="","",AO9-AP9-AQ9) | AS9: =IF($A9="","",SUMPRODUCT(('紐付け'!$A$4:$A$200=$A9)*('紐付け'!$C$4:$C$200<>"")*(COUNTIF('業務'!$C$4:$C$200,'紐付け'!$C$4:$C$200)=0)*(COUNTIFS('システム'!$A$4:$A$200,'紐付け'!$C$4:$C$200,'システム'!$N$4:$N$200,"留保")>0))) | AT9: =IF($A9="","",SUMPRODUCT(('紐付け'!$A$4:$A$200=$A9)*('紐付け'!$C$4:$C$200<>"")*(COUNTIF('業務'!$C$4:$C$200,'紐付け'!$C$4:$C$200)=0))-AS9) | AU9: =IF($A9="","",COUNTIF('契約'!$C$4:$C$200,$A9)) | AV9: =IF($A9="","",COUNTIFS('契約'!$C$4:$C$200,$A9,'契約'!$O$4:$O$200,"移管")) | AW9: =IF($A9="","",COUNTIFS('契約'!$C$4:$C$200,$A9,'契約'!$O$4:$O$200,"一部")) | AX9: =IF($A9="","",COUNTIFS('契約'!$C$4:$C$200,$A9,'契約'!$O$4:$O$200,"判定保留")) | AY9: =IF($A9="","",COUNTIFS('契約'!$C$4:$C$200,$A9,'契約'!$O$4:$O$200,"留保"))
S10: =IF(COUNT(G10:R10)=0,"",SUM(G10:R10)) | AF10: =IF(COUNT(T10:AE10)=0,"",SUM(T10:AE10)) | AL10: =IF($A10="","",IF(OR(AM10="移管",AN10="移管"),"移管",IF(OR(AM10="一部",AN10="一部"),"一部",IF(OR(AM10="判定保留",AN10="判定保留"),"判定保留",IF(OR(AM10="留保",AN10="留保"),"留保","対象外"))))) | AM10: =IF($A10="","",IF(AU10=0,"対象外",IF(AV10=AU10,"移管",IF(AV10+AW10>0,"一部",IF(AX10>0,"判定保留",IF(AY10>0,"留保","対象外")))))) | AN10: =IF($A10="","",IF((AO10+AS10+AT10)=0,"対象外",IF(AP10=(AO10+AS10+AT10),"移管",IF(AP10>0,"一部",IF(AR10+AT10>0,"判定保留",IF(AQ10+AS10>0,"留保","対象外")))))) | AO10: =IF($A10="","",SUMPRODUCT((COUNTIFS('紐付け'!$A$4:$A$200,$A10,'紐付け'!$C$4:$C$200,'業務'!$C$4:$C$200)>0)*('業務'!$A$4:$A$200<>""))) | AP10: =IF($A10="","",SUMPRODUCT((COUNTIFS('紐付け'!$A$4:$A$200,$A10,'紐付け'!$C$4:$C$200,'業務'!$C$4:$C$200)>0)*('業務'!$A$4:$A$200<>"")*('業務'!$P$4:$P$200="移管"))) | AQ10: =IF($A10="","",SUMPRODUCT((COUNTIFS('紐付け'!$A$4:$A$200,$A10,'紐付け'!$C$4:$C$200,'業務'!$C$4:$C$200)>0)*('業務'!$A$4:$A$200<>"")*('業務'!$P$4:$P$200="留保"))) | AR10: =IF($A10="","",AO10-AP10-AQ10) | AS10: =IF($A10="","",SUMPRODUCT(('紐付け'!$A$4:$A$200=$A10)*('紐付け'!$C$4:$C$200<>"")*(COUNTIF('業務'!$C$4:$C$200,'紐付け'!$C$4:$C$200)=0)*(COUNTIFS('システム'!$A$4:$A$200,'紐付け'!$C$4:$C$200,'システム'!$N$4:$N$200,"留保")>0))) | AT10: =IF($A10="","",SUMPRODUCT(('紐付け'!$A$4:$A$200=$A10)*('紐付け'!$C$4:$C$200<>"")*(COUNTIF('業務'!$C$4:$C$200,'紐付け'!$C$4:$C$200)=0))-AS10) | AU10: =IF($A10="","",COUNTIF('契約'!$C$4:$C$200,$A10)) | AV10: =IF($A10="","",COUNTIFS('契約'!$C$4:$C$200,$A10,'契約'!$O$4:$O$200,"移管")) | AW10: =IF($A10="","",COUNTIFS('契約'!$C$4:$C$200,$A10,'契約'!$O$4:$O$200,"一部")) | AX10: =IF($A10="","",COUNTIFS('契約'!$C$4:$C$200,$A10,'契約'!$O$4:$O$200,"判定保留")) | AY10: =IF($A10="","",COUNTIFS('契約'!$C$4:$C$200,$A10,'契約'!$O$4:$O$200,"留保"))
S11: =IF(COUNT(G11:R11)=0,"",SUM(G11:R11)) | AF11: =IF(COUNT(T11:AE11)=0,"",SUM(T11:AE11)) | AL11: =IF($A11="","",IF(OR(AM11="移管",AN11="移管"),"移管",IF(OR(AM11="一部",AN11="一部"),"一部",IF(OR(AM11="判定保留",AN11="判定保留"),"判定保留",IF(OR(AM11="留保",AN11="留保"),"留保","対象外"))))) | AM11: =IF($A11="","",IF(AU11=0,"対象外",IF(AV11=AU11,"移管",IF(AV11+AW11>0,"一部",IF(AX11>0,"判定保留",IF(AY11>0,"留保","対象外")))))) | AN11: =IF($A11="","",IF((AO11+AS11+AT11)=0,"対象外",IF(AP11=(AO11+AS11+AT11),"移管",IF(AP11>0,"一部",IF(AR11+AT11>0,"判定保留",IF(AQ11+AS11>0,"留保","対象外")))))) | AO11: =IF($A11="","",SUMPRODUCT((COUNTIFS('紐付け'!$A$4:$A$200,$A11,'紐付け'!$C$4:$C$200,'業務'!$C$4:$C$200)>0)*('業務'!$A$4:$A$200<>""))) | AP11: =IF($A11="","",SUMPRODUCT((COUNTIFS('紐付け'!$A$4:$A$200,$A11,'紐付け'!$C$4:$C$200,'業務'!$C$4:$C$200)>0)*('業務'!$A$4:$A$200<>"")*('業務'!$P$4:$P$200="移管"))) | AQ11: =IF($A11="","",SUMPRODUCT((COUNTIFS('紐付け'!$A$4:$A$200,$A11,'紐付け'!$C$4:$C$200,'業務'!$C$4:$C$200)>0)*('業務'!$A$4:$A$200<>"")*('業務'!$P$4:$P$200="留保"))) | AR11: =IF($A11="","",AO11-AP11-AQ11) | AS11: =IF($A11="","",SUMPRODUCT(('紐付け'!$A$4:$A$200=$A11)*('紐付け'!$C$4:$C$200<>"")*(COUNTIF('業務'!$C$4:$C$200,'紐付け'!$C$4:$C$200)=0)*(COUNTIFS('システム'!$A$4:$A$200,'紐付け'!$C$4:$C$200,'システム'!$N$4:$N$200,"留保")>0))) | AT11: =IF($A11="","",SUMPRODUCT(('紐付け'!$A$4:$A$200=$A11)*('紐付け'!$C$4:$C$200<>"")*(COUNTIF('業務'!$C$4:$C$200,'紐付け'!$C$4:$C$200)=0))-AS11) | AU11: =IF($A11="","",COUNTIF('契約'!$C$4:$C$200,$A11)) | AV11: =IF($A11="","",COUNTIFS('契約'!$C$4:$C$200,$A11,'契約'!$O$4:$O$200,"移管")) | AW11: =IF($A11="","",COUNTIFS('契約'!$C$4:$C$200,$A11,'契約'!$O$4:$O$200,"一部")) | AX11: =IF($A11="","",COUNTIFS('契約'!$C$4:$C$200,$A11,'契約'!$O$4:$O$200,"判定保留")) | AY11: =IF($A11="","",COUNTIFS('契約'!$C$4:$C$200,$A11,'契約'!$O$4:$O$200,"留保"))
S12: =IF(COUNT(G12:R12)=0,"",SUM(G12:R12)) | AF12: =IF(COUNT(T12:AE12)=0,"",SUM(T12:AE12)) | AL12: =IF($A12="","",IF(OR(AM12="移管",AN12="移管"),"移管",IF(OR(AM12="一部",AN12="一部"),"一部",IF(OR(AM12="判定保留",AN12="判定保留"),"判定保留",IF(OR(AM12="留保",AN12="留保"),"留保","対象外"))))) | AM12: =IF($A12="","",IF(AU12=0,"対象外",IF(AV12=AU12,"移管",IF(AV12+AW12>0,"一部",IF(AX12>0,"判定保留",IF(AY12>0,"留保","対象外")))))) | AN12: =IF($A12="","",IF((AO12+AS12+AT12)=0,"対象外",IF(AP12=(AO12+AS12+AT12),"移管",IF(AP12>0,"一部",IF(AR12+AT12>0,"判定保留",IF(AQ12+AS12>0,"留保","対象外")))))) | AO12: =IF($A12="","",SUMPRODUCT((COUNTIFS('紐付け'!$A$4:$A$200,$A12,'紐付け'!$C$4:$C$200,'業務'!$C$4:$C$200)>0)*('業務'!$A$4:$A$200<>""))) | AP12: =IF($A12="","",SUMPRODUCT((COUNTIFS('紐付け'!$A$4:$A$200,$A12,'紐付け'!$C$4:$C$200,'業務'!$C$4:$C$200)>0)*('業務'!$A$4:$A$200<>"")*('業務'!$P$4:$P$200="移管"))) | AQ12: =IF($A12="","",SUMPRODUCT((COUNTIFS('紐付け'!$A$4:$A$200,$A12,'紐付け'!$C$4:$C$200,'業務'!$C$4:$C$200)>0)*('業務'!$A$4:$A$200<>"")*('業務'!$P$4:$P$200="留保"))) | AR12: =IF($A12="","",AO12-AP12-AQ12) | AS12: =IF($A12="","",SUMPRODUCT(('紐付け'!$A$4:$A$200=$A12)*('紐付け'!$C$4:$C$200<>"")*(COUNTIF('業務'!$C$4:$C$200,'紐付け'!$C$4:$C$200)=0)*(COUNTIFS('システム'!$A$4:$A$200,'紐付け'!$C$4:$C$200,'システム'!$N$4:$N$200,"留保")>0))) | AT12: =IF($A12="","",SUMPRODUCT(('紐付け'!$A$4:$A$200=$A12)*('紐付け'!$C$4:$C$200<>"")*(COUNTIF('業務'!$C$4:$C$200,'紐付け'!$C$4:$C$200)=0))-AS12) | AU12: =IF($A12="","",COUNTIF('契約'!$C$4:$C$200,$A12)) | AV12: =IF($A12="","",COUNTIFS('契約'!$C$4:$C$200,$A12,'契約'!$O$4:$O$200,"移管")) | AW12: =IF($A12="","",COUNTIFS('契約'!$C$4:$C$200,$A12,'契約'!$O$4:$O$200,"一部")) | AX12: =IF($A12="","",COUNTIFS('契約'!$C$4:$C$200,$A12,'契約'!$O$4:$O$200,"判定保留")) | AY12: =IF($A12="","",COUNTIFS('契約'!$C$4:$C$200,$A12,'契約'!$O$4:$O$200,"留保"))
S13: =IF(COUNT(G13:R13)=0,"",SUM(G13:R13)) | AF13: =IF(COUNT(T13:AE13)=0,"",SUM(T13:AE13)) | AL13: =IF($A13="","",IF(OR(AM13="移管",AN13="移管"),"移管",IF(OR(AM13="一部",AN13="一部"),"一部",IF(OR(AM13="判定保留",AN13="判定保留"),"判定保留",IF(OR(AM13="留保",AN13="留保"),"留保","対象外"))))) | AM13: =IF($A13="","",IF(AU13=0,"対象外",IF(AV13=AU13,"移管",IF(AV13+AW13>0,"一部",IF(AX13>0,"判定保留",IF(AY13>0,"留保","対象外")))))) | AN13: =IF($A13="","",IF((AO13+AS13+AT13)=0,"対象外",IF(AP13=(AO13+AS13+AT13),"移管",IF(AP13>0,"一部",IF(AR13+AT13>0,"判定保留",IF(AQ13+AS13>0,"留保","対象外")))))) | AO13: =IF($A13="","",SUMPRODUCT((COUNTIFS('紐付け'!$A$4:$A$200,$A13,'紐付け'!$C$4:$C$200,'業務'!$C$4:$C$200)>0)*('業務'!$A$4:$A$200<>""))) | AP13: =IF($A13="","",SUMPRODUCT((COUNTIFS('紐付け'!$A$4:$A$200,$A13,'紐付け'!$C$4:$C$200,'業務'!$C$4:$C$200)>0)*('業務'!$A$4:$A$200<>"")*('業務'!$P$4:$P$200="移管"))) | AQ13: =IF($A13="","",SUMPRODUCT((COUNTIFS('紐付け'!$A$4:$A$200,$A13,'紐付け'!$C$4:$C$200,'業務'!$C$4:$C$200)>0)*('業務'!$A$4:$A$200<>"")*('業務'!$P$4:$P$200="留保"))) | AR13: =IF($A13="","",AO13-AP13-AQ13) | AS13: =IF($A13="","",SUMPRODUCT(('紐付け'!$A$4:$A$200=$A13)*('紐付け'!$C$4:$C$200<>"")*(COUNTIF('業務'!$C$4:$C$200,'紐付け'!$C$4:$C$200)=0)*(COUNTIFS('システム'!$A$4:$A$200,'紐付け'!$C$4:$C$200,'システム'!$N$4:$N$200,"留保")>0))) | AT13: =IF($A13="","",SUMPRODUCT(('紐付け'!$A$4:$A$200=$A13)*('紐付け'!$C$4:$C$200<>"")*(COUNTIF('業務'!$C$4:$C$200,'紐付け'!$C$4:$C$200)=0))-AS13) | AU13: =IF($A13="","",COUNTIF('契約'!$C$4:$C$200,$A13)) | AV13: =IF($A13="","",COUNTIFS('契約'!$C$4:$C$200,$A13,'契約'!$O$4:$O$200,"移管")) | AW13: =IF($A13="","",COUNTIFS('契約'!$C$4:$C$200,$A13,'契約'!$O$4:$O$200,"一部")) | AX13: =IF($A13="","",COUNTIFS('契約'!$C$4:$C$200,$A13,'契約'!$O$4:$O$200,"判定保留")) | AY13: =IF($A13="","",COUNTIFS('契約'!$C$4:$C$200,$A13,'契約'!$O$4:$O$200,"留保"))
S14: =IF(COUNT(G14:R14)=0,"",SUM(G14:R14)) | AF14: =IF(COUNT(T14:AE14)=0,"",SUM(T14:AE14)) | AL14: =IF($A14="","",IF(OR(AM14="移管",AN14="移管"),"移管",IF(OR(AM14="一部",AN14="一部"),"一部",IF(OR(AM14="判定保留",AN14="判定保留"),"判定保留",IF(OR(AM14="留保",AN14="留保"),"留保","対象外"))))) | AM14: =IF($A14="","",IF(AU14=0,"対象外",IF(AV14=AU14,"移管",IF(AV14+AW14>0,"一部",IF(AX14>0,"判定保留",IF(AY14>0,"留保","対象外")))))) | AN14: =IF($A14="","",IF((AO14+AS14+AT14)=0,"対象外",IF(AP14=(AO14+AS14+AT14),"移管",IF(AP14>0,"一部",IF(AR14+AT14>0,"判定保留",IF(AQ14+AS14>0,"留保","対象外")))))) | AO14: =IF($A14="","",SUMPRODUCT((COUNTIFS('紐付け'!$A$4:$A$200,$A14,'紐付け'!$C$4:$C$200,'業務'!$C$4:$C$200)>0)*('業務'!$A$4:$A$200<>""))) | AP14: =IF($A14="","",SUMPRODUCT((COUNTIFS('紐付け'!$A$4:$A$200,$A14,'紐付け'!$C$4:$C$200,'業務'!$C$4:$C$200)>0)*('業務'!$A$4:$A$200<>"")*('業務'!$P$4:$P$200="移管"))) | AQ14: =IF($A14="","",SUMPRODUCT((COUNTIFS('紐付け'!$A$4:$A$200,$A14,'紐付け'!$C$4:$C$200,'業務'!$C$4:$C$200)>0)*('業務'!$A$4:$A$200<>"")*('業務'!$P$4:$P$200="留保"))) | AR14: =IF($A14="","",AO14-AP14-AQ14) | AS14: =IF($A14="","",SUMPRODUCT(('紐付け'!$A$4:$A$200=$A14)*('紐付け'!$C$4:$C$200<>"")*(COUNTIF('業務'!$C$4:$C$200,'紐付け'!$C$4:$C$200)=0)*(COUNTIFS('システム'!$A$4:$A$200,'紐付け'!$C$4:$C$200,'システム'!$N$4:$N$200,"留保")>0))) | AT14: =IF($A14="","",SUMPRODUCT(('紐付け'!$A$4:$A$200=$A14)*('紐付け'!$C$4:$C$200<>"")*(COUNTIF('業務'!$C$4:$C$200,'紐付け'!$C$4:$C$200)=0))-AS14) | AU14: =IF($A14="","",COUNTIF('契約'!$C$4:$C$200,$A14)) | AV14: =IF($A14="","",COUNTIFS('契約'!$C$4:$C$200,$A14,'契約'!$O$4:$O$200,"移管")) | AW14: =IF($A14="","",COUNTIFS('契約'!$C$4:$C$200,$A14,'契約'!$O$4:$O$200,"一部")) | AX14: =IF($A14="","",COUNTIFS('契約'!$C$4:$C$200,$A14,'契約'!$O$4:$O$200,"判定保留")) | AY14: =IF($A14="","",COUNTIFS('契約'!$C$4:$C$200,$A14,'契約'!$O$4:$O$200,"留保"))
S15: =IF(COUNT(G15:R15)=0,"",SUM(G15:R15)) | AF15: =IF(COUNT(T15:AE15)=0,"",SUM(T15:AE15)) | AL15: =IF($A15="","",IF(OR(AM15="移管",AN15="移管"),"移管",IF(OR(AM15="一部",AN15="一部"),"一部",IF(OR(AM15="判定保留",AN15="判定保留"),"判定保留",IF(OR(AM15="留保",AN15="留保"),"留保","対象外"))))) | AM15: =IF($A15="","",IF(AU15=0,"対象外",IF(AV15=AU15,"移管",IF(AV15+AW15>0,"一部",IF(AX15>0,"判定保留",IF(AY15>0,"留保","対象外")))))) | AN15: =IF($A15="","",IF((AO15+AS15+AT15)=0,"対象外",IF(AP15=(AO15+AS15+AT15),"移管",IF(AP15>0,"一部",IF(AR15+AT15>0,"判定保留",IF(AQ15+AS15>0,"留保","対象外")))))) | AO15: =IF($A15="","",SUMPRODUCT((COUNTIFS('紐付け'!$A$4:$A$200,$A15,'紐付け'!$C$4:$C$200,'業務'!$C$4:$C$200)>0)*('業務'!$A$4:$A$200<>""))) | AP15: =IF($A15="","",SUMPRODUCT((COUNTIFS('紐付け'!$A$4:$A$200,$A15,'紐付け'!$C$4:$C$200,'業務'!$C$4:$C$200)>0)*('業務'!$A$4:$A$200<>"")*('業務'!$P$4:$P$200="移管"))) | AQ15: =IF($A15="","",SUMPRODUCT((COUNTIFS('紐付け'!$A$4:$A$200,$A15,'紐付け'!$C$4:$C$200,'業務'!$C$4:$C$200)>0)*('業務'!$A$4:$A$200<>"")*('業務'!$P$4:$P$200="留保"))) | AR15: =IF($A15="","",AO15-AP15-AQ15) | AS15: =IF($A15="","",SUMPRODUCT(('紐付け'!$A$4:$A$200=$A15)*('紐付け'!$C$4:$C$200<>"")*(COUNTIF('業務'!$C$4:$C$200,'紐付け'!$C$4:$C$200)=0)*(COUNTIFS('システム'!$A$4:$A$200,'紐付け'!$C$4:$C$200,'システム'!$N$4:$N$200,"留保")>0))) | AT15: =IF($A15="","",SUMPRODUCT(('紐付け'!$A$4:$A$200=$A15)*('紐付け'!$C$4:$C$200<>"")*(COUNTIF('業務'!$C$4:$C$200,'紐付け'!$C$4:$C$200)=0))-AS15) | AU15: =IF($A15="","",COUNTIF('契約'!$C$4:$C$200,$A15)) | AV15: =IF($A15="","",COUNTIFS('契約'!$C$4:$C$200,$A15,'契約'!$O$4:$O$200,"移管")) | AW15: =IF($A15="","",COUNTIFS('契約'!$C$4:$C$200,$A15,'契約'!$O$4:$O$200,"一部")) | AX15: =IF($A15="","",COUNTIFS('契約'!$C$4:$C$200,$A15,'契約'!$O$4:$O$200,"判定保留")) | AY15: =IF($A15="","",COUNTIFS('契約'!$C$4:$C$200,$A15,'契約'!$O$4:$O$200,"留保"))
S16: =IF(COUNT(G16:R16)=0,"",SUM(G16:R16)) | AF16: =IF(COUNT(T16:AE16)=0,"",SUM(T16:AE16)) | AL16: =IF($A16="","",IF(OR(AM16="移管",AN16="移管"),"移管",IF(OR(AM16="一部",AN16="一部"),"一部",IF(OR(AM16="判定保留",AN16="判定保留"),"判定保留",IF(OR(AM16="留保",AN16="留保"),"留保","対象外"))))) | AM16: =IF($A16="","",IF(AU16=0,"対象外",IF(AV16=AU16,"移管",IF(AV16+AW16>0,"一部",IF(AX16>0,"判定保留",IF(AY16>0,"留保","対象外")))))) | AN16: =IF($A16="","",IF((AO16+AS16+AT16)=0,"対象外",IF(AP16=(AO16+AS16+AT16),"移管",IF(AP16>0,"一部",IF(AR16+AT16>0,"判定保留",IF(AQ16+AS16>0,"留保","対象外")))))) | AO16: =IF($A16="","",SUMPRODUCT((COUNTIFS('紐付け'!$A$4:$A$200,$A16,'紐付け'!$C$4:$C$200,'業務'!$C$4:$C$200)>0)*('業務'!$A$4:$A$200<>""))) | AP16: =IF($A16="","",SUMPRODUCT((COUNTIFS('紐付け'!$A$4:$A$200,$A16,'紐付け'!$C$4:$C$200,'業務'!$C$4:$C$200)>0)*('業務'!$A$4:$A$200<>"")*('業務'!$P$4:$P$200="移管"))) | AQ16: =IF($A16="","",SUMPRODUCT((COUNTIFS('紐付け'!$A$4:$A$200,$A16,'紐付け'!$C$4:$C$200,'業務'!$C$4:$C$200)>0)*('業務'!$A$4:$A$200<>"")*('業務'!$P$4:$P$200="留保"))) | AR16: =IF($A16="","",AO16-AP16-AQ16) | AS16: =IF($A16="","",SUMPRODUCT(('紐付け'!$A$4:$A$200=$A16)*('紐付け'!$C$4:$C$200<>"")*(COUNTIF('業務'!$C$4:$C$200,'紐付け'!$C$4:$C$200)=0)*(COUNTIFS('システム'!$A$4:$A$200,'紐付け'!$C$4:$C$200,'システム'!$N$4:$N$200,"留保")>0))) | AT16: =IF($A16="","",SUMPRODUCT(('紐付け'!$A$4:$A$200=$A16)*('紐付け'!$C$4:$C$200<>"")*(COUNTIF('業務'!$C$4:$C$200,'紐付け'!$C$4:$C$200)=0))-AS16) | AU16: =IF($A16="","",COUNTIF('契約'!$C$4:$C$200,$A16)) | AV16: =IF($A16="","",COUNTIFS('契約'!$C$4:$C$200,$A16,'契約'!$O$4:$O$200,"移管")) | AW16: =IF($A16="","",COUNTIFS('契約'!$C$4:$C$200,$A16,'契約'!$O$4:$O$200,"一部")) | AX16: =IF($A16="","",COUNTIFS('契約'!$C$4:$C$200,$A16,'契約'!$O$4:$O$200,"判定保留")) | AY16: =IF($A16="","",COUNTIFS('契約'!$C$4:$C$200,$A16,'契約'!$O$4:$O$200,"留保"))
S17: =IF(COUNT(G17:R17)=0,"",SUM(G17:R17)) | AF17: =IF(COUNT(T17:AE17)=0,"",SUM(T17:AE17)) | AL17: =IF($A17="","",IF(OR(AM17="移管",AN17="移管"),"移管",IF(OR(AM17="一部",AN17="一部"),"一部",IF(OR(AM17="判定保留",AN17="判定保留"),"判定保留",IF(OR(AM17="留保",AN17="留保"),"留保","対象外"))))) | AM17: =IF($A17="","",IF(AU17=0,"対象外",IF(AV17=AU17,"移管",IF(AV17+AW17>0,"一部",IF(AX17>0,"判定保留",IF(AY17>0,"留保","対象外")))))) | AN17: =IF($A17="","",IF((AO17+AS17+AT17)=0,"対象外",IF(AP17=(AO17+AS17+AT17),"移管",IF(AP17>0,"一部",IF(AR17+AT17>0,"判定保留",IF(AQ17+AS17>0,"留保","対象外")))))) | AO17: =IF($A17="","",SUMPRODUCT((COUNTIFS('紐付け'!$A$4:$A$200,$A17,'紐付け'!$C$4:$C$200,'業務'!$C$4:$C$200)>0)*('業務'!$A$4:$A$200<>""))) | AP17: =IF($A17="","",SUMPRODUCT((COUNTIFS('紐付け'!$A$4:$A$200,$A17,'紐付け'!$C$4:$C$200,'業務'!$C$4:$C$200)>0)*('業務'!$A$4:$A$200<>"")*('業務'!$P$4:$P$200="移管"))) | AQ17: =IF($A17="","",SUMPRODUCT((COUNTIFS('紐付け'!$A$4:$A$200,$A17,'紐付け'!$C$4:$C$200,'業務'!$C$4:$C$200)>0)*('業務'!$A$4:$A$200<>"")*('業務'!$P$4:$P$200="留保"))) | AR17: =IF($A17="","",AO17-AP17-AQ17) | AS17: =IF($A17="","",SUMPRODUCT(('紐付け'!$A$4:$A$200=$A17)*('紐付け'!$C$4:$C$200<>"")*(COUNTIF('業務'!$C$4:$C$200,'紐付け'!$C$4:$C$200)=0)*(COUNTIFS('システム'!$A$4:$A$200,'紐付け'!$C$4:$C$200,'システム'!$N$4:$N$200,"留保")>0))) | AT17: =IF($A17="","",SUMPRODUCT(('紐付け'!$A$4:$A$200=$A17)*('紐付け'!$C$4:$C$200<>"")*(COUNTIF('業務'!$C$4:$C$200,'紐付け'!$C$4:$C$200)=0))-AS17) | AU17: =IF($A17="","",COUNTIF('契約'!$C$4:$C$200,$A17)) | AV17: =IF($A17="","",COUNTIFS('契約'!$C$4:$C$200,$A17,'契約'!$O$4:$O$200,"移管")) | AW17: =IF($A17="","",COUNTIFS('契約'!$C$4:$C$200,$A17,'契約'!$O$4:$O$200,"一部")) | AX17: =IF($A17="","",COUNTIFS('契約'!$C$4:$C$200,$A17,'契約'!$O$4:$O$200,"判定保留")) | AY17: =IF($A17="","",COUNTIFS('契約'!$C$4:$C$200,$A17,'契約'!$O$4:$O$200,"留保"))
S18: =IF(COUNT(G18:R18)=0,"",SUM(G18:R18)) | AF18: =IF(COUNT(T18:AE18)=0,"",SUM(T18:AE18)) | AL18: =IF($A18="","",IF(OR(AM18="移管",AN18="移管"),"移管",IF(OR(AM18="一部",AN18="一部"),"一部",IF(OR(AM18="判定保留",AN18="判定保留"),"判定保留",IF(OR(AM18="留保",AN18="留保"),"留保","対象外"))))) | AM18: =IF($A18="","",IF(AU18=0,"対象外",IF(AV18=AU18,"移管",IF(AV18+AW18>0,"一部",IF(AX18>0,"判定保留",IF(AY18>0,"留保","対象外")))))) | AN18: =IF($A18="","",IF((AO18+AS18+AT18)=0,"対象外",IF(AP18=(AO18+AS18+AT18),"移管",IF(AP18>0,"一部",IF(AR18+AT18>0,"判定保留",IF(AQ18+AS18>0,"留保","対象外")))))) | AO18: =IF($A18="","",SUMPRODUCT((COUNTIFS('紐付け'!$A$4:$A$200,$A18,'紐付け'!$C$4:$C$200,'業務'!$C$4:$C$200)>0)*('業務'!$A$4:$A$200<>""))) | AP18: =IF($A18="","",SUMPRODUCT((COUNTIFS('紐付け'!$A$4:$A$200,$A18,'紐付け'!$C$4:$C$200,'業務'!$C$4:$C$200)>0)*('業務'!$A$4:$A$200<>"")*('業務'!$P$4:$P$200="移管"))) | AQ18: =IF($A18="","",SUMPRODUCT((COUNTIFS('紐付け'!$A$4:$A$200,$A18,'紐付け'!$C$4:$C$200,'業務'!$C$4:$C$200)>0)*('業務'!$A$4:$A$200<>"")*('業務'!$P$4:$P$200="留保"))) | AR18: =IF($A18="","",AO18-AP18-AQ18) | AS18: =IF($A18="","",SUMPRODUCT(('紐付け'!$A$4:$A$200=$A18)*('紐付け'!$C$4:$C$200<>"")*(COUNTIF('業務'!$C$4:$C$200,'紐付け'!$C$4:$C$200)=0)*(COUNTIFS('システム'!$A$4:$A$200,'紐付け'!$C$4:$C$200,'システム'!$N$4:$N$200,"留保")>0))) | AT18: =IF($A18="","",SUMPRODUCT(('紐付け'!$A$4:$A$200=$A18)*('紐付け'!$C$4:$C$200<>"")*(COUNTIF('業務'!$C$4:$C$200,'紐付け'!$C$4:$C$200)=0))-AS18) | AU18: =IF($A18="","",COUNTIF('契約'!$C$4:$C$200,$A18)) | AV18: =IF($A18="","",COUNTIFS('契約'!$C$4:$C$200,$A18,'契約'!$O$4:$O$200,"移管")) | AW18: =IF($A18="","",COUNTIFS('契約'!$C$4:$C$200,$A18,'契約'!$O$4:$O$200,"一部")) | AX18: =IF($A18="","",COUNTIFS('契約'!$C$4:$C$200,$A18,'契約'!$O$4:$O$200,"判定保留")) | AY18: =IF($A18="","",COUNTIFS('契約'!$C$4:$C$200,$A18,'契約'!$O$4:$O$200,"留保"))
S19: =IF(COUNT(G19:R19)=0,"",SUM(G19:R19)) | AF19: =IF(COUNT(T19:AE19)=0,"",SUM(T19:AE19)) | AL19: =IF($A19="","",IF(OR(AM19="移管",AN19="移管"),"移管",IF(OR(AM19="一部",AN19="一部"),"一部",IF(OR(AM19="判定保留",AN19="判定保留"),"判定保留",IF(OR(AM19="留保",AN19="留保"),"留保","対象外"))))) | AM19: =IF($A19="","",IF(AU19=0,"対象外",IF(AV19=AU19,"移管",IF(AV19+AW19>0,"一部",IF(AX19>0,"判定保留",IF(AY19>0,"留保","対象外")))))) | AN19: =IF($A19="","",IF((AO19+AS19+AT19)=0,"対象外",IF(AP19=(AO19+AS19+AT19),"移管",IF(AP19>0,"一部",IF(AR19+AT19>0,"判定保留",IF(AQ19+AS19>0,"留保","対象外")))))) | AO19: =IF($A19="","",SUMPRODUCT((COUNTIFS('紐付け'!$A$4:$A$200,$A19,'紐付け'!$C$4:$C$200,'業務'!$C$4:$C$200)>0)*('業務'!$A$4:$A$200<>""))) | AP19: =IF($A19="","",SUMPRODUCT((COUNTIFS('紐付け'!$A$4:$A$200,$A19,'紐付け'!$C$4:$C$200,'業務'!$C$4:$C$200)>0)*('業務'!$A$4:$A$200<>"")*('業務'!$P$4:$P$200="移管"))) | AQ19: =IF($A19="","",SUMPRODUCT((COUNTIFS('紐付け'!$A$4:$A$200,$A19,'紐付け'!$C$4:$C$200,'業務'!$C$4:$C$200)>0)*('業務'!$A$4:$A$200<>"")*('業務'!$P$4:$P$200="留保"))) | AR19: =IF($A19="","",AO19-AP19-AQ19) | AS19: =IF($A19="","",SUMPRODUCT(('紐付け'!$A$4:$A$200=$A19)*('紐付け'!$C$4:$C$200<>"")*(COUNTIF('業務'!$C$4:$C$200,'紐付け'!$C$4:$C$200)=0)*(COUNTIFS('システム'!$A$4:$A$200,'紐付け'!$C$4:$C$200,'システム'!$N$4:$N$200,"留保")>0))) | AT19: =IF($A19="","",SUMPRODUCT(('紐付け'!$A$4:$A$200=$A19)*('紐付け'!$C$4:$C$200<>"")*(COUNTIF('業務'!$C$4:$C$200,'紐付け'!$C$4:$C$200)=0))-AS19) | AU19: =IF($A19="","",COUNTIF('契約'!$C$4:$C$200,$A19)) | AV19: =IF($A19="","",COUNTIFS('契約'!$C$4:$C$200,$A19,'契約'!$O$4:$O$200,"移管")) | AW19: =IF($A19="","",COUNTIFS('契約'!$C$4:$C$200,$A19,'契約'!$O$4:$O$200,"一部")) | AX19: =IF($A19="","",COUNTIFS('契約'!$C$4:$C$200,$A19,'契約'!$O$4:$O$200,"判定保留")) | AY19: =IF($A19="","",COUNTIFS('契約'!$C$4:$C$200,$A19,'契約'!$O$4:$O$200,"留保"))
... S200: =IF(COUNT(G200:R200)=0,"",SUM(G200:R200)) | AF200: =IF(COUNT(T200:AE200)=0,"",SUM(T200:AE200)) | AL200: =IF($A200="","",IF(OR(AM200="移管",AN200="移管"),"移管",IF(OR(AM200="一部",AN200="一部"),"一部",IF(OR(AM200="判定保留",AN200="判定保留"),"判定保留",IF(OR(AM200="留保",AN200="留保"),"留保","対象外"))))) | AM200: =IF($A200="","",IF(AU200=0,"対象外",IF(AV200=AU200,"移管",IF(AV200+AW200>0,"一部",IF(AX200>0,"判定保留",IF(AY200>0,"留保","対象外")))))) | AN200: =IF($A200="","",IF((AO200+AS200+AT200)=0,"対象外",IF(AP200=(AO200+AS200+AT200),"移管",IF(AP200>0,"一部",IF(AR200+AT200>0,"判定保留",IF(AQ200+AS200>0,"留保","対象外")))))) | AO200: =IF($A200="","",SUMPRODUCT((COUNTIFS('紐付け'!$A$4:$A$200,$A200,'紐付け'!$C$4:$C$200,'業務'!$C$4:$C$200)>0)*('業務'!$A$4:$A$200<>""))) | AP200: =IF($A200="","",SUMPRODUCT((COUNTIFS('紐付け'!$A$4:$A$200,$A200,'紐付け'!$C$4:$C$200,'業務'!$C$4:$C$200)>0)*('業務'!$A$4:$A$200<>"")*('業務'!$P$4:$P$200="移管"))) | AQ200: =IF($A200="","",SUMPRODUCT((COUNTIFS('紐付け'!$A$4:$A$200,$A200,'紐付け'!$C$4:$C$200,'業務'!$C$4:$C$200)>0)*('業務'!$A$4:$A$200<>"")*('業務'!$P$4:$P$200="留保"))) | AR200: =IF($A200="","",AO200-AP200-AQ200) | AS200: =IF($A200="","",SUMPRODUCT(('紐付け'!$A$4:$A$200=$A200)*('紐付け'!$C$4:$C$200<>"")*(COUNTIF('業務'!$C$4:$C$200,'紐付け'!$C$4:$C$200)=0)*(COUNTIFS('システム'!$A$4:$A$200,'紐付け'!$C$4:$C$200,'システム'!$N$4:$N$200,"留保")>0))) | AT200: =IF($A200="","",SUMPRODUCT(('紐付け'!$A$4:$A$200=$A200)*('紐付け'!$C$4:$C$200<>"")*(COUNTIF('業務'!$C$4:$C$200,'紐付け'!$C$4:$C$200)=0))-AS200) | AU200: =IF($A200="","",COUNTIF('契約'!$C$4:$C$200,$A200)) | AV200: =IF($A200="","",COUNTIFS('契約'!$C$4:$C$200,$A200,'契約'!$O$4:$O$200,"移管")) | AW200: =IF($A200="","",COUNTIFS('契約'!$C$4:$C$200,$A200,'契約'!$O$4:$O$200,"一部")) | AX200: =IF($A200="","",COUNTIFS('契約'!$C$4:$C$200,$A200,'契約'!$O$4:$O$200,"判定保留")) | AY200: =IF($A200="","",COUNTIFS('契約'!$C$4:$C$200,$A200,'契約'!$O$4:$O$200,"留保"))

Sheet 紐付け
A1: 紐付け（案件×システム）
A2: 1行＝1つの対応（案件×システム）。1案件に複数のシステム、1システムに複数の案件があれば行を分ける。紐付け以外の情報は持たない。
A3: 案件ID | B3: 案件名（自動） | C3: システムID | D3: システム名（自動）
A4: BUD-001 | B4: =IF(A4="","",IFERROR(INDEX('予算シート'!$B:$B,MATCH(A4,'予算シート'!$A:$A,0)),"案件が未登録")) | C4: SYS-012 | D4: =IF(C4="","",IFERROR(INDEX('システム'!$B:$B,MATCH(C4,'システム'!$A:$A,0)),"システムが未登録"))
A5: BUD-001 | B5: =IF(A5="","",IFERROR(INDEX('予算シート'!$B:$B,MATCH(A5,'予算シート'!$A:$A,0)),"案件が未登録")) | C5: SYS-041 | D5: =IF(C5="","",IFERROR(INDEX('システム'!$B:$B,MATCH(C5,'システム'!$A:$A,0)),"システムが未登録"))
A6: BUD-002 | B6: =IF(A6="","",IFERROR(INDEX('予算シート'!$B:$B,MATCH(A6,'予算シート'!$A:$A,0)),"案件が未登録")) | C6: SYS-003 | D6: =IF(C6="","",IFERROR(INDEX('システム'!$B:$B,MATCH(C6,'システム'!$A:$A,0)),"システムが未登録"))
A7: BUD-003 | B7: =IF(A7="","",IFERROR(INDEX('予算シート'!$B:$B,MATCH(A7,'予算シート'!$A:$A,0)),"案件が未登録")) | C7: SYS-041 | D7: =IF(C7="","",IFERROR(INDEX('システム'!$B:$B,MATCH(C7,'システム'!$A:$A,0)),"システムが未登録"))
B8: =IF(A8="","",IFERROR(INDEX('予算シート'!$B:$B,MATCH(A8,'予算シート'!$A:$A,0)),"案件が未登録")) | D8: =IF(C8="","",IFERROR(INDEX('システム'!$B:$B,MATCH(C8,'システム'!$A:$A,0)),"システムが未登録"))
B9: =IF(A9="","",IFERROR(INDEX('予算シート'!$B:$B,MATCH(A9,'予算シート'!$A:$A,0)),"案件が未登録")) | D9: =IF(C9="","",IFERROR(INDEX('システム'!$B:$B,MATCH(C9,'システム'!$A:$A,0)),"システムが未登録"))
B10: =IF(A10="","",IFERROR(INDEX('予算シート'!$B:$B,MATCH(A10,'予算シート'!$A:$A,0)),"案件が未登録")) | D10: =IF(C10="","",IFERROR(INDEX('システム'!$B:$B,MATCH(C10,'システム'!$A:$A,0)),"システムが未登録"))
B11: =IF(A11="","",IFERROR(INDEX('予算シート'!$B:$B,MATCH(A11,'予算シート'!$A:$A,0)),"案件が未登録")) | D11: =IF(C11="","",IFERROR(INDEX('システム'!$B:$B,MATCH(C11,'システム'!$A:$A,0)),"システムが未登録"))
B12: =IF(A12="","",IFERROR(INDEX('予算シート'!$B:$B,MATCH(A12,'予算シート'!$A:$A,0)),"案件が未登録")) | D12: =IF(C12="","",IFERROR(INDEX('システム'!$B:$B,MATCH(C12,'システム'!$A:$A,0)),"システムが未登録"))
B13: =IF(A13="","",IFERROR(INDEX('予算シート'!$B:$B,MATCH(A13,'予算シート'!$A:$A,0)),"案件が未登録")) | D13: =IF(C13="","",IFERROR(INDEX('システム'!$B:$B,MATCH(C13,'システム'!$A:$A,0)),"システムが未登録"))
B14: =IF(A14="","",IFERROR(INDEX('予算シート'!$B:$B,MATCH(A14,'予算シート'!$A:$A,0)),"案件が未登録")) | D14: =IF(C14="","",IFERROR(INDEX('システム'!$B:$B,MATCH(C14,'システム'!$A:$A,0)),"システムが未登録"))
B15: =IF(A15="","",IFERROR(INDEX('予算シート'!$B:$B,MATCH(A15,'予算シート'!$A:$A,0)),"案件が未登録")) | D15: =IF(C15="","",IFERROR(INDEX('システム'!$B:$B,MATCH(C15,'システム'!$A:$A,0)),"システムが未登録"))
B16: =IF(A16="","",IFERROR(INDEX('予算シート'!$B:$B,MATCH(A16,'予算シート'!$A:$A,0)),"案件が未登録")) | D16: =IF(C16="","",IFERROR(INDEX('システム'!$B:$B,MATCH(C16,'システム'!$A:$A,0)),"システムが未登録"))
B17: =IF(A17="","",IFERROR(INDEX('予算シート'!$B:$B,MATCH(A17,'予算シート'!$A:$A,0)),"案件が未登録")) | D17: =IF(C17="","",IFERROR(INDEX('システム'!$B:$B,MATCH(C17,'システム'!$A:$A,0)),"システムが未登録"))
B18: =IF(A18="","",IFERROR(INDEX('予算シート'!$B:$B,MATCH(A18,'予算シート'!$A:$A,0)),"案件が未登録")) | D18: =IF(C18="","",IFERROR(INDEX('システム'!$B:$B,MATCH(C18,'システム'!$A:$A,0)),"システムが未登録"))
B19: =IF(A19="","",IFERROR(INDEX('予算シート'!$B:$B,MATCH(A19,'予算シート'!$A:$A,0)),"案件が未登録")) | D19: =IF(C19="","",IFERROR(INDEX('システム'!$B:$B,MATCH(C19,'システム'!$A:$A,0)),"システムが未登録"))
... B200: =IF(A200="","",IFERROR(INDEX('予算シート'!$B:$B,MATCH(A200,'予算シート'!$A:$A,0)),"案件が未登録")) | D200: =IF(C200="","",IFERROR(INDEX('システム'!$B:$B,MATCH(C200,'システム'!$A:$A,0)),"システムが未登録"))

Sheet システム
A1: システム（実在のシステム名）
A2: 1行＝1システム。外部性（利用範囲・データの利用範囲・環境）だけで移管するかを決め、安定性（文書の整備・内部の管理者、GxP対象・個人情報）で移管の順番（初年度／2年目以降）を決める。基準は「判定表」の1〜4。案件との対応は「紐付け」シートに書く。灰色の列は数式。薄い色の3行は記入例。
A3: システムID | B3: システム名 | C3: オーナー部門 | D3: GxP対象 | E3: 個人情報 | F3: EOL期限 （決まっていれば日付） | G3: 利用範囲 | H3: データの利用範囲 | I3: 環境 | J3: 外部性（自動） | K3: 文書の整備 | L3: 内部の管理者 | M3: 安定性（自動） | N3: システム移管判定（自動） | O3: 移管時期（自動）
A4: SYS-003 | B4: 品質文書システム | C4: 品質保証部 | D4: はい | E4: いいえ | F4: 46843 | G4: 他部門も利用 | H4: 他部門・他システムも利用 | I4: 自部門専用 | J4: =IF(A4="","",IF(COUNTA(G4:I4)<3,"判定保留",IFERROR(CHOOSE(MAX(INDEX('判定表'!$D:$D,MATCH("E|利用範囲|"&G4,'判定表'!$A:$A,0)),INDEX('判定表'!$D:$D,MATCH("E|データの利用範囲|"&H4,'判定表'!$A:$A,0)),INDEX('判定表'!$D:$D,MATCH("E|環境|"&I4,'判定表'!$A:$A,0)))+1,"低","中","高"),"判定表にない回答"))) | K4: 一式ある | L4: いる（内容を判断できる） | M4: =IF(A4="","",IF(OR(K4="",L4="",D4="",E4="",D4="未確認",E4="未確認"),"判定保留",IFERROR(IF(OR(D4="はい",E4="はい"),INDEX('判定表'!$D:$D,MATCH("L|"&INDEX('判定表'!$D:$D,MATCH("D|"&K4&"|"&L4,'判定表'!$A:$A,0)),'判定表'!$A:$A,0)),INDEX('判定表'!$D:$D,MATCH("D|"&K4&"|"&L4,'判定表'!$A:$A,0))),"判定表にない組み合わせ"))) | N4: =IF(A4="","",IF(J4="判定保留","判定保留",IFERROR(INDEX('判定表'!$D:$D,MATCH("S|"&J4,'判定表'!$A:$A,0)),"判定表にない回答"))) | O4: =IF(A4="","",IF(N4="留保","—",IF(OR(N4="判定保留",M4="判定保留"),"判定保留",IFERROR(INDEX('判定表'!$D:$D,MATCH("T|"&J4&"|"&M4,'判定表'!$A:$A,0)),"判定表にない組み合わせ"))))
A5: SYS-012 | B5: 研究クラウド基盤 | C5: IT部門 | D5: いいえ | E5: いいえ | G5: 他部門も利用 | H5: 他部門・他システムも利用 | I5: 全社共用の基盤そのもの | J5: =IF(A5="","",IF(COUNTA(G5:I5)<3,"判定保留",IFERROR(CHOOSE(MAX(INDEX('判定表'!$D:$D,MATCH("E|利用範囲|"&G5,'判定表'!$A:$A,0)),INDEX('判定表'!$D:$D,MATCH("E|データの利用範囲|"&H5,'判定表'!$A:$A,0)),INDEX('判定表'!$D:$D,MATCH("E|環境|"&I5,'判定表'!$A:$A,0)))+1,"低","中","高"),"判定表にない回答"))) | K5: 一部ある | L5: 名目上いる | M5: =IF(A5="","",IF(OR(K5="",L5="",D5="",E5="",D5="未確認",E5="未確認"),"判定保留",IFERROR(IF(OR(D5="はい",E5="はい"),INDEX('判定表'!$D:$D,MATCH("L|"&INDEX('判定表'!$D:$D,MATCH("D|"&K5&"|"&L5,'判定表'!$A:$A,0)),'判定表'!$A:$A,0)),INDEX('判定表'!$D:$D,MATCH("D|"&K5&"|"&L5,'判定表'!$A:$A,0))),"判定表にない組み合わせ"))) | N5: =IF(A5="","",IF(J5="判定保留","判定保留",IFERROR(INDEX('判定表'!$D:$D,MATCH("S|"&J5,'判定表'!$A:$A,0)),"判定表にない回答"))) | O5: =IF(A5="","",IF(N5="留保","—",IF(OR(N5="判定保留",M5="判定保留"),"判定保留",IFERROR(INDEX('判定表'!$D:$D,MATCH("T|"&J5&"|"&M5,'判定表'!$A:$A,0)),"判定表にない組み合わせ"))))
A6: SYS-041 | B6: 実験データ集計ツール | C6: 研究本部 | D6: いいえ | E6: いいえ | G6: 自部門のみ | H6: 自部門のみ | I6: 自部門専用 | J6: =IF(A6="","",IF(COUNTA(G6:I6)<3,"判定保留",IFERROR(CHOOSE(MAX(INDEX('判定表'!$D:$D,MATCH("E|利用範囲|"&G6,'判定表'!$A:$A,0)),INDEX('判定表'!$D:$D,MATCH("E|データの利用範囲|"&H6,'判定表'!$A:$A,0)),INDEX('判定表'!$D:$D,MATCH("E|環境|"&I6,'判定表'!$A:$A,0)))+1,"低","中","高"),"判定表にない回答"))) | K6: ない | L6: いる（内容を判断できる） | M6: =IF(A6="","",IF(OR(K6="",L6="",D6="",E6="",D6="未確認",E6="未確認"),"判定保留",IFERROR(IF(OR(D6="はい",E6="はい"),INDEX('判定表'!$D:$D,MATCH("L|"&INDEX('判定表'!$D:$D,MATCH("D|"&K6&"|"&L6,'判定表'!$A:$A,0)),'判定表'!$A:$A,0)),INDEX('判定表'!$D:$D,MATCH("D|"&K6&"|"&L6,'判定表'!$A:$A,0))),"判定表にない組み合わせ"))) | N6: =IF(A6="","",IF(J6="判定保留","判定保留",IFERROR(INDEX('判定表'!$D:$D,MATCH("S|"&J6,'判定表'!$A:$A,0)),"判定表にない回答"))) | O6: =IF(A6="","",IF(N6="留保","—",IF(OR(N6="判定保留",M6="判定保留"),"判定保留",IFERROR(INDEX('判定表'!$D:$D,MATCH("T|"&J6&"|"&M6,'判定表'!$A:$A,0)),"判定表にない組み合わせ"))))
J7: =IF(A7="","",IF(COUNTA(G7:I7)<3,"判定保留",IFERROR(CHOOSE(MAX(INDEX('判定表'!$D:$D,MATCH("E|利用範囲|"&G7,'判定表'!$A:$A,0)),INDEX('判定表'!$D:$D,MATCH("E|データの利用範囲|"&H7,'判定表'!$A:$A,0)),INDEX('判定表'!$D:$D,MATCH("E|環境|"&I7,'判定表'!$A:$A,0)))+1,"低","中","高"),"判定表にない回答"))) | M7: =IF(A7="","",IF(OR(K7="",L7="",D7="",E7="",D7="未確認",E7="未確認"),"判定保留",IFERROR(IF(OR(D7="はい",E7="はい"),INDEX('判定表'!$D:$D,MATCH("L|"&INDEX('判定表'!$D:$D,MATCH("D|"&K7&"|"&L7,'判定表'!$A:$A,0)),'判定表'!$A:$A,0)),INDEX('判定表'!$D:$D,MATCH("D|"&K7&"|"&L7,'判定表'!$A:$A,0))),"判定表にない組み合わせ"))) | N7: =IF(A7="","",IF(J7="判定保留","判定保留",IFERROR(INDEX('判定表'!$D:$D,MATCH("S|"&J7,'判定表'!$A:$A,0)),"判定表にない回答"))) | O7: =IF(A7="","",IF(N7="留保","—",IF(OR(N7="判定保留",M7="判定保留"),"判定保留",IFERROR(INDEX('判定表'!$D:$D,MATCH("T|"&J7&"|"&M7,'判定表'!$A:$A,0)),"判定表にない組み合わせ"))))
J8: =IF(A8="","",IF(COUNTA(G8:I8)<3,"判定保留",IFERROR(CHOOSE(MAX(INDEX('判定表'!$D:$D,MATCH("E|利用範囲|"&G8,'判定表'!$A:$A,0)),INDEX('判定表'!$D:$D,MATCH("E|データの利用範囲|"&H8,'判定表'!$A:$A,0)),INDEX('判定表'!$D:$D,MATCH("E|環境|"&I8,'判定表'!$A:$A,0)))+1,"低","中","高"),"判定表にない回答"))) | M8: =IF(A8="","",IF(OR(K8="",L8="",D8="",E8="",D8="未確認",E8="未確認"),"判定保留",IFERROR(IF(OR(D8="はい",E8="はい"),INDEX('判定表'!$D:$D,MATCH("L|"&INDEX('判定表'!$D:$D,MATCH("D|"&K8&"|"&L8,'判定表'!$A:$A,0)),'判定表'!$A:$A,0)),INDEX('判定表'!$D:$D,MATCH("D|"&K8&"|"&L8,'判定表'!$A:$A,0))),"判定表にない組み合わせ"))) | N8: =IF(A8="","",IF(J8="判定保留","判定保留",IFERROR(INDEX('判定表'!$D:$D,MATCH("S|"&J8,'判定表'!$A:$A,0)),"判定表にない回答"))) | O8: =IF(A8="","",IF(N8="留保","—",IF(OR(N8="判定保留",M8="判定保留"),"判定保留",IFERROR(INDEX('判定表'!$D:$D,MATCH("T|"&J8&"|"&M8,'判定表'!$A:$A,0)),"判定表にない組み合わせ"))))
J9: =IF(A9="","",IF(COUNTA(G9:I9)<3,"判定保留",IFERROR(CHOOSE(MAX(INDEX('判定表'!$D:$D,MATCH("E|利用範囲|"&G9,'判定表'!$A:$A,0)),INDEX('判定表'!$D:$D,MATCH("E|データの利用範囲|"&H9,'判定表'!$A:$A,0)),INDEX('判定表'!$D:$D,MATCH("E|環境|"&I9,'判定表'!$A:$A,0)))+1,"低","中","高"),"判定表にない回答"))) | M9: =IF(A9="","",IF(OR(K9="",L9="",D9="",E9="",D9="未確認",E9="未確認"),"判定保留",IFERROR(IF(OR(D9="はい",E9="はい"),INDEX('判定表'!$D:$D,MATCH("L|"&INDEX('判定表'!$D:$D,MATCH("D|"&K9&"|"&L9,'判定表'!$A:$A,0)),'判定表'!$A:$A,0)),INDEX('判定表'!$D:$D,MATCH("D|"&K9&"|"&L9,'判定表'!$A:$A,0))),"判定表にない組み合わせ"))) | N9: =IF(A9="","",IF(J9="判定保留","判定保留",IFERROR(INDEX('判定表'!$D:$D,MATCH("S|"&J9,'判定表'!$A:$A,0)),"判定表にない回答"))) | O9: =IF(A9="","",IF(N9="留保","—",IF(OR(N9="判定保留",M9="判定保留"),"判定保留",IFERROR(INDEX('判定表'!$D:$D,MATCH("T|"&J9&"|"&M9,'判定表'!$A:$A,0)),"判定表にない組み合わせ"))))
J10: =IF(A10="","",IF(COUNTA(G10:I10)<3,"判定保留",IFERROR(CHOOSE(MAX(INDEX('判定表'!$D:$D,MATCH("E|利用範囲|"&G10,'判定表'!$A:$A,0)),INDEX('判定表'!$D:$D,MATCH("E|データの利用範囲|"&H10,'判定表'!$A:$A,0)),INDEX('判定表'!$D:$D,MATCH("E|環境|"&I10,'判定表'!$A:$A,0)))+1,"低","中","高"),"判定表にない回答"))) | M10: =IF(A10="","",IF(OR(K10="",L10="",D10="",E10="",D10="未確認",E10="未確認"),"判定保留",IFERROR(IF(OR(D10="はい",E10="はい"),INDEX('判定表'!$D:$D,MATCH("L|"&INDEX('判定表'!$D:$D,MATCH("D|"&K10&"|"&L10,'判定表'!$A:$A,0)),'判定表'!$A:$A,0)),INDEX('判定表'!$D:$D,MATCH("D|"&K10&"|"&L10,'判定表'!$A:$A,0))),"判定表にない組み合わせ"))) | N10: =IF(A10="","",IF(J10="判定保留","判定保留",IFERROR(INDEX('判定表'!$D:$D,MATCH("S|"&J10,'判定表'!$A:$A,0)),"判定表にない回答"))) | O10: =IF(A10="","",IF(N10="留保","—",IF(OR(N10="判定保留",M10="判定保留"),"判定保留",IFERROR(INDEX('判定表'!$D:$D,MATCH("T|"&J10&"|"&M10,'判定表'!$A:$A,0)),"判定表にない組み合わせ"))))
J11: =IF(A11="","",IF(COUNTA(G11:I11)<3,"判定保留",IFERROR(CHOOSE(MAX(INDEX('判定表'!$D:$D,MATCH("E|利用範囲|"&G11,'判定表'!$A:$A,0)),INDEX('判定表'!$D:$D,MATCH("E|データの利用範囲|"&H11,'判定表'!$A:$A,0)),INDEX('判定表'!$D:$D,MATCH("E|環境|"&I11,'判定表'!$A:$A,0)))+1,"低","中","高"),"判定表にない回答"))) | M11: =IF(A11="","",IF(OR(K11="",L11="",D11="",E11="",D11="未確認",E11="未確認"),"判定保留",IFERROR(IF(OR(D11="はい",E11="はい"),INDEX('判定表'!$D:$D,MATCH("L|"&INDEX('判定表'!$D:$D,MATCH("D|"&K11&"|"&L11,'判定表'!$A:$A,0)),'判定表'!$A:$A,0)),INDEX('判定表'!$D:$D,MATCH("D|"&K11&"|"&L11,'判定表'!$A:$A,0))),"判定表にない組み合わせ"))) | N11: =IF(A11="","",IF(J11="判定保留","判定保留",IFERROR(INDEX('判定表'!$D:$D,MATCH("S|"&J11,'判定表'!$A:$A,0)),"判定表にない回答"))) | O11: =IF(A11="","",IF(N11="留保","—",IF(OR(N11="判定保留",M11="判定保留"),"判定保留",IFERROR(INDEX('判定表'!$D:$D,MATCH("T|"&J11&"|"&M11,'判定表'!$A:$A,0)),"判定表にない組み合わせ"))))
J12: =IF(A12="","",IF(COUNTA(G12:I12)<3,"判定保留",IFERROR(CHOOSE(MAX(INDEX('判定表'!$D:$D,MATCH("E|利用範囲|"&G12,'判定表'!$A:$A,0)),INDEX('判定表'!$D:$D,MATCH("E|データの利用範囲|"&H12,'判定表'!$A:$A,0)),INDEX('判定表'!$D:$D,MATCH("E|環境|"&I12,'判定表'!$A:$A,0)))+1,"低","中","高"),"判定表にない回答"))) | M12: =IF(A12="","",IF(OR(K12="",L12="",D12="",E12="",D12="未確認",E12="未確認"),"判定保留",IFERROR(IF(OR(D12="はい",E12="はい"),INDEX('判定表'!$D:$D,MATCH("L|"&INDEX('判定表'!$D:$D,MATCH("D|"&K12&"|"&L12,'判定表'!$A:$A,0)),'判定表'!$A:$A,0)),INDEX('判定表'!$D:$D,MATCH("D|"&K12&"|"&L12,'判定表'!$A:$A,0))),"判定表にない組み合わせ"))) | N12: =IF(A12="","",IF(J12="判定保留","判定保留",IFERROR(INDEX('判定表'!$D:$D,MATCH("S|"&J12,'判定表'!$A:$A,0)),"判定表にない回答"))) | O12: =IF(A12="","",IF(N12="留保","—",IF(OR(N12="判定保留",M12="判定保留"),"判定保留",IFERROR(INDEX('判定表'!$D:$D,MATCH("T|"&J12&"|"&M12,'判定表'!$A:$A,0)),"判定表にない組み合わせ"))))
J13: =IF(A13="","",IF(COUNTA(G13:I13)<3,"判定保留",IFERROR(CHOOSE(MAX(INDEX('判定表'!$D:$D,MATCH("E|利用範囲|"&G13,'判定表'!$A:$A,0)),INDEX('判定表'!$D:$D,MATCH("E|データの利用範囲|"&H13,'判定表'!$A:$A,0)),INDEX('判定表'!$D:$D,MATCH("E|環境|"&I13,'判定表'!$A:$A,0)))+1,"低","中","高"),"判定表にない回答"))) | M13: =IF(A13="","",IF(OR(K13="",L13="",D13="",E13="",D13="未確認",E13="未確認"),"判定保留",IFERROR(IF(OR(D13="はい",E13="はい"),INDEX('判定表'!$D:$D,MATCH("L|"&INDEX('判定表'!$D:$D,MATCH("D|"&K13&"|"&L13,'判定表'!$A:$A,0)),'判定表'!$A:$A,0)),INDEX('判定表'!$D:$D,MATCH("D|"&K13&"|"&L13,'判定表'!$A:$A,0))),"判定表にない組み合わせ"))) | N13: =IF(A13="","",IF(J13="判定保留","判定保留",IFERROR(INDEX('判定表'!$D:$D,MATCH("S|"&J13,'判定表'!$A:$A,0)),"判定表にない回答"))) | O13: =IF(A13="","",IF(N13="留保","—",IF(OR(N13="判定保留",M13="判定保留"),"判定保留",IFERROR(INDEX('判定表'!$D:$D,MATCH("T|"&J13&"|"&M13,'判定表'!$A:$A,0)),"判定表にない組み合わせ"))))
J14: =IF(A14="","",IF(COUNTA(G14:I14)<3,"判定保留",IFERROR(CHOOSE(MAX(INDEX('判定表'!$D:$D,MATCH("E|利用範囲|"&G14,'判定表'!$A:$A,0)),INDEX('判定表'!$D:$D,MATCH("E|データの利用範囲|"&H14,'判定表'!$A:$A,0)),INDEX('判定表'!$D:$D,MATCH("E|環境|"&I14,'判定表'!$A:$A,0)))+1,"低","中","高"),"判定表にない回答"))) | M14: =IF(A14="","",IF(OR(K14="",L14="",D14="",E14="",D14="未確認",E14="未確認"),"判定保留",IFERROR(IF(OR(D14="はい",E14="はい"),INDEX('判定表'!$D:$D,MATCH("L|"&INDEX('判定表'!$D:$D,MATCH("D|"&K14&"|"&L14,'判定表'!$A:$A,0)),'判定表'!$A:$A,0)),INDEX('判定表'!$D:$D,MATCH("D|"&K14&"|"&L14,'判定表'!$A:$A,0))),"判定表にない組み合わせ"))) | N14: =IF(A14="","",IF(J14="判定保留","判定保留",IFERROR(INDEX('判定表'!$D:$D,MATCH("S|"&J14,'判定表'!$A:$A,0)),"判定表にない回答"))) | O14: =IF(A14="","",IF(N14="留保","—",IF(OR(N14="判定保留",M14="判定保留"),"判定保留",IFERROR(INDEX('判定表'!$D:$D,MATCH("T|"&J14&"|"&M14,'判定表'!$A:$A,0)),"判定表にない組み合わせ"))))
J15: =IF(A15="","",IF(COUNTA(G15:I15)<3,"判定保留",IFERROR(CHOOSE(MAX(INDEX('判定表'!$D:$D,MATCH("E|利用範囲|"&G15,'判定表'!$A:$A,0)),INDEX('判定表'!$D:$D,MATCH("E|データの利用範囲|"&H15,'判定表'!$A:$A,0)),INDEX('判定表'!$D:$D,MATCH("E|環境|"&I15,'判定表'!$A:$A,0)))+1,"低","中","高"),"判定表にない回答"))) | M15: =IF(A15="","",IF(OR(K15="",L15="",D15="",E15="",D15="未確認",E15="未確認"),"判定保留",IFERROR(IF(OR(D15="はい",E15="はい"),INDEX('判定表'!$D:$D,MATCH("L|"&INDEX('判定表'!$D:$D,MATCH("D|"&K15&"|"&L15,'判定表'!$A:$A,0)),'判定表'!$A:$A,0)),INDEX('判定表'!$D:$D,MATCH("D|"&K15&"|"&L15,'判定表'!$A:$A,0))),"判定表にない組み合わせ"))) | N15: =IF(A15="","",IF(J15="判定保留","判定保留",IFERROR(INDEX('判定表'!$D:$D,MATCH("S|"&J15,'判定表'!$A:$A,0)),"判定表にない回答"))) | O15: =IF(A15="","",IF(N15="留保","—",IF(OR(N15="判定保留",M15="判定保留"),"判定保留",IFERROR(INDEX('判定表'!$D:$D,MATCH("T|"&J15&"|"&M15,'判定表'!$A:$A,0)),"判定表にない組み合わせ"))))
J16: =IF(A16="","",IF(COUNTA(G16:I16)<3,"判定保留",IFERROR(CHOOSE(MAX(INDEX('判定表'!$D:$D,MATCH("E|利用範囲|"&G16,'判定表'!$A:$A,0)),INDEX('判定表'!$D:$D,MATCH("E|データの利用範囲|"&H16,'判定表'!$A:$A,0)),INDEX('判定表'!$D:$D,MATCH("E|環境|"&I16,'判定表'!$A:$A,0)))+1,"低","中","高"),"判定表にない回答"))) | M16: =IF(A16="","",IF(OR(K16="",L16="",D16="",E16="",D16="未確認",E16="未確認"),"判定保留",IFERROR(IF(OR(D16="はい",E16="はい"),INDEX('判定表'!$D:$D,MATCH("L|"&INDEX('判定表'!$D:$D,MATCH("D|"&K16&"|"&L16,'判定表'!$A:$A,0)),'判定表'!$A:$A,0)),INDEX('判定表'!$D:$D,MATCH("D|"&K16&"|"&L16,'判定表'!$A:$A,0))),"判定表にない組み合わせ"))) | N16: =IF(A16="","",IF(J16="判定保留","判定保留",IFERROR(INDEX('判定表'!$D:$D,MATCH("S|"&J16,'判定表'!$A:$A,0)),"判定表にない回答"))) | O16: =IF(A16="","",IF(N16="留保","—",IF(OR(N16="判定保留",M16="判定保留"),"判定保留",IFERROR(INDEX('判定表'!$D:$D,MATCH("T|"&J16&"|"&M16,'判定表'!$A:$A,0)),"判定表にない組み合わせ"))))
J17: =IF(A17="","",IF(COUNTA(G17:I17)<3,"判定保留",IFERROR(CHOOSE(MAX(INDEX('判定表'!$D:$D,MATCH("E|利用範囲|"&G17,'判定表'!$A:$A,0)),INDEX('判定表'!$D:$D,MATCH("E|データの利用範囲|"&H17,'判定表'!$A:$A,0)),INDEX('判定表'!$D:$D,MATCH("E|環境|"&I17,'判定表'!$A:$A,0)))+1,"低","中","高"),"判定表にない回答"))) | M17: =IF(A17="","",IF(OR(K17="",L17="",D17="",E17="",D17="未確認",E17="未確認"),"判定保留",IFERROR(IF(OR(D17="はい",E17="はい"),INDEX('判定表'!$D:$D,MATCH("L|"&INDEX('判定表'!$D:$D,MATCH("D|"&K17&"|"&L17,'判定表'!$A:$A,0)),'判定表'!$A:$A,0)),INDEX('判定表'!$D:$D,MATCH("D|"&K17&"|"&L17,'判定表'!$A:$A,0))),"判定表にない組み合わせ"))) | N17: =IF(A17="","",IF(J17="判定保留","判定保留",IFERROR(INDEX('判定表'!$D:$D,MATCH("S|"&J17,'判定表'!$A:$A,0)),"判定表にない回答"))) | O17: =IF(A17="","",IF(N17="留保","—",IF(OR(N17="判定保留",M17="判定保留"),"判定保留",IFERROR(INDEX('判定表'!$D:$D,MATCH("T|"&J17&"|"&M17,'判定表'!$A:$A,0)),"判定表にない組み合わせ"))))
J18: =IF(A18="","",IF(COUNTA(G18:I18)<3,"判定保留",IFERROR(CHOOSE(MAX(INDEX('判定表'!$D:$D,MATCH("E|利用範囲|"&G18,'判定表'!$A:$A,0)),INDEX('判定表'!$D:$D,MATCH("E|データの利用範囲|"&H18,'判定表'!$A:$A,0)),INDEX('判定表'!$D:$D,MATCH("E|環境|"&I18,'判定表'!$A:$A,0)))+1,"低","中","高"),"判定表にない回答"))) | M18: =IF(A18="","",IF(OR(K18="",L18="",D18="",E18="",D18="未確認",E18="未確認"),"判定保留",IFERROR(IF(OR(D18="はい",E18="はい"),INDEX('判定表'!$D:$D,MATCH("L|"&INDEX('判定表'!$D:$D,MATCH("D|"&K18&"|"&L18,'判定表'!$A:$A,0)),'判定表'!$A:$A,0)),INDEX('判定表'!$D:$D,MATCH("D|"&K18&"|"&L18,'判定表'!$A:$A,0))),"判定表にない組み合わせ"))) | N18: =IF(A18="","",IF(J18="判定保留","判定保留",IFERROR(INDEX('判定表'!$D:$D,MATCH("S|"&J18,'判定表'!$A:$A,0)),"判定表にない回答"))) | O18: =IF(A18="","",IF(N18="留保","—",IF(OR(N18="判定保留",M18="判定保留"),"判定保留",IFERROR(INDEX('判定表'!$D:$D,MATCH("T|"&J18&"|"&M18,'判定表'!$A:$A,0)),"判定表にない組み合わせ"))))
... J200: =IF(A200="","",IF(COUNTA(G200:I200)<3,"判定保留",IFERROR(CHOOSE(MAX(INDEX('判定表'!$D:$D,MATCH("E|利用範囲|"&G200,'判定表'!$A:$A,0)),INDEX('判定表'!$D:$D,MATCH("E|データの利用範囲|"&H200,'判定表'!$A:$A,0)),INDEX('判定表'!$D:$D,MATCH("E|環境|"&I200,'判定表'!$A:$A,0)))+1,"低","中","高"),"判定表にない回答"))) | M200: =IF(A200="","",IF(OR(K200="",L200="",D200="",E200="",D200="未確認",E200="未確認"),"判定保留",IFERROR(IF(OR(D200="はい",E200="はい"),INDEX('判定表'!$D:$D,MATCH("L|"&INDEX('判定表'!$D:$D,MATCH("D|"&K200&"|"&L200,'判定表'!$A:$A,0)),'判定表'!$A:$A,0)),INDEX('判定表'!$D:$D,MATCH("D|"&K200&"|"&L200,'判定表'!$A:$A,0))),"判定表にない組み合わせ"))) | N200: =IF(A200="","",IF(J200="判定保留","判定保留",IFERROR(INDEX('判定表'!$D:$D,MATCH("S|"&J200,'判定表'!$A:$A,0)),"判定表にない回答"))) | O200: =IF(A200="","",IF(N200="留保","—",IF(OR(N200="判定保留",M200="判定保留"),"判定保留",IFERROR(INDEX('判定表'!$D:$D,MATCH("T|"&J200&"|"&M200,'判定表'!$A:$A,0)),"判定表にない組み合わせ"))))

Sheet 業務
A1: 業務（移管の対象と引継ぎ）
A2: 1行＝1つの業務。システムに関する業務だけを棚卸しする（システムの運用・開発、委託先の管理、契約・予算の管理など）。業務移管判定はシステムの判定を引き継ぎ、困難度は現場の関わり方とGxP対象・個人情報・SOP有無から決まる（「判定表」の5）。契約を管理する業務には関連契約IDを書く。灰色の列は数式。薄い色の行は記入例。
A3: 業務ID | B3: 業務名 | C3: 対象システムID | D3: システム名（自動） | E3: 業務の種類 | F3: 現在の実施者 | G3: 頻度 | H3: 年間工数（人日） | I3: 棚卸し （済／未） | J3: GxP対象 | K3: 個人情報 | L3: SOP有無 | M3: 関連契約ID | N3: 現場の関わり方 | O3: 困難度（自動） | P3: 業務移管判定（自動） | Q3: 移管の方法（自動）
A4: OPS-001 | B4: クラウド環境の監視と障害一次対応 | C4: SYS-012 | D4: =IF(C4="","",IFERROR(INDEX('システム'!$B:$B,MATCH(C4,'システム'!$A:$A,0)),"システムが未登録")) | E4: 運用・監視 | F4: 委託先 | G4: 日次 | H4: 60 | I4: 済 | J4: いいえ | K4: いいえ | L4: 有 | M4: CT-2201 | N4: 委託先の管理（指示・検収） | O4: =IF(A4="","",IF(I4<>"済","判定保留",IF(OR(N4="",J4="",K4="",L4="",J4="未確認",K4="未確認"),"判定保留",IF(AND(J4="はい",L4="無"),"入力エラー（GxP対象でSOP無）",IFERROR(INDEX('判定表'!$D:$D,MATCH("W|"&N4&"|"&IF(OR(J4="はい",K4="はい",L4="無"),"あり","なし"),'判定表'!$A:$A,0)),"判定表にない組み合わせ"))))) | P4: =IF(A4="","",IF(C4="","対象外",IF(COUNTIFS('システム'!$A$4:$A$200,C4,'システム'!$N$4:$N$200,"移管")>0,"移管",IF(COUNTIFS('システム'!$A$4:$A$200,C4,'システム'!$N$4:$N$200,"留保")>0,"留保","判定保留")))) | Q4: =IF(A4="","",IF(P4<>"移管","—",IF(N4="","判定保留",IFERROR(INDEX('判定表'!$E:$E,MATCH("W|"&N4&"|なし",'判定表'!$A:$A,0)),"判定表にない回答"))))
A5: OPS-002 | B5: 利用者アカウントの登録・削除 | C5: SYS-003 | D5: =IF(C5="","",IFERROR(INDEX('システム'!$B:$B,MATCH(C5,'システム'!$A:$A,0)),"システムが未登録")) | E5: ユーザー管理 | F5: 現場部門 | G5: 随時 | H5: 24 | I5: 済 | J5: はい | K5: いいえ | L5: 有 | N5: 自ら運用・開発 | O5: =IF(A5="","",IF(I5<>"済","判定保留",IF(OR(N5="",J5="",K5="",L5="",J5="未確認",K5="未確認"),"判定保留",IF(AND(J5="はい",L5="無"),"入力エラー（GxP対象でSOP無）",IFERROR(INDEX('判定表'!$D:$D,MATCH("W|"&N5&"|"&IF(OR(J5="はい",K5="はい",L5="無"),"あり","なし"),'判定表'!$A:$A,0)),"判定表にない組み合わせ"))))) | P5: =IF(A5="","",IF(C5="","対象外",IF(COUNTIFS('システム'!$A$4:$A$200,C5,'システム'!$N$4:$N$200,"移管")>0,"移管",IF(COUNTIFS('システム'!$A$4:$A$200,C5,'システム'!$N$4:$N$200,"留保")>0,"留保","判定保留")))) | Q5: =IF(A5="","",IF(P5<>"移管","—",IF(N5="","判定保留",IFERROR(INDEX('判定表'!$E:$E,MATCH("W|"&N5&"|なし",'判定表'!$A:$A,0)),"判定表にない回答"))))
A6: OPS-003 | B6: 委託先の月次報告のレビューと検収 | C6: SYS-012 | D6: =IF(C6="","",IFERROR(INDEX('システム'!$B:$B,MATCH(C6,'システム'!$A:$A,0)),"システムが未登録")) | E6: 委託先管理 | F6: 現場部門 | G6: 月次 | H6: 12 | I6: 済 | J6: いいえ | K6: いいえ | L6: 無 | M6: CT-2201 | N6: 委託先の管理（指示・検収） | O6: =IF(A6="","",IF(I6<>"済","判定保留",IF(OR(N6="",J6="",K6="",L6="",J6="未確認",K6="未確認"),"判定保留",IF(AND(J6="はい",L6="無"),"入力エラー（GxP対象でSOP無）",IFERROR(INDEX('判定表'!$D:$D,MATCH("W|"&N6&"|"&IF(OR(J6="はい",K6="はい",L6="無"),"あり","なし"),'判定表'!$A:$A,0)),"判定表にない組み合わせ"))))) | P6: =IF(A6="","",IF(C6="","対象外",IF(COUNTIFS('システム'!$A$4:$A$200,C6,'システム'!$N$4:$N$200,"移管")>0,"移管",IF(COUNTIFS('システム'!$A$4:$A$200,C6,'システム'!$N$4:$N$200,"留保")>0,"留保","判定保留")))) | Q6: =IF(A6="","",IF(P6<>"移管","—",IF(N6="","判定保留",IFERROR(INDEX('判定表'!$E:$E,MATCH("W|"&N6&"|なし",'判定表'!$A:$A,0)),"判定表にない回答"))))
A7: OPS-004 | B7: eDMS保守契約の発注・検収・支払い | C7: SYS-003 | D7: =IF(C7="","",IFERROR(INDEX('システム'!$B:$B,MATCH(C7,'システム'!$A:$A,0)),"システムが未登録")) | E7: 費用管理 | F7: 現場部門 | G7: 月次 | H7: 6 | I7: 済 | J7: はい | K7: いいえ | L7: 有 | M7: CT-1187 | N7: 予算・契約の管理のみ | O7: =IF(A7="","",IF(I7<>"済","判定保留",IF(OR(N7="",J7="",K7="",L7="",J7="未確認",K7="未確認"),"判定保留",IF(AND(J7="はい",L7="無"),"入力エラー（GxP対象でSOP無）",IFERROR(INDEX('判定表'!$D:$D,MATCH("W|"&N7&"|"&IF(OR(J7="はい",K7="はい",L7="無"),"あり","なし"),'判定表'!$A:$A,0)),"判定表にない組み合わせ"))))) | P7: =IF(A7="","",IF(C7="","対象外",IF(COUNTIFS('システム'!$A$4:$A$200,C7,'システム'!$N$4:$N$200,"移管")>0,"移管",IF(COUNTIFS('システム'!$A$4:$A$200,C7,'システム'!$N$4:$N$200,"留保")>0,"留保","判定保留")))) | Q7: =IF(A7="","",IF(P7<>"移管","—",IF(N7="","判定保留",IFERROR(INDEX('判定表'!$E:$E,MATCH("W|"&N7&"|なし",'判定表'!$A:$A,0)),"判定表にない回答"))))
D8: =IF(C8="","",IFERROR(INDEX('システム'!$B:$B,MATCH(C8,'システム'!$A:$A,0)),"システムが未登録")) | O8: =IF(A8="","",IF(I8<>"済","判定保留",IF(OR(N8="",J8="",K8="",L8="",J8="未確認",K8="未確認"),"判定保留",IF(AND(J8="はい",L8="無"),"入力エラー（GxP対象でSOP無）",IFERROR(INDEX('判定表'!$D:$D,MATCH("W|"&N8&"|"&IF(OR(J8="はい",K8="はい",L8="無"),"あり","なし"),'判定表'!$A:$A,0)),"判定表にない組み合わせ"))))) | P8: =IF(A8="","",IF(C8="","対象外",IF(COUNTIFS('システム'!$A$4:$A$200,C8,'システム'!$N$4:$N$200,"移管")>0,"移管",IF(COUNTIFS('システム'!$A$4:$A$200,C8,'システム'!$N$4:$N$200,"留保")>0,"留保","判定保留")))) | Q8: =IF(A8="","",IF(P8<>"移管","—",IF(N8="","判定保留",IFERROR(INDEX('判定表'!$E:$E,MATCH("W|"&N8&"|なし",'判定表'!$A:$A,0)),"判定表にない回答"))))
D9: =IF(C9="","",IFERROR(INDEX('システム'!$B:$B,MATCH(C9,'システム'!$A:$A,0)),"システムが未登録")) | O9: =IF(A9="","",IF(I9<>"済","判定保留",IF(OR(N9="",J9="",K9="",L9="",J9="未確認",K9="未確認"),"判定保留",IF(AND(J9="はい",L9="無"),"入力エラー（GxP対象でSOP無）",IFERROR(INDEX('判定表'!$D:$D,MATCH("W|"&N9&"|"&IF(OR(J9="はい",K9="はい",L9="無"),"あり","なし"),'判定表'!$A:$A,0)),"判定表にない組み合わせ"))))) | P9: =IF(A9="","",IF(C9="","対象外",IF(COUNTIFS('システム'!$A$4:$A$200,C9,'システム'!$N$4:$N$200,"移管")>0,"移管",IF(COUNTIFS('システム'!$A$4:$A$200,C9,'システム'!$N$4:$N$200,"留保")>0,"留保","判定保留")))) | Q9: =IF(A9="","",IF(P9<>"移管","—",IF(N9="","判定保留",IFERROR(INDEX('判定表'!$E:$E,MATCH("W|"&N9&"|なし",'判定表'!$A:$A,0)),"判定表にない回答"))))
D10: =IF(C10="","",IFERROR(INDEX('システム'!$B:$B,MATCH(C10,'システム'!$A:$A,0)),"システムが未登録")) | O10: =IF(A10="","",IF(I10<>"済","判定保留",IF(OR(N10="",J10="",K10="",L10="",J10="未確認",K10="未確認"),"判定保留",IF(AND(J10="はい",L10="無"),"入力エラー（GxP対象でSOP無）",IFERROR(INDEX('判定表'!$D:$D,MATCH("W|"&N10&"|"&IF(OR(J10="はい",K10="はい",L10="無"),"あり","なし"),'判定表'!$A:$A,0)),"判定表にない組み合わせ"))))) | P10: =IF(A10="","",IF(C10="","対象外",IF(COUNTIFS('システム'!$A$4:$A$200,C10,'システム'!$N$4:$N$200,"移管")>0,"移管",IF(COUNTIFS('システム'!$A$4:$A$200,C10,'システム'!$N$4:$N$200,"留保")>0,"留保","判定保留")))) | Q10: =IF(A10="","",IF(P10<>"移管","—",IF(N10="","判定保留",IFERROR(INDEX('判定表'!$E:$E,MATCH("W|"&N10&"|なし",'判定表'!$A:$A,0)),"判定表にない回答"))))
D11: =IF(C11="","",IFERROR(INDEX('システム'!$B:$B,MATCH(C11,'システム'!$A:$A,0)),"システムが未登録")) | O11: =IF(A11="","",IF(I11<>"済","判定保留",IF(OR(N11="",J11="",K11="",L11="",J11="未確認",K11="未確認"),"判定保留",IF(AND(J11="はい",L11="無"),"入力エラー（GxP対象でSOP無）",IFERROR(INDEX('判定表'!$D:$D,MATCH("W|"&N11&"|"&IF(OR(J11="はい",K11="はい",L11="無"),"あり","なし"),'判定表'!$A:$A,0)),"判定表にない組み合わせ"))))) | P11: =IF(A11="","",IF(C11="","対象外",IF(COUNTIFS('システム'!$A$4:$A$200,C11,'システム'!$N$4:$N$200,"移管")>0,"移管",IF(COUNTIFS('システム'!$A$4:$A$200,C11,'システム'!$N$4:$N$200,"留保")>0,"留保","判定保留")))) | Q11: =IF(A11="","",IF(P11<>"移管","—",IF(N11="","判定保留",IFERROR(INDEX('判定表'!$E:$E,MATCH("W|"&N11&"|なし",'判定表'!$A:$A,0)),"判定表にない回答"))))
D12: =IF(C12="","",IFERROR(INDEX('システム'!$B:$B,MATCH(C12,'システム'!$A:$A,0)),"システムが未登録")) | O12: =IF(A12="","",IF(I12<>"済","判定保留",IF(OR(N12="",J12="",K12="",L12="",J12="未確認",K12="未確認"),"判定保留",IF(AND(J12="はい",L12="無"),"入力エラー（GxP対象でSOP無）",IFERROR(INDEX('判定表'!$D:$D,MATCH("W|"&N12&"|"&IF(OR(J12="はい",K12="はい",L12="無"),"あり","なし"),'判定表'!$A:$A,0)),"判定表にない組み合わせ"))))) | P12: =IF(A12="","",IF(C12="","対象外",IF(COUNTIFS('システム'!$A$4:$A$200,C12,'システム'!$N$4:$N$200,"移管")>0,"移管",IF(COUNTIFS('システム'!$A$4:$A$200,C12,'システム'!$N$4:$N$200,"留保")>0,"留保","判定保留")))) | Q12: =IF(A12="","",IF(P12<>"移管","—",IF(N12="","判定保留",IFERROR(INDEX('判定表'!$E:$E,MATCH("W|"&N12&"|なし",'判定表'!$A:$A,0)),"判定表にない回答"))))
D13: =IF(C13="","",IFERROR(INDEX('システム'!$B:$B,MATCH(C13,'システム'!$A:$A,0)),"システムが未登録")) | O13: =IF(A13="","",IF(I13<>"済","判定保留",IF(OR(N13="",J13="",K13="",L13="",J13="未確認",K13="未確認"),"判定保留",IF(AND(J13="はい",L13="無"),"入力エラー（GxP対象でSOP無）",IFERROR(INDEX('判定表'!$D:$D,MATCH("W|"&N13&"|"&IF(OR(J13="はい",K13="はい",L13="無"),"あり","なし"),'判定表'!$A:$A,0)),"判定表にない組み合わせ"))))) | P13: =IF(A13="","",IF(C13="","対象外",IF(COUNTIFS('システム'!$A$4:$A$200,C13,'システム'!$N$4:$N$200,"移管")>0,"移管",IF(COUNTIFS('システム'!$A$4:$A$200,C13,'システム'!$N$4:$N$200,"留保")>0,"留保","判定保留")))) | Q13: =IF(A13="","",IF(P13<>"移管","—",IF(N13="","判定保留",IFERROR(INDEX('判定表'!$E:$E,MATCH("W|"&N13&"|なし",'判定表'!$A:$A,0)),"判定表にない回答"))))
D14: =IF(C14="","",IFERROR(INDEX('システム'!$B:$B,MATCH(C14,'システム'!$A:$A,0)),"システムが未登録")) | O14: =IF(A14="","",IF(I14<>"済","判定保留",IF(OR(N14="",J14="",K14="",L14="",J14="未確認",K14="未確認"),"判定保留",IF(AND(J14="はい",L14="無"),"入力エラー（GxP対象でSOP無）",IFERROR(INDEX('判定表'!$D:$D,MATCH("W|"&N14&"|"&IF(OR(J14="はい",K14="はい",L14="無"),"あり","なし"),'判定表'!$A:$A,0)),"判定表にない組み合わせ"))))) | P14: =IF(A14="","",IF(C14="","対象外",IF(COUNTIFS('システム'!$A$4:$A$200,C14,'システム'!$N$4:$N$200,"移管")>0,"移管",IF(COUNTIFS('システム'!$A$4:$A$200,C14,'システム'!$N$4:$N$200,"留保")>0,"留保","判定保留")))) | Q14: =IF(A14="","",IF(P14<>"移管","—",IF(N14="","判定保留",IFERROR(INDEX('判定表'!$E:$E,MATCH("W|"&N14&"|なし",'判定表'!$A:$A,0)),"判定表にない回答"))))
D15: =IF(C15="","",IFERROR(INDEX('システム'!$B:$B,MATCH(C15,'システム'!$A:$A,0)),"システムが未登録")) | O15: =IF(A15="","",IF(I15<>"済","判定保留",IF(OR(N15="",J15="",K15="",L15="",J15="未確認",K15="未確認"),"判定保留",IF(AND(J15="はい",L15="無"),"入力エラー（GxP対象でSOP無）",IFERROR(INDEX('判定表'!$D:$D,MATCH("W|"&N15&"|"&IF(OR(J15="はい",K15="はい",L15="無"),"あり","なし"),'判定表'!$A:$A,0)),"判定表にない組み合わせ"))))) | P15: =IF(A15="","",IF(C15="","対象外",IF(COUNTIFS('システム'!$A$4:$A$200,C15,'システム'!$N$4:$N$200,"移管")>0,"移管",IF(COUNTIFS('システム'!$A$4:$A$200,C15,'システム'!$N$4:$N$200,"留保")>0,"留保","判定保留")))) | Q15: =IF(A15="","",IF(P15<>"移管","—",IF(N15="","判定保留",IFERROR(INDEX('判定表'!$E:$E,MATCH("W|"&N15&"|なし",'判定表'!$A:$A,0)),"判定表にない回答"))))
D16: =IF(C16="","",IFERROR(INDEX('システム'!$B:$B,MATCH(C16,'システム'!$A:$A,0)),"システムが未登録")) | O16: =IF(A16="","",IF(I16<>"済","判定保留",IF(OR(N16="",J16="",K16="",L16="",J16="未確認",K16="未確認"),"判定保留",IF(AND(J16="はい",L16="無"),"入力エラー（GxP対象でSOP無）",IFERROR(INDEX('判定表'!$D:$D,MATCH("W|"&N16&"|"&IF(OR(J16="はい",K16="はい",L16="無"),"あり","なし"),'判定表'!$A:$A,0)),"判定表にない組み合わせ"))))) | P16: =IF(A16="","",IF(C16="","対象外",IF(COUNTIFS('システム'!$A$4:$A$200,C16,'システム'!$N$4:$N$200,"移管")>0,"移管",IF(COUNTIFS('システム'!$A$4:$A$200,C16,'システム'!$N$4:$N$200,"留保")>0,"留保","判定保留")))) | Q16: =IF(A16="","",IF(P16<>"移管","—",IF(N16="","判定保留",IFERROR(INDEX('判定表'!$E:$E,MATCH("W|"&N16&"|なし",'判定表'!$A:$A,0)),"判定表にない回答"))))
D17: =IF(C17="","",IFERROR(INDEX('システム'!$B:$B,MATCH(C17,'システム'!$A:$A,0)),"システムが未登録")) | O17: =IF(A17="","",IF(I17<>"済","判定保留",IF(OR(N17="",J17="",K17="",L17="",J17="未確認",K17="未確認"),"判定保留",IF(AND(J17="はい",L17="無"),"入力エラー（GxP対象でSOP無）",IFERROR(INDEX('判定表'!$D:$D,MATCH("W|"&N17&"|"&IF(OR(J17="はい",K17="はい",L17="無"),"あり","なし"),'判定表'!$A:$A,0)),"判定表にない組み合わせ"))))) | P17: =IF(A17="","",IF(C17="","対象外",IF(COUNTIFS('システム'!$A$4:$A$200,C17,'システム'!$N$4:$N$200,"移管")>0,"移管",IF(COUNTIFS('システム'!$A$4:$A$200,C17,'システム'!$N$4:$N$200,"留保")>0,"留保","判定保留")))) | Q17: =IF(A17="","",IF(P17<>"移管","—",IF(N17="","判定保留",IFERROR(INDEX('判定表'!$E:$E,MATCH("W|"&N17&"|なし",'判定表'!$A:$A,0)),"判定表にない回答"))))
D18: =IF(C18="","",IFERROR(INDEX('システム'!$B:$B,MATCH(C18,'システム'!$A:$A,0)),"システムが未登録")) | O18: =IF(A18="","",IF(I18<>"済","判定保留",IF(OR(N18="",J18="",K18="",L18="",J18="未確認",K18="未確認"),"判定保留",IF(AND(J18="はい",L18="無"),"入力エラー（GxP対象でSOP無）",IFERROR(INDEX('判定表'!$D:$D,MATCH("W|"&N18&"|"&IF(OR(J18="はい",K18="はい",L18="無"),"あり","なし"),'判定表'!$A:$A,0)),"判定表にない組み合わせ"))))) | P18: =IF(A18="","",IF(C18="","対象外",IF(COUNTIFS('システム'!$A$4:$A$200,C18,'システム'!$N$4:$N$200,"移管")>0,"移管",IF(COUNTIFS('システム'!$A$4:$A$200,C18,'システム'!$N$4:$N$200,"留保")>0,"留保","判定保留")))) | Q18: =IF(A18="","",IF(P18<>"移管","—",IF(N18="","判定保留",IFERROR(INDEX('判定表'!$E:$E,MATCH("W|"&N18&"|なし",'判定表'!$A:$A,0)),"判定表にない回答"))))
D19: =IF(C19="","",IFERROR(INDEX('システム'!$B:$B,MATCH(C19,'システム'!$A:$A,0)),"システムが未登録")) | O19: =IF(A19="","",IF(I19<>"済","判定保留",IF(OR(N19="",J19="",K19="",L19="",J19="未確認",K19="未確認"),"判定保留",IF(AND(J19="はい",L19="無"),"入力エラー（GxP対象でSOP無）",IFERROR(INDEX('判定表'!$D:$D,MATCH("W|"&N19&"|"&IF(OR(J19="はい",K19="はい",L19="無"),"あり","なし"),'判定表'!$A:$A,0)),"判定表にない組み合わせ"))))) | P19: =IF(A19="","",IF(C19="","対象外",IF(COUNTIFS('システム'!$A$4:$A$200,C19,'システム'!$N$4:$N$200,"移管")>0,"移管",IF(COUNTIFS('システム'!$A$4:$A$200,C19,'システム'!$N$4:$N$200,"留保")>0,"留保","判定保留")))) | Q19: =IF(A19="","",IF(P19<>"移管","—",IF(N19="","判定保留",IFERROR(INDEX('判定表'!$E:$E,MATCH("W|"&N19&"|なし",'判定表'!$A:$A,0)),"判定表にない回答"))))
... D200: =IF(C200="","",IFERROR(INDEX('システム'!$B:$B,MATCH(C200,'システム'!$A:$A,0)),"システムが未登録")) | O200: =IF(A200="","",IF(I200<>"済","判定保留",IF(OR(N200="",J200="",K200="",L200="",J200="未確認",K200="未確認"),"判定保留",IF(AND(J200="はい",L200="無"),"入力エラー（GxP対象でSOP無）",IFERROR(INDEX('判定表'!$D:$D,MATCH("W|"&N200&"|"&IF(OR(J200="はい",K200="はい",L200="無"),"あり","なし"),'判定表'!$A:$A,0)),"判定表にない組み合わせ"))))) | P200: =IF(A200="","",IF(C200="","対象外",IF(COUNTIFS('システム'!$A$4:$A$200,C200,'システム'!$N$4:$N$200,"移管")>0,"移管",IF(COUNTIFS('システム'!$A$4:$A$200,C200,'システム'!$N$4:$N$200,"留保")>0,"留保","判定保留")))) | Q200: =IF(A200="","",IF(P200<>"移管","—",IF(N200="","判定保留",IFERROR(INDEX('判定表'!$E:$E,MATCH("W|"&N200&"|なし",'判定表'!$A:$A,0)),"判定表にない回答"))))

Sheet 契約
A1: 契約（移管の対象と時期）
A2: 1行＝1契約。案件IDは予算シートの案件IDを選ぶ。契約の移管は紐づく業務（業務シートの関連契約ID）で決まる。紐づく業務がない契約（書籍の購読など、システムと関係ないもの）は対象外。灰色の列は数式。薄い色の3行は記入例。
A3: 契約ID | B3: 契約名 | C3: 案件ID | D3: 案件名（自動） | E3: 相手先 | F3: 契約種別 | G3: 契約名義（部門） | H3: 契約開始日 | I3: 契約満了日 | J3: 自動更新 | K3: 解約予告（か月） | L3: 通知期限（自動） | M3: 年間契約金額 | N3: 紐づく業務数（自動） | O3: 契約移管判定（自動）
A4: CT-2201 | B4: クラウド利用・運用委託契約 | C4: BUD-001 | D4: =IF(C4="","",IFERROR(INDEX('予算シート'!$B:$B,MATCH(C4,'予算シート'!$A:$A,0)),"案件が未登録")) | E4: A社 | F4: 準委任 | G4: 研究本部 | H4: 45748 | I4: 46477 | J4: 有 | K4: 3 | L4: =IF(OR(I4="",K4=""),"",EDATE(I4,-K4)) | M4: 15000000 | N4: =IF(A4="","",COUNTIF('業務'!$M$4:$M$200,A4)) | O4: =IF(A4="","",IF(N4=0,"対象外",IF(COUNTIFS('業務'!$M$4:$M$200,A4,'業務'!$P$4:$P$200,"移管")=N4,"移管",IF(COUNTIFS('業務'!$M$4:$M$200,A4,'業務'!$P$4:$P$200,"移管")>0,"一部",IF(COUNTIFS('業務'!$M$4:$M$200,A4,'業務'!$P$4:$P$200,"対象外")+COUNTIFS('業務'!$M$4:$M$200,A4,'業務'!$P$4:$P$200,"留保")=N4,IF(COUNTIFS('業務'!$M$4:$M$200,A4,'業務'!$P$4:$P$200,"留保")>0,"留保","対象外"),"判定保留")))))
