Workbook

Sheet バリューストリーム
A1: バリューストリーム（L1〜L4）
A2: 対象：日本の製薬会社（研究開発型。GxP規制下のコンピュータ化システムを持ち、IT機能は内製と外部委託を併用）／日本の規制・法令基準（GMP省令・ER/ES指針・コンピュータ化システム適正管理ガイドライン・個人情報保護法・金商法〔J-SOX〕・取適法ほか）。1行1項目。L1〜L4列の●がその行のレベル。L2はIT4IT（The Open Group）の4つのバリューストリーム（S2P・R2D・R2F・D2C）に対応する。出口はL2、入力・出力情報・関連法令・規制・主な関与者はL4の項目。 入力情報・出力情報はVS定義の過程で得られる正本（直接入力する）。情報オブジェクトはこれを取りまとめて一覧化したもの。★＝製薬のGxP規制、または日本のIT外部委託（請負・準委任、取適法）・IT全般統制（J-SOX）に固有の項目。
A3: ID | B3: L1 | C3: L2 | D3: L3 | E3: L4 | F3: VS項目名 | G3: VSの定義 | H3: 出口（ゲート） | I3: 入力情報 | J3: 出力情報 | K3: 関連法令・規制 | L3: 主な関与者（社内／外部）
A4: VS | B4: ● | F4: Manage IT / Digital Solutions | G4: 事業戦略をIT投資とポートフォリオに変換し、要件からデジタルソリューションを開発・配備して、利用者の申請に応じて提供し、運用の中で障害を検知・是正するまで。事業に必要なデジタル機能とシステム資産を、GxP・法令に適合した状態で供給し続ける
A5: 01 | C5: ● | F5: 戦略・ポートフォリオ（S2P） | G5: 事業戦略をIT戦略とアーキテクチャに落とし込み、事業部門の需要を評価して、投資する案件をポートフォリオとして決める段階 | H5: 投資の承認（ポートフォリオへの組入れ）
A6: 01-01 | D6: ● | F6: IT戦略・アーキテクチャの策定 | G6: 事業戦略・DX方針を受けて、IT戦略・ロードマップ、将来のアーキテクチャ、技術標準とIT規程を定める
A7: 01-01-01 | E7: ● | F7: 事業戦略・DX方針の把握とIT課題の整理 | I7: 事業戦略・DX方針、アプリケーション台帳 | J7: IT戦略・ロードマップ | K7: なし | L7: CIO・IT企画／経営企画
A8: 01-01-02 | E8: ● | F8: IT戦略・ロードマップの策定 | I8: 事業戦略・DX方針、ITポートフォリオ、ITリスク登録簿 | J8: IT戦略・ロードマップ | K8: なし | L8: CIO・IT企画／経営層
A9: 01-01-03 | E9: ● | F9: 現状・将来アーキテクチャの策定（業務・アプリケーション・データ・技術） | I9: IT戦略・ロードマップ、アプリケーション台帳、構成情報 | J9: エンタープライズアーキテクチャ、データ定義・データカタログ | K9: なし | L9: ITアーキテクト／—
A10: 01-01-04 | E10: ● | F10: 技術標準の策定（クラウド・セキュリティ・連携の標準） | I10: エンタープライズアーキテクチャ、ITリスク登録簿 | J10: 技術標準 | K10: なし | L10: ITアーキテクト・ITセキュリティ／—
A11: 01-01-05 | E11: ● | F11: ★IT規程・標準手順書の制定（CSV・IT全般統制・セキュリティ） | I11: 技術標準、ITリスク登録簿 | J11: IT規程・手順書 | K11: GxP・金商法 | L11: IT企画・品質保証（QA）・内部統制／—
A12: 01-02 | D12: ● | F12: 需要管理・構想 | G12: 事業部門の需要を受け付け、構想・概算見積・ソーシング方針とGxP該当性をまとめて投資要求にする
A13: 01-02-01 | E13: ● | F13: 事業部門の需要（IT投資要求）の受付 | I13: 事業戦略・DX方針 | J13: IT投資要求 | K13: なし | L13: 事業部門・ITビジネスパートナー／—
A14: 01-02-02 | E14: ● | F14: 構想・概算見積・ビジネスケースの作成 | I14: IT投資要求、エンタープライズアーキテクチャ、技術標準 | J14: ビジネスケース | K14: なし | L14: ITビジネスパートナー・事業部門／SIer（概算見積）
A15: 01-02-03 | E15: ● | F15: ★GxP該当性の初期判定（システム分類） | I15: IT投資要求、IT規程・手順書 | J15: GxP該当性評価 | K15: GxP | L15: システムオーナー・品質保証（QA）・IT／—
A16: 01-02-04 | E16: ● | F16: ★ソーシング方針の判断（内製・外部委託・SaaS） | I16: ビジネスケース、IT人材・スキル情報、ベンダー情報 | J16: ビジネスケース | K16: なし | L16: IT企画・調達／—
A17: 01-03 | D17: ● | F17: ポートフォリオ・投資判断 | G17: 案件を評価して優先順位を付け、予算を配分し、既存のシステムを含むポートフォリオを見直す
A18: 01-03-01 | E18: ● | F18: 投資案件の評価・優先順位付け | I18: ビジネスケース、ITポートフォリオ、ITリスク登録簿 | J18: ITポートフォリオ | K18: なし | L18: IT企画・経営層／—
A19: 01-03-02 | E19: ● | F19: IT予算の配分・承認 | I19: ITポートフォリオ、IT予算・費用実績 | J19: IT予算・費用実績 | K19: なし | L19: CIO・経理・経営層／—
A20: 01-03-03 | E20: ● | F20: ポートフォリオの見直し（継続・統合・廃止） | I20: アプリケーション台帳、サービスレベル実績、IT予算・費用実績 | J20: ITポートフォリオ、アプリケーション台帳 | K20: なし | L20: IT企画・システムオーナー／—
A21: 02 | C21: ● | F21: 要件定義・開発・配備（R2D） | G21: 承認された案件について、要件を定義し、設計・開発・テスト・バリデーションを行って本番環境に配備し、運用へ引き継ぐ段階 | H21: 本番稼働の承認（リリース判定）
A22: 02-01 | D22: ● | F22: プロジェクト立上げ・委託 | G22: 計画と体制を決め、委託先を選んで契約し、GxPのリスクに応じたバリデーションの計画を立てる
A23: 02-01-01 | E23: ● | F23: プロジェクト計画・体制の決定（内製と委託の役割分担） | I23: ビジネスケース、ITポートフォリオ、IT人材・スキル情報 | J23: プロジェクト計画 | K23: なし | L23: PM・システムオーナー／—
A24: 02-01-02 | E24: ● | F24: ★委託先の選定と契約（請負・準委任の区別、発注内容の明示） | I24: ビジネスケース、ベンダー情報、ベンダー評価記録 | J24: 委託契約・発注書 | K24: 取適法・派遣法 | L24: PM・調達・法務／SIer・ベンダー
A25: 02-01-03 | E25: ● | F25: ★リスクアセスメントとバリデーション計画（GxP・データインテグリティ） | I25: GxP該当性評価、プロジェクト計画 | J25: リスクアセスメント、バリデーション計画書 | K25: GxP | L25: PM・品質保証（QA）・システムオーナー／SIer
A26: 02-02 | D26: ● | F26: 要件定義・設計 | G26: 利用者の要求を仕様にまとめ、機能・構成を設計する。アクセス制御・監査証跡・電子署名などの要件を組み込む
A27: 02-02-01 | E27: ● | F27: ユーザー要求仕様（URS）の作成 | I27: ビジネスケース、リスクアセスメント | J27: 要求仕様書（URS） | K27: GxP | L27: システムオーナー・業務部門／—
A28: 02-02-02 | E28: ● | F28: 機能仕様・設計仕様の作成 | I28: 要求仕様書（URS）、技術標準、エンタープライズアーキテクチャ、データ定義・データカタログ | J28: 設計書（機能・設計仕様） | K28: GxP | L28: ITアーキテクト・PM／SIer
A29: 02-02-03 | E29: ● | F29: ★セキュリティ・データインテグリティ要件の設計（アクセス制御・監査証跡・電子署名・個人情報） | I29: 要求仕様書（URS）、リスクアセスメント、IT規程・手順書 | J29: 設計書（機能・設計仕様）、個人情報取扱台帳 | K29: GxP・個人情報保護法 | L29: ITセキュリティ・品質保証（QA）／SIer
A30: 02-03 | D30: ● | F30: 開発・構成・テスト | G30: アプリケーションを開発し、パッケージ・SaaSを設定してシステムを連携し、テストして委託先の成果物を検収する
A31: 02-03-01 | E31: ● | F31: アプリケーション開発・パッケージ／SaaSの設定 | I31: 設計書（機能・設計仕様）、技術標準 | J31: ソースコード・構成設定 | K31: なし | L31: 開発チーム／SIer
A32: 02-03-02 | E32: ● | F32: システム連携とデータ移行の準備 | I32: 設計書（機能・設計仕様）、データ定義・データカタログ | J32: ソースコード・構成設定、リリース・移行計画 | K32: なし | L32: 開発チーム・ITアーキテクト／SIer
A33: 02-03-03 | E33: ● | F33: テストの実施（単体・結合・システム） | I33: 設計書（機能・設計仕様）、ソースコード・構成設定 | J33: テスト記録 | K33: なし | L33: 開発チーム・PM／SIer
A34: 02-03-04 | E34: ● | F34: ★委託先の成果物の検収 | I34: 委託契約・発注書、テスト記録 | J34: 検収記録 | K34: 取適法 | L34: PM・調達／SIer
A35: 02-04 | D35: ● | F35: バリデーション・リリース | G35: 適格性を確認してデータを移行し、バリデーションの結果をもとにリリースを判定して、本番に配備し運用へ引き継ぐ
A36: 02-04-01 | E36: ● | F36: ★据付時・運用時の適格性確認（IQ・OQ） | I36: バリデーション計画書、設計書（機能・設計仕様）、テスト記録 | J36: テスト記録 | K36: GxP | L36: 品質保証（QA）・IT／SIer
A37: 02-04-02 | E37: ● | F37: ★ユーザー受入テスト・性能適格性確認（UAT・PQ） | I37: 要求仕様書（URS）、バリデーション計画書 | J37: テスト記録 | K37: GxP | L37: システムオーナー・業務部門・品質保証（QA）／—
A38: 02-04-03 | E38: ● | F38: データ移行と移行結果の検証 | I38: リリース・移行計画、データ定義・データカタログ | J38: テスト記録 | K38: GxP | L38: IT・業務部門／SIer
A39: 02-04-04 | E39: ● | F39: ★バリデーション報告とリリース判定 | I39: テスト記録、要求仕様書（URS）、バリデーション計画書 | J39: バリデーション報告書 | K39: GxP | L39: 品質保証（QA）・システムオーナー・PM／—
A40: 02-04-05 | E40: ● | F40: 本番配備と運用への引継ぎ（台帳・構成情報・カタログへの登録） | I40: バリデーション報告書、リリース・移行計画 | J40: 構成情報、アプリケーション台帳、ITサービスカタログ | K40: GxP | L40: IT運用・PM／SIer・運用委託先
...

Sheet ケイパビリティマップ
A1: ビジネス・ケイパビリティマップ（L1〜L3）
A2: 対象：日本の製薬会社（研究開発型。GxP規制下のコンピュータ化システムを持ち、IT機能は内製と外部委託を併用）／日本の規制・法令基準（GMP省令・ER/ES指針・コンピュータ化システム適正管理ガイドライン・個人情報保護法・金商法〔J-SOX〕・取適法ほか）。1行1項目。L1〜L3列の●がその行のレベル。区分はL1、範囲・アウトカムはL3の項目。★＝製薬のGxP規制、または日本のIT外部委託（請負・準委任、取適法）・IT全般統制（J-SOX）に固有、または特に強調する能力。
A3: ID | B3: L1 | C3: L2 | D3: L3 | E3: ケイパビリティ名 | F3: ケイパビリティの定義 | G3: 区分 | H3: 範囲（含む） | I3: 範囲（含まない） | J3: アウトカム
A4: C01 | B4: ● | E4: IT戦略・ガバナンス | F4: 事業戦略からIT戦略・アーキテクチャ・投資の方針を定め、規程・リスク・統制・予算でIT全体を統制する能力 | G4: 戦略
A5: C01-01 | C5: ● | E5: IT戦略・DX企画 | F5: 事業戦略を受けてIT戦略とロードマップを定め、デジタル技術による業務・事業の変革を企画する
A6: C01-01-01 | D6: ● | E6: IT戦略・ロードマップ策定 | F6: 事業戦略・DX方針から、ITの目標・重点施策・中長期の実行計画を定める | H6: IT戦略、ロードマップ、重点施策 | I6: 個別案件の評価（C01-03-02） | J6: 事業の方向とそろったIT投資
A7: C01-01-02 | D7: ● | E7: DX・デジタル企画 | F7: データ・AI・クラウドなどを使った業務・事業の変革を企画し、事業部門と構想を描く | H7: DXテーマの探索、構想、効果の仮説 | I7: 案件ごとの概算見積（C01-03-01） | J7: 事業部門と共有された変革の構想
A8: C01-02 | C8: ● | E8: エンタープライズアーキテクチャ | F8: 業務・アプリケーション・データ・技術の現状と将来像を描き、技術標準とアプリケーションの全体を管理する
A9: C01-02-01 | D9: ● | E9: アーキテクチャ設計（現状・将来像） | F9: 業務・アプリケーション・データ・技術の現状と将来像、移行の道筋を描く | H9: 現状・将来のアーキテクチャ、移行計画 | I9: 個別システムの設計（C02-02-02） | J9: 全体として整合したシステム構成
A10: C01-02-02 | D10: ● | E10: 技術標準・アーキテクチャレビュー | F10: 採用する技術・製品・連携方式の標準を定め、案件の設計が標準に沿うかを審査する | H10: 技術標準、設計レビュー、例外の承認 | I10: セキュリティの方針（C05-01-01） | J10: 重複や乱立のない技術基盤
A11: C01-02-03 | D11: ● | E11: アプリケーションポートフォリオ管理 | F11: すべてのアプリケーションを台帳で管理し、価値・技術・コストの面から継続・統合・廃止を評価する | H11: アプリケーション台帳、ライフサイクルの状態、評価 | I11: 投資案件の優先順位付け（C01-03-02） | J11: 把握され、整理されたアプリケーション群
A12: C01-03 | C12: ● | E12: ITポートフォリオ・需要管理 | F12: 事業部門の需要を受け付けて構想にまとめ、投資案件を評価・選択し、ポートフォリオ全体を監視する
A13: C01-03-01 | D13: ● | E13: 需要管理 | F13: 事業部門のIT需要を一つの窓口で受け付け、構想・概算見積・ビジネスケースにまとめる | H13: 需要の受付、構想、ビジネスケース | I13: 予算の承認（C01-05-01） | J13: 見える化され、比較できる需要
A14: C01-03-02 | D14: ● | E14: 投資評価・優先順位付け | F14: 共通の基準で投資案件を評価し、優先順位を付けて、実施する案件を決める | H14: 評価基準、優先順位、投資判断 | I14: 個別プロジェクトの進捗管理（C02-01-01） | J14: 価値の高い案件への資源の集中
A15: C01-03-03 | D15: ● | E15: ポートフォリオの監視・見直し | F15: 実行中の案件と既存システムの成果を監視し、継続・中止・統合を見直す | H15: 案件の監視、効果の検証、見直し | I15: アプリケーション台帳の維持（C01-02-03） | J15: 成果に応じて組み替えられるポートフォリオ
A16: C01-04 | C16: ● | E16: ITガバナンス・リスク管理★ | F16: IT規程と標準手順を定め、ITのリスクを管理し、IT全般統制を整備・評価する
A17: C01-04-01 | D17: ● | E17: IT規程・標準手順★ | F17: IT規程と、CSV・変更管理・アクセス管理などの標準手順書（SOP）を定め、改訂する | H17: IT規程、IT標準手順書、GxP関連のSOP | I17: 個別システムの運用手順書（C07-03-01） | J17: 規制と社内ルールに沿った一貫したIT業務
A18: C01-04-02 | D18: ● | E18: テクノロジーリスク管理 | F18: ITに関するリスク（老朽化・ベンダー依存・障害・サイバーなど）を洗い出し、評価して対策を管理する | H18: ITリスク登録簿、リスク評価、対策の管理 | I18: サイバーセキュリティの詳細なリスク評価（C05-01-01） | J18: 経営が把握し、管理されたITリスク
A19: C01-04-03 | D19: ● | E19: IT全般統制・監査対応★ | F19: 財務報告に関わるシステムのIT全般統制（開発・変更・運用・アクセス）を整備し、評価と監査に対応する | H19: IT全般統制、統制の評価、監査対応 | I19: GxPの定期レビュー（C06-01-03） | J19: 有効性を説明できるIT統制
A20: C01-05 | C20: ● | E20: IT財務管理 | F20: IT予算を立てて配分し、費用の実績を把握して部門に配賦する
A21: C01-05-01 | D21: ● | E21: IT予算管理 | F21: IT予算を立てて案件・サービスに配分し、実績と比較する | H21: IT予算、予実管理、概算見積の確認 | I21: 投資案件の評価（C01-03-02） | J21: 予算内に管理されたIT支出
A22: C01-05-02 | D22: ● | E22: IT費用の配賦・分析 | F22: ITの費用をサービス・部門に配賦し、総保有コストを分析する | H22: 費用の配賦、TCO分析 | I22: ライセンスの利用把握（C04-04-02） | J22: 説明できるITのコスト
A23: C02 | B23: ● | E23: ソリューション開発・導入 | F23: 承認された案件を、要件定義・設計・開発・テスト・リリースを通じて、内製と外部委託の組み合わせで実現する能力 | G23: コア
A24: C02-01 | C24: ● | E24: プロジェクト管理★ | F24: プロジェクトの計画・体制・進捗・品質を管理し、委託先の作業を監督する
A25: C02-01-01 | D25: ● | E25: プロジェクト計画・進捗管理 | F25: プロジェクトの計画・体制・スケジュールを立て、進捗・課題・リスクを管理する | H25: 計画、体制、進捗、課題・リスク | I25: ポートフォリオ全体の監視（C01-03-03） | J25: 計画どおりに完了するプロジェクト
A26: C02-01-02 | D26: ● | E26: 委託先の開発管理★ | F26: 委託先の作業範囲・進捗・品質を監督し、成果物を検収する。請負と準委任の違いに応じて指揮の範囲を守る | H26: 作業範囲の管理、進捗・品質の監督、成果物の検収 | I26: 委託先の選定・契約（C07-01-02） | J26: 丸投げにならず、中身を説明できる開発
A27: C02-02 | C27: ● | E27: 要件定義・設計 | F27: 利用者の要求を仕様にまとめ、機能・構成・連携を設計する
A28: C02-02-01 | D28: ● | E28: 要件定義 | F28: 業務の要求をユーザー要求仕様（URS）にまとめ、優先度と受入の基準を定める | H28: ユーザー要求仕様、非機能要件、受入の基準 | I28: 構想・概算見積（C01-03-01） | J28: 検証できる形でそろった要求
A29: C02-02-02 | D29: ● | E29: 設計（機能・設計仕様） | F29: 要求を満たす機能・データ・画面・構成を設計し、機能仕様書・設計仕様書にまとめる | H29: 機能仕様、設計仕様、データ設計 | I29: 全社のアーキテクチャ（C01-02-01） | J29: 要求を追跡できる設計
A30: C02-03 | C30: ● | E30: 開発・構成 | F30: アプリケーションを開発し、パッケージ・SaaSを設定して、システム間を連携する
A31: C02-03-01 | D31: ● | E31: アプリケーション開発 | F31: アプリケーションをコーディングし、ソースコードを版管理する | H31: コーディング、ソースコード管理、コードレビュー | I31: テスト（C02-04-01） | J31: 保守できる品質のソフトウェア
A32: C02-03-02 | D32: ● | E32: パッケージ・SaaSの設定 | F32: パッケージ・SaaSを標準機能中心に設定し、設定内容を記録する | H32: パラメータ設定、アドオンの抑制、設定の記録 | I32: SaaSの契約（C04-04-02） | J32: 標準に近く、更新しやすいシステム
A33: C02-03-03 | D33: ● | E33: システム連携 | F33: システム間のデータ連携・インターフェースを開発する | H33: API、ファイル連携、連携基盤 | I33: 連携方式の標準（C01-02-02） | J33: 正確で追跡できるデータ連携
A34: C02-04 | C34: ● | E34: テスト・リリース | F34: テストを計画・実施し、データを移行して、本番環境に配備する
A35: C02-04-01 | D35: ● | E35: テスト管理 | F35: テストを計画・実施し、不具合を記録して是正を確認する | H35: テスト計画、テスト記録、不具合管理 | I35: GxPの適格性確認（C06-01-02） | J35: 不具合が取り除かれたシステム
A36: C02-04-02 | D36: ● | E36: データ移行 | F36: 旧システムのデータを移行し、件数・内容の正しさを検証する | H36: 移行計画、移行、移行結果の検証 | I36: マスタの定義（C06-03-01） | J36: 欠落・改変のない移行データ
A37: C02-04-03 | D37: ● | E37: リリース・配備 | F37: リリースを計画して本番環境に配備し、運用へ引き継ぐ | H37: リリース計画、配備、運用への引継ぎ | I37: 変更の承認（C03-05-01） | J37: 安全に本番へ移行されたシステム
A38: C03 | B38: ● | E38: ITサービス管理・運用 | F38: ITサービスを定義して提供し、日々の運用・監視と、インシデント・問題・変更の管理で、合意したサービスレベルを保つ能力 | G38: コア
A39: C03-01 | C39: ● | E39: サービスカタログ・サービスレベル管理 | F39: ITサービスを定義してカタログに載せ、サービスレベルを合意し、実績を報告する
A40: C03-01-01 | D40: ● | E40: サービスカタログ管理 | F40: 提供するITサービスの内容・条件・申請方法を定め、カタログとして公開する | H40: サービスの定義、カタログの公開・改訂 | I40: 申請の処理（C03-02-02） | J40: 利用者が選んで申請できるサービス
...

Sheet ケイパビリティレベル
A1: ケイパビリティの成熟度レベル（L2ごとの定義）
A2: 対象：日本の製薬会社（研究開発型。GxP規制下のコンピュータ化システムを持ち、IT機能は内製と外部委託を併用）／日本の規制・法令基準（GMP省令・ER/ES指針・コンピュータ化システム適正管理ガイドライン・個人情報保護法・金商法〔J-SOX〕・取適法ほか）。評価の対象はL2。規制上の最低水準：GxP・法令（GMP省令・ER/ES指針・金商法〔J-SOX〕・個人情報保護法・取適法など）が関わるL2はレベル3が事実上の最低水準。
A3: レベル | B3: 名称 | C3: 共通定義
A4: 1 | B4: 初期 | C4: 属人的・場当たり的。成果が個人に依存し、再現できない
A5: 2 | B5: 管理された | C5: 案件・システムごとに計画・管理され、再現できる。ただし方法は案件・部門・委託先で異なる
A6: 3 | B6: 定義された | C6: 全社標準のプロセス・役割・データ定義があり、一貫して運用される
A7: 4 | B7: 定量的に管理された | C7: 指標で成果・品質を測定し、データに基づいて管理・予測する
A8: 5 | B8: 最適化された | C8: 継続的な改善と先進的な手法により、変化に先回りし、先進的な水準にある
A10: L2 ID | B10: ケイパビリティL1 | C10: ケイパビリティL2 | D10: 規制上の最低水準 | E10: レベル1 初期 | F10: レベル2 管理された | G10: レベル3 定義された | H10: レベル4 定量的に管理された | I10: レベル5 最適化された
A11: C01-01 | B11: IT戦略・ガバナンス | C11: IT戦略・DX企画 | D11: — | E11: ITの計画が年度予算の積み上げで、事業戦略との関係が説明できない | F11: 重点システムについて中期の計画を立てる | G11: 事業戦略とそろえたIT戦略・ロードマップを全社共通の方法で策定し、毎年見直す | H11: IT施策の事業への効果を指標で測定し、戦略に反映する | I11: 事業部門と一体でデジタルによる事業の変革を先導する
A12: C01-02 | C12: エンタープライズアーキテクチャ | D12: — | E12: システムの全体像を誰も把握していない | F12: 主要システムの構成図と一覧を部門ごとに持つ | G12: 全社のアプリケーション台帳・技術標準・将来像を持ち、案件を標準に照らして審査する | H12: 重複・老朽化・標準からの逸脱を指標で監視する | I12: アーキテクチャが事業の変化に先回りして組み替えられる
A13: C01-03 | C13: ITポートフォリオ・需要管理 | D13: — | E13: 声の大きい部門の要求から着手する | F13: 案件ごとに稟議で投資を判断する | G13: 全社共通の受付窓口と評価基準で、案件を比較して優先順位を決める | H13: 投資の効果を事後に検証し、評価基準を改善する | I13: ポートフォリオ全体の価値とリスクを最適化し続ける
A14: C01-04 | C14: ITガバナンス・リスク管理★ | D14: レベル3（GMP省令・コンピュータ化システム適正管理ガイドライン・金商法） | E14: IT規程がなく、担当者の判断で作業する | F14: IT規程はあるが、手順書の整備と運用が部門・委託先ごとに異なる | G14: IT規程・標準手順書・IT全般統制を全社標準で整備し、一貫して運用する | H14: 統制の不備・逸脱・リスクを指標で監視し、早期に是正する | I14: リスクの変化に先回りして、統制と手順を見直す
A15: C01-05 | C15: IT財務管理 | D15: — | E15: IT費用の全体を把握していない | F15: IT部門の予算と実績を年度で管理する | G15: 案件・サービス別に予算と実績を管理し、部門へ配賦する | H15: 総保有コストと単価を指標で管理し、比較する | I15: 費用とサービスの価値を結び付けて投資配分を最適化する
A16: C02-01 | B16: ソリューション開発・導入 | C16: プロジェクト管理★ | D16: — | E16: 計画がなく、委託先に任せきりで進捗が分からない | F16: 案件ごとに計画を立て、委託先から報告を受ける | G16: 全社標準のプロジェクト管理と委託先の監督の方法で、請負・準委任の区別を守って管理する | H16: 品質・進捗・コストの実績を指標で管理し、予測する | I16: 内製と委託を組み合わせ、変化に強い進め方を選べる
A17: C02-02 | C17: 要件定義・設計 | D17: レベル3（GMP省令・コンピュータ化システム適正管理ガイドライン） | E17: 要件が口頭や会議のメモだけで決まる | F17: 案件ごとに要件定義書を作るが、形式と粒度がばらばら | G17: 全社標準のURS・設計書の様式で、要求から設計まで追跡できる | H17: 要件の変更・漏れを指標で管理する | I17: 利用者と短い周期で要求を確かめながら設計する
A18: C02-03 | C18: 開発・構成 | D18: — | E18: 個人の書き方で開発し、ソースや設定の所在が分からない | F18: 案件ごとにソースと設定を管理する | G18: 全社標準のリポジトリ・コーディング規約・設定の記録で、版を管理する | H18: 品質指標（不具合密度・レビューの指摘）で管理する | I18: 自動化されたパイプラインで、速く安全に変更できる
A19: C02-04 | C19: テスト・リリース | D19: レベル3（GMP省令・コンピュータ化システム適正管理ガイドライン） | E19: テストが担当者任せで、記録が残らない | F19: 案件ごとにテストを計画し、結果を記録する | G19: 全社標準のテスト・移行・リリースの手順で、判定基準を満たしてから本番に出す | H19: 不具合の流出・リリース後の障害を指標で管理する | I19: テストと配備が自動化され、小さく頻繁にリリースできる
A20: C03-01 | B20: ITサービス管理・運用 | C20: サービスカタログ・サービスレベル管理 | D20: — | E20: 提供するサービスの範囲と水準が決まっていない | F20: 主要なシステムについて運用時間・連絡先を決める | G20: 全社のサービスカタログとSLAを持ち、実績を定期的に報告する | H20: SLAの実績を指標で管理し、改善につなげる | I20: 利用者の体験を測り、サービスを先回りして改善する
A21: C03-02 | C21: サービスデスク・要求実現 | D21: — | E21: 問合せ先がシステムごとに異なり、記録が残らない | F21: 主要な窓口を決めて問合せを記録する | G21: 全社で一つの窓口とカタログからの申請で、受付から完了まで記録する | H21: 解決までの時間・一次解決率を指標で管理する | I21: セルフサービスと自動化で、待たずに解決する
A22: C03-03 | C22: IT運用・監視 | D22: レベル3（GMP省令〔バックアップ〕・金商法） | E22: 障害が利用者からの連絡で分かる | F22: 主要なシステムを監視し、バックアップを取る | G22: 全社標準の監視・ジョブ・バックアップと復元テストの手順で運用する | H22: 稼働率・容量の傾向を指標で管理し、予測する | I22: 異常を予兆で検知し、自動で回復する
A23: C03-04 | C23: インシデント・問題管理 | D23: レベル3（GMP省令） | E23: 障害のたびに担当者が個別に対応し、記録が残らない | F23: インシデントを記録し、重大な障害は報告する | G23: 全社標準のインシデント・問題管理とIT事業継続計画で対応し、GxPへの影響を評価する | H23: 復旧時間・再発件数を指標で管理する | I23: 傾向の分析で障害を未然に防ぐ
A24: C03-05 | C24: 変更・構成管理★ | D24: レベル3（GMP省令・コンピュータ化システム適正管理ガイドライン・金商法） | E24: 本番環境を担当者が承認なしに変更する | F24: 変更を申請・承認するが、影響評価と構成情報が不十分 | G24: 全社標準の変更管理で、GxP・統制への影響を評価して承認し、構成情報を最新に保つ | H24: 変更による障害・緊急変更の割合を指標で管理する | I24: 自動化された検証で、安全な変更を速く行う
A25: C04-01 | B25: ITプラットフォーム | C25: クラウド・データセンター | D25: — | E25: サーバーやクラウドを部門が個別に用意する | F25: IT部門が基盤を用意するが、構成が案件ごとに異なる | G25: 全社標準の構成で、クラウドとサーバーを提供・運用する | H25: 利用率・費用・保守期限を指標で管理する | I25: 需要に応じて自動で拡張・最適化される
A26: C04-02 | C26: ネットワーク | D26: — | E26: 拠点ごとにネットワークを構築し、全体の構成が分からない | F26: 主要な拠点のネットワークを管理する | G26: 全社標準の構成で拠点と外部の接続を管理する | H26: 通信の品質・障害を指標で管理する | I26: 場所に依存しない安全な接続（ゼロトラスト）を実現する
A27: C04-03 | C27: エンドユーザー環境 | D27: — | E27: 端末を利用者が個別に設定する | F27: 端末の設定と配布を手順化する | G27: 全社標準の構成と管理ツールで、端末とコラボレーション環境を提供する | H27: 更新の適用率・問合せ件数を指標で管理する | I27: 利用者が自分で準備でき、どこでも同じ環境で働ける
A28: C04-04 | C28: IT資産・ライセンス管理 | D28: — | E28: 資産とライセンスの台帳がない | F28: 資産台帳を持つが、所在・利用者が最新でない | G28: 全社の台帳で資産とライセンス・SaaSを管理し、定期的に棚卸しする | H28: 利用率・過不足・保守期限を指標で管理する | I28: 利用データに応じてライセンスを自動で最適化する
A29: C05-01 | B29: サイバーセキュリティ | C29: セキュリティガバナンス | D29: レベル3（個人情報保護法〔安全管理措置〕） | E29: セキュリティの方針がない | F29: 方針はあるが、リスク評価と教育が年1回の形式にとどまる | G29: 全社標準の方針・リスク評価・教育で、委託先を含めて管理する | H29: リスクと訓練の結果を指標で管理する | I29: 脅威の変化に先回りして対策を組み替える
A30: C05-02 | C30: ID・アクセス管理★ | D30: レベル3（GMP省令・ER/ES指針・金商法） | E30: IDを共有し、退職者のIDが残る | F30: システムごとに申請書で権限を付与する | G30: 人事と連携したID管理と、職務分掌に沿った権限付与・定期棚卸を全社標準で行う | H30: 不要な権限・棚卸の指摘を指標で管理する | I30: 権限の付与と見直しを自動化し、常に最小の権限に保つ
A31: C05-03 | C31: セキュリティ運用 | D31: レベル3（個人情報保護法〔漏えい等の報告〕） | E31: 攻撃や脆弱性に気づかない | F31: 主要な機器のパッチを当て、ウイルス対策を行う | G31: 全社標準の脆弱性管理・監視・CSIRTの手順で対応する | H31: 検知・対応の時間と未対応の脆弱性を指標で管理する | I31: 脅威情報を使って攻撃を先回りして防ぐ
A32: C06-01 | B32: データ・GxPコンプライアンス | C32: GxPシステム管理（CSV）★ | D32: レベル3（GMP省令・コンピュータ化システム適正管理ガイドライン） | E32: GxPに該当するシステムを把握していない | F32: 案件ごとにバリデーション文書を作るが、方法と量がばらばら | G32: 全社標準のGxP該当性評価と、リスクに応じたバリデーション・定期レビューを行う | H32: バリデーションの工数・指摘・逸脱を指標で管理する | I32: 重要な機能に集中した合理的な保証（CSA）で、速く確実に使い始められる
A33: C06-02 | C33: データインテグリティ★ | D33: レベル3（GMP省令・ER/ES指針） | E33: 紙と電子の記録が混在し、元の記録が分からない | F33: システムごとに監査証跡と保存を設定する | G33: 全社標準のデータインテグリティの方針で、監査証跡・電子署名・保存・アーカイブを管理する | H33: データインテグリティの指摘・監査証跡の確認結果を指標で管理する | I33: データのライフサイクル全体でリスクを先回りして管理する
A34: C06-03 | C34: データ管理 | D34: — | E34: マスタとデータの定義がシステムごとに異なる | F34: 主要なマスタを部門ごとに管理する | G34: 全社標準のマスタの正本・データカタログ・品質の基準で管理する | H34: データの品質を指標で管理し、改善する | I34: データを全社の資産として活用し、新しい価値を生む
A35: C06-04 | C35: 個人情報・データ保護 | D35: レベル3（個人情報保護法） | E35: どのシステムで個人情報を扱うか分からない | F35: 主要なシステムについて個人情報の取扱いを確認する | G35: 全社の取扱台帳と情報の分類で管理し、漏えい等の報告の手順を持つ | H35: 持出し・誤送信などの件数を指標で管理する | I35: プライバシーを設計段階から組み込む（プライバシー・バイ・デザイン）
A36: C07-01 | B36: IT組織・ソーシング基盤 | C36: ITソーシング・ベンダー管理★ | D36: レベル3（取適法・派遣法・GMP省令〔供給者管理〕） | E36: 特定のベンダーに任せきりで、比較も評価もしない | F36: 案件ごとに見積を比較し、契約書を結ぶ | G36: 全社標準のソーシング方針・選定・契約・評価の手順で、請負・準委任の区別と取適法を守る | H36: 委託先の品質・SLA・コストを指標で比較・管理する | I36: 戦略的なパートナーと、内製の力を保ちながら共同で改善する
A37: C07-02 | C37: IT人材・組織★ | D37: レベル3（GMP省令〔教育訓練〕） | E37: ITの役割とスキルが定義されておらず、ベンダー頼み | F37: 主要な役割について担当者を育成する | G37: 全社標準の役割定義・スキル評価・教育記録で、内製すべき力を計画的に育てる | H37: スキルの充足・育成の効果を指標で管理する | I37: 必要な人材を先回りして育成・採用し、内製の力で変化に対応する
A38: C07-03 | C38: ITナレッジ・文書管理 | D38: — | E38: 手順書が個人のPCにあり、最新版が分からない | F38: システムごとに手順書を管理する | G38: 全社標準の文書管理とナレッジの仕組みで、承認・版・共有を管理する | H38: ナレッジの利用率・更新の状況を指標で管理する | I38: ナレッジが自動で集まり、誰でも使える

Sheet VS×ケイパビリティ関係
A1: VS×ケイパビリティ関係（正本：VS L4 × ケイパビリティL3）
A2: 1行1関係。区分は「主」（そのL4の中核）か「支援」（下支え）。マトリクスはこのシートから数式で集計する。関係の追加・変更はこのシートで行う。灰色の列は数式（編集しない）。
A3: VS L4 ID | B3: VS L4 | C3: ケイパビリティL3 ID | D3: ケイパビリティL3 | E3: 区分 | F3: VS L3 ID | G3: ケイパビリティL2 ID
A4: 01-01-01 | B4: 事業戦略・DX方針の把握とIT課題の整理 | C4: C01-01-01 | D4: =IFERROR(INDEX(ケイパビリティマップ!$E:$E,MATCH(C4,ケイパビリティマップ!$A:$A,0)),"（IDなし）") | E4: 主 | F4: =LEFT(A4,5) | G4: =LEFT(C4,6)
A5: 01-01-01 | B5: 事業戦略・DX方針の把握とIT課題の整理 | C5: C01-01-02 | D5: =IFERROR(INDEX(ケイパビリティマップ!$E:$E,MATCH(C5,ケイパビリティマップ!$A:$A,0)),"（IDなし）") | E5: 支援 | F5: =LEFT(A5,5) | G5: =LEFT(C5,6)
A6: 01-01-01 | B6: 事業戦略・DX方針の把握とIT課題の整理 | C6: C01-02-03 | D6: =IFERROR(INDEX(ケイパビリティマップ!$E:$E,MATCH(C6,ケイパビリティマップ!$A:$A,0)),"（IDなし）") | E6: 支援 | F6: =LEFT(A6,5) | G6: =LEFT(C6,6)
A7: 01-01-02 | B7: IT戦略・ロードマップの策定 | C7: C01-01-01 | D7: =IFERROR(INDEX(ケイパビリティマップ!$E:$E,MATCH(C7,ケイパビリティマップ!$A:$A,0)),"（IDなし）") | E7: 主 | F7: =LEFT(A7,5) | G7: =LEFT(C7,6)
A8: 01-01-02 | B8: IT戦略・ロードマップの策定 | C8: C01-01-02 | D8: =IFERROR(INDEX(ケイパビリティマップ!$E:$E,MATCH(C8,ケイパビリティマップ!$A:$A,0)),"（IDなし）") | E8: 主 | F8: =LEFT(A8,5) | G8: =LEFT(C8,6)
A9: 01-01-02 | B9: IT戦略・ロードマップの策定 | C9: C07-01-01 | D9: =IFERROR(INDEX(ケイパビリティマップ!$E:$E,MATCH(C9,ケイパビリティマップ!$A:$A,0)),"（IDなし）") | E9: 支援 | F9: =LEFT(A9,5) | G9: =LEFT(C9,6)
A10: 01-01-03 | B10: 現状・将来アーキテクチャの策定（業務・アプリケーション・データ・技術） | C10: C01-02-01 | D10: =IFERROR(INDEX(ケイパビリティマップ!$E:$E,MATCH(C10,ケイパビリティマップ!$A:$A,0)),"（IDなし）") | E10: 主 | F10: =LEFT(A10,5) | G10: =LEFT(C10,6)
A11: 01-01-03 | B11: 現状・将来アーキテクチャの策定（業務・アプリケーション・データ・技術） | C11: C01-02-03 | D11: =IFERROR(INDEX(ケイパビリティマップ!$E:$E,MATCH(C11,ケイパビリティマップ!$A:$A,0)),"（IDなし）") | E11: 支援 | F11: =LEFT(A11,5) | G11: =LEFT(C11,6)
A12: 01-01-03 | B12: 現状・将来アーキテクチャの策定（業務・アプリケーション・データ・技術） | C12: C06-03-02 | D12: =IFERROR(INDEX(ケイパビリティマップ!$E:$E,MATCH(C12,ケイパビリティマップ!$A:$A,0)),"（IDなし）") | E12: 支援 | F12: =LEFT(A12,5) | G12: =LEFT(C12,6)
A13: 01-01-04 | B13: 技術標準の策定（クラウド・セキュリティ・連携の標準） | C13: C01-02-02 | D13: =IFERROR(INDEX(ケイパビリティマップ!$E:$E,MATCH(C13,ケイパビリティマップ!$A:$A,0)),"（IDなし）") | E13: 主 | F13: =LEFT(A13,5) | G13: =LEFT(C13,6)
A14: 01-01-04 | B14: 技術標準の策定（クラウド・セキュリティ・連携の標準） | C14: C05-01-01 | D14: =IFERROR(INDEX(ケイパビリティマップ!$E:$E,MATCH(C14,ケイパビリティマップ!$A:$A,0)),"（IDなし）") | E14: 支援 | F14: =LEFT(A14,5) | G14: =LEFT(C14,6)
A15: 01-01-05 | B15: ★IT規程・標準手順書の制定（CSV・IT全般統制・セキュリティ） | C15: C01-04-01 | D15: =IFERROR(INDEX(ケイパビリティマップ!$E:$E,MATCH(C15,ケイパビリティマップ!$A:$A,0)),"（IDなし）") | E15: 主 | F15: =LEFT(A15,5) | G15: =LEFT(C15,6)
... A141: 04-04-06 | B141: 改善の提案（次の投資要求へ） | C141: C01-04-02 | D141: =IFERROR(INDEX(ケイパビリティマップ!$E:$E,MATCH(C141,ケイパビリティマップ!$A:$A,0)),"（IDなし）") | E141: 支援 | F141: =LEFT(A141,5) | G141: =LEFT(C141,6)
D142: =IF(C142="","",IFERROR(INDEX(ケイパビリティマップ!$E:$E,MATCH(C142,ケイパビリティマップ!$A:$A,0)),"（IDなし）")) | F142: =IF(A142="","",LEFT(A142,5)) | G142: =IF(C142="","",LEFT(C142,6))
D143: =IF(C143="","",IFERROR(INDEX(ケイパビリティマップ!$E:$E,MATCH(C143,ケイパビリティマップ!$A:$A,0)),"（IDなし）")) | F143: =IF(A143="","",LEFT(A143,5)) | G143: =IF(C143="","",LEFT(C143,6))
D144: =IF(C144="","",IFERROR(INDEX(ケイパビリティマップ!$E:$E,MATCH(C144,ケイパビリティマップ!$A:$A,0)),"（IDなし）")) | F144: =IF(A144="","",LEFT(A144,5)) | G144: =IF(C144="","",LEFT(C144,6))
D145: =IF(C145="","",IFERROR(INDEX(ケイパビリティマップ!$E:$E,MATCH(C145,ケイパビリティマップ!$A:$A,0)),"（IDなし）")) | F145: =IF(A145="","",LEFT(A145,5)) | G145: =IF(C145="","",LEFT(C145,6))
D146: =IF(C146="","",IFERROR(INDEX(ケイパビリティマップ!$E:$E,MATCH(C146,ケイパビリティマップ!$A:$A,0)),"（IDなし）")) | F146: =IF(A146="","",LEFT(A146,5)) | G146: =IF(C146="","",LEFT(C146,6))
D147: =IF(C147="","",IFERROR(INDEX(ケイパビリティマップ!$E:$E,MATCH(C147,ケイパビリティマップ!$A:$A,0)),"（IDなし）")) | F147: =IF(A147="","",LEFT(A147,5)) | G147: =IF(C147="","",LEFT(C147,6))
D148: =IF(C148="","",IFERROR(INDEX(ケイパビリティマップ!$E:$E,MATCH(C148,ケイパビリティマップ!$A:$A,0)),"（IDなし）")) | F148: =IF(A148="","",LEFT(A148,5)) | G148: =IF(C148="","",LEFT(C148,6))
D149: =IF(C149="","",IFERROR(INDEX(ケイパビリティマップ!$E:$E,MATCH(C149,ケイパビリティマップ!$A:$A,0)),"（IDなし）")) | F149: =IF(A149="","",LEFT(A149,5)) | G149: =IF(C149="","",LEFT(C149,6))
D150: =IF(C150="","",IFERROR(INDEX(ケイパビリティマップ!$E:$E,MATCH(C150,ケイパビリティマップ!$A:$A,0)),"（IDなし）")) | F150: =IF(A150="","",LEFT(A150,5)) | G150: =IF(C150="","",LEFT(C150,6))
D151: =IF(C151="","",IFERROR(INDEX(ケイパビリティマップ!$E:$E,MATCH(C151,ケイパビリティマップ!$A:$A,0)),"（IDなし）")) | F151: =IF(A151="","",LEFT(A151,5)) | G151: =IF(C151="","",LEFT(C151,6))
D152: =IF(C152="","",IFERROR(INDEX(ケイパビリティマップ!$E:$E,MATCH(C152,ケイパビリティマップ!$A:$A,0)),"（IDなし）")) | F152: =IF(A152="","",LEFT(A152,5)) | G152: =IF(C152="","",LEFT(C152,6))
D153: =IF(C153="","",IFERROR(INDEX(ケイパビリティマップ!$E:$E,MATCH(C153,ケイパビリティマップ!$A:$A,0)),"（IDなし）")) | F153: =IF(A153="","",LEFT(A153,5)) | G153: =IF(C153="","",LEFT(C153,6))
... D341: =IF(C341="","",IFERROR(INDEX(ケイパビリティマップ!$E:$E,MATCH(C341,ケイパビリティマップ!$A:$A,0)),"（IDなし）")) | F341: =IF(A341="","",LEFT(A341,5)) | G341: =IF(C341="","",LEFT(C341,6))

Sheet VS×ケイパビリティ
A1: バリューストリーム×ケイパビリティマップ（行：バリューストリームL3 × 列：ケイパビリティL2）
A2: ●＝主（配下のL4×L3の関係に「主」が1つ以上） ○＝支援のみ 空欄＝関係なし。各セルは「VS×ケイパビリティ関係」シートから数式で集計（直接入力しない）。
A4: VS L2 | B4: L3 ID | C4: VS L3 | D4: C01 IT戦略・ガバナンス | I4: C02 ソリューション開発・導入 | M4: C03 ITサービス管理・運用 | R4: C04 ITプラットフォーム | V4: C05 サイバーセキュリティ | Y4: C06 データ・GxPコンプライアンス | AC4: C07 IT組織・ソーシング基盤 | AF4: ●の数 | AG4: ○の数
D5: C01-01 | E5: C01-02 | F5: C01-03 | G5: C01-04 | H5: C01-05 | I5: C02-01 | J5: C02-02 | K5: C02-03 | L5: C02-04 | M5: C03-01 | N5: C03-02 | O5: C03-03 | P5: C03-04 | Q5: C03-05 | R5: C04-01 | S5: C04-02 | T5: C04-03 | U5: C04-04 | V5: C05-01 | W5: C05-02 | X5: C05-03 | Y5: C06-01 | Z5: C06-02 | AA5: C06-03 | AB5: C06-04 | AC5: C07-01 | AD5: C07-02 | AE5: C07-03
D6: IT戦略・DX企画 | E6: エンタープライズアーキテクチャ | F6: ITポートフォリオ・需要管理 | G6: ITガバナンス・リスク管理★ | H6: IT財務管理 | I6: プロジェクト管理★ | J6: 要件定義・設計 | K6: 開発・構成 | L6: テスト・リリース | M6: サービスカタログ・サービスレベル管理 | N6: サービスデスク・要求実現 | O6: IT運用・監視 | P6: インシデント・問題管理 | Q6: 変更・構成管理★ | R6: クラウド・データセンター | S6: ネットワーク | T6: エンドユーザー環境 | U6: IT資産・ライセンス管理 | V6: セキュリティガバナンス | W6: ID・アクセス管理★ | X6: セキュリティ運用 | Y6: GxPシステム管理（CSV）★ | Z6: データインテグリティ★ | AA6: データ管理 | AB6: 個人情報・データ保護 | AC6: ITソーシング・ベンダー管理★ | AD6: IT人材・組織★ | AE6: ITナレッジ・文書管理
A7: 01 戦略・ポートフォリオ（S2P） | B7: 01-01 | C7: IT戦略・アーキテクチャの策定 | D7: =IF(COUNTIFS('VS×ケイパビリティ関係'!$F$4:$F$341,$B7,'VS×ケイパビリティ関係'!$G$4:$G$341,D$5,'VS×ケイパビリティ関係'!$E$4:$E$341,"主")>0,"●",IF(COUNTIFS('VS×ケイパビリティ関係'!$F$4:$F$341,$B7,'VS×ケイパビリティ関係'!$G$4:$G$341,D$5,'VS×ケイパビリティ関係'!$E$4:$E$341,"支援")>0,"○","")) | E7: =IF(COUNTIFS('VS×ケイパビリティ関係'!$F$4:$F$341,$B7,'VS×ケイパビリティ関係'!$G$4:$G$341,E$5,'VS×ケイパビリティ関係'!$E$4:$E$341,"主")>0,"●",IF(COUNTIFS('VS×ケイパビリティ関係'!$F$4:$F$341,$B7,'VS×ケイパビリティ関係'!$G$4:$G$341,E$5,'VS×ケイパビリティ関係'!$E$4:$E$341,"支援")>0,"○","")) | F7: =IF(COUNTIFS('VS×ケイパビリティ関係'!$F$4:$F$341,$B7,'VS×ケイパビリティ関係'!$G$4:$G$341,F$5,'VS×ケイパビリティ関係'!$E$4:$E$341,"主")>0,"●",IF(COUNTIFS('VS×ケイパビリティ関係'!$F$4:$F$341,$B7,'VS×ケイパビリティ関係'!$G$4:$G$341,F$5,'VS×ケイパビリティ関係'!$E$4:$E$341,"支援")>0,"○","")) | G7: =IF(COUNTIFS('VS×ケイパビリティ関係'!$F$4:$F$341,$B7,'VS×ケイパビリティ関係'!$G$4:$G$341,G$5,'VS×ケイパビリティ関係'!$E$4:$E$341,"主")>0,"●",IF(COUNTIFS('VS×ケイパビリティ関係'!$F$4:$F$341,$B7,'VS×ケイパビリティ関係'!$G$4:$G$341,G$5,'VS×ケイパビリティ関係'!$E$4:$E$341,"支援")>0,"○","")) | H7: =IF(COUNTIFS('VS×ケイパビリティ関係'!$F$4:$F$341,$B7,'VS×ケイパビリティ関係'!$G$4:$G$341,H$5,'VS×ケイパビリティ関係'!$E$4:$E$341,"主")>0,"●",IF(COUNTIFS('VS×ケイパビリティ関係'!$F$4:$F$341,$B7,'VS×ケイパビリティ関係'!$G$4:$G$341,H$5,'VS×ケイパビリティ関係'!$E$4:$E$341,"支援")>0,"○","")) | I7: =IF(COUNTIFS('VS×ケイパビリティ関係'!$F$4:$F$341,$B7,'VS×ケイパビリティ関係'!$G$4:$G$341,I$5,'VS×ケイパビリティ関係'!$E$4:$E$341,"主")>0,"●",IF(COUNTIFS('VS×ケイパビリティ関係'!$F$4:$F$341,$B7,'VS×ケイパビリティ関係'!$G$4:$G$341,I$5,'VS×ケイパビリティ関係'!$E$4:$E$341,"支援")>0,"○","")) | J7: =IF(COUNTIFS('VS×ケイパビリティ関係'!$F$4:$F$341,$B7,'VS×ケイパビリティ関係'!$G$4:$G$341,J$5,'VS×ケイパビリティ関係'!$E$4:$E$341,"主")>0,"●",IF(COUNTIFS('VS×ケイパビリティ関係'!$F$4:$F$341,$B7,'VS×ケイパビリティ関係'!$G$4:$G$341,J$5,'VS×ケイパビリティ関係'!$E$4:$E$341,"支援")>0,"○","")) | K7: =IF(COUNTIFS('VS×ケイパビリティ関係'!$F$4:$F$341,$B7,'VS×ケイパビリティ関係'!$G$4:$G$341,K$5,'VS×ケイパビリティ関係'!$E$4:$E$341,"主")>0,"●",IF(COUNTIFS('VS×ケイパビリティ関係'!$F$4:$F$341,$B7,'VS×ケイパビリティ関係'!$G$4:$G$341,K$5,'VS×ケイパビリティ関係'!$E$4:$E$341,"支援")>0,"○","")) | ... AE7: =IF(COUNTIFS('VS×ケイパビリティ関係'!$F$4:$F$341,$B7,'VS×ケイパビリティ関係'!$G$4:$G$341,AE$5,'VS×ケイパビリティ関係'!$E$4:$E$341,"主")>0,"●",IF(COUNTIFS('VS×ケイパビリティ関係'!$F$4:$F$341,$B7,'VS×ケイパビリティ関係'!$G$4:$G$341,AE$5,'VS×ケイパビリティ関係'!$E$4:$E$341,"支援")>0,"○","")) | AF7: =COUNTIF(D7:AE7,"●") | AG7: =COUNTIF(D7:AE7,"○")
B8: 01-02 | C8: 需要管理・構想 | D8: =IF(COUNTIFS('VS×ケイパビリティ関係'!$F$4:$F$341,$B8,'VS×ケイパビリティ関係'!$G$4:$G$341,D$5,'VS×ケイパビリティ関係'!$E$4:$E$341,"主")>0,"●",IF(COUNTIFS('VS×ケイパビリティ関係'!$F$4:$F$341,$B8,'VS×ケイパビリティ関係'!$G$4:$G$341,D$5,'VS×ケイパビリティ関係'!$E$4:$E$341,"支援")>0,"○","")) | E8: =IF(COUNTIFS('VS×ケイパビリティ関係'!$F$4:$F$341,$B8,'VS×ケイパビリティ関係'!$G$4:$G$341,E$5,'VS×ケイパビリティ関係'!$E$4:$E$341,"主")>0,"●",IF(COUNTIFS('VS×ケイパビリティ関係'!$F$4:$F$341,$B8,'VS×ケイパビリティ関係'!$G$4:$G$341,E$5,'VS×ケイパビリティ関係'!$E$4:$E$341,"支援")>0,"○","")) | F8: =IF(COUNTIFS('VS×ケイパビリティ関係'!$F$4:$F$341,$B8,'VS×ケイパビリティ関係'!$G$4:$G$341,F$5,'VS×ケイパビリティ関係'!$E$4:$E$341,"主")>0,"●",IF(COUNTIFS('VS×ケイパビリティ関係'!$F$4:$F$341,$B8,'VS×ケイパビリティ関係'!$G$4:$G$341,F$5,'VS×ケイパビリティ関係'!$E$4:$E$341,"支援")>0,"○","")) | G8: =IF(COUNTIFS('VS×ケイパビリティ関係'!$F$4:$F$341,$B8,'VS×ケイパビリティ関係'!$G$4:$G$341,G$5,'VS×ケイパビリティ関係'!$E$4:$E$341,"主")>0,"●",IF(COUNTIFS('VS×ケイパビリティ関係'!$F$4:$F$341,$B8,'VS×ケイパビリティ関係'!$G$4:$G$341,G$5,'VS×ケイパビリティ関係'!$E$4:$E$341,"支援")>0,"○","")) | H8: =IF(COUNTIFS('VS×ケイパビリティ関係'!$F$4:$F$341,$B8,'VS×ケイパビリティ関係'!$G$4:$G$341,H$5,'VS×ケイパビリティ関係'!$E$4:$E$341,"主")>0,"●",IF(COUNTIFS('VS×ケイパビリティ関係'!$F$4:$F$341,$B8,'VS×ケイパビリティ関係'!$G$4:$G$341,H$5,'VS×ケイパビリティ関係'!$E$4:$E$341,"支援")>0,"○","")) | I8: =IF(COUNTIFS('VS×ケイパビリティ関係'!$F$4:$F$341,$B8,'VS×ケイパビリティ関係'!$G$4:$G$341,I$5,'VS×ケイパビリティ関係'!$E$4:$E$341,"主")>0,"●",IF(COUNTIFS('VS×ケイパビリティ関係'!$F$4:$F$341,$B8,'VS×ケイパビリティ関係'!$G$4:$G$341,I$5,'VS×ケイパビリティ関係'!$E$4:$E$341,"支援")>0,"○","")) | J8: =IF(COUNTIFS('VS×ケイパビリティ関係'!$F$4:$F$341,$B8,'VS×ケイパビリティ関係'!$G$4:$G$341,J$5,'VS×ケイパビリティ関係'!$E$4:$E$341,"主")>0,"●",IF(COUNTIFS('VS×ケイパビリティ関係'!$F$4:$F$341,$B8,'VS×ケイパビリティ関係'!$G$4:$G$341,J$5,'VS×ケイパビリティ関係'!$E$4:$E$341,"支援")>0,"○","")) | K8: =IF(COUNTIFS('VS×ケイパビリティ関係'!$F$4:$F$341,$B8,'VS×ケイパビリティ関係'!$G$4:$G$341,K$5,'VS×ケイパビリティ関係'!$E$4:$E$341,"主")>0,"●",IF(COUNTIFS('VS×ケイパビリティ関係'!$F$4:$F$341,$B8,'VS×ケイパビリティ関係'!$G$4:$G$341,K$5,'VS×ケイパビリティ関係'!$E$4:$E$341,"支援")>0,"○","")) | ... AE8: =IF(COUNTIFS('VS×ケイパビリティ関係'!$F$4:$F$341,$B8,'VS×ケイパビリティ関係'!$G$4:$G$341,AE$5,'VS×ケイパビリティ関係'!$E$4:$E$341,"主")>0,"●",IF(COUNTIFS('VS×ケイパビリティ関係'!$F$4:$F$341,$B8,'VS×ケイパビリティ関係'!$G$4:$G$341,AE$5,'VS×ケイパビリティ関係'!$E$4:$E$341,"支援")>0,"○","")) | AF8: =COUNTIF(D8:AE8,"●") | AG8: =COUNTIF(D8:AE8,"○")
B9: 01-03 | C9: ポートフォリオ・投資判断 | D9: =IF(COUNTIFS('VS×ケイパビリティ関係'!$F$4:$F$341,$B9,'VS×ケイパビリティ関係'!$G$4:$G$341,D$5,'VS×ケイパビリティ関係'!$E$4:$E$341,"主")>0,"●",IF(COUNTIFS('VS×ケイパビリティ関係'!$F$4:$F$341,$B9,'VS×ケイパビリティ関係'!$G$4:$G$341,D$5,'VS×ケイパビリティ関係'!$E$4:$E$341,"支援")>0,"○","")) | E9: =IF(COUNTIFS('VS×ケイパビリティ関係'!$F$4:$F$341,$B9,'VS×ケイパビリティ関係'!$G$4:$G$341,E$5,'VS×ケイパビリティ関係'!$E$4:$E$341,"主")>0,"●",IF(COUNTIFS('VS×ケイパビリティ関係'!$F$4:$F$341,$B9,'VS×ケイパビリティ関係'!$G$4:$G$341,E$5,'VS×ケイパビリティ関係'!$E$4:$E$341,"支援")>0,"○","")) | F9: =IF(COUNTIFS('VS×ケイパビリティ関係'!$F$4:$F$341,$B9,'VS×ケイパビリティ関係'!$G$4:$G$341,F$5,'VS×ケイパビリティ関係'!$E$4:$E$341,"主")>0,"●",IF(COUNTIFS('VS×ケイパビリティ関係'!$F$4:$F$341,$B9,'VS×ケイパビリティ関係'!$G$4:$G$341,F$5,'VS×ケイパビリティ関係'!$E$4:$E$341,"支援")>0,"○","")) | G9: =IF(COUNTIFS('VS×ケイパビリティ関係'!$F$4:$F$341,$B9,'VS×ケイパビリティ関係'!$G$4:$G$341,G$5,'VS×ケイパビリティ関係'!$E$4:$E$341,"主")>0,"●",IF(COUNTIFS('VS×ケイパビリティ関係'!$F$4:$F$341,$B9,'VS×ケイパビリティ関係'!$G$4:$G$341,G$5,'VS×ケイパビリティ関係'!$E$4:$E$341,"支援")>0,"○","")) | H9: =IF(COUNTIFS('VS×ケイパビリティ関係'!$F$4:$F$341,$B9,'VS×ケイパビリティ関係'!$G$4:$G$341,H$5,'VS×ケイパビリティ関係'!$E$4:$E$341,"主")>0,"●",IF(COUNTIFS('VS×ケイパビリティ関係'!$F$4:$F$341,$B9,'VS×ケイパビリティ関係'!$G$4:$G$341,H$5,'VS×ケイパビリティ関係'!$E$4:$E$341,"支援")>0,"○","")) | I9: =IF(COUNTIFS('VS×ケイパビリティ関係'!$F$4:$F$341,$B9,'VS×ケイパビリティ関係'!$G$4:$G$341,I$5,'VS×ケイパビリティ関係'!$E$4:$E$341,"主")>0,"●",IF(COUNTIFS('VS×ケイパビリティ関係'!$F$4:$F$341,$B9,'VS×ケイパビリティ関係'!$G$4:$G$341,I$5,'VS×ケイパビリティ関係'!$E$4:$E$341,"支援")>0,"○","")) | J9: =IF(COUNTIFS('VS×ケイパビリティ関係'!$F$4:$F$341,$B9,'VS×ケイパビリティ関係'!$G$4:$G$341,J$5,'VS×ケイパビリティ関係'!$E$4:$E$341,"主")>0,"●",IF(COUNTIFS('VS×ケイパビリティ関係'!$F$4:$F$341,$B9,'VS×ケイパビリティ関係'!$G$4:$G$341,J$5,'VS×ケイパビリティ関係'!$E$4:$E$341,"支援")>0,"○","")) | K9: =IF(COUNTIFS('VS×ケイパビリティ関係'!$F$4:$F$341,$B9,'VS×ケイパビリティ関係'!$G$4:$G$341,K$5,'VS×ケイパビリティ関係'!$E$4:$E$341,"主")>0,"●",IF(COUNTIFS('VS×ケイパビリティ関係'!$F$4:$F$341,$B9,'VS×ケイパビリティ関係'!$G$4:$G$341,K$5,'VS×ケイパビリティ関係'!$E$4:$E$341,"支援")>0,"○","")) | ... AE9: =IF(COUNTIFS('VS×ケイパビリティ関係'!$F$4:$F$341,$B9,'VS×ケイパビリティ関係'!$G$4:$G$341,AE$5,'VS×ケイパビリティ関係'!$E$4:$E$341,"主")>0,"●",IF(COUNTIFS('VS×ケイパビリティ関係'!$F$4:$F$341,$B9,'VS×ケイパビリティ関係'!$G$4:$G$341,AE$5,'VS×ケイパビリティ関係'!$E$4:$E$341,"支援")>0,"○","")) | AF9: =COUNTIF(D9:AE9,"●") | AG9: =COUNTIF(D9:AE9,"○")
A10: 02 要件定義・開発・配備（R2D） | B10: 02-01 | C10: プロジェクト立上げ・委託 | D10: =IF(COUNTIFS('VS×ケイパビリティ関係'!$F$4:$F$341,$B10,'VS×ケイパビリティ関係'!$G$4:$G$341,D$5,'VS×ケイパビリティ関係'!$E$4:$E$341,"主")>0,"●",IF(COUNTIFS('VS×ケイパビリティ関係'!$F$4:$F$341,$B10,'VS×ケイパビリティ関係'!$G$4:$G$341,D$5,'VS×ケイパビリティ関係'!$E$4:$E$341,"支援")>0,"○","")) | E10: =IF(COUNTIFS('VS×ケイパビリティ関係'!$F$4:$F$341,$B10,'VS×ケイパビリティ関係'!$G$4:$G$341,E$5,'VS×ケイパビリティ関係'!$E$4:$E$341,"主")>0,"●",IF(COUNTIFS('VS×ケイパビリティ関係'!$F$4:$F$341,$B10,'VS×ケイパビリティ関係'!$G$4:$G$341,E$5,'VS×ケイパビリティ関係'!$E$4:$E$341,"支援")>0,"○","")) | F10: =IF(COUNTIFS('VS×ケイパビリティ関係'!$F$4:$F$341,$B10,'VS×ケイパビリティ関係'!$G$4:$G$341,F$5,'VS×ケイパビリティ関係'!$E$4:$E$341,"主")>0,"●",IF(COUNTIFS('VS×ケイパビリティ関係'!$F$4:$F$341,$B10,'VS×ケイパビリティ関係'!$G$4:$G$341,F$5,'VS×ケイパビリティ関係'!$E$4:$E$341,"支援")>0,"○","")) | G10: =IF(COUNTIFS('VS×ケイパビリティ関係'!$F$4:$F$341,$B10,'VS×ケイパビリティ関係'!$G$4:$G$341,G$5,'VS×ケイパビリティ関係'!$E$4:$E$341,"主")>0,"●",IF(COUNTIFS('VS×ケイパビリティ関係'!$F$4:$F$341,$B10,'VS×ケイパビリティ関係'!$G$4:$G$341,G$5,'VS×ケイパビリティ関係'!$E$4:$E$341,"支援")>0,"○","")) | H10: =IF(COUNTIFS('VS×ケイパビリティ関係'!$F$4:$F$341,$B10,'VS×ケイパビリティ関係'!$G$4:$G$341,H$5,'VS×ケイパビリティ関係'!$E$4:$E$341,"主")>0,"●",IF(COUNTIFS('VS×ケイパビリティ関係'!$F$4:$F$341,$B10,'VS×ケイパビリティ関係'!$G$4:$G$341,H$5,'VS×ケイパビリティ関係'!$E$4:$E$341,"支援")>0,"○","")) | I10: =IF(COUNTIFS('VS×ケイパビリティ関係'!$F$4:$F$341,$B10,'VS×ケイパビリティ関係'!$G$4:$G$341,I$5,'VS×ケイパビリティ関係'!$E$4:$E$341,"主")>0,"●",IF(COUNTIFS('VS×ケイパビリティ関係'!$F$4:$F$341,$B10,'VS×ケイパビリティ関係'!$G$4:$G$341,I$5,'VS×ケイパビリティ関係'!$E$4:$E$341,"支援")>0,"○","")) | J10: =IF(COUNTIFS('VS×ケイパビリティ関係'!$F$4:$F$341,$B10,'VS×ケイパビリティ関係'!$G$4:$G$341,J$5,'VS×ケイパビリティ関係'!$E$4:$E$341,"主")>0,"●",IF(COUNTIFS('VS×ケイパビリティ関係'!$F$4:$F$341,$B10,'VS×ケイパビリティ関係'!$G$4:$G$341,J$5,'VS×ケイパビリティ関係'!$E$4:$E$341,"支援")>0,"○","")) | K10: =IF(COUNTIFS('VS×ケイパビリティ関係'!$F$4:$F$341,$B10,'VS×ケイパビリティ関係'!$G$4:$G$341,K$5,'VS×ケイパビリティ関係'!$E$4:$E$341,"主")>0,"●",IF(COUNTIFS('VS×ケイパビリティ関係'!$F$4:$F$341,$B10,'VS×ケイパビリティ関係'!$G$4:$G$341,K$5,'VS×ケイパビリティ関係'!$E$4:$E$341,"支援")>0,"○","")) | ... AE10: =IF(COUNTIFS('VS×ケイパビリティ関係'!$F$4:$F$341,$B10,'VS×ケイパビリティ関係'!$G$4:$G$341,AE$5,'VS×ケイパビリティ関係'!$E$4:$E$341,"主")>0,"●",IF(COUNTIFS('VS×ケイパビリティ関係'!$F$4:$F$341,$B10,'VS×ケイパビリティ関係'!$G$4:$G$341,AE$5,'VS×ケイパビリティ関係'!$E$4:$E$341,"支援")>0,"○","")) | AF10: =COUNTIF(D10:AE10,"●") | AG10: =COUNTIF(D10:AE10,"○")
B11: 02-02 | C11: 要件定義・設計 | D11: =IF(COUNTIFS('VS×ケイパビリティ関係'!$F$4:$F$341,$B11,'VS×ケイパビリティ関係'!$G$4:$G$341,D$5,'VS×ケイパビリティ関係'!$E$4:$E$341,"主")>0,"●",IF(COUNTIFS('VS×ケイパビリティ関係'!$F$4:$F$341,$B11,'VS×ケイパビリティ関係'!$G$4:$G$341,D$5,'VS×ケイパビリティ関係'!$E$4:$E$341,"支援")>0,"○","")) | E11: =IF(COUNTIFS('VS×ケイパビリティ関係'!$F$4:$F$341,$B11,'VS×ケイパビリティ関係'!$G$4:$G$341,E$5,'VS×ケイパビリティ関係'!$E$4:$E$341,"主")>0,"●",IF(COUNTIFS('VS×ケイパビリティ関係'!$F$4:$F$341,$B11,'VS×ケイパビリティ関係'!$G$4:$G$341,E$5,'VS×ケイパビリティ関係'!$E$4:$E$341,"支援")>0,"○","")) | F11: =IF(COUNTIFS('VS×ケイパビリティ関係'!$F$4:$F$341,$B11,'VS×ケイパビリティ関係'!$G$4:$G$341,F$5,'VS×ケイパビリティ関係'!$E$4:$E$341,"主")>0,"●",IF(COUNTIFS('VS×ケイパビリティ関係'!$F$4:$F$341,$B11,'VS×ケイパビリティ関係'!$G$4:$G$341,F$5,'VS×ケイパビリティ関係'!$E$4:$E$341,"支援")>0,"○","")) | G11: =IF(COUNTIFS('VS×ケイパビリティ関係'!$F$4:$F$341,$B11,'VS×ケイパビリティ関係'!$G$4:$G$341,G$5,'VS×ケイパビリティ関係'!$E$4:$E$341,"主")>0,"●",IF(COUNTIFS('VS×ケイパビリティ関係'!$F$4:$F$341,$B11,'VS×ケイパビリティ関係'!$G$4:$G$341,G$5,'VS×ケイパビリティ関係'!$E$4:$E$341,"支援")>0,"○","")) | H11: =IF(COUNTIFS('VS×ケイパビリティ関係'!$F$4:$F$341,$B11,'VS×ケイパビリティ関係'!$G$4:$G$341,H$5,'VS×ケイパビリティ関係'!$E$4:$E$341,"主")>0,"●",IF(COUNTIFS('VS×ケイパビリティ関係'!$F$4:$F$341,$B11,'VS×ケイパビリティ関係'!$G$4:$G$341,H$5,'VS×ケイパビリティ関係'!$E$4:$E$341,"支援")>0,"○","")) | I11: =IF(COUNTIFS('VS×ケイパビリティ関係'!$F$4:$F$341,$B11,'VS×ケイパビリティ関係'!$G$4:$G$341,I$5,'VS×ケイパビリティ関係'!$E$4:$E$341,"主")>0,"●",IF(COUNTIFS('VS×ケイパビリティ関係'!$F$4:$F$341,$B11,'VS×ケイパビリティ関係'!$G$4:$G$341,I$5,'VS×ケイパビリティ関係'!$E$4:$E$341,"支援")>0,"○","")) | J11: =IF(COUNTIFS('VS×ケイパビリティ関係'!$F$4:$F$341,$B11,'VS×ケイパビリティ関係'!$G$4:$G$341,J$5,'VS×ケイパビリティ関係'!$E$4:$E$341,"主")>0,"●",IF(COUNTIFS('VS×ケイパビリティ関係'!$F$4:$F$341,$B11,'VS×ケイパビリティ関係'!$G$4:$G$341,J$5,'VS×ケイパビリティ関係'!$E$4:$E$341,"支援")>0,"○","")) | K11: =IF(COUNTIFS('VS×ケイパビリティ関係'!$F$4:$F$341,$B11,'VS×ケイパビリティ関係'!$G$4:$G$341,K$5,'VS×ケイパビリティ関係'!$E$4:$E$341,"主")>0,"●",IF(COUNTIFS('VS×ケイパビリティ関係'!$F$4:$F$341,$B11,'VS×ケイパビリティ関係'!$G$4:$G$341,K$5,'VS×ケイパビリティ関係'!$E$4:$E$341,"支援")>0,"○","")) | ... AE11: =IF(COUNTIFS('VS×ケイパビリティ関係'!$F$4:$F$341,$B11,'VS×ケイパビリティ関係'!$G$4:$G$341,AE$5,'VS×ケイパビリティ関係'!$E$4:$E$341,"主")>0,"●",IF(COUNTIFS('VS×ケイパビリティ関係'!$F$4:$F$341,$B11,'VS×ケイパビリティ関係'!$G$4:$G$341,AE$5,'VS×ケイパビリティ関係'!$E$4:$E$341,"支援")>0,"○","")) | AF11: =COUNTIF(D11:AE11,"●") | AG11: =COUNTIF(D11:AE11,"○")
B12: 02-03 | C12: 開発・構成・テスト | D12: =IF(COUNTIFS('VS×ケイパビリティ関係'!$F$4:$F$341,$B12,'VS×ケイパビリティ関係'!$G$4:$G$341,D$5,'VS×ケイパビリティ関係'!$E$4:$E$341,"主")>0,"●",IF(COUNTIFS('VS×ケイパビリティ関係'!$F$4:$F$341,$B12,'VS×ケイパビリティ関係'!$G$4:$G$341,D$5,'VS×ケイパビリティ関係'!$E$4:$E$341,"支援")>0,"○","")) | E12: =IF(COUNTIFS('VS×ケイパビリティ関係'!$F$4:$F$341,$B12,'VS×ケイパビリティ関係'!$G$4:$G$341,E$5,'VS×ケイパビリティ関係'!$E$4:$E$341,"主")>0,"●",IF(COUNTIFS('VS×ケイパビリティ関係'!$F$4:$F$341,$B12,'VS×ケイパビリティ関係'!$G$4:$G$341,E$5,'VS×ケイパビリティ関係'!$E$4:$E$341,"支援")>0,"○","")) | F12: =IF(COUNTIFS('VS×ケイパビリティ関係'!$F$4:$F$341,$B12,'VS×ケイパビリティ関係'!$G$4:$G$341,F$5,'VS×ケイパビリティ関係'!$E$4:$E$341,"主")>0,"●",IF(COUNTIFS('VS×ケイパビリティ関係'!$F$4:$F$341,$B12,'VS×ケイパビリティ関係'!$G$4:$G$341,F$5,'VS×ケイパビリティ関係'!$E$4:$E$341,"支援")>0,"○","")) | G12: =IF(COUNTIFS('VS×ケイパビリティ関係'!$F$4:$F$341,$B12,'VS×ケイパビリティ関係'!$G$4:$G$341,G$5,'VS×ケイパビリティ関係'!$E$4:$E$341,"主")>0,"●",IF(COUNTIFS('VS×ケイパビリティ関係'!$F$4:$F$341,$B12,'VS×ケイパビリティ関係'!$G$4:$G$341,G$5,'VS×ケイパビリティ関係'!$E$4:$E$341,"支援")>0,"○","")) | H12: =IF(COUNTIFS('VS×ケイパビリティ関係'!$F$4:$F$341,$B12,'VS×ケイパビリティ関係'!$G$4:$G$341,H$5,'VS×ケイパビリティ関係'!$E$4:$E$341,"主")>0,"●",IF(COUNTIFS('VS×ケイパビリティ関係'!$F$4:$F$341,$B12,'VS×ケイパビリティ関係'!$G$4:$G$341,H$5,'VS×ケイパビリティ関係'!$E$4:$E$341,"支援")>0,"○","")) | I12: =IF(COUNTIFS('VS×ケイパビリティ関係'!$F$4:$F$341,$B12,'VS×ケイパビリティ関係'!$G$4:$G$341,I$5,'VS×ケイパビリティ関係'!$E$4:$E$341,"主")>0,"●",IF(COUNTIFS('VS×ケイパビリティ関係'!$F$4:$F$341,$B12,'VS×ケイパビリティ関係'!$G$4:$G$341,I$5,'VS×ケイパビリティ関係'!$E$4:$E$341,"支援")>0,"○","")) | J12: =IF(COUNTIFS('VS×ケイパビリティ関係'!$F$4:$F$341,$B12,'VS×ケイパビリティ関係'!$G$4:$G$341,J$5,'VS×ケイパビリティ関係'!$E$4:$E$341,"主")>0,"●",IF(COUNTIFS('VS×ケイパビリティ関係'!$F$4:$F$341,$B12,'VS×ケイパビリティ関係'!$G$4:$G$341,J$5,'VS×ケイパビリティ関係'!$E$4:$E$341,"支援")>0,"○","")) | K12: =IF(COUNTIFS('VS×ケイパビリティ関係'!$F$4:$F$341,$B12,'VS×ケイパビリティ関係'!$G$4:$G$341,K$5,'VS×ケイパビリティ関係'!$E$4:$E$341,"主")>0,"●",IF(COUNTIFS('VS×ケイパビリティ関係'!$F$4:$F$341,$B12,'VS×ケイパビリティ関係'!$G$4:$G$341,K$5,'VS×ケイパビリティ関係'!$E$4:$E$341,"支援")>0,"○","")) | ... AE12: =IF(COUNTIFS('VS×ケイパビリティ関係'!$F$4:$F$341,$B12,'VS×ケイパビリティ関係'!$G$4:$G$341,AE$5,'VS×ケイパビリティ関係'!$E$4:$E$341,"主")>0,"●",IF(COUNTIFS('VS×ケイパビリティ関係'!$F$4:$F$341,$B12,'VS×ケイパビリティ関係'!$G$4:$G$341,AE$5,'VS×ケイパビリティ関係'!$E$4:$E$341,"支援")>0,"○","")) | AF12: =COUNTIF(D12:AE12,"●") | AG12: =COUNTIF(D12:AE12,"○")
B13: 02-04 | C13: バリデーション・リリース | D13: =IF(COUNTIFS('VS×ケイパビリティ関係'!$F$4:$F$341,$B13,'VS×ケイパビリティ関係'!$G$4:$G$341,D$5,'VS×ケイパビリティ関係'!$E$4:$E$341,"主")>0,"●",IF(COUNTIFS('VS×ケイパビリティ関係'!$F$4:$F$341,$B13,'VS×ケイパビリティ関係'!$G$4:$G$341,D$5,'VS×ケイパビリティ関係'!$E$4:$E$341,"支援")>0,"○","")) | E13: =IF(COUNTIFS('VS×ケイパビリティ関係'!$F$4:$F$341,$B13,'VS×ケイパビリティ関係'!$G$4:$G$341,E$5,'VS×ケイパビリティ関係'!$E$4:$E$341,"主")>0,"●",IF(COUNTIFS('VS×ケイパビリティ関係'!$F$4:$F$341,$B13,'VS×ケイパビリティ関係'!$G$4:$G$341,E$5,'VS×ケイパビリティ関係'!$E$4:$E$341,"支援")>0,"○","")) | F13: =IF(COUNTIFS('VS×ケイパビリティ関係'!$F$4:$F$341,$B13,'VS×ケイパビリティ関係'!$G$4:$G$341,F$5,'VS×ケイパビリティ関係'!$E$4:$E$341,"主")>0,"●",IF(COUNTIFS('VS×ケイパビリティ関係'!$F$4:$F$341,$B13,'VS×ケイパビリティ関係'!$G$4:$G$341,F$5,'VS×ケイパビリティ関係'!$E$4:$E$341,"支援")>0,"○","")) | G13: =IF(COUNTIFS('VS×ケイパビリティ関係'!$F$4:$F$341,$B13,'VS×ケイパビリティ関係'!$G$4:$G$341,G$5,'VS×ケイパビリティ関係'!$E$4:$E$341,"主")>0,"●",IF(COUNTIFS('VS×ケイパビリティ関係'!$F$4:$F$341,$B13,'VS×ケイパビリティ関係'!$G$4:$G$341,G$5,'VS×ケイパビリティ関係'!$E$4:$E$341,"支援")>0,"○","")) | H13: =IF(COUNTIFS('VS×ケイパビリティ関係'!$F$4:$F$341,$B13,'VS×ケイパビリティ関係'!$G$4:$G$341,H$5,'VS×ケイパビリティ関係'!$E$4:$E$341,"主")>0,"●",IF(COUNTIFS('VS×ケイパビリティ関係'!$F$4:$F$341,$B13,'VS×ケイパビリティ関係'!$G$4:$G$341,H$5,'VS×ケイパビリティ関係'!$E$4:$E$341,"支援")>0,"○","")) | I13: =IF(COUNTIFS('VS×ケイパビリティ関係'!$F$4:$F$341,$B13,'VS×ケイパビリティ関係'!$G$4:$G$341,I$5,'VS×ケイパビリティ関係'!$E$4:$E$341,"主")>0,"●",IF(COUNTIFS('VS×ケイパビリティ関係'!$F$4:$F$341,$B13,'VS×ケイパビリティ関係'!$G$4:$G$341,I$5,'VS×ケイパビリティ関係'!$E$4:$E$341,"支援")>0,"○","")) | J13: =IF(COUNTIFS('VS×ケイパビリティ関係'!$F$4:$F$341,$B13,'VS×ケイパビリティ関係'!$G$4:$G$341,J$5,'VS×ケイパビリティ関係'!$E$4:$E$341,"主")>0,"●",IF(COUNTIFS('VS×ケイパビリティ関係'!$F$4:$F$341,$B13,'VS×ケイパビリティ関係'!$G$4:$G$341,J$5,'VS×ケイパビリティ関係'!$E$4:$E$341,"支援")>0,"○","")) | K13: =IF(COUNTIFS('VS×ケイパビリティ関係'!$F$4:$F$341,$B13,'VS×ケイパビリティ関係'!$G$4:$G$341,K$5,'VS×ケイパビリティ関係'!$E$4:$E$341,"主")>0,"●",IF(COUNTIFS('VS×ケイパビリティ関係'!$F$4:$F$341,$B13,'VS×ケイパビリティ関係'!$G$4:$G$341,K$5,'VS×ケイパビリティ関係'!$E$4:$E$341,"支援")>0,"○","")) | ... AE13: =IF(COUNTIFS('VS×ケイパビリティ関係'!$F$4:$F$341,$B13,'VS×ケイパビリティ関係'!$G$4:$G$341,AE$5,'VS×ケイパビリティ関係'!$E$4:$E$341,"主")>0,"●",IF(COUNTIFS('VS×ケイパビリティ関係'!$F$4:$F$341,$B13,'VS×ケイパビリティ関係'!$G$4:$G$341,AE$5,'VS×ケイパビリティ関係'!$E$4:$E$341,"支援")>0,"○","")) | AF13: =COUNTIF(D13:AE13,"●") | AG13: =COUNTIF(D13:AE13,"○")
A14: 03 利用申請・提供（R2F） | B14: 03-01 | C14: サービスカタログの公開 | D14: =IF(COUNTIFS('VS×ケイパビリティ関係'!$F$4:$F$341,$B14,'VS×ケイパビリティ関係'!$G$4:$G$341,D$5,'VS×ケイパビリティ関係'!$E$4:$E$341,"主")>0,"●",IF(COUNTIFS('VS×ケイパビリティ関係'!$F$4:$F$341,$B14,'VS×ケイパビリティ関係'!$G$4:$G$341,D$5,'VS×ケイパビリティ関係'!$E$4:$E$341,"支援")>0,"○","")) | E14: =IF(COUNTIFS('VS×ケイパビリティ関係'!$F$4:$F$341,$B14,'VS×ケイパビリティ関係'!$G$4:$G$341,E$5,'VS×ケイパビリティ関係'!$E$4:$E$341,"主")>0,"●",IF(COUNTIFS('VS×ケイパビリティ関係'!$F$4:$F$341,$B14,'VS×ケイパビリティ関係'!$G$4:$G$341,E$5,'VS×ケイパビリティ関係'!$E$4:$E$341,"支援")>0,"○","")) | F14: =IF(COUNTIFS('VS×ケイパビリティ関係'!$F$4:$F$341,$B14,'VS×ケイパビリティ関係'!$G$4:$G$341,F$5,'VS×ケイパビリティ関係'!$E$4:$E$341,"主")>0,"●",IF(COUNTIFS('VS×ケイパビリティ関係'!$F$4:$F$341,$B14,'VS×ケイパビリティ関係'!$G$4:$G$341,F$5,'VS×ケイパビリティ関係'!$E$4:$E$341,"支援")>0,"○","")) | G14: =IF(COUNTIFS('VS×ケイパビリティ関係'!$F$4:$F$341,$B14,'VS×ケイパビリティ関係'!$G$4:$G$341,G$5,'VS×ケイパビリティ関係'!$E$4:$E$341,"主")>0,"●",IF(COUNTIFS('VS×ケイパビリティ関係'!$F$4:$F$341,$B14,'VS×ケイパビリティ関係'!$G$4:$G$341,G$5,'VS×ケイパビリティ関係'!$E$4:$E$341,"支援")>0,"○","")) | H14: =IF(COUNTIFS('VS×ケイパビリティ関係'!$F$4:$F$341,$B14,'VS×ケイパビリティ関係'!$G$4:$G$341,H$5,'VS×ケイパビリティ関係'!$E$4:$E$341,"主")>0,"●",IF(COUNTIFS('VS×ケイパビリティ関係'!$F$4:$F$341,$B14,'VS×ケイパビリティ関係'!$G$4:$G$341,H$5,'VS×ケイパビリティ関係'!$E$4:$E$341,"支援")>0,"○","")) | I14: =IF(COUNTIFS('VS×ケイパビリティ関係'!$F$4:$F$341,$B14,'VS×ケイパビリティ関係'!$G$4:$G$341,I$5,'VS×ケイパビリティ関係'!$E$4:$E$341,"主")>0,"●",IF(COUNTIFS('VS×ケイパビリティ関係'!$F$4:$F$341,$B14,'VS×ケイパビリティ関係'!$G$4:$G$341,I$5,'VS×ケイパビリティ関係'!$E$4:$E$341,"支援")>0,"○","")) | J14: =IF(COUNTIFS('VS×ケイパビリティ関係'!$F$4:$F$341,$B14,'VS×ケイパビリティ関係'!$G$4:$G$341,J$5,'VS×ケイパビリティ関係'!$E$4:$E$341,"主")>0,"●",IF(COUNTIFS('VS×ケイパビリティ関係'!$F$4:$F$341,$B14,'VS×ケイパビリティ関係'!$G$4:$G$341,J$5,'VS×ケイパビリティ関係'!$E$4:$E$341,"支援")>0,"○","")) | K14: =IF(COUNTIFS('VS×ケイパビリティ関係'!$F$4:$F$341,$B14,'VS×ケイパビリティ関係'!$G$4:$G$341,K$5,'VS×ケイパビリティ関係'!$E$4:$E$341,"主")>0,"●",IF(COUNTIFS('VS×ケイパビリティ関係'!$F$4:$F$341,$B14,'VS×ケイパビリティ関係'!$G$4:$G$341,K$5,'VS×ケイパビリティ関係'!$E$4:$E$341,"支援")>0,"○","")) | ... AE14: =IF(COUNTIFS('VS×ケイパビリティ関係'!$F$4:$F$341,$B14,'VS×ケイパビリティ関係'!$G$4:$G$341,AE$5,'VS×ケイパビリティ関係'!$E$4:$E$341,"主")>0,"●",IF(COUNTIFS('VS×ケイパビリティ関係'!$F$4:$F$341,$B14,'VS×ケイパビリティ関係'!$G$4:$G$341,AE$5,'VS×ケイパビリティ関係'!$E$4:$E$341,"支援")>0,"○","")) | AF14: =COUNTIF(D14:AE14,"●") | AG14: =COUNTIF(D14:AE14,"○")
B15: 03-02 | C15: 申請・承認 | D15: =IF(COUNTIFS('VS×ケイパビリティ関係'!$F$4:$F$341,$B15,'VS×ケイパビリティ関係'!$G$4:$G$341,D$5,'VS×ケイパビリティ関係'!$E$4:$E$341,"主")>0,"●",IF(COUNTIFS('VS×ケイパビリティ関係'!$F$4:$F$341,$B15,'VS×ケイパビリティ関係'!$G$4:$G$341,D$5,'VS×ケイパビリティ関係'!$E$4:$E$341,"支援")>0,"○","")) | E15: =IF(COUNTIFS('VS×ケイパビリティ関係'!$F$4:$F$341,$B15,'VS×ケイパビリティ関係'!$G$4:$G$341,E$5,'VS×ケイパビリティ関係'!$E$4:$E$341,"主")>0,"●",IF(COUNTIFS('VS×ケイパビリティ関係'!$F$4:$F$341,$B15,'VS×ケイパビリティ関係'!$G$4:$G$341,E$5,'VS×ケイパビリティ関係'!$E$4:$E$341,"支援")>0,"○","")) | F15: =IF(COUNTIFS('VS×ケイパビリティ関係'!$F$4:$F$341,$B15,'VS×ケイパビリティ関係'!$G$4:$G$341,F$5,'VS×ケイパビリティ関係'!$E$4:$E$341,"主")>0,"●",IF(COUNTIFS('VS×ケイパビリティ関係'!$F$4:$F$341,$B15,'VS×ケイパビリティ関係'!$G$4:$G$341,F$5,'VS×ケイパビリティ関係'!$E$4:$E$341,"支援")>0,"○","")) | G15: =IF(COUNTIFS('VS×ケイパビリティ関係'!$F$4:$F$341,$B15,'VS×ケイパビリティ関係'!$G$4:$G$341,G$5,'VS×ケイパビリティ関係'!$E$4:$E$341,"主")>0,"●",IF(COUNTIFS('VS×ケイパビリティ関係'!$F$4:$F$341,$B15,'VS×ケイパビリティ関係'!$G$4:$G$341,G$5,'VS×ケイパビリティ関係'!$E$4:$E$341,"支援")>0,"○","")) | H15: =IF(COUNTIFS('VS×ケイパビリティ関係'!$F$4:$F$341,$B15,'VS×ケイパビリティ関係'!$G$4:$G$341,H$5,'VS×ケイパビリティ関係'!$E$4:$E$341,"主")>0,"●",IF(COUNTIFS('VS×ケイパビリティ関係'!$F$4:$F$341,$B15,'VS×ケイパビリティ関係'!$G$4:$G$341,H$5,'VS×ケイパビリティ関係'!$E$4:$E$341,"支援")>0,"○","")) | I15: =IF(COUNTIFS('VS×ケイパビリティ関係'!$F$4:$F$341,$B15,'VS×ケイパビリティ関係'!$G$4:$G$341,I$5,'VS×ケイパビリティ関係'!$E$4:$E$341,"主")>0,"●",IF(COUNTIFS('VS×ケイパビリティ関係'!$F$4:$F$341,$B15,'VS×ケイパビリティ関係'!$G$4:$G$341,I$5,'VS×ケイパビリティ関係'!$E$4:$E$341,"支援")>0,"○","")) | J15: =IF(COUNTIFS('VS×ケイパビリティ関係'!$F$4:$F$341,$B15,'VS×ケイパビリティ関係'!$G$4:$G$341,J$5,'VS×ケイパビリティ関係'!$E$4:$E$341,"主")>0,"●",IF(COUNTIFS('VS×ケイパビリティ関係'!$F$4:$F$341,$B15,'VS×ケイパビリティ関係'!$G$4:$G$341,J$5,'VS×ケイパビリティ関係'!$E$4:$E$341,"支援")>0,"○","")) | K15: =IF(COUNTIFS('VS×ケイパビリティ関係'!$F$4:$F$341,$B15,'VS×ケイパビリティ関係'!$G$4:$G$341,K$5,'VS×ケイパビリティ関係'!$E$4:$E$341,"主")>0,"●",IF(COUNTIFS('VS×ケイパビリティ関係'!$F$4:$F$341,$B15,'VS×ケイパビリティ関係'!$G$4:$G$341,K$5,'VS×ケイパビリティ関係'!$E$4:$E$341,"支援")>0,"○","")) | ... AE15: =IF(COUNTIFS('VS×ケイパビリティ関係'!$F$4:$F$341,$B15,'VS×ケイパビリティ関係'!$G$4:$G$341,AE$5,'VS×ケイパビリティ関係'!$E$4:$E$341,"主")>0,"●",IF(COUNTIFS('VS×ケイパビリティ関係'!$F$4:$F$341,$B15,'VS×ケイパビリティ関係'!$G$4:$G$341,AE$5,'VS×ケイパビリティ関係'!$E$4:$E$341,"支援")>0,"○","")) | AF15: =COUNTIF(D15:AE15,"●") | AG15: =COUNTIF(D15:AE15,"○")
B16: 03-03 | C16: 提供 | D16: =IF(COUNTIFS('VS×ケイパビリティ関係'!$F$4:$F$341,$B16,'VS×ケイパビリティ関係'!$G$4:$G$341,D$5,'VS×ケイパビリティ関係'!$E$4:$E$341,"主")>0,"●",IF(COUNTIFS('VS×ケイパビリティ関係'!$F$4:$F$341,$B16,'VS×ケイパビリティ関係'!$G$4:$G$341,D$5,'VS×ケイパビリティ関係'!$E$4:$E$341,"支援")>0,"○","")) | E16: =IF(COUNTIFS('VS×ケイパビリティ関係'!$F$4:$F$341,$B16,'VS×ケイパビリティ関係'!$G$4:$G$341,E$5,'VS×ケイパビリティ関係'!$E$4:$E$341,"主")>0,"●",IF(COUNTIFS('VS×ケイパビリティ関係'!$F$4:$F$341,$B16,'VS×ケイパビリティ関係'!$G$4:$G$341,E$5,'VS×ケイパビリティ関係'!$E$4:$E$341,"支援")>0,"○","")) | F16: =IF(COUNTIFS('VS×ケイパビリティ関係'!$F$4:$F$341,$B16,'VS×ケイパビリティ関係'!$G$4:$G$341,F$5,'VS×ケイパビリティ関係'!$E$4:$E$341,"主")>0,"●",IF(COUNTIFS('VS×ケイパビリティ関係'!$F$4:$F$341,$B16,'VS×ケイパビリティ関係'!$G$4:$G$341,F$5,'VS×ケイパビリティ関係'!$E$4:$E$341,"支援")>0,"○","")) | G16: =IF(COUNTIFS('VS×ケイパビリティ関係'!$F$4:$F$341,$B16,'VS×ケイパビリティ関係'!$G$4:$G$341,G$5,'VS×ケイパビリティ関係'!$E$4:$E$341,"主")>0,"●",IF(COUNTIFS('VS×ケイパビリティ関係'!$F$4:$F$341,$B16,'VS×ケイパビリティ関係'!$G$4:$G$341,G$5,'VS×ケイパビリティ関係'!$E$4:$E$341,"支援")>0,"○","")) | H16: =IF(COUNTIFS('VS×ケイパビリティ関係'!$F$4:$F$341,$B16,'VS×ケイパビリティ関係'!$G$4:$G$341,H$5,'VS×ケイパビリティ関係'!$E$4:$E$341,"主")>0,"●",IF(COUNTIFS('VS×ケイパビリティ関係'!$F$4:$F$341,$B16,'VS×ケイパビリティ関係'!$G$4:$G$341,H$5,'VS×ケイパビリティ関係'!$E$4:$E$341,"支援")>0,"○","")) | I16: =IF(COUNTIFS('VS×ケイパビリティ関係'!$F$4:$F$341,$B16,'VS×ケイパビリティ関係'!$G$4:$G$341,I$5,'VS×ケイパビリティ関係'!$E$4:$E$341,"主")>0,"●",IF(COUNTIFS('VS×ケイパビリティ関係'!$F$4:$F$341,$B16,'VS×ケイパビリティ関係'!$G$4:$G$341,I$5,'VS×ケイパビリティ関係'!$E$4:$E$341,"支援")>0,"○","")) | J16: =IF(COUNTIFS('VS×ケイパビリティ関係'!$F$4:$F$341,$B16,'VS×ケイパビリティ関係'!$G$4:$G$341,J$5,'VS×ケイパビリティ関係'!$E$4:$E$341,"主")>0,"●",IF(COUNTIFS('VS×ケイパビリティ関係'!$F$4:$F$341,$B16,'VS×ケイパビリティ関係'!$G$4:$G$341,J$5,'VS×ケイパビリティ関係'!$E$4:$E$341,"支援")>0,"○","")) | K16: =IF(COUNTIFS('VS×ケイパビリティ関係'!$F$4:$F$341,$B16,'VS×ケイパビリティ関係'!$G$4:$G$341,K$5,'VS×ケイパビリティ関係'!$E$4:$E$341,"主")>0,"●",IF(COUNTIFS('VS×ケイパビリティ関係'!$F$4:$F$341,$B16,'VS×ケイパビリティ関係'!$G$4:$G$341,K$5,'VS×ケイパビリティ関係'!$E$4:$E$341,"支援")>0,"○","")) | ... AE16: =IF(COUNTIFS('VS×ケイパビリティ関係'!$F$4:$F$341,$B16,'VS×ケイパビリティ関係'!$G$4:$G$341,AE$5,'VS×ケイパビリティ関係'!$E$4:$E$341,"主")>0,"●",IF(COUNTIFS('VS×ケイパビリティ関係'!$F$4:$F$341,$B16,'VS×ケイパビリティ関係'!$G$4:$G$341,AE$5,'VS×ケイパビリティ関係'!$E$4:$E$341,"支援")>0,"○","")) | AF16: =COUNTIF(D16:AE16,"●") | AG16: =COUNTIF(D16:AE16,"○")
B17: 03-04 | C17: 利用・費用管理 | D17: =IF(COUNTIFS('VS×ケイパビリティ関係'!$F$4:$F$341,$B17,'VS×ケイパビリティ関係'!$G$4:$G$341,D$5,'VS×ケイパビリティ関係'!$E$4:$E$341,"主")>0,"●",IF(COUNTIFS('VS×ケイパビリティ関係'!$F$4:$F$341,$B17,'VS×ケイパビリティ関係'!$G$4:$G$341,D$5,'VS×ケイパビリティ関係'!$E$4:$E$341,"支援")>0,"○","")) | E17: =IF(COUNTIFS('VS×ケイパビリティ関係'!$F$4:$F$341,$B17,'VS×ケイパビリティ関係'!$G$4:$G$341,E$5,'VS×ケイパビリティ関係'!$E$4:$E$341,"主")>0,"●",IF(COUNTIFS('VS×ケイパビリティ関係'!$F$4:$F$341,$B17,'VS×ケイパビリティ関係'!$G$4:$G$341,E$5,'VS×ケイパビリティ関係'!$E$4:$E$341,"支援")>0,"○","")) | F17: =IF(COUNTIFS('VS×ケイパビリティ関係'!$F$4:$F$341,$B17,'VS×ケイパビリティ関係'!$G$4:$G$341,F$5,'VS×ケイパビリティ関係'!$E$4:$E$341,"主")>0,"●",IF(COUNTIFS('VS×ケイパビリティ関係'!$F$4:$F$341,$B17,'VS×ケイパビリティ関係'!$G$4:$G$341,F$5,'VS×ケイパビリティ関係'!$E$4:$E$341,"支援")>0,"○","")) | G17: =IF(COUNTIFS('VS×ケイパビリティ関係'!$F$4:$F$341,$B17,'VS×ケイパビリティ関係'!$G$4:$G$341,G$5,'VS×ケイパビリティ関係'!$E$4:$E$341,"主")>0,"●",IF(COUNTIFS('VS×ケイパビリティ関係'!$F$4:$F$341,$B17,'VS×ケイパビリティ関係'!$G$4:$G$341,G$5,'VS×ケイパビリティ関係'!$E$4:$E$341,"支援")>0,"○","")) | H17: =IF(COUNTIFS('VS×ケイパビリティ関係'!$F$4:$F$341,$B17,'VS×ケイパビリティ関係'!$G$4:$G$341,H$5,'VS×ケイパビリティ関係'!$E$4:$E$341,"主")>0,"●",IF(COUNTIFS('VS×ケイパビリティ関係'!$F$4:$F$341,$B17,'VS×ケイパビリティ関係'!$G$4:$G$341,H$5,'VS×ケイパビリティ関係'!$E$4:$E$341,"支援")>0,"○","")) | I17: =IF(COUNTIFS('VS×ケイパビリティ関係'!$F$4:$F$341,$B17,'VS×ケイパビリティ関係'!$G$4:$G$341,I$5,'VS×ケイパビリティ関係'!$E$4:$E$341,"主")>0,"●",IF(COUNTIFS('VS×ケイパビリティ関係'!$F$4:$F$341,$B17,'VS×ケイパビリティ関係'!$G$4:$G$341,I$5,'VS×ケイパビリティ関係'!$E$4:$E$341,"支援")>0,"○","")) | J17: =IF(COUNTIFS('VS×ケイパビリティ関係'!$F$4:$F$341,$B17,'VS×ケイパビリティ関係'!$G$4:$G$341,J$5,'VS×ケイパビリティ関係'!$E$4:$E$341,"主")>0,"●",IF(COUNTIFS('VS×ケイパビリティ関係'!$F$4:$F$341,$B17,'VS×ケイパビリティ関係'!$G$4:$G$341,J$5,'VS×ケイパビリティ関係'!$E$4:$E$341,"支援")>0,"○","")) | K17: =IF(COUNTIFS('VS×ケイパビリティ関係'!$F$4:$F$341,$B17,'VS×ケイパビリティ関係'!$G$4:$G$341,K$5,'VS×ケイパビリティ関係'!$E$4:$E$341,"主")>0,"●",IF(COUNTIFS('VS×ケイパビリティ関係'!$F$4:$F$341,$B17,'VS×ケイパビリティ関係'!$G$4:$G$341,K$5,'VS×ケイパビリティ関係'!$E$4:$E$341,"支援")>0,"○","")) | ... AE17: =IF(COUNTIFS('VS×ケイパビリティ関係'!$F$4:$F$341,$B17,'VS×ケイパビリティ関係'!$G$4:$G$341,AE$5,'VS×ケイパビリティ関係'!$E$4:$E$341,"主")>0,"●",IF(COUNTIFS('VS×ケイパビリティ関係'!$F$4:$F$341,$B17,'VS×ケイパビリティ関係'!$G$4:$G$341,AE$5,'VS×ケイパビリティ関係'!$E$4:$E$341,"支援")>0,"○","")) | AF17: =COUNTIF(D17:AE17,"●") | AG17: =COUNTIF(D17:AE17,"○")
A18: 04 検知・是正（D2C） | B18: 04-01 | C18: 監視・検知 | D18: =IF(COUNTIFS('VS×ケイパビリティ関係'!$F$4:$F$341,$B18,'VS×ケイパビリティ関係'!$G$4:$G$341,D$5,'VS×ケイパビリティ関係'!$E$4:$E$341,"主")>0,"●",IF(COUNTIFS('VS×ケイパビリティ関係'!$F$4:$F$341,$B18,'VS×ケイパビリティ関係'!$G$4:$G$341,D$5,'VS×ケイパビリティ関係'!$E$4:$E$341,"支援")>0,"○","")) | E18: =IF(COUNTIFS('VS×ケイパビリティ関係'!$F$4:$F$341,$B18,'VS×ケイパビリティ関係'!$G$4:$G$341,E$5,'VS×ケイパビリティ関係'!$E$4:$E$341,"主")>0,"●",IF(COUNTIFS('VS×ケイパビリティ関係'!$F$4:$F$341,$B18,'VS×ケイパビリティ関係'!$G$4:$G$341,E$5,'VS×ケイパビリティ関係'!$E$4:$E$341,"支援")>0,"○","")) | F18: =IF(COUNTIFS('VS×ケイパビリティ関係'!$F$4:$F$341,$B18,'VS×ケイパビリティ関係'!$G$4:$G$341,F$5,'VS×ケイパビリティ関係'!$E$4:$E$341,"主")>0,"●",IF(COUNTIFS('VS×ケイパビリティ関係'!$F$4:$F$341,$B18,'VS×ケイパビリティ関係'!$G$4:$G$341,F$5,'VS×ケイパビリティ関係'!$E$4:$E$341,"支援")>0,"○","")) | G18: =IF(COUNTIFS('VS×ケイパビリティ関係'!$F$4:$F$341,$B18,'VS×ケイパビリティ関係'!$G$4:$G$341,G$5,'VS×ケイパビリティ関係'!$E$4:$E$341,"主")>0,"●",IF(COUNTIFS('VS×ケイパビリティ関係'!$F$4:$F$341,$B18,'VS×ケイパビリティ関係'!$G$4:$G$341,G$5,'VS×ケイパビリティ関係'!$E$4:$E$341,"支援")>0,"○","")) | H18: =IF(COUNTIFS('VS×ケイパビリティ関係'!$F$4:$F$341,$B18,'VS×ケイパビリティ関係'!$G$4:$G$341,H$5,'VS×ケイパビリティ関係'!$E$4:$E$341,"主")>0,"●",IF(COUNTIFS('VS×ケイパビリティ関係'!$F$4:$F$341,$B18,'VS×ケイパビリティ関係'!$G$4:$G$341,H$5,'VS×ケイパビリティ関係'!$E$4:$E$341,"支援")>0,"○","")) | I18: =IF(COUNTIFS('VS×ケイパビリティ関係'!$F$4:$F$341,$B18,'VS×ケイパビリティ関係'!$G$4:$G$341,I$5,'VS×ケイパビリティ関係'!$E$4:$E$341,"主")>0,"●",IF(COUNTIFS('VS×ケイパビリティ関係'!$F$4:$F$341,$B18,'VS×ケイパビリティ関係'!$G$4:$G$341,I$5,'VS×ケイパビリティ関係'!$E$4:$E$341,"支援")>0,"○","")) | J18: =IF(COUNTIFS('VS×ケイパビリティ関係'!$F$4:$F$341,$B18,'VS×ケイパビリティ関係'!$G$4:$G$341,J$5,'VS×ケイパビリティ関係'!$E$4:$E$341,"主")>0,"●",IF(COUNTIFS('VS×ケイパビリティ関係'!$F$4:$F$341,$B18,'VS×ケイパビリティ関係'!$G$4:$G$341,J$5,'VS×ケイパビリティ関係'!$E$4:$E$341,"支援")>0,"○","")) | K18: =IF(COUNTIFS('VS×ケイパビリティ関係'!$F$4:$F$341,$B18,'VS×ケイパビリティ関係'!$G$4:$G$341,K$5,'VS×ケイパビリティ関係'!$E$4:$E$341,"主")>0,"●",IF(COUNTIFS('VS×ケイパビリティ関係'!$F$4:$F$341,$B18,'VS×ケイパビリティ関係'!$G$4:$G$341,K$5,'VS×ケイパビリティ関係'!$E$4:$E$341,"支援")>0,"○","")) | ... AE18: =IF(COUNTIFS('VS×ケイパビリティ関係'!$F$4:$F$341,$B18,'VS×ケイパビリティ関係'!$G$4:$G$341,AE$5,'VS×ケイパビリティ関係'!$E$4:$E$341,"主")>0,"●",IF(COUNTIFS('VS×ケイパビリティ関係'!$F$4:$F$341,$B18,'VS×ケイパビリティ関係'!$G$4:$G$341,AE$5,'VS×ケイパビリティ関係'!$E$4:$E$341,"支援")>0,"○","")) | AF18: =COUNTIF(D18:AE18,"●") | AG18: =COUNTIF(D18:AE18,"○")
B19: 04-02 | C19: インシデント対応 | D19: =IF(COUNTIFS('VS×ケイパビリティ関係'!$F$4:$F$341,$B19,'VS×ケイパビリティ関係'!$G$4:$G$341,D$5,'VS×ケイパビリティ関係'!$E$4:$E$341,"主")>0,"●",IF(COUNTIFS('VS×ケイパビリティ関係'!$F$4:$F$341,$B19,'VS×ケイパビリティ関係'!$G$4:$G$341,D$5,'VS×ケイパビリティ関係'!$E$4:$E$341,"支援")>0,"○","")) | E19: =IF(COUNTIFS('VS×ケイパビリティ関係'!$F$4:$F$341,$B19,'VS×ケイパビリティ関係'!$G$4:$G$341,E$5,'VS×ケイパビリティ関係'!$E$4:$E$341,"主")>0,"●",IF(COUNTIFS('VS×ケイパビリティ関係'!$F$4:$F$341,$B19,'VS×ケイパビリティ関係'!$G$4:$G$341,E$5,'VS×ケイパビリティ関係'!$E$4:$E$341,"支援")>0,"○","")) | F19: =IF(COUNTIFS('VS×ケイパビリティ関係'!$F$4:$F$341,$B19,'VS×ケイパビリティ関係'!$G$4:$G$341,F$5,'VS×ケイパビリティ関係'!$E$4:$E$341,"主")>0,"●",IF(COUNTIFS('VS×ケイパビリティ関係'!$F$4:$F$341,$B19,'VS×ケイパビリティ関係'!$G$4:$G$341,F$5,'VS×ケイパビリティ関係'!$E$4:$E$341,"支援")>0,"○","")) | G19: =IF(COUNTIFS('VS×ケイパビリティ関係'!$F$4:$F$341,$B19,'VS×ケイパビリティ関係'!$G$4:$G$341,G$5,'VS×ケイパビリティ関係'!$E$4:$E$341,"主")>0,"●",IF(COUNTIFS('VS×ケイパビリティ関係'!$F$4:$F$341,$B19,'VS×ケイパビリティ関係'!$G$4:$G$341,G$5,'VS×ケイパビリティ関係'!$E$4:$E$341,"支援")>0,"○","")) | H19: =IF(COUNTIFS('VS×ケイパビリティ関係'!$F$4:$F$341,$B19,'VS×ケイパビリティ関係'!$G$4:$G$341,H$5,'VS×ケイパビリティ関係'!$E$4:$E$341,"主")>0,"●",IF(COUNTIFS('VS×ケイパビリティ関係'!$F$4:$F$341,$B19,'VS×ケイパビリティ関係'!$G$4:$G$341,H$5,'VS×ケイパビリティ関係'!$E$4:$E$341,"支援")>0,"○","")) | I19: =IF(COUNTIFS('VS×ケイパビリティ関係'!$F$4:$F$341,$B19,'VS×ケイパビリティ関係'!$G$4:$G$341,I$5,'VS×ケイパビリティ関係'!$E$4:$E$341,"主")>0,"●",IF(COUNTIFS('VS×ケイパビリティ関係'!$F$4:$F$341,$B19,'VS×ケイパビリティ関係'!$G$4:$G$341,I$5,'VS×ケイパビリティ関係'!$E$4:$E$341,"支援")>0,"○","")) | J19: =IF(COUNTIFS('VS×ケイパビリティ関係'!$F$4:$F$341,$B19,'VS×ケイパビリティ関係'!$G$4:$G$341,J$5,'VS×ケイパビリティ関係'!$E$4:$E$341,"主")>0,"●",IF(COUNTIFS('VS×ケイパビリティ関係'!$F$4:$F$341,$B19,'VS×ケイパビリティ関係'!$G$4:$G$341,J$5,'VS×ケイパビリティ関係'!$E$4:$E$341,"支援")>0,"○","")) | K19: =IF(COUNTIFS('VS×ケイパビリティ関係'!$F$4:$F$341,$B19,'VS×ケイパビリティ関係'!$G$4:$G$341,K$5,'VS×ケイパビリティ関係'!$E$4:$E$341,"主")>0,"●",IF(COUNTIFS('VS×ケイパビリティ関係'!$F$4:$F$341,$B19,'VS×ケイパビリティ関係'!$G$4:$G$341,K$5,'VS×ケイパビリティ関係'!$E$4:$E$341,"支援")>0,"○","")) | ... AE19: =IF(COUNTIFS('VS×ケイパビリティ関係'!$F$4:$F$341,$B19,'VS×ケイパビリティ関係'!$G$4:$G$341,AE$5,'VS×ケイパビリティ関係'!$E$4:$E$341,"主")>0,"●",IF(COUNTIFS('VS×ケイパビリティ関係'!$F$4:$F$341,$B19,'VS×ケイパビリティ関係'!$G$4:$G$341,AE$5,'VS×ケイパビリティ関係'!$E$4:$E$341,"支援")>0,"○","")) | AF19: =COUNTIF(D19:AE19,"●") | AG19: =COUNTIF(D19:AE19,"○")
B20: 04-03 | C20: 問題・変更管理 | D20: =IF(COUNTIFS('VS×ケイパビリティ関係'!$F$4:$F$341,$B20,'VS×ケイパビリティ関係'!$G$4:$G$341,D$5,'VS×ケイパビリティ関係'!$E$4:$E$341,"主")>0,"●",IF(COUNTIFS('VS×ケイパビリティ関係'!$F$4:$F$341,$B20,'VS×ケイパビリティ関係'!$G$4:$G$341,D$5,'VS×ケイパビリティ関係'!$E$4:$E$341,"支援")>0,"○","")) | E20: =IF(COUNTIFS('VS×ケイパビリティ関係'!$F$4:$F$341,$B20,'VS×ケイパビリティ関係'!$G$4:$G$341,E$5,'VS×ケイパビリティ関係'!$E$4:$E$341,"主")>0,"●",IF(COUNTIFS('VS×ケイパビリティ関係'!$F$4:$F$341,$B20,'VS×ケイパビリティ関係'!$G$4:$G$341,E$5,'VS×ケイパビリティ関係'!$E$4:$E$341,"支援")>0,"○","")) | F20: =IF(COUNTIFS('VS×ケイパビリティ関係'!$F$4:$F$341,$B20,'VS×ケイパビリティ関係'!$G$4:$G$341,F$5,'VS×ケイパビリティ関係'!$E$4:$E$341,"主")>0,"●",IF(COUNTIFS('VS×ケイパビリティ関係'!$F$4:$F$341,$B20,'VS×ケイパビリティ関係'!$G$4:$G$341,F$5,'VS×ケイパビリティ関係'!$E$4:$E$341,"支援")>0,"○","")) | G20: =IF(COUNTIFS('VS×ケイパビリティ関係'!$F$4:$F$341,$B20,'VS×ケイパビリティ関係'!$G$4:$G$341,G$5,'VS×ケイパビリティ関係'!$E$4:$E$341,"主")>0,"●",IF(COUNTIFS('VS×ケイパビリティ関係'!$F$4:$F$341,$B20,'VS×ケイパビリティ関係'!$G$4:$G$341,G$5,'VS×ケイパビリティ関係'!$E$4:$E$341,"支援")>0,"○","")) | H20: =IF(COUNTIFS('VS×ケイパビリティ関係'!$F$4:$F$341,$B20,'VS×ケイパビリティ関係'!$G$4:$G$341,H$5,'VS×ケイパビリティ関係'!$E$4:$E$341,"主")>0,"●",IF(COUNTIFS('VS×ケイパビリティ関係'!$F$4:$F$341,$B20,'VS×ケイパビリティ関係'!$G$4:$G$341,H$5,'VS×ケイパビリティ関係'!$E$4:$E$341,"支援")>0,"○","")) | I20: =IF(COUNTIFS('VS×ケイパビリティ関係'!$F$4:$F$341,$B20,'VS×ケイパビリティ関係'!$G$4:$G$341,I$5,'VS×ケイパビリティ関係'!$E$4:$E$341,"主")>0,"●",IF(COUNTIFS('VS×ケイパビリティ関係'!$F$4:$F$341,$B20,'VS×ケイパビリティ関係'!$G$4:$G$341,I$5,'VS×ケイパビリティ関係'!$E$4:$E$341,"支援")>0,"○","")) | J20: =IF(COUNTIFS('VS×ケイパビリティ関係'!$F$4:$F$341,$B20,'VS×ケイパビリティ関係'!$G$4:$G$341,J$5,'VS×ケイパビリティ関係'!$E$4:$E$341,"主")>0,"●",IF(COUNTIFS('VS×ケイパビリティ関係'!$F$4:$F$341,$B20,'VS×ケイパビリティ関係'!$G$4:$G$341,J$5,'VS×ケイパビリティ関係'!$E$4:$E$341,"支援")>0,"○","")) | K20: =IF(COUNTIFS('VS×ケイパビリティ関係'!$F$4:$F$341,$B20,'VS×ケイパビリティ関係'!$G$4:$G$341,K$5,'VS×ケイパビリティ関係'!$E$4:$E$341,"主")>0,"●",IF(COUNTIFS('VS×ケイパビリティ関係'!$F$4:$F$341,$B20,'VS×ケイパビリティ関係'!$G$4:$G$341,K$5,'VS×ケイパビリティ関係'!$E$4:$E$341,"支援")>0,"○","")) | ... AE20: =IF(COUNTIFS('VS×ケイパビリティ関係'!$F$4:$F$341,$B20,'VS×ケイパビリティ関係'!$G$4:$G$341,AE$5,'VS×ケイパビリティ関係'!$E$4:$E$341,"主")>0,"●",IF(COUNTIFS('VS×ケイパビリティ関係'!$F$4:$F$341,$B20,'VS×ケイパビリティ関係'!$G$4:$G$341,AE$5,'VS×ケイパビリティ関係'!$E$4:$E$341,"支援")>0,"○","")) | AF20: =COUNTIF(D20:AE20,"●") | AG20: =COUNTIF(D20:AE20,"○")
B21: 04-04 | C21: 定期評価・継続的改善 | D21: =IF(COUNTIFS('VS×ケイパビリティ関係'!$F$4:$F$341,$B21,'VS×ケイパビリティ関係'!$G$4:$G$341,D$5,'VS×ケイパビリティ関係'!$E$4:$E$341,"主")>0,"●",IF(COUNTIFS('VS×ケイパビリティ関係'!$F$4:$F$341,$B21,'VS×ケイパビリティ関係'!$G$4:$G$341,D$5,'VS×ケイパビリティ関係'!$E$4:$E$341,"支援")>0,"○","")) | E21: =IF(COUNTIFS('VS×ケイパビリティ関係'!$F$4:$F$341,$B21,'VS×ケイパビリティ関係'!$G$4:$G$341,E$5,'VS×ケイパビリティ関係'!$E$4:$E$341,"主")>0,"●",IF(COUNTIFS('VS×ケイパビリティ関係'!$F$4:$F$341,$B21,'VS×ケイパビリティ関係'!$G$4:$G$341,E$5,'VS×ケイパビリティ関係'!$E$4:$E$341,"支援")>0,"○","")) | F21: =IF(COUNTIFS('VS×ケイパビリティ関係'!$F$4:$F$341,$B21,'VS×ケイパビリティ関係'!$G$4:$G$341,F$5,'VS×ケイパビリティ関係'!$E$4:$E$341,"主")>0,"●",IF(COUNTIFS('VS×ケイパビリティ関係'!$F$4:$F$341,$B21,'VS×ケイパビリティ関係'!$G$4:$G$341,F$5,'VS×ケイパビリティ関係'!$E$4:$E$341,"支援")>0,"○","")) | G21: =IF(COUNTIFS('VS×ケイパビリティ関係'!$F$4:$F$341,$B21,'VS×ケイパビリティ関係'!$G$4:$G$341,G$5,'VS×ケイパビリティ関係'!$E$4:$E$341,"主")>0,"●",IF(COUNTIFS('VS×ケイパビリティ関係'!$F$4:$F$341,$B21,'VS×ケイパビリティ関係'!$G$4:$G$341,G$5,'VS×ケイパビリティ関係'!$E$4:$E$341,"支援")>0,"○","")) | H21: =IF(COUNTIFS('VS×ケイパビリティ関係'!$F$4:$F$341,$B21,'VS×ケイパビリティ関係'!$G$4:$G$341,H$5,'VS×ケイパビリティ関係'!$E$4:$E$341,"主")>0,"●",IF(COUNTIFS('VS×ケイパビリティ関係'!$F$4:$F$341,$B21,'VS×ケイパビリティ関係'!$G$4:$G$341,H$5,'VS×ケイパビリティ関係'!$E$4:$E$341,"支援")>0,"○","")) | I21: =IF(COUNTIFS('VS×ケイパビリティ関係'!$F$4:$F$341,$B21,'VS×ケイパビリティ関係'!$G$4:$G$341,I$5,'VS×ケイパビリティ関係'!$E$4:$E$341,"主")>0,"●",IF(COUNTIFS('VS×ケイパビリティ関係'!$F$4:$F$341,$B21,'VS×ケイパビリティ関係'!$G$4:$G$341,I$5,'VS×ケイパビリティ関係'!$E$4:$E$341,"支援")>0,"○","")) | J21: =IF(COUNTIFS('VS×ケイパビリティ関係'!$F$4:$F$341,$B21,'VS×ケイパビリティ関係'!$G$4:$G$341,J$5,'VS×ケイパビリティ関係'!$E$4:$E$341,"主")>0,"●",IF(COUNTIFS('VS×ケイパビリティ関係'!$F$4:$F$341,$B21,'VS×ケイパビリティ関係'!$G$4:$G$341,J$5,'VS×ケイパビリティ関係'!$E$4:$E$341,"支援")>0,"○","")) | K21: =IF(COUNTIFS('VS×ケイパビリティ関係'!$F$4:$F$341,$B21,'VS×ケイパビリティ関係'!$G$4:$G$341,K$5,'VS×ケイパビリティ関係'!$E$4:$E$341,"主")>0,"●",IF(COUNTIFS('VS×ケイパビリティ関係'!$F$4:$F$341,$B21,'VS×ケイパビリティ関係'!$G$4:$G$341,K$5,'VS×ケイパビリティ関係'!$E$4:$E$341,"支援")>0,"○","")) | ... AE21: =IF(COUNTIFS('VS×ケイパビリティ関係'!$F$4:$F$341,$B21,'VS×ケイパビリティ関係'!$G$4:$G$341,AE$5,'VS×ケイパビリティ関係'!$E$4:$E$341,"主")>0,"●",IF(COUNTIFS('VS×ケイパビリティ関係'!$F$4:$F$341,$B21,'VS×ケイパビリティ関係'!$G$4:$G$341,AE$5,'VS×ケイパビリティ関係'!$E$4:$E$341,"支援")>0,"○","")) | AF21: =COUNTIF(D21:AE21,"●") | AG21: =COUNTIF(D21:AE21,"○")

Sheet 情報オブジェクト
A1: 情報オブジェクト（正本：用語集と分類）
A2: 1行1オブジェクト。業務上ひとまとまりで管理される情報の単位（状態の違いは属性として扱う）。名称・分類・オーナーはこのシートで編集する。灰色の列は数式（編集しない）。GxP記録の対象：関連法令・規制にGxPを含むもの。ER/ES指針の要件（監査証跡・電子署名・保存）を満たすべき電子記録の候補。
A3: ID | B3: 領域 | C3: 情報オブジェクト | D3: 英語名 | E3: 説明 | F3: データ種別 | G3: 関連法令・規制 | H3: GxP記録 の対象 | I3: 個人情報 | J3: オーナー ケイパビリティL2 ID | K3: オーナー ケイパビリティL2 | L3: 作成する ケイパビリティL2の数 | M3: 利用する ケイパビリティL2の数
A4: MST-01 | B4: 共通・マスタ | C4: アプリケーション台帳 | D4: Application Inventory | E4: 全アプリケーションの名称・オーナー・GxP区分・ライフサイクルの状態・委託先 | F4: マスタ | G4: GxP | H4: =IF(ISNUMBER(SEARCH("GxP",G4)),"対象候補","—") | I4: なし | J4: C01-02 | K4: =IFERROR(INDEX(ケイパビリティマップ!$E:$E,MATCH(J4,ケイパビリティマップ!$A:$A,0)),"（IDなし）") | L4: =COUNTIF('ケイパビリティ×情報オブジェクト'!D$6:D$33,"C") | M4: =COUNTIF('ケイパビリティ×情報オブジェクト'!D$6:D$33,"R")
A5: MST-02 | B5: 共通・マスタ | C5: 構成情報 | D5: Configuration Item (CMDB) | E5: システムを構成するサーバー・ソフトウェア・設定・連携と、その関係 | F5: マスタ | G5: 金商法 | H5: =IF(ISNUMBER(SEARCH("GxP",G5)),"対象候補","—") | I5: なし | J5: C03-05 | K5: =IFERROR(INDEX(ケイパビリティマップ!$E:$E,MATCH(J5,ケイパビリティマップ!$A:$A,0)),"（IDなし）") | L5: =COUNTIF('ケイパビリティ×情報オブジェクト'!E$6:E$33,"C") | M5: =COUNTIF('ケイパビリティ×情報オブジェクト'!E$6:E$33,"R")
A6: MST-03 | B6: 共通・マスタ | C6: IT資産・ライセンス台帳 | D6: IT Asset & License Register | E6: 端末・機器の所在・利用者と、ソフトウェアライセンス・SaaSの契約・割当 | F6: マスタ | G6: なし | H6: =IF(ISNUMBER(SEARCH("GxP",G6)),"対象候補","—") | I6: 従業員 | J6: C04-04 | K6: =IFERROR(INDEX(ケイパビリティマップ!$E:$E,MATCH(J6,ケイパビリティマップ!$A:$A,0)),"（IDなし）") | L6: =COUNTIF('ケイパビリティ×情報オブジェクト'!F$6:F$33,"C") | M6: =COUNTIF('ケイパビリティ×情報オブジェクト'!F$6:F$33,"R")
A7: MST-04 | B7: 共通・マスタ | C7: ITサービスカタログ | D7: IT Service Catalog | E7: 提供するITサービスの内容・条件・申請方法・承認者 | F7: 定義・仕様 | G7: なし | H7: =IF(ISNUMBER(SEARCH("GxP",G7)),"対象候補","—") | I7: なし | J7: C03-01 | K7: =IFERROR(INDEX(ケイパビリティマップ!$E:$E,MATCH(J7,ケイパビリティマップ!$A:$A,0)),"（IDなし）") | L7: =COUNTIF('ケイパビリティ×情報オブジェクト'!G$6:G$33,"C") | M7: =COUNTIF('ケイパビリティ×情報オブジェクト'!G$6:G$33,"R")
A8: MST-05 | B8: 共通・マスタ | C8: ID・アカウント情報 | D8: Identity & Account | E8: 利用者のID・所属・雇用状態と、各システムのアカウント | F8: マスタ | G8: GxP・金商法 | H8: =IF(ISNUMBER(SEARCH("GxP",G8)),"対象候補","—") | I8: 従業員 | J8: C05-02 | K8: =IFERROR(INDEX(ケイパビリティマップ!$E:$E,MATCH(J8,ケイパビリティマップ!$A:$A,0)),"（IDなし）") | L8: =COUNTIF('ケイパビリティ×情報オブジェクト'!H$6:H$33,"C") | M8: =COUNTIF('ケイパビリティ×情報オブジェクト'!H$6:H$33,"R")
