Workbook

Sheet バリューストリーム
A1: バリューストリーム（L1〜L4）
A2: 対象：日本の事業会社（正社員中心、新卒・経験者採用、月給制）／日本の法令・制度基準（労基法・安衛法・社会保険・税法ほか）。1行1項目。L1〜L4列の●がその行のレベル。出口はL2、入力・出力情報・関連法令・主な関与者はL4の項目。 入力情報・出力情報はVS定義の過程で得られる正本（直接入力する）。情報オブジェクトはこれを取りまとめて一覧化したもの。★＝日本の制度・雇用慣行に固有の項目。
A3: ID | B3: L1 | C3: L2 | D3: L3 | E3: L4 | F3: VS項目名 | G3: VSの定義 | H3: 出口（ゲート） | I3: 入力情報 | J3: 出力情報 | K3: 関連法令 | L3: 主な関与者（社内／外部）
A4: VS | B4: ● | F4: Hire-to-Retire | G4: 事業に必要な人材を計画・採用し、入社から育成・評価・処遇・配置を経て退職まで、従業員の雇用ライフサイクル全体を通じて組織に能力を供給し、従業員の成長と働きがいを高める
A5: 01 | C5: ● | F5: 人員計画・採用 | G5: 事業計画から必要な人材を見定め、候補者を集めて公正に選考し、内定の承諾を得るまでの段階 | H5: 内定承諾
A6: 01-01 | D6: ● | F6: 人事戦略・要員計画 | G6: 経営戦略から人事戦略と要員計画を定め、人件費予算と採用計画に落とし込む
A7: 01-01-01 | E7: ● | F7: 人事戦略・人的資本KPIの設定 | I7: 人的資本開示情報 | J7: 人事戦略・人的資本KPI | K7: なし | L7: 経営・人事企画／—
A8: 01-01-02 | E8: ● | F8: 要員計画の策定（職種・等級・雇用形態別） | I8: 人事戦略・人的資本KPI、組織マスタ、従業員マスタ | J8: 要員計画 | K8: なし | L8: 人事企画・事業部門／—
A9: 01-01-03 | E9: ● | F9: 人件費予算の策定 | I9: 要員計画、報酬テーブル、人件費実績 | J9: 人件費予算 | K9: なし | L9: 人事企画・経理／—
A10: 01-01-04 | E10: ● | F10: 職務・ポジション要件の定義 | I10: 要員計画、職務・ポジション | J10: 職務・ポジション | K10: なし | L10: 人事・配属部門／—
A11: 01-01-05 | E11: ● | F11: 採用計画の策定（新卒・経験者別の人数・時期・チャネル） | I11: 要員計画、採用チャネル実績 | J11: 採用計画 | K11: なし | L11: 採用担当・事業部門／—
A12: 01-02 | D12: ● | F12: 母集団形成 | G12: 会社の魅力を発信し、求人を公開して、応募者を集める
A13: 01-02-01 | E13: ● | F13: 採用ブランディング・採用広報 | I13: 採用計画、人的資本開示情報 | J13: 求人票 | K13: 職安法 | L13: 採用・広報／採用媒体
A14: 01-02-02 | E14: ● | F14: ★求人票の作成・公開（業務・就業場所の変更の範囲を含む労働条件の明示） | I14: 職務・ポジション、就業規則・人事規程、報酬テーブル | J14: 求人票 | K14: 職安法 | L14: 採用／求人媒体、ハローワーク
A15: 01-02-03 | E15: ● | F15: ★インターンシップ・会社説明会の運営（新卒） | I15: 採用計画、求人票 | J15: 応募者情報 | K15: 職安法・個人情報保護法 | L15: 採用・現場社員／大学、就職情報会社
A16: 01-02-04 | E16: ● | F16: 人材紹介・リファラル・ダイレクトリクルーティングの活用（経験者） | I16: 求人票 | J16: 応募者情報、採用チャネル実績 | K16: 職安法・個人情報保護法 | L16: 採用・現場社員／人材紹介会社
A17: 01-03 | D17: ● | F17: 選考 | G17: 書類・適性検査・面接で、職務への適性と能力を公正に評価し、採否を決める
A18: 01-03-01 | E18: ● | F18: 書類選考（エントリーシート・職務経歴書） | I18: 応募者情報、職務・ポジション | J18: 選考記録 | K18: 職安法・個人情報保護法 | L18: 採用・面接官／—
A19: 01-03-02 | E19: ● | F19: 適性検査・面接の実施 | I19: 応募者情報、選考記録 | J19: 選考記録 | K19: 職安法 | L19: 面接官・採用／適性検査会社
A20: 01-03-03 | E20: ● | F20: ★公正な採用選考の点検（本人に責任のない事項・思想信条を選考に用いない） | I20: 選考記録 | J20: 選考記録 | K20: 職安法 | L20: 採用・面接官／—
A21: 01-03-04 | E21: ● | F21: 採否の判定 | I21: 選考記録、採用計画 | J21: 選考記録 | K21: なし | L21: 採用・部門長／—
A22: 01-04 | D22: ● | F22: 内定 | G22: 処遇条件を決めて内定を出し、承諾を得て入社まで関係を保つ
A23: 01-04-01 | E23: ● | F23: 処遇条件の決定・オファー提示 | I23: 選考記録、報酬テーブル、等級制度 | J23: 内定・オファー | K23: 職安法 | L23: 採用・人事企画／—
A24: 01-04-02 | E24: ● | F24: ★内定通知・内定承諾の取得（労働条件の明示を含む） | I24: 内定・オファー、就業規則・人事規程 | J24: 内定・オファー | K24: 職安法・労基法 | L24: 採用／—
A25: 01-04-03 | E25: ● | F25: ★内定者フォロー（内定式・内定者研修、辞退の防止） | I25: 内定・オファー、応募者情報 | J25: 内定・オファー | K25: なし | L25: 採用・現場社員／—
A26: 01-04-04 | E26: ● | F26: 不採用者への通知と応募者情報の返却・廃棄 | I26: 応募者情報、選考記録 | J26: 応募者情報 | K26: 個人情報保護法 | L26: 採用／—
A27: 01-04-05 | E27: ● | F27: 採用活動の振り返り（チャネル別の実績・コスト） | I27: 選考記録、採用計画、内定・オファー | J27: 採用チャネル実績 | K27: なし | L27: 採用／—
A28: 02 | C28: ● | F28: 入社・オンボーディング | G28: 雇用契約と入社手続きを完了し、受入れ・研修・定着支援を経て本採用に至るまでの段階 | H28: 本採用（試用期間終了）
A29: 02-01 | D29: ● | F29: 雇用契約・入社手続き | G29: 雇用契約を結び、入社書類・マイナンバー・社会保険の手続きと従業員情報の登録を行う
A30: 02-01-01 | E30: ● | F30: 雇用契約の締結・労働条件通知書の交付 | I30: 内定・オファー、就業規則・人事規程 | J30: 雇用契約 | K30: 労基法 | L30: 人事労務／—
A31: 02-01-02 | E31: ● | F31: 入社書類の回収（誓約書・身元保証書・扶養・通勤・口座） | I31: 雇用契約 | J31: 入社書類、源泉徴収・年末調整情報 | K31: 個人情報保護法・税法 | L31: 人事労務・入社者／—
A32: 02-01-03 | E32: ● | F32: ★マイナンバーの収集・本人確認 | I32: 入社書類 | J32: マイナンバー | K32: 番号法 | L32: 人事労務・入社者／—
A33: 02-01-04 | E33: ● | F33: 従業員情報の登録（社員番号・所属・等級）と労働者名簿の作成 | I33: 雇用契約、入社書類、組織マスタ | J33: 従業員マスタ、労働者名簿、異動・発令履歴 | K33: 労基法 | L33: 人事労務／—
A34: 02-01-05 | E34: ● | F34: ★社会保険・雇用保険の資格取得届（健保・厚年は5日以内、雇用保険は翌月10日まで） | I34: 従業員マスタ、マイナンバー、入社書類 | J34: 社会保険・雇用保険の資格情報 | K34: 社会保険・雇用保険 | L34: 人事労務／年金事務所、ハローワーク、健康保険組合
A35: 02-01-06 | E35: ● | F35: 給与・勤怠の初期設定（支給項目・通勤手当・勤務形態） | I35: 雇用契約、従業員マスタ、入社書類 | J35: 従業員マスタ、勤務予定・勤怠記録 | K35: 労基法 | L35: 人事労務／—
A36: 02-02 | D36: ● | F36: 受入れ準備 | G36: 配属先・貸与物・アカウントを整え、雇入時の健康診断と安全衛生教育を行う
A37: 02-02-01 | E37: ● | F37: 配属先の決定・受入れ準備 | I37: 要員計画、選考記録 | J37: 異動・発令履歴、オンボーディング計画 | K37: なし | L37: 人事・配属部門／—
A38: 02-02-02 | E38: ● | F38: PC・社員証などの貸与とアカウントの発行 | I38: 従業員マスタ | J38: 貸与物・アカウント記録 | K38: なし | L38: 人事・情報システム／—
A39: 02-02-03 | E39: ● | F39: ★雇入時の健康診断 | I39: 従業員マスタ | J39: 健康診断・面接指導記録 | K39: 安衛法 | L39: 人事・産業医／健診機関
A40: 02-02-04 | E40: ● | F40: ★雇入れ時の安全衛生教育 | I40: 育成体系・研修カタログ | J40: 受講記録 | K40: 安衛法 | L40: 人事・配属部門／—
...

Sheet ケイパビリティマップ
A1: ビジネス・ケイパビリティマップ（L1〜L3）
A2: 対象：日本の事業会社（正社員中心、新卒・経験者採用、月給制）／日本の法令・制度基準（労基法・安衛法・社会保険・税法ほか）。1行1項目。L1〜L3列の●がその行のレベル。区分はL1、範囲・アウトカムはL3の項目。★＝日本の制度・雇用慣行に固有、または特に強調する能力。
A3: ID | B3: L1 | C3: L2 | D3: L3 | E3: ケイパビリティ名 | F3: ケイパビリティの定義 | G3: 区分 | H3: 範囲（含む） | I3: 範囲（含まない） | J3: アウトカム
A4: C01 | B4: ● | E4: 人事戦略・組織設計 | F4: 経営戦略を人と組織の方針に落とし込み、要員・人件費・組織・等級の枠組みを定める能力 | G4: 戦略
A5: C01-01 | C5: ● | E5: 人事戦略・人的資本経営★ | F5: 経営戦略と連動した人事戦略と人的資本の指標を定め、人事制度・規程と開示を統制する
A6: C01-01-01 | D6: ● | E6: 人事戦略策定 | F6: 経営戦略・事業計画を受けて、人材・組織の方針と重点施策を定める | H6: 人材ポートフォリオの方針、重点施策、人的資本KPIの設定 | I6: 要員数の計画（C01-02-01） | J6: 経営戦略と連動した人事戦略
A7: C01-01-02 | D7: ● | E7: 人的資本情報の開示★ | F7: 有価証券報告書・統合報告書などで人的資本の方針・指標を開示する | H7: 人材育成方針・社内環境整備方針、指標と目標、女性管理職比率・男性育休取得率・男女賃金差異の開示 | I7: 女性活躍推進法の行動計画策定（C07-04-01） | J7: 投資家・求職者に信頼される人的資本の開示
A8: C01-01-03 | D8: ● | E8: 就業規則・人事規程管理★ | F8: 就業規則・人事規程を制定・改定し、労働基準監督署への届出と従業員への周知を行う | H8: 規程の起案・改定、過半数代表の意見聴取、届出、周知 | I8: 労使協定の締結（C06-03-01） | J8: 法令に適合し、周知された就業規則
A9: C01-02 | C9: ● | E9: 要員計画・人件費管理 | F9: 事業計画に必要な人員と人件費を計画し、実績を管理する
A10: C01-02-01 | D10: ● | E10: 要員計画策定 | F10: 事業計画から職種・等級・雇用区分別の必要人員と過不足を見積もる | H10: 必要人員の見積もり、過不足分析、採用・異動・育成での充足方針 | I10: 個々の採用計画（C02-01-01） | J10: 事業計画を実現できる要員計画
A11: C01-02-02 | D11: ● | E11: 人件費予算・実績管理 | F11: 人件費の予算を立て、給与計算の結果から実績を把握する | H11: 人件費予算、人件費の会計計上、予実管理 | I11: 給与計算そのもの（C05-03-01） | J11: 予算内に管理された人件費
A12: C01-02-03 | D12: ● | E12: 雇用形態ポートフォリオ管理 | F12: 正社員・有期契約・パートタイム・派遣・業務委託の構成を管理する | H12: 雇用形態別の構成、派遣受入れ期間の管理 | I12: 有期契約の更新手続き（C03-01-05） | J12: 事業に合った雇用形態の組み合わせ
A13: C01-03 | C13: ● | E13: 組織・職務設計 | F13: 組織構造・職務・等級の枠組みを設計する
A14: C01-03-01 | D14: ● | E14: 組織設計・組織改編 | F14: 組織構造を設計し、組織改編を計画・実施する | H14: 組織図、組織改編、組織コード | I14: 異動の発令（C07-01-02） | J14: 事業戦略に合った組織
A15: C01-03-02 | D15: ● | E15: 職務・ポジション定義 | F15: 職務の役割・責任・要件と、ポジション（定員）を定義する | H15: 職務記述書、ポジション管理、職務要件 | I15: スキル体系の定義（C04-02-01） | J15: 役割と要件が明確な職務
A16: C01-03-03 | D16: ● | E16: 等級制度設計 | F16: 職能・職務・役割などに基づく等級制度を設計・改定する | H16: 等級の定義、等級と報酬・評価の対応 | I16: 賃金テーブルの設計（C05-02-01） | J16: 期待役割が明確な等級制度
A17: C02 | B17: ● | E17: タレント獲得 | F17: 必要な人材を惹きつけ、公正に選考して採用する能力 | G17: コア
A18: C02-01 | C18: ● | E18: 採用計画・採用ブランディング | F18: 採用計画を立て、候補者に選ばれるための発信と採用チャネルを管理する
A19: C02-01-01 | D19: ● | E19: 採用計画策定 | F19: 要員計画から新卒・経験者別の採用人数・時期・予算を決める | H19: 採用人数・時期・予算、職種別の優先順位 | I19: 要員計画の策定（C01-02-01） | J19: 要員計画と整合した採用計画
A20: C02-01-02 | D20: ● | E20: 採用ブランディング・採用広報 | F20: 会社の魅力と働き方を候補者に伝える | H20: 採用サイト、SNS、説明会資料、社員の発信 | I20: 商品・企業広報 | J20: 候補者から選ばれる雇用主のブランド
A21: C02-01-03 | D21: ● | E21: 採用チャネル管理 | F21: 求人媒体・人材紹介・リファラル・ダイレクトリクルーティングを選び、実績を管理する | H21: チャネルの選定・契約、チャネル別の実績とコスト | I21: 個々の候補者の選考（C02-03-02） | J21: 費用対効果の高い採用チャネル
A22: C02-02 | C22: ● | E22: 新卒採用★ | F22: 学生を対象に、インターンシップから内定者フォローまでを一括して行う
A23: C02-02-01 | D23: ● | E23: インターンシップ・母集団形成★ | F23: インターンシップ・説明会で学生との接点をつくり、応募者を集める | H23: インターンシップ、会社説明会、大学との連携 | I23: 経験者向けの求人公開（C02-03-01） | J23: 質・量ともに十分な応募者
A24: C02-02-02 | D24: ● | E24: 新卒選考運営 | F24: エントリーシート・適性検査・面接で選考する | H24: ES、適性検査、グループ討議、面接 | I24: 採否の最終判定の基準づくり（C02-04-01） | J24: 基準に沿って選ばれた内定者
A25: C02-02-03 | D25: ● | E25: 内定者管理・フォロー★ | F25: 内定から入社までの関係を維持し、辞退を防ぐ | H25: 内定式、内定者研修、内定者との連絡 | I25: 入社後の研修（C03-02-01） | J25: 辞退が少なく、準備ができた入社者
A26: C02-03 | C26: ● | E26: 経験者採用 | F26: 職務に合った経験者を募集・選考し、条件を提示して採用する
A27: C02-03-01 | D27: ● | E27: 求人票作成・求人公開 | F27: 職務要件と労働条件を記載した求人票を作り、公開する | H27: 求人票、労働条件の明示、求人の公開 | I27: 労働条件通知書の交付（C03-01-01） | J27: 正確で魅力的な求人
A28: C02-03-02 | D28: ● | E28: 候補者選考・面接 | F28: 書類選考・適性検査・面接で候補者を評価し、採否を決める | H28: 書類選考、適性検査、面接、採否の判定 | I28: 新卒の選考（C02-02-02） | J28: 職務に合った候補者の選抜
A29: C02-03-03 | D29: ● | E29: 条件提示・オファー | F29: 処遇条件を決めてオファーを出し、承諾を得る | H29: 等級・報酬の決定、オファーレター、条件交渉 | I29: 賃金テーブルの設計（C05-02-01） | J29: 承諾されたオファー
A30: C02-04 | C30: ● | E30: 採用コンプライアンス★ | F30: 採用の過程で公正さと法令順守、応募者の個人情報の保護を確保する
A31: C02-04-01 | D31: ● | E31: 公正な採用選考★ | F31: 本人に責任のない事項や思想・信条などを選考に用いず、適性と能力で判断する | H31: 面接官研修、質問の禁止事項、選考基準の点検 | I31: 評価者研修（C05-01-02） | J31: 公正で説明できる選考
A32: C02-04-02 | D32: ● | E32: 労働条件の明示★ | F32: 求人・内定の時点で労働条件（業務・就業場所の変更の範囲等）を明示する | H32: 求人時・内定時の明示事項、変更時の明示 | I32: 雇用契約の締結（C03-01-01） | J32: 候補者が正しく理解した労働条件
A33: C02-04-03 | D33: ● | E33: 応募者個人情報管理 | F33: 応募者の個人情報を目的の範囲で扱い、不採用者の情報を返却・廃棄する | H33: 利用目的の通知、保管期間、返却・廃棄 | I33: 従業員の個人情報保護（C09-03-01） | J33: 漏えい・目的外利用のない応募者情報
A34: C03 | B34: ● | E34: 入社・雇用管理 | F34: 雇用契約を結び、入社手続きを行い、従業員の情報を正確に管理する能力 | G34: コア
A35: C03-01 | C35: ● | E35: 雇用契約・入社手続き★ | F35: 雇用契約の締結と、社会保険・税・マイナンバーの入社時手続きを行う
A36: C03-01-01 | D36: ● | E36: 雇用契約締結 | F36: 労働条件通知書を交付し、雇用契約を締結する | H36: 労働条件通知書、雇用契約書、電子契約 | I36: 求人時の労働条件の明示（C02-04-02） | J36: 双方が合意した雇用契約
A37: C03-01-02 | D37: ● | E37: 社会保険・雇用保険の資格取得★ | F37: 健康保険・厚生年金・雇用保険の資格取得届を期限内に提出する | H37: 資格取得届、被扶養者届、電子申請 | I37: 定例の届出（C05-04-01） | J37: 入社日から保険の資格がある従業員
A38: C03-01-03 | D38: ● | E38: マイナンバー収集・管理★ | F38: マイナンバーを本人確認とともに収集し、安全に管理する | H38: 利用目的の通知、本人確認、保管・廃棄 | I38: マイナンバーの安全管理措置全般（C09-03-01） | J38: 適法に収集・管理された特定個人情報
A39: C03-01-04 | D39: ● | E39: 入社書類管理 | F39: 誓約書・身元保証書・扶養情報などの入社書類を回収・確認する | H39: 書類の案内・回収・確認・保管 | I39: マイナンバーの収集（C03-01-03） | J39: 不備のない入社書類
A40: C03-01-05 | D40: ● | E40: 有期契約の更新・無期転換★ | F40: 有期労働契約の更新・雇止めと、無期転換の申込みを管理する | H40: 契約期間・更新上限の管理、無期転換の申込権の通知 | I40: 定年後の再雇用（C08-02-02） | J40: 紛争のない契約更新と無期転換
...

Sheet ケイパビリティレベル
A1: ケイパビリティの成熟度レベル（L2ごとの定義）
A2: 対象：日本の事業会社（正社員中心、新卒・経験者採用、月給制）／日本の法令・制度基準（労基法・安衛法・社会保険・税法ほか）。評価の対象はL2。法令上の最低水準：労働法令・社会保険・税などの法令順守が関わるL2はレベル3が事実上の最低水準。
A3: レベル | B3: 名称 | C3: 共通定義
A4: 1 | B4: 初期 | C4: 属人的・場当たり的。成果が個人に依存し、再現できない
A5: 2 | B5: 管理された | C5: 部門・拠点ごとに計画・管理され、再現できる。ただし方法は部門・拠点で異なる
A6: 3 | B6: 定義された | C6: 全社標準のプロセス・役割・データ定義があり、一貫して運用される
A7: 4 | B7: 定量的に管理された | C7: 指標で成果・品質を測定し、データに基づいて管理・予測する
A8: 5 | B8: 最適化された | C8: 継続的な改善と先進的な手法により、変化に先回りし、先進的な水準にある
A10: L2 ID | B10: ケイパビリティL1 | C10: ケイパビリティL2 | D10: 法令上の最低水準 | E10: レベル1 初期 | F10: レベル2 管理された | G10: レベル3 定義された | H10: レベル4 定量的に管理された | I10: レベル5 最適化された
A11: C01-01 | B11: 人事戦略・組織設計 | C11: 人事戦略・人的資本経営★ | D11: レベル3（労基法・金商法） | E11: 人事方針が明文化されておらず、施策が場当たり的 | F11: 人事施策ごとに方針を定めるが、経営戦略との結びつきが弱い | G11: 経営戦略と連動した人事戦略・人的資本KPIを定め、規程と開示を全社で一貫して管理する | H11: 人的資本KPIを定期的に測定し、戦略の達成度に基づいて施策を見直す | I11: 人的資本の投資対効果を分析し、経営の意思決定に人事の視点を先回りして組み込む
A12: C01-02 | C12: 要員計画・人件費管理 | D12: — | E12: 要員・人件費の計画がなく、欠員が出てから補充する | F12: 部門ごとに要員・人件費の計画を立てるが、方法がばらばら | G12: 全社共通の方法で雇用区分別の要員計画と人件費予算を立て、実績と比較する | H12: 要員・人件費の予実差を指標で管理し、先行して計画を修正する | I12: 事業シナリオに応じた人員構成をシミュレーションし、先回りして人材を確保する
A13: C01-03 | C13: 組織・職務設計 | D13: — | E13: 組織・職務の定義がなく、担当者が口頭で運用する | F13: 組織図と職務記述を部門ごとに作成する | G13: 全社標準の組織・職務・等級の定義を持ち、変更を一元管理する | H13: 組織・職務の変更の効果（スパン・コスト等）を指標で評価する | I13: 事業の変化に先回りして、組織と職務を柔軟に組み替える
A14: C02-01 | B14: タレント獲得 | C14: 採用計画・採用ブランディング | D14: — | E14: 欠員が出てから場当たり的に募集する | F14: 年度ごとに採用計画を立てるが、チャネルの効果を振り返らない | G14: 全社標準の採用計画・チャネル管理・採用広報の仕組みを持つ | H14: チャネル別の応募・内定・定着・コストを指標で管理し、配分を最適化する | I14: 採用市場の変化に先回りし、候補者との長期的な関係を築く
A15: C02-02 | C15: 新卒採用★ | D15: レベル3（職安法） | E15: 採用担当者の経験に頼って選考する | F15: 年度ごとの採用スケジュールと選考基準がある | G15: 全社標準の選考基準・スケジュール・内定者フォローの仕組みを持つ | H15: 選考段階別の歩留まりと入社後の活躍・定着を指標で検証する | I15: 入社後の活躍データを選考に反映し、採用手法を先回りして改善する
A16: C02-03 | C16: 経験者採用 | D16: レベル3（職安法） | E16: 部門の個別判断で募集・選考する | F16: 募集ポジションごとに要件と選考手順を定める | G16: 全社標準の求人・選考・オファーの手順と面接官の基準を持つ | H16: 採用までの期間・内定承諾率・入社後の評価を指標で管理する | I16: 外部人材市場の動きに先回りして、候補者プールを常に維持する
A17: C02-04 | C17: 採用コンプライアンス★ | D17: レベル3（職安法・個人情報保護法） | E17: 面接官が質問してはいけない事項を知らない | F17: 採用担当者が法令を理解しているが、面接官への徹底は不十分 | G17: 公正採用の基準・面接官研修・応募者情報の取扱いルールを全社で運用する | H17: 違反の兆候や応募者からの苦情を指標で監視し、再発を防ぐ | I17: 採用のAI活用などの新しい手法についても、公正さを先回りして評価する
A18: C03-01 | B18: 入社・雇用管理 | C18: 雇用契約・入社手続き★ | D18: レベル3（労基法・社会保険・番号法） | E18: 手続きが担当者の記憶頼りで、届出の漏れ・遅れがある | F18: チェックリストで手続きを管理する | G18: 全社標準の手続きと電子申請で、期限内に確実に処理する | H18: 手続きのリードタイムと誤りを指標で管理する | I18: 入社前から自動で手続きが進み、従業員の手間を最小にする
A19: C03-02 | C19: オンボーディング | D19: — | E19: 受入れが配属先任せで、立ち上がりに差がある | F19: 入社時研修と受入れの手順がある | G19: 全社標準のオンボーディング計画（研修・メンター・面談）を運用する | H19: 立ち上がりの期間と早期離職率を指標で管理する | I19: 入社者の経験データから、一人ひとりに合った受入れを先回りして設計する
A20: C03-03 | C20: 従業員情報管理★ | D20: レベル3（労基法） | E20: 従業員情報が部門やファイルごとに分散している | F20: 人事部門が台帳で従業員情報を管理する | G20: 人事システムで従業員情報を一元管理し、法定帳簿を整える | H20: データの正確さ・更新の遅れを指標で管理する | I20: 従業員情報を全社の意思決定の基盤として活用する
A21: C04-01 | B21: 人材育成・能力開発 | C21: 育成体系・研修管理 | D21: — | E21: 研修が単発で、体系がない | F21: 部門ごとに研修を企画・実施する | G21: 全社の育成体系（階層別・職種別）に沿って研修を計画・運営し、記録する | H21: 研修の受講率・効果・費用を指標で管理する | I21: 事業と人材の変化に先回りして、学びの仕組みを組み替える
A22: C04-02 | C22: スキル・資格管理 | D22: — | E22: 誰がどのスキルを持つか把握していない | F22: 部門ごとにスキル表を作る | G22: 全社共通のスキル体系で、スキルと資格を一元管理する | H22: スキルの過不足を指標で管理し、育成・採用の計画に反映する | I22: 将来必要なスキルを先回りして特定し、計画的に獲得する
A23: C04-03 | C23: キャリア開発支援 | D23: — | E23: キャリアは会社任せで、本人の希望を聞かない | F23: 自己申告制度があるが、活用が限られる | G23: キャリア面談・キャリア研修・自己啓発支援を全社で運用する | H23: キャリアの希望と配置の実現度を指標で管理する | I23: 社内外の機会を先回りして示し、自律的なキャリアを後押しする
A24: C04-04 | C24: 法定・コンプライアンス教育 | D24: レベル3（安衛法・労働施策総合推進法） | E24: 教育の対象者・記録が不明確 | F24: 部門ごとに必要な教育を実施する | G24: 対象者・頻度・記録を定めて、全社で確実に実施する | H24: 受講率と違反・事故の発生を指標で管理する | I24: 新しいリスクに先回りして教育内容を更新する
A25: C05-01 | B25: パフォーマンス・報酬管理 | C25: 目標・評価管理 | D25: — | E25: 評価基準がなく、上司の主観で決まる | F25: 部門ごとに評価の方法と時期を決める | G25: 全社標準の目標設定・評価・調整・フィードバックの仕組みを運用する | H25: 評価の分布・納得度を指標で管理し、評価の質を改善する | I25: 継続的なフィードバックで、成長と成果を同時に高める
A26: C05-02 | C26: 報酬制度・報酬決定 | D26: レベル3（最低賃金法・パート有期法） | E26: 報酬が個別交渉や慣行で決まる | F26: 賃金テーブルがあるが、見直しが不定期 | G26: 全社標準の報酬制度で、評価と連動した昇給・賞与を決める | H26: 市場水準・社内の公平性（同一労働同一賃金、男女差異）を指標で管理する | I26: 人材戦略に合わせて報酬を先回りして設計し、競争力を保つ
A27: C05-03 | C27: 給与計算・支払★ | D27: レベル3（労基法・税法） | E27: 手計算が多く、誤りが起きる | F27: 給与システムで計算するが、確認が人手に頼る | G27: 全社標準の手順とシステムで、正確に期日どおり支払う | H27: 誤りの件数と処理時間を指標で管理する | I27: 勤怠から支払・会計まで自動でつながり、誤りが起きない
A28: C05-04 | C28: 社会保険・福利厚生 | D28: レベル3（社会保険・雇用保険） | E28: 届出が遅れ、保険料の誤りが起きる | F28: 年間の手続きカレンダーで管理する | G28: 全社標準の手続きと電子申請で、定例の届出を確実に行う | H28: 届出の誤り・遅れと福利厚生の利用率を指標で管理する | I28: 従業員のニーズに先回りして、福利厚生を設計し直す
A29: C06-01 | B29: 就業・労務管理 | C29: 勤怠・休暇管理★ | D29: レベル3（労基法・安衛法・育介法） | E29: 労働時間を自己申告だけで把握している | F29: 勤怠システムで記録するが、上限の管理が事後になる | G29: 客観的な記録と、36協定の上限・有給休暇の取得義務を全社で管理する | H29: 長時間労働・休暇取得を指標で監視し、事前に手を打つ | I29: 働き方のデータから、業務と人員配置を先回りして見直す
A30: C06-02 | C30: 健康・安全管理★ | D30: レベル3（安衛法） | E30: 健康診断の実施・事後措置が不十分 | F30: 健康診断は実施するが、事後措置が拠点任せ | G30: 健康診断・ストレスチェック・面接指導・労災対応を全社標準で運用する | H30: 受診率・有所見率・休業災害を指標で管理する | I30: 健康データを活用し、不調や災害を先回りして防ぐ
A31: C06-03 | C31: 労使関係・従業員対応 | D31: レベル3（労基法・労働施策総合推進法） | E31: 相談窓口がなく、問題が表に出ない | F31: 相談窓口はあるが、対応が担当者任せ | G31: 労使協議・相談対応・懲戒の手順を全社で定め、公正に運用する | H31: 相談件数・対応期間・再発を指標で管理する | I31: 従業員の声から問題を先回りして見つけ、制度を改善する
A32: C06-04 | C32: エンゲージメント・働き方 | D32: — | E32: 従業員の声を聞く仕組みがない | F32: 不定期に満足度調査を行う | G32: 定期的なエンゲージメント調査と改善、柔軟な働き方の制度を全社で運用する | H32: エンゲージメントと離職・生産性の関係を指標で分析する | I32: データに基づいて職場ごとに先回りして改善する
A33: C07-01 | B33: タレントマネジメント・配置 | C33: タレントレビュー・配置 | D33: — | E33: 異動が上司の個人的な判断で決まる | F33: 部門ごとに人材の見極めと異動を行う | G33: 全社共通のタレントレビューと異動のルールで配置を決める | H33: 配置後の活躍・定着を指標で検証する | I33: 本人のキャリア希望と事業ニーズを先回りして組み合わせる
A34: C07-02 | C34: 昇格・登用 | D34: — | E34: 昇格が年功や上司の推薦だけで決まる | F34: 昇格の基準があるが、運用が部門ごと | G34: 全社共通の昇格基準・審査（試験・アセスメント）で決める | H34: 昇格者の登用後の活躍を指標で検証する | I34: 将来の役割から逆算して、登用を先回りして計画する
A35: C07-03 | C35: 後継者・リーダー育成 | D35: — | E35: 後継者を決めていない | F35: 一部の役員ポストについて後継者を検討する | G35: 重要ポストの後継者計画と選抜型育成を全社で運用する | H35: 後継者の準備度とポストの充足率を指標で管理する | I35: 経営環境に先回りして、リーダー層を計画的に厚くする
A36: C07-04 | C36: 多様な人材の活躍推進★ | D36: レベル3（女性活躍推進法・障害者雇用促進法・高年法） | E36: 法定の計画・報告が期限直前の対応になる | F36: 法定の計画・報告は行うが、施策が限られる | G36: 行動計画・雇用率・情報公表を全社で管理し、施策を実行する | H36: 多様性の指標と目標の達成度を管理する | I36: 多様性を事業の強みとして先回りして生かす
A37: C08-01 | B37: 退職・雇用終了 | C37: 退職手続き★ | D37: レベル3（労基法・社会保険・税法） | E37: 手続きの漏れや書類の交付遅れがある | F37: チェックリストで手続きを管理する | G37: 全社標準の手続きと電子申請で、期限内に確実に処理する | H37: 手続きの期間・誤りを指標で管理する | I37: 退職の申出から手続きまで自動でつながる
A38: C08-02 | C38: 定年・再雇用★ | D38: レベル3（高年法） | E38: 定年到達者の把握が遅れる | F38: 定年到達者ごとに再雇用を個別に判断する | G38: 全社標準の手順で意向確認・再雇用契約・処遇を決める | H38: 再雇用者の活躍と処遇の納得度を指標で管理する | I38: 年齢に関係なく役割で処遇する仕組みに先回りして移行する
A39: C08-03 | C39: オフボーディング | D39: — | E39: 引継ぎやアカウント停止が漏れる | F39: 退職時チェックリストで管理する | G39: 全社標準のオフボーディングで、引継ぎ・返却・停止を確実に行う | H39: 離職理由を分析し、定着策に反映する | I39: アルムナイとの関係を生かして、再入社や協業につなげる
A40: C09-01 | B40: 人事基盤 | C40: 人事データ・分析 | D40: — | E40: 人事データの集計が手作業で、時間がかかる | F40: 定型のレポートを定期的に作成する | G40: 全社共通の定義で人事データを集約し、ダッシュボードで提供する | H40: 指標の予測・要因分析で施策の効果を検証する | I40: データに基づく人事判断が組織の標準になっている
A41: C09-02 | C41: 人事サービス提供 | D41: — | E41: 問い合わせが担当者個人に集中する | F41: 問い合わせ窓口を設けている | G41: 人事ポータル・セルフサービス・問い合わせ管理を全社で運用する | H41: 問い合わせの件数・解決時間・満足度を指標で管理する | I41: 問い合わせを先回りして減らすよう、制度と情報提供を改善する
...

Sheet VS×ケイパビリティ関係
A1: VS×ケイパビリティ関係（正本：VS L4 × ケイパビリティL3）
A2: 1行1関係。区分は「主」（そのL4の中核）か「支援」（下支え）。マトリクスはこのシートから数式で集計する。関係の追加・変更はこのシートで行う。灰色の列は数式（編集しない）。
A3: VS L4 ID | B3: VS L4 | C3: ケイパビリティL3 ID | D3: ケイパビリティL3 | E3: 区分 | F3: VS L3 ID | G3: ケイパビリティL2 ID
A4: 01-01-01 | B4: 人事戦略・人的資本KPIの設定 | C4: C01-01-01 | D4: =IFERROR(INDEX(ケイパビリティマップ!$E:$E,MATCH(C4,ケイパビリティマップ!$A:$A,0)),"（IDなし）") | E4: 主 | F4: =LEFT(A4,5) | G4: =LEFT(C4,6)
A5: 01-01-02 | B5: 要員計画の策定（職種・等級・雇用形態別） | C5: C01-02-01 | D5: =IFERROR(INDEX(ケイパビリティマップ!$E:$E,MATCH(C5,ケイパビリティマップ!$A:$A,0)),"（IDなし）") | E5: 主 | F5: =LEFT(A5,5) | G5: =LEFT(C5,6)
A6: 01-01-02 | B6: 要員計画の策定（職種・等級・雇用形態別） | C6: C01-02-03 | D6: =IFERROR(INDEX(ケイパビリティマップ!$E:$E,MATCH(C6,ケイパビリティマップ!$A:$A,0)),"（IDなし）") | E6: 支援 | F6: =LEFT(A6,5) | G6: =LEFT(C6,6)
A7: 01-01-03 | B7: 人件費予算の策定 | C7: C01-02-02 | D7: =IFERROR(INDEX(ケイパビリティマップ!$E:$E,MATCH(C7,ケイパビリティマップ!$A:$A,0)),"（IDなし）") | E7: 主 | F7: =LEFT(A7,5) | G7: =LEFT(C7,6)
A8: 01-01-04 | B8: 職務・ポジション要件の定義 | C8: C01-03-02 | D8: =IFERROR(INDEX(ケイパビリティマップ!$E:$E,MATCH(C8,ケイパビリティマップ!$A:$A,0)),"（IDなし）") | E8: 主 | F8: =LEFT(A8,5) | G8: =LEFT(C8,6)
A9: 01-01-05 | B9: 採用計画の策定（新卒・経験者別の人数・時期・チャネル） | C9: C02-01-01 | D9: =IFERROR(INDEX(ケイパビリティマップ!$E:$E,MATCH(C9,ケイパビリティマップ!$A:$A,0)),"（IDなし）") | E9: 主 | F9: =LEFT(A9,5) | G9: =LEFT(C9,6)
A10: 01-01-05 | B10: 採用計画の策定（新卒・経験者別の人数・時期・チャネル） | C10: C02-01-03 | D10: =IFERROR(INDEX(ケイパビリティマップ!$E:$E,MATCH(C10,ケイパビリティマップ!$A:$A,0)),"（IDなし）") | E10: 支援 | F10: =LEFT(A10,5) | G10: =LEFT(C10,6)
A11: 01-02-01 | B11: 採用ブランディング・採用広報 | C11: C02-01-02 | D11: =IFERROR(INDEX(ケイパビリティマップ!$E:$E,MATCH(C11,ケイパビリティマップ!$A:$A,0)),"（IDなし）") | E11: 主 | F11: =LEFT(A11,5) | G11: =LEFT(C11,6)
A12: 01-02-02 | B12: ★求人票の作成・公開（業務・就業場所の変更の範囲を含む労働条件の明示） | C12: C02-03-01 | D12: =IFERROR(INDEX(ケイパビリティマップ!$E:$E,MATCH(C12,ケイパビリティマップ!$A:$A,0)),"（IDなし）") | E12: 主 | F12: =LEFT(A12,5) | G12: =LEFT(C12,6)
A13: 01-02-02 | B13: ★求人票の作成・公開（業務・就業場所の変更の範囲を含む労働条件の明示） | C13: C02-04-02 | D13: =IFERROR(INDEX(ケイパビリティマップ!$E:$E,MATCH(C13,ケイパビリティマップ!$A:$A,0)),"（IDなし）") | E13: 支援 | F13: =LEFT(A13,5) | G13: =LEFT(C13,6)
A14: 01-02-03 | B14: ★インターンシップ・会社説明会の運営（新卒） | C14: C02-02-01 | D14: =IFERROR(INDEX(ケイパビリティマップ!$E:$E,MATCH(C14,ケイパビリティマップ!$A:$A,0)),"（IDなし）") | E14: 主 | F14: =LEFT(A14,5) | G14: =LEFT(C14,6)
A15: 01-02-03 | B15: ★インターンシップ・会社説明会の運営（新卒） | C15: C02-04-03 | D15: =IFERROR(INDEX(ケイパビリティマップ!$E:$E,MATCH(C15,ケイパビリティマップ!$A:$A,0)),"（IDなし）") | E15: 支援 | F15: =LEFT(A15,5) | G15: =LEFT(C15,6)
... A170: 06-04-05 | B170: 離職分析とアルムナイ・ネットワークの運営 | C170: C08-03-04 | D170: =IFERROR(INDEX(ケイパビリティマップ!$E:$E,MATCH(C170,ケイパビリティマップ!$A:$A,0)),"（IDなし）") | E170: 主 | F170: =LEFT(A170,5) | G170: =LEFT(C170,6)
D171: =IF(C171="","",IFERROR(INDEX(ケイパビリティマップ!$E:$E,MATCH(C171,ケイパビリティマップ!$A:$A,0)),"（IDなし）")) | F171: =IF(A171="","",LEFT(A171,5)) | G171: =IF(C171="","",LEFT(C171,6))
D172: =IF(C172="","",IFERROR(INDEX(ケイパビリティマップ!$E:$E,MATCH(C172,ケイパビリティマップ!$A:$A,0)),"（IDなし）")) | F172: =IF(A172="","",LEFT(A172,5)) | G172: =IF(C172="","",LEFT(C172,6))
D173: =IF(C173="","",IFERROR(INDEX(ケイパビリティマップ!$E:$E,MATCH(C173,ケイパビリティマップ!$A:$A,0)),"（IDなし）")) | F173: =IF(A173="","",LEFT(A173,5)) | G173: =IF(C173="","",LEFT(C173,6))
D174: =IF(C174="","",IFERROR(INDEX(ケイパビリティマップ!$E:$E,MATCH(C174,ケイパビリティマップ!$A:$A,0)),"（IDなし）")) | F174: =IF(A174="","",LEFT(A174,5)) | G174: =IF(C174="","",LEFT(C174,6))
D175: =IF(C175="","",IFERROR(INDEX(ケイパビリティマップ!$E:$E,MATCH(C175,ケイパビリティマップ!$A:$A,0)),"（IDなし）")) | F175: =IF(A175="","",LEFT(A175,5)) | G175: =IF(C175="","",LEFT(C175,6))
D176: =IF(C176="","",IFERROR(INDEX(ケイパビリティマップ!$E:$E,MATCH(C176,ケイパビリティマップ!$A:$A,0)),"（IDなし）")) | F176: =IF(A176="","",LEFT(A176,5)) | G176: =IF(C176="","",LEFT(C176,6))
D177: =IF(C177="","",IFERROR(INDEX(ケイパビリティマップ!$E:$E,MATCH(C177,ケイパビリティマップ!$A:$A,0)),"（IDなし）")) | F177: =IF(A177="","",LEFT(A177,5)) | G177: =IF(C177="","",LEFT(C177,6))
D178: =IF(C178="","",IFERROR(INDEX(ケイパビリティマップ!$E:$E,MATCH(C178,ケイパビリティマップ!$A:$A,0)),"（IDなし）")) | F178: =IF(A178="","",LEFT(A178,5)) | G178: =IF(C178="","",LEFT(C178,6))
D179: =IF(C179="","",IFERROR(INDEX(ケイパビリティマップ!$E:$E,MATCH(C179,ケイパビリティマップ!$A:$A,0)),"（IDなし）")) | F179: =IF(A179="","",LEFT(A179,5)) | G179: =IF(C179="","",LEFT(C179,6))
D180: =IF(C180="","",IFERROR(INDEX(ケイパビリティマップ!$E:$E,MATCH(C180,ケイパビリティマップ!$A:$A,0)),"（IDなし）")) | F180: =IF(A180="","",LEFT(A180,5)) | G180: =IF(C180="","",LEFT(C180,6))
D181: =IF(C181="","",IFERROR(INDEX(ケイパビリティマップ!$E:$E,MATCH(C181,ケイパビリティマップ!$A:$A,0)),"（IDなし）")) | F181: =IF(A181="","",LEFT(A181,5)) | G181: =IF(C181="","",LEFT(C181,6))
D182: =IF(C182="","",IFERROR(INDEX(ケイパビリティマップ!$E:$E,MATCH(C182,ケイパビリティマップ!$A:$A,0)),"（IDなし）")) | F182: =IF(A182="","",LEFT(A182,5)) | G182: =IF(C182="","",LEFT(C182,6))
... D370: =IF(C370="","",IFERROR(INDEX(ケイパビリティマップ!$E:$E,MATCH(C370,ケイパビリティマップ!$A:$A,0)),"（IDなし）")) | F370: =IF(A370="","",LEFT(A370,5)) | G370: =IF(C370="","",LEFT(C370,6))

Sheet VS×ケイパビリティ
A1: バリューストリーム×ケイパビリティマップ（行：バリューストリームL3 × 列：ケイパビリティL2）
A2: ●＝主（配下のL4×L3の関係に「主」が1つ以上） ○＝支援のみ 空欄＝関係なし。各セルは「VS×ケイパビリティ関係」シートから数式で集計（直接入力しない）。
A4: VS L2 | B4: L3 ID | C4: VS L3 | D4: C01 人事戦略・組織設計 | G4: C02 タレント獲得 | K4: C03 入社・雇用管理 | N4: C04 人材育成・能力開発 | R4: C05 パフォーマンス・報酬管理 | V4: C06 就業・労務管理 | Z4: C07 タレントマネジメント・配置 | AD4: C08 退職・雇用終了 | AG4: C09 人事基盤 | AJ4: ●の数 | AK4: ○の数
D5: C01-01 | E5: C01-02 | F5: C01-03 | G5: C02-01 | H5: C02-02 | I5: C02-03 | J5: C02-04 | K5: C03-01 | L5: C03-02 | M5: C03-03 | N5: C04-01 | O5: C04-02 | P5: C04-03 | Q5: C04-04 | R5: C05-01 | S5: C05-02 | T5: C05-03 | U5: C05-04 | V5: C06-01 | W5: C06-02 | X5: C06-03 | Y5: C06-04 | Z5: C07-01 | AA5: C07-02 | AB5: C07-03 | AC5: C07-04 | AD5: C08-01 | AE5: C08-02 | AF5: C08-03 | AG5: C09-01 | AH5: C09-02 | AI5: C09-03
D6: 人事戦略・人的資本経営★ | E6: 要員計画・人件費管理 | F6: 組織・職務設計 | G6: 採用計画・採用ブランディング | H6: 新卒採用★ | I6: 経験者採用 | J6: 採用コンプライアンス★ | K6: 雇用契約・入社手続き★ | L6: オンボーディング | M6: 従業員情報管理★ | N6: 育成体系・研修管理 | O6: スキル・資格管理 | P6: キャリア開発支援 | Q6: 法定・コンプライアンス教育 | R6: 目標・評価管理 | S6: 報酬制度・報酬決定 | T6: 給与計算・支払★ | U6: 社会保険・福利厚生 | V6: 勤怠・休暇管理★ | W6: 健康・安全管理★ | X6: 労使関係・従業員対応 | Y6: エンゲージメント・働き方 | Z6: タレントレビュー・配置 | AA6: 昇格・登用 | AB6: 後継者・リーダー育成 | AC6: 多様な人材の活躍推進★ | AD6: 退職手続き★ | AE6: 定年・再雇用★ | AF6: オフボーディング | AG6: 人事データ・分析 | AH6: 人事サービス提供 | AI6: 人事情報セキュリティ・個人情報保護★
A7: 01 人員計画・採用 | B7: 01-01 | C7: 人事戦略・要員計画 | D7: =IF(COUNTIFS('VS×ケイパビリティ関係'!$F$4:$F$370,$B7,'VS×ケイパビリティ関係'!$G$4:$G$370,D$5,'VS×ケイパビリティ関係'!$E$4:$E$370,"主")>0,"●",IF(COUNTIFS('VS×ケイパビリティ関係'!$F$4:$F$370,$B7,'VS×ケイパビリティ関係'!$G$4:$G$370,D$5,'VS×ケイパビリティ関係'!$E$4:$E$370,"支援")>0,"○","")) | E7: =IF(COUNTIFS('VS×ケイパビリティ関係'!$F$4:$F$370,$B7,'VS×ケイパビリティ関係'!$G$4:$G$370,E$5,'VS×ケイパビリティ関係'!$E$4:$E$370,"主")>0,"●",IF(COUNTIFS('VS×ケイパビリティ関係'!$F$4:$F$370,$B7,'VS×ケイパビリティ関係'!$G$4:$G$370,E$5,'VS×ケイパビリティ関係'!$E$4:$E$370,"支援")>0,"○","")) | F7: =IF(COUNTIFS('VS×ケイパビリティ関係'!$F$4:$F$370,$B7,'VS×ケイパビリティ関係'!$G$4:$G$370,F$5,'VS×ケイパビリティ関係'!$E$4:$E$370,"主")>0,"●",IF(COUNTIFS('VS×ケイパビリティ関係'!$F$4:$F$370,$B7,'VS×ケイパビリティ関係'!$G$4:$G$370,F$5,'VS×ケイパビリティ関係'!$E$4:$E$370,"支援")>0,"○","")) | G7: =IF(COUNTIFS('VS×ケイパビリティ関係'!$F$4:$F$370,$B7,'VS×ケイパビリティ関係'!$G$4:$G$370,G$5,'VS×ケイパビリティ関係'!$E$4:$E$370,"主")>0,"●",IF(COUNTIFS('VS×ケイパビリティ関係'!$F$4:$F$370,$B7,'VS×ケイパビリティ関係'!$G$4:$G$370,G$5,'VS×ケイパビリティ関係'!$E$4:$E$370,"支援")>0,"○","")) | H7: =IF(COUNTIFS('VS×ケイパビリティ関係'!$F$4:$F$370,$B7,'VS×ケイパビリティ関係'!$G$4:$G$370,H$5,'VS×ケイパビリティ関係'!$E$4:$E$370,"主")>0,"●",IF(COUNTIFS('VS×ケイパビリティ関係'!$F$4:$F$370,$B7,'VS×ケイパビリティ関係'!$G$4:$G$370,H$5,'VS×ケイパビリティ関係'!$E$4:$E$370,"支援")>0,"○","")) | I7: =IF(COUNTIFS('VS×ケイパビリティ関係'!$F$4:$F$370,$B7,'VS×ケイパビリティ関係'!$G$4:$G$370,I$5,'VS×ケイパビリティ関係'!$E$4:$E$370,"主")>0,"●",IF(COUNTIFS('VS×ケイパビリティ関係'!$F$4:$F$370,$B7,'VS×ケイパビリティ関係'!$G$4:$G$370,I$5,'VS×ケイパビリティ関係'!$E$4:$E$370,"支援")>0,"○","")) | J7: =IF(COUNTIFS('VS×ケイパビリティ関係'!$F$4:$F$370,$B7,'VS×ケイパビリティ関係'!$G$4:$G$370,J$5,'VS×ケイパビリティ関係'!$E$4:$E$370,"主")>0,"●",IF(COUNTIFS('VS×ケイパビリティ関係'!$F$4:$F$370,$B7,'VS×ケイパビリティ関係'!$G$4:$G$370,J$5,'VS×ケイパビリティ関係'!$E$4:$E$370,"支援")>0,"○","")) | K7: =IF(COUNTIFS('VS×ケイパビリティ関係'!$F$4:$F$370,$B7,'VS×ケイパビリティ関係'!$G$4:$G$370,K$5,'VS×ケイパビリティ関係'!$E$4:$E$370,"主")>0,"●",IF(COUNTIFS('VS×ケイパビリティ関係'!$F$4:$F$370,$B7,'VS×ケイパビリティ関係'!$G$4:$G$370,K$5,'VS×ケイパビリティ関係'!$E$4:$E$370,"支援")>0,"○","")) | ... AI7: =IF(COUNTIFS('VS×ケイパビリティ関係'!$F$4:$F$370,$B7,'VS×ケイパビリティ関係'!$G$4:$G$370,AI$5,'VS×ケイパビリティ関係'!$E$4:$E$370,"主")>0,"●",IF(COUNTIFS('VS×ケイパビリティ関係'!$F$4:$F$370,$B7,'VS×ケイパビリティ関係'!$G$4:$G$370,AI$5,'VS×ケイパビリティ関係'!$E$4:$E$370,"支援")>0,"○","")) | AJ7: =COUNTIF(D7:AI7,"●") | AK7: =COUNTIF(D7:AI7,"○")
B8: 01-02 | C8: 母集団形成 | D8: =IF(COUNTIFS('VS×ケイパビリティ関係'!$F$4:$F$370,$B8,'VS×ケイパビリティ関係'!$G$4:$G$370,D$5,'VS×ケイパビリティ関係'!$E$4:$E$370,"主")>0,"●",IF(COUNTIFS('VS×ケイパビリティ関係'!$F$4:$F$370,$B8,'VS×ケイパビリティ関係'!$G$4:$G$370,D$5,'VS×ケイパビリティ関係'!$E$4:$E$370,"支援")>0,"○","")) | E8: =IF(COUNTIFS('VS×ケイパビリティ関係'!$F$4:$F$370,$B8,'VS×ケイパビリティ関係'!$G$4:$G$370,E$5,'VS×ケイパビリティ関係'!$E$4:$E$370,"主")>0,"●",IF(COUNTIFS('VS×ケイパビリティ関係'!$F$4:$F$370,$B8,'VS×ケイパビリティ関係'!$G$4:$G$370,E$5,'VS×ケイパビリティ関係'!$E$4:$E$370,"支援")>0,"○","")) | F8: =IF(COUNTIFS('VS×ケイパビリティ関係'!$F$4:$F$370,$B8,'VS×ケイパビリティ関係'!$G$4:$G$370,F$5,'VS×ケイパビリティ関係'!$E$4:$E$370,"主")>0,"●",IF(COUNTIFS('VS×ケイパビリティ関係'!$F$4:$F$370,$B8,'VS×ケイパビリティ関係'!$G$4:$G$370,F$5,'VS×ケイパビリティ関係'!$E$4:$E$370,"支援")>0,"○","")) | G8: =IF(COUNTIFS('VS×ケイパビリティ関係'!$F$4:$F$370,$B8,'VS×ケイパビリティ関係'!$G$4:$G$370,G$5,'VS×ケイパビリティ関係'!$E$4:$E$370,"主")>0,"●",IF(COUNTIFS('VS×ケイパビリティ関係'!$F$4:$F$370,$B8,'VS×ケイパビリティ関係'!$G$4:$G$370,G$5,'VS×ケイパビリティ関係'!$E$4:$E$370,"支援")>0,"○","")) | H8: =IF(COUNTIFS('VS×ケイパビリティ関係'!$F$4:$F$370,$B8,'VS×ケイパビリティ関係'!$G$4:$G$370,H$5,'VS×ケイパビリティ関係'!$E$4:$E$370,"主")>0,"●",IF(COUNTIFS('VS×ケイパビリティ関係'!$F$4:$F$370,$B8,'VS×ケイパビリティ関係'!$G$4:$G$370,H$5,'VS×ケイパビリティ関係'!$E$4:$E$370,"支援")>0,"○","")) | I8: =IF(COUNTIFS('VS×ケイパビリティ関係'!$F$4:$F$370,$B8,'VS×ケイパビリティ関係'!$G$4:$G$370,I$5,'VS×ケイパビリティ関係'!$E$4:$E$370,"主")>0,"●",IF(COUNTIFS('VS×ケイパビリティ関係'!$F$4:$F$370,$B8,'VS×ケイパビリティ関係'!$G$4:$G$370,I$5,'VS×ケイパビリティ関係'!$E$4:$E$370,"支援")>0,"○","")) | J8: =IF(COUNTIFS('VS×ケイパビリティ関係'!$F$4:$F$370,$B8,'VS×ケイパビリティ関係'!$G$4:$G$370,J$5,'VS×ケイパビリティ関係'!$E$4:$E$370,"主")>0,"●",IF(COUNTIFS('VS×ケイパビリティ関係'!$F$4:$F$370,$B8,'VS×ケイパビリティ関係'!$G$4:$G$370,J$5,'VS×ケイパビリティ関係'!$E$4:$E$370,"支援")>0,"○","")) | K8: =IF(COUNTIFS('VS×ケイパビリティ関係'!$F$4:$F$370,$B8,'VS×ケイパビリティ関係'!$G$4:$G$370,K$5,'VS×ケイパビリティ関係'!$E$4:$E$370,"主")>0,"●",IF(COUNTIFS('VS×ケイパビリティ関係'!$F$4:$F$370,$B8,'VS×ケイパビリティ関係'!$G$4:$G$370,K$5,'VS×ケイパビリティ関係'!$E$4:$E$370,"支援")>0,"○","")) | ... AI8: =IF(COUNTIFS('VS×ケイパビリティ関係'!$F$4:$F$370,$B8,'VS×ケイパビリティ関係'!$G$4:$G$370,AI$5,'VS×ケイパビリティ関係'!$E$4:$E$370,"主")>0,"●",IF(COUNTIFS('VS×ケイパビリティ関係'!$F$4:$F$370,$B8,'VS×ケイパビリティ関係'!$G$4:$G$370,AI$5,'VS×ケイパビリティ関係'!$E$4:$E$370,"支援")>0,"○","")) | AJ8: =COUNTIF(D8:AI8,"●") | AK8: =COUNTIF(D8:AI8,"○")
B9: 01-03 | C9: 選考 | D9: =IF(COUNTIFS('VS×ケイパビリティ関係'!$F$4:$F$370,$B9,'VS×ケイパビリティ関係'!$G$4:$G$370,D$5,'VS×ケイパビリティ関係'!$E$4:$E$370,"主")>0,"●",IF(COUNTIFS('VS×ケイパビリティ関係'!$F$4:$F$370,$B9,'VS×ケイパビリティ関係'!$G$4:$G$370,D$5,'VS×ケイパビリティ関係'!$E$4:$E$370,"支援")>0,"○","")) | E9: =IF(COUNTIFS('VS×ケイパビリティ関係'!$F$4:$F$370,$B9,'VS×ケイパビリティ関係'!$G$4:$G$370,E$5,'VS×ケイパビリティ関係'!$E$4:$E$370,"主")>0,"●",IF(COUNTIFS('VS×ケイパビリティ関係'!$F$4:$F$370,$B9,'VS×ケイパビリティ関係'!$G$4:$G$370,E$5,'VS×ケイパビリティ関係'!$E$4:$E$370,"支援")>0,"○","")) | F9: =IF(COUNTIFS('VS×ケイパビリティ関係'!$F$4:$F$370,$B9,'VS×ケイパビリティ関係'!$G$4:$G$370,F$5,'VS×ケイパビリティ関係'!$E$4:$E$370,"主")>0,"●",IF(COUNTIFS('VS×ケイパビリティ関係'!$F$4:$F$370,$B9,'VS×ケイパビリティ関係'!$G$4:$G$370,F$5,'VS×ケイパビリティ関係'!$E$4:$E$370,"支援")>0,"○","")) | G9: =IF(COUNTIFS('VS×ケイパビリティ関係'!$F$4:$F$370,$B9,'VS×ケイパビリティ関係'!$G$4:$G$370,G$5,'VS×ケイパビリティ関係'!$E$4:$E$370,"主")>0,"●",IF(COUNTIFS('VS×ケイパビリティ関係'!$F$4:$F$370,$B9,'VS×ケイパビリティ関係'!$G$4:$G$370,G$5,'VS×ケイパビリティ関係'!$E$4:$E$370,"支援")>0,"○","")) | H9: =IF(COUNTIFS('VS×ケイパビリティ関係'!$F$4:$F$370,$B9,'VS×ケイパビリティ関係'!$G$4:$G$370,H$5,'VS×ケイパビリティ関係'!$E$4:$E$370,"主")>0,"●",IF(COUNTIFS('VS×ケイパビリティ関係'!$F$4:$F$370,$B9,'VS×ケイパビリティ関係'!$G$4:$G$370,H$5,'VS×ケイパビリティ関係'!$E$4:$E$370,"支援")>0,"○","")) | I9: =IF(COUNTIFS('VS×ケイパビリティ関係'!$F$4:$F$370,$B9,'VS×ケイパビリティ関係'!$G$4:$G$370,I$5,'VS×ケイパビリティ関係'!$E$4:$E$370,"主")>0,"●",IF(COUNTIFS('VS×ケイパビリティ関係'!$F$4:$F$370,$B9,'VS×ケイパビリティ関係'!$G$4:$G$370,I$5,'VS×ケイパビリティ関係'!$E$4:$E$370,"支援")>0,"○","")) | J9: =IF(COUNTIFS('VS×ケイパビリティ関係'!$F$4:$F$370,$B9,'VS×ケイパビリティ関係'!$G$4:$G$370,J$5,'VS×ケイパビリティ関係'!$E$4:$E$370,"主")>0,"●",IF(COUNTIFS('VS×ケイパビリティ関係'!$F$4:$F$370,$B9,'VS×ケイパビリティ関係'!$G$4:$G$370,J$5,'VS×ケイパビリティ関係'!$E$4:$E$370,"支援")>0,"○","")) | K9: =IF(COUNTIFS('VS×ケイパビリティ関係'!$F$4:$F$370,$B9,'VS×ケイパビリティ関係'!$G$4:$G$370,K$5,'VS×ケイパビリティ関係'!$E$4:$E$370,"主")>0,"●",IF(COUNTIFS('VS×ケイパビリティ関係'!$F$4:$F$370,$B9,'VS×ケイパビリティ関係'!$G$4:$G$370,K$5,'VS×ケイパビリティ関係'!$E$4:$E$370,"支援")>0,"○","")) | ... AI9: =IF(COUNTIFS('VS×ケイパビリティ関係'!$F$4:$F$370,$B9,'VS×ケイパビリティ関係'!$G$4:$G$370,AI$5,'VS×ケイパビリティ関係'!$E$4:$E$370,"主")>0,"●",IF(COUNTIFS('VS×ケイパビリティ関係'!$F$4:$F$370,$B9,'VS×ケイパビリティ関係'!$G$4:$G$370,AI$5,'VS×ケイパビリティ関係'!$E$4:$E$370,"支援")>0,"○","")) | AJ9: =COUNTIF(D9:AI9,"●") | AK9: =COUNTIF(D9:AI9,"○")
B10: 01-04 | C10: 内定 | D10: =IF(COUNTIFS('VS×ケイパビリティ関係'!$F$4:$F$370,$B10,'VS×ケイパビリティ関係'!$G$4:$G$370,D$5,'VS×ケイパビリティ関係'!$E$4:$E$370,"主")>0,"●",IF(COUNTIFS('VS×ケイパビリティ関係'!$F$4:$F$370,$B10,'VS×ケイパビリティ関係'!$G$4:$G$370,D$5,'VS×ケイパビリティ関係'!$E$4:$E$370,"支援")>0,"○","")) | E10: =IF(COUNTIFS('VS×ケイパビリティ関係'!$F$4:$F$370,$B10,'VS×ケイパビリティ関係'!$G$4:$G$370,E$5,'VS×ケイパビリティ関係'!$E$4:$E$370,"主")>0,"●",IF(COUNTIFS('VS×ケイパビリティ関係'!$F$4:$F$370,$B10,'VS×ケイパビリティ関係'!$G$4:$G$370,E$5,'VS×ケイパビリティ関係'!$E$4:$E$370,"支援")>0,"○","")) | F10: =IF(COUNTIFS('VS×ケイパビリティ関係'!$F$4:$F$370,$B10,'VS×ケイパビリティ関係'!$G$4:$G$370,F$5,'VS×ケイパビリティ関係'!$E$4:$E$370,"主")>0,"●",IF(COUNTIFS('VS×ケイパビリティ関係'!$F$4:$F$370,$B10,'VS×ケイパビリティ関係'!$G$4:$G$370,F$5,'VS×ケイパビリティ関係'!$E$4:$E$370,"支援")>0,"○","")) | G10: =IF(COUNTIFS('VS×ケイパビリティ関係'!$F$4:$F$370,$B10,'VS×ケイパビリティ関係'!$G$4:$G$370,G$5,'VS×ケイパビリティ関係'!$E$4:$E$370,"主")>0,"●",IF(COUNTIFS('VS×ケイパビリティ関係'!$F$4:$F$370,$B10,'VS×ケイパビリティ関係'!$G$4:$G$370,G$5,'VS×ケイパビリティ関係'!$E$4:$E$370,"支援")>0,"○","")) | H10: =IF(COUNTIFS('VS×ケイパビリティ関係'!$F$4:$F$370,$B10,'VS×ケイパビリティ関係'!$G$4:$G$370,H$5,'VS×ケイパビリティ関係'!$E$4:$E$370,"主")>0,"●",IF(COUNTIFS('VS×ケイパビリティ関係'!$F$4:$F$370,$B10,'VS×ケイパビリティ関係'!$G$4:$G$370,H$5,'VS×ケイパビリティ関係'!$E$4:$E$370,"支援")>0,"○","")) | I10: =IF(COUNTIFS('VS×ケイパビリティ関係'!$F$4:$F$370,$B10,'VS×ケイパビリティ関係'!$G$4:$G$370,I$5,'VS×ケイパビリティ関係'!$E$4:$E$370,"主")>0,"●",IF(COUNTIFS('VS×ケイパビリティ関係'!$F$4:$F$370,$B10,'VS×ケイパビリティ関係'!$G$4:$G$370,I$5,'VS×ケイパビリティ関係'!$E$4:$E$370,"支援")>0,"○","")) | J10: =IF(COUNTIFS('VS×ケイパビリティ関係'!$F$4:$F$370,$B10,'VS×ケイパビリティ関係'!$G$4:$G$370,J$5,'VS×ケイパビリティ関係'!$E$4:$E$370,"主")>0,"●",IF(COUNTIFS('VS×ケイパビリティ関係'!$F$4:$F$370,$B10,'VS×ケイパビリティ関係'!$G$4:$G$370,J$5,'VS×ケイパビリティ関係'!$E$4:$E$370,"支援")>0,"○","")) | K10: =IF(COUNTIFS('VS×ケイパビリティ関係'!$F$4:$F$370,$B10,'VS×ケイパビリティ関係'!$G$4:$G$370,K$5,'VS×ケイパビリティ関係'!$E$4:$E$370,"主")>0,"●",IF(COUNTIFS('VS×ケイパビリティ関係'!$F$4:$F$370,$B10,'VS×ケイパビリティ関係'!$G$4:$G$370,K$5,'VS×ケイパビリティ関係'!$E$4:$E$370,"支援")>0,"○","")) | ... AI10: =IF(COUNTIFS('VS×ケイパビリティ関係'!$F$4:$F$370,$B10,'VS×ケイパビリティ関係'!$G$4:$G$370,AI$5,'VS×ケイパビリティ関係'!$E$4:$E$370,"主")>0,"●",IF(COUNTIFS('VS×ケイパビリティ関係'!$F$4:$F$370,$B10,'VS×ケイパビリティ関係'!$G$4:$G$370,AI$5,'VS×ケイパビリティ関係'!$E$4:$E$370,"支援")>0,"○","")) | AJ10: =COUNTIF(D10:AI10,"●") | AK10: =COUNTIF(D10:AI10,"○")
A11: 02 入社・オンボーディング | B11: 02-01 | C11: 雇用契約・入社手続き | D11: =IF(COUNTIFS('VS×ケイパビリティ関係'!$F$4:$F$370,$B11,'VS×ケイパビリティ関係'!$G$4:$G$370,D$5,'VS×ケイパビリティ関係'!$E$4:$E$370,"主")>0,"●",IF(COUNTIFS('VS×ケイパビリティ関係'!$F$4:$F$370,$B11,'VS×ケイパビリティ関係'!$G$4:$G$370,D$5,'VS×ケイパビリティ関係'!$E$4:$E$370,"支援")>0,"○","")) | E11: =IF(COUNTIFS('VS×ケイパビリティ関係'!$F$4:$F$370,$B11,'VS×ケイパビリティ関係'!$G$4:$G$370,E$5,'VS×ケイパビリティ関係'!$E$4:$E$370,"主")>0,"●",IF(COUNTIFS('VS×ケイパビリティ関係'!$F$4:$F$370,$B11,'VS×ケイパビリティ関係'!$G$4:$G$370,E$5,'VS×ケイパビリティ関係'!$E$4:$E$370,"支援")>0,"○","")) | F11: =IF(COUNTIFS('VS×ケイパビリティ関係'!$F$4:$F$370,$B11,'VS×ケイパビリティ関係'!$G$4:$G$370,F$5,'VS×ケイパビリティ関係'!$E$4:$E$370,"主")>0,"●",IF(COUNTIFS('VS×ケイパビリティ関係'!$F$4:$F$370,$B11,'VS×ケイパビリティ関係'!$G$4:$G$370,F$5,'VS×ケイパビリティ関係'!$E$4:$E$370,"支援")>0,"○","")) | G11: =IF(COUNTIFS('VS×ケイパビリティ関係'!$F$4:$F$370,$B11,'VS×ケイパビリティ関係'!$G$4:$G$370,G$5,'VS×ケイパビリティ関係'!$E$4:$E$370,"主")>0,"●",IF(COUNTIFS('VS×ケイパビリティ関係'!$F$4:$F$370,$B11,'VS×ケイパビリティ関係'!$G$4:$G$370,G$5,'VS×ケイパビリティ関係'!$E$4:$E$370,"支援")>0,"○","")) | H11: =IF(COUNTIFS('VS×ケイパビリティ関係'!$F$4:$F$370,$B11,'VS×ケイパビリティ関係'!$G$4:$G$370,H$5,'VS×ケイパビリティ関係'!$E$4:$E$370,"主")>0,"●",IF(COUNTIFS('VS×ケイパビリティ関係'!$F$4:$F$370,$B11,'VS×ケイパビリティ関係'!$G$4:$G$370,H$5,'VS×ケイパビリティ関係'!$E$4:$E$370,"支援")>0,"○","")) | I11: =IF(COUNTIFS('VS×ケイパビリティ関係'!$F$4:$F$370,$B11,'VS×ケイパビリティ関係'!$G$4:$G$370,I$5,'VS×ケイパビリティ関係'!$E$4:$E$370,"主")>0,"●",IF(COUNTIFS('VS×ケイパビリティ関係'!$F$4:$F$370,$B11,'VS×ケイパビリティ関係'!$G$4:$G$370,I$5,'VS×ケイパビリティ関係'!$E$4:$E$370,"支援")>0,"○","")) | J11: =IF(COUNTIFS('VS×ケイパビリティ関係'!$F$4:$F$370,$B11,'VS×ケイパビリティ関係'!$G$4:$G$370,J$5,'VS×ケイパビリティ関係'!$E$4:$E$370,"主")>0,"●",IF(COUNTIFS('VS×ケイパビリティ関係'!$F$4:$F$370,$B11,'VS×ケイパビリティ関係'!$G$4:$G$370,J$5,'VS×ケイパビリティ関係'!$E$4:$E$370,"支援")>0,"○","")) | K11: =IF(COUNTIFS('VS×ケイパビリティ関係'!$F$4:$F$370,$B11,'VS×ケイパビリティ関係'!$G$4:$G$370,K$5,'VS×ケイパビリティ関係'!$E$4:$E$370,"主")>0,"●",IF(COUNTIFS('VS×ケイパビリティ関係'!$F$4:$F$370,$B11,'VS×ケイパビリティ関係'!$G$4:$G$370,K$5,'VS×ケイパビリティ関係'!$E$4:$E$370,"支援")>0,"○","")) | ... AI11: =IF(COUNTIFS('VS×ケイパビリティ関係'!$F$4:$F$370,$B11,'VS×ケイパビリティ関係'!$G$4:$G$370,AI$5,'VS×ケイパビリティ関係'!$E$4:$E$370,"主")>0,"●",IF(COUNTIFS('VS×ケイパビリティ関係'!$F$4:$F$370,$B11,'VS×ケイパビリティ関係'!$G$4:$G$370,AI$5,'VS×ケイパビリティ関係'!$E$4:$E$370,"支援")>0,"○","")) | AJ11: =COUNTIF(D11:AI11,"●") | AK11: =COUNTIF(D11:AI11,"○")
B12: 02-02 | C12: 受入れ準備 | D12: =IF(COUNTIFS('VS×ケイパビリティ関係'!$F$4:$F$370,$B12,'VS×ケイパビリティ関係'!$G$4:$G$370,D$5,'VS×ケイパビリティ関係'!$E$4:$E$370,"主")>0,"●",IF(COUNTIFS('VS×ケイパビリティ関係'!$F$4:$F$370,$B12,'VS×ケイパビリティ関係'!$G$4:$G$370,D$5,'VS×ケイパビリティ関係'!$E$4:$E$370,"支援")>0,"○","")) | E12: =IF(COUNTIFS('VS×ケイパビリティ関係'!$F$4:$F$370,$B12,'VS×ケイパビリティ関係'!$G$4:$G$370,E$5,'VS×ケイパビリティ関係'!$E$4:$E$370,"主")>0,"●",IF(COUNTIFS('VS×ケイパビリティ関係'!$F$4:$F$370,$B12,'VS×ケイパビリティ関係'!$G$4:$G$370,E$5,'VS×ケイパビリティ関係'!$E$4:$E$370,"支援")>0,"○","")) | F12: =IF(COUNTIFS('VS×ケイパビリティ関係'!$F$4:$F$370,$B12,'VS×ケイパビリティ関係'!$G$4:$G$370,F$5,'VS×ケイパビリティ関係'!$E$4:$E$370,"主")>0,"●",IF(COUNTIFS('VS×ケイパビリティ関係'!$F$4:$F$370,$B12,'VS×ケイパビリティ関係'!$G$4:$G$370,F$5,'VS×ケイパビリティ関係'!$E$4:$E$370,"支援")>0,"○","")) | G12: =IF(COUNTIFS('VS×ケイパビリティ関係'!$F$4:$F$370,$B12,'VS×ケイパビリティ関係'!$G$4:$G$370,G$5,'VS×ケイパビリティ関係'!$E$4:$E$370,"主")>0,"●",IF(COUNTIFS('VS×ケイパビリティ関係'!$F$4:$F$370,$B12,'VS×ケイパビリティ関係'!$G$4:$G$370,G$5,'VS×ケイパビリティ関係'!$E$4:$E$370,"支援")>0,"○","")) | H12: =IF(COUNTIFS('VS×ケイパビリティ関係'!$F$4:$F$370,$B12,'VS×ケイパビリティ関係'!$G$4:$G$370,H$5,'VS×ケイパビリティ関係'!$E$4:$E$370,"主")>0,"●",IF(COUNTIFS('VS×ケイパビリティ関係'!$F$4:$F$370,$B12,'VS×ケイパビリティ関係'!$G$4:$G$370,H$5,'VS×ケイパビリティ関係'!$E$4:$E$370,"支援")>0,"○","")) | I12: =IF(COUNTIFS('VS×ケイパビリティ関係'!$F$4:$F$370,$B12,'VS×ケイパビリティ関係'!$G$4:$G$370,I$5,'VS×ケイパビリティ関係'!$E$4:$E$370,"主")>0,"●",IF(COUNTIFS('VS×ケイパビリティ関係'!$F$4:$F$370,$B12,'VS×ケイパビリティ関係'!$G$4:$G$370,I$5,'VS×ケイパビリティ関係'!$E$4:$E$370,"支援")>0,"○","")) | J12: =IF(COUNTIFS('VS×ケイパビリティ関係'!$F$4:$F$370,$B12,'VS×ケイパビリティ関係'!$G$4:$G$370,J$5,'VS×ケイパビリティ関係'!$E$4:$E$370,"主")>0,"●",IF(COUNTIFS('VS×ケイパビリティ関係'!$F$4:$F$370,$B12,'VS×ケイパビリティ関係'!$G$4:$G$370,J$5,'VS×ケイパビリティ関係'!$E$4:$E$370,"支援")>0,"○","")) | K12: =IF(COUNTIFS('VS×ケイパビリティ関係'!$F$4:$F$370,$B12,'VS×ケイパビリティ関係'!$G$4:$G$370,K$5,'VS×ケイパビリティ関係'!$E$4:$E$370,"主")>0,"●",IF(COUNTIFS('VS×ケイパビリティ関係'!$F$4:$F$370,$B12,'VS×ケイパビリティ関係'!$G$4:$G$370,K$5,'VS×ケイパビリティ関係'!$E$4:$E$370,"支援")>0,"○","")) | ... AI12: =IF(COUNTIFS('VS×ケイパビリティ関係'!$F$4:$F$370,$B12,'VS×ケイパビリティ関係'!$G$4:$G$370,AI$5,'VS×ケイパビリティ関係'!$E$4:$E$370,"主")>0,"●",IF(COUNTIFS('VS×ケイパビリティ関係'!$F$4:$F$370,$B12,'VS×ケイパビリティ関係'!$G$4:$G$370,AI$5,'VS×ケイパビリティ関係'!$E$4:$E$370,"支援")>0,"○","")) | AJ12: =COUNTIF(D12:AI12,"●") | AK12: =COUNTIF(D12:AI12,"○")
B13: 02-03 | C13: オンボーディング・定着 | D13: =IF(COUNTIFS('VS×ケイパビリティ関係'!$F$4:$F$370,$B13,'VS×ケイパビリティ関係'!$G$4:$G$370,D$5,'VS×ケイパビリティ関係'!$E$4:$E$370,"主")>0,"●",IF(COUNTIFS('VS×ケイパビリティ関係'!$F$4:$F$370,$B13,'VS×ケイパビリティ関係'!$G$4:$G$370,D$5,'VS×ケイパビリティ関係'!$E$4:$E$370,"支援")>0,"○","")) | E13: =IF(COUNTIFS('VS×ケイパビリティ関係'!$F$4:$F$370,$B13,'VS×ケイパビリティ関係'!$G$4:$G$370,E$5,'VS×ケイパビリティ関係'!$E$4:$E$370,"主")>0,"●",IF(COUNTIFS('VS×ケイパビリティ関係'!$F$4:$F$370,$B13,'VS×ケイパビリティ関係'!$G$4:$G$370,E$5,'VS×ケイパビリティ関係'!$E$4:$E$370,"支援")>0,"○","")) | F13: =IF(COUNTIFS('VS×ケイパビリティ関係'!$F$4:$F$370,$B13,'VS×ケイパビリティ関係'!$G$4:$G$370,F$5,'VS×ケイパビリティ関係'!$E$4:$E$370,"主")>0,"●",IF(COUNTIFS('VS×ケイパビリティ関係'!$F$4:$F$370,$B13,'VS×ケイパビリティ関係'!$G$4:$G$370,F$5,'VS×ケイパビリティ関係'!$E$4:$E$370,"支援")>0,"○","")) | G13: =IF(COUNTIFS('VS×ケイパビリティ関係'!$F$4:$F$370,$B13,'VS×ケイパビリティ関係'!$G$4:$G$370,G$5,'VS×ケイパビリティ関係'!$E$4:$E$370,"主")>0,"●",IF(COUNTIFS('VS×ケイパビリティ関係'!$F$4:$F$370,$B13,'VS×ケイパビリティ関係'!$G$4:$G$370,G$5,'VS×ケイパビリティ関係'!$E$4:$E$370,"支援")>0,"○","")) | H13: =IF(COUNTIFS('VS×ケイパビリティ関係'!$F$4:$F$370,$B13,'VS×ケイパビリティ関係'!$G$4:$G$370,H$5,'VS×ケイパビリティ関係'!$E$4:$E$370,"主")>0,"●",IF(COUNTIFS('VS×ケイパビリティ関係'!$F$4:$F$370,$B13,'VS×ケイパビリティ関係'!$G$4:$G$370,H$5,'VS×ケイパビリティ関係'!$E$4:$E$370,"支援")>0,"○","")) | I13: =IF(COUNTIFS('VS×ケイパビリティ関係'!$F$4:$F$370,$B13,'VS×ケイパビリティ関係'!$G$4:$G$370,I$5,'VS×ケイパビリティ関係'!$E$4:$E$370,"主")>0,"●",IF(COUNTIFS('VS×ケイパビリティ関係'!$F$4:$F$370,$B13,'VS×ケイパビリティ関係'!$G$4:$G$370,I$5,'VS×ケイパビリティ関係'!$E$4:$E$370,"支援")>0,"○","")) | J13: =IF(COUNTIFS('VS×ケイパビリティ関係'!$F$4:$F$370,$B13,'VS×ケイパビリティ関係'!$G$4:$G$370,J$5,'VS×ケイパビリティ関係'!$E$4:$E$370,"主")>0,"●",IF(COUNTIFS('VS×ケイパビリティ関係'!$F$4:$F$370,$B13,'VS×ケイパビリティ関係'!$G$4:$G$370,J$5,'VS×ケイパビリティ関係'!$E$4:$E$370,"支援")>0,"○","")) | K13: =IF(COUNTIFS('VS×ケイパビリティ関係'!$F$4:$F$370,$B13,'VS×ケイパビリティ関係'!$G$4:$G$370,K$5,'VS×ケイパビリティ関係'!$E$4:$E$370,"主")>0,"●",IF(COUNTIFS('VS×ケイパビリティ関係'!$F$4:$F$370,$B13,'VS×ケイパビリティ関係'!$G$4:$G$370,K$5,'VS×ケイパビリティ関係'!$E$4:$E$370,"支援")>0,"○","")) | ... AI13: =IF(COUNTIFS('VS×ケイパビリティ関係'!$F$4:$F$370,$B13,'VS×ケイパビリティ関係'!$G$4:$G$370,AI$5,'VS×ケイパビリティ関係'!$E$4:$E$370,"主")>0,"●",IF(COUNTIFS('VS×ケイパビリティ関係'!$F$4:$F$370,$B13,'VS×ケイパビリティ関係'!$G$4:$G$370,AI$5,'VS×ケイパビリティ関係'!$E$4:$E$370,"支援")>0,"○","")) | AJ13: =COUNTIF(D13:AI13,"●") | AK13: =COUNTIF(D13:AI13,"○")
A14: 03 人材育成・能力開発 | B14: 03-01 | C14: 育成計画 | D14: =IF(COUNTIFS('VS×ケイパビリティ関係'!$F$4:$F$370,$B14,'VS×ケイパビリティ関係'!$G$4:$G$370,D$5,'VS×ケイパビリティ関係'!$E$4:$E$370,"主")>0,"●",IF(COUNTIFS('VS×ケイパビリティ関係'!$F$4:$F$370,$B14,'VS×ケイパビリティ関係'!$G$4:$G$370,D$5,'VS×ケイパビリティ関係'!$E$4:$E$370,"支援")>0,"○","")) | E14: =IF(COUNTIFS('VS×ケイパビリティ関係'!$F$4:$F$370,$B14,'VS×ケイパビリティ関係'!$G$4:$G$370,E$5,'VS×ケイパビリティ関係'!$E$4:$E$370,"主")>0,"●",IF(COUNTIFS('VS×ケイパビリティ関係'!$F$4:$F$370,$B14,'VS×ケイパビリティ関係'!$G$4:$G$370,E$5,'VS×ケイパビリティ関係'!$E$4:$E$370,"支援")>0,"○","")) | F14: =IF(COUNTIFS('VS×ケイパビリティ関係'!$F$4:$F$370,$B14,'VS×ケイパビリティ関係'!$G$4:$G$370,F$5,'VS×ケイパビリティ関係'!$E$4:$E$370,"主")>0,"●",IF(COUNTIFS('VS×ケイパビリティ関係'!$F$4:$F$370,$B14,'VS×ケイパビリティ関係'!$G$4:$G$370,F$5,'VS×ケイパビリティ関係'!$E$4:$E$370,"支援")>0,"○","")) | G14: =IF(COUNTIFS('VS×ケイパビリティ関係'!$F$4:$F$370,$B14,'VS×ケイパビリティ関係'!$G$4:$G$370,G$5,'VS×ケイパビリティ関係'!$E$4:$E$370,"主")>0,"●",IF(COUNTIFS('VS×ケイパビリティ関係'!$F$4:$F$370,$B14,'VS×ケイパビリティ関係'!$G$4:$G$370,G$5,'VS×ケイパビリティ関係'!$E$4:$E$370,"支援")>0,"○","")) | H14: =IF(COUNTIFS('VS×ケイパビリティ関係'!$F$4:$F$370,$B14,'VS×ケイパビリティ関係'!$G$4:$G$370,H$5,'VS×ケイパビリティ関係'!$E$4:$E$370,"主")>0,"●",IF(COUNTIFS('VS×ケイパビリティ関係'!$F$4:$F$370,$B14,'VS×ケイパビリティ関係'!$G$4:$G$370,H$5,'VS×ケイパビリティ関係'!$E$4:$E$370,"支援")>0,"○","")) | I14: =IF(COUNTIFS('VS×ケイパビリティ関係'!$F$4:$F$370,$B14,'VS×ケイパビリティ関係'!$G$4:$G$370,I$5,'VS×ケイパビリティ関係'!$E$4:$E$370,"主")>0,"●",IF(COUNTIFS('VS×ケイパビリティ関係'!$F$4:$F$370,$B14,'VS×ケイパビリティ関係'!$G$4:$G$370,I$5,'VS×ケイパビリティ関係'!$E$4:$E$370,"支援")>0,"○","")) | J14: =IF(COUNTIFS('VS×ケイパビリティ関係'!$F$4:$F$370,$B14,'VS×ケイパビリティ関係'!$G$4:$G$370,J$5,'VS×ケイパビリティ関係'!$E$4:$E$370,"主")>0,"●",IF(COUNTIFS('VS×ケイパビリティ関係'!$F$4:$F$370,$B14,'VS×ケイパビリティ関係'!$G$4:$G$370,J$5,'VS×ケイパビリティ関係'!$E$4:$E$370,"支援")>0,"○","")) | K14: =IF(COUNTIFS('VS×ケイパビリティ関係'!$F$4:$F$370,$B14,'VS×ケイパビリティ関係'!$G$4:$G$370,K$5,'VS×ケイパビリティ関係'!$E$4:$E$370,"主")>0,"●",IF(COUNTIFS('VS×ケイパビリティ関係'!$F$4:$F$370,$B14,'VS×ケイパビリティ関係'!$G$4:$G$370,K$5,'VS×ケイパビリティ関係'!$E$4:$E$370,"支援")>0,"○","")) | ... AI14: =IF(COUNTIFS('VS×ケイパビリティ関係'!$F$4:$F$370,$B14,'VS×ケイパビリティ関係'!$G$4:$G$370,AI$5,'VS×ケイパビリティ関係'!$E$4:$E$370,"主")>0,"●",IF(COUNTIFS('VS×ケイパビリティ関係'!$F$4:$F$370,$B14,'VS×ケイパビリティ関係'!$G$4:$G$370,AI$5,'VS×ケイパビリティ関係'!$E$4:$E$370,"支援")>0,"○","")) | AJ14: =COUNTIF(D14:AI14,"●") | AK14: =COUNTIF(D14:AI14,"○")
B15: 03-02 | C15: 研修・学習 | D15: =IF(COUNTIFS('VS×ケイパビリティ関係'!$F$4:$F$370,$B15,'VS×ケイパビリティ関係'!$G$4:$G$370,D$5,'VS×ケイパビリティ関係'!$E$4:$E$370,"主")>0,"●",IF(COUNTIFS('VS×ケイパビリティ関係'!$F$4:$F$370,$B15,'VS×ケイパビリティ関係'!$G$4:$G$370,D$5,'VS×ケイパビリティ関係'!$E$4:$E$370,"支援")>0,"○","")) | E15: =IF(COUNTIFS('VS×ケイパビリティ関係'!$F$4:$F$370,$B15,'VS×ケイパビリティ関係'!$G$4:$G$370,E$5,'VS×ケイパビリティ関係'!$E$4:$E$370,"主")>0,"●",IF(COUNTIFS('VS×ケイパビリティ関係'!$F$4:$F$370,$B15,'VS×ケイパビリティ関係'!$G$4:$G$370,E$5,'VS×ケイパビリティ関係'!$E$4:$E$370,"支援")>0,"○","")) | F15: =IF(COUNTIFS('VS×ケイパビリティ関係'!$F$4:$F$370,$B15,'VS×ケイパビリティ関係'!$G$4:$G$370,F$5,'VS×ケイパビリティ関係'!$E$4:$E$370,"主")>0,"●",IF(COUNTIFS('VS×ケイパビリティ関係'!$F$4:$F$370,$B15,'VS×ケイパビリティ関係'!$G$4:$G$370,F$5,'VS×ケイパビリティ関係'!$E$4:$E$370,"支援")>0,"○","")) | G15: =IF(COUNTIFS('VS×ケイパビリティ関係'!$F$4:$F$370,$B15,'VS×ケイパビリティ関係'!$G$4:$G$370,G$5,'VS×ケイパビリティ関係'!$E$4:$E$370,"主")>0,"●",IF(COUNTIFS('VS×ケイパビリティ関係'!$F$4:$F$370,$B15,'VS×ケイパビリティ関係'!$G$4:$G$370,G$5,'VS×ケイパビリティ関係'!$E$4:$E$370,"支援")>0,"○","")) | H15: =IF(COUNTIFS('VS×ケイパビリティ関係'!$F$4:$F$370,$B15,'VS×ケイパビリティ関係'!$G$4:$G$370,H$5,'VS×ケイパビリティ関係'!$E$4:$E$370,"主")>0,"●",IF(COUNTIFS('VS×ケイパビリティ関係'!$F$4:$F$370,$B15,'VS×ケイパビリティ関係'!$G$4:$G$370,H$5,'VS×ケイパビリティ関係'!$E$4:$E$370,"支援")>0,"○","")) | I15: =IF(COUNTIFS('VS×ケイパビリティ関係'!$F$4:$F$370,$B15,'VS×ケイパビリティ関係'!$G$4:$G$370,I$5,'VS×ケイパビリティ関係'!$E$4:$E$370,"主")>0,"●",IF(COUNTIFS('VS×ケイパビリティ関係'!$F$4:$F$370,$B15,'VS×ケイパビリティ関係'!$G$4:$G$370,I$5,'VS×ケイパビリティ関係'!$E$4:$E$370,"支援")>0,"○","")) | J15: =IF(COUNTIFS('VS×ケイパビリティ関係'!$F$4:$F$370,$B15,'VS×ケイパビリティ関係'!$G$4:$G$370,J$5,'VS×ケイパビリティ関係'!$E$4:$E$370,"主")>0,"●",IF(COUNTIFS('VS×ケイパビリティ関係'!$F$4:$F$370,$B15,'VS×ケイパビリティ関係'!$G$4:$G$370,J$5,'VS×ケイパビリティ関係'!$E$4:$E$370,"支援")>0,"○","")) | K15: =IF(COUNTIFS('VS×ケイパビリティ関係'!$F$4:$F$370,$B15,'VS×ケイパビリティ関係'!$G$4:$G$370,K$5,'VS×ケイパビリティ関係'!$E$4:$E$370,"主")>0,"●",IF(COUNTIFS('VS×ケイパビリティ関係'!$F$4:$F$370,$B15,'VS×ケイパビリティ関係'!$G$4:$G$370,K$5,'VS×ケイパビリティ関係'!$E$4:$E$370,"支援")>0,"○","")) | ... AI15: =IF(COUNTIFS('VS×ケイパビリティ関係'!$F$4:$F$370,$B15,'VS×ケイパビリティ関係'!$G$4:$G$370,AI$5,'VS×ケイパビリティ関係'!$E$4:$E$370,"主")>0,"●",IF(COUNTIFS('VS×ケイパビリティ関係'!$F$4:$F$370,$B15,'VS×ケイパビリティ関係'!$G$4:$G$370,AI$5,'VS×ケイパビリティ関係'!$E$4:$E$370,"支援")>0,"○","")) | AJ15: =COUNTIF(D15:AI15,"●") | AK15: =COUNTIF(D15:AI15,"○")
B16: 03-03 | C16: スキル・資格の習得 | D16: =IF(COUNTIFS('VS×ケイパビリティ関係'!$F$4:$F$370,$B16,'VS×ケイパビリティ関係'!$G$4:$G$370,D$5,'VS×ケイパビリティ関係'!$E$4:$E$370,"主")>0,"●",IF(COUNTIFS('VS×ケイパビリティ関係'!$F$4:$F$370,$B16,'VS×ケイパビリティ関係'!$G$4:$G$370,D$5,'VS×ケイパビリティ関係'!$E$4:$E$370,"支援")>0,"○","")) | E16: =IF(COUNTIFS('VS×ケイパビリティ関係'!$F$4:$F$370,$B16,'VS×ケイパビリティ関係'!$G$4:$G$370,E$5,'VS×ケイパビリティ関係'!$E$4:$E$370,"主")>0,"●",IF(COUNTIFS('VS×ケイパビリティ関係'!$F$4:$F$370,$B16,'VS×ケイパビリティ関係'!$G$4:$G$370,E$5,'VS×ケイパビリティ関係'!$E$4:$E$370,"支援")>0,"○","")) | F16: =IF(COUNTIFS('VS×ケイパビリティ関係'!$F$4:$F$370,$B16,'VS×ケイパビリティ関係'!$G$4:$G$370,F$5,'VS×ケイパビリティ関係'!$E$4:$E$370,"主")>0,"●",IF(COUNTIFS('VS×ケイパビリティ関係'!$F$4:$F$370,$B16,'VS×ケイパビリティ関係'!$G$4:$G$370,F$5,'VS×ケイパビリティ関係'!$E$4:$E$370,"支援")>0,"○","")) | G16: =IF(COUNTIFS('VS×ケイパビリティ関係'!$F$4:$F$370,$B16,'VS×ケイパビリティ関係'!$G$4:$G$370,G$5,'VS×ケイパビリティ関係'!$E$4:$E$370,"主")>0,"●",IF(COUNTIFS('VS×ケイパビリティ関係'!$F$4:$F$370,$B16,'VS×ケイパビリティ関係'!$G$4:$G$370,G$5,'VS×ケイパビリティ関係'!$E$4:$E$370,"支援")>0,"○","")) | H16: =IF(COUNTIFS('VS×ケイパビリティ関係'!$F$4:$F$370,$B16,'VS×ケイパビリティ関係'!$G$4:$G$370,H$5,'VS×ケイパビリティ関係'!$E$4:$E$370,"主")>0,"●",IF(COUNTIFS('VS×ケイパビリティ関係'!$F$4:$F$370,$B16,'VS×ケイパビリティ関係'!$G$4:$G$370,H$5,'VS×ケイパビリティ関係'!$E$4:$E$370,"支援")>0,"○","")) | I16: =IF(COUNTIFS('VS×ケイパビリティ関係'!$F$4:$F$370,$B16,'VS×ケイパビリティ関係'!$G$4:$G$370,I$5,'VS×ケイパビリティ関係'!$E$4:$E$370,"主")>0,"●",IF(COUNTIFS('VS×ケイパビリティ関係'!$F$4:$F$370,$B16,'VS×ケイパビリティ関係'!$G$4:$G$370,I$5,'VS×ケイパビリティ関係'!$E$4:$E$370,"支援")>0,"○","")) | J16: =IF(COUNTIFS('VS×ケイパビリティ関係'!$F$4:$F$370,$B16,'VS×ケイパビリティ関係'!$G$4:$G$370,J$5,'VS×ケイパビリティ関係'!$E$4:$E$370,"主")>0,"●",IF(COUNTIFS('VS×ケイパビリティ関係'!$F$4:$F$370,$B16,'VS×ケイパビリティ関係'!$G$4:$G$370,J$5,'VS×ケイパビリティ関係'!$E$4:$E$370,"支援")>0,"○","")) | K16: =IF(COUNTIFS('VS×ケイパビリティ関係'!$F$4:$F$370,$B16,'VS×ケイパビリティ関係'!$G$4:$G$370,K$5,'VS×ケイパビリティ関係'!$E$4:$E$370,"主")>0,"●",IF(COUNTIFS('VS×ケイパビリティ関係'!$F$4:$F$370,$B16,'VS×ケイパビリティ関係'!$G$4:$G$370,K$5,'VS×ケイパビリティ関係'!$E$4:$E$370,"支援")>0,"○","")) | ... AI16: =IF(COUNTIFS('VS×ケイパビリティ関係'!$F$4:$F$370,$B16,'VS×ケイパビリティ関係'!$G$4:$G$370,AI$5,'VS×ケイパビリティ関係'!$E$4:$E$370,"主")>0,"●",IF(COUNTIFS('VS×ケイパビリティ関係'!$F$4:$F$370,$B16,'VS×ケイパビリティ関係'!$G$4:$G$370,AI$5,'VS×ケイパビリティ関係'!$E$4:$E$370,"支援")>0,"○","")) | AJ16: =COUNTIF(D16:AI16,"●") | AK16: =COUNTIF(D16:AI16,"○")
B17: 03-04 | C17: キャリア開発 | D17: =IF(COUNTIFS('VS×ケイパビリティ関係'!$F$4:$F$370,$B17,'VS×ケイパビリティ関係'!$G$4:$G$370,D$5,'VS×ケイパビリティ関係'!$E$4:$E$370,"主")>0,"●",IF(COUNTIFS('VS×ケイパビリティ関係'!$F$4:$F$370,$B17,'VS×ケイパビリティ関係'!$G$4:$G$370,D$5,'VS×ケイパビリティ関係'!$E$4:$E$370,"支援")>0,"○","")) | E17: =IF(COUNTIFS('VS×ケイパビリティ関係'!$F$4:$F$370,$B17,'VS×ケイパビリティ関係'!$G$4:$G$370,E$5,'VS×ケイパビリティ関係'!$E$4:$E$370,"主")>0,"●",IF(COUNTIFS('VS×ケイパビリティ関係'!$F$4:$F$370,$B17,'VS×ケイパビリティ関係'!$G$4:$G$370,E$5,'VS×ケイパビリティ関係'!$E$4:$E$370,"支援")>0,"○","")) | F17: =IF(COUNTIFS('VS×ケイパビリティ関係'!$F$4:$F$370,$B17,'VS×ケイパビリティ関係'!$G$4:$G$370,F$5,'VS×ケイパビリティ関係'!$E$4:$E$370,"主")>0,"●",IF(COUNTIFS('VS×ケイパビリティ関係'!$F$4:$F$370,$B17,'VS×ケイパビリティ関係'!$G$4:$G$370,F$5,'VS×ケイパビリティ関係'!$E$4:$E$370,"支援")>0,"○","")) | G17: =IF(COUNTIFS('VS×ケイパビリティ関係'!$F$4:$F$370,$B17,'VS×ケイパビリティ関係'!$G$4:$G$370,G$5,'VS×ケイパビリティ関係'!$E$4:$E$370,"主")>0,"●",IF(COUNTIFS('VS×ケイパビリティ関係'!$F$4:$F$370,$B17,'VS×ケイパビリティ関係'!$G$4:$G$370,G$5,'VS×ケイパビリティ関係'!$E$4:$E$370,"支援")>0,"○","")) | H17: =IF(COUNTIFS('VS×ケイパビリティ関係'!$F$4:$F$370,$B17,'VS×ケイパビリティ関係'!$G$4:$G$370,H$5,'VS×ケイパビリティ関係'!$E$4:$E$370,"主")>0,"●",IF(COUNTIFS('VS×ケイパビリティ関係'!$F$4:$F$370,$B17,'VS×ケイパビリティ関係'!$G$4:$G$370,H$5,'VS×ケイパビリティ関係'!$E$4:$E$370,"支援")>0,"○","")) | I17: =IF(COUNTIFS('VS×ケイパビリティ関係'!$F$4:$F$370,$B17,'VS×ケイパビリティ関係'!$G$4:$G$370,I$5,'VS×ケイパビリティ関係'!$E$4:$E$370,"主")>0,"●",IF(COUNTIFS('VS×ケイパビリティ関係'!$F$4:$F$370,$B17,'VS×ケイパビリティ関係'!$G$4:$G$370,I$5,'VS×ケイパビリティ関係'!$E$4:$E$370,"支援")>0,"○","")) | J17: =IF(COUNTIFS('VS×ケイパビリティ関係'!$F$4:$F$370,$B17,'VS×ケイパビリティ関係'!$G$4:$G$370,J$5,'VS×ケイパビリティ関係'!$E$4:$E$370,"主")>0,"●",IF(COUNTIFS('VS×ケイパビリティ関係'!$F$4:$F$370,$B17,'VS×ケイパビリティ関係'!$G$4:$G$370,J$5,'VS×ケイパビリティ関係'!$E$4:$E$370,"支援")>0,"○","")) | K17: =IF(COUNTIFS('VS×ケイパビリティ関係'!$F$4:$F$370,$B17,'VS×ケイパビリティ関係'!$G$4:$G$370,K$5,'VS×ケイパビリティ関係'!$E$4:$E$370,"主")>0,"●",IF(COUNTIFS('VS×ケイパビリティ関係'!$F$4:$F$370,$B17,'VS×ケイパビリティ関係'!$G$4:$G$370,K$5,'VS×ケイパビリティ関係'!$E$4:$E$370,"支援")>0,"○","")) | ... AI17: =IF(COUNTIFS('VS×ケイパビリティ関係'!$F$4:$F$370,$B17,'VS×ケイパビリティ関係'!$G$4:$G$370,AI$5,'VS×ケイパビリティ関係'!$E$4:$E$370,"主")>0,"●",IF(COUNTIFS('VS×ケイパビリティ関係'!$F$4:$F$370,$B17,'VS×ケイパビリティ関係'!$G$4:$G$370,AI$5,'VS×ケイパビリティ関係'!$E$4:$E$370,"支援")>0,"○","")) | AJ17: =COUNTIF(D17:AI17,"●") | AK17: =COUNTIF(D17:AI17,"○")
A18: 04 評価・処遇 | B18: 04-01 | C18: 目標設定・評価 | D18: =IF(COUNTIFS('VS×ケイパビリティ関係'!$F$4:$F$370,$B18,'VS×ケイパビリティ関係'!$G$4:$G$370,D$5,'VS×ケイパビリティ関係'!$E$4:$E$370,"主")>0,"●",IF(COUNTIFS('VS×ケイパビリティ関係'!$F$4:$F$370,$B18,'VS×ケイパビリティ関係'!$G$4:$G$370,D$5,'VS×ケイパビリティ関係'!$E$4:$E$370,"支援")>0,"○","")) | E18: =IF(COUNTIFS('VS×ケイパビリティ関係'!$F$4:$F$370,$B18,'VS×ケイパビリティ関係'!$G$4:$G$370,E$5,'VS×ケイパビリティ関係'!$E$4:$E$370,"主")>0,"●",IF(COUNTIFS('VS×ケイパビリティ関係'!$F$4:$F$370,$B18,'VS×ケイパビリティ関係'!$G$4:$G$370,E$5,'VS×ケイパビリティ関係'!$E$4:$E$370,"支援")>0,"○","")) | F18: =IF(COUNTIFS('VS×ケイパビリティ関係'!$F$4:$F$370,$B18,'VS×ケイパビリティ関係'!$G$4:$G$370,F$5,'VS×ケイパビリティ関係'!$E$4:$E$370,"主")>0,"●",IF(COUNTIFS('VS×ケイパビリティ関係'!$F$4:$F$370,$B18,'VS×ケイパビリティ関係'!$G$4:$G$370,F$5,'VS×ケイパビリティ関係'!$E$4:$E$370,"支援")>0,"○","")) | G18: =IF(COUNTIFS('VS×ケイパビリティ関係'!$F$4:$F$370,$B18,'VS×ケイパビリティ関係'!$G$4:$G$370,G$5,'VS×ケイパビリティ関係'!$E$4:$E$370,"主")>0,"●",IF(COUNTIFS('VS×ケイパビリティ関係'!$F$4:$F$370,$B18,'VS×ケイパビリティ関係'!$G$4:$G$370,G$5,'VS×ケイパビリティ関係'!$E$4:$E$370,"支援")>0,"○","")) | H18: =IF(COUNTIFS('VS×ケイパビリティ関係'!$F$4:$F$370,$B18,'VS×ケイパビリティ関係'!$G$4:$G$370,H$5,'VS×ケイパビリティ関係'!$E$4:$E$370,"主")>0,"●",IF(COUNTIFS('VS×ケイパビリティ関係'!$F$4:$F$370,$B18,'VS×ケイパビリティ関係'!$G$4:$G$370,H$5,'VS×ケイパビリティ関係'!$E$4:$E$370,"支援")>0,"○","")) | I18: =IF(COUNTIFS('VS×ケイパビリティ関係'!$F$4:$F$370,$B18,'VS×ケイパビリティ関係'!$G$4:$G$370,I$5,'VS×ケイパビリティ関係'!$E$4:$E$370,"主")>0,"●",IF(COUNTIFS('VS×ケイパビリティ関係'!$F$4:$F$370,$B18,'VS×ケイパビリティ関係'!$G$4:$G$370,I$5,'VS×ケイパビリティ関係'!$E$4:$E$370,"支援")>0,"○","")) | J18: =IF(COUNTIFS('VS×ケイパビリティ関係'!$F$4:$F$370,$B18,'VS×ケイパビリティ関係'!$G$4:$G$370,J$5,'VS×ケイパビリティ関係'!$E$4:$E$370,"主")>0,"●",IF(COUNTIFS('VS×ケイパビリティ関係'!$F$4:$F$370,$B18,'VS×ケイパビリティ関係'!$G$4:$G$370,J$5,'VS×ケイパビリティ関係'!$E$4:$E$370,"支援")>0,"○","")) | K18: =IF(COUNTIFS('VS×ケイパビリティ関係'!$F$4:$F$370,$B18,'VS×ケイパビリティ関係'!$G$4:$G$370,K$5,'VS×ケイパビリティ関係'!$E$4:$E$370,"主")>0,"●",IF(COUNTIFS('VS×ケイパビリティ関係'!$F$4:$F$370,$B18,'VS×ケイパビリティ関係'!$G$4:$G$370,K$5,'VS×ケイパビリティ関係'!$E$4:$E$370,"支援")>0,"○","")) | ... AI18: =IF(COUNTIFS('VS×ケイパビリティ関係'!$F$4:$F$370,$B18,'VS×ケイパビリティ関係'!$G$4:$G$370,AI$5,'VS×ケイパビリティ関係'!$E$4:$E$370,"主")>0,"●",IF(COUNTIFS('VS×ケイパビリティ関係'!$F$4:$F$370,$B18,'VS×ケイパビリティ関係'!$G$4:$G$370,AI$5,'VS×ケイパビリティ関係'!$E$4:$E$370,"支援")>0,"○","")) | AJ18: =COUNTIF(D18:AI18,"●") | AK18: =COUNTIF(D18:AI18,"○")
B19: 04-02 | C19: 報酬決定 | D19: =IF(COUNTIFS('VS×ケイパビリティ関係'!$F$4:$F$370,$B19,'VS×ケイパビリティ関係'!$G$4:$G$370,D$5,'VS×ケイパビリティ関係'!$E$4:$E$370,"主")>0,"●",IF(COUNTIFS('VS×ケイパビリティ関係'!$F$4:$F$370,$B19,'VS×ケイパビリティ関係'!$G$4:$G$370,D$5,'VS×ケイパビリティ関係'!$E$4:$E$370,"支援")>0,"○","")) | E19: =IF(COUNTIFS('VS×ケイパビリティ関係'!$F$4:$F$370,$B19,'VS×ケイパビリティ関係'!$G$4:$G$370,E$5,'VS×ケイパビリティ関係'!$E$4:$E$370,"主")>0,"●",IF(COUNTIFS('VS×ケイパビリティ関係'!$F$4:$F$370,$B19,'VS×ケイパビリティ関係'!$G$4:$G$370,E$5,'VS×ケイパビリティ関係'!$E$4:$E$370,"支援")>0,"○","")) | F19: =IF(COUNTIFS('VS×ケイパビリティ関係'!$F$4:$F$370,$B19,'VS×ケイパビリティ関係'!$G$4:$G$370,F$5,'VS×ケイパビリティ関係'!$E$4:$E$370,"主")>0,"●",IF(COUNTIFS('VS×ケイパビリティ関係'!$F$4:$F$370,$B19,'VS×ケイパビリティ関係'!$G$4:$G$370,F$5,'VS×ケイパビリティ関係'!$E$4:$E$370,"支援")>0,"○","")) | G19: =IF(COUNTIFS('VS×ケイパビリティ関係'!$F$4:$F$370,$B19,'VS×ケイパビリティ関係'!$G$4:$G$370,G$5,'VS×ケイパビリティ関係'!$E$4:$E$370,"主")>0,"●",IF(COUNTIFS('VS×ケイパビリティ関係'!$F$4:$F$370,$B19,'VS×ケイパビリティ関係'!$G$4:$G$370,G$5,'VS×ケイパビリティ関係'!$E$4:$E$370,"支援")>0,"○","")) | H19: =IF(COUNTIFS('VS×ケイパビリティ関係'!$F$4:$F$370,$B19,'VS×ケイパビリティ関係'!$G$4:$G$370,H$5,'VS×ケイパビリティ関係'!$E$4:$E$370,"主")>0,"●",IF(COUNTIFS('VS×ケイパビリティ関係'!$F$4:$F$370,$B19,'VS×ケイパビリティ関係'!$G$4:$G$370,H$5,'VS×ケイパビリティ関係'!$E$4:$E$370,"支援")>0,"○","")) | I19: =IF(COUNTIFS('VS×ケイパビリティ関係'!$F$4:$F$370,$B19,'VS×ケイパビリティ関係'!$G$4:$G$370,I$5,'VS×ケイパビリティ関係'!$E$4:$E$370,"主")>0,"●",IF(COUNTIFS('VS×ケイパビリティ関係'!$F$4:$F$370,$B19,'VS×ケイパビリティ関係'!$G$4:$G$370,I$5,'VS×ケイパビリティ関係'!$E$4:$E$370,"支援")>0,"○","")) | J19: =IF(COUNTIFS('VS×ケイパビリティ関係'!$F$4:$F$370,$B19,'VS×ケイパビリティ関係'!$G$4:$G$370,J$5,'VS×ケイパビリティ関係'!$E$4:$E$370,"主")>0,"●",IF(COUNTIFS('VS×ケイパビリティ関係'!$F$4:$F$370,$B19,'VS×ケイパビリティ関係'!$G$4:$G$370,J$5,'VS×ケイパビリティ関係'!$E$4:$E$370,"支援")>0,"○","")) | K19: =IF(COUNTIFS('VS×ケイパビリティ関係'!$F$4:$F$370,$B19,'VS×ケイパビリティ関係'!$G$4:$G$370,K$5,'VS×ケイパビリティ関係'!$E$4:$E$370,"主")>0,"●",IF(COUNTIFS('VS×ケイパビリティ関係'!$F$4:$F$370,$B19,'VS×ケイパビリティ関係'!$G$4:$G$370,K$5,'VS×ケイパビリティ関係'!$E$4:$E$370,"支援")>0,"○","")) | ... AI19: =IF(COUNTIFS('VS×ケイパビリティ関係'!$F$4:$F$370,$B19,'VS×ケイパビリティ関係'!$G$4:$G$370,AI$5,'VS×ケイパビリティ関係'!$E$4:$E$370,"主")>0,"●",IF(COUNTIFS('VS×ケイパビリティ関係'!$F$4:$F$370,$B19,'VS×ケイパビリティ関係'!$G$4:$G$370,AI$5,'VS×ケイパビリティ関係'!$E$4:$E$370,"支援")>0,"○","")) | AJ19: =COUNTIF(D19:AI19,"●") | AK19: =COUNTIF(D19:AI19,"○")
B20: 04-03 | C20: 勤怠・休暇管理 | D20: =IF(COUNTIFS('VS×ケイパビリティ関係'!$F$4:$F$370,$B20,'VS×ケイパビリティ関係'!$G$4:$G$370,D$5,'VS×ケイパビリティ関係'!$E$4:$E$370,"主")>0,"●",IF(COUNTIFS('VS×ケイパビリティ関係'!$F$4:$F$370,$B20,'VS×ケイパビリティ関係'!$G$4:$G$370,D$5,'VS×ケイパビリティ関係'!$E$4:$E$370,"支援")>0,"○","")) | E20: =IF(COUNTIFS('VS×ケイパビリティ関係'!$F$4:$F$370,$B20,'VS×ケイパビリティ関係'!$G$4:$G$370,E$5,'VS×ケイパビリティ関係'!$E$4:$E$370,"主")>0,"●",IF(COUNTIFS('VS×ケイパビリティ関係'!$F$4:$F$370,$B20,'VS×ケイパビリティ関係'!$G$4:$G$370,E$5,'VS×ケイパビリティ関係'!$E$4:$E$370,"支援")>0,"○","")) | F20: =IF(COUNTIFS('VS×ケイパビリティ関係'!$F$4:$F$370,$B20,'VS×ケイパビリティ関係'!$G$4:$G$370,F$5,'VS×ケイパビリティ関係'!$E$4:$E$370,"主")>0,"●",IF(COUNTIFS('VS×ケイパビリティ関係'!$F$4:$F$370,$B20,'VS×ケイパビリティ関係'!$G$4:$G$370,F$5,'VS×ケイパビリティ関係'!$E$4:$E$370,"支援")>0,"○","")) | G20: =IF(COUNTIFS('VS×ケイパビリティ関係'!$F$4:$F$370,$B20,'VS×ケイパビリティ関係'!$G$4:$G$370,G$5,'VS×ケイパビリティ関係'!$E$4:$E$370,"主")>0,"●",IF(COUNTIFS('VS×ケイパビリティ関係'!$F$4:$F$370,$B20,'VS×ケイパビリティ関係'!$G$4:$G$370,G$5,'VS×ケイパビリティ関係'!$E$4:$E$370,"支援")>0,"○","")) | H20: =IF(COUNTIFS('VS×ケイパビリティ関係'!$F$4:$F$370,$B20,'VS×ケイパビリティ関係'!$G$4:$G$370,H$5,'VS×ケイパビリティ関係'!$E$4:$E$370,"主")>0,"●",IF(COUNTIFS('VS×ケイパビリティ関係'!$F$4:$F$370,$B20,'VS×ケイパビリティ関係'!$G$4:$G$370,H$5,'VS×ケイパビリティ関係'!$E$4:$E$370,"支援")>0,"○","")) | I20: =IF(COUNTIFS('VS×ケイパビリティ関係'!$F$4:$F$370,$B20,'VS×ケイパビリティ関係'!$G$4:$G$370,I$5,'VS×ケイパビリティ関係'!$E$4:$E$370,"主")>0,"●",IF(COUNTIFS('VS×ケイパビリティ関係'!$F$4:$F$370,$B20,'VS×ケイパビリティ関係'!$G$4:$G$370,I$5,'VS×ケイパビリティ関係'!$E$4:$E$370,"支援")>0,"○","")) | J20: =IF(COUNTIFS('VS×ケイパビリティ関係'!$F$4:$F$370,$B20,'VS×ケイパビリティ関係'!$G$4:$G$370,J$5,'VS×ケイパビリティ関係'!$E$4:$E$370,"主")>0,"●",IF(COUNTIFS('VS×ケイパビリティ関係'!$F$4:$F$370,$B20,'VS×ケイパビリティ関係'!$G$4:$G$370,J$5,'VS×ケイパビリティ関係'!$E$4:$E$370,"支援")>0,"○","")) | K20: =IF(COUNTIFS('VS×ケイパビリティ関係'!$F$4:$F$370,$B20,'VS×ケイパビリティ関係'!$G$4:$G$370,K$5,'VS×ケイパビリティ関係'!$E$4:$E$370,"主")>0,"●",IF(COUNTIFS('VS×ケイパビリティ関係'!$F$4:$F$370,$B20,'VS×ケイパビリティ関係'!$G$4:$G$370,K$5,'VS×ケイパビリティ関係'!$E$4:$E$370,"支援")>0,"○","")) | ... AI20: =IF(COUNTIFS('VS×ケイパビリティ関係'!$F$4:$F$370,$B20,'VS×ケイパビリティ関係'!$G$4:$G$370,AI$5,'VS×ケイパビリティ関係'!$E$4:$E$370,"主")>0,"●",IF(COUNTIFS('VS×ケイパビリティ関係'!$F$4:$F$370,$B20,'VS×ケイパビリティ関係'!$G$4:$G$370,AI$5,'VS×ケイパビリティ関係'!$E$4:$E$370,"支援")>0,"○","")) | AJ20: =COUNTIF(D20:AI20,"●") | AK20: =COUNTIF(D20:AI20,"○")
B21: 04-04 | C21: 給与・社会保険・福利厚生 | D21: =IF(COUNTIFS('VS×ケイパビリティ関係'!$F$4:$F$370,$B21,'VS×ケイパビリティ関係'!$G$4:$G$370,D$5,'VS×ケイパビリティ関係'!$E$4:$E$370,"主")>0,"●",IF(COUNTIFS('VS×ケイパビリティ関係'!$F$4:$F$370,$B21,'VS×ケイパビリティ関係'!$G$4:$G$370,D$5,'VS×ケイパビリティ関係'!$E$4:$E$370,"支援")>0,"○","")) | E21: =IF(COUNTIFS('VS×ケイパビリティ関係'!$F$4:$F$370,$B21,'VS×ケイパビリティ関係'!$G$4:$G$370,E$5,'VS×ケイパビリティ関係'!$E$4:$E$370,"主")>0,"●",IF(COUNTIFS('VS×ケイパビリティ関係'!$F$4:$F$370,$B21,'VS×ケイパビリティ関係'!$G$4:$G$370,E$5,'VS×ケイパビリティ関係'!$E$4:$E$370,"支援")>0,"○","")) | F21: =IF(COUNTIFS('VS×ケイパビリティ関係'!$F$4:$F$370,$B21,'VS×ケイパビリティ関係'!$G$4:$G$370,F$5,'VS×ケイパビリティ関係'!$E$4:$E$370,"主")>0,"●",IF(COUNTIFS('VS×ケイパビリティ関係'!$F$4:$F$370,$B21,'VS×ケイパビリティ関係'!$G$4:$G$370,F$5,'VS×ケイパビリティ関係'!$E$4:$E$370,"支援")>0,"○","")) | G21: =IF(COUNTIFS('VS×ケイパビリティ関係'!$F$4:$F$370,$B21,'VS×ケイパビリティ関係'!$G$4:$G$370,G$5,'VS×ケイパビリティ関係'!$E$4:$E$370,"主")>0,"●",IF(COUNTIFS('VS×ケイパビリティ関係'!$F$4:$F$370,$B21,'VS×ケイパビリティ関係'!$G$4:$G$370,G$5,'VS×ケイパビリティ関係'!$E$4:$E$370,"支援")>0,"○","")) | H21: =IF(COUNTIFS('VS×ケイパビリティ関係'!$F$4:$F$370,$B21,'VS×ケイパビリティ関係'!$G$4:$G$370,H$5,'VS×ケイパビリティ関係'!$E$4:$E$370,"主")>0,"●",IF(COUNTIFS('VS×ケイパビリティ関係'!$F$4:$F$370,$B21,'VS×ケイパビリティ関係'!$G$4:$G$370,H$5,'VS×ケイパビリティ関係'!$E$4:$E$370,"支援")>0,"○","")) | I21: =IF(COUNTIFS('VS×ケイパビリティ関係'!$F$4:$F$370,$B21,'VS×ケイパビリティ関係'!$G$4:$G$370,I$5,'VS×ケイパビリティ関係'!$E$4:$E$370,"主")>0,"●",IF(COUNTIFS('VS×ケイパビリティ関係'!$F$4:$F$370,$B21,'VS×ケイパビリティ関係'!$G$4:$G$370,I$5,'VS×ケイパビリティ関係'!$E$4:$E$370,"支援")>0,"○","")) | J21: =IF(COUNTIFS('VS×ケイパビリティ関係'!$F$4:$F$370,$B21,'VS×ケイパビリティ関係'!$G$4:$G$370,J$5,'VS×ケイパビリティ関係'!$E$4:$E$370,"主")>0,"●",IF(COUNTIFS('VS×ケイパビリティ関係'!$F$4:$F$370,$B21,'VS×ケイパビリティ関係'!$G$4:$G$370,J$5,'VS×ケイパビリティ関係'!$E$4:$E$370,"支援")>0,"○","")) | K21: =IF(COUNTIFS('VS×ケイパビリティ関係'!$F$4:$F$370,$B21,'VS×ケイパビリティ関係'!$G$4:$G$370,K$5,'VS×ケイパビリティ関係'!$E$4:$E$370,"主")>0,"●",IF(COUNTIFS('VS×ケイパビリティ関係'!$F$4:$F$370,$B21,'VS×ケイパビリティ関係'!$G$4:$G$370,K$5,'VS×ケイパビリティ関係'!$E$4:$E$370,"支援")>0,"○","")) | ... AI21: =IF(COUNTIFS('VS×ケイパビリティ関係'!$F$4:$F$370,$B21,'VS×ケイパビリティ関係'!$G$4:$G$370,AI$5,'VS×ケイパビリティ関係'!$E$4:$E$370,"主")>0,"●",IF(COUNTIFS('VS×ケイパビリティ関係'!$F$4:$F$370,$B21,'VS×ケイパビリティ関係'!$G$4:$G$370,AI$5,'VS×ケイパビリティ関係'!$E$4:$E$370,"支援")>0,"○","")) | AJ21: =COUNTIF(D21:AI21,"●") | AK21: =COUNTIF(D21:AI21,"○")
B22: 04-05 | C22: 健康・安全・職場環境 | D22: =IF(COUNTIFS('VS×ケイパビリティ関係'!$F$4:$F$370,$B22,'VS×ケイパビリティ関係'!$G$4:$G$370,D$5,'VS×ケイパビリティ関係'!$E$4:$E$370,"主")>0,"●",IF(COUNTIFS('VS×ケイパビリティ関係'!$F$4:$F$370,$B22,'VS×ケイパビリティ関係'!$G$4:$G$370,D$5,'VS×ケイパビリティ関係'!$E$4:$E$370,"支援")>0,"○","")) | E22: =IF(COUNTIFS('VS×ケイパビリティ関係'!$F$4:$F$370,$B22,'VS×ケイパビリティ関係'!$G$4:$G$370,E$5,'VS×ケイパビリティ関係'!$E$4:$E$370,"主")>0,"●",IF(COUNTIFS('VS×ケイパビリティ関係'!$F$4:$F$370,$B22,'VS×ケイパビリティ関係'!$G$4:$G$370,E$5,'VS×ケイパビリティ関係'!$E$4:$E$370,"支援")>0,"○","")) | F22: =IF(COUNTIFS('VS×ケイパビリティ関係'!$F$4:$F$370,$B22,'VS×ケイパビリティ関係'!$G$4:$G$370,F$5,'VS×ケイパビリティ関係'!$E$4:$E$370,"主")>0,"●",IF(COUNTIFS('VS×ケイパビリティ関係'!$F$4:$F$370,$B22,'VS×ケイパビリティ関係'!$G$4:$G$370,F$5,'VS×ケイパビリティ関係'!$E$4:$E$370,"支援")>0,"○","")) | G22: =IF(COUNTIFS('VS×ケイパビリティ関係'!$F$4:$F$370,$B22,'VS×ケイパビリティ関係'!$G$4:$G$370,G$5,'VS×ケイパビリティ関係'!$E$4:$E$370,"主")>0,"●",IF(COUNTIFS('VS×ケイパビリティ関係'!$F$4:$F$370,$B22,'VS×ケイパビリティ関係'!$G$4:$G$370,G$5,'VS×ケイパビリティ関係'!$E$4:$E$370,"支援")>0,"○","")) | H22: =IF(COUNTIFS('VS×ケイパビリティ関係'!$F$4:$F$370,$B22,'VS×ケイパビリティ関係'!$G$4:$G$370,H$5,'VS×ケイパビリティ関係'!$E$4:$E$370,"主")>0,"●",IF(COUNTIFS('VS×ケイパビリティ関係'!$F$4:$F$370,$B22,'VS×ケイパビリティ関係'!$G$4:$G$370,H$5,'VS×ケイパビリティ関係'!$E$4:$E$370,"支援")>0,"○","")) | I22: =IF(COUNTIFS('VS×ケイパビリティ関係'!$F$4:$F$370,$B22,'VS×ケイパビリティ関係'!$G$4:$G$370,I$5,'VS×ケイパビリティ関係'!$E$4:$E$370,"主")>0,"●",IF(COUNTIFS('VS×ケイパビリティ関係'!$F$4:$F$370,$B22,'VS×ケイパビリティ関係'!$G$4:$G$370,I$5,'VS×ケイパビリティ関係'!$E$4:$E$370,"支援")>0,"○","")) | J22: =IF(COUNTIFS('VS×ケイパビリティ関係'!$F$4:$F$370,$B22,'VS×ケイパビリティ関係'!$G$4:$G$370,J$5,'VS×ケイパビリティ関係'!$E$4:$E$370,"主")>0,"●",IF(COUNTIFS('VS×ケイパビリティ関係'!$F$4:$F$370,$B22,'VS×ケイパビリティ関係'!$G$4:$G$370,J$5,'VS×ケイパビリティ関係'!$E$4:$E$370,"支援")>0,"○","")) | K22: =IF(COUNTIFS('VS×ケイパビリティ関係'!$F$4:$F$370,$B22,'VS×ケイパビリティ関係'!$G$4:$G$370,K$5,'VS×ケイパビリティ関係'!$E$4:$E$370,"主")>0,"●",IF(COUNTIFS('VS×ケイパビリティ関係'!$F$4:$F$370,$B22,'VS×ケイパビリティ関係'!$G$4:$G$370,K$5,'VS×ケイパビリティ関係'!$E$4:$E$370,"支援")>0,"○","")) | ... AI22: =IF(COUNTIFS('VS×ケイパビリティ関係'!$F$4:$F$370,$B22,'VS×ケイパビリティ関係'!$G$4:$G$370,AI$5,'VS×ケイパビリティ関係'!$E$4:$E$370,"主")>0,"●",IF(COUNTIFS('VS×ケイパビリティ関係'!$F$4:$F$370,$B22,'VS×ケイパビリティ関係'!$G$4:$G$370,AI$5,'VS×ケイパビリティ関係'!$E$4:$E$370,"支援")>0,"○","")) | AJ22: =COUNTIF(D22:AI22,"●") | AK22: =COUNTIF(D22:AI22,"○")
