Workbook

Sheet 予算一覧
A1: 予算一覧（案件一覧）
A2: 移管対象部門の予算シートに、移管に必要な列を足したもの。1行＝1案件。投資予算と経費予算が混在する案件は行を分ける。移管するのは予算・契約と、契約に基づく間接業務。直接業務は移管対象部門に残る。今年度から続く投資案件（投資の区分＝継続）は対象外で、移管対象部門に残る。移管判定（AL〜AN）は自動（移管／対象外／判定保留／—）。判定保留は入力が足りないことを示す。窓口担当（AY）は事務局が割り当てる。移管ステータス（AP）は窓口担当が更新し、「確認（自動）」に判定との食い違いを表示する。予算は全ての案件で一括移管の実施日に移す。経過措置（AO）は、担当の変更に正式な手続きが要るため、手続きが完了するまで今の担当のまま行う間接業務がある案件に「あり」と表示する。薄い色の行は記入例なので、使うときは削除する。
A3: 基本（移管対象部門の予算シート） | G3: 今年度実績（見込み含む） | T3: 来年度予算 | AG3: 予算移管事務局が記入 | AK3: 移管対象部門から | AL3: 移管判定（自動） | AP3: 移管ステータス | AY3: 予算移管事務局が記入
A4: 案件ID | B4: 案件名 | C4: 案件概要 | D4: 担当者 | E4: コストセンター | F4: 勘定科目 | G4: 1月 | H4: 2月 | I4: 3月 | J4: 4月 | K4: 5月 | L4: 6月 | M4: 7月 | N4: 8月 | O4: 9月 | P4: 10月 | Q4: 11月 | R4: 12月 | S4: 年額 | T4: 1月 | U4: 2月 | V4: 3月 | W4: 4月 | X4: 5月 | Y4: 6月 | Z4: 7月 | AA4: 8月 | AB4: 9月 | AC4: 10月 | AD4: 11月 | AE4: 12月 | AF4: 年額 | AG4: 部門 | AH4: 予算区分 | AI4: 費用の性質 （経費予算のみ） | AJ4: システム関連 | AK4: 移管対象部門のコメント （懸念・条件） | AL4: 予算（自動） | AM4: 契約（自動） | AN4: 間接業務（自動） | AO4: 経過措置（自動） | AP4: 移管ステータス | AQ4: ステータス更新日 | AR4: 確認（自動） | AS4: 紐付けシステム数 | AT4: 業務のないシステム数 | AU4: 棚卸し未了の業務数 | AV4: 契約数 | AW4: 経過措置の業務数 | AY4: 窓口担当 （IT部門） | AZ4: 投資の区分 （投資予算のみ）
A5: BUD-001 | B5: クラウド基盤の利用料（研究本部） | C5: 研究本部が利用しているクラウド環境の利用料と運用委託 | D5: 山田 | E5: CC-4100 | F5: 支払手数料 | G5: 1200000 | H5: 1200000 | I5: 1200000 | J5: 1200000 | K5: 1200000 | L5: 1200000 | M5: 1200000 | N5: 1200000 | O5: 1200000 | P5: 1200000 | Q5: 1200000 | R5: 1200000 | S5: =IF(COUNT(G5:R5)=0,"",SUM(G5:R5)) | T5: 1250000 | U5: 1250000 | V5: 1250000 | W5: 1250000 | X5: 1250000 | Y5: 1250000 | Z5: 1250000 | AA5: 1250000 | AB5: 1250000 | AC5: 1250000 | AD5: 1250000 | AE5: 1250000 | AF5: =IF(COUNT(T5:AE5)=0,"",SUM(T5:AE5)) | AG5: 研究本部 | AH5: 経費予算 | AI5: 変動費 | AJ5: はい | AK5: 基盤の運用は任せたい。構成変更への回答は今までどおり早くしてほしい | AL5: =IF($A5="","",IF(AJ5="いいえ","対象外",IF(AND(AH5="投資予算",AZ5="継続"),"対象外",IF(OR(AH5="",AJ5="",AJ5="未確認",AND(AH5="投資予算",OR(AZ5="",AZ5="未確認")),AM5="判定保留",AN5="判定保留"),"判定保留","移管")))) | AM5: =IF($A5="","",IF(AJ5="いいえ","対象外",IF(AND(AH5="投資予算",AZ5="継続"),"対象外",IF(OR(AJ5="",AJ5="未確認"),"判定保留",IF(AV5=0,"—","移管"))))) | AN5: =IF($A5="","",IF(AJ5="いいえ","対象外",IF(AH5="投資予算","—",IF(OR(AH5="",AJ5="",AJ5="未確認",AS5=0,AT5>0,AU5>0),"判定保留","移管")))) | AO5: =IF($A5="","",IF(AL5<>"移管","—",IF(AW5>0,"あり","なし"))) | AP5: 合意済み | AQ5: 46357 | AR5: =IF($A5="","",IF(AP5="","ステータス未設定",IF(AND(AL5="対象外",AP5<>"対象外"),"判定は対象外",IF(AND(AL5<>"対象外",AP5="対象外"),"判定は対象外ではない",IF(AND(AL5="判定保留",AP5<>"棚卸し中"),"判定保留が残っている",IF(AND(AL5="移管",AP5="棚卸し中"),"判定保留なし（棚卸し済みへ）","")))))) | AS5: =IF($A5="","",COUNTIFS('紐付け'!$A$4:$A$200,$A5,'紐付け'!$C$4:$C$200,"<>")) | AT5: =IF($A5="","",SUMPRODUCT(('紐付け'!$A$4:$A$200=$A5)*('紐付け'!$C$4:$C$200<>"")*(COUNTIFS('業務'!$C$4:$C$200,'紐付け'!$C$4:$C$200,'業務'!$F$4:$F$200,"間接業務",'業務'!$U$4:$U$200,$A5)=0))) | AU5: =IF($A5="","",COUNTIFS('業務'!$U$4:$U$200,$A5,'業務'!$A$4:$A$200,"<>",'業務'!$J$4:$J$200,"<>済")) | AV5: =IF($A5="","",COUNTIF('契約'!$C$4:$C$200,$A5)) | AW5: =IF($A5="","",COUNTIFS('業務'!$U$4:$U$200,$A5,'業務'!$A$4:$A$200,"<>",'業務'!$S$4:$S$200,"<>",'業務'!$F$4:$F$200,"間接業務")) | AY5: （記入例）
A6: BUD-002 | B6: 品質文書システムの保守 | C6: eDMSの保守契約とバリデーション支援 | D6: 佐藤 | E6: CC-3200 | F6: 修繕費 | G6: 0 | H6: 0 | I6: 0 | J6: 4500000 | K6: 0 | L6: 0 | M6: 0 | N6: 0 | O6: 0 | P6: 4500000 | Q6: 0 | R6: 0 | S6: =IF(COUNT(G6:R6)=0,"",SUM(G6:R6)) | T6: 0 | U6: 0 | V6: 0 | W6: 4700000 | X6: 0 | Y6: 0 | Z6: 0 | AA6: 0 | AB6: 0 | AC6: 4700000 | AD6: 0 | AE6: 0 | AF6: =IF(COUNT(T6:AE6)=0,"",SUM(T6:AE6)) | AG6: 品質保証部 | AH6: 経費予算 | AI6: 固定費 | AJ6: はい | AK6: アカウント管理は部門の担当者が行っている。GxPの手順を変えずに引き継いでほしい | AL6: =IF($A6="","",IF(AJ6="いいえ","対象外",IF(AND(AH6="投資予算",AZ6="継続"),"対象外",IF(OR(AH6="",AJ6="",AJ6="未確認",AND(AH6="投資予算",OR(AZ6="",AZ6="未確認")),AM6="判定保留",AN6="判定保留"),"判定保留","移管")))) | AM6: =IF($A6="","",IF(AJ6="いいえ","対象外",IF(AND(AH6="投資予算",AZ6="継続"),"対象外",IF(OR(AJ6="",AJ6="未確認"),"判定保留",IF(AV6=0,"—","移管"))))) | AN6: =IF($A6="","",IF(AJ6="いいえ","対象外",IF(AH6="投資予算","—",IF(OR(AH6="",AJ6="",AJ6="未確認",AS6=0,AT6>0,AU6>0),"判定保留","移管")))) | AO6: =IF($A6="","",IF(AL6<>"移管","—",IF(AW6>0,"あり","なし"))) | AP6: 合意済み | AQ6: 46366 | AR6: =IF($A6="","",IF(AP6="","ステータス未設定",IF(AND(AL6="対象外",AP6<>"対象外"),"判定は対象外",IF(AND(AL6<>"対象外",AP6="対象外"),"判定は対象外ではない",IF(AND(AL6="判定保留",AP6<>"棚卸し中"),"判定保留が残っている",IF(AND(AL6="移管",AP6="棚卸し中"),"判定保留なし（棚卸し済みへ）","")))))) | AS6: =IF($A6="","",COUNTIFS('紐付け'!$A$4:$A$200,$A6,'紐付け'!$C$4:$C$200,"<>")) | AT6: =IF($A6="","",SUMPRODUCT(('紐付け'!$A$4:$A$200=$A6)*('紐付け'!$C$4:$C$200<>"")*(COUNTIFS('業務'!$C$4:$C$200,'紐付け'!$C$4:$C$200,'業務'!$F$4:$F$200,"間接業務",'業務'!$U$4:$U$200,$A6)=0))) | AU6: =IF($A6="","",COUNTIFS('業務'!$U$4:$U$200,$A6,'業務'!$A$4:$A$200,"<>",'業務'!$J$4:$J$200,"<>済")) | AV6: =IF($A6="","",COUNTIF('契約'!$C$4:$C$200,$A6)) | AW6: =IF($A6="","",COUNTIFS('業務'!$U$4:$U$200,$A6,'業務'!$A$4:$A$200,"<>",'業務'!$S$4:$S$200,"<>",'業務'!$F$4:$F$200,"間接業務")) | AY6: （記入例）
A7: BUD-003 | B7: 実験データ集計ツールの改修 | C7: 研究本部だけで使う集計ツールの機能追加 | D7: 鈴木 | E7: CC-4100 | F7: 外注費 | G7: 0 | H7: 0 | I7: 0 | J7: 0 | K7: 0 | L7: 0 | M7: 0 | N7: 0 | O7: 0 | P7: 0 | Q7: 0 | R7: 0 | S7: =IF(COUNT(G7:R7)=0,"",SUM(G7:R7)) | T7: 0 | U7: 0 | V7: 3000000 | W7: 0 | X7: 0 | Y7: 0 | Z7: 0 | AA7: 0 | AB7: 0 | AC7: 0 | AD7: 0 | AE7: 0 | AF7: =IF(COUNT(T7:AE7)=0,"",SUM(T7:AE7)) | AG7: 研究本部 | AH7: 投資予算 | AJ7: はい | AK7: 要件は引き続き部門で決めたい | AL7: =IF($A7="","",IF(AJ7="いいえ","対象外",IF(AND(AH7="投資予算",AZ7="継続"),"対象外",IF(OR(AH7="",AJ7="",AJ7="未確認",AND(AH7="投資予算",OR(AZ7="",AZ7="未確認")),AM7="判定保留",AN7="判定保留"),"判定保留","移管")))) | AM7: =IF($A7="","",IF(AJ7="いいえ","対象外",IF(AND(AH7="投資予算",AZ7="継続"),"対象外",IF(OR(AJ7="",AJ7="未確認"),"判定保留",IF(AV7=0,"—","移管"))))) | AN7: =IF($A7="","",IF(AJ7="いいえ","対象外",IF(AH7="投資予算","—",IF(OR(AH7="",AJ7="",AJ7="未確認",AS7=0,AT7>0,AU7>0),"判定保留","移管")))) | AO7: =IF($A7="","",IF(AL7<>"移管","—",IF(AW7>0,"あり","なし"))) | AP7: 対象外 | AQ7: 46346 | AR7: =IF($A7="","",IF(AP7="","ステータス未設定",IF(AND(AL7="対象外",AP7<>"対象外"),"判定は対象外",IF(AND(AL7<>"対象外",AP7="対象外"),"判定は対象外ではない",IF(AND(AL7="判定保留",AP7<>"棚卸し中"),"判定保留が残っている",IF(AND(AL7="移管",AP7="棚卸し中"),"判定保留なし（棚卸し済みへ）","")))))) | AS7: =IF($A7="","",COUNTIFS('紐付け'!$A$4:$A$200,$A7,'紐付け'!$C$4:$C$200,"<>")) | AT7: =IF($A7="","",SUMPRODUCT(('紐付け'!$A$4:$A$200=$A7)*('紐付け'!$C$4:$C$200<>"")*(COUNTIFS('業務'!$C$4:$C$200,'紐付け'!$C$4:$C$200,'業務'!$F$4:$F$200,"間接業務",'業務'!$U$4:$U$200,$A7)=0))) | AU7: =IF($A7="","",COUNTIFS('業務'!$U$4:$U$200,$A7,'業務'!$A$4:$A$200,"<>",'業務'!$J$4:$J$200,"<>済")) | AV7: =IF($A7="","",COUNTIF('契約'!$C$4:$C$200,$A7)) | AW7: =IF($A7="","",COUNTIFS('業務'!$U$4:$U$200,$A7,'業務'!$A$4:$A$200,"<>",'業務'!$S$4:$S$200,"<>",'業務'!$F$4:$F$200,"間接業務")) | AY7: （記入例） | AZ7: 継続
S8: =IF(COUNT(G8:R8)=0,"",SUM(G8:R8)) | AF8: =IF(COUNT(T8:AE8)=0,"",SUM(T8:AE8)) | AL8: =IF($A8="","",IF(AJ8="いいえ","対象外",IF(AND(AH8="投資予算",AZ8="継続"),"対象外",IF(OR(AH8="",AJ8="",AJ8="未確認",AND(AH8="投資予算",OR(AZ8="",AZ8="未確認")),AM8="判定保留",AN8="判定保留"),"判定保留","移管")))) | AM8: =IF($A8="","",IF(AJ8="いいえ","対象外",IF(AND(AH8="投資予算",AZ8="継続"),"対象外",IF(OR(AJ8="",AJ8="未確認"),"判定保留",IF(AV8=0,"—","移管"))))) | AN8: =IF($A8="","",IF(AJ8="いいえ","対象外",IF(AH8="投資予算","—",IF(OR(AH8="",AJ8="",AJ8="未確認",AS8=0,AT8>0,AU8>0),"判定保留","移管")))) | AO8: =IF($A8="","",IF(AL8<>"移管","—",IF(AW8>0,"あり","なし"))) | AR8: =IF($A8="","",IF(AP8="","ステータス未設定",IF(AND(AL8="対象外",AP8<>"対象外"),"判定は対象外",IF(AND(AL8<>"対象外",AP8="対象外"),"判定は対象外ではない",IF(AND(AL8="判定保留",AP8<>"棚卸し中"),"判定保留が残っている",IF(AND(AL8="移管",AP8="棚卸し中"),"判定保留なし（棚卸し済みへ）","")))))) | AS8: =IF($A8="","",COUNTIFS('紐付け'!$A$4:$A$200,$A8,'紐付け'!$C$4:$C$200,"<>")) | AT8: =IF($A8="","",SUMPRODUCT(('紐付け'!$A$4:$A$200=$A8)*('紐付け'!$C$4:$C$200<>"")*(COUNTIFS('業務'!$C$4:$C$200,'紐付け'!$C$4:$C$200,'業務'!$F$4:$F$200,"間接業務",'業務'!$U$4:$U$200,$A8)=0))) | AU8: =IF($A8="","",COUNTIFS('業務'!$U$4:$U$200,$A8,'業務'!$A$4:$A$200,"<>",'業務'!$J$4:$J$200,"<>済")) | AV8: =IF($A8="","",COUNTIF('契約'!$C$4:$C$200,$A8)) | AW8: =IF($A8="","",COUNTIFS('業務'!$U$4:$U$200,$A8,'業務'!$A$4:$A$200,"<>",'業務'!$S$4:$S$200,"<>",'業務'!$F$4:$F$200,"間接業務"))
S9: =IF(COUNT(G9:R9)=0,"",SUM(G9:R9)) | AF9: =IF(COUNT(T9:AE9)=0,"",SUM(T9:AE9)) | AL9: =IF($A9="","",IF(AJ9="いいえ","対象外",IF(AND(AH9="投資予算",AZ9="継続"),"対象外",IF(OR(AH9="",AJ9="",AJ9="未確認",AND(AH9="投資予算",OR(AZ9="",AZ9="未確認")),AM9="判定保留",AN9="判定保留"),"判定保留","移管")))) | AM9: =IF($A9="","",IF(AJ9="いいえ","対象外",IF(AND(AH9="投資予算",AZ9="継続"),"対象外",IF(OR(AJ9="",AJ9="未確認"),"判定保留",IF(AV9=0,"—","移管"))))) | AN9: =IF($A9="","",IF(AJ9="いいえ","対象外",IF(AH9="投資予算","—",IF(OR(AH9="",AJ9="",AJ9="未確認",AS9=0,AT9>0,AU9>0),"判定保留","移管")))) | AO9: =IF($A9="","",IF(AL9<>"移管","—",IF(AW9>0,"あり","なし"))) | AR9: =IF($A9="","",IF(AP9="","ステータス未設定",IF(AND(AL9="対象外",AP9<>"対象外"),"判定は対象外",IF(AND(AL9<>"対象外",AP9="対象外"),"判定は対象外ではない",IF(AND(AL9="判定保留",AP9<>"棚卸し中"),"判定保留が残っている",IF(AND(AL9="移管",AP9="棚卸し中"),"判定保留なし（棚卸し済みへ）","")))))) | AS9: =IF($A9="","",COUNTIFS('紐付け'!$A$4:$A$200,$A9,'紐付け'!$C$4:$C$200,"<>")) | AT9: =IF($A9="","",SUMPRODUCT(('紐付け'!$A$4:$A$200=$A9)*('紐付け'!$C$4:$C$200<>"")*(COUNTIFS('業務'!$C$4:$C$200,'紐付け'!$C$4:$C$200,'業務'!$F$4:$F$200,"間接業務",'業務'!$U$4:$U$200,$A9)=0))) | AU9: =IF($A9="","",COUNTIFS('業務'!$U$4:$U$200,$A9,'業務'!$A$4:$A$200,"<>",'業務'!$J$4:$J$200,"<>済")) | AV9: =IF($A9="","",COUNTIF('契約'!$C$4:$C$200,$A9)) | AW9: =IF($A9="","",COUNTIFS('業務'!$U$4:$U$200,$A9,'業務'!$A$4:$A$200,"<>",'業務'!$S$4:$S$200,"<>",'業務'!$F$4:$F$200,"間接業務"))
S10: =IF(COUNT(G10:R10)=0,"",SUM(G10:R10)) | AF10: =IF(COUNT(T10:AE10)=0,"",SUM(T10:AE10)) | AL10: =IF($A10="","",IF(AJ10="いいえ","対象外",IF(AND(AH10="投資予算",AZ10="継続"),"対象外",IF(OR(AH10="",AJ10="",AJ10="未確認",AND(AH10="投資予算",OR(AZ10="",AZ10="未確認")),AM10="判定保留",AN10="判定保留"),"判定保留","移管")))) | AM10: =IF($A10="","",IF(AJ10="いいえ","対象外",IF(AND(AH10="投資予算",AZ10="継続"),"対象外",IF(OR(AJ10="",AJ10="未確認"),"判定保留",IF(AV10=0,"—","移管"))))) | AN10: =IF($A10="","",IF(AJ10="いいえ","対象外",IF(AH10="投資予算","—",IF(OR(AH10="",AJ10="",AJ10="未確認",AS10=0,AT10>0,AU10>0),"判定保留","移管")))) | AO10: =IF($A10="","",IF(AL10<>"移管","—",IF(AW10>0,"あり","なし"))) | AR10: =IF($A10="","",IF(AP10="","ステータス未設定",IF(AND(AL10="対象外",AP10<>"対象外"),"判定は対象外",IF(AND(AL10<>"対象外",AP10="対象外"),"判定は対象外ではない",IF(AND(AL10="判定保留",AP10<>"棚卸し中"),"判定保留が残っている",IF(AND(AL10="移管",AP10="棚卸し中"),"判定保留なし（棚卸し済みへ）","")))))) | AS10: =IF($A10="","",COUNTIFS('紐付け'!$A$4:$A$200,$A10,'紐付け'!$C$4:$C$200,"<>")) | AT10: =IF($A10="","",SUMPRODUCT(('紐付け'!$A$4:$A$200=$A10)*('紐付け'!$C$4:$C$200<>"")*(COUNTIFS('業務'!$C$4:$C$200,'紐付け'!$C$4:$C$200,'業務'!$F$4:$F$200,"間接業務",'業務'!$U$4:$U$200,$A10)=0))) | AU10: =IF($A10="","",COUNTIFS('業務'!$U$4:$U$200,$A10,'業務'!$A$4:$A$200,"<>",'業務'!$J$4:$J$200,"<>済")) | AV10: =IF($A10="","",COUNTIF('契約'!$C$4:$C$200,$A10)) | AW10: =IF($A10="","",COUNTIFS('業務'!$U$4:$U$200,$A10,'業務'!$A$4:$A$200,"<>",'業務'!$S$4:$S$200,"<>",'業務'!$F$4:$F$200,"間接業務"))
S11: =IF(COUNT(G11:R11)=0,"",SUM(G11:R11)) | AF11: =IF(COUNT(T11:AE11)=0,"",SUM(T11:AE11)) | AL11: =IF($A11="","",IF(AJ11="いいえ","対象外",IF(AND(AH11="投資予算",AZ11="継続"),"対象外",IF(OR(AH11="",AJ11="",AJ11="未確認",AND(AH11="投資予算",OR(AZ11="",AZ11="未確認")),AM11="判定保留",AN11="判定保留"),"判定保留","移管")))) | AM11: =IF($A11="","",IF(AJ11="いいえ","対象外",IF(AND(AH11="投資予算",AZ11="継続"),"対象外",IF(OR(AJ11="",AJ11="未確認"),"判定保留",IF(AV11=0,"—","移管"))))) | AN11: =IF($A11="","",IF(AJ11="いいえ","対象外",IF(AH11="投資予算","—",IF(OR(AH11="",AJ11="",AJ11="未確認",AS11=0,AT11>0,AU11>0),"判定保留","移管")))) | AO11: =IF($A11="","",IF(AL11<>"移管","—",IF(AW11>0,"あり","なし"))) | AR11: =IF($A11="","",IF(AP11="","ステータス未設定",IF(AND(AL11="対象外",AP11<>"対象外"),"判定は対象外",IF(AND(AL11<>"対象外",AP11="対象外"),"判定は対象外ではない",IF(AND(AL11="判定保留",AP11<>"棚卸し中"),"判定保留が残っている",IF(AND(AL11="移管",AP11="棚卸し中"),"判定保留なし（棚卸し済みへ）","")))))) | AS11: =IF($A11="","",COUNTIFS('紐付け'!$A$4:$A$200,$A11,'紐付け'!$C$4:$C$200,"<>")) | AT11: =IF($A11="","",SUMPRODUCT(('紐付け'!$A$4:$A$200=$A11)*('紐付け'!$C$4:$C$200<>"")*(COUNTIFS('業務'!$C$4:$C$200,'紐付け'!$C$4:$C$200,'業務'!$F$4:$F$200,"間接業務",'業務'!$U$4:$U$200,$A11)=0))) | AU11: =IF($A11="","",COUNTIFS('業務'!$U$4:$U$200,$A11,'業務'!$A$4:$A$200,"<>",'業務'!$J$4:$J$200,"<>済")) | AV11: =IF($A11="","",COUNTIF('契約'!$C$4:$C$200,$A11)) | AW11: =IF($A11="","",COUNTIFS('業務'!$U$4:$U$200,$A11,'業務'!$A$4:$A$200,"<>",'業務'!$S$4:$S$200,"<>",'業務'!$F$4:$F$200,"間接業務"))
S12: =IF(COUNT(G12:R12)=0,"",SUM(G12:R12)) | AF12: =IF(COUNT(T12:AE12)=0,"",SUM(T12:AE12)) | AL12: =IF($A12="","",IF(AJ12="いいえ","対象外",IF(AND(AH12="投資予算",AZ12="継続"),"対象外",IF(OR(AH12="",AJ12="",AJ12="未確認",AND(AH12="投資予算",OR(AZ12="",AZ12="未確認")),AM12="判定保留",AN12="判定保留"),"判定保留","移管")))) | AM12: =IF($A12="","",IF(AJ12="いいえ","対象外",IF(AND(AH12="投資予算",AZ12="継続"),"対象外",IF(OR(AJ12="",AJ12="未確認"),"判定保留",IF(AV12=0,"—","移管"))))) | AN12: =IF($A12="","",IF(AJ12="いいえ","対象外",IF(AH12="投資予算","—",IF(OR(AH12="",AJ12="",AJ12="未確認",AS12=0,AT12>0,AU12>0),"判定保留","移管")))) | AO12: =IF($A12="","",IF(AL12<>"移管","—",IF(AW12>0,"あり","なし"))) | AR12: =IF($A12="","",IF(AP12="","ステータス未設定",IF(AND(AL12="対象外",AP12<>"対象外"),"判定は対象外",IF(AND(AL12<>"対象外",AP12="対象外"),"判定は対象外ではない",IF(AND(AL12="判定保留",AP12<>"棚卸し中"),"判定保留が残っている",IF(AND(AL12="移管",AP12="棚卸し中"),"判定保留なし（棚卸し済みへ）","")))))) | AS12: =IF($A12="","",COUNTIFS('紐付け'!$A$4:$A$200,$A12,'紐付け'!$C$4:$C$200,"<>")) | AT12: =IF($A12="","",SUMPRODUCT(('紐付け'!$A$4:$A$200=$A12)*('紐付け'!$C$4:$C$200<>"")*(COUNTIFS('業務'!$C$4:$C$200,'紐付け'!$C$4:$C$200,'業務'!$F$4:$F$200,"間接業務",'業務'!$U$4:$U$200,$A12)=0))) | AU12: =IF($A12="","",COUNTIFS('業務'!$U$4:$U$200,$A12,'業務'!$A$4:$A$200,"<>",'業務'!$J$4:$J$200,"<>済")) | AV12: =IF($A12="","",COUNTIF('契約'!$C$4:$C$200,$A12)) | AW12: =IF($A12="","",COUNTIFS('業務'!$U$4:$U$200,$A12,'業務'!$A$4:$A$200,"<>",'業務'!$S$4:$S$200,"<>",'業務'!$F$4:$F$200,"間接業務"))
S13: =IF(COUNT(G13:R13)=0,"",SUM(G13:R13)) | AF13: =IF(COUNT(T13:AE13)=0,"",SUM(T13:AE13)) | AL13: =IF($A13="","",IF(AJ13="いいえ","対象外",IF(AND(AH13="投資予算",AZ13="継続"),"対象外",IF(OR(AH13="",AJ13="",AJ13="未確認",AND(AH13="投資予算",OR(AZ13="",AZ13="未確認")),AM13="判定保留",AN13="判定保留"),"判定保留","移管")))) | AM13: =IF($A13="","",IF(AJ13="いいえ","対象外",IF(AND(AH13="投資予算",AZ13="継続"),"対象外",IF(OR(AJ13="",AJ13="未確認"),"判定保留",IF(AV13=0,"—","移管"))))) | AN13: =IF($A13="","",IF(AJ13="いいえ","対象外",IF(AH13="投資予算","—",IF(OR(AH13="",AJ13="",AJ13="未確認",AS13=0,AT13>0,AU13>0),"判定保留","移管")))) | AO13: =IF($A13="","",IF(AL13<>"移管","—",IF(AW13>0,"あり","なし"))) | AR13: =IF($A13="","",IF(AP13="","ステータス未設定",IF(AND(AL13="対象外",AP13<>"対象外"),"判定は対象外",IF(AND(AL13<>"対象外",AP13="対象外"),"判定は対象外ではない",IF(AND(AL13="判定保留",AP13<>"棚卸し中"),"判定保留が残っている",IF(AND(AL13="移管",AP13="棚卸し中"),"判定保留なし（棚卸し済みへ）","")))))) | AS13: =IF($A13="","",COUNTIFS('紐付け'!$A$4:$A$200,$A13,'紐付け'!$C$4:$C$200,"<>")) | AT13: =IF($A13="","",SUMPRODUCT(('紐付け'!$A$4:$A$200=$A13)*('紐付け'!$C$4:$C$200<>"")*(COUNTIFS('業務'!$C$4:$C$200,'紐付け'!$C$4:$C$200,'業務'!$F$4:$F$200,"間接業務",'業務'!$U$4:$U$200,$A13)=0))) | AU13: =IF($A13="","",COUNTIFS('業務'!$U$4:$U$200,$A13,'業務'!$A$4:$A$200,"<>",'業務'!$J$4:$J$200,"<>済")) | AV13: =IF($A13="","",COUNTIF('契約'!$C$4:$C$200,$A13)) | AW13: =IF($A13="","",COUNTIFS('業務'!$U$4:$U$200,$A13,'業務'!$A$4:$A$200,"<>",'業務'!$S$4:$S$200,"<>",'業務'!$F$4:$F$200,"間接業務"))
S14: =IF(COUNT(G14:R14)=0,"",SUM(G14:R14)) | AF14: =IF(COUNT(T14:AE14)=0,"",SUM(T14:AE14)) | AL14: =IF($A14="","",IF(AJ14="いいえ","対象外",IF(AND(AH14="投資予算",AZ14="継続"),"対象外",IF(OR(AH14="",AJ14="",AJ14="未確認",AND(AH14="投資予算",OR(AZ14="",AZ14="未確認")),AM14="判定保留",AN14="判定保留"),"判定保留","移管")))) | AM14: =IF($A14="","",IF(AJ14="いいえ","対象外",IF(AND(AH14="投資予算",AZ14="継続"),"対象外",IF(OR(AJ14="",AJ14="未確認"),"判定保留",IF(AV14=0,"—","移管"))))) | AN14: =IF($A14="","",IF(AJ14="いいえ","対象外",IF(AH14="投資予算","—",IF(OR(AH14="",AJ14="",AJ14="未確認",AS14=0,AT14>0,AU14>0),"判定保留","移管")))) | AO14: =IF($A14="","",IF(AL14<>"移管","—",IF(AW14>0,"あり","なし"))) | AR14: =IF($A14="","",IF(AP14="","ステータス未設定",IF(AND(AL14="対象外",AP14<>"対象外"),"判定は対象外",IF(AND(AL14<>"対象外",AP14="対象外"),"判定は対象外ではない",IF(AND(AL14="判定保留",AP14<>"棚卸し中"),"判定保留が残っている",IF(AND(AL14="移管",AP14="棚卸し中"),"判定保留なし（棚卸し済みへ）","")))))) | AS14: =IF($A14="","",COUNTIFS('紐付け'!$A$4:$A$200,$A14,'紐付け'!$C$4:$C$200,"<>")) | AT14: =IF($A14="","",SUMPRODUCT(('紐付け'!$A$4:$A$200=$A14)*('紐付け'!$C$4:$C$200<>"")*(COUNTIFS('業務'!$C$4:$C$200,'紐付け'!$C$4:$C$200,'業務'!$F$4:$F$200,"間接業務",'業務'!$U$4:$U$200,$A14)=0))) | AU14: =IF($A14="","",COUNTIFS('業務'!$U$4:$U$200,$A14,'業務'!$A$4:$A$200,"<>",'業務'!$J$4:$J$200,"<>済")) | AV14: =IF($A14="","",COUNTIF('契約'!$C$4:$C$200,$A14)) | AW14: =IF($A14="","",COUNTIFS('業務'!$U$4:$U$200,$A14,'業務'!$A$4:$A$200,"<>",'業務'!$S$4:$S$200,"<>",'業務'!$F$4:$F$200,"間接業務"))
S15: =IF(COUNT(G15:R15)=0,"",SUM(G15:R15)) | AF15: =IF(COUNT(T15:AE15)=0,"",SUM(T15:AE15)) | AL15: =IF($A15="","",IF(AJ15="いいえ","対象外",IF(AND(AH15="投資予算",AZ15="継続"),"対象外",IF(OR(AH15="",AJ15="",AJ15="未確認",AND(AH15="投資予算",OR(AZ15="",AZ15="未確認")),AM15="判定保留",AN15="判定保留"),"判定保留","移管")))) | AM15: =IF($A15="","",IF(AJ15="いいえ","対象外",IF(AND(AH15="投資予算",AZ15="継続"),"対象外",IF(OR(AJ15="",AJ15="未確認"),"判定保留",IF(AV15=0,"—","移管"))))) | AN15: =IF($A15="","",IF(AJ15="いいえ","対象外",IF(AH15="投資予算","—",IF(OR(AH15="",AJ15="",AJ15="未確認",AS15=0,AT15>0,AU15>0),"判定保留","移管")))) | AO15: =IF($A15="","",IF(AL15<>"移管","—",IF(AW15>0,"あり","なし"))) | AR15: =IF($A15="","",IF(AP15="","ステータス未設定",IF(AND(AL15="対象外",AP15<>"対象外"),"判定は対象外",IF(AND(AL15<>"対象外",AP15="対象外"),"判定は対象外ではない",IF(AND(AL15="判定保留",AP15<>"棚卸し中"),"判定保留が残っている",IF(AND(AL15="移管",AP15="棚卸し中"),"判定保留なし（棚卸し済みへ）","")))))) | AS15: =IF($A15="","",COUNTIFS('紐付け'!$A$4:$A$200,$A15,'紐付け'!$C$4:$C$200,"<>")) | AT15: =IF($A15="","",SUMPRODUCT(('紐付け'!$A$4:$A$200=$A15)*('紐付け'!$C$4:$C$200<>"")*(COUNTIFS('業務'!$C$4:$C$200,'紐付け'!$C$4:$C$200,'業務'!$F$4:$F$200,"間接業務",'業務'!$U$4:$U$200,$A15)=0))) | AU15: =IF($A15="","",COUNTIFS('業務'!$U$4:$U$200,$A15,'業務'!$A$4:$A$200,"<>",'業務'!$J$4:$J$200,"<>済")) | AV15: =IF($A15="","",COUNTIF('契約'!$C$4:$C$200,$A15)) | AW15: =IF($A15="","",COUNTIFS('業務'!$U$4:$U$200,$A15,'業務'!$A$4:$A$200,"<>",'業務'!$S$4:$S$200,"<>",'業務'!$F$4:$F$200,"間接業務"))
S16: =IF(COUNT(G16:R16)=0,"",SUM(G16:R16)) | AF16: =IF(COUNT(T16:AE16)=0,"",SUM(T16:AE16)) | AL16: =IF($A16="","",IF(AJ16="いいえ","対象外",IF(AND(AH16="投資予算",AZ16="継続"),"対象外",IF(OR(AH16="",AJ16="",AJ16="未確認",AND(AH16="投資予算",OR(AZ16="",AZ16="未確認")),AM16="判定保留",AN16="判定保留"),"判定保留","移管")))) | AM16: =IF($A16="","",IF(AJ16="いいえ","対象外",IF(AND(AH16="投資予算",AZ16="継続"),"対象外",IF(OR(AJ16="",AJ16="未確認"),"判定保留",IF(AV16=0,"—","移管"))))) | AN16: =IF($A16="","",IF(AJ16="いいえ","対象外",IF(AH16="投資予算","—",IF(OR(AH16="",AJ16="",AJ16="未確認",AS16=0,AT16>0,AU16>0),"判定保留","移管")))) | AO16: =IF($A16="","",IF(AL16<>"移管","—",IF(AW16>0,"あり","なし"))) | AR16: =IF($A16="","",IF(AP16="","ステータス未設定",IF(AND(AL16="対象外",AP16<>"対象外"),"判定は対象外",IF(AND(AL16<>"対象外",AP16="対象外"),"判定は対象外ではない",IF(AND(AL16="判定保留",AP16<>"棚卸し中"),"判定保留が残っている",IF(AND(AL16="移管",AP16="棚卸し中"),"判定保留なし（棚卸し済みへ）","")))))) | AS16: =IF($A16="","",COUNTIFS('紐付け'!$A$4:$A$200,$A16,'紐付け'!$C$4:$C$200,"<>")) | AT16: =IF($A16="","",SUMPRODUCT(('紐付け'!$A$4:$A$200=$A16)*('紐付け'!$C$4:$C$200<>"")*(COUNTIFS('業務'!$C$4:$C$200,'紐付け'!$C$4:$C$200,'業務'!$F$4:$F$200,"間接業務",'業務'!$U$4:$U$200,$A16)=0))) | AU16: =IF($A16="","",COUNTIFS('業務'!$U$4:$U$200,$A16,'業務'!$A$4:$A$200,"<>",'業務'!$J$4:$J$200,"<>済")) | AV16: =IF($A16="","",COUNTIF('契約'!$C$4:$C$200,$A16)) | AW16: =IF($A16="","",COUNTIFS('業務'!$U$4:$U$200,$A16,'業務'!$A$4:$A$200,"<>",'業務'!$S$4:$S$200,"<>",'業務'!$F$4:$F$200,"間接業務"))
S17: =IF(COUNT(G17:R17)=0,"",SUM(G17:R17)) | AF17: =IF(COUNT(T17:AE17)=0,"",SUM(T17:AE17)) | AL17: =IF($A17="","",IF(AJ17="いいえ","対象外",IF(AND(AH17="投資予算",AZ17="継続"),"対象外",IF(OR(AH17="",AJ17="",AJ17="未確認",AND(AH17="投資予算",OR(AZ17="",AZ17="未確認")),AM17="判定保留",AN17="判定保留"),"判定保留","移管")))) | AM17: =IF($A17="","",IF(AJ17="いいえ","対象外",IF(AND(AH17="投資予算",AZ17="継続"),"対象外",IF(OR(AJ17="",AJ17="未確認"),"判定保留",IF(AV17=0,"—","移管"))))) | AN17: =IF($A17="","",IF(AJ17="いいえ","対象外",IF(AH17="投資予算","—",IF(OR(AH17="",AJ17="",AJ17="未確認",AS17=0,AT17>0,AU17>0),"判定保留","移管")))) | AO17: =IF($A17="","",IF(AL17<>"移管","—",IF(AW17>0,"あり","なし"))) | AR17: =IF($A17="","",IF(AP17="","ステータス未設定",IF(AND(AL17="対象外",AP17<>"対象外"),"判定は対象外",IF(AND(AL17<>"対象外",AP17="対象外"),"判定は対象外ではない",IF(AND(AL17="判定保留",AP17<>"棚卸し中"),"判定保留が残っている",IF(AND(AL17="移管",AP17="棚卸し中"),"判定保留なし（棚卸し済みへ）","")))))) | AS17: =IF($A17="","",COUNTIFS('紐付け'!$A$4:$A$200,$A17,'紐付け'!$C$4:$C$200,"<>")) | AT17: =IF($A17="","",SUMPRODUCT(('紐付け'!$A$4:$A$200=$A17)*('紐付け'!$C$4:$C$200<>"")*(COUNTIFS('業務'!$C$4:$C$200,'紐付け'!$C$4:$C$200,'業務'!$F$4:$F$200,"間接業務",'業務'!$U$4:$U$200,$A17)=0))) | AU17: =IF($A17="","",COUNTIFS('業務'!$U$4:$U$200,$A17,'業務'!$A$4:$A$200,"<>",'業務'!$J$4:$J$200,"<>済")) | AV17: =IF($A17="","",COUNTIF('契約'!$C$4:$C$200,$A17)) | AW17: =IF($A17="","",COUNTIFS('業務'!$U$4:$U$200,$A17,'業務'!$A$4:$A$200,"<>",'業務'!$S$4:$S$200,"<>",'業務'!$F$4:$F$200,"間接業務"))
S18: =IF(COUNT(G18:R18)=0,"",SUM(G18:R18)) | AF18: =IF(COUNT(T18:AE18)=0,"",SUM(T18:AE18)) | AL18: =IF($A18="","",IF(AJ18="いいえ","対象外",IF(AND(AH18="投資予算",AZ18="継続"),"対象外",IF(OR(AH18="",AJ18="",AJ18="未確認",AND(AH18="投資予算",OR(AZ18="",AZ18="未確認")),AM18="判定保留",AN18="判定保留"),"判定保留","移管")))) | AM18: =IF($A18="","",IF(AJ18="いいえ","対象外",IF(AND(AH18="投資予算",AZ18="継続"),"対象外",IF(OR(AJ18="",AJ18="未確認"),"判定保留",IF(AV18=0,"—","移管"))))) | AN18: =IF($A18="","",IF(AJ18="いいえ","対象外",IF(AH18="投資予算","—",IF(OR(AH18="",AJ18="",AJ18="未確認",AS18=0,AT18>0,AU18>0),"判定保留","移管")))) | AO18: =IF($A18="","",IF(AL18<>"移管","—",IF(AW18>0,"あり","なし"))) | AR18: =IF($A18="","",IF(AP18="","ステータス未設定",IF(AND(AL18="対象外",AP18<>"対象外"),"判定は対象外",IF(AND(AL18<>"対象外",AP18="対象外"),"判定は対象外ではない",IF(AND(AL18="判定保留",AP18<>"棚卸し中"),"判定保留が残っている",IF(AND(AL18="移管",AP18="棚卸し中"),"判定保留なし（棚卸し済みへ）","")))))) | AS18: =IF($A18="","",COUNTIFS('紐付け'!$A$4:$A$200,$A18,'紐付け'!$C$4:$C$200,"<>")) | AT18: =IF($A18="","",SUMPRODUCT(('紐付け'!$A$4:$A$200=$A18)*('紐付け'!$C$4:$C$200<>"")*(COUNTIFS('業務'!$C$4:$C$200,'紐付け'!$C$4:$C$200,'業務'!$F$4:$F$200,"間接業務",'業務'!$U$4:$U$200,$A18)=0))) | AU18: =IF($A18="","",COUNTIFS('業務'!$U$4:$U$200,$A18,'業務'!$A$4:$A$200,"<>",'業務'!$J$4:$J$200,"<>済")) | AV18: =IF($A18="","",COUNTIF('契約'!$C$4:$C$200,$A18)) | AW18: =IF($A18="","",COUNTIFS('業務'!$U$4:$U$200,$A18,'業務'!$A$4:$A$200,"<>",'業務'!$S$4:$S$200,"<>",'業務'!$F$4:$F$200,"間接業務"))
S19: =IF(COUNT(G19:R19)=0,"",SUM(G19:R19)) | AF19: =IF(COUNT(T19:AE19)=0,"",SUM(T19:AE19)) | AL19: =IF($A19="","",IF(AJ19="いいえ","対象外",IF(AND(AH19="投資予算",AZ19="継続"),"対象外",IF(OR(AH19="",AJ19="",AJ19="未確認",AND(AH19="投資予算",OR(AZ19="",AZ19="未確認")),AM19="判定保留",AN19="判定保留"),"判定保留","移管")))) | AM19: =IF($A19="","",IF(AJ19="いいえ","対象外",IF(AND(AH19="投資予算",AZ19="継続"),"対象外",IF(OR(AJ19="",AJ19="未確認"),"判定保留",IF(AV19=0,"—","移管"))))) | AN19: =IF($A19="","",IF(AJ19="いいえ","対象外",IF(AH19="投資予算","—",IF(OR(AH19="",AJ19="",AJ19="未確認",AS19=0,AT19>0,AU19>0),"判定保留","移管")))) | AO19: =IF($A19="","",IF(AL19<>"移管","—",IF(AW19>0,"あり","なし"))) | AR19: =IF($A19="","",IF(AP19="","ステータス未設定",IF(AND(AL19="対象外",AP19<>"対象外"),"判定は対象外",IF(AND(AL19<>"対象外",AP19="対象外"),"判定は対象外ではない",IF(AND(AL19="判定保留",AP19<>"棚卸し中"),"判定保留が残っている",IF(AND(AL19="移管",AP19="棚卸し中"),"判定保留なし（棚卸し済みへ）","")))))) | AS19: =IF($A19="","",COUNTIFS('紐付け'!$A$4:$A$200,$A19,'紐付け'!$C$4:$C$200,"<>")) | AT19: =IF($A19="","",SUMPRODUCT(('紐付け'!$A$4:$A$200=$A19)*('紐付け'!$C$4:$C$200<>"")*(COUNTIFS('業務'!$C$4:$C$200,'紐付け'!$C$4:$C$200,'業務'!$F$4:$F$200,"間接業務",'業務'!$U$4:$U$200,$A19)=0))) | AU19: =IF($A19="","",COUNTIFS('業務'!$U$4:$U$200,$A19,'業務'!$A$4:$A$200,"<>",'業務'!$J$4:$J$200,"<>済")) | AV19: =IF($A19="","",COUNTIF('契約'!$C$4:$C$200,$A19)) | AW19: =IF($A19="","",COUNTIFS('業務'!$U$4:$U$200,$A19,'業務'!$A$4:$A$200,"<>",'業務'!$S$4:$S$200,"<>",'業務'!$F$4:$F$200,"間接業務"))
... S200: =IF(COUNT(G200:R200)=0,"",SUM(G200:R200)) | AF200: =IF(COUNT(T200:AE200)=0,"",SUM(T200:AE200)) | AL200: =IF($A200="","",IF(AJ200="いいえ","対象外",IF(AND(AH200="投資予算",AZ200="継続"),"対象外",IF(OR(AH200="",AJ200="",AJ200="未確認",AND(AH200="投資予算",OR(AZ200="",AZ200="未確認")),AM200="判定保留",AN200="判定保留"),"判定保留","移管")))) | AM200: =IF($A200="","",IF(AJ200="いいえ","対象外",IF(AND(AH200="投資予算",AZ200="継続"),"対象外",IF(OR(AJ200="",AJ200="未確認"),"判定保留",IF(AV200=0,"—","移管"))))) | AN200: =IF($A200="","",IF(AJ200="いいえ","対象外",IF(AH200="投資予算","—",IF(OR(AH200="",AJ200="",AJ200="未確認",AS200=0,AT200>0,AU200>0),"判定保留","移管")))) | AO200: =IF($A200="","",IF(AL200<>"移管","—",IF(AW200>0,"あり","なし"))) | AR200: =IF($A200="","",IF(AP200="","ステータス未設定",IF(AND(AL200="対象外",AP200<>"対象外"),"判定は対象外",IF(AND(AL200<>"対象外",AP200="対象外"),"判定は対象外ではない",IF(AND(AL200="判定保留",AP200<>"棚卸し中"),"判定保留が残っている",IF(AND(AL200="移管",AP200="棚卸し中"),"判定保留なし（棚卸し済みへ）","")))))) | AS200: =IF($A200="","",COUNTIFS('紐付け'!$A$4:$A$200,$A200,'紐付け'!$C$4:$C$200,"<>")) | AT200: =IF($A200="","",SUMPRODUCT(('紐付け'!$A$4:$A$200=$A200)*('紐付け'!$C$4:$C$200<>"")*(COUNTIFS('業務'!$C$4:$C$200,'紐付け'!$C$4:$C$200,'業務'!$F$4:$F$200,"間接業務",'業務'!$U$4:$U$200,$A200)=0))) | AU200: =IF($A200="","",COUNTIFS('業務'!$U$4:$U$200,$A200,'業務'!$A$4:$A$200,"<>",'業務'!$J$4:$J$200,"<>済")) | AV200: =IF($A200="","",COUNTIF('契約'!$C$4:$C$200,$A200)) | AW200: =IF($A200="","",COUNTIFS('業務'!$U$4:$U$200,$A200,'業務'!$A$4:$A$200,"<>",'業務'!$S$4:$S$200,"<>",'業務'!$F$4:$F$200,"間接業務"))

Sheet モニタリング
A1: モニタリング（自動）
A2: 予算一覧の移管ステータスと移管判定、進捗シートの役割別のタスクを集計する。数式なので編集しない。記入例の行を削除してから使う。
A3: 1. 移管ステータス別
A4: 移管ステータス | B4: 案件数 | C4: 来年度予算（年額）
A5: 棚卸し中 | B5: =COUNTIFS('予算一覧'!$AP$5:$AP$200,A5,'予算一覧'!$A$5:$A$200,"<>") | C5: =SUMIFS('予算一覧'!$AF$5:$AF$200,'予算一覧'!$AP$5:$AP$200,A5,'予算一覧'!$A$5:$A$200,"<>")
A6: 棚卸し済み | B6: =COUNTIFS('予算一覧'!$AP$5:$AP$200,A6,'予算一覧'!$A$5:$A$200,"<>") | C6: =SUMIFS('予算一覧'!$AF$5:$AF$200,'予算一覧'!$AP$5:$AP$200,A6,'予算一覧'!$A$5:$A$200,"<>")
A7: 合意済み | B7: =COUNTIFS('予算一覧'!$AP$5:$AP$200,A7,'予算一覧'!$A$5:$A$200,"<>") | C7: =SUMIFS('予算一覧'!$AF$5:$AF$200,'予算一覧'!$AP$5:$AP$200,A7,'予算一覧'!$A$5:$A$200,"<>")
A8: 準備完了 | B8: =COUNTIFS('予算一覧'!$AP$5:$AP$200,A8,'予算一覧'!$A$5:$A$200,"<>") | C8: =SUMIFS('予算一覧'!$AF$5:$AF$200,'予算一覧'!$AP$5:$AP$200,A8,'予算一覧'!$A$5:$A$200,"<>")
A9: 対象外 | B9: =COUNTIFS('予算一覧'!$AP$5:$AP$200,A9,'予算一覧'!$A$5:$A$200,"<>") | C9: =SUMIFS('予算一覧'!$AF$5:$AF$200,'予算一覧'!$AP$5:$AP$200,A9,'予算一覧'!$A$5:$A$200,"<>")
A10: 未設定 | B10: =COUNTIFS('予算一覧'!$A$5:$A$200,"<>",'予算一覧'!$AP$5:$AP$200,"") | C10: =SUMIFS('予算一覧'!$AF$5:$AF$200,'予算一覧'!$A$5:$A$200,"<>",'予算一覧'!$AP$5:$AP$200,"")
A11: 合計 | B11: =SUM(B5:B10) | C11: =SUM(C5:C10)
A15: 2. 移管判定別
A16: 移管判定 | B16: 案件数 | C16: 来年度予算（年額）
A17: 移管 | B17: =COUNTIF('予算一覧'!$AL$5:$AL$200,"移管") | C17: =SUMIFS('予算一覧'!$AF$5:$AF$200,'予算一覧'!$AL$5:$AL$200,"移管")
A18: うち経過措置あり | B18: =COUNTIFS('予算一覧'!$AL$5:$AL$200,"移管",'予算一覧'!$AO$5:$AO$200,"あり") | C18: =SUMIFS('予算一覧'!$AF$5:$AF$200,'予算一覧'!$AL$5:$AL$200,"移管",'予算一覧'!$AO$5:$AO$200,"あり")
A19: 対象外 | B19: =COUNTIF('予算一覧'!$AL$5:$AL$200,"対象外") | C19: =SUMIFS('予算一覧'!$AF$5:$AF$200,'予算一覧'!$AL$5:$AL$200,"対象外")
A20: 判定保留 | B20: =COUNTIF('予算一覧'!$AL$5:$AL$200,"判定保留") | C20: =SUMIFS('予算一覧'!$AF$5:$AF$200,'予算一覧'!$AL$5:$AL$200,"判定保留")
A22: 3. 部門別の移管ステータス（案件数）
A23: 部門 | B23: 棚卸し中 | C23: 棚卸し済み | D23: 合意済み | E23: 準備完了 | F23: 対象外 | G23: 未設定 | H23: 判定保留
A24: =IF('窓口'!A4="","",'窓口'!A4) | B24: =IF($A24="","",COUNTIFS('予算一覧'!$AG$5:$AG$200,$A24,'予算一覧'!$AP$5:$AP$200,"棚卸し中")) | C24: =IF($A24="","",COUNTIFS('予算一覧'!$AG$5:$AG$200,$A24,'予算一覧'!$AP$5:$AP$200,"棚卸し済み")) | D24: =IF($A24="","",COUNTIFS('予算一覧'!$AG$5:$AG$200,$A24,'予算一覧'!$AP$5:$AP$200,"合意済み")) | E24: =IF($A24="","",COUNTIFS('予算一覧'!$AG$5:$AG$200,$A24,'予算一覧'!$AP$5:$AP$200,"準備完了")) | F24: =IF($A24="","",COUNTIFS('予算一覧'!$AG$5:$AG$200,$A24,'予算一覧'!$AP$5:$AP$200,"対象外")) | G24: =IF($A24="","",COUNTIFS('予算一覧'!$AG$5:$AG$200,$A24,'予算一覧'!$AP$5:$AP$200,"")) | H24: =IF($A24="","",COUNTIFS('予算一覧'!$AG$5:$AG$200,$A24,'予算一覧'!$AL$5:$AL$200,"判定保留"))
A25: =IF('窓口'!A5="","",'窓口'!A5) | B25: =IF($A25="","",COUNTIFS('予算一覧'!$AG$5:$AG$200,$A25,'予算一覧'!$AP$5:$AP$200,"棚卸し中")) | C25: =IF($A25="","",COUNTIFS('予算一覧'!$AG$5:$AG$200,$A25,'予算一覧'!$AP$5:$AP$200,"棚卸し済み")) | D25: =IF($A25="","",COUNTIFS('予算一覧'!$AG$5:$AG$200,$A25,'予算一覧'!$AP$5:$AP$200,"合意済み")) | E25: =IF($A25="","",COUNTIFS('予算一覧'!$AG$5:$AG$200,$A25,'予算一覧'!$AP$5:$AP$200,"準備完了")) | F25: =IF($A25="","",COUNTIFS('予算一覧'!$AG$5:$AG$200,$A25,'予算一覧'!$AP$5:$AP$200,"対象外")) | G25: =IF($A25="","",COUNTIFS('予算一覧'!$AG$5:$AG$200,$A25,'予算一覧'!$AP$5:$AP$200,"")) | H25: =IF($A25="","",COUNTIFS('予算一覧'!$AG$5:$AG$200,$A25,'予算一覧'!$AL$5:$AL$200,"判定保留"))
A26: =IF('窓口'!A6="","",'窓口'!A6) | B26: =IF($A26="","",COUNTIFS('予算一覧'!$AG$5:$AG$200,$A26,'予算一覧'!$AP$5:$AP$200,"棚卸し中")) | C26: =IF($A26="","",COUNTIFS('予算一覧'!$AG$5:$AG$200,$A26,'予算一覧'!$AP$5:$AP$200,"棚卸し済み")) | D26: =IF($A26="","",COUNTIFS('予算一覧'!$AG$5:$AG$200,$A26,'予算一覧'!$AP$5:$AP$200,"合意済み")) | E26: =IF($A26="","",COUNTIFS('予算一覧'!$AG$5:$AG$200,$A26,'予算一覧'!$AP$5:$AP$200,"準備完了")) | F26: =IF($A26="","",COUNTIFS('予算一覧'!$AG$5:$AG$200,$A26,'予算一覧'!$AP$5:$AP$200,"対象外")) | G26: =IF($A26="","",COUNTIFS('予算一覧'!$AG$5:$AG$200,$A26,'予算一覧'!$AP$5:$AP$200,"")) | H26: =IF($A26="","",COUNTIFS('予算一覧'!$AG$5:$AG$200,$A26,'予算一覧'!$AL$5:$AL$200,"判定保留"))
A27: =IF('窓口'!A7="","",'窓口'!A7) | B27: =IF($A27="","",COUNTIFS('予算一覧'!$AG$5:$AG$200,$A27,'予算一覧'!$AP$5:$AP$200,"棚卸し中")) | C27: =IF($A27="","",COUNTIFS('予算一覧'!$AG$5:$AG$200,$A27,'予算一覧'!$AP$5:$AP$200,"棚卸し済み")) | D27: =IF($A27="","",COUNTIFS('予算一覧'!$AG$5:$AG$200,$A27,'予算一覧'!$AP$5:$AP$200,"合意済み")) | E27: =IF($A27="","",COUNTIFS('予算一覧'!$AG$5:$AG$200,$A27,'予算一覧'!$AP$5:$AP$200,"準備完了")) | F27: =IF($A27="","",COUNTIFS('予算一覧'!$AG$5:$AG$200,$A27,'予算一覧'!$AP$5:$AP$200,"対象外")) | G27: =IF($A27="","",COUNTIFS('予算一覧'!$AG$5:$AG$200,$A27,'予算一覧'!$AP$5:$AP$200,"")) | H27: =IF($A27="","",COUNTIFS('予算一覧'!$AG$5:$AG$200,$A27,'予算一覧'!$AL$5:$AL$200,"判定保留"))
A28: =IF('窓口'!A8="","",'窓口'!A8) | B28: =IF($A28="","",COUNTIFS('予算一覧'!$AG$5:$AG$200,$A28,'予算一覧'!$AP$5:$AP$200,"棚卸し中")) | C28: =IF($A28="","",COUNTIFS('予算一覧'!$AG$5:$AG$200,$A28,'予算一覧'!$AP$5:$AP$200,"棚卸し済み")) | D28: =IF($A28="","",COUNTIFS('予算一覧'!$AG$5:$AG$200,$A28,'予算一覧'!$AP$5:$AP$200,"合意済み")) | E28: =IF($A28="","",COUNTIFS('予算一覧'!$AG$5:$AG$200,$A28,'予算一覧'!$AP$5:$AP$200,"準備完了")) | F28: =IF($A28="","",COUNTIFS('予算一覧'!$AG$5:$AG$200,$A28,'予算一覧'!$AP$5:$AP$200,"対象外")) | G28: =IF($A28="","",COUNTIFS('予算一覧'!$AG$5:$AG$200,$A28,'予算一覧'!$AP$5:$AP$200,"")) | H28: =IF($A28="","",COUNTIFS('予算一覧'!$AG$5:$AG$200,$A28,'予算一覧'!$AL$5:$AL$200,"判定保留"))
A29: =IF('窓口'!A9="","",'窓口'!A9) | B29: =IF($A29="","",COUNTIFS('予算一覧'!$AG$5:$AG$200,$A29,'予算一覧'!$AP$5:$AP$200,"棚卸し中")) | C29: =IF($A29="","",COUNTIFS('予算一覧'!$AG$5:$AG$200,$A29,'予算一覧'!$AP$5:$AP$200,"棚卸し済み")) | D29: =IF($A29="","",COUNTIFS('予算一覧'!$AG$5:$AG$200,$A29,'予算一覧'!$AP$5:$AP$200,"合意済み")) | E29: =IF($A29="","",COUNTIFS('予算一覧'!$AG$5:$AG$200,$A29,'予算一覧'!$AP$5:$AP$200,"準備完了")) | F29: =IF($A29="","",COUNTIFS('予算一覧'!$AG$5:$AG$200,$A29,'予算一覧'!$AP$5:$AP$200,"対象外")) | G29: =IF($A29="","",COUNTIFS('予算一覧'!$AG$5:$AG$200,$A29,'予算一覧'!$AP$5:$AP$200,"")) | H29: =IF($A29="","",COUNTIFS('予算一覧'!$AG$5:$AG$200,$A29,'予算一覧'!$AL$5:$AL$200,"判定保留"))
A30: =IF('窓口'!A10="","",'窓口'!A10) | B30: =IF($A30="","",COUNTIFS('予算一覧'!$AG$5:$AG$200,$A30,'予算一覧'!$AP$5:$AP$200,"棚卸し中")) | C30: =IF($A30="","",COUNTIFS('予算一覧'!$AG$5:$AG$200,$A30,'予算一覧'!$AP$5:$AP$200,"棚卸し済み")) | D30: =IF($A30="","",COUNTIFS('予算一覧'!$AG$5:$AG$200,$A30,'予算一覧'!$AP$5:$AP$200,"合意済み")) | E30: =IF($A30="","",COUNTIFS('予算一覧'!$AG$5:$AG$200,$A30,'予算一覧'!$AP$5:$AP$200,"準備完了")) | F30: =IF($A30="","",COUNTIFS('予算一覧'!$AG$5:$AG$200,$A30,'予算一覧'!$AP$5:$AP$200,"対象外")) | G30: =IF($A30="","",COUNTIFS('予算一覧'!$AG$5:$AG$200,$A30,'予算一覧'!$AP$5:$AP$200,"")) | H30: =IF($A30="","",COUNTIFS('予算一覧'!$AG$5:$AG$200,$A30,'予算一覧'!$AL$5:$AL$200,"判定保留"))
A31: =IF('窓口'!A11="","",'窓口'!A11) | B31: =IF($A31="","",COUNTIFS('予算一覧'!$AG$5:$AG$200,$A31,'予算一覧'!$AP$5:$AP$200,"棚卸し中")) | C31: =IF($A31="","",COUNTIFS('予算一覧'!$AG$5:$AG$200,$A31,'予算一覧'!$AP$5:$AP$200,"棚卸し済み")) | D31: =IF($A31="","",COUNTIFS('予算一覧'!$AG$5:$AG$200,$A31,'予算一覧'!$AP$5:$AP$200,"合意済み")) | E31: =IF($A31="","",COUNTIFS('予算一覧'!$AG$5:$AG$200,$A31,'予算一覧'!$AP$5:$AP$200,"準備完了")) | F31: =IF($A31="","",COUNTIFS('予算一覧'!$AG$5:$AG$200,$A31,'予算一覧'!$AP$5:$AP$200,"対象外")) | G31: =IF($A31="","",COUNTIFS('予算一覧'!$AG$5:$AG$200,$A31,'予算一覧'!$AP$5:$AP$200,"")) | H31: =IF($A31="","",COUNTIFS('予算一覧'!$AG$5:$AG$200,$A31,'予算一覧'!$AL$5:$AL$200,"判定保留"))
A32: =IF('窓口'!A12="","",'窓口'!A12) | B32: =IF($A32="","",COUNTIFS('予算一覧'!$AG$5:$AG$200,$A32,'予算一覧'!$AP$5:$AP$200,"棚卸し中")) | C32: =IF($A32="","",COUNTIFS('予算一覧'!$AG$5:$AG$200,$A32,'予算一覧'!$AP$5:$AP$200,"棚卸し済み")) | D32: =IF($A32="","",COUNTIFS('予算一覧'!$AG$5:$AG$200,$A32,'予算一覧'!$AP$5:$AP$200,"合意済み")) | E32: =IF($A32="","",COUNTIFS('予算一覧'!$AG$5:$AG$200,$A32,'予算一覧'!$AP$5:$AP$200,"準備完了")) | F32: =IF($A32="","",COUNTIFS('予算一覧'!$AG$5:$AG$200,$A32,'予算一覧'!$AP$5:$AP$200,"対象外")) | G32: =IF($A32="","",COUNTIFS('予算一覧'!$AG$5:$AG$200,$A32,'予算一覧'!$AP$5:$AP$200,"")) | H32: =IF($A32="","",COUNTIFS('予算一覧'!$AG$5:$AG$200,$A32,'予算一覧'!$AL$5:$AL$200,"判定保留"))
A33: =IF('窓口'!A13="","",'窓口'!A13) | B33: =IF($A33="","",COUNTIFS('予算一覧'!$AG$5:$AG$200,$A33,'予算一覧'!$AP$5:$AP$200,"棚卸し中")) | C33: =IF($A33="","",COUNTIFS('予算一覧'!$AG$5:$AG$200,$A33,'予算一覧'!$AP$5:$AP$200,"棚卸し済み")) | D33: =IF($A33="","",COUNTIFS('予算一覧'!$AG$5:$AG$200,$A33,'予算一覧'!$AP$5:$AP$200,"合意済み")) | E33: =IF($A33="","",COUNTIFS('予算一覧'!$AG$5:$AG$200,$A33,'予算一覧'!$AP$5:$AP$200,"準備完了")) | F33: =IF($A33="","",COUNTIFS('予算一覧'!$AG$5:$AG$200,$A33,'予算一覧'!$AP$5:$AP$200,"対象外")) | G33: =IF($A33="","",COUNTIFS('予算一覧'!$AG$5:$AG$200,$A33,'予算一覧'!$AP$5:$AP$200,"")) | H33: =IF($A33="","",COUNTIFS('予算一覧'!$AG$5:$AG$200,$A33,'予算一覧'!$AL$5:$AL$200,"判定保留"))
A34: =IF('窓口'!A14="","",'窓口'!A14) | B34: =IF($A34="","",COUNTIFS('予算一覧'!$AG$5:$AG$200,$A34,'予算一覧'!$AP$5:$AP$200,"棚卸し中")) | C34: =IF($A34="","",COUNTIFS('予算一覧'!$AG$5:$AG$200,$A34,'予算一覧'!$AP$5:$AP$200,"棚卸し済み")) | D34: =IF($A34="","",COUNTIFS('予算一覧'!$AG$5:$AG$200,$A34,'予算一覧'!$AP$5:$AP$200,"合意済み")) | E34: =IF($A34="","",COUNTIFS('予算一覧'!$AG$5:$AG$200,$A34,'予算一覧'!$AP$5:$AP$200,"準備完了")) | F34: =IF($A34="","",COUNTIFS('予算一覧'!$AG$5:$AG$200,$A34,'予算一覧'!$AP$5:$AP$200,"対象外")) | G34: =IF($A34="","",COUNTIFS('予算一覧'!$AG$5:$AG$200,$A34,'予算一覧'!$AP$5:$AP$200,"")) | H34: =IF($A34="","",COUNTIFS('予算一覧'!$AG$5:$AG$200,$A34,'予算一覧'!$AL$5:$AL$200,"判定保留"))
A35: =IF('窓口'!A15="","",'窓口'!A15) | B35: =IF($A35="","",COUNTIFS('予算一覧'!$AG$5:$AG$200,$A35,'予算一覧'!$AP$5:$AP$200,"棚卸し中")) | C35: =IF($A35="","",COUNTIFS('予算一覧'!$AG$5:$AG$200,$A35,'予算一覧'!$AP$5:$AP$200,"棚卸し済み")) | D35: =IF($A35="","",COUNTIFS('予算一覧'!$AG$5:$AG$200,$A35,'予算一覧'!$AP$5:$AP$200,"合意済み")) | E35: =IF($A35="","",COUNTIFS('予算一覧'!$AG$5:$AG$200,$A35,'予算一覧'!$AP$5:$AP$200,"準備完了")) | F35: =IF($A35="","",COUNTIFS('予算一覧'!$AG$5:$AG$200,$A35,'予算一覧'!$AP$5:$AP$200,"対象外")) | G35: =IF($A35="","",COUNTIFS('予算一覧'!$AG$5:$AG$200,$A35,'予算一覧'!$AP$5:$AP$200,"")) | H35: =IF($A35="","",COUNTIFS('予算一覧'!$AG$5:$AG$200,$A35,'予算一覧'!$AL$5:$AL$200,"判定保留"))
... A53: =IF('窓口'!A33="","",'窓口'!A33) | B53: =IF($A53="","",COUNTIFS('予算一覧'!$AG$5:$AG$200,$A53,'予算一覧'!$AP$5:$AP$200,"棚卸し中")) | C53: =IF($A53="","",COUNTIFS('予算一覧'!$AG$5:$AG$200,$A53,'予算一覧'!$AP$5:$AP$200,"棚卸し済み")) | D53: =IF($A53="","",COUNTIFS('予算一覧'!$AG$5:$AG$200,$A53,'予算一覧'!$AP$5:$AP$200,"合意済み")) | E53: =IF($A53="","",COUNTIFS('予算一覧'!$AG$5:$AG$200,$A53,'予算一覧'!$AP$5:$AP$200,"準備完了")) | F53: =IF($A53="","",COUNTIFS('予算一覧'!$AG$5:$AG$200,$A53,'予算一覧'!$AP$5:$AP$200,"対象外")) | G53: =IF($A53="","",COUNTIFS('予算一覧'!$AG$5:$AG$200,$A53,'予算一覧'!$AP$5:$AP$200,"")) | H53: =IF($A53="","",COUNTIFS('予算一覧'!$AG$5:$AG$200,$A53,'予算一覧'!$AL$5:$AL$200,"判定保留"))
A55: 4. 役割別のタスクの進捗（件数）
A56: 役割 | B56: 未着手 | C56: 進行中 | D56: 完了 | E56: 保留 | F56: 期限超過
A57: 事務局 | B57: =COUNTIFS('進捗'!$C$4:$C$200,$A57,'進捗'!$I$4:$I$200,"未着手") | C57: =COUNTIFS('進捗'!$C$4:$C$200,$A57,'進捗'!$I$4:$I$200,"進行中") | D57: =COUNTIFS('進捗'!$C$4:$C$200,$A57,'進捗'!$I$4:$I$200,"完了") | E57: =COUNTIFS('進捗'!$C$4:$C$200,$A57,'進捗'!$I$4:$I$200,"保留") | F57: =COUNTIFS('進捗'!$C$4:$C$200,$A57,'進捗'!$L$4:$L$200,"期限超過")
A58: 窓口担当 | B58: =COUNTIFS('進捗'!$C$4:$C$200,$A58,'進捗'!$I$4:$I$200,"未着手") | C58: =COUNTIFS('進捗'!$C$4:$C$200,$A58,'進捗'!$I$4:$I$200,"進行中") | D58: =COUNTIFS('進捗'!$C$4:$C$200,$A58,'進捗'!$I$4:$I$200,"完了") | E58: =COUNTIFS('進捗'!$C$4:$C$200,$A58,'進捗'!$I$4:$I$200,"保留") | F58: =COUNTIFS('進捗'!$C$4:$C$200,$A58,'進捗'!$L$4:$L$200,"期限超過")
A59: 移管元の責任者 | B59: =COUNTIFS('進捗'!$C$4:$C$200,$A59,'進捗'!$I$4:$I$200,"未着手") | C59: =COUNTIFS('進捗'!$C$4:$C$200,$A59,'進捗'!$I$4:$I$200,"進行中") | D59: =COUNTIFS('進捗'!$C$4:$C$200,$A59,'進捗'!$I$4:$I$200,"完了") | E59: =COUNTIFS('進捗'!$C$4:$C$200,$A59,'進捗'!$I$4:$I$200,"保留") | F59: =COUNTIFS('進捗'!$C$4:$C$200,$A59,'進捗'!$L$4:$L$200,"期限超過")
A60: IT部門長 | B60: =COUNTIFS('進捗'!$C$4:$C$200,$A60,'進捗'!$I$4:$I$200,"未着手") | C60: =COUNTIFS('進捗'!$C$4:$C$200,$A60,'進捗'!$I$4:$I$200,"進行中") | D60: =COUNTIFS('進捗'!$C$4:$C$200,$A60,'進捗'!$I$4:$I$200,"完了") | E60: =COUNTIFS('進捗'!$C$4:$C$200,$A60,'進捗'!$I$4:$I$200,"保留") | F60: =COUNTIFS('進捗'!$C$4:$C$200,$A60,'進捗'!$L$4:$L$200,"期限超過")
A61: 部門長同士（稟議） | B61: =COUNTIFS('進捗'!$C$4:$C$200,$A61,'進捗'!$I$4:$I$200,"未着手") | C61: =COUNTIFS('進捗'!$C$4:$C$200,$A61,'進捗'!$I$4:$I$200,"進行中") | D61: =COUNTIFS('進捗'!$C$4:$C$200,$A61,'進捗'!$I$4:$I$200,"完了") | E61: =COUNTIFS('進捗'!$C$4:$C$200,$A61,'進捗'!$I$4:$I$200,"保留") | F61: =COUNTIFS('進捗'!$C$4:$C$200,$A61,'進捗'!$L$4:$L$200,"期限超過")

Sheet 進捗
A1: 進捗（役割別のタスク）
A2: 1行＝1件のタスク（対象の部門・案件・契約ごと）。全体と部門の行は事務局が、案件・契約の行は窓口担当が作り、自分の行の状態・完了日を更新する。承認の行は、依頼した者（A-03は窓口担当、それ以外は事務局）が更新する。役割とタスク名はタスクIDから自動で表示される。期限を過ぎて完了していない行は「期限超過」と表示する。薄い色の行は記入例。
A3: No. | B3: タスクID | C3: 役割（自動） | D3: タスク（自動） | E3: Runbook の節（自動） | F3: 対象 （部門・案件ID・契約ID） | G3: 担当者 | H3: 期限 | I3: 状態 | J3: 完了日 | K3: メモ | L3: 期限超過（自動）
A4: 1 | B4: P-02 | C4: =IF(B4="","",IFERROR(INDEX('タスク一覧'!$B:$B,MATCH(B4,'タスク一覧'!$A:$A,0)),"タスクIDが未登録")) | D4: =IF(B4="","",IFERROR(INDEX('タスク一覧'!$C:$C,MATCH(B4,'タスク一覧'!$A:$A,0)),"")) | E4: =IF(B4="","",IFERROR(INDEX('タスク一覧'!$D:$D,MATCH(B4,'タスク一覧'!$A:$A,0)),"")) | F4: 研究本部 | G4: （記入例） | H4: 46295 | I4: 完了 | J4: 46294 | L4: =IF(OR(B4="",H4=""),"",IF(AND(I4<>"完了",H4<TODAY()),"期限超過",""))
A5: 2 | B5: C-01 | C5: =IF(B5="","",IFERROR(INDEX('タスク一覧'!$B:$B,MATCH(B5,'タスク一覧'!$A:$A,0)),"タスクIDが未登録")) | D5: =IF(B5="","",IFERROR(INDEX('タスク一覧'!$C:$C,MATCH(B5,'タスク一覧'!$A:$A,0)),"")) | E5: =IF(B5="","",IFERROR(INDEX('タスク一覧'!$D:$D,MATCH(B5,'タスク一覧'!$A:$A,0)),"")) | F5: BUD-001 | G5: （記入例） | H5: 46326 | I5: 進行中 | L5: =IF(OR(B5="",H5=""),"",IF(AND(I5<>"完了",H5<TODAY()),"期限超過",""))
A6: 3 | B6: C-05 | C6: =IF(B6="","",IFERROR(INDEX('タスク一覧'!$B:$B,MATCH(B6,'タスク一覧'!$A:$A,0)),"タスクIDが未登録")) | D6: =IF(B6="","",IFERROR(INDEX('タスク一覧'!$C:$C,MATCH(B6,'タスク一覧'!$A:$A,0)),"")) | E6: =IF(B6="","",IFERROR(INDEX('タスク一覧'!$D:$D,MATCH(B6,'タスク一覧'!$A:$A,0)),"")) | F6: BUD-002 | G6: （記入例） | H6: 46367 | I6: 完了 | J6: 46366 | K6: 合意文書を承認（経過措置1件：GxPの変更管理が完了するまで、eDMSの発注・検収・支払いは品質保証部の担当のまま） | L6: =IF(OR(B6="",H6=""),"",IF(AND(I6<>"完了",H6<TODAY()),"期限超過",""))
C7: =IF(B7="","",IFERROR(INDEX('タスク一覧'!$B:$B,MATCH(B7,'タスク一覧'!$A:$A,0)),"タスクIDが未登録")) | D7: =IF(B7="","",IFERROR(INDEX('タスク一覧'!$C:$C,MATCH(B7,'タスク一覧'!$A:$A,0)),"")) | E7: =IF(B7="","",IFERROR(INDEX('タスク一覧'!$D:$D,MATCH(B7,'タスク一覧'!$A:$A,0)),"")) | L7: =IF(OR(B7="",H7=""),"",IF(AND(I7<>"完了",H7<TODAY()),"期限超過",""))
C8: =IF(B8="","",IFERROR(INDEX('タスク一覧'!$B:$B,MATCH(B8,'タスク一覧'!$A:$A,0)),"タスクIDが未登録")) | D8: =IF(B8="","",IFERROR(INDEX('タスク一覧'!$C:$C,MATCH(B8,'タスク一覧'!$A:$A,0)),"")) | E8: =IF(B8="","",IFERROR(INDEX('タスク一覧'!$D:$D,MATCH(B8,'タスク一覧'!$A:$A,0)),"")) | L8: =IF(OR(B8="",H8=""),"",IF(AND(I8<>"完了",H8<TODAY()),"期限超過",""))
C9: =IF(B9="","",IFERROR(INDEX('タスク一覧'!$B:$B,MATCH(B9,'タスク一覧'!$A:$A,0)),"タスクIDが未登録")) | D9: =IF(B9="","",IFERROR(INDEX('タスク一覧'!$C:$C,MATCH(B9,'タスク一覧'!$A:$A,0)),"")) | E9: =IF(B9="","",IFERROR(INDEX('タスク一覧'!$D:$D,MATCH(B9,'タスク一覧'!$A:$A,0)),"")) | L9: =IF(OR(B9="",H9=""),"",IF(AND(I9<>"完了",H9<TODAY()),"期限超過",""))
C10: =IF(B10="","",IFERROR(INDEX('タスク一覧'!$B:$B,MATCH(B10,'タスク一覧'!$A:$A,0)),"タスクIDが未登録")) | D10: =IF(B10="","",IFERROR(INDEX('タスク一覧'!$C:$C,MATCH(B10,'タスク一覧'!$A:$A,0)),"")) | E10: =IF(B10="","",IFERROR(INDEX('タスク一覧'!$D:$D,MATCH(B10,'タスク一覧'!$A:$A,0)),"")) | L10: =IF(OR(B10="",H10=""),"",IF(AND(I10<>"完了",H10<TODAY()),"期限超過",""))
C11: =IF(B11="","",IFERROR(INDEX('タスク一覧'!$B:$B,MATCH(B11,'タスク一覧'!$A:$A,0)),"タスクIDが未登録")) | D11: =IF(B11="","",IFERROR(INDEX('タスク一覧'!$C:$C,MATCH(B11,'タスク一覧'!$A:$A,0)),"")) | E11: =IF(B11="","",IFERROR(INDEX('タスク一覧'!$D:$D,MATCH(B11,'タスク一覧'!$A:$A,0)),"")) | L11: =IF(OR(B11="",H11=""),"",IF(AND(I11<>"完了",H11<TODAY()),"期限超過",""))
C12: =IF(B12="","",IFERROR(INDEX('タスク一覧'!$B:$B,MATCH(B12,'タスク一覧'!$A:$A,0)),"タスクIDが未登録")) | D12: =IF(B12="","",IFERROR(INDEX('タスク一覧'!$C:$C,MATCH(B12,'タスク一覧'!$A:$A,0)),"")) | E12: =IF(B12="","",IFERROR(INDEX('タスク一覧'!$D:$D,MATCH(B12,'タスク一覧'!$A:$A,0)),"")) | L12: =IF(OR(B12="",H12=""),"",IF(AND(I12<>"完了",H12<TODAY()),"期限超過",""))
C13: =IF(B13="","",IFERROR(INDEX('タスク一覧'!$B:$B,MATCH(B13,'タスク一覧'!$A:$A,0)),"タスクIDが未登録")) | D13: =IF(B13="","",IFERROR(INDEX('タスク一覧'!$C:$C,MATCH(B13,'タスク一覧'!$A:$A,0)),"")) | E13: =IF(B13="","",IFERROR(INDEX('タスク一覧'!$D:$D,MATCH(B13,'タスク一覧'!$A:$A,0)),"")) | L13: =IF(OR(B13="",H13=""),"",IF(AND(I13<>"完了",H13<TODAY()),"期限超過",""))
C14: =IF(B14="","",IFERROR(INDEX('タスク一覧'!$B:$B,MATCH(B14,'タスク一覧'!$A:$A,0)),"タスクIDが未登録")) | D14: =IF(B14="","",IFERROR(INDEX('タスク一覧'!$C:$C,MATCH(B14,'タスク一覧'!$A:$A,0)),"")) | E14: =IF(B14="","",IFERROR(INDEX('タスク一覧'!$D:$D,MATCH(B14,'タスク一覧'!$A:$A,0)),"")) | L14: =IF(OR(B14="",H14=""),"",IF(AND(I14<>"完了",H14<TODAY()),"期限超過",""))
C15: =IF(B15="","",IFERROR(INDEX('タスク一覧'!$B:$B,MATCH(B15,'タスク一覧'!$A:$A,0)),"タスクIDが未登録")) | D15: =IF(B15="","",IFERROR(INDEX('タスク一覧'!$C:$C,MATCH(B15,'タスク一覧'!$A:$A,0)),"")) | E15: =IF(B15="","",IFERROR(INDEX('タスク一覧'!$D:$D,MATCH(B15,'タスク一覧'!$A:$A,0)),"")) | L15: =IF(OR(B15="",H15=""),"",IF(AND(I15<>"完了",H15<TODAY()),"期限超過",""))
C16: =IF(B16="","",IFERROR(INDEX('タスク一覧'!$B:$B,MATCH(B16,'タスク一覧'!$A:$A,0)),"タスクIDが未登録")) | D16: =IF(B16="","",IFERROR(INDEX('タスク一覧'!$C:$C,MATCH(B16,'タスク一覧'!$A:$A,0)),"")) | E16: =IF(B16="","",IFERROR(INDEX('タスク一覧'!$D:$D,MATCH(B16,'タスク一覧'!$A:$A,0)),"")) | L16: =IF(OR(B16="",H16=""),"",IF(AND(I16<>"完了",H16<TODAY()),"期限超過",""))
C17: =IF(B17="","",IFERROR(INDEX('タスク一覧'!$B:$B,MATCH(B17,'タスク一覧'!$A:$A,0)),"タスクIDが未登録")) | D17: =IF(B17="","",IFERROR(INDEX('タスク一覧'!$C:$C,MATCH(B17,'タスク一覧'!$A:$A,0)),"")) | E17: =IF(B17="","",IFERROR(INDEX('タスク一覧'!$D:$D,MATCH(B17,'タスク一覧'!$A:$A,0)),"")) | L17: =IF(OR(B17="",H17=""),"",IF(AND(I17<>"完了",H17<TODAY()),"期限超過",""))
C18: =IF(B18="","",IFERROR(INDEX('タスク一覧'!$B:$B,MATCH(B18,'タスク一覧'!$A:$A,0)),"タスクIDが未登録")) | D18: =IF(B18="","",IFERROR(INDEX('タスク一覧'!$C:$C,MATCH(B18,'タスク一覧'!$A:$A,0)),"")) | E18: =IF(B18="","",IFERROR(INDEX('タスク一覧'!$D:$D,MATCH(B18,'タスク一覧'!$A:$A,0)),"")) | L18: =IF(OR(B18="",H18=""),"",IF(AND(I18<>"完了",H18<TODAY()),"期限超過",""))
... C200: =IF(B200="","",IFERROR(INDEX('タスク一覧'!$B:$B,MATCH(B200,'タスク一覧'!$A:$A,0)),"タスクIDが未登録")) | D200: =IF(B200="","",IFERROR(INDEX('タスク一覧'!$C:$C,MATCH(B200,'タスク一覧'!$A:$A,0)),"")) | E200: =IF(B200="","",IFERROR(INDEX('タスク一覧'!$D:$D,MATCH(B200,'タスク一覧'!$A:$A,0)),"")) | L200: =IF(OR(B200="",H200=""),"",IF(AND(I200<>"完了",H200<TODAY()),"期限超過",""))

Sheet 窓口
A1: 窓口（移管対象部門）
A2: 1行＝1部門。移管元の責任者（承認者）と、部門の担当者（情報の提供の問い合わせ先）、予算シートの受領日を記録する。部門名は予算一覧の「部門」の選択肢になる。
A3: 部門 | B3: 移管元の責任者 | C3: 担当者（問い合わせ先） | D3: 連絡先 | E3: 予算シートの受領日 | F3: 案件数（自動）
A4: 研究本部 | B4: （記入例） | C4: （記入例） | E4: 46290 | F4: =IF(A4="","",COUNTIF('予算一覧'!$AG$5:$AG$200,A4))
A5: 品質保証部 | B5: （記入例） | C5: （記入例） | E5: 46290 | F5: =IF(A5="","",COUNTIF('予算一覧'!$AG$5:$AG$200,A5))
F6: =IF(A6="","",COUNTIF('予算一覧'!$AG$5:$AG$200,A6))
F7: =IF(A7="","",COUNTIF('予算一覧'!$AG$5:$AG$200,A7))
F8: =IF(A8="","",COUNTIF('予算一覧'!$AG$5:$AG$200,A8))
F9: =IF(A9="","",COUNTIF('予算一覧'!$AG$5:$AG$200,A9))
F10: =IF(A10="","",COUNTIF('予算一覧'!$AG$5:$AG$200,A10))
F11: =IF(A11="","",COUNTIF('予算一覧'!$AG$5:$AG$200,A11))
F12: =IF(A12="","",COUNTIF('予算一覧'!$AG$5:$AG$200,A12))
F13: =IF(A13="","",COUNTIF('予算一覧'!$AG$5:$AG$200,A13))
F14: =IF(A14="","",COUNTIF('予算一覧'!$AG$5:$AG$200,A14))
F15: =IF(A15="","",COUNTIF('予算一覧'!$AG$5:$AG$200,A15))
F16: =IF(A16="","",COUNTIF('予算一覧'!$AG$5:$AG$200,A16))
F17: =IF(A17="","",COUNTIF('予算一覧'!$AG$5:$AG$200,A17))
... F200: =IF(A200="","",COUNTIF('予算一覧'!$AG$5:$AG$200,A200))

Sheet 紐付け
A1: 紐付け（案件×システム）
A2: 1行＝1つの対応（案件×システム）。1案件に複数のシステム、1システムに複数の案件があれば行を分ける。紐付け以外の情報は持たない。 新規の投資案件は、既存のシステムの改修のときだけ書く。
A3: 案件ID | B3: 案件名（自動） | C3: システムID | D3: システム名（自動）
A4: BUD-001 | B4: =IF(A4="","",IFERROR(INDEX('予算一覧'!$B:$B,MATCH(A4,'予算一覧'!$A:$A,0)),"案件が未登録")) | C4: SYS-012 | D4: =IF(C4="","",IFERROR(INDEX('システム'!$B:$B,MATCH(C4,'システム'!$A:$A,0)),"システムが未登録"))
A5: BUD-002 | B5: =IF(A5="","",IFERROR(INDEX('予算一覧'!$B:$B,MATCH(A5,'予算一覧'!$A:$A,0)),"案件が未登録")) | C5: SYS-003 | D5: =IF(C5="","",IFERROR(INDEX('システム'!$B:$B,MATCH(C5,'システム'!$A:$A,0)),"システムが未登録"))
A6: BUD-003 | B6: =IF(A6="","",IFERROR(INDEX('予算一覧'!$B:$B,MATCH(A6,'予算一覧'!$A:$A,0)),"案件が未登録")) | C6: SYS-041 | D6: =IF(C6="","",IFERROR(INDEX('システム'!$B:$B,MATCH(C6,'システム'!$A:$A,0)),"システムが未登録"))
B7: =IF(A7="","",IFERROR(INDEX('予算一覧'!$B:$B,MATCH(A7,'予算一覧'!$A:$A,0)),"案件が未登録")) | D7: =IF(C7="","",IFERROR(INDEX('システム'!$B:$B,MATCH(C7,'システム'!$A:$A,0)),"システムが未登録"))
B8: =IF(A8="","",IFERROR(INDEX('予算一覧'!$B:$B,MATCH(A8,'予算一覧'!$A:$A,0)),"案件が未登録")) | D8: =IF(C8="","",IFERROR(INDEX('システム'!$B:$B,MATCH(C8,'システム'!$A:$A,0)),"システムが未登録"))
B9: =IF(A9="","",IFERROR(INDEX('予算一覧'!$B:$B,MATCH(A9,'予算一覧'!$A:$A,0)),"案件が未登録")) | D9: =IF(C9="","",IFERROR(INDEX('システム'!$B:$B,MATCH(C9,'システム'!$A:$A,0)),"システムが未登録"))
B10: =IF(A10="","",IFERROR(INDEX('予算一覧'!$B:$B,MATCH(A10,'予算一覧'!$A:$A,0)),"案件が未登録")) | D10: =IF(C10="","",IFERROR(INDEX('システム'!$B:$B,MATCH(C10,'システム'!$A:$A,0)),"システムが未登録"))
B11: =IF(A11="","",IFERROR(INDEX('予算一覧'!$B:$B,MATCH(A11,'予算一覧'!$A:$A,0)),"案件が未登録")) | D11: =IF(C11="","",IFERROR(INDEX('システム'!$B:$B,MATCH(C11,'システム'!$A:$A,0)),"システムが未登録"))
B12: =IF(A12="","",IFERROR(INDEX('予算一覧'!$B:$B,MATCH(A12,'予算一覧'!$A:$A,0)),"案件が未登録")) | D12: =IF(C12="","",IFERROR(INDEX('システム'!$B:$B,MATCH(C12,'システム'!$A:$A,0)),"システムが未登録"))
B13: =IF(A13="","",IFERROR(INDEX('予算一覧'!$B:$B,MATCH(A13,'予算一覧'!$A:$A,0)),"案件が未登録")) | D13: =IF(C13="","",IFERROR(INDEX('システム'!$B:$B,MATCH(C13,'システム'!$A:$A,0)),"システムが未登録"))
B14: =IF(A14="","",IFERROR(INDEX('予算一覧'!$B:$B,MATCH(A14,'予算一覧'!$A:$A,0)),"案件が未登録")) | D14: =IF(C14="","",IFERROR(INDEX('システム'!$B:$B,MATCH(C14,'システム'!$A:$A,0)),"システムが未登録"))
B15: =IF(A15="","",IFERROR(INDEX('予算一覧'!$B:$B,MATCH(A15,'予算一覧'!$A:$A,0)),"案件が未登録")) | D15: =IF(C15="","",IFERROR(INDEX('システム'!$B:$B,MATCH(C15,'システム'!$A:$A,0)),"システムが未登録"))
B16: =IF(A16="","",IFERROR(INDEX('予算一覧'!$B:$B,MATCH(A16,'予算一覧'!$A:$A,0)),"案件が未登録")) | D16: =IF(C16="","",IFERROR(INDEX('システム'!$B:$B,MATCH(C16,'システム'!$A:$A,0)),"システムが未登録"))
B17: =IF(A17="","",IFERROR(INDEX('予算一覧'!$B:$B,MATCH(A17,'予算一覧'!$A:$A,0)),"案件が未登録")) | D17: =IF(C17="","",IFERROR(INDEX('システム'!$B:$B,MATCH(C17,'システム'!$A:$A,0)),"システムが未登録"))
B18: =IF(A18="","",IFERROR(INDEX('予算一覧'!$B:$B,MATCH(A18,'予算一覧'!$A:$A,0)),"案件が未登録")) | D18: =IF(C18="","",IFERROR(INDEX('システム'!$B:$B,MATCH(C18,'システム'!$A:$A,0)),"システムが未登録"))
... B200: =IF(A200="","",IFERROR(INDEX('予算一覧'!$B:$B,MATCH(A200,'予算一覧'!$A:$A,0)),"案件が未登録")) | D200: =IF(C200="","",IFERROR(INDEX('システム'!$B:$B,MATCH(C200,'システム'!$A:$A,0)),"システムが未登録"))

Sheet システム
A1: システム（実在のシステム名）
A2: 1行＝1システム。移管するかどうかはシステムでは判定しない（移管対象の組織では、移管できるものはすべて移管する）。業務（直接業務・間接業務）の棚卸しの進み具合を確認するための一覧。案件との対応は「紐付け」シートに書く。灰色の列は数式。薄い色の行は記入例。
A3: システムID | B3: システム名 | C3: オーナー部門 | D3: GxP対象 | E3: 個人情報 | F3: EOL期限 （決まっていれば日付） | G3: 紐づく案件数（自動） | H3: 業務数（自動） | I3: 棚卸し（自動）
A4: SYS-003 | B4: 品質文書システム | C4: 品質保証部 | D4: はい | E4: いいえ | F4: 46843 | G4: =IF(A4="","",COUNTIF('紐付け'!$C$4:$C$200,A4)) | H4: =IF(A4="","",COUNTIF('業務'!$C$4:$C$200,A4)) | I4: =IF(A4="","",IF(H4=0,"業務が未登録",IF(COUNTIFS('業務'!$C$4:$C$200,A4,'業務'!$J$4:$J$200,"済")=H4,"済","未")))
A5: SYS-012 | B5: 研究クラウド基盤 | C5: 研究本部 | D5: いいえ | E5: いいえ | G5: =IF(A5="","",COUNTIF('紐付け'!$C$4:$C$200,A5)) | H5: =IF(A5="","",COUNTIF('業務'!$C$4:$C$200,A5)) | I5: =IF(A5="","",IF(H5=0,"業務が未登録",IF(COUNTIFS('業務'!$C$4:$C$200,A5,'業務'!$J$4:$J$200,"済")=H5,"済","未")))
A6: SYS-041 | B6: 実験データ集計ツール | C6: 研究本部 | D6: いいえ | E6: いいえ | G6: =IF(A6="","",COUNTIF('紐付け'!$C$4:$C$200,A6)) | H6: =IF(A6="","",COUNTIF('業務'!$C$4:$C$200,A6)) | I6: =IF(A6="","",IF(H6=0,"業務が未登録",IF(COUNTIFS('業務'!$C$4:$C$200,A6,'業務'!$J$4:$J$200,"済")=H6,"済","未")))
G7: =IF(A7="","",COUNTIF('紐付け'!$C$4:$C$200,A7)) | H7: =IF(A7="","",COUNTIF('業務'!$C$4:$C$200,A7)) | I7: =IF(A7="","",IF(H7=0,"業務が未登録",IF(COUNTIFS('業務'!$C$4:$C$200,A7,'業務'!$J$4:$J$200,"済")=H7,"済","未")))
G8: =IF(A8="","",COUNTIF('紐付け'!$C$4:$C$200,A8)) | H8: =IF(A8="","",COUNTIF('業務'!$C$4:$C$200,A8)) | I8: =IF(A8="","",IF(H8=0,"業務が未登録",IF(COUNTIFS('業務'!$C$4:$C$200,A8,'業務'!$J$4:$J$200,"済")=H8,"済","未")))
G9: =IF(A9="","",COUNTIF('紐付け'!$C$4:$C$200,A9)) | H9: =IF(A9="","",COUNTIF('業務'!$C$4:$C$200,A9)) | I9: =IF(A9="","",IF(H9=0,"業務が未登録",IF(COUNTIFS('業務'!$C$4:$C$200,A9,'業務'!$J$4:$J$200,"済")=H9,"済","未")))
G10: =IF(A10="","",COUNTIF('紐付け'!$C$4:$C$200,A10)) | H10: =IF(A10="","",COUNTIF('業務'!$C$4:$C$200,A10)) | I10: =IF(A10="","",IF(H10=0,"業務が未登録",IF(COUNTIFS('業務'!$C$4:$C$200,A10,'業務'!$J$4:$J$200,"済")=H10,"済","未")))
G11: =IF(A11="","",COUNTIF('紐付け'!$C$4:$C$200,A11)) | H11: =IF(A11="","",COUNTIF('業務'!$C$4:$C$200,A11)) | I11: =IF(A11="","",IF(H11=0,"業務が未登録",IF(COUNTIFS('業務'!$C$4:$C$200,A11,'業務'!$J$4:$J$200,"済")=H11,"済","未")))
G12: =IF(A12="","",COUNTIF('紐付け'!$C$4:$C$200,A12)) | H12: =IF(A12="","",COUNTIF('業務'!$C$4:$C$200,A12)) | I12: =IF(A12="","",IF(H12=0,"業務が未登録",IF(COUNTIFS('業務'!$C$4:$C$200,A12,'業務'!$J$4:$J$200,"済")=H12,"済","未")))
G13: =IF(A13="","",COUNTIF('紐付け'!$C$4:$C$200,A13)) | H13: =IF(A13="","",COUNTIF('業務'!$C$4:$C$200,A13)) | I13: =IF(A13="","",IF(H13=0,"業務が未登録",IF(COUNTIFS('業務'!$C$4:$C$200,A13,'業務'!$J$4:$J$200,"済")=H13,"済","未")))
G14: =IF(A14="","",COUNTIF('紐付け'!$C$4:$C$200,A14)) | H14: =IF(A14="","",COUNTIF('業務'!$C$4:$C$200,A14)) | I14: =IF(A14="","",IF(H14=0,"業務が未登録",IF(COUNTIFS('業務'!$C$4:$C$200,A14,'業務'!$J$4:$J$200,"済")=H14,"済","未")))
G15: =IF(A15="","",COUNTIF('紐付け'!$C$4:$C$200,A15)) | H15: =IF(A15="","",COUNTIF('業務'!$C$4:$C$200,A15)) | I15: =IF(A15="","",IF(H15=0,"業務が未登録",IF(COUNTIFS('業務'!$C$4:$C$200,A15,'業務'!$J$4:$J$200,"済")=H15,"済","未")))
G16: =IF(A16="","",COUNTIF('紐付け'!$C$4:$C$200,A16)) | H16: =IF(A16="","",COUNTIF('業務'!$C$4:$C$200,A16)) | I16: =IF(A16="","",IF(H16=0,"業務が未登録",IF(COUNTIFS('業務'!$C$4:$C$200,A16,'業務'!$J$4:$J$200,"済")=H16,"済","未")))
G17: =IF(A17="","",COUNTIF('紐付け'!$C$4:$C$200,A17)) | H17: =IF(A17="","",COUNTIF('業務'!$C$4:$C$200,A17)) | I17: =IF(A17="","",IF(H17=0,"業務が未登録",IF(COUNTIFS('業務'!$C$4:$C$200,A17,'業務'!$J$4:$J$200,"済")=H17,"済","未")))
G18: =IF(A18="","",COUNTIF('紐付け'!$C$4:$C$200,A18)) | H18: =IF(A18="","",COUNTIF('業務'!$C$4:$C$200,A18)) | I18: =IF(A18="","",IF(H18=0,"業務が未登録",IF(COUNTIFS('業務'!$C$4:$C$200,A18,'業務'!$J$4:$J$200,"済")=H18,"済","未")))
... G200: =IF(A200="","",COUNTIF('紐付け'!$C$4:$C$200,A200)) | H200: =IF(A200="","",COUNTIF('業務'!$C$4:$C$200,A200)) | I200: =IF(A200="","",IF(H200=0,"業務が未登録",IF(COUNTIFS('業務'!$C$4:$C$200,A200,'業務'!$J$4:$J$200,"済")=H200,"済","未")))

Sheet 業務
A1: 業務（直接業務と間接業務の棚卸し）
A2: 1行＝1つの業務。システムに関わる、移管対象部門の業務を棚卸しする。業務の種類を選ぶと業務区分が自動で決まる。間接業務（予算・契約の管理、発注・検収・支払い、委託先の管理など）は移管し、直接業務（業務要件の決定、業務での利用、受け入れの確認、部門で行う運用など）は移管対象部門に残る。区分は全ての案件で同じで、案件ごとに変えない。今の担当が SOP・規程など承認済みの文書や記録で定められていて、担当の変更に正式な手続き（例：GxPの変更管理）が要る間接業務は、手続きが完了するまで今の担当のまま行う（経過措置）。その業務だけ、完了予定（S）と手続きの内容（T）を書く（予算は一括して移す）。契約を管理する業務には関連契約IDを書く。灰色の列は数式。薄い色の行は記入例。 業務は案件×システムの単位で書く。同じシステムの業務でも、案件ごとに行を分け、案件ID（U）を入れる（案件IDと対象システムIDの組み合わせは紐付けシートにあること）。 経費予算の案件は、紐付けたシステムごとに、その案件の間接業務を1行以上書く（ないと間接業務の判定が判定保留のまま）。新規の投資案件は業務を書かない。
A3: 業務ID | B3: 業務名 | C3: 対象システムID | D3: システム名（自動） | E3: 業務の種類 | F3: 業務区分（自動） | G3: 現在の実施者 | H3: 頻度 | I3: 年間工数（人日） | J3: 棚卸し （済／未） | K3: GxP対象 | L3: 個人情報 | M3: SOP有無 | N3: 関連契約ID | O3: 現場の関わり方 （間接業務のみ） | P3: 困難度（自動） | Q3: 業務移管判定（自動） | R3: 移管の方法（自動） | S3: 経過措置の完了予定 （担当の変更に手続きが要る業務のみ） | T3: 変更手続きの内容 （例：GxPの変更管理） | U3: 案件ID | V3: 案件名（自動）
A4: OPS-001 | B4: クラウド運用の委託先への指示と障害時の連絡 | C4: SYS-012 | D4: =IF(C4="","",IFERROR(INDEX('システム'!$B:$B,MATCH(C4,'システム'!$A:$A,0)),"システムが未登録")) | E4: 委託先の管理（指示・報告の確認） | F4: =IF(E4="","",IFERROR(INDEX('選択肢'!$L$5:$L$14,MATCH(E4,'選択肢'!$K$5:$K$14,0)),"選択肢にない種類")) | G4: 現場部門 | H4: 随時 | I4: 30 | J4: 済 | K4: いいえ | L4: いいえ | M4: 有 | N4: CT-2201 | O4: 委託先の管理（指示・検収） | P4: =IF(A4="","",IF(F4="直接業務","—",IF(J4<>"済","判定保留",IF(OR(O4="",K4="",L4="",M4="",K4="未確認",L4="未確認"),"判定保留",IF(AND(K4="はい",M4="無"),"入力エラー（GxP対象でSOP無）",IFERROR(INDEX('判定表'!$D:$D,MATCH("W|"&O4&"|"&IF(OR(K4="はい",L4="はい",M4="無"),"あり","なし"),'判定表'!$A:$A,0)),"判定表にない組み合わせ")))))) | Q4: =IF(A4="","",IF(C4="","対象外",IF(F4="直接業務","対象外",IF(OR(F4<>"間接業務",COUNTIF('システム'!$A$4:$A$200,C4)=0,U4="",V4="紐付けにない組み合わせ",V4="案件が未登録"),"判定保留","移管")))) | R4: =IF(A4="","",IF(Q4<>"移管","—",IF(O4="","判定保留",IFERROR(INDEX('判定表'!$E:$E,MATCH("W|"&O4&"|なし",'判定表'!$A:$A,0)),"判定表にない回答")))) | U4: BUD-001 | V4: =IF(U4="","",IF(COUNTIFS('紐付け'!$A$4:$A$200,U4,'紐付け'!$C$4:$C$200,C4)=0,"紐付けにない組み合わせ",IFERROR(INDEX('予算一覧'!$B:$B,MATCH(U4,'予算一覧'!$A:$A,0)),"案件が未登録")))
A5: OPS-002 | B5: 利用者アカウントの登録・削除 | C5: SYS-003 | D5: =IF(C5="","",IFERROR(INDEX('システム'!$B:$B,MATCH(C5,'システム'!$A:$A,0)),"システムが未登録")) | E5: 部門で行う運用（ユーザー管理など） | F5: =IF(E5="","",IFERROR(INDEX('選択肢'!$L$5:$L$14,MATCH(E5,'選択肢'!$K$5:$K$14,0)),"選択肢にない種類")) | G5: 現場部門 | H5: 随時 | I5: 24 | J5: 済 | K5: はい | L5: いいえ | M5: 有 | P5: =IF(A5="","",IF(F5="直接業務","—",IF(J5<>"済","判定保留",IF(OR(O5="",K5="",L5="",M5="",K5="未確認",L5="未確認"),"判定保留",IF(AND(K5="はい",M5="無"),"入力エラー（GxP対象でSOP無）",IFERROR(INDEX('判定表'!$D:$D,MATCH("W|"&O5&"|"&IF(OR(K5="はい",L5="はい",M5="無"),"あり","なし"),'判定表'!$A:$A,0)),"判定表にない組み合わせ")))))) | Q5: =IF(A5="","",IF(C5="","対象外",IF(F5="直接業務","対象外",IF(OR(F5<>"間接業務",COUNTIF('システム'!$A$4:$A$200,C5)=0,U5="",V5="紐付けにない組み合わせ",V5="案件が未登録"),"判定保留","移管")))) | R5: =IF(A5="","",IF(Q5<>"移管","—",IF(O5="","判定保留",IFERROR(INDEX('判定表'!$E:$E,MATCH("W|"&O5&"|なし",'判定表'!$A:$A,0)),"判定表にない回答")))) | U5: BUD-002 | V5: =IF(U5="","",IF(COUNTIFS('紐付け'!$A$4:$A$200,U5,'紐付け'!$C$4:$C$200,C5)=0,"紐付けにない組み合わせ",IFERROR(INDEX('予算一覧'!$B:$B,MATCH(U5,'予算一覧'!$A:$A,0)),"案件が未登録")))
A6: OPS-003 | B6: 委託先の月次報告の確認と検収 | C6: SYS-012 | D6: =IF(C6="","",IFERROR(INDEX('システム'!$B:$B,MATCH(C6,'システム'!$A:$A,0)),"システムが未登録")) | E6: 発注・検収・支払い | F6: =IF(E6="","",IFERROR(INDEX('選択肢'!$L$5:$L$14,MATCH(E6,'選択肢'!$K$5:$K$14,0)),"選択肢にない種類")) | G6: 現場部門 | H6: 月次 | I6: 12 | J6: 済 | K6: いいえ | L6: いいえ | M6: 無 | N6: CT-2201 | O6: 委託先の管理（指示・検収） | P6: =IF(A6="","",IF(F6="直接業務","—",IF(J6<>"済","判定保留",IF(OR(O6="",K6="",L6="",M6="",K6="未確認",L6="未確認"),"判定保留",IF(AND(K6="はい",M6="無"),"入力エラー（GxP対象でSOP無）",IFERROR(INDEX('判定表'!$D:$D,MATCH("W|"&O6&"|"&IF(OR(K6="はい",L6="はい",M6="無"),"あり","なし"),'判定表'!$A:$A,0)),"判定表にない組み合わせ")))))) | Q6: =IF(A6="","",IF(C6="","対象外",IF(F6="直接業務","対象外",IF(OR(F6<>"間接業務",COUNTIF('システム'!$A$4:$A$200,C6)=0,U6="",V6="紐付けにない組み合わせ",V6="案件が未登録"),"判定保留","移管")))) | R6: =IF(A6="","",IF(Q6<>"移管","—",IF(O6="","判定保留",IFERROR(INDEX('判定表'!$E:$E,MATCH("W|"&O6&"|なし",'判定表'!$A:$A,0)),"判定表にない回答")))) | U6: BUD-001 | V6: =IF(U6="","",IF(COUNTIFS('紐付け'!$A$4:$A$200,U6,'紐付け'!$C$4:$C$200,C6)=0,"紐付けにない組み合わせ",IFERROR(INDEX('予算一覧'!$B:$B,MATCH(U6,'予算一覧'!$A:$A,0)),"案件が未登録")))
A7: OPS-004 | B7: eDMS保守契約の発注・検収・支払い | C7: SYS-003 | D7: =IF(C7="","",IFERROR(INDEX('システム'!$B:$B,MATCH(C7,'システム'!$A:$A,0)),"システムが未登録")) | E7: 発注・検収・支払い | F7: =IF(E7="","",IFERROR(INDEX('選択肢'!$L$5:$L$14,MATCH(E7,'選択肢'!$K$5:$K$14,0)),"選択肢にない種類")) | G7: 現場部門 | H7: 月次 | I7: 6 | J7: 済 | K7: はい | L7: いいえ | M7: 有 | N7: CT-1187 | O7: 予算・契約の管理のみ | P7: =IF(A7="","",IF(F7="直接業務","—",IF(J7<>"済","判定保留",IF(OR(O7="",K7="",L7="",M7="",K7="未確認",L7="未確認"),"判定保留",IF(AND(K7="はい",M7="無"),"入力エラー（GxP対象でSOP無）",IFERROR(INDEX('判定表'!$D:$D,MATCH("W|"&O7&"|"&IF(OR(K7="はい",L7="はい",M7="無"),"あり","なし"),'判定表'!$A:$A,0)),"判定表にない組み合わせ")))))) | Q7: =IF(A7="","",IF(C7="","対象外",IF(F7="直接業務","対象外",IF(OR(F7<>"間接業務",COUNTIF('システム'!$A$4:$A$200,C7)=0,U7="",V7="紐付けにない組み合わせ",V7="案件が未登録"),"判定保留","移管")))) | R7: =IF(A7="","",IF(Q7<>"移管","—",IF(O7="","判定保留",IFERROR(INDEX('判定表'!$E:$E,MATCH("W|"&O7&"|なし",'判定表'!$A:$A,0)),"判定表にない回答")))) | S7: 46661 | T7: GxPの変更管理（SOPの改訂とIT部門の手順の制定）。完了までは品質保証部の担当のまま行う | U7: BUD-002 | V7: =IF(U7="","",IF(COUNTIFS('紐付け'!$A$4:$A$200,U7,'紐付け'!$C$4:$C$200,C7)=0,"紐付けにない組み合わせ",IFERROR(INDEX('予算一覧'!$B:$B,MATCH(U7,'予算一覧'!$A:$A,0)),"案件が未登録")))
A8: OPS-005 | B8: 集計ツールの使い方の問い合わせ対応 | C8: SYS-041 | D8: =IF(C8="","",IFERROR(INDEX('システム'!$B:$B,MATCH(C8,'システム'!$A:$A,0)),"システムが未登録")) | E8: 利用者への教育 | F8: =IF(E8="","",IFERROR(INDEX('選択肢'!$L$5:$L$14,MATCH(E8,'選択肢'!$K$5:$K$14,0)),"選択肢にない種類")) | G8: 現場部門 | H8: 随時 | I8: 10 | J8: 済 | K8: いいえ | L8: いいえ | M8: 無 | P8: =IF(A8="","",IF(F8="直接業務","—",IF(J8<>"済","判定保留",IF(OR(O8="",K8="",L8="",M8="",K8="未確認",L8="未確認"),"判定保留",IF(AND(K8="はい",M8="無"),"入力エラー（GxP対象でSOP無）",IFERROR(INDEX('判定表'!$D:$D,MATCH("W|"&O8&"|"&IF(OR(K8="はい",L8="はい",M8="無"),"あり","なし"),'判定表'!$A:$A,0)),"判定表にない組み合わせ")))))) | Q8: =IF(A8="","",IF(C8="","対象外",IF(F8="直接業務","対象外",IF(OR(F8<>"間接業務",COUNTIF('システム'!$A$4:$A$200,C8)=0,U8="",V8="紐付けにない組み合わせ",V8="案件が未登録"),"判定保留","移管")))) | R8: =IF(A8="","",IF(Q8<>"移管","—",IF(O8="","判定保留",IFERROR(INDEX('判定表'!$E:$E,MATCH("W|"&O8&"|なし",'判定表'!$A:$A,0)),"判定表にない回答")))) | U8: BUD-003 | V8: =IF(U8="","",IF(COUNTIFS('紐付け'!$A$4:$A$200,U8,'紐付け'!$C$4:$C$200,C8)=0,"紐付けにない組み合わせ",IFERROR(INDEX('予算一覧'!$B:$B,MATCH(U8,'予算一覧'!$A:$A,0)),"案件が未登録")))
D9: =IF(C9="","",IFERROR(INDEX('システム'!$B:$B,MATCH(C9,'システム'!$A:$A,0)),"システムが未登録")) | F9: =IF(E9="","",IFERROR(INDEX('選択肢'!$L$5:$L$14,MATCH(E9,'選択肢'!$K$5:$K$14,0)),"選択肢にない種類")) | P9: =IF(A9="","",IF(F9="直接業務","—",IF(J9<>"済","判定保留",IF(OR(O9="",K9="",L9="",M9="",K9="未確認",L9="未確認"),"判定保留",IF(AND(K9="はい",M9="無"),"入力エラー（GxP対象でSOP無）",IFERROR(INDEX('判定表'!$D:$D,MATCH("W|"&O9&"|"&IF(OR(K9="はい",L9="はい",M9="無"),"あり","なし"),'判定表'!$A:$A,0)),"判定表にない組み合わせ")))))) | Q9: =IF(A9="","",IF(C9="","対象外",IF(F9="直接業務","対象外",IF(OR(F9<>"間接業務",COUNTIF('システム'!$A$4:$A$200,C9)=0,U9="",V9="紐付けにない組み合わせ",V9="案件が未登録"),"判定保留","移管")))) | R9: =IF(A9="","",IF(Q9<>"移管","—",IF(O9="","判定保留",IFERROR(INDEX('判定表'!$E:$E,MATCH("W|"&O9&"|なし",'判定表'!$A:$A,0)),"判定表にない回答")))) | V9: =IF(U9="","",IF(COUNTIFS('紐付け'!$A$4:$A$200,U9,'紐付け'!$C$4:$C$200,C9)=0,"紐付けにない組み合わせ",IFERROR(INDEX('予算一覧'!$B:$B,MATCH(U9,'予算一覧'!$A:$A,0)),"案件が未登録")))
D10: =IF(C10="","",IFERROR(INDEX('システム'!$B:$B,MATCH(C10,'システム'!$A:$A,0)),"システムが未登録")) | F10: =IF(E10="","",IFERROR(INDEX('選択肢'!$L$5:$L$14,MATCH(E10,'選択肢'!$K$5:$K$14,0)),"選択肢にない種類")) | P10: =IF(A10="","",IF(F10="直接業務","—",IF(J10<>"済","判定保留",IF(OR(O10="",K10="",L10="",M10="",K10="未確認",L10="未確認"),"判定保留",IF(AND(K10="はい",M10="無"),"入力エラー（GxP対象でSOP無）",IFERROR(INDEX('判定表'!$D:$D,MATCH("W|"&O10&"|"&IF(OR(K10="はい",L10="はい",M10="無"),"あり","なし"),'判定表'!$A:$A,0)),"判定表にない組み合わせ")))))) | Q10: =IF(A10="","",IF(C10="","対象外",IF(F10="直接業務","対象外",IF(OR(F10<>"間接業務",COUNTIF('システム'!$A$4:$A$200,C10)=0,U10="",V10="紐付けにない組み合わせ",V10="案件が未登録"),"判定保留","移管")))) | R10: =IF(A10="","",IF(Q10<>"移管","—",IF(O10="","判定保留",IFERROR(INDEX('判定表'!$E:$E,MATCH("W|"&O10&"|なし",'判定表'!$A:$A,0)),"判定表にない回答")))) | V10: =IF(U10="","",IF(COUNTIFS('紐付け'!$A$4:$A$200,U10,'紐付け'!$C$4:$C$200,C10)=0,"紐付けにない組み合わせ",IFERROR(INDEX('予算一覧'!$B:$B,MATCH(U10,'予算一覧'!$A:$A,0)),"案件が未登録")))
D11: =IF(C11="","",IFERROR(INDEX('システム'!$B:$B,MATCH(C11,'システム'!$A:$A,0)),"システムが未登録")) | F11: =IF(E11="","",IFERROR(INDEX('選択肢'!$L$5:$L$14,MATCH(E11,'選択肢'!$K$5:$K$14,0)),"選択肢にない種類")) | P11: =IF(A11="","",IF(F11="直接業務","—",IF(J11<>"済","判定保留",IF(OR(O11="",K11="",L11="",M11="",K11="未確認",L11="未確認"),"判定保留",IF(AND(K11="はい",M11="無"),"入力エラー（GxP対象でSOP無）",IFERROR(INDEX('判定表'!$D:$D,MATCH("W|"&O11&"|"&IF(OR(K11="はい",L11="はい",M11="無"),"あり","なし"),'判定表'!$A:$A,0)),"判定表にない組み合わせ")))))) | Q11: =IF(A11="","",IF(C11="","対象外",IF(F11="直接業務","対象外",IF(OR(F11<>"間接業務",COUNTIF('システム'!$A$4:$A$200,C11)=0,U11="",V11="紐付けにない組み合わせ",V11="案件が未登録"),"判定保留","移管")))) | R11: =IF(A11="","",IF(Q11<>"移管","—",IF(O11="","判定保留",IFERROR(INDEX('判定表'!$E:$E,MATCH("W|"&O11&"|なし",'判定表'!$A:$A,0)),"判定表にない回答")))) | V11: =IF(U11="","",IF(COUNTIFS('紐付け'!$A$4:$A$200,U11,'紐付け'!$C$4:$C$200,C11)=0,"紐付けにない組み合わせ",IFERROR(INDEX('予算一覧'!$B:$B,MATCH(U11,'予算一覧'!$A:$A,0)),"案件が未登録")))
D12: =IF(C12="","",IFERROR(INDEX('システム'!$B:$B,MATCH(C12,'システム'!$A:$A,0)),"システムが未登録")) | F12: =IF(E12="","",IFERROR(INDEX('選択肢'!$L$5:$L$14,MATCH(E12,'選択肢'!$K$5:$K$14,0)),"選択肢にない種類")) | P12: =IF(A12="","",IF(F12="直接業務","—",IF(J12<>"済","判定保留",IF(OR(O12="",K12="",L12="",M12="",K12="未確認",L12="未確認"),"判定保留",IF(AND(K12="はい",M12="無"),"入力エラー（GxP対象でSOP無）",IFERROR(INDEX('判定表'!$D:$D,MATCH("W|"&O12&"|"&IF(OR(K12="はい",L12="はい",M12="無"),"あり","なし"),'判定表'!$A:$A,0)),"判定表にない組み合わせ")))))) | Q12: =IF(A12="","",IF(C12="","対象外",IF(F12="直接業務","対象外",IF(OR(F12<>"間接業務",COUNTIF('システム'!$A$4:$A$200,C12)=0,U12="",V12="紐付けにない組み合わせ",V12="案件が未登録"),"判定保留","移管")))) | R12: =IF(A12="","",IF(Q12<>"移管","—",IF(O12="","判定保留",IFERROR(INDEX('判定表'!$E:$E,MATCH("W|"&O12&"|なし",'判定表'!$A:$A,0)),"判定表にない回答")))) | V12: =IF(U12="","",IF(COUNTIFS('紐付け'!$A$4:$A$200,U12,'紐付け'!$C$4:$C$200,C12)=0,"紐付けにない組み合わせ",IFERROR(INDEX('予算一覧'!$B:$B,MATCH(U12,'予算一覧'!$A:$A,0)),"案件が未登録")))
