Workbook

Sheet 使い方
A1: ケイパビリティ観測 調査集計・スコアリングブック
A2: ジョブロール別ケイパビリティ観測計画（骨格）に対応。アンケートで集めた結果を転記し、can-do到達率(y)の推移を見るためのブックです。
A4: 手順1 | B4: 「マスタ設定」を埋める。職種×担当領域、対象者名簿、四半期の期末日、難易度区分の定義。ここが空だと以降が計算されません。
A5: 手順2 | B5: アンケートの回収結果を「調査集計表」に1案件1行で転記する。黄色いセルだけを埋めます。
A6: 手順3 | B6: 「スコアリング」「四半期集計」「成長曲線」は自動計算です。手を入れる必要はありません。
A8: 色の意味 | B8: 黄色地・青文字＝入力するセル ／ 白地・黒文字＝自動計算 ／ グレー地・斜体＝記入例
A9: 記入例について | B9: 「マスタ設定」と「調査集計表」にはグレーの記入例が入っています。実データを入れる前に、記入例の行を削除してください。
A11: 採点の考え方 | B11: 案件ごとに2つの軸を5段階で採点し、要求水準（レベル3）を100とする比に換算して合成します。
B12: レベル1→33／レベル2→67／レベル3→100／レベル4→133／レベル5→167
B13: フィードバック軸は関与者3名以上の中央値。品質・コスト軸は案件責任者とレビュアーの平均。
B14: 合成の重みは職種×担当領域ごとに「マスタ設定」で指定します。
A16: 四半期の値 | B16: その期末から遡って12か月以内に完了した案件の平均です。案件のない期でも数字が途切れないようにするためです。
A17: 有効判定 | B17: 関与者の回答が3名以上、かつ品質・コスト軸を2名が採点している案件を「有効」とし、集計対象にします。
B18: 「要確認」の案件は集計に入りません。人数を満たすか、集計から外すかを判断してください。
A20: 注意 | B20: y の絶対値は細かく読みません。要求水準（100）に対してどちら側にいるか、時間を追ってどう動いているかを見ます。

Sheet マスタ設定
A1: マスタ設定
A2: 黄色いセルを埋めてください。ここが観測の前提になります。
A3: 【1】職種×担当領域マスタ ― 要求水準（＝100）と型の方針は、この組み合わせごとに決めます
A4: 単位ID | B4: 職種 | C4: 担当領域 | D4: 型の方針 | E4: フィードバック重み(%) | F4: 品質・コスト重み(%) | G4: レベル3（要求水準）の状態記述
A5: U01 | B5: ビジネスパートナー | C5: ERP領域（専任） | D5: 飽和型 | E5: 70 | F5: 30 | G5: ERP標準機能の範囲で、事業部門から直接相談を受け、技術検討を介さず自分で提言できる
A6: U02 | B6: データアーキテクト | C6: データ活用基盤 | D6: 創発型 | E6: 50 | F6: 50 | G6: 全社標準のデータアーキテクチャを、レビューなしで自律的に設計できる
A15: ※ 型の方針は「飽和型」または「創発型」。重みは2つの合計が100になるようにします（既定は50／50）。
A16: 【2】対象者名簿
A17: 対象者ID | B17: 氏名 | C17: 単位ID | D17: 群（任意） | E17: 備考
A18: P01 | B18: 佐藤（記入例） | C18: U01 | D18: 介入群
A19: P02 | B19: 鈴木（記入例） | C19: U01 | D19: 対照群
A20: P03 | B20: 田中（記入例） | C20: U02 | D20: 介入群
A39: 【3】四半期の定義 ― 期末日は、その期に「完了した案件」を締める日付です
A40: 期ラベル | B40: 期末日 | C40: 経過t（0〜100）
A41: 2026 Q1 | B41: 46112 | C41: 0
A42: 2026 Q2 | B42: 46203 | C42: 12.5
A43: 2026 Q3 | B43: 46295 | C43: 25
A44: 2026 Q4 | B44: 46387 | C44: 37.5
A45: 2027 Q1 | B45: 46477 | C45: 50
A46: 2027 Q2 | B46: 46568 | C46: 62.5
A47: 2027 Q3 | B47: 46660 | C47: 75
A48: 2027 Q4 | B48: 46752 | C48: 87.5
A49: 2028 Q1 | B49: 46843 | C49: 100
A50: ※ 経過t は「測定開始＝0、目標の期限＝100」の目盛りです。2年・四半期測定なら 0, 12.5, … , 100 の9回になります。
A51: 【4】難易度区分の定義 ― 最初に決めて、途中で動かしません
A52: 区分 | B52: 定義
A53: 難1 | B53: 定型的。過去の類似案件をなぞれば進められる
A54: 難2 | B54: 標準的。判断を要する論点がいくつかある
A55: 難3 | B55: 困難。前例がない、または関係者が多く調整が重い
A57: 【5】採点の5段階（参照用） ― 要求水準はレベル3に置きます
A58: レベル | B58: フィードバック軸 | C58: 品質・コスト軸 | D58: y換算
A59: 5 | B59: この人の関与をきっかけに、他の人や他の案件のやり方自体が変わった | C59: 成果物が他の案件でも再利用され、他の案件の手間まで下げた | D59: 167
A60: 4 | B60: 担当範囲を超えて、他の案件や他のメンバーにも良い影響が及んだ | C60: 品質を満たしたうえで、手間が想定より少なかった | D60: 133
A61: 3 | B61: この領域で任せるべき範囲を、確認なしで任せられた（＝要求水準） | C61: 求められる品質を満たし、手間も想定どおりだった（＝要求水準） | D61: 100
A62: 2 | B62: 決められた範囲は任せられるが、判断は周囲に確認しながらだった | C62: 成果物は使えるが、指摘が多かった／想定より手間がかかった | D62: 67
A63: 1 | B63: 単独では任せられなかった。手戻りや補助が必要だった | C63: 品質か手間のどちらかに問題があり、やり直しや追加の手当てが必要だった | D63: 33
A64: ※ 物差しの上端を要求水準に置かないこと。レベル4・5が無くなると、要求を超えて伸びている状態（過剰投資）が見えなくなります。

Sheet 調査集計表
A1: 調査集計表 ― アンケートの回収結果を、1案件1行で転記します | I1: ※ 関与者の枠は5名分。6名以上から回答があった場合は、案件責任者が指名した5名までを転記します。
A2: 案件ID | B2: 案件名 | C2: 完了日 | D2: 対象者ID | E2: 対象者氏名 | F2: 単位ID | G2: 役割 | H2: 難易度区分 | I2: 関与者1 氏名 | J2: 関与者1 点 | K2: 関与者2 氏名 | L2: 関与者2 点 | M2: 関与者3 氏名 | N2: 関与者3 点 | O2: 関与者4 氏名 | P2: 関与者4 点 | Q2: 関与者5 氏名 | R2: 関与者5 点 | S2: 案件責任者 氏名 | T2: 責任者 品質・コスト点 | U2: レビュアー 氏名 | V2: レビュアー 品質・コスト点 | W2: 備考
A3: A-001 | B3: 販売管理 追加要件対応 | C3: 46063 | D3: P01 | E3: =IFERROR(INDEX(マスタ設定!$B$18:$B$37,MATCH($D3,マスタ設定!$A$18:$A$37,0)),"") -> 佐藤（記入例） | F3: =IFERROR(INDEX(マスタ設定!$C$18:$C$37,MATCH($D3,マスタ設定!$A$18:$A$37,0)),"") -> U01 | G3: 要件定義 | H3: 難2 | I3: 関与者A | J3: 2 | K3: 関与者B | L3: 2 | M3: 関与者C | N3: 3 | S3: 責任者X | T3: 2 | U3: レビュアーY | V3: 2 | W3: 記入例
A4: A-002 | B4: 会計月次締め改善 | C4: 46086 | D4: P01 | E4: =IFERROR(INDEX(マスタ設定!$B$18:$B$37,MATCH($D4,マスタ設定!$A$18:$A$37,0)),"") -> 佐藤（記入例） | F4: =IFERROR(INDEX(マスタ設定!$C$18:$C$37,MATCH($D4,マスタ設定!$A$18:$A$37,0)),"") -> U01 | G4: 要件定義 | H4: 難1 | I4: 関与者A | J4: 3 | K4: 関与者B | L4: 2 | M4: 関与者C | N4: 2 | S4: 責任者X | T4: 2 | U4: レビュアーY | V4: 3 | W4: 記入例
A5: A-003 | B5: 購買マスタ統合 | C5: 46162 | D5: P01 | E5: =IFERROR(INDEX(マスタ設定!$B$18:$B$37,MATCH($D5,マスタ設定!$A$18:$A$37,0)),"") -> 佐藤（記入例） | F5: =IFERROR(INDEX(マスタ設定!$C$18:$C$37,MATCH($D5,マスタ設定!$A$18:$A$37,0)),"") -> U01 | G5: 要件定義・調整 | H5: 難2 | I5: 関与者A | J5: 3 | K5: 関与者B | L5: 3 | M5: 関与者C | N5: 2 | O5: 関与者D | P5: 3 | S5: 責任者X | T5: 3 | U5: レビュアーY | V5: 3 | W5: 記入例
A6: A-004 | B6: 在庫可視化 要件整理 | C6: 46246 | D6: P01 | E6: =IFERROR(INDEX(マスタ設定!$B$18:$B$37,MATCH($D6,マスタ設定!$A$18:$A$37,0)),"") -> 佐藤（記入例） | F6: =IFERROR(INDEX(マスタ設定!$C$18:$C$37,MATCH($D6,マスタ設定!$A$18:$A$37,0)),"") -> U01 | G6: 要件定義 | H6: 難2 | I6: 関与者A | J6: 3 | K6: 関与者B | L6: 3 | M6: 関与者C | N6: 3 | S6: 責任者X | T6: 3 | U6: レビュアーY | V6: 3 | W6: 記入例
A7: A-005 | B7: 受注プロセス見直し | C7: 46344 | D7: P01 | E7: =IFERROR(INDEX(マスタ設定!$B$18:$B$37,MATCH($D7,マスタ設定!$A$18:$A$37,0)),"") -> 佐藤（記入例） | F7: =IFERROR(INDEX(マスタ設定!$C$18:$C$37,MATCH($D7,マスタ設定!$A$18:$A$37,0)),"") -> U01 | G7: 提言・調整 | H7: 難3 | I7: 関与者A | J7: 4 | K7: 関与者B | L7: 3 | M7: 関与者C | N7: 4 | O7: 関与者D | P7: 3 | S7: 責任者X | T7: 3 | U7: レビュアーY | V7: 4 | W7: 記入例
A8: A-006 | B8: ERP標準化 方針策定 | C8: 46440 | D8: P01 | E8: =IFERROR(INDEX(マスタ設定!$B$18:$B$37,MATCH($D8,マスタ設定!$A$18:$A$37,0)),"") -> 佐藤（記入例） | F8: =IFERROR(INDEX(マスタ設定!$C$18:$C$37,MATCH($D8,マスタ設定!$A$18:$A$37,0)),"") -> U01 | G8: 提言 | H8: 難3 | I8: 関与者A | J8: 4 | K8: 関与者B | L8: 4 | M8: 関与者C | N8: 3 | O8: 関与者D | P8: 4 | S8: 責任者X | T8: 4 | U8: レビュアーY | V8: 3 | W8: 記入例
A9: B-001 | B9: 経費精算 改善要望整理 | C9: 46078 | D9: P02 | E9: =IFERROR(INDEX(マスタ設定!$B$18:$B$37,MATCH($D9,マスタ設定!$A$18:$A$37,0)),"") -> 鈴木（記入例） | F9: =IFERROR(INDEX(マスタ設定!$C$18:$C$37,MATCH($D9,マスタ設定!$A$18:$A$37,0)),"") -> U01 | G9: 要件定義 | H9: 難1 | I9: 関与者A | J9: 2 | K9: 関与者B | L9: 2 | M9: 関与者C | N9: 2 | S9: 責任者X | T9: 2 | U9: レビュアーY | V9: 2 | W9: 記入例
A10: B-002 | B10: 販売レポート追加 | C10: 46176 | D10: P02 | E10: =IFERROR(INDEX(マスタ設定!$B$18:$B$37,MATCH($D10,マスタ設定!$A$18:$A$37,0)),"") -> 鈴木（記入例） | F10: =IFERROR(INDEX(マスタ設定!$C$18:$C$37,MATCH($D10,マスタ設定!$A$18:$A$37,0)),"") -> U01 | G10: 要件定義 | H10: 難1 | I10: 関与者A | J10: 2 | K10: 関与者B | L10: 3 | M10: 関与者C | N10: 2 | S10: 責任者X | T10: 2 | U10: レビュアーY | V10: 2 | W10: 記入例
A11: B-003 | B11: 取引先マスタ整備 | C11: 46279 | D11: P02 | E11: =IFERROR(INDEX(マスタ設定!$B$18:$B$37,MATCH($D11,マスタ設定!$A$18:$A$37,0)),"") -> 鈴木（記入例） | F11: =IFERROR(INDEX(マスタ設定!$C$18:$C$37,MATCH($D11,マスタ設定!$A$18:$A$37,0)),"") -> U01 | G11: 要件定義 | H11: 難2 | I11: 関与者A | J11: 3 | K11: 関与者B | L11: 2 | M11: 関与者C | N11: 3 | S11: 責任者X | T11: 3 | U11: レビュアーY | V11: 2 | W11: 記入例
A12: B-004 | B12: 月次レポート自動化 | C12: 46364 | D12: P02 | E12: =IFERROR(INDEX(マスタ設定!$B$18:$B$37,MATCH($D12,マスタ設定!$A$18:$A$37,0)),"") -> 鈴木（記入例） | F12: =IFERROR(INDEX(マスタ設定!$C$18:$C$37,MATCH($D12,マスタ設定!$A$18:$A$37,0)),"") -> U01 | G12: 要件定義 | H12: 難2 | I12: 関与者A | J12: 3 | K12: 関与者B | L12: 3 | M12: 関与者C | N12: 2 | S12: 責任者X | T12: 3 | U12: レビュアーY | V12: 3 | W12: 記入例
A13: B-005 | B13: 与信プロセス整理 | C13: 46456 | D13: P02 | E13: =IFERROR(INDEX(マスタ設定!$B$18:$B$37,MATCH($D13,マスタ設定!$A$18:$A$37,0)),"") -> 鈴木（記入例） | F13: =IFERROR(INDEX(マスタ設定!$C$18:$C$37,MATCH($D13,マスタ設定!$A$18:$A$37,0)),"") -> U01 | G13: 要件定義 | H13: 難2 | I13: 関与者A | J13: 3 | K13: 関与者B | L13: 3 | M13: 関与者C | N13: 3 | S13: 責任者X | T13: 3 | U13: レビュアーY | V13: 3 | W13: 記入例
A14: C-001 | B14: データ基盤 論理設計 | C14: 46071 | D14: P03 | E14: =IFERROR(INDEX(マスタ設定!$B$18:$B$37,MATCH($D14,マスタ設定!$A$18:$A$37,0)),"") -> 田中（記入例） | F14: =IFERROR(INDEX(マスタ設定!$C$18:$C$37,MATCH($D14,マスタ設定!$A$18:$A$37,0)),"") -> U02 | G14: 設計 | H14: 難2 | I14: 関与者A | J14: 3 | K14: 関与者B | L14: 2 | M14: 関与者C | N14: 3 | S14: 責任者X | T14: 3 | U14: レビュアーY | V14: 2 | W14: 記入例
A15: C-002 | B15: 顧客データ統合設計 | C15: 46171 | D15: P03 | E15: =IFERROR(INDEX(マスタ設定!$B$18:$B$37,MATCH($D15,マスタ設定!$A$18:$A$37,0)),"") -> 田中（記入例） | F15: =IFERROR(INDEX(マスタ設定!$C$18:$C$37,MATCH($D15,マスタ設定!$A$18:$A$37,0)),"") -> U02 | G15: 設計 | H15: 難2 | I15: 関与者A | J15: 3 | K15: 関与者B | L15: 3 | M15: 関与者C | N15: 3 | S15: 責任者X | T15: 3 | U15: レビュアーY | V15: 3 | W15: 記入例
A16: C-003 | B16: 共通データモデル策定 | C16: 46290 | D16: P03 | E16: =IFERROR(INDEX(マスタ設定!$B$18:$B$37,MATCH($D16,マスタ設定!$A$18:$A$37,0)),"") -> 田中（記入例） | F16: =IFERROR(INDEX(マスタ設定!$C$18:$C$37,MATCH($D16,マスタ設定!$A$18:$A$37,0)),"") -> U02 | G16: 設計・標準化 | H16: 難3 | I16: 関与者A | J16: 4 | K16: 関与者B | L16: 3 | M16: 関与者C | N16: 4 | O16: 関与者D | P16: 3 | S16: 責任者X | T16: 4 | U16: レビュアーY | V16: 3 | W16: 記入例
A17: C-004 | B17: パイプライン再利用基盤 | C17: 46376 | D17: P03 | E17: =IFERROR(INDEX(マスタ設定!$B$18:$B$37,MATCH($D17,マスタ設定!$A$18:$A$37,0)),"") -> 田中（記入例） | F17: =IFERROR(INDEX(マスタ設定!$C$18:$C$37,MATCH($D17,マスタ設定!$A$18:$A$37,0)),"") -> U02 | G17: 設計・標準化 | H17: 難3 | I17: 関与者A | J17: 4 | K17: 関与者B | L17: 4 | M17: 関与者C | N17: 4 | O17: 関与者D | P17: 4 | S17: 責任者X | T17: 4 | U17: レビュアーY | V17: 4 | W17: 記入例
A18: C-005 | B18: 全社データ標準の展開 | C18: 46464 | D18: P03 | E18: =IFERROR(INDEX(マスタ設定!$B$18:$B$37,MATCH($D18,マスタ設定!$A$18:$A$37,0)),"") -> 田中（記入例） | F18: =IFERROR(INDEX(マスタ設定!$C$18:$C$37,MATCH($D18,マスタ設定!$A$18:$A$37,0)),"") -> U02 | G18: 設計・展開 | H18: 難3 | I18: 関与者A | J18: 5 | K18: 関与者B | L18: 4 | M18: 関与者C | N18: 5 | O18: 関与者D | P18: 4 | S18: 責任者X | T18: 5 | U18: レビュアーY | V18: 4 | W18: 記入例
A19: A-007 | B19: ERP次期構想 支援 | C19: 46553 | D19: P01 | E19: =IFERROR(INDEX(マスタ設定!$B$18:$B$37,MATCH($D19,マスタ設定!$A$18:$A$37,0)),"") -> 佐藤（記入例） | F19: =IFERROR(INDEX(マスタ設定!$C$18:$C$37,MATCH($D19,マスタ設定!$A$18:$A$37,0)),"") -> U01 | G19: 提言 | H19: 難2 | I19: 関与者A | J19: 3 | K19: 関与者B | L19: 4 | M19: 関与者C | N19: 3 | S19: 責任者X | T19: 3 | U19: レビュアーY | V19: 4 | W19: 記入例
A20: A-008 | B20: 販売系 追加要件対応 | C20: 46667 | D20: P01 | E20: =IFERROR(INDEX(マスタ設定!$B$18:$B$37,MATCH($D20,マスタ設定!$A$18:$A$37,0)),"") -> 佐藤（記入例） | F20: =IFERROR(INDEX(マスタ設定!$C$18:$C$37,MATCH($D20,マスタ設定!$A$18:$A$37,0)),"") -> U01 | G20: 要件定義 | H20: 難2 | I20: 関与者A | J20: 3 | K20: 関与者B | L20: 3 | M20: 関与者C | N20: 4 | S20: 責任者X | T20: 3 | U20: レビュアーY | V20: 3 | W20: 記入例
A21: A-009 | B21: 原価管理 改善 | C21: 46788 | D21: P01 | E21: =IFERROR(INDEX(マスタ設定!$B$18:$B$37,MATCH($D21,マスタ設定!$A$18:$A$37,0)),"") -> 佐藤（記入例） | F21: =IFERROR(INDEX(マスタ設定!$C$18:$C$37,MATCH($D21,マスタ設定!$A$18:$A$37,0)),"") -> U01 | G21: 要件定義・提言 | H21: 難2 | I21: 関与者A | J21: 4 | K21: 関与者B | L21: 3 | M21: 関与者C | N21: 3 | S21: 責任者X | T21: 3 | U21: レビュアーY | V21: 4 | W21: 記入例
A22: B-006 | B22: 債権管理 要件整理 | C22: 46589 | D22: P02 | E22: =IFERROR(INDEX(マスタ設定!$B$18:$B$37,MATCH($D22,マスタ設定!$A$18:$A$37,0)),"") -> 鈴木（記入例） | F22: =IFERROR(INDEX(マスタ設定!$C$18:$C$37,MATCH($D22,マスタ設定!$A$18:$A$37,0)),"") -> U01 | G22: 要件定義 | H22: 難2 | I22: 関与者A | J22: 3 | K22: 関与者B | L22: 3 | M22: 関与者C | N22: 3 | S22: 責任者X | T22: 3 | U22: レビュアーY | V22: 3 | W22: 記入例
A23: B-007 | B23: 帳票基盤 移行支援 | C23: 46703 | D23: P02 | E23: =IFERROR(INDEX(マスタ設定!$B$18:$B$37,MATCH($D23,マスタ設定!$A$18:$A$37,0)),"") -> 鈴木（記入例） | F23: =IFERROR(INDEX(マスタ設定!$C$18:$C$37,MATCH($D23,マスタ設定!$A$18:$A$37,0)),"") -> U01 | G23: 要件定義 | H23: 難2 | I23: 関与者A | J23: 3 | K23: 関与者B | L23: 4 | M23: 関与者C | N23: 3 | S23: 責任者X | T23: 3 | U23: レビュアーY | V23: 3 | W23: 記入例
A24: B-008 | B24: 在庫プロセス見直し | C24: 46799 | D24: P02 | E24: =IFERROR(INDEX(マスタ設定!$B$18:$B$37,MATCH($D24,マスタ設定!$A$18:$A$37,0)),"") -> 鈴木（記入例） | F24: =IFERROR(INDEX(マスタ設定!$C$18:$C$37,MATCH($D24,マスタ設定!$A$18:$A$37,0)),"") -> U01 | G24: 要件定義・調整 | H24: 難3 | I24: 関与者A | J24: 3 | K24: 関与者B | L24: 3 | M24: 関与者C | N24: 4 | S24: 責任者X | T24: 3 | U24: レビュアーY | V24: 4 | W24: 記入例
A25: C-006 | B25: データ品質ルール整備 | C25: 46576 | D25: P03 | E25: =IFERROR(INDEX(マスタ設定!$B$18:$B$37,MATCH($D25,マスタ設定!$A$18:$A$37,0)),"") -> 田中（記入例） | F25: =IFERROR(INDEX(マスタ設定!$C$18:$C$37,MATCH($D25,マスタ設定!$A$18:$A$37,0)),"") -> U02 | G25: 設計・標準化 | H25: 難3 | I25: 関与者A | J25: 5 | K25: 関与者B | L25: 4 | M25: 関与者C | N25: 5 | O25: 関与者D | P25: 5 | S25: 責任者X | T25: 5 | U25: レビュアーY | V25: 4 | W25: 記入例
A26: C-007 | B26: 分析基盤 全社展開 | C26: 46718 | D26: P03 | E26: =IFERROR(INDEX(マスタ設定!$B$18:$B$37,MATCH($D26,マスタ設定!$A$18:$A$37,0)),"") -> 田中（記入例） | F26: =IFERROR(INDEX(マスタ設定!$C$18:$C$37,MATCH($D26,マスタ設定!$A$18:$A$37,0)),"") -> U02 | G26: 設計・展開 | H26: 難3 | I26: 関与者A | J26: 5 | K26: 関与者B | L26: 5 | M26: 関与者C | N26: 4 | O26: 関与者D | P26: 5 | S26: 責任者X | T26: 5 | U26: レビュアーY | V26: 5 | W26: 記入例
A27: C-008 | B27: データ設計の外部発信 | C27: 46807 | D27: P03 | E27: =IFERROR(INDEX(マスタ設定!$B$18:$B$37,MATCH($D27,マスタ設定!$A$18:$A$37,0)),"") -> 田中（記入例） | F27: =IFERROR(INDEX(マスタ設定!$C$18:$C$37,MATCH($D27,マスタ設定!$A$18:$A$37,0)),"") -> U02 | G27: 標準化・育成 | H27: 難3 | I27: 関与者A | J27: 5 | K27: 関与者B | L27: 5 | M27: 関与者C | N27: 5 | O27: 関与者D | P27: 4 | S27: 責任者X | T27: 5 | U27: レビュアーY | V27: 5 | W27: 記入例
E28: =IFERROR(INDEX(マスタ設定!$B$18:$B$37,MATCH($D28,マスタ設定!$A$18:$A$37,0)),"") | F28: =IFERROR(INDEX(マスタ設定!$C$18:$C$37,MATCH($D28,マスタ設定!$A$18:$A$37,0)),"")
E29: =IFERROR(INDEX(マスタ設定!$B$18:$B$37,MATCH($D29,マスタ設定!$A$18:$A$37,0)),"") | F29: =IFERROR(INDEX(マスタ設定!$C$18:$C$37,MATCH($D29,マスタ設定!$A$18:$A$37,0)),"")
E30: =IFERROR(INDEX(マスタ設定!$B$18:$B$37,MATCH($D30,マスタ設定!$A$18:$A$37,0)),"") | F30: =IFERROR(INDEX(マスタ設定!$C$18:$C$37,MATCH($D30,マスタ設定!$A$18:$A$37,0)),"")
E31: =IFERROR(INDEX(マスタ設定!$B$18:$B$37,MATCH($D31,マスタ設定!$A$18:$A$37,0)),"") | F31: =IFERROR(INDEX(マスタ設定!$C$18:$C$37,MATCH($D31,マスタ設定!$A$18:$A$37,0)),"")
E32: =IFERROR(INDEX(マスタ設定!$B$18:$B$37,MATCH($D32,マスタ設定!$A$18:$A$37,0)),"") | F32: =IFERROR(INDEX(マスタ設定!$C$18:$C$37,MATCH($D32,マスタ設定!$A$18:$A$37,0)),"")
E33: =IFERROR(INDEX(マスタ設定!$B$18:$B$37,MATCH($D33,マスタ設定!$A$18:$A$37,0)),"") | F33: =IFERROR(INDEX(マスタ設定!$C$18:$C$37,MATCH($D33,マスタ設定!$A$18:$A$37,0)),"")
E34: =IFERROR(INDEX(マスタ設定!$B$18:$B$37,MATCH($D34,マスタ設定!$A$18:$A$37,0)),"") | F34: =IFERROR(INDEX(マスタ設定!$C$18:$C$37,MATCH($D34,マスタ設定!$A$18:$A$37,0)),"")
E35: =IFERROR(INDEX(マスタ設定!$B$18:$B$37,MATCH($D35,マスタ設定!$A$18:$A$37,0)),"") | F35: =IFERROR(INDEX(マスタ設定!$C$18:$C$37,MATCH($D35,マスタ設定!$A$18:$A$37,0)),"")
E36: =IFERROR(INDEX(マスタ設定!$B$18:$B$37,MATCH($D36,マスタ設定!$A$18:$A$37,0)),"") | F36: =IFERROR(INDEX(マスタ設定!$C$18:$C$37,MATCH($D36,マスタ設定!$A$18:$A$37,0)),"")
E37: =IFERROR(INDEX(マスタ設定!$B$18:$B$37,MATCH($D37,マスタ設定!$A$18:$A$37,0)),"") | F37: =IFERROR(INDEX(マスタ設定!$C$18:$C$37,MATCH($D37,マスタ設定!$A$18:$A$37,0)),"")
E38: =IFERROR(INDEX(マスタ設定!$B$18:$B$37,MATCH($D38,マスタ設定!$A$18:$A$37,0)),"") | F38: =IFERROR(INDEX(マスタ設定!$C$18:$C$37,MATCH($D38,マスタ設定!$A$18:$A$37,0)),"")
E39: =IFERROR(INDEX(マスタ設定!$B$18:$B$37,MATCH($D39,マスタ設定!$A$18:$A$37,0)),"") | F39: =IFERROR(INDEX(マスタ設定!$C$18:$C$37,MATCH($D39,マスタ設定!$A$18:$A$37,0)),"")
... E202: =IFERROR(INDEX(マスタ設定!$B$18:$B$37,MATCH($D202,マスタ設定!$A$18:$A$37,0)),"") | F202: =IFERROR(INDEX(マスタ設定!$C$18:$C$37,MATCH($D202,マスタ設定!$A$18:$A$37,0)),"")

Sheet スコアリング
A1: スコアリング ― 自動計算です。手入力しないでください
A2: 案件ID | B2: 完了日 | C2: 対象者ID | D2: 対象者氏名 | E2: 単位ID | F2: 難易度区分 | G2: 関与者 回答数 | H2: フィードバック 素点(中央値) | I2: 品質・コスト 素点(平均) | J2: 品質採点 人数 | K2: フィードバック y換算 | L2: 品質・コスト y換算 | M2: FB重み | N2: QC重み | O2: 合成 y | P2: 判定
A3: =IF(調査集計表!A3="","",調査集計表!A3) -> A-001 | B3: =IF(調査集計表!C3="","",調査集計表!C3) -> 46063 | C3: =IF(調査集計表!D3="","",調査集計表!D3) -> P01 | D3: =IF(調査集計表!E3="","",調査集計表!E3) -> 佐藤（記入例） | E3: =IF(調査集計表!F3="","",調査集計表!F3) -> U01 | F3: =IF(調査集計表!H3="","",調査集計表!H3) -> 難2 | G3: =COUNT(調査集計表!J3,調査集計表!L3,調査集計表!N3,調査集計表!P3,調査集計表!R3) -> 3 | H3: =IF($G3=0,"",MEDIAN(調査集計表!J3,調査集計表!L3,調査集計表!N3,調査集計表!P3,調査集計表!R3)) -> 2 | I3: =IFERROR(AVERAGE(調査集計表!T3,調査集計表!V3),"") -> 2 | J3: =COUNT(調査集計表!T3,調査集計表!V3) -> 2 | K3: =IF($H3="","",ROUND($H3/3*100,1)) -> 66.7 | L3: =IF($I3="","",ROUND($I3/3*100,1)) -> 66.7 | M3: =IFERROR(INDEX(マスタ設定!$E$5:$E$14,MATCH($E3,マスタ設定!$A$5:$A$14,0))/100,"") -> 0.7 | N3: =IFERROR(INDEX(マスタ設定!$F$5:$F$14,MATCH($E3,マスタ設定!$A$5:$A$14,0))/100,"") -> 0.3 | O3: =IF(OR($K3="",$L3="",$M3="",$N3=""),"",ROUND($K3*$M3+$L3*$N3,1)) -> 66.7 | P3: =IF($A3="","",IF($O3="","データ不足",IF(AND($G3>=3,$J3>=2),"有効","要確認"))) -> 有効
A4: =IF(調査集計表!A4="","",調査集計表!A4) -> A-002 | B4: =IF(調査集計表!C4="","",調査集計表!C4) -> 46086 | C4: =IF(調査集計表!D4="","",調査集計表!D4) -> P01 | D4: =IF(調査集計表!E4="","",調査集計表!E4) -> 佐藤（記入例） | E4: =IF(調査集計表!F4="","",調査集計表!F4) -> U01 | F4: =IF(調査集計表!H4="","",調査集計表!H4) -> 難1 | G4: =COUNT(調査集計表!J4,調査集計表!L4,調査集計表!N4,調査集計表!P4,調査集計表!R4) -> 3 | H4: =IF($G4=0,"",MEDIAN(調査集計表!J4,調査集計表!L4,調査集計表!N4,調査集計表!P4,調査集計表!R4)) -> 2 | I4: =IFERROR(AVERAGE(調査集計表!T4,調査集計表!V4),"") -> 2.5 | J4: =COUNT(調査集計表!T4,調査集計表!V4) -> 2 | K4: =IF($H4="","",ROUND($H4/3*100,1)) -> 66.7 | L4: =IF($I4="","",ROUND($I4/3*100,1)) -> 83.3 | M4: =IFERROR(INDEX(マスタ設定!$E$5:$E$14,MATCH($E4,マスタ設定!$A$5:$A$14,0))/100,"") -> 0.7 | N4: =IFERROR(INDEX(マスタ設定!$F$5:$F$14,MATCH($E4,マスタ設定!$A$5:$A$14,0))/100,"") -> 0.3 | O4: =IF(OR($K4="",$L4="",$M4="",$N4=""),"",ROUND($K4*$M4+$L4*$N4,1)) -> 71.7 | P4: =IF($A4="","",IF($O4="","データ不足",IF(AND($G4>=3,$J4>=2),"有効","要確認"))) -> 有効
A5: =IF(調査集計表!A5="","",調査集計表!A5) -> A-003 | B5: =IF(調査集計表!C5="","",調査集計表!C5) -> 46162 | C5: =IF(調査集計表!D5="","",調査集計表!D5) -> P01 | D5: =IF(調査集計表!E5="","",調査集計表!E5) -> 佐藤（記入例） | E5: =IF(調査集計表!F5="","",調査集計表!F5) -> U01 | F5: =IF(調査集計表!H5="","",調査集計表!H5) -> 難2 | G5: =COUNT(調査集計表!J5,調査集計表!L5,調査集計表!N5,調査集計表!P5,調査集計表!R5) -> 4 | H5: =IF($G5=0,"",MEDIAN(調査集計表!J5,調査集計表!L5,調査集計表!N5,調査集計表!P5,調査集計表!R5)) -> 3 | I5: =IFERROR(AVERAGE(調査集計表!T5,調査集計表!V5),"") -> 3 | J5: =COUNT(調査集計表!T5,調査集計表!V5) -> 2 | K5: =IF($H5="","",ROUND($H5/3*100,1)) -> 100 | L5: =IF($I5="","",ROUND($I5/3*100,1)) -> 100 | M5: =IFERROR(INDEX(マスタ設定!$E$5:$E$14,MATCH($E5,マスタ設定!$A$5:$A$14,0))/100,"") -> 0.7 | N5: =IFERROR(INDEX(マスタ設定!$F$5:$F$14,MATCH($E5,マスタ設定!$A$5:$A$14,0))/100,"") -> 0.3 | O5: =IF(OR($K5="",$L5="",$M5="",$N5=""),"",ROUND($K5*$M5+$L5*$N5,1)) -> 100 | P5: =IF($A5="","",IF($O5="","データ不足",IF(AND($G5>=3,$J5>=2),"有効","要確認"))) -> 有効
A6: =IF(調査集計表!A6="","",調査集計表!A6) -> A-004 | B6: =IF(調査集計表!C6="","",調査集計表!C6) -> 46246 | C6: =IF(調査集計表!D6="","",調査集計表!D6) -> P01 | D6: =IF(調査集計表!E6="","",調査集計表!E6) -> 佐藤（記入例） | E6: =IF(調査集計表!F6="","",調査集計表!F6) -> U01 | F6: =IF(調査集計表!H6="","",調査集計表!H6) -> 難2 | G6: =COUNT(調査集計表!J6,調査集計表!L6,調査集計表!N6,調査集計表!P6,調査集計表!R6) -> 3 | H6: =IF($G6=0,"",MEDIAN(調査集計表!J6,調査集計表!L6,調査集計表!N6,調査集計表!P6,調査集計表!R6)) -> 3 | I6: =IFERROR(AVERAGE(調査集計表!T6,調査集計表!V6),"") -> 3 | J6: =COUNT(調査集計表!T6,調査集計表!V6) -> 2 | K6: =IF($H6="","",ROUND($H6/3*100,1)) -> 100 | L6: =IF($I6="","",ROUND($I6/3*100,1)) -> 100 | M6: =IFERROR(INDEX(マスタ設定!$E$5:$E$14,MATCH($E6,マスタ設定!$A$5:$A$14,0))/100,"") -> 0.7 | N6: =IFERROR(INDEX(マスタ設定!$F$5:$F$14,MATCH($E6,マスタ設定!$A$5:$A$14,0))/100,"") -> 0.3 | O6: =IF(OR($K6="",$L6="",$M6="",$N6=""),"",ROUND($K6*$M6+$L6*$N6,1)) -> 100 | P6: =IF($A6="","",IF($O6="","データ不足",IF(AND($G6>=3,$J6>=2),"有効","要確認"))) -> 有効
A7: =IF(調査集計表!A7="","",調査集計表!A7) -> A-005 | B7: =IF(調査集計表!C7="","",調査集計表!C7) -> 46344 | C7: =IF(調査集計表!D7="","",調査集計表!D7) -> P01 | D7: =IF(調査集計表!E7="","",調査集計表!E7) -> 佐藤（記入例） | E7: =IF(調査集計表!F7="","",調査集計表!F7) -> U01 | F7: =IF(調査集計表!H7="","",調査集計表!H7) -> 難3 | G7: =COUNT(調査集計表!J7,調査集計表!L7,調査集計表!N7,調査集計表!P7,調査集計表!R7) -> 4 | H7: =IF($G7=0,"",MEDIAN(調査集計表!J7,調査集計表!L7,調査集計表!N7,調査集計表!P7,調査集計表!R7)) -> 3.5 | I7: =IFERROR(AVERAGE(調査集計表!T7,調査集計表!V7),"") -> 3.5 | J7: =COUNT(調査集計表!T7,調査集計表!V7) -> 2 | K7: =IF($H7="","",ROUND($H7/3*100,1)) -> 116.7 | L7: =IF($I7="","",ROUND($I7/3*100,1)) -> 116.7 | M7: =IFERROR(INDEX(マスタ設定!$E$5:$E$14,MATCH($E7,マスタ設定!$A$5:$A$14,0))/100,"") -> 0.7 | N7: =IFERROR(INDEX(マスタ設定!$F$5:$F$14,MATCH($E7,マスタ設定!$A$5:$A$14,0))/100,"") -> 0.3 | O7: =IF(OR($K7="",$L7="",$M7="",$N7=""),"",ROUND($K7*$M7+$L7*$N7,1)) -> 116.7 | P7: =IF($A7="","",IF($O7="","データ不足",IF(AND($G7>=3,$J7>=2),"有効","要確認"))) -> 有効
A8: =IF(調査集計表!A8="","",調査集計表!A8) -> A-006 | B8: =IF(調査集計表!C8="","",調査集計表!C8) -> 46440 | C8: =IF(調査集計表!D8="","",調査集計表!D8) -> P01 | D8: =IF(調査集計表!E8="","",調査集計表!E8) -> 佐藤（記入例） | E8: =IF(調査集計表!F8="","",調査集計表!F8) -> U01 | F8: =IF(調査集計表!H8="","",調査集計表!H8) -> 難3 | G8: =COUNT(調査集計表!J8,調査集計表!L8,調査集計表!N8,調査集計表!P8,調査集計表!R8) -> 4 | H8: =IF($G8=0,"",MEDIAN(調査集計表!J8,調査集計表!L8,調査集計表!N8,調査集計表!P8,調査集計表!R8)) -> 4 | I8: =IFERROR(AVERAGE(調査集計表!T8,調査集計表!V8),"") -> 3.5 | J8: =COUNT(調査集計表!T8,調査集計表!V8) -> 2 | K8: =IF($H8="","",ROUND($H8/3*100,1)) -> 133.3 | L8: =IF($I8="","",ROUND($I8/3*100,1)) -> 116.7 | M8: =IFERROR(INDEX(マスタ設定!$E$5:$E$14,MATCH($E8,マスタ設定!$A$5:$A$14,0))/100,"") -> 0.7 | N8: =IFERROR(INDEX(マスタ設定!$F$5:$F$14,MATCH($E8,マスタ設定!$A$5:$A$14,0))/100,"") -> 0.3 | O8: =IF(OR($K8="",$L8="",$M8="",$N8=""),"",ROUND($K8*$M8+$L8*$N8,1)) -> 128.3 | P8: =IF($A8="","",IF($O8="","データ不足",IF(AND($G8>=3,$J8>=2),"有効","要確認"))) -> 有効
A9: =IF(調査集計表!A9="","",調査集計表!A9) -> B-001 | B9: =IF(調査集計表!C9="","",調査集計表!C9) -> 46078 | C9: =IF(調査集計表!D9="","",調査集計表!D9) -> P02 | D9: =IF(調査集計表!E9="","",調査集計表!E9) -> 鈴木（記入例） | E9: =IF(調査集計表!F9="","",調査集計表!F9) -> U01 | F9: =IF(調査集計表!H9="","",調査集計表!H9) -> 難1 | G9: =COUNT(調査集計表!J9,調査集計表!L9,調査集計表!N9,調査集計表!P9,調査集計表!R9) -> 3 | H9: =IF($G9=0,"",MEDIAN(調査集計表!J9,調査集計表!L9,調査集計表!N9,調査集計表!P9,調査集計表!R9)) -> 2 | I9: =IFERROR(AVERAGE(調査集計表!T9,調査集計表!V9),"") -> 2 | J9: =COUNT(調査集計表!T9,調査集計表!V9) -> 2 | K9: =IF($H9="","",ROUND($H9/3*100,1)) -> 66.7 | L9: =IF($I9="","",ROUND($I9/3*100,1)) -> 66.7 | M9: =IFERROR(INDEX(マスタ設定!$E$5:$E$14,MATCH($E9,マスタ設定!$A$5:$A$14,0))/100,"") -> 0.7 | N9: =IFERROR(INDEX(マスタ設定!$F$5:$F$14,MATCH($E9,マスタ設定!$A$5:$A$14,0))/100,"") -> 0.3 | O9: =IF(OR($K9="",$L9="",$M9="",$N9=""),"",ROUND($K9*$M9+$L9*$N9,1)) -> 66.7 | P9: =IF($A9="","",IF($O9="","データ不足",IF(AND($G9>=3,$J9>=2),"有効","要確認"))) -> 有効
A10: =IF(調査集計表!A10="","",調査集計表!A10) -> B-002 | B10: =IF(調査集計表!C10="","",調査集計表!C10) -> 46176 | C10: =IF(調査集計表!D10="","",調査集計表!D10) -> P02 | D10: =IF(調査集計表!E10="","",調査集計表!E10) -> 鈴木（記入例） | E10: =IF(調査集計表!F10="","",調査集計表!F10) -> U01 | F10: =IF(調査集計表!H10="","",調査集計表!H10) -> 難1 | G10: =COUNT(調査集計表!J10,調査集計表!L10,調査集計表!N10,調査集計表!P10,調査集計表!R10) -> 3 | H10: =IF($G10=0,"",MEDIAN(調査集計表!J10,調査集計表!L10,調査集計表!N10,調査集計表!P10,調査集計表!R10)) -> 2 | I10: =IFERROR(AVERAGE(調査集計表!T10,調査集計表!V10),"") -> 2 | J10: =COUNT(調査集計表!T10,調査集計表!V10) -> 2 | K10: =IF($H10="","",ROUND($H10/3*100,1)) -> 66.7 | L10: =IF($I10="","",ROUND($I10/3*100,1)) -> 66.7 | M10: =IFERROR(INDEX(マスタ設定!$E$5:$E$14,MATCH($E10,マスタ設定!$A$5:$A$14,0))/100,"") -> 0.7 | N10: =IFERROR(INDEX(マスタ設定!$F$5:$F$14,MATCH($E10,マスタ設定!$A$5:$A$14,0))/100,"") -> 0.3 | O10: =IF(OR($K10="",$L10="",$M10="",$N10=""),"",ROUND($K10*$M10+$L10*$N10,1)) -> 66.7 | P10: =IF($A10="","",IF($O10="","データ不足",IF(AND($G10>=3,$J10>=2),"有効","要確認"))) -> 有効
A11: =IF(調査集計表!A11="","",調査集計表!A11) -> B-003 | B11: =IF(調査集計表!C11="","",調査集計表!C11) -> 46279 | C11: =IF(調査集計表!D11="","",調査集計表!D11) -> P02 | D11: =IF(調査集計表!E11="","",調査集計表!E11) -> 鈴木（記入例） | E11: =IF(調査集計表!F11="","",調査集計表!F11) -> U01 | F11: =IF(調査集計表!H11="","",調査集計表!H11) -> 難2 | G11: =COUNT(調査集計表!J11,調査集計表!L11,調査集計表!N11,調査集計表!P11,調査集計表!R11) -> 3 | H11: =IF($G11=0,"",MEDIAN(調査集計表!J11,調査集計表!L11,調査集計表!N11,調査集計表!P11,調査集計表!R11)) -> 3 | I11: =IFERROR(AVERAGE(調査集計表!T11,調査集計表!V11),"") -> 2.5 | J11: =COUNT(調査集計表!T11,調査集計表!V11) -> 2 | K11: =IF($H11="","",ROUND($H11/3*100,1)) -> 100 | L11: =IF($I11="","",ROUND($I11/3*100,1)) -> 83.3 | M11: =IFERROR(INDEX(マスタ設定!$E$5:$E$14,MATCH($E11,マスタ設定!$A$5:$A$14,0))/100,"") -> 0.7 | N11: =IFERROR(INDEX(マスタ設定!$F$5:$F$14,MATCH($E11,マスタ設定!$A$5:$A$14,0))/100,"") -> 0.3 | O11: =IF(OR($K11="",$L11="",$M11="",$N11=""),"",ROUND($K11*$M11+$L11*$N11,1)) -> 95 | P11: =IF($A11="","",IF($O11="","データ不足",IF(AND($G11>=3,$J11>=2),"有効","要確認"))) -> 有効
A12: =IF(調査集計表!A12="","",調査集計表!A12) -> B-004 | B12: =IF(調査集計表!C12="","",調査集計表!C12) -> 46364 | C12: =IF(調査集計表!D12="","",調査集計表!D12) -> P02 | D12: =IF(調査集計表!E12="","",調査集計表!E12) -> 鈴木（記入例） | E12: =IF(調査集計表!F12="","",調査集計表!F12) -> U01 | F12: =IF(調査集計表!H12="","",調査集計表!H12) -> 難2 | G12: =COUNT(調査集計表!J12,調査集計表!L12,調査集計表!N12,調査集計表!P12,調査集計表!R12) -> 3 | H12: =IF($G12=0,"",MEDIAN(調査集計表!J12,調査集計表!L12,調査集計表!N12,調査集計表!P12,調査集計表!R12)) -> 3 | I12: =IFERROR(AVERAGE(調査集計表!T12,調査集計表!V12),"") -> 3 | J12: =COUNT(調査集計表!T12,調査集計表!V12) -> 2 | K12: =IF($H12="","",ROUND($H12/3*100,1)) -> 100 | L12: =IF($I12="","",ROUND($I12/3*100,1)) -> 100 | M12: =IFERROR(INDEX(マスタ設定!$E$5:$E$14,MATCH($E12,マスタ設定!$A$5:$A$14,0))/100,"") -> 0.7 | N12: =IFERROR(INDEX(マスタ設定!$F$5:$F$14,MATCH($E12,マスタ設定!$A$5:$A$14,0))/100,"") -> 0.3 | O12: =IF(OR($K12="",$L12="",$M12="",$N12=""),"",ROUND($K12*$M12+$L12*$N12,1)) -> 100 | P12: =IF($A12="","",IF($O12="","データ不足",IF(AND($G12>=3,$J12>=2),"有効","要確認"))) -> 有効
A13: =IF(調査集計表!A13="","",調査集計表!A13) -> B-005 | B13: =IF(調査集計表!C13="","",調査集計表!C13) -> 46456 | C13: =IF(調査集計表!D13="","",調査集計表!D13) -> P02 | D13: =IF(調査集計表!E13="","",調査集計表!E13) -> 鈴木（記入例） | E13: =IF(調査集計表!F13="","",調査集計表!F13) -> U01 | F13: =IF(調査集計表!H13="","",調査集計表!H13) -> 難2 | G13: =COUNT(調査集計表!J13,調査集計表!L13,調査集計表!N13,調査集計表!P13,調査集計表!R13) -> 3 | H13: =IF($G13=0,"",MEDIAN(調査集計表!J13,調査集計表!L13,調査集計表!N13,調査集計表!P13,調査集計表!R13)) -> 3 | I13: =IFERROR(AVERAGE(調査集計表!T13,調査集計表!V13),"") -> 3 | J13: =COUNT(調査集計表!T13,調査集計表!V13) -> 2 | K13: =IF($H13="","",ROUND($H13/3*100,1)) -> 100 | L13: =IF($I13="","",ROUND($I13/3*100,1)) -> 100 | M13: =IFERROR(INDEX(マスタ設定!$E$5:$E$14,MATCH($E13,マスタ設定!$A$5:$A$14,0))/100,"") -> 0.7 | N13: =IFERROR(INDEX(マスタ設定!$F$5:$F$14,MATCH($E13,マスタ設定!$A$5:$A$14,0))/100,"") -> 0.3 | O13: =IF(OR($K13="",$L13="",$M13="",$N13=""),"",ROUND($K13*$M13+$L13*$N13,1)) -> 100 | P13: =IF($A13="","",IF($O13="","データ不足",IF(AND($G13>=3,$J13>=2),"有効","要確認"))) -> 有効
A14: =IF(調査集計表!A14="","",調査集計表!A14) -> C-001 | B14: =IF(調査集計表!C14="","",調査集計表!C14) -> 46071 | C14: =IF(調査集計表!D14="","",調査集計表!D14) -> P03 | D14: =IF(調査集計表!E14="","",調査集計表!E14) -> 田中（記入例） | E14: =IF(調査集計表!F14="","",調査集計表!F14) -> U02 | F14: =IF(調査集計表!H14="","",調査集計表!H14) -> 難2 | G14: =COUNT(調査集計表!J14,調査集計表!L14,調査集計表!N14,調査集計表!P14,調査集計表!R14) -> 3 | H14: =IF($G14=0,"",MEDIAN(調査集計表!J14,調査集計表!L14,調査集計表!N14,調査集計表!P14,調査集計表!R14)) -> 3 | I14: =IFERROR(AVERAGE(調査集計表!T14,調査集計表!V14),"") -> 2.5 | J14: =COUNT(調査集計表!T14,調査集計表!V14) -> 2 | K14: =IF($H14="","",ROUND($H14/3*100,1)) -> 100 | L14: =IF($I14="","",ROUND($I14/3*100,1)) -> 83.3 | M14: =IFERROR(INDEX(マスタ設定!$E$5:$E$14,MATCH($E14,マスタ設定!$A$5:$A$14,0))/100,"") -> 0.5 | N14: =IFERROR(INDEX(マスタ設定!$F$5:$F$14,MATCH($E14,マスタ設定!$A$5:$A$14,0))/100,"") -> 0.5 | O14: =IF(OR($K14="",$L14="",$M14="",$N14=""),"",ROUND($K14*$M14+$L14*$N14,1)) -> 91.7 | P14: =IF($A14="","",IF($O14="","データ不足",IF(AND($G14>=3,$J14>=2),"有効","要確認"))) -> 有効
... A202: =IF(調査集計表!A202="","",調査集計表!A202) | B202: =IF(調査集計表!C202="","",調査集計表!C202) | C202: =IF(調査集計表!D202="","",調査集計表!D202) | D202: =IF(調査集計表!E202="","",調査集計表!E202) | E202: =IF(調査集計表!F202="","",調査集計表!F202) | F202: =IF(調査集計表!H202="","",調査集計表!H202) | G202: =COUNT(調査集計表!J202,調査集計表!L202,調査集計表!N202,調査集計表!P202,調査集計表!R202) -> 0 | H202: =IF($G202=0,"",MEDIAN(調査集計表!J202,調査集計表!L202,調査集計表!N202,調査集計表!P202,調査集計表!R202)) | I202: =IFERROR(AVERAGE(調査集計表!T202,調査集計表!V202),"") | J202: =COUNT(調査集計表!T202,調査集計表!V202) -> 0 | K202: =IF($H202="","",ROUND($H202/3*100,1)) | L202: =IF($I202="","",ROUND($I202/3*100,1)) | M202: =IFERROR(INDEX(マスタ設定!$E$5:$E$14,MATCH($E202,マスタ設定!$A$5:$A$14,0))/100,"") | N202: =IFERROR(INDEX(マスタ設定!$F$5:$F$14,MATCH($E202,マスタ設定!$A$5:$A$14,0))/100,"") | O202: =IF(OR($K202="",$L202="",$M202="",$N202=""),"",ROUND($K202*$M202+$L202*$N202,1)) | P202: =IF($A202="","",IF($O202="","データ不足",IF(AND($G202>=3,$J202>=2),"有効","要確認")))
A204: ※ 判定「有効」＝ 関与者の回答が3名以上、かつ品質・コスト軸を2名が採点している案件。四半期集計と成長曲線は「有効」のみを対象にします。

Sheet 四半期集計
A1: 四半期集計 ― 対象者ごとの can-do到達率(y)。各期末から遡って12か月以内に完了した案件の平均です
A2: 対象者ID | B2: 氏名 | C2: 単位ID | D2: =マスタ設定!A41 -> 2026 Q1 | E2: =マスタ設定!A42 -> 2026 Q2 | F2: =マスタ設定!A43 -> 2026 Q3 | G2: =マスタ設定!A44 -> 2026 Q4 | H2: =マスタ設定!A45 -> 2027 Q1 | I2: =マスタ設定!A46 -> 2027 Q2 | J2: =マスタ設定!A47 -> 2027 Q3 | K2: =マスタ設定!A48 -> 2027 Q4 | L2: =マスタ設定!A49 -> 2028 Q1
A3: =IF(マスタ設定!A18="","",マスタ設定!A18) -> P01 | B3: =IF(マスタ設定!B18="","",マスタ設定!B18) -> 佐藤（記入例） | C3: =IF(マスタ設定!C18="","",マスタ設定!C18) -> U01 | D3: =IF($A3="","",IFERROR(AVERAGEIFS(スコアリング!$O$3:$O$202,スコアリング!$C$3:$C$202,$A3,スコアリング!$P$3:$P$202,"有効",スコアリング!$B$3:$B$202,">="&マスタ設定!$B$41-364,スコアリング!$B$3:$B$202,"<="&マスタ設定!$B$41),"")) -> 69.2 | E3: =IF($A3="","",IFERROR(AVERAGEIFS(スコアリング!$O$3:$O$202,スコアリング!$C$3:$C$202,$A3,スコアリング!$P$3:$P$202,"有効",スコアリング!$B$3:$B$202,">="&マスタ設定!$B$42-364,スコアリング!$B$3:$B$202,"<="&マスタ設定!$B$42),"")) -> 79.466667 | F3: =IF($A3="","",IFERROR(AVERAGEIFS(スコアリング!$O$3:$O$202,スコアリング!$C$3:$C$202,$A3,スコアリング!$P$3:$P$202,"有効",スコアリング!$B$3:$B$202,">="&マスタ設定!$B$43-364,スコアリング!$B$3:$B$202,"<="&マスタ設定!$B$43),"")) -> 84.6 | G3: =IF($A3="","",IFERROR(AVERAGEIFS(スコアリング!$O$3:$O$202,スコアリング!$C$3:$C$202,$A3,スコアリング!$P$3:$P$202,"有効",スコアリング!$B$3:$B$202,">="&マスタ設定!$B$44-364,スコアリング!$B$3:$B$202,"<="&マスタ設定!$B$44),"")) -> 91.02 | H3: =IF($A3="","",IFERROR(AVERAGEIFS(スコアリング!$O$3:$O$202,スコアリング!$C$3:$C$202,$A3,スコアリング!$P$3:$P$202,"有効",スコアリング!$B$3:$B$202,">="&マスタ設定!$B$45-364,スコアリング!$B$3:$B$202,"<="&マスタ設定!$B$45),"")) -> 111.25 | I3: =IF($A3="","",IFERROR(AVERAGEIFS(スコアリング!$O$3:$O$202,スコアリング!$C$3:$C$202,$A3,スコアリング!$P$3:$P$202,"有効",スコアリング!$B$3:$B$202,">="&マスタ設定!$B$46-364,スコアリング!$B$3:$B$202,"<="&マスタ設定!$B$46),"")) -> 112.5 | J3: =IF($A3="","",IFERROR(AVERAGEIFS(スコアリング!$O$3:$O$202,スコアリング!$C$3:$C$202,$A3,スコアリング!$P$3:$P$202,"有効",スコアリング!$B$3:$B$202,">="&マスタ設定!$B$47-364,スコアリング!$B$3:$B$202,"<="&マスタ設定!$B$47),"")) -> 116.66667 | K3: =IF($A3="","",IFERROR(AVERAGEIFS(スコアリング!$O$3:$O$202,スコアリング!$C$3:$C$202,$A3,スコアリング!$P$3:$P$202,"有効",スコアリング!$B$3:$B$202,">="&マスタ設定!$B$48-364,スコアリング!$B$3:$B$202,"<="&マスタ設定!$B$48),"")) -> 111.1 | L3: =IF($A3="","",IFERROR(AVERAGEIFS(スコアリング!$O$3:$O$202,スコアリング!$C$3:$C$202,$A3,スコアリング!$P$3:$P$202,"有効",スコアリング!$B$3:$B$202,">="&マスタ設定!$B$49-364,スコアリング!$B$3:$B$202,"<="&マスタ設定!$B$49),"")) -> 103.33333
A4: =IF(マスタ設定!A19="","",マスタ設定!A19) -> P02 | B4: =IF(マスタ設定!B19="","",マスタ設定!B19) -> 鈴木（記入例） | C4: =IF(マスタ設定!C19="","",マスタ設定!C19) -> U01 | D4: =IF($A4="","",IFERROR(AVERAGEIFS(スコアリング!$O$3:$O$202,スコアリング!$C$3:$C$202,$A4,スコアリング!$P$3:$P$202,"有効",スコアリング!$B$3:$B$202,">="&マスタ設定!$B$41-364,スコアリング!$B$3:$B$202,"<="&マスタ設定!$B$41),"")) -> 66.7 | E4: =IF($A4="","",IFERROR(AVERAGEIFS(スコアリング!$O$3:$O$202,スコアリング!$C$3:$C$202,$A4,スコアリング!$P$3:$P$202,"有効",スコアリング!$B$3:$B$202,">="&マスタ設定!$B$42-364,スコアリング!$B$3:$B$202,"<="&マスタ設定!$B$42),"")) -> 66.7 | F4: =IF($A4="","",IFERROR(AVERAGEIFS(スコアリング!$O$3:$O$202,スコアリング!$C$3:$C$202,$A4,スコアリング!$P$3:$P$202,"有効",スコアリング!$B$3:$B$202,">="&マスタ設定!$B$43-364,スコアリング!$B$3:$B$202,"<="&マスタ設定!$B$43),"")) -> 76.133333 | G4: =IF($A4="","",IFERROR(AVERAGEIFS(スコアリング!$O$3:$O$202,スコアリング!$C$3:$C$202,$A4,スコアリング!$P$3:$P$202,"有効",スコアリング!$B$3:$B$202,">="&マスタ設定!$B$44-364,スコアリング!$B$3:$B$202,"<="&マスタ設定!$B$44),"")) -> 82.1 | H4: =IF($A4="","",IFERROR(AVERAGEIFS(スコアリング!$O$3:$O$202,スコアリング!$C$3:$C$202,$A4,スコアリング!$P$3:$P$202,"有効",スコアリング!$B$3:$B$202,">="&マスタ設定!$B$45-364,スコアリング!$B$3:$B$202,"<="&マスタ設定!$B$45),"")) -> 90.425 | I4: =IF($A4="","",IFERROR(AVERAGEIFS(スコアリング!$O$3:$O$202,スコアリング!$C$3:$C$202,$A4,スコアリング!$P$3:$P$202,"有効",スコアリング!$B$3:$B$202,">="&マスタ設定!$B$46-364,スコアリング!$B$3:$B$202,"<="&マスタ設定!$B$46),"")) -> 98.333333 | J4: =IF($A4="","",IFERROR(AVERAGEIFS(スコアリング!$O$3:$O$202,スコアリング!$C$3:$C$202,$A4,スコアリング!$P$3:$P$202,"有効",スコアリング!$B$3:$B$202,">="&マスタ設定!$B$47-364,スコアリング!$B$3:$B$202,"<="&マスタ設定!$B$47),"")) -> 100 | K4: =IF($A4="","",IFERROR(AVERAGEIFS(スコアリング!$O$3:$O$202,スコアリング!$C$3:$C$202,$A4,スコアリング!$P$3:$P$202,"有効",スコアリング!$B$3:$B$202,">="&マスタ設定!$B$48-364,スコアリング!$B$3:$B$202,"<="&マスタ設定!$B$48),"")) -> 100 | L4: =IF($A4="","",IFERROR(AVERAGEIFS(スコアリング!$O$3:$O$202,スコアリング!$C$3:$C$202,$A4,スコアリング!$P$3:$P$202,"有効",スコアリング!$B$3:$B$202,">="&マスタ設定!$B$49-364,スコアリング!$B$3:$B$202,"<="&マスタ設定!$B$49),"")) -> 101.66667
A5: =IF(マスタ設定!A20="","",マスタ設定!A20) -> P03 | B5: =IF(マスタ設定!B20="","",マスタ設定!B20) -> 田中（記入例） | C5: =IF(マスタ設定!C20="","",マスタ設定!C20) -> U02 | D5: =IF($A5="","",IFERROR(AVERAGEIFS(スコアリング!$O$3:$O$202,スコアリング!$C$3:$C$202,$A5,スコアリング!$P$3:$P$202,"有効",スコアリング!$B$3:$B$202,">="&マスタ設定!$B$41-364,スコアリング!$B$3:$B$202,"<="&マスタ設定!$B$41),"")) -> 91.7 | E5: =IF($A5="","",IFERROR(AVERAGEIFS(スコアリング!$O$3:$O$202,スコアリング!$C$3:$C$202,$A5,スコアリング!$P$3:$P$202,"有効",スコアリング!$B$3:$B$202,">="&マスタ設定!$B$42-364,スコアリング!$B$3:$B$202,"<="&マスタ設定!$B$42),"")) -> 95.85 | F5: =IF($A5="","",IFERROR(AVERAGEIFS(スコアリング!$O$3:$O$202,スコアリング!$C$3:$C$202,$A5,スコアリング!$P$3:$P$202,"有効",スコアリング!$B$3:$B$202,">="&マスタ設定!$B$43-364,スコアリング!$B$3:$B$202,"<="&マスタ設定!$B$43),"")) -> 102.8 | G5: =IF($A5="","",IFERROR(AVERAGEIFS(スコアリング!$O$3:$O$202,スコアリング!$C$3:$C$202,$A5,スコアリング!$P$3:$P$202,"有効",スコアリング!$B$3:$B$202,">="&マスタ設定!$B$44-364,スコアリング!$B$3:$B$202,"<="&マスタ設定!$B$44),"")) -> 110.425 | H5: =IF($A5="","",IFERROR(AVERAGEIFS(スコアリング!$O$3:$O$202,スコアリング!$C$3:$C$202,$A5,スコアリング!$P$3:$P$202,"有効",スコアリング!$B$3:$B$202,">="&マスタ設定!$B$45-364,スコアリング!$B$3:$B$202,"<="&マスタ設定!$B$45),"")) -> 125 | I5: =IF($A5="","",IFERROR(AVERAGEIFS(スコアリング!$O$3:$O$202,スコアリング!$C$3:$C$202,$A5,スコアリング!$P$3:$P$202,"有効",スコアリング!$B$3:$B$202,">="&マスタ設定!$B$46-364,スコアリング!$B$3:$B$202,"<="&マスタ設定!$B$46),"")) -> 133.33333 | J5: =IF($A5="","",IFERROR(AVERAGEIFS(スコアリング!$O$3:$O$202,スコアリング!$C$3:$C$202,$A5,スコアリング!$P$3:$P$202,"有効",スコアリング!$B$3:$B$202,">="&マスタ設定!$B$47-364,スコアリング!$B$3:$B$202,"<="&マスタ設定!$B$47),"")) -> 147.23333 | K5: =IF($A5="","",IFERROR(AVERAGEIFS(スコアリング!$O$3:$O$202,スコアリング!$C$3:$C$202,$A5,スコアリング!$P$3:$P$202,"有効",スコアリング!$B$3:$B$202,">="&マスタ設定!$B$48-364,スコアリング!$B$3:$B$202,"<="&マスタ設定!$B$48),"")) -> 158.36667 | L5: =IF($A5="","",IFERROR(AVERAGEIFS(スコアリング!$O$3:$O$202,スコアリング!$C$3:$C$202,$A5,スコアリング!$P$3:$P$202,"有効",スコアリング!$B$3:$B$202,">="&マスタ設定!$B$49-364,スコアリング!$B$3:$B$202,"<="&マスタ設定!$B$49),"")) -> 163.93333
A6: =IF(マスタ設定!A21="","",マスタ設定!A21) | B6: =IF(マスタ設定!B21="","",マスタ設定!B21) | C6: =IF(マスタ設定!C21="","",マスタ設定!C21) | D6: =IF($A6="","",IFERROR(AVERAGEIFS(スコアリング!$O$3:$O$202,スコアリング!$C$3:$C$202,$A6,スコアリング!$P$3:$P$202,"有効",スコアリング!$B$3:$B$202,">="&マスタ設定!$B$41-364,スコアリング!$B$3:$B$202,"<="&マスタ設定!$B$41),"")) | E6: =IF($A6="","",IFERROR(AVERAGEIFS(スコアリング!$O$3:$O$202,スコアリング!$C$3:$C$202,$A6,スコアリング!$P$3:$P$202,"有効",スコアリング!$B$3:$B$202,">="&マスタ設定!$B$42-364,スコアリング!$B$3:$B$202,"<="&マスタ設定!$B$42),"")) | F6: =IF($A6="","",IFERROR(AVERAGEIFS(スコアリング!$O$3:$O$202,スコアリング!$C$3:$C$202,$A6,スコアリング!$P$3:$P$202,"有効",スコアリング!$B$3:$B$202,">="&マスタ設定!$B$43-364,スコアリング!$B$3:$B$202,"<="&マスタ設定!$B$43),"")) | G6: =IF($A6="","",IFERROR(AVERAGEIFS(スコアリング!$O$3:$O$202,スコアリング!$C$3:$C$202,$A6,スコアリング!$P$3:$P$202,"有効",スコアリング!$B$3:$B$202,">="&マスタ設定!$B$44-364,スコアリング!$B$3:$B$202,"<="&マスタ設定!$B$44),"")) | H6: =IF($A6="","",IFERROR(AVERAGEIFS(スコアリング!$O$3:$O$202,スコアリング!$C$3:$C$202,$A6,スコアリング!$P$3:$P$202,"有効",スコアリング!$B$3:$B$202,">="&マスタ設定!$B$45-364,スコアリング!$B$3:$B$202,"<="&マスタ設定!$B$45),"")) | I6: =IF($A6="","",IFERROR(AVERAGEIFS(スコアリング!$O$3:$O$202,スコアリング!$C$3:$C$202,$A6,スコアリング!$P$3:$P$202,"有効",スコアリング!$B$3:$B$202,">="&マスタ設定!$B$46-364,スコアリング!$B$3:$B$202,"<="&マスタ設定!$B$46),"")) | J6: =IF($A6="","",IFERROR(AVERAGEIFS(スコアリング!$O$3:$O$202,スコアリング!$C$3:$C$202,$A6,スコアリング!$P$3:$P$202,"有効",スコアリング!$B$3:$B$202,">="&マスタ設定!$B$47-364,スコアリング!$B$3:$B$202,"<="&マスタ設定!$B$47),"")) | K6: =IF($A6="","",IFERROR(AVERAGEIFS(スコアリング!$O$3:$O$202,スコアリング!$C$3:$C$202,$A6,スコアリング!$P$3:$P$202,"有効",スコアリング!$B$3:$B$202,">="&マスタ設定!$B$48-364,スコアリング!$B$3:$B$202,"<="&マスタ設定!$B$48),"")) | L6: =IF($A6="","",IFERROR(AVERAGEIFS(スコアリング!$O$3:$O$202,スコアリング!$C$3:$C$202,$A6,スコアリング!$P$3:$P$202,"有効",スコアリング!$B$3:$B$202,">="&マスタ設定!$B$49-364,スコアリング!$B$3:$B$202,"<="&マスタ設定!$B$49),""))
A7: =IF(マスタ設定!A22="","",マスタ設定!A22) | B7: =IF(マスタ設定!B22="","",マスタ設定!B22) | C7: =IF(マスタ設定!C22="","",マスタ設定!C22) | D7: =IF($A7="","",IFERROR(AVERAGEIFS(スコアリング!$O$3:$O$202,スコアリング!$C$3:$C$202,$A7,スコアリング!$P$3:$P$202,"有効",スコアリング!$B$3:$B$202,">="&マスタ設定!$B$41-364,スコアリング!$B$3:$B$202,"<="&マスタ設定!$B$41),"")) | E7: =IF($A7="","",IFERROR(AVERAGEIFS(スコアリング!$O$3:$O$202,スコアリング!$C$3:$C$202,$A7,スコアリング!$P$3:$P$202,"有効",スコアリング!$B$3:$B$202,">="&マスタ設定!$B$42-364,スコアリング!$B$3:$B$202,"<="&マスタ設定!$B$42),"")) | F7: =IF($A7="","",IFERROR(AVERAGEIFS(スコアリング!$O$3:$O$202,スコアリング!$C$3:$C$202,$A7,スコアリング!$P$3:$P$202,"有効",スコアリング!$B$3:$B$202,">="&マスタ設定!$B$43-364,スコアリング!$B$3:$B$202,"<="&マスタ設定!$B$43),"")) | G7: =IF($A7="","",IFERROR(AVERAGEIFS(スコアリング!$O$3:$O$202,スコアリング!$C$3:$C$202,$A7,スコアリング!$P$3:$P$202,"有効",スコアリング!$B$3:$B$202,">="&マスタ設定!$B$44-364,スコアリング!$B$3:$B$202,"<="&マスタ設定!$B$44),"")) | H7: =IF($A7="","",IFERROR(AVERAGEIFS(スコアリング!$O$3:$O$202,スコアリング!$C$3:$C$202,$A7,スコアリング!$P$3:$P$202,"有効",スコアリング!$B$3:$B$202,">="&マスタ設定!$B$45-364,スコアリング!$B$3:$B$202,"<="&マスタ設定!$B$45),"")) | I7: =IF($A7="","",IFERROR(AVERAGEIFS(スコアリング!$O$3:$O$202,スコアリング!$C$3:$C$202,$A7,スコアリング!$P$3:$P$202,"有効",スコアリング!$B$3:$B$202,">="&マスタ設定!$B$46-364,スコアリング!$B$3:$B$202,"<="&マスタ設定!$B$46),"")) | J7: =IF($A7="","",IFERROR(AVERAGEIFS(スコアリング!$O$3:$O$202,スコアリング!$C$3:$C$202,$A7,スコアリング!$P$3:$P$202,"有効",スコアリング!$B$3:$B$202,">="&マスタ設定!$B$47-364,スコアリング!$B$3:$B$202,"<="&マスタ設定!$B$47),"")) | K7: =IF($A7="","",IFERROR(AVERAGEIFS(スコアリング!$O$3:$O$202,スコアリング!$C$3:$C$202,$A7,スコアリング!$P$3:$P$202,"有効",スコアリング!$B$3:$B$202,">="&マスタ設定!$B$48-364,スコアリング!$B$3:$B$202,"<="&マスタ設定!$B$48),"")) | L7: =IF($A7="","",IFERROR(AVERAGEIFS(スコアリング!$O$3:$O$202,スコアリング!$C$3:$C$202,$A7,スコアリング!$P$3:$P$202,"有効",スコアリング!$B$3:$B$202,">="&マスタ設定!$B$49-364,スコアリング!$B$3:$B$202,"<="&マスタ設定!$B$49),""))
A8: =IF(マスタ設定!A23="","",マスタ設定!A23) | B8: =IF(マスタ設定!B23="","",マスタ設定!B23) | C8: =IF(マスタ設定!C23="","",マスタ設定!C23) | D8: =IF($A8="","",IFERROR(AVERAGEIFS(スコアリング!$O$3:$O$202,スコアリング!$C$3:$C$202,$A8,スコアリング!$P$3:$P$202,"有効",スコアリング!$B$3:$B$202,">="&マスタ設定!$B$41-364,スコアリング!$B$3:$B$202,"<="&マスタ設定!$B$41),"")) | E8: =IF($A8="","",IFERROR(AVERAGEIFS(スコアリング!$O$3:$O$202,スコアリング!$C$3:$C$202,$A8,スコアリング!$P$3:$P$202,"有効",スコアリング!$B$3:$B$202,">="&マスタ設定!$B$42-364,スコアリング!$B$3:$B$202,"<="&マスタ設定!$B$42),"")) | F8: =IF($A8="","",IFERROR(AVERAGEIFS(スコアリング!$O$3:$O$202,スコアリング!$C$3:$C$202,$A8,スコアリング!$P$3:$P$202,"有効",スコアリング!$B$3:$B$202,">="&マスタ設定!$B$43-364,スコアリング!$B$3:$B$202,"<="&マスタ設定!$B$43),"")) | G8: =IF($A8="","",IFERROR(AVERAGEIFS(スコアリング!$O$3:$O$202,スコアリング!$C$3:$C$202,$A8,スコアリング!$P$3:$P$202,"有効",スコアリング!$B$3:$B$202,">="&マスタ設定!$B$44-364,スコアリング!$B$3:$B$202,"<="&マスタ設定!$B$44),"")) | H8: =IF($A8="","",IFERROR(AVERAGEIFS(スコアリング!$O$3:$O$202,スコアリング!$C$3:$C$202,$A8,スコアリング!$P$3:$P$202,"有効",スコアリング!$B$3:$B$202,">="&マスタ設定!$B$45-364,スコアリング!$B$3:$B$202,"<="&マスタ設定!$B$45),"")) | I8: =IF($A8="","",IFERROR(AVERAGEIFS(スコアリング!$O$3:$O$202,スコアリング!$C$3:$C$202,$A8,スコアリング!$P$3:$P$202,"有効",スコアリング!$B$3:$B$202,">="&マスタ設定!$B$46-364,スコアリング!$B$3:$B$202,"<="&マスタ設定!$B$46),"")) | J8: =IF($A8="","",IFERROR(AVERAGEIFS(スコアリング!$O$3:$O$202,スコアリング!$C$3:$C$202,$A8,スコアリング!$P$3:$P$202,"有効",スコアリング!$B$3:$B$202,">="&マスタ設定!$B$47-364,スコアリング!$B$3:$B$202,"<="&マスタ設定!$B$47),"")) | K8: =IF($A8="","",IFERROR(AVERAGEIFS(スコアリング!$O$3:$O$202,スコアリング!$C$3:$C$202,$A8,スコアリング!$P$3:$P$202,"有効",スコアリング!$B$3:$B$202,">="&マスタ設定!$B$48-364,スコアリング!$B$3:$B$202,"<="&マスタ設定!$B$48),"")) | L8: =IF($A8="","",IFERROR(AVERAGEIFS(スコアリング!$O$3:$O$202,スコアリング!$C$3:$C$202,$A8,スコアリング!$P$3:$P$202,"有効",スコアリング!$B$3:$B$202,">="&マスタ設定!$B$49-364,スコアリング!$B$3:$B$202,"<="&マスタ設定!$B$49),""))
A9: =IF(マスタ設定!A24="","",マスタ設定!A24) | B9: =IF(マスタ設定!B24="","",マスタ設定!B24) | C9: =IF(マスタ設定!C24="","",マスタ設定!C24) | D9: =IF($A9="","",IFERROR(AVERAGEIFS(スコアリング!$O$3:$O$202,スコアリング!$C$3:$C$202,$A9,スコアリング!$P$3:$P$202,"有効",スコアリング!$B$3:$B$202,">="&マスタ設定!$B$41-364,スコアリング!$B$3:$B$202,"<="&マスタ設定!$B$41),"")) | E9: =IF($A9="","",IFERROR(AVERAGEIFS(スコアリング!$O$3:$O$202,スコアリング!$C$3:$C$202,$A9,スコアリング!$P$3:$P$202,"有効",スコアリング!$B$3:$B$202,">="&マスタ設定!$B$42-364,スコアリング!$B$3:$B$202,"<="&マスタ設定!$B$42),"")) | F9: =IF($A9="","",IFERROR(AVERAGEIFS(スコアリング!$O$3:$O$202,スコアリング!$C$3:$C$202,$A9,スコアリング!$P$3:$P$202,"有効",スコアリング!$B$3:$B$202,">="&マスタ設定!$B$43-364,スコアリング!$B$3:$B$202,"<="&マスタ設定!$B$43),"")) | G9: =IF($A9="","",IFERROR(AVERAGEIFS(スコアリング!$O$3:$O$202,スコアリング!$C$3:$C$202,$A9,スコアリング!$P$3:$P$202,"有効",スコアリング!$B$3:$B$202,">="&マスタ設定!$B$44-364,スコアリング!$B$3:$B$202,"<="&マスタ設定!$B$44),"")) | H9: =IF($A9="","",IFERROR(AVERAGEIFS(スコアリング!$O$3:$O$202,スコアリング!$C$3:$C$202,$A9,スコアリング!$P$3:$P$202,"有効",スコアリング!$B$3:$B$202,">="&マスタ設定!$B$45-364,スコアリング!$B$3:$B$202,"<="&マスタ設定!$B$45),"")) | I9: =IF($A9="","",IFERROR(AVERAGEIFS(スコアリング!$O$3:$O$202,スコアリング!$C$3:$C$202,$A9,スコアリング!$P$3:$P$202,"有効",スコアリング!$B$3:$B$202,">="&マスタ設定!$B$46-364,スコアリング!$B$3:$B$202,"<="&マスタ設定!$B$46),"")) | J9: =IF($A9="","",IFERROR(AVERAGEIFS(スコアリング!$O$3:$O$202,スコアリング!$C$3:$C$202,$A9,スコアリング!$P$3:$P$202,"有効",スコアリング!$B$3:$B$202,">="&マスタ設定!$B$47-364,スコアリング!$B$3:$B$202,"<="&マスタ設定!$B$47),"")) | K9: =IF($A9="","",IFERROR(AVERAGEIFS(スコアリング!$O$3:$O$202,スコアリング!$C$3:$C$202,$A9,スコアリング!$P$3:$P$202,"有効",スコアリング!$B$3:$B$202,">="&マスタ設定!$B$48-364,スコアリング!$B$3:$B$202,"<="&マスタ設定!$B$48),"")) | L9: =IF($A9="","",IFERROR(AVERAGEIFS(スコアリング!$O$3:$O$202,スコアリング!$C$3:$C$202,$A9,スコアリング!$P$3:$P$202,"有効",スコアリング!$B$3:$B$202,">="&マスタ設定!$B$49-364,スコアリング!$B$3:$B$202,"<="&マスタ設定!$B$49),""))
A10: =IF(マスタ設定!A25="","",マスタ設定!A25) | B10: =IF(マスタ設定!B25="","",マスタ設定!B25) | C10: =IF(マスタ設定!C25="","",マスタ設定!C25) | D10: =IF($A10="","",IFERROR(AVERAGEIFS(スコアリング!$O$3:$O$202,スコアリング!$C$3:$C$202,$A10,スコアリング!$P$3:$P$202,"有効",スコアリング!$B$3:$B$202,">="&マスタ設定!$B$41-364,スコアリング!$B$3:$B$202,"<="&マスタ設定!$B$41),"")) | E10: =IF($A10="","",IFERROR(AVERAGEIFS(スコアリング!$O$3:$O$202,スコアリング!$C$3:$C$202,$A10,スコアリング!$P$3:$P$202,"有効",スコアリング!$B$3:$B$202,">="&マスタ設定!$B$42-364,スコアリング!$B$3:$B$202,"<="&マスタ設定!$B$42),"")) | F10: =IF($A10="","",IFERROR(AVERAGEIFS(スコアリング!$O$3:$O$202,スコアリング!$C$3:$C$202,$A10,スコアリング!$P$3:$P$202,"有効",スコアリング!$B$3:$B$202,">="&マスタ設定!$B$43-364,スコアリング!$B$3:$B$202,"<="&マスタ設定!$B$43),"")) | G10: =IF($A10="","",IFERROR(AVERAGEIFS(スコアリング!$O$3:$O$202,スコアリング!$C$3:$C$202,$A10,スコアリング!$P$3:$P$202,"有効",スコアリング!$B$3:$B$202,">="&マスタ設定!$B$44-364,スコアリング!$B$3:$B$202,"<="&マスタ設定!$B$44),"")) | H10: =IF($A10="","",IFERROR(AVERAGEIFS(スコアリング!$O$3:$O$202,スコアリング!$C$3:$C$202,$A10,スコアリング!$P$3:$P$202,"有効",スコアリング!$B$3:$B$202,">="&マスタ設定!$B$45-364,スコアリング!$B$3:$B$202,"<="&マスタ設定!$B$45),"")) | I10: =IF($A10="","",IFERROR(AVERAGEIFS(スコアリング!$O$3:$O$202,スコアリング!$C$3:$C$202,$A10,スコアリング!$P$3:$P$202,"有効",スコアリング!$B$3:$B$202,">="&マスタ設定!$B$46-364,スコアリング!$B$3:$B$202,"<="&マスタ設定!$B$46),"")) | J10: =IF($A10="","",IFERROR(AVERAGEIFS(スコアリング!$O$3:$O$202,スコアリング!$C$3:$C$202,$A10,スコアリング!$P$3:$P$202,"有効",スコアリング!$B$3:$B$202,">="&マスタ設定!$B$47-364,スコアリング!$B$3:$B$202,"<="&マスタ設定!$B$47),"")) | K10: =IF($A10="","",IFERROR(AVERAGEIFS(スコアリング!$O$3:$O$202,スコアリング!$C$3:$C$202,$A10,スコアリング!$P$3:$P$202,"有効",スコアリング!$B$3:$B$202,">="&マスタ設定!$B$48-364,スコアリング!$B$3:$B$202,"<="&マスタ設定!$B$48),"")) | L10: =IF($A10="","",IFERROR(AVERAGEIFS(スコアリング!$O$3:$O$202,スコアリング!$C$3:$C$202,$A10,スコアリング!$P$3:$P$202,"有効",スコアリング!$B$3:$B$202,">="&マスタ設定!$B$49-364,スコアリング!$B$3:$B$202,"<="&マスタ設定!$B$49),""))
A11: =IF(マスタ設定!A26="","",マスタ設定!A26) | B11: =IF(マスタ設定!B26="","",マスタ設定!B26) | C11: =IF(マスタ設定!C26="","",マスタ設定!C26) | D11: =IF($A11="","",IFERROR(AVERAGEIFS(スコアリング!$O$3:$O$202,スコアリング!$C$3:$C$202,$A11,スコアリング!$P$3:$P$202,"有効",スコアリング!$B$3:$B$202,">="&マスタ設定!$B$41-364,スコアリング!$B$3:$B$202,"<="&マスタ設定!$B$41),"")) | E11: =IF($A11="","",IFERROR(AVERAGEIFS(スコアリング!$O$3:$O$202,スコアリング!$C$3:$C$202,$A11,スコアリング!$P$3:$P$202,"有効",スコアリング!$B$3:$B$202,">="&マスタ設定!$B$42-364,スコアリング!$B$3:$B$202,"<="&マスタ設定!$B$42),"")) | F11: =IF($A11="","",IFERROR(AVERAGEIFS(スコアリング!$O$3:$O$202,スコアリング!$C$3:$C$202,$A11,スコアリング!$P$3:$P$202,"有効",スコアリング!$B$3:$B$202,">="&マスタ設定!$B$43-364,スコアリング!$B$3:$B$202,"<="&マスタ設定!$B$43),"")) | G11: =IF($A11="","",IFERROR(AVERAGEIFS(スコアリング!$O$3:$O$202,スコアリング!$C$3:$C$202,$A11,スコアリング!$P$3:$P$202,"有効",スコアリング!$B$3:$B$202,">="&マスタ設定!$B$44-364,スコアリング!$B$3:$B$202,"<="&マスタ設定!$B$44),"")) | H11: =IF($A11="","",IFERROR(AVERAGEIFS(スコアリング!$O$3:$O$202,スコアリング!$C$3:$C$202,$A11,スコアリング!$P$3:$P$202,"有効",スコアリング!$B$3:$B$202,">="&マスタ設定!$B$45-364,スコアリング!$B$3:$B$202,"<="&マスタ設定!$B$45),"")) | I11: =IF($A11="","",IFERROR(AVERAGEIFS(スコアリング!$O$3:$O$202,スコアリング!$C$3:$C$202,$A11,スコアリング!$P$3:$P$202,"有効",スコアリング!$B$3:$B$202,">="&マスタ設定!$B$46-364,スコアリング!$B$3:$B$202,"<="&マスタ設定!$B$46),"")) | J11: =IF($A11="","",IFERROR(AVERAGEIFS(スコアリング!$O$3:$O$202,スコアリング!$C$3:$C$202,$A11,スコアリング!$P$3:$P$202,"有効",スコアリング!$B$3:$B$202,">="&マスタ設定!$B$47-364,スコアリング!$B$3:$B$202,"<="&マスタ設定!$B$47),"")) | K11: =IF($A11="","",IFERROR(AVERAGEIFS(スコアリング!$O$3:$O$202,スコアリング!$C$3:$C$202,$A11,スコアリング!$P$3:$P$202,"有効",スコアリング!$B$3:$B$202,">="&マスタ設定!$B$48-364,スコアリング!$B$3:$B$202,"<="&マスタ設定!$B$48),"")) | L11: =IF($A11="","",IFERROR(AVERAGEIFS(スコアリング!$O$3:$O$202,スコアリング!$C$3:$C$202,$A11,スコアリング!$P$3:$P$202,"有効",スコアリング!$B$3:$B$202,">="&マスタ設定!$B$49-364,スコアリング!$B$3:$B$202,"<="&マスタ設定!$B$49),""))
A12: =IF(マスタ設定!A27="","",マスタ設定!A27) | B12: =IF(マスタ設定!B27="","",マスタ設定!B27) | C12: =IF(マスタ設定!C27="","",マスタ設定!C27) | D12: =IF($A12="","",IFERROR(AVERAGEIFS(スコアリング!$O$3:$O$202,スコアリング!$C$3:$C$202,$A12,スコアリング!$P$3:$P$202,"有効",スコアリング!$B$3:$B$202,">="&マスタ設定!$B$41-364,スコアリング!$B$3:$B$202,"<="&マスタ設定!$B$41),"")) | E12: =IF($A12="","",IFERROR(AVERAGEIFS(スコアリング!$O$3:$O$202,スコアリング!$C$3:$C$202,$A12,スコアリング!$P$3:$P$202,"有効",スコアリング!$B$3:$B$202,">="&マスタ設定!$B$42-364,スコアリング!$B$3:$B$202,"<="&マスタ設定!$B$42),"")) | F12: =IF($A12="","",IFERROR(AVERAGEIFS(スコアリング!$O$3:$O$202,スコアリング!$C$3:$C$202,$A12,スコアリング!$P$3:$P$202,"有効",スコアリング!$B$3:$B$202,">="&マスタ設定!$B$43-364,スコアリング!$B$3:$B$202,"<="&マスタ設定!$B$43),"")) | G12: =IF($A12="","",IFERROR(AVERAGEIFS(スコアリング!$O$3:$O$202,スコアリング!$C$3:$C$202,$A12,スコアリング!$P$3:$P$202,"有効",スコアリング!$B$3:$B$202,">="&マスタ設定!$B$44-364,スコアリング!$B$3:$B$202,"<="&マスタ設定!$B$44),"")) | H12: =IF($A12="","",IFERROR(AVERAGEIFS(スコアリング!$O$3:$O$202,スコアリング!$C$3:$C$202,$A12,スコアリング!$P$3:$P$202,"有効",スコアリング!$B$3:$B$202,">="&マスタ設定!$B$45-364,スコアリング!$B$3:$B$202,"<="&マスタ設定!$B$45),"")) | I12: =IF($A12="","",IFERROR(AVERAGEIFS(スコアリング!$O$3:$O$202,スコアリング!$C$3:$C$202,$A12,スコアリング!$P$3:$P$202,"有効",スコアリング!$B$3:$B$202,">="&マスタ設定!$B$46-364,スコアリング!$B$3:$B$202,"<="&マスタ設定!$B$46),"")) | J12: =IF($A12="","",IFERROR(AVERAGEIFS(スコアリング!$O$3:$O$202,スコアリング!$C$3:$C$202,$A12,スコアリング!$P$3:$P$202,"有効",スコアリング!$B$3:$B$202,">="&マスタ設定!$B$47-364,スコアリング!$B$3:$B$202,"<="&マスタ設定!$B$47),"")) | K12: =IF($A12="","",IFERROR(AVERAGEIFS(スコアリング!$O$3:$O$202,スコアリング!$C$3:$C$202,$A12,スコアリング!$P$3:$P$202,"有効",スコアリング!$B$3:$B$202,">="&マスタ設定!$B$48-364,スコアリング!$B$3:$B$202,"<="&マスタ設定!$B$48),"")) | L12: =IF($A12="","",IFERROR(AVERAGEIFS(スコアリング!$O$3:$O$202,スコアリング!$C$3:$C$202,$A12,スコアリング!$P$3:$P$202,"有効",スコアリング!$B$3:$B$202,">="&マスタ設定!$B$49-364,スコアリング!$B$3:$B$202,"<="&マスタ設定!$B$49),""))
A13: =IF(マスタ設定!A28="","",マスタ設定!A28) | B13: =IF(マスタ設定!B28="","",マスタ設定!B28) | C13: =IF(マスタ設定!C28="","",マスタ設定!C28) | D13: =IF($A13="","",IFERROR(AVERAGEIFS(スコアリング!$O$3:$O$202,スコアリング!$C$3:$C$202,$A13,スコアリング!$P$3:$P$202,"有効",スコアリング!$B$3:$B$202,">="&マスタ設定!$B$41-364,スコアリング!$B$3:$B$202,"<="&マスタ設定!$B$41),"")) | E13: =IF($A13="","",IFERROR(AVERAGEIFS(スコアリング!$O$3:$O$202,スコアリング!$C$3:$C$202,$A13,スコアリング!$P$3:$P$202,"有効",スコアリング!$B$3:$B$202,">="&マスタ設定!$B$42-364,スコアリング!$B$3:$B$202,"<="&マスタ設定!$B$42),"")) | F13: =IF($A13="","",IFERROR(AVERAGEIFS(スコアリング!$O$3:$O$202,スコアリング!$C$3:$C$202,$A13,スコアリング!$P$3:$P$202,"有効",スコアリング!$B$3:$B$202,">="&マスタ設定!$B$43-364,スコアリング!$B$3:$B$202,"<="&マスタ設定!$B$43),"")) | G13: =IF($A13="","",IFERROR(AVERAGEIFS(スコアリング!$O$3:$O$202,スコアリング!$C$3:$C$202,$A13,スコアリング!$P$3:$P$202,"有効",スコアリング!$B$3:$B$202,">="&マスタ設定!$B$44-364,スコアリング!$B$3:$B$202,"<="&マスタ設定!$B$44),"")) | H13: =IF($A13="","",IFERROR(AVERAGEIFS(スコアリング!$O$3:$O$202,スコアリング!$C$3:$C$202,$A13,スコアリング!$P$3:$P$202,"有効",スコアリング!$B$3:$B$202,">="&マスタ設定!$B$45-364,スコアリング!$B$3:$B$202,"<="&マスタ設定!$B$45),"")) | I13: =IF($A13="","",IFERROR(AVERAGEIFS(スコアリング!$O$3:$O$202,スコアリング!$C$3:$C$202,$A13,スコアリング!$P$3:$P$202,"有効",スコアリング!$B$3:$B$202,">="&マスタ設定!$B$46-364,スコアリング!$B$3:$B$202,"<="&マスタ設定!$B$46),"")) | J13: =IF($A13="","",IFERROR(AVERAGEIFS(スコアリング!$O$3:$O$202,スコアリング!$C$3:$C$202,$A13,スコアリング!$P$3:$P$202,"有効",スコアリング!$B$3:$B$202,">="&マスタ設定!$B$47-364,スコアリング!$B$3:$B$202,"<="&マスタ設定!$B$47),"")) | K13: =IF($A13="","",IFERROR(AVERAGEIFS(スコアリング!$O$3:$O$202,スコアリング!$C$3:$C$202,$A13,スコアリング!$P$3:$P$202,"有効",スコアリング!$B$3:$B$202,">="&マスタ設定!$B$48-364,スコアリング!$B$3:$B$202,"<="&マスタ設定!$B$48),"")) | L13: =IF($A13="","",IFERROR(AVERAGEIFS(スコアリング!$O$3:$O$202,スコアリング!$C$3:$C$202,$A13,スコアリング!$P$3:$P$202,"有効",スコアリング!$B$3:$B$202,">="&マスタ設定!$B$49-364,スコアリング!$B$3:$B$202,"<="&マスタ設定!$B$49),""))
A14: =IF(マスタ設定!A29="","",マスタ設定!A29) | B14: =IF(マスタ設定!B29="","",マスタ設定!B29) | C14: =IF(マスタ設定!C29="","",マスタ設定!C29) | D14: =IF($A14="","",IFERROR(AVERAGEIFS(スコアリング!$O$3:$O$202,スコアリング!$C$3:$C$202,$A14,スコアリング!$P$3:$P$202,"有効",スコアリング!$B$3:$B$202,">="&マスタ設定!$B$41-364,スコアリング!$B$3:$B$202,"<="&マスタ設定!$B$41),"")) | E14: =IF($A14="","",IFERROR(AVERAGEIFS(スコアリング!$O$3:$O$202,スコアリング!$C$3:$C$202,$A14,スコアリング!$P$3:$P$202,"有効",スコアリング!$B$3:$B$202,">="&マスタ設定!$B$42-364,スコアリング!$B$3:$B$202,"<="&マスタ設定!$B$42),"")) | F14: =IF($A14="","",IFERROR(AVERAGEIFS(スコアリング!$O$3:$O$202,スコアリング!$C$3:$C$202,$A14,スコアリング!$P$3:$P$202,"有効",スコアリング!$B$3:$B$202,">="&マスタ設定!$B$43-364,スコアリング!$B$3:$B$202,"<="&マスタ設定!$B$43),"")) | G14: =IF($A14="","",IFERROR(AVERAGEIFS(スコアリング!$O$3:$O$202,スコアリング!$C$3:$C$202,$A14,スコアリング!$P$3:$P$202,"有効",スコアリング!$B$3:$B$202,">="&マスタ設定!$B$44-364,スコアリング!$B$3:$B$202,"<="&マスタ設定!$B$44),"")) | H14: =IF($A14="","",IFERROR(AVERAGEIFS(スコアリング!$O$3:$O$202,スコアリング!$C$3:$C$202,$A14,スコアリング!$P$3:$P$202,"有効",スコアリング!$B$3:$B$202,">="&マスタ設定!$B$45-364,スコアリング!$B$3:$B$202,"<="&マスタ設定!$B$45),"")) | I14: =IF($A14="","",IFERROR(AVERAGEIFS(スコアリング!$O$3:$O$202,スコアリング!$C$3:$C$202,$A14,スコアリング!$P$3:$P$202,"有効",スコアリング!$B$3:$B$202,">="&マスタ設定!$B$46-364,スコアリング!$B$3:$B$202,"<="&マスタ設定!$B$46),"")) | J14: =IF($A14="","",IFERROR(AVERAGEIFS(スコアリング!$O$3:$O$202,スコアリング!$C$3:$C$202,$A14,スコアリング!$P$3:$P$202,"有効",スコアリング!$B$3:$B$202,">="&マスタ設定!$B$47-364,スコアリング!$B$3:$B$202,"<="&マスタ設定!$B$47),"")) | K14: =IF($A14="","",IFERROR(AVERAGEIFS(スコアリング!$O$3:$O$202,スコアリング!$C$3:$C$202,$A14,スコアリング!$P$3:$P$202,"有効",スコアリング!$B$3:$B$202,">="&マスタ設定!$B$48-364,スコアリング!$B$3:$B$202,"<="&マスタ設定!$B$48),"")) | L14: =IF($A14="","",IFERROR(AVERAGEIFS(スコアリング!$O$3:$O$202,スコアリング!$C$3:$C$202,$A14,スコアリング!$P$3:$P$202,"有効",スコアリング!$B$3:$B$202,">="&マスタ設定!$B$49-364,スコアリング!$B$3:$B$202,"<="&マスタ設定!$B$49),""))
... A22: =IF(マスタ設定!A37="","",マスタ設定!A37) | B22: =IF(マスタ設定!B37="","",マスタ設定!B37) | C22: =IF(マスタ設定!C37="","",マスタ設定!C37) | D22: =IF($A22="","",IFERROR(AVERAGEIFS(スコアリング!$O$3:$O$202,スコアリング!$C$3:$C$202,$A22,スコアリング!$P$3:$P$202,"有効",スコアリング!$B$3:$B$202,">="&マスタ設定!$B$41-364,スコアリング!$B$3:$B$202,"<="&マスタ設定!$B$41),"")) | E22: =IF($A22="","",IFERROR(AVERAGEIFS(スコアリング!$O$3:$O$202,スコアリング!$C$3:$C$202,$A22,スコアリング!$P$3:$P$202,"有効",スコアリング!$B$3:$B$202,">="&マスタ設定!$B$42-364,スコアリング!$B$3:$B$202,"<="&マスタ設定!$B$42),"")) | F22: =IF($A22="","",IFERROR(AVERAGEIFS(スコアリング!$O$3:$O$202,スコアリング!$C$3:$C$202,$A22,スコアリング!$P$3:$P$202,"有効",スコアリング!$B$3:$B$202,">="&マスタ設定!$B$43-364,スコアリング!$B$3:$B$202,"<="&マスタ設定!$B$43),"")) | G22: =IF($A22="","",IFERROR(AVERAGEIFS(スコアリング!$O$3:$O$202,スコアリング!$C$3:$C$202,$A22,スコアリング!$P$3:$P$202,"有効",スコアリング!$B$3:$B$202,">="&マスタ設定!$B$44-364,スコアリング!$B$3:$B$202,"<="&マスタ設定!$B$44),"")) | H22: =IF($A22="","",IFERROR(AVERAGEIFS(スコアリング!$O$3:$O$202,スコアリング!$C$3:$C$202,$A22,スコアリング!$P$3:$P$202,"有効",スコアリング!$B$3:$B$202,">="&マスタ設定!$B$45-364,スコアリング!$B$3:$B$202,"<="&マスタ設定!$B$45),"")) | I22: =IF($A22="","",IFERROR(AVERAGEIFS(スコアリング!$O$3:$O$202,スコアリング!$C$3:$C$202,$A22,スコアリング!$P$3:$P$202,"有効",スコアリング!$B$3:$B$202,">="&マスタ設定!$B$46-364,スコアリング!$B$3:$B$202,"<="&マスタ設定!$B$46),"")) | J22: =IF($A22="","",IFERROR(AVERAGEIFS(スコアリング!$O$3:$O$202,スコアリング!$C$3:$C$202,$A22,スコアリング!$P$3:$P$202,"有効",スコアリング!$B$3:$B$202,">="&マスタ設定!$B$47-364,スコアリング!$B$3:$B$202,"<="&マスタ設定!$B$47),"")) | K22: =IF($A22="","",IFERROR(AVERAGEIFS(スコアリング!$O$3:$O$202,スコアリング!$C$3:$C$202,$A22,スコアリング!$P$3:$P$202,"有効",スコアリング!$B$3:$B$202,">="&マスタ設定!$B$48-364,スコアリング!$B$3:$B$202,"<="&マスタ設定!$B$48),"")) | L22: =IF($A22="","",IFERROR(AVERAGEIFS(スコアリング!$O$3:$O$202,スコアリング!$C$3:$C$202,$A22,スコアリング!$P$3:$P$202,"有効",スコアリング!$B$3:$B$202,">="&マスタ設定!$B$49-364,スコアリング!$B$3:$B$202,"<="&マスタ設定!$B$49),""))
A24: ※ 空欄は、その期末までの12か月に有効な案件が1件も無かったことを示します。

Sheet 成長曲線
A1: 成長曲線 ― 職種×担当領域ごとの can-do到達率(y) の推移
A2: 要求水準（100）に対してどちら側にいるか、時間を追ってどう動いているかを見ます。グラフには単位マスタの先頭6件を表示します。
A4: 単位ID → | D4: =IF(マスタ設定!A5="","",マスタ設定!A5) -> U01 | E4: =IF(マスタ設定!A6="","",マスタ設定!A6) -> U02 | F4: =IF(マスタ設定!A7="","",マスタ設定!A7) | G4: =IF(マスタ設定!A8="","",マスタ設定!A8) | H4: =IF(マスタ設定!A9="","",マスタ設定!A9) | I4: =IF(マスタ設定!A10="","",マスタ設定!A10)
A5: 期ラベル | B5: 期末日 | C5: 経過t | D5: =IF(マスタ設定!A5="","（未設定）",マスタ設定!B5&"／"&マスタ設定!C5) -> ビジネスパートナー／ERP領域（専任） | E5: =IF(マスタ設定!A6="","（未設定）",マスタ設定!B6&"／"&マスタ設定!C6) -> データアーキテクト／データ活用基盤 | F5: =IF(マスタ設定!A7="","（未設定）",マスタ設定!B7&"／"&マスタ設定!C7) -> （未設定） | G5: =IF(マスタ設定!A8="","（未設定）",マスタ設定!B8&"／"&マスタ設定!C8) -> （未設定） | H5: =IF(マスタ設定!A9="","（未設定）",マスタ設定!B9&"／"&マスタ設定!C9) -> （未設定） | I5: =IF(マスタ設定!A10="","（未設定）",マスタ設定!B10&"／"&マスタ設定!C10) -> （未設定） | J5: 要求水準（＝100）
A6: =マスタ設定!A41 -> 2026 Q1 | B6: =マスタ設定!B41 -> 46112 | C6: =マスタ設定!C41 -> 0 | D6: =IF(D$4="","",IFERROR(AVERAGEIFS(スコアリング!$O$3:$O$202,スコアリング!$E$3:$E$202,D$4,スコアリング!$P$3:$P$202,"有効",スコアリング!$B$3:$B$202,">="&$B6-364,スコアリング!$B$3:$B$202,"<="&$B6),"")) -> 68.366667 | E6: =IF(E$4="","",IFERROR(AVERAGEIFS(スコアリング!$O$3:$O$202,スコアリング!$E$3:$E$202,E$4,スコアリング!$P$3:$P$202,"有効",スコアリング!$B$3:$B$202,">="&$B6-364,スコアリング!$B$3:$B$202,"<="&$B6),"")) -> 91.7 | F6: =IF(F$4="","",IFERROR(AVERAGEIFS(スコアリング!$O$3:$O$202,スコアリング!$E$3:$E$202,F$4,スコアリング!$P$3:$P$202,"有効",スコアリング!$B$3:$B$202,">="&$B6-364,スコアリング!$B$3:$B$202,"<="&$B6),"")) | G6: =IF(G$4="","",IFERROR(AVERAGEIFS(スコアリング!$O$3:$O$202,スコアリング!$E$3:$E$202,G$4,スコアリング!$P$3:$P$202,"有効",スコアリング!$B$3:$B$202,">="&$B6-364,スコアリング!$B$3:$B$202,"<="&$B6),"")) | H6: =IF(H$4="","",IFERROR(AVERAGEIFS(スコアリング!$O$3:$O$202,スコアリング!$E$3:$E$202,H$4,スコアリング!$P$3:$P$202,"有効",スコアリング!$B$3:$B$202,">="&$B6-364,スコアリング!$B$3:$B$202,"<="&$B6),"")) | I6: =IF(I$4="","",IFERROR(AVERAGEIFS(スコアリング!$O$3:$O$202,スコアリング!$E$3:$E$202,I$4,スコアリング!$P$3:$P$202,"有効",スコアリング!$B$3:$B$202,">="&$B6-364,スコアリング!$B$3:$B$202,"<="&$B6),"")) | J6: 100
A7: =マスタ設定!A42 -> 2026 Q2 | B7: =マスタ設定!B42 -> 46203 | C7: =マスタ設定!C42 -> 12.5 | D7: =IF(D$4="","",IFERROR(AVERAGEIFS(スコアリング!$O$3:$O$202,スコアリング!$E$3:$E$202,D$4,スコアリング!$P$3:$P$202,"有効",スコアリング!$B$3:$B$202,">="&$B7-364,スコアリング!$B$3:$B$202,"<="&$B7),"")) -> 74.36 | E7: =IF(E$4="","",IFERROR(AVERAGEIFS(スコアリング!$O$3:$O$202,スコアリング!$E$3:$E$202,E$4,スコアリング!$P$3:$P$202,"有効",スコアリング!$B$3:$B$202,">="&$B7-364,スコアリング!$B$3:$B$202,"<="&$B7),"")) -> 95.85 | F7: =IF(F$4="","",IFERROR(AVERAGEIFS(スコアリング!$O$3:$O$202,スコアリング!$E$3:$E$202,F$4,スコアリング!$P$3:$P$202,"有効",スコアリング!$B$3:$B$202,">="&$B7-364,スコアリング!$B$3:$B$202,"<="&$B7),"")) | G7: =IF(G$4="","",IFERROR(AVERAGEIFS(スコアリング!$O$3:$O$202,スコアリング!$E$3:$E$202,G$4,スコアリング!$P$3:$P$202,"有効",スコアリング!$B$3:$B$202,">="&$B7-364,スコアリング!$B$3:$B$202,"<="&$B7),"")) | H7: =IF(H$4="","",IFERROR(AVERAGEIFS(スコアリング!$O$3:$O$202,スコアリング!$E$3:$E$202,H$4,スコアリング!$P$3:$P$202,"有効",スコアリング!$B$3:$B$202,">="&$B7-364,スコアリング!$B$3:$B$202,"<="&$B7),"")) | I7: =IF(I$4="","",IFERROR(AVERAGEIFS(スコアリング!$O$3:$O$202,スコアリング!$E$3:$E$202,I$4,スコアリング!$P$3:$P$202,"有効",スコアリング!$B$3:$B$202,">="&$B7-364,スコアリング!$B$3:$B$202,"<="&$B7),"")) | J7: 100
A8: =マスタ設定!A43 -> 2026 Q3 | B8: =マスタ設定!B43 -> 46295 | C8: =マスタ設定!C43 -> 25 | D8: =IF(D$4="","",IFERROR(AVERAGEIFS(スコアリング!$O$3:$O$202,スコアリング!$E$3:$E$202,D$4,スコアリング!$P$3:$P$202,"有効",スコアリング!$B$3:$B$202,">="&$B8-364,スコアリング!$B$3:$B$202,"<="&$B8),"")) -> 80.971429 | E8: =IF(E$4="","",IFERROR(AVERAGEIFS(スコアリング!$O$3:$O$202,スコアリング!$E$3:$E$202,E$4,スコアリング!$P$3:$P$202,"有効",スコアリング!$B$3:$B$202,">="&$B8-364,スコアリング!$B$3:$B$202,"<="&$B8),"")) -> 102.8 | F8: =IF(F$4="","",IFERROR(AVERAGEIFS(スコアリング!$O$3:$O$202,スコアリング!$E$3:$E$202,F$4,スコアリング!$P$3:$P$202,"有効",スコアリング!$B$3:$B$202,">="&$B8-364,スコアリング!$B$3:$B$202,"<="&$B8),"")) | G8: =IF(G$4="","",IFERROR(AVERAGEIFS(スコアリング!$O$3:$O$202,スコアリング!$E$3:$E$202,G$4,スコアリング!$P$3:$P$202,"有効",スコアリング!$B$3:$B$202,">="&$B8-364,スコアリング!$B$3:$B$202,"<="&$B8),"")) | H8: =IF(H$4="","",IFERROR(AVERAGEIFS(スコアリング!$O$3:$O$202,スコアリング!$E$3:$E$202,H$4,スコアリング!$P$3:$P$202,"有効",スコアリング!$B$3:$B$202,">="&$B8-364,スコアリング!$B$3:$B$202,"<="&$B8),"")) | I8: =IF(I$4="","",IFERROR(AVERAGEIFS(スコアリング!$O$3:$O$202,スコアリング!$E$3:$E$202,I$4,スコアリング!$P$3:$P$202,"有効",スコアリング!$B$3:$B$202,">="&$B8-364,スコアリング!$B$3:$B$202,"<="&$B8),"")) | J8: 100
A9: =マスタ設定!A44 -> 2026 Q4 | B9: =マスタ設定!B44 -> 46387 | C9: =マスタ設定!C44 -> 37.5 | D9: =IF(D$4="","",IFERROR(AVERAGEIFS(スコアリング!$O$3:$O$202,スコアリング!$E$3:$E$202,D$4,スコアリング!$P$3:$P$202,"有効",スコアリング!$B$3:$B$202,">="&$B9-364,スコアリング!$B$3:$B$202,"<="&$B9),"")) -> 87.055556 | E9: =IF(E$4="","",IFERROR(AVERAGEIFS(スコアリング!$O$3:$O$202,スコアリング!$E$3:$E$202,E$4,スコアリング!$P$3:$P$202,"有効",スコアリング!$B$3:$B$202,">="&$B9-364,スコアリング!$B$3:$B$202,"<="&$B9),"")) -> 110.425 | F9: =IF(F$4="","",IFERROR(AVERAGEIFS(スコアリング!$O$3:$O$202,スコアリング!$E$3:$E$202,F$4,スコアリング!$P$3:$P$202,"有効",スコアリング!$B$3:$B$202,">="&$B9-364,スコアリング!$B$3:$B$202,"<="&$B9),"")) | G9: =IF(G$4="","",IFERROR(AVERAGEIFS(スコアリング!$O$3:$O$202,スコアリング!$E$3:$E$202,G$4,スコアリング!$P$3:$P$202,"有効",スコアリング!$B$3:$B$202,">="&$B9-364,スコアリング!$B$3:$B$202,"<="&$B9),"")) | H9: =IF(H$4="","",IFERROR(AVERAGEIFS(スコアリング!$O$3:$O$202,スコアリング!$E$3:$E$202,H$4,スコアリング!$P$3:$P$202,"有効",スコアリング!$B$3:$B$202,">="&$B9-364,スコアリング!$B$3:$B$202,"<="&$B9),"")) | I9: =IF(I$4="","",IFERROR(AVERAGEIFS(スコアリング!$O$3:$O$202,スコアリング!$E$3:$E$202,I$4,スコアリング!$P$3:$P$202,"有効",スコアリング!$B$3:$B$202,">="&$B9-364,スコアリング!$B$3:$B$202,"<="&$B9),"")) | J9: 100
A10: =マスタ設定!A45 -> 2027 Q1 | B10: =マスタ設定!B45 -> 46477 | C10: =マスタ設定!C45 -> 50 | D10: =IF(D$4="","",IFERROR(AVERAGEIFS(スコアリング!$O$3:$O$202,スコアリング!$E$3:$E$202,D$4,スコアリング!$P$3:$P$202,"有効",スコアリング!$B$3:$B$202,">="&$B10-364,スコアリング!$B$3:$B$202,"<="&$B10),"")) -> 100.8375 | E10: =IF(E$4="","",IFERROR(AVERAGEIFS(スコアリング!$O$3:$O$202,スコアリング!$E$3:$E$202,E$4,スコアリング!$P$3:$P$202,"有効",スコアリング!$B$3:$B$202,">="&$B10-364,スコアリング!$B$3:$B$202,"<="&$B10),"")) -> 125 | F10: =IF(F$4="","",IFERROR(AVERAGEIFS(スコアリング!$O$3:$O$202,スコアリング!$E$3:$E$202,F$4,スコアリング!$P$3:$P$202,"有効",スコアリング!$B$3:$B$202,">="&$B10-364,スコアリング!$B$3:$B$202,"<="&$B10),"")) | G10: =IF(G$4="","",IFERROR(AVERAGEIFS(スコアリング!$O$3:$O$202,スコアリング!$E$3:$E$202,G$4,スコアリング!$P$3:$P$202,"有効",スコアリング!$B$3:$B$202,">="&$B10-364,スコアリング!$B$3:$B$202,"<="&$B10),"")) | H10: =IF(H$4="","",IFERROR(AVERAGEIFS(スコアリング!$O$3:$O$202,スコアリング!$E$3:$E$202,H$4,スコアリング!$P$3:$P$202,"有効",スコアリング!$B$3:$B$202,">="&$B10-364,スコアリング!$B$3:$B$202,"<="&$B10),"")) | I10: =IF(I$4="","",IFERROR(AVERAGEIFS(スコアリング!$O$3:$O$202,スコアリング!$E$3:$E$202,I$4,スコアリング!$P$3:$P$202,"有効",スコアリング!$B$3:$B$202,">="&$B10-364,スコアリング!$B$3:$B$202,"<="&$B10),"")) | J10: 100
A11: =マスタ設定!A46 -> 2027 Q2 | B11: =マスタ設定!B46 -> 46568 | C11: =マスタ設定!C46 -> 62.5 | D11: =IF(D$4="","",IFERROR(AVERAGEIFS(スコアリング!$O$3:$O$202,スコアリング!$E$3:$E$202,D$4,スコアリング!$P$3:$P$202,"有効",スコアリング!$B$3:$B$202,">="&$B11-364,スコアリング!$B$3:$B$202,"<="&$B11),"")) -> 106.42857 | E11: =IF(E$4="","",IFERROR(AVERAGEIFS(スコアリング!$O$3:$O$202,スコアリング!$E$3:$E$202,E$4,スコアリング!$P$3:$P$202,"有効",スコアリング!$B$3:$B$202,">="&$B11-364,スコアリング!$B$3:$B$202,"<="&$B11),"")) -> 133.33333 | F11: =IF(F$4="","",IFERROR(AVERAGEIFS(スコアリング!$O$3:$O$202,スコアリング!$E$3:$E$202,F$4,スコアリング!$P$3:$P$202,"有効",スコアリング!$B$3:$B$202,">="&$B11-364,スコアリング!$B$3:$B$202,"<="&$B11),"")) | G11: =IF(G$4="","",IFERROR(AVERAGEIFS(スコアリング!$O$3:$O$202,スコアリング!$E$3:$E$202,G$4,スコアリング!$P$3:$P$202,"有効",スコアリング!$B$3:$B$202,">="&$B11-364,スコアリング!$B$3:$B$202,"<="&$B11),"")) | H11: =IF(H$4="","",IFERROR(AVERAGEIFS(スコアリング!$O$3:$O$202,スコアリング!$E$3:$E$202,H$4,スコアリング!$P$3:$P$202,"有効",スコアリング!$B$3:$B$202,">="&$B11-364,スコアリング!$B$3:$B$202,"<="&$B11),"")) | I11: =IF(I$4="","",IFERROR(AVERAGEIFS(スコアリング!$O$3:$O$202,スコアリング!$E$3:$E$202,I$4,スコアリング!$P$3:$P$202,"有効",スコアリング!$B$3:$B$202,">="&$B11-364,スコアリング!$B$3:$B$202,"<="&$B11),"")) | J11: 100
A12: =マスタ設定!A47 -> 2027 Q3 | B12: =マスタ設定!B47 -> 46660 | C12: =マスタ設定!C47 -> 75 | D12: =IF(D$4="","",IFERROR(AVERAGEIFS(スコアリング!$O$3:$O$202,スコアリング!$E$3:$E$202,D$4,スコアリング!$P$3:$P$202,"有効",スコアリング!$B$3:$B$202,">="&$B12-364,スコアリング!$B$3:$B$202,"<="&$B12),"")) -> 108.33333 | E12: =IF(E$4="","",IFERROR(AVERAGEIFS(スコアリング!$O$3:$O$202,スコアリング!$E$3:$E$202,E$4,スコアリング!$P$3:$P$202,"有効",スコアリング!$B$3:$B$202,">="&$B12-364,スコアリング!$B$3:$B$202,"<="&$B12),"")) -> 147.23333 | F12: =IF(F$4="","",IFERROR(AVERAGEIFS(スコアリング!$O$3:$O$202,スコアリング!$E$3:$E$202,F$4,スコアリング!$P$3:$P$202,"有効",スコアリング!$B$3:$B$202,">="&$B12-364,スコアリング!$B$3:$B$202,"<="&$B12),"")) | G12: =IF(G$4="","",IFERROR(AVERAGEIFS(スコアリング!$O$3:$O$202,スコアリング!$E$3:$E$202,G$4,スコアリング!$P$3:$P$202,"有効",スコアリング!$B$3:$B$202,">="&$B12-364,スコアリング!$B$3:$B$202,"<="&$B12),"")) | H12: =IF(H$4="","",IFERROR(AVERAGEIFS(スコアリング!$O$3:$O$202,スコアリング!$E$3:$E$202,H$4,スコアリング!$P$3:$P$202,"有効",スコアリング!$B$3:$B$202,">="&$B12-364,スコアリング!$B$3:$B$202,"<="&$B12),"")) | I12: =IF(I$4="","",IFERROR(AVERAGEIFS(スコアリング!$O$3:$O$202,スコアリング!$E$3:$E$202,I$4,スコアリング!$P$3:$P$202,"有効",スコアリング!$B$3:$B$202,">="&$B12-364,スコアリング!$B$3:$B$202,"<="&$B12),"")) | J12: 100
